<robot name = "robot">
    <link name="Link0">
        <inertial>
            <origin xyz="0 0 0.460422873994446" rpy="0 0 0"/>
            <mass value="1" />
            <inertia ixx="100" ixy="0" ixz="0" iyy="100" iyz="0" izz="100" />
        </inertial>
        <visual>
            <origin xyz="0 0 0.460422873994446" rpy="0 0 0"/>
            <geometry>
                <box size="0.422115585827912 0.920845747988892 0.276108834875504" />
            </geometry>
            <material name="Blue">
                <color rgba="0 0.0 1.0 1.0"/>
            </material>
        </visual>
        <collision>
            <origin xyz="0 0 0.460422873994446" rpy="0 0 0"/>
            <geometry>
                <box size="0.422115585827912 0.920845747988892 0.276108834875504" />
            </geometry>
        </collision>
    </link>
    <joint name="Link0_Link1" type="revolute">
       <parent link="Link0"/>
       <child  link="Link1"/>
       <origin rpy="0 0 0" xyz="0 0.460422873994446 0.276108834875504" />
     <axis xyz="1 0 0"/>
       <limit effort="0.0" lower="-3.14159" upper="3.14159" velocity="0.0"/>
    </joint>
    <link name="Link1">
        <inertial>
            <origin xyz="0 0.2477790828679342 0.03585233914019931" rpy="0 0 0"/>
            <mass value="1" />
            <inertia ixx="100" ixy="0" ixz="0" iyy="100" iyz="0" izz="100" />
        </inertial>
        <visual>
            <origin xyz="0 0.2477790828679342 0.03585233914019931" rpy="0 0 0"/>
            <geometry>
                <box size="0.8694046619033527 0.4955581657358684 0.07170467828039861" />
            </geometry>
            <material name="Blue">
                <color rgba="0 0.0 1.0 1.0"/>
            </material>
        </visual>
        <collision>
            <origin xyz="0 0.2477790828679342 0.03585233914019931" rpy="0 0 0"/>
            <geometry>
                <box size="0.8694046619033527 0.4955581657358684 0.07170467828039861" />
            </geometry>
        </collision>
    </link>
    <joint name="Link1_Link2" type="revolute">
       <parent link="Link1"/>
       <child  link="Link2"/>
       <origin rpy="0 0 0" xyz="0 0.4955581657358684 0.07170467828039861" />
     <axis xyz="1 0 0"/>
       <limit effort="0.0" lower="-3.14159" upper="3.14159" velocity="0.0"/>
    </joint>
    <link name="Link2">
        <inertial>
            <origin xyz="0 0.06192979423223305 0.007219282139909133" rpy="0 0 0"/>
            <mass value="1" />
            <inertia ixx="100" ixy="0" ixz="0" iyy="100" iyz="0" izz="100" />
        </inertial>
        <visual>
            <origin xyz="0 0.06192979423223305 0.007219282139909133" rpy="0 0 0"/>
            <geometry>
                <box size="0.5606379114658376 0.1238595884644661 0.014438564279818267" />
            </geometry>
            <material name="Green">
                <color rgba="0 1.0 0.0 1.0"/>
            </material>
        </visual>
        <collision>
            <origin xyz="0 0.06192979423223305 0.007219282139909133" rpy="0 0 0"/>
            <geometry>
                <box size="0.5606379114658376 0.1238595884644661 0.014438564279818267" />
            </geometry>
        </collision>
    </link>
    <joint name="Link2_Link3" type="revolute">
       <parent link="Link2"/>
       <child  link="Link3"/>
       <origin rpy="0 0 0" xyz="0 0.1238595884644661 0.014438564279818267" />
     <axis xyz="1 0 0"/>
       <limit effort="0.0" lower="-3.14159" upper="3.14159" velocity="0.0"/>
    </joint>
    <link name="Link3">
        <inertial>
            <origin xyz="0 0.1679552936414876 0.25874081545413924" rpy="0 0 0"/>
            <mass value="1" />
            <inertia ixx="100" ixy="0" ixz="0" iyy="100" iyz="0" izz="100" />
        </inertial>
        <visual>
            <origin xyz="0 0.1679552936414876 0.25874081545413924" rpy="0 0 0"/>
            <geometry>
                <box size="0.1512264558107128 0.3359105872829752 0.5174816309082785" />
            </geometry>
            <material name="Blue">
                <color rgba="0 0.0 1.0 1.0"/>
            </material>
        </visual>
        <collision>
            <origin xyz="0 0.1679552936414876 0.25874081545413924" rpy="0 0 0"/>
            <geometry>
                <box size="0.1512264558107128 0.3359105872829752 0.5174816309082785" />
            </geometry>
        </collision>
    </link>
    <joint name="Link3_Link4" type="revolute">
       <parent link="Link3"/>
       <child  link="Link4"/>
       <origin rpy="0 0 0" xyz="0 0.3359105872829752 0.5174816309082785" />
     <axis xyz="1 0 0"/>
       <limit effort="0.0" lower="-3.14159" upper="3.14159" velocity="0.0"/>
    </joint>
    <link name="Link4">
        <inertial>
            <origin xyz="0 0.3266674260257849 0.10763894353148057" rpy="0 0 0"/>
            <mass value="1" />
            <inertia ixx="100" ixy="0" ixz="0" iyy="100" iyz="0" izz="100" />
        </inertial>
        <visual>
            <origin xyz="0 0.3266674260257849 0.10763894353148057" rpy="0 0 0"/>
            <geometry>
                <box size="0.5812727893602095 0.6533348520515698 0.21527788706296114" />
            </geometry>
            <material name="Green">
                <color rgba="0 1.0 0.0 1.0"/>
            </material>
        </visual>
        <collision>
            <origin xyz="0 0.3266674260257849 0.10763894353148057" rpy="0 0 0"/>
            <geometry>
                <box size="0.5812727893602095 0.6533348520515698 0.21527788706296114" />
            </geometry>
        </collision>
    </link>
</robot>