<robot name = "robot">
    <link name="Link0">
        <inertial>
            <origin xyz="0 0 2.4499393746082765" rpy="0 0 0"/>
            <mass value="1" />
            <inertia ixx="100" ixy="0" ixz="0" iyy="100" iyz="0" izz="100" />
        </inertial>
        <visual>
            <origin xyz="0 0 2.4499393746082765" rpy="0 0 0"/>
            <geometry>
                <box size="0.1551013545875376 0.705744030810681 0.8998787492165525" />
            </geometry>
            <material name="Green">
                <color rgba="0 1.0 0.0 1.0"/>
            </material>
        </visual>
        <collision>
            <origin xyz="0 0 2.4499393746082765" rpy="0 0 0"/>
            <geometry>
                <box size="0.1551013545875376 0.705744030810681 0.8998787492165525" />
            </geometry>
        </collision>
    </link>
    <joint name="Link0_Link1" type="revolute">
       <parent link="Link0"/>
       <child  link="Link1"/>
       <origin rpy="0 0 0" xyz="0 0.3528720154053405 2.8998787492165525" />
     <axis xyz="1 0 0"/>
       <limit effort="0.0" lower="-3.14159" upper="3.14159" velocity="0.0"/>
    </joint>
    <link name="Link1">
        <inertial>
            <origin xyz="0 0.3528720154053405 -0.44993937460827627" rpy="0 0 0"/>
            <mass value="1" />
            <inertia ixx="100" ixy="0" ixz="0" iyy="100" iyz="0" izz="100" />
        </inertial>
        <visual>
            <origin xyz="0 0.3528720154053405 -0.44993937460827627" rpy="0 0 0"/>
            <geometry>
                <box size="0.1551013545875376 0.705744030810681 0.8998787492165525" />
            </geometry>
            <material name="Green">
                <color rgba="0 1.0 0.0 1.0"/>
            </material>
        </visual>
        <collision>
            <origin xyz="0 0.3528720154053405 -0.44993937460827627" rpy="0 0 0"/>
            <geometry>
                <box size="0.1551013545875376 0.705744030810681 0.8998787492165525" />
            </geometry>
        </collision>
    </link>
    <joint name="Link1_Link2" type="revolute">
       <parent link="Link1"/>
       <child  link="Link2"/>
       <origin rpy="0 0 0" xyz="0 0.0 0.0" />
     <axis xyz="1 0 0"/>
       <limit effort="0.0" lower="-3.14159" upper="3.14159" velocity="0.0"/>
    </joint>
    <link name="Link2">
        <inertial>
            <origin xyz="0 -0.3237336024570753 0.19350059255471252" rpy="0 0 0"/>
            <mass value="1" />
            <inertia ixx="100" ixy="0" ixz="0" iyy="100" iyz="0" izz="100" />
        </inertial>
        <visual>
            <origin xyz="0 -0.3237336024570753 0.19350059255471252" rpy="0 0 0"/>
            <geometry>
                <box size="0.08179332746738877 0.6474672049141506 0.38700118510942505" />
            </geometry>
            <material name="Green">
                <color rgba="0 1.0 0.0 1.0"/>
            </material>
        </visual>
        <collision>
            <origin xyz="0 -0.3237336024570753 0.19350059255471252" rpy="0 0 0"/>
            <geometry>
                <box size="0.08179332746738877 0.6474672049141506 0.38700118510942505" />
            </geometry>
        </collision>
    </link>
    <joint name="Link2_Link3" type="revolute">
       <parent link="Link2"/>
       <child  link="Link3"/>
       <origin rpy="0 0 0" xyz="0 -0.6474672049141506 0.38700118510942505" />
     <axis xyz="1 0 0"/>
       <limit effort="0.0" lower="-3.14159" upper="3.14159" velocity="0.0"/>
    </joint>
    <link name="Link3">
        <inertial>
            <origin xyz="0 -0.19333017049233658 0.10412186178044003" rpy="0 0 0"/>
            <mass value="1" />
            <inertia ixx="100" ixy="0" ixz="0" iyy="100" iyz="0" izz="100" />
        </inertial>
        <visual>
            <origin xyz="0 -0.19333017049233658 0.10412186178044003" rpy="0 0 0"/>
            <geometry>
                <box size="0.05321360906075134 0.38666034098467317 0.20824372356088006" />
            </geometry>
            <material name="Green">
                <color rgba="0 1.0 0.0 1.0"/>
            </material>
        </visual>
        <collision>
            <origin xyz="0 -0.19333017049233658 0.10412186178044003" rpy="0 0 0"/>
            <geometry>
                <box size="0.05321360906075134 0.38666034098467317 0.20824372356088006" />
            </geometry>
        </collision>
    </link>
    <joint name="Link3_Link4" type="revolute">
       <parent link="Link3"/>
       <child  link="Link4"/>
       <origin rpy="0 0 0" xyz="0 0.0 0.20824372356088006" />
     <axis xyz="1 0 0"/>
       <limit effort="0.0" lower="-3.14159" upper="3.14159" velocity="0.0"/>
    </joint>
    <link name="Link4">
        <inertial>
            <origin xyz="0 0.4459379444805548 0.07803929219250683" rpy="0 0 0"/>
            <mass value="1" />
            <inertia ixx="100" ixy="0" ixz="0" iyy="100" iyz="0" izz="100" />
        </inertial>
        <visual>
            <origin xyz="0 0.4459379444805548 0.07803929219250683" rpy="0 0 0"/>
            <geometry>
                <box size="0.9523007459912233 0.8918758889611096 0.15607858438501365" />
            </geometry>
            <material name="Blue">
                <color rgba="0 0.0 1.0 1.0"/>
            </material>
        </visual>
        <collision>
            <origin xyz="0 0.4459379444805548 0.07803929219250683" rpy="0 0 0"/>
            <geometry>
                <box size="0.9523007459912233 0.8918758889611096 0.15607858438501365" />
            </geometry>
        </collision>
    </link>
    <joint name="Link4_Link5" type="revolute">
       <parent link="Link4"/>
       <child  link="Link5"/>
       <origin rpy="0 0 0" xyz="0 0.0 0.15607858438501365" />
     <axis xyz="1 0 0"/>
       <limit effort="0.0" lower="-3.14159" upper="3.14159" velocity="0.0"/>
    </joint>
    <link name="Link5">
        <inertial>
            <origin xyz="0 -0.35723296728045045 -0.13532925107994542" rpy="0 0 0"/>
            <mass value="1" />
            <inertia ixx="100" ixy="0" ixz="0" iyy="100" iyz="0" izz="100" />
        </inertial>
        <visual>
            <origin xyz="0 -0.35723296728045045 -0.13532925107994542" rpy="0 0 0"/>
            <geometry>
                <box size="0.0895208945576037 0.7144659345609009 0.27065850215989085" />
            </geometry>
            <material name="Green">
                <color rgba="0 1.0 0.0 1.0"/>
            </material>
        </visual>
        <collision>
            <origin xyz="0 -0.35723296728045045 -0.13532925107994542" rpy="0 0 0"/>
            <geometry>
                <box size="0.0895208945576037 0.7144659345609009 0.27065850215989085" />
            </geometry>
        </collision>
    </link>
</robot>