<robot name = "robot">
    <link name="Link0">
        <inertial>
            <origin xyz="0 0 2.2615571766642883" rpy="0 0 0"/>
            <mass value="1" />
            <inertia ixx="100" ixy="0" ixz="0" iyy="100" iyz="0" izz="100" />
        </inertial>
        <visual>
            <origin xyz="0 0 2.2615571766642883" rpy="0 0 0"/>
            <geometry>
                <box size="0.9395300314265851 0.3246791003920062 0.5231143533285769" />
            </geometry>
            <material name="Green">
                <color rgba="0 1.0 0.0 1.0"/>
            </material>
        </visual>
        <collision>
            <origin xyz="0 0 2.2615571766642883" rpy="0 0 0"/>
            <geometry>
                <box size="0.9395300314265851 0.3246791003920062 0.5231143533285769" />
            </geometry>
        </collision>
    </link>
    <joint name="Link0_Link1" type="revolute">
       <parent link="Link0"/>
       <child  link="Link1"/>
       <origin rpy="0 0 0" xyz="0 0.1623395501960031 2.5231143533285767" />
     <axis xyz="1 0 0"/>
       <limit effort="0.0" lower="-3.14159" upper="3.14159" velocity="0.0"/>
    </joint>
    <link name="Link1">
        <inertial>
            <origin xyz="0 0.1623395501960031 -0.26155717666428846" rpy="0 0 0"/>
            <mass value="1" />
            <inertia ixx="100" ixy="0" ixz="0" iyy="100" iyz="0" izz="100" />
        </inertial>
        <visual>
            <origin xyz="0 0.1623395501960031 -0.26155717666428846" rpy="0 0 0"/>
            <geometry>
                <box size="0.9395300314265851 0.3246791003920062 0.5231143533285769" />
            </geometry>
            <material name="Blue">
                <color rgba="0 0.0 1.0 1.0"/>
            </material>
        </visual>
        <collision>
            <origin xyz="0 0.1623395501960031 -0.26155717666428846" rpy="0 0 0"/>
            <geometry>
                <box size="0.9395300314265851 0.3246791003920062 0.5231143533285769" />
            </geometry>
        </collision>
    </link>
    <joint name="Link1_Link2" type="revolute">
       <parent link="Link1"/>
       <child  link="Link2"/>
       <origin rpy="0 0 0" xyz="-0.46976501571329254 0.1623395501960031 0.0" />
     <axis xyz="0 1 0"/>
       <limit effort="0.0" lower="-3.14159" upper="3.14159" velocity="0.0"/>
    </joint>
    <link name="Link2">
        <inertial>
            <origin xyz="-0.315648224446112 0 0.47932113214997496" rpy="0 0 0"/>
            <mass value="1" />
            <inertia ixx="100" ixy="0" ixz="0" iyy="100" iyz="0" izz="100" />
        </inertial>
        <visual>
            <origin xyz="-0.315648224446112 0 0.47932113214997496" rpy="0 0 0"/>
            <geometry>
                <box size="0.631296448892224 0.9654740730688702 0.9586422642999499" />
            </geometry>
            <material name="Blue">
                <color rgba="0 0.0 1.0 1.0"/>
            </material>
        </visual>
        <collision>
            <origin xyz="-0.315648224446112 0 0.47932113214997496" rpy="0 0 0"/>
            <geometry>
                <box size="0.631296448892224 0.9654740730688702 0.9586422642999499" />
            </geometry>
        </collision>
    </link>
    <joint name="Link2_Link3" type="revolute">
       <parent link="Link2"/>
       <child  link="Link3"/>
       <origin rpy="0 0 0" xyz="-0.315648224446112 -0.4827370365344351 0.9586422642999499" />
     <axis xyz="1 0 0"/>
       <limit effort="0.0" lower="-3.14159" upper="3.14159" velocity="0.0"/>
    </joint>
    <link name="Link3">
        <inertial>
            <origin xyz="0 -0.3959843909057375 -0.43335215182015324" rpy="0 0 0"/>
            <mass value="1" />
            <inertia ixx="100" ixy="0" ixz="0" iyy="100" iyz="0" izz="100" />
        </inertial>
        <visual>
            <origin xyz="0 -0.3959843909057375 -0.43335215182015324" rpy="0 0 0"/>
            <geometry>
                <box size="0.47175243604779904 0.791968781811475 0.8667043036403065" />
            </geometry>
            <material name="Blue">
                <color rgba="0 0.0 1.0 1.0"/>
            </material>
        </visual>
        <collision>
            <origin xyz="0 -0.3959843909057375 -0.43335215182015324" rpy="0 0 0"/>
            <geometry>
                <box size="0.47175243604779904 0.791968781811475 0.8667043036403065" />
            </geometry>
        </collision>
    </link>
    <joint name="Link3_Link4" type="revolute">
       <parent link="Link3"/>
       <child  link="Link4"/>
       <origin rpy="0 0 0" xyz="0.23587621802389952 -0.3959843909057375 0.0" />
     <axis xyz="0 1 0"/>
       <limit effort="0.0" lower="-3.14159" upper="3.14159" velocity="0.0"/>
    </joint>
    <link name="Link4">
        <inertial>
            <origin xyz="0.17884432689233515 0 -0.26505678108168895" rpy="0 0 0"/>
            <mass value="1" />
            <inertia ixx="100" ixy="0" ixz="0" iyy="100" iyz="0" izz="100" />
        </inertial>
        <visual>
            <origin xyz="0.17884432689233515 0 -0.26505678108168895" rpy="0 0 0"/>
            <geometry>
                <box size="0.3576886537846703 0.9560327949772778 0.5301135621633779" />
            </geometry>
            <material name="Blue">
                <color rgba="0 0.0 1.0 1.0"/>
            </material>
        </visual>
        <collision>
            <origin xyz="0.17884432689233515 0 -0.26505678108168895" rpy="0 0 0"/>
            <geometry>
                <box size="0.3576886537846703 0.9560327949772778 0.5301135621633779" />
            </geometry>
        </collision>
    </link>
    <joint name="Link4_Link5" type="revolute">
       <parent link="Link4"/>
       <child  link="Link5"/>
       <origin rpy="0 0 0" xyz="0.0 0 0.0" />
     <axis xyz="0 1 0"/>
       <limit effort="0.0" lower="-3.14159" upper="3.14159" velocity="0.0"/>
    </joint>
    <link name="Link5">
        <inertial>
            <origin xyz="-0.33386826216178206 0 0.09755224127932932" rpy="0 0 0"/>
            <mass value="1" />
            <inertia ixx="100" ixy="0" ixz="0" iyy="100" iyz="0" izz="100" />
        </inertial>
        <visual>
            <origin xyz="-0.33386826216178206 0 0.09755224127932932" rpy="0 0 0"/>
            <geometry>
                <box size="0.6677365243235641 0.47449457662589456 0.19510448255865864" />
            </geometry>
            <material name="Green">
                <color rgba="0 1.0 0.0 1.0"/>
            </material>
        </visual>
        <collision>
            <origin xyz="-0.33386826216178206 0 0.09755224127932932" rpy="0 0 0"/>
            <geometry>
                <box size="0.6677365243235641 0.47449457662589456 0.19510448255865864" />
            </geometry>
        </collision>
    </link>
    <joint name="Link5_Link6" type="revolute">
       <parent link="Link5"/>
       <child  link="Link6"/>
       <origin rpy="0 0 0" xyz="-0.33386826216178206 0.23724728831294728 0.19510448255865864" />
     <axis xyz="1 0 0"/>
       <limit effort="0.0" lower="-3.14159" upper="3.14159" velocity="0.0"/>
    </joint>
    <link name="Link6">
        <inertial>
            <origin xyz="0 0.020148266454805108 0.05221485965126943" rpy="0 0 0"/>
            <mass value="1" />
            <inertia ixx="100" ixy="0" ixz="0" iyy="100" iyz="0" izz="100" />
        </inertial>
        <visual>
            <origin xyz="0 0.020148266454805108 0.05221485965126943" rpy="0 0 0"/>
            <geometry>
                <box size="0.5837604685076184 0.040296532909610216 0.10442971930253886" />
            </geometry>
            <material name="Blue">
                <color rgba="0 0.0 1.0 1.0"/>
            </material>
        </visual>
        <collision>
            <origin xyz="0 0.020148266454805108 0.05221485965126943" rpy="0 0 0"/>
            <geometry>
                <box size="0.5837604685076184 0.040296532909610216 0.10442971930253886" />
            </geometry>
        </collision>
    </link>
</robot>