<robot name = "robot">
    <link name="Link0">
        <inertial>
            <origin xyz="0 0 2.4697945678645725" rpy="0 0 0"/>
            <mass value="1" />
            <inertia ixx="100" ixy="0" ixz="0" iyy="100" iyz="0" izz="100" />
        </inertial>
        <visual>
            <origin xyz="0 0 2.4697945678645725" rpy="0 0 0"/>
            <geometry>
                <box size="0.6709302981958342 0.05389616363684191 0.9395891357291452" />
            </geometry>
            <material name="Green">
                <color rgba="0 1.0 0.0 1.0"/>
            </material>
        </visual>
        <collision>
            <origin xyz="0 0 2.4697945678645725" rpy="0 0 0"/>
            <geometry>
                <box size="0.6709302981958342 0.05389616363684191 0.9395891357291452" />
            </geometry>
        </collision>
    </link>
    <joint name="Link0_Link1" type="revolute">
       <parent link="Link0"/>
       <child  link="Link1"/>
       <origin rpy="0 0 0" xyz="0 0.026948081818420955 2.939589135729145" />
     <axis xyz="1 0 0"/>
       <limit effort="0.0" lower="-3.14159" upper="3.14159" velocity="0.0"/>
    </joint>
    <link name="Link1">
        <inertial>
            <origin xyz="0 0.026948081818420955 -0.4697945678645726" rpy="0 0 0"/>
            <mass value="1" />
            <inertia ixx="100" ixy="0" ixz="0" iyy="100" iyz="0" izz="100" />
        </inertial>
        <visual>
            <origin xyz="0 0.026948081818420955 -0.4697945678645726" rpy="0 0 0"/>
            <geometry>
                <box size="0.6709302981958342 0.05389616363684191 0.9395891357291452" />
            </geometry>
            <material name="Green">
                <color rgba="0 1.0 0.0 1.0"/>
            </material>
        </visual>
        <collision>
            <origin xyz="0 0.026948081818420955 -0.4697945678645726" rpy="0 0 0"/>
            <geometry>
                <box size="0.6709302981958342 0.05389616363684191 0.9395891357291452" />
            </geometry>
        </collision>
    </link>
    <joint name="Link1_Link2" type="revolute">
       <parent link="Link1"/>
       <child  link="Link2"/>
       <origin rpy="0 0 0" xyz="0.3354651490979171 0.026948081818420955 0.0" />
     <axis xyz="0 1 0"/>
       <limit effort="0.0" lower="-3.14159" upper="3.14159" velocity="0.0"/>
    </joint>
    <link name="Link2">
        <inertial>
            <origin xyz="0.47288905374660634 0 0.07752920236214172" rpy="0 0 0"/>
            <mass value="1" />
            <inertia ixx="100" ixy="0" ixz="0" iyy="100" iyz="0" izz="100" />
        </inertial>
        <visual>
            <origin xyz="0.47288905374660634 0 0.07752920236214172" rpy="0 0 0"/>
            <geometry>
                <box size="0.9457781074932127 0.34521026125690646 0.15505840472428345" />
            </geometry>
            <material name="Blue">
                <color rgba="0 0.0 1.0 1.0"/>
            </material>
        </visual>
        <collision>
            <origin xyz="0.47288905374660634 0 0.07752920236214172" rpy="0 0 0"/>
            <geometry>
                <box size="0.9457781074932127 0.34521026125690646 0.15505840472428345" />
            </geometry>
        </collision>
    </link>
    <joint name="Link2_Link3" type="revolute">
       <parent link="Link2"/>
       <child  link="Link3"/>
       <origin rpy="0 0 0" xyz="0.9457781074932127 0 0.15505840472428345" />
     <axis xyz="0 1 0"/>
       <limit effort="0.0" lower="-3.14159" upper="3.14159" velocity="0.0"/>
    </joint>
    <link name="Link3">
        <inertial>
            <origin xyz="0.491958430543972 0 0.03369681171980654" rpy="0 0 0"/>
            <mass value="1" />
            <inertia ixx="100" ixy="0" ixz="0" iyy="100" iyz="0" izz="100" />
        </inertial>
        <visual>
            <origin xyz="0.491958430543972 0 0.03369681171980654" rpy="0 0 0"/>
            <geometry>
                <box size="0.983916861087944 0.9735063778323491 0.06739362343961308" />
            </geometry>
            <material name="Blue">
                <color rgba="0 0.0 1.0 1.0"/>
            </material>
        </visual>
        <collision>
            <origin xyz="0.491958430543972 0 0.03369681171980654" rpy="0 0 0"/>
            <geometry>
                <box size="0.983916861087944 0.9735063778323491 0.06739362343961308" />
            </geometry>
        </collision>
    </link>
    <joint name="Link3_Link4" type="revolute">
       <parent link="Link3"/>
       <child  link="Link4"/>
       <origin rpy="0 0 0" xyz="0.491958430543972 0.48675318891617453 0.06739362343961308" />
     <axis xyz="1 0 0"/>
       <limit effort="0.0" lower="-3.14159" upper="3.14159" velocity="0.0"/>
    </joint>
    <link name="Link4">
        <inertial>
            <origin xyz="0 0.37098230242557007 0.2508446815435501" rpy="0 0 0"/>
            <mass value="1" />
            <inertia ixx="100" ixy="0" ixz="0" iyy="100" iyz="0" izz="100" />
        </inertial>
        <visual>
            <origin xyz="0 0.37098230242557007 0.2508446815435501" rpy="0 0 0"/>
            <geometry>
                <box size="0.10938544147123297 0.7419646048511401 0.5016893630871002" />
            </geometry>
            <material name="Green">
                <color rgba="0 1.0 0.0 1.0"/>
            </material>
        </visual>
        <collision>
            <origin xyz="0 0.37098230242557007 0.2508446815435501" rpy="0 0 0"/>
            <geometry>
                <box size="0.10938544147123297 0.7419646048511401 0.5016893630871002" />
            </geometry>
        </collision>
    </link>
    <joint name="Link4_Link5" type="revolute">
       <parent link="Link4"/>
       <child  link="Link5"/>
       <origin rpy="0 0 0" xyz="0 0.7419646048511401 0.5016893630871002" />
     <axis xyz="1 0 0"/>
       <limit effort="0.0" lower="-3.14159" upper="3.14159" velocity="0.0"/>
    </joint>
    <link name="Link5">
        <inertial>
            <origin xyz="0 0.053747882011127956 0.21499150211039914" rpy="0 0 0"/>
            <mass value="1" />
            <inertia ixx="100" ixy="0" ixz="0" iyy="100" iyz="0" izz="100" />
        </inertial>
        <visual>
            <origin xyz="0 0.053747882011127956 0.21499150211039914" rpy="0 0 0"/>
            <geometry>
                <box size="0.5940215535953925 0.10749576402225591 0.42998300422079827" />
            </geometry>
            <material name="Blue">
                <color rgba="0 0.0 1.0 1.0"/>
            </material>
        </visual>
        <collision>
            <origin xyz="0 0.053747882011127956 0.21499150211039914" rpy="0 0 0"/>
            <geometry>
                <box size="0.5940215535953925 0.10749576402225591 0.42998300422079827" />
            </geometry>
        </collision>
    </link>
</robot>