<robot name = "robot">
    <link name="Link0">
        <inertial>
            <origin xyz="0 0 2.3059773676346307" rpy="0 0 0"/>
            <mass value="1" />
            <inertia ixx="100" ixy="0" ixz="0" iyy="100" iyz="0" izz="100" />
        </inertial>
        <visual>
            <origin xyz="0 0 2.3059773676346307" rpy="0 0 0"/>
            <geometry>
                <box size="0.8333613262539843 0.0854115108583483 0.6119547352692611" />
            </geometry>
            <material name="Green">
                <color rgba="0 1.0 0.0 1.0"/>
            </material>
        </visual>
        <collision>
            <origin xyz="0 0 2.3059773676346307" rpy="0 0 0"/>
            <geometry>
                <box size="0.8333613262539843 0.0854115108583483 0.6119547352692611" />
            </geometry>
        </collision>
    </link>
    <joint name="Link0_Link1" type="revolute">
       <parent link="Link0"/>
       <child  link="Link1"/>
       <origin rpy="0 0 0" xyz="0 0.04270575542917415 2.6119547352692614" />
     <axis xyz="1 0 0"/>
       <limit effort="0.0" lower="-3.14159" upper="3.14159" velocity="0.0"/>
    </joint>
    <link name="Link1">
        <inertial>
            <origin xyz="0 0.04270575542917415 -0.30597736763463057" rpy="0 0 0"/>
            <mass value="1" />
            <inertia ixx="100" ixy="0" ixz="0" iyy="100" iyz="0" izz="100" />
        </inertial>
        <visual>
            <origin xyz="0 0.04270575542917415 -0.30597736763463057" rpy="0 0 0"/>
            <geometry>
                <box size="0.8333613262539843 0.0854115108583483 0.6119547352692611" />
            </geometry>
            <material name="Green">
                <color rgba="0 1.0 0.0 1.0"/>
            </material>
        </visual>
        <collision>
            <origin xyz="0 0.04270575542917415 -0.30597736763463057" rpy="0 0 0"/>
            <geometry>
                <box size="0.8333613262539843 0.0854115108583483 0.6119547352692611" />
            </geometry>
        </collision>
    </link>
    <joint name="Link1_Link2" type="revolute">
       <parent link="Link1"/>
       <child  link="Link2"/>
       <origin rpy="0 0 0" xyz="-0.41668066312699215 0.04270575542917415 0.0" />
     <axis xyz="0 1 0"/>
       <limit effort="0.0" lower="-3.14159" upper="3.14159" velocity="0.0"/>
    </joint>
    <link name="Link2">
        <inertial>
            <origin xyz="-0.3165073062601812 0 0.3616715130059275" rpy="0 0 0"/>
            <mass value="1" />
            <inertia ixx="100" ixy="0" ixz="0" iyy="100" iyz="0" izz="100" />
        </inertial>
        <visual>
            <origin xyz="-0.3165073062601812 0 0.3616715130059275" rpy="0 0 0"/>
            <geometry>
                <box size="0.6330146125203624 0.3214184381021217 0.723343026011855" />
            </geometry>
            <material name="Blue">
                <color rgba="0 0.0 1.0 1.0"/>
            </material>
        </visual>
        <collision>
            <origin xyz="-0.3165073062601812 0 0.3616715130059275" rpy="0 0 0"/>
            <geometry>
                <box size="0.6330146125203624 0.3214184381021217 0.723343026011855" />
            </geometry>
        </collision>
    </link>
    <joint name="Link2_Link3" type="revolute">
       <parent link="Link2"/>
       <child  link="Link3"/>
       <origin rpy="0 0 0" xyz="0.0 0 0.723343026011855" />
     <axis xyz="0 1 0"/>
       <limit effort="0.0" lower="-3.14159" upper="3.14159" velocity="0.0"/>
    </joint>
    <link name="Link3">
        <inertial>
            <origin xyz="0.19979748371518974 0 -0.4744499928697384" rpy="0 0 0"/>
            <mass value="1" />
            <inertia ixx="100" ixy="0" ixz="0" iyy="100" iyz="0" izz="100" />
        </inertial>
        <visual>
            <origin xyz="0.19979748371518974 0 -0.4744499928697384" rpy="0 0 0"/>
            <geometry>
                <box size="0.3995949674303795 0.6126918567956128 0.9488999857394768" />
            </geometry>
            <material name="Blue">
                <color rgba="0 0.0 1.0 1.0"/>
            </material>
        </visual>
        <collision>
            <origin xyz="0.19979748371518974 0 -0.4744499928697384" rpy="0 0 0"/>
            <geometry>
                <box size="0.3995949674303795 0.6126918567956128 0.9488999857394768" />
            </geometry>
        </collision>
    </link>
    <joint name="Link3_Link4" type="revolute">
       <parent link="Link3"/>
       <child  link="Link4"/>
       <origin rpy="0 0 0" xyz="0.0 0 0.0" />
     <axis xyz="0 1 0"/>
       <limit effort="0.0" lower="-3.14159" upper="3.14159" velocity="0.0"/>
    </joint>
    <link name="Link4">
        <inertial>
            <origin xyz="-0.39277841796660556 0 0.09776375832250933" rpy="0 0 0"/>
            <mass value="1" />
            <inertia ixx="100" ixy="0" ixz="0" iyy="100" iyz="0" izz="100" />
        </inertial>
        <visual>
            <origin xyz="-0.39277841796660556 0 0.09776375832250933" rpy="0 0 0"/>
            <geometry>
                <box size="0.7855568359332111 0.6902100131900866 0.19552751664501866" />
            </geometry>
            <material name="Green">
                <color rgba="0 1.0 0.0 1.0"/>
            </material>
        </visual>
        <collision>
            <origin xyz="-0.39277841796660556 0 0.09776375832250933" rpy="0 0 0"/>
            <geometry>
                <box size="0.7855568359332111 0.6902100131900866 0.19552751664501866" />
            </geometry>
        </collision>
    </link>
    <joint name="Link4_Link5" type="revolute">
       <parent link="Link4"/>
       <child  link="Link5"/>
       <origin rpy="0 0 0" xyz="0.0 0 0.19552751664501866" />
     <axis xyz="0 1 0"/>
       <limit effort="0.0" lower="-3.14159" upper="3.14159" velocity="0.0"/>
    </joint>
    <link name="Link5">
        <inertial>
            <origin xyz="0.05770391337372932 0 0.2762863608099731" rpy="0 0 0"/>
            <mass value="1" />
            <inertia ixx="100" ixy="0" ixz="0" iyy="100" iyz="0" izz="100" />
        </inertial>
        <visual>
            <origin xyz="0.05770391337372932 0 0.2762863608099731" rpy="0 0 0"/>
            <geometry>
                <box size="0.11540782674745864 0.9988924936778217 0.5525727216199462" />
            </geometry>
            <material name="Green">
                <color rgba="0 1.0 0.0 1.0"/>
            </material>
        </visual>
        <collision>
            <origin xyz="0.05770391337372932 0 0.2762863608099731" rpy="0 0 0"/>
            <geometry>
                <box size="0.11540782674745864 0.9988924936778217 0.5525727216199462" />
            </geometry>
        </collision>
    </link>
</robot>