<robot name = "robot">
    <link name="Link0">
        <inertial>
            <origin xyz="0 0 2.1785310608076127" rpy="0 0 0"/>
            <mass value="1" />
            <inertia ixx="100" ixy="0" ixz="0" iyy="100" iyz="0" izz="100" />
        </inertial>
        <visual>
            <origin xyz="0 0 2.1785310608076127" rpy="0 0 0"/>
            <geometry>
                <box size="0.6207114730393869 0.19737492234925302 0.3570621216152259" />
            </geometry>
            <material name="Green">
                <color rgba="0 1.0 0.0 1.0"/>
            </material>
        </visual>
        <collision>
            <origin xyz="0 0 2.1785310608076127" rpy="0 0 0"/>
            <geometry>
                <box size="0.6207114730393869 0.19737492234925302 0.3570621216152259" />
            </geometry>
        </collision>
    </link>
    <joint name="Link0_Link1" type="revolute">
       <parent link="Link0"/>
       <child  link="Link1"/>
       <origin rpy="0 0 0" xyz="0 0.09868746117462651 2.357062121615226" />
     <axis xyz="1 0 0"/>
       <limit effort="0.0" lower="-3.14159" upper="3.14159" velocity="0.0"/>
    </joint>
    <link name="Link1">
        <inertial>
            <origin xyz="0 0.09868746117462651 -0.17853106080761294" rpy="0 0 0"/>
            <mass value="1" />
            <inertia ixx="100" ixy="0" ixz="0" iyy="100" iyz="0" izz="100" />
        </inertial>
        <visual>
            <origin xyz="0 0.09868746117462651 -0.17853106080761294" rpy="0 0 0"/>
            <geometry>
                <box size="0.6207114730393869 0.19737492234925302 0.3570621216152259" />
            </geometry>
            <material name="Blue">
                <color rgba="0 0.0 1.0 1.0"/>
            </material>
        </visual>
        <collision>
            <origin xyz="0 0.09868746117462651 -0.17853106080761294" rpy="0 0 0"/>
            <geometry>
                <box size="0.6207114730393869 0.19737492234925302 0.3570621216152259" />
            </geometry>
        </collision>
    </link>
    <joint name="Link1_Link2" type="revolute">
       <parent link="Link1"/>
       <child  link="Link2"/>
       <origin rpy="0 0 0" xyz="0.31035573651969345 0.09868746117462651 0.0" />
     <axis xyz="0 1 0"/>
       <limit effort="0.0" lower="-3.14159" upper="3.14159" velocity="0.0"/>
    </joint>
    <link name="Link2">
        <inertial>
            <origin xyz="0.3653405432184597 0 -0.1058497698084378" rpy="0 0 0"/>
            <mass value="1" />
            <inertia ixx="100" ixy="0" ixz="0" iyy="100" iyz="0" izz="100" />
        </inertial>
        <visual>
            <origin xyz="0.3653405432184597 0 -0.1058497698084378" rpy="0 0 0"/>
            <geometry>
                <box size="0.7306810864369194 0.8168809944070211 0.2116995396168756" />
            </geometry>
            <material name="Green">
                <color rgba="0 1.0 0.0 1.0"/>
            </material>
        </visual>
        <collision>
            <origin xyz="0.3653405432184597 0 -0.1058497698084378" rpy="0 0 0"/>
            <geometry>
                <box size="0.7306810864369194 0.8168809944070211 0.2116995396168756" />
            </geometry>
        </collision>
    </link>
    <joint name="Link2_Link3" type="revolute">
       <parent link="Link2"/>
       <child  link="Link3"/>
       <origin rpy="0 0 0" xyz="0.0 0 0.0" />
     <axis xyz="0 1 0"/>
       <limit effort="0.0" lower="-3.14159" upper="3.14159" velocity="0.0"/>
    </joint>
    <link name="Link3">
        <inertial>
            <origin xyz="-0.3423548572522197 0 0.1174744931114266" rpy="0 0 0"/>
            <mass value="1" />
            <inertia ixx="100" ixy="0" ixz="0" iyy="100" iyz="0" izz="100" />
        </inertial>
        <visual>
            <origin xyz="-0.3423548572522197 0 0.1174744931114266" rpy="0 0 0"/>
            <geometry>
                <box size="0.6847097145044394 0.0706328758602468 0.2349489862228532" />
            </geometry>
            <material name="Blue">
                <color rgba="0 0.0 1.0 1.0"/>
            </material>
        </visual>
        <collision>
            <origin xyz="-0.3423548572522197 0 0.1174744931114266" rpy="0 0 0"/>
            <geometry>
                <box size="0.6847097145044394 0.0706328758602468 0.2349489862228532" />
            </geometry>
        </collision>
    </link>
    <joint name="Link3_Link4" type="revolute">
       <parent link="Link3"/>
       <child  link="Link4"/>
       <origin rpy="0 0 0" xyz="-0.6847097145044394 0 0.2349489862228532" />
     <axis xyz="0 1 0"/>
       <limit effort="0.0" lower="-3.14159" upper="3.14159" velocity="0.0"/>
    </joint>
    <link name="Link4">
        <inertial>
            <origin xyz="-0.04209587123920472 0 -0.3359263287620351" rpy="0 0 0"/>
            <mass value="1" />
            <inertia ixx="100" ixy="0" ixz="0" iyy="100" iyz="0" izz="100" />
        </inertial>
        <visual>
            <origin xyz="-0.04209587123920472 0 -0.3359263287620351" rpy="0 0 0"/>
            <geometry>
                <box size="0.08419174247840944 0.38587251780201504 0.6718526575240702" />
            </geometry>
            <material name="Green">
                <color rgba="0 1.0 0.0 1.0"/>
            </material>
        </visual>
        <collision>
            <origin xyz="-0.04209587123920472 0 -0.3359263287620351" rpy="0 0 0"/>
            <geometry>
                <box size="0.08419174247840944 0.38587251780201504 0.6718526575240702" />
            </geometry>
        </collision>
    </link>
    <joint name="Link4_Link5" type="revolute">
       <parent link="Link4"/>
       <child  link="Link5"/>
       <origin rpy="0 0 0" xyz="-0.08419174247840944 0 0.0" />
     <axis xyz="0 1 0"/>
       <limit effort="0.0" lower="-3.14159" upper="3.14159" velocity="0.0"/>
    </joint>
    <link name="Link5">
        <inertial>
            <origin xyz="-0.014799314183372214 0 0.2700044860321371" rpy="0 0 0"/>
            <mass value="1" />
            <inertia ixx="100" ixy="0" ixz="0" iyy="100" iyz="0" izz="100" />
        </inertial>
        <visual>
            <origin xyz="-0.014799314183372214 0 0.2700044860321371" rpy="0 0 0"/>
            <geometry>
                <box size="0.02959862836674443 0.4088691808530046 0.5400089720642742" />
            </geometry>
            <material name="Blue">
                <color rgba="0 0.0 1.0 1.0"/>
            </material>
        </visual>
        <collision>
            <origin xyz="-0.014799314183372214 0 0.2700044860321371" rpy="0 0 0"/>
            <geometry>
                <box size="0.02959862836674443 0.4088691808530046 0.5400089720642742" />
            </geometry>
        </collision>
    </link>
</robot>