<robot name = "robot">
    <link name="Link0">
        <inertial>
            <origin xyz="0 0 2.139363389429443" rpy="0 0 0"/>
            <mass value="1" />
            <inertia ixx="100" ixy="0" ixz="0" iyy="100" iyz="0" izz="100" />
        </inertial>
        <visual>
            <origin xyz="0 0 2.139363389429443" rpy="0 0 0"/>
            <geometry>
                <box size="0.00020971421932836076 0.9635813813489954 0.27872677885888597" />
            </geometry>
            <material name="Green">
                <color rgba="0 1.0 0.0 1.0"/>
            </material>
        </visual>
        <collision>
            <origin xyz="0 0 2.139363389429443" rpy="0 0 0"/>
            <geometry>
                <box size="0.00020971421932836076 0.9635813813489954 0.27872677885888597" />
            </geometry>
        </collision>
    </link>
    <joint name="Link0_Link1" type="revolute">
       <parent link="Link0"/>
       <child  link="Link1"/>
       <origin rpy="0 0 0" xyz="0 0.4817906906744977 2.278726778858886" />
     <axis xyz="1 0 0"/>
       <limit effort="0.0" lower="-3.14159" upper="3.14159" velocity="0.0"/>
    </joint>
    <link name="Link1">
        <inertial>
            <origin xyz="0 0.4817906906744977 -0.13936338942944299" rpy="0 0 0"/>
            <mass value="1" />
            <inertia ixx="100" ixy="0" ixz="0" iyy="100" iyz="0" izz="100" />
        </inertial>
        <visual>
            <origin xyz="0 0.4817906906744977 -0.13936338942944299" rpy="0 0 0"/>
            <geometry>
                <box size="0.00020971421932836076 0.9635813813489954 0.27872677885888597" />
            </geometry>
            <material name="Green">
                <color rgba="0 1.0 0.0 1.0"/>
            </material>
        </visual>
        <collision>
            <origin xyz="0 0.4817906906744977 -0.13936338942944299" rpy="0 0 0"/>
            <geometry>
                <box size="0.00020971421932836076 0.9635813813489954 0.27872677885888597" />
            </geometry>
        </collision>
    </link>
    <joint name="Link1_Link2" type="revolute">
       <parent link="Link1"/>
       <child  link="Link2"/>
       <origin rpy="0 0 0" xyz="0 0.0 0.0" />
     <axis xyz="1 0 0"/>
       <limit effort="0.0" lower="-3.14159" upper="3.14159" velocity="0.0"/>
    </joint>
    <link name="Link2">
        <inertial>
            <origin xyz="0 -0.06917882969961708 0.391945015985019" rpy="0 0 0"/>
            <mass value="1" />
            <inertia ixx="100" ixy="0" ixz="0" iyy="100" iyz="0" izz="100" />
        </inertial>
        <visual>
            <origin xyz="0 -0.06917882969961708 0.391945015985019" rpy="0 0 0"/>
            <geometry>
                <box size="0.7657908878111624 0.13835765939923417 0.783890031970038" />
            </geometry>
            <material name="Blue">
                <color rgba="0 0.0 1.0 1.0"/>
            </material>
        </visual>
        <collision>
            <origin xyz="0 -0.06917882969961708 0.391945015985019" rpy="0 0 0"/>
            <geometry>
                <box size="0.7657908878111624 0.13835765939923417 0.783890031970038" />
            </geometry>
        </collision>
    </link>
    <joint name="Link2_Link3" type="revolute">
       <parent link="Link2"/>
       <child  link="Link3"/>
       <origin rpy="0 0 0" xyz="0 0.0 0.783890031970038" />
     <axis xyz="1 0 0"/>
       <limit effort="0.0" lower="-3.14159" upper="3.14159" velocity="0.0"/>
    </joint>
    <link name="Link3">
        <inertial>
            <origin xyz="0 0.35049522498100444 0.49172976673434127" rpy="0 0 0"/>
            <mass value="1" />
            <inertia ixx="100" ixy="0" ixz="0" iyy="100" iyz="0" izz="100" />
        </inertial>
        <visual>
            <origin xyz="0 0.35049522498100444 0.49172976673434127" rpy="0 0 0"/>
            <geometry>
                <box size="0.30184337285889384 0.7009904499620089 0.9834595334686825" />
            </geometry>
            <material name="Blue">
                <color rgba="0 0.0 1.0 1.0"/>
            </material>
        </visual>
        <collision>
            <origin xyz="0 0.35049522498100444 0.49172976673434127" rpy="0 0 0"/>
            <geometry>
                <box size="0.30184337285889384 0.7009904499620089 0.9834595334686825" />
            </geometry>
        </collision>
    </link>
    <joint name="Link3_Link4" type="revolute">
       <parent link="Link3"/>
       <child  link="Link4"/>
       <origin rpy="0 0 0" xyz="0 0.0 0.9834595334686825" />
     <axis xyz="1 0 0"/>
       <limit effort="0.0" lower="-3.14159" upper="3.14159" velocity="0.0"/>
    </joint>
    <link name="Link4">
        <inertial>
            <origin xyz="0 -0.16923836943746506 -0.4812252941624684" rpy="0 0 0"/>
            <mass value="1" />
            <inertia ixx="100" ixy="0" ixz="0" iyy="100" iyz="0" izz="100" />
        </inertial>
        <visual>
            <origin xyz="0 -0.16923836943746506 -0.4812252941624684" rpy="0 0 0"/>
            <geometry>
                <box size="0.5986488245976731 0.3384767388749301 0.9624505883249368" />
            </geometry>
            <material name="Green">
                <color rgba="0 1.0 0.0 1.0"/>
            </material>
        </visual>
        <collision>
            <origin xyz="0 -0.16923836943746506 -0.4812252941624684" rpy="0 0 0"/>
            <geometry>
                <box size="0.5986488245976731 0.3384767388749301 0.9624505883249368" />
            </geometry>
        </collision>
    </link>
    <joint name="Link4_Link5" type="revolute">
       <parent link="Link4"/>
       <child  link="Link5"/>
       <origin rpy="0 0 0" xyz="0 0.0 0.0" />
     <axis xyz="1 0 0"/>
       <limit effort="0.0" lower="-3.14159" upper="3.14159" velocity="0.0"/>
    </joint>
    <link name="Link5">
        <inertial>
            <origin xyz="0 0.1105553864836531 0.20368975471501116" rpy="0 0 0"/>
            <mass value="1" />
            <inertia ixx="100" ixy="0" ixz="0" iyy="100" iyz="0" izz="100" />
        </inertial>
        <visual>
            <origin xyz="0 0.1105553864836531 0.20368975471501116" rpy="0 0 0"/>
            <geometry>
                <box size="0.852093983589467 0.2211107729673062 0.4073795094300223" />
            </geometry>
            <material name="Blue">
                <color rgba="0 0.0 1.0 1.0"/>
            </material>
        </visual>
        <collision>
            <origin xyz="0 0.1105553864836531 0.20368975471501116" rpy="0 0 0"/>
            <geometry>
                <box size="0.852093983589467 0.2211107729673062 0.4073795094300223" />
            </geometry>
        </collision>
    </link>
    <joint name="Link5_Link6" type="revolute">
       <parent link="Link5"/>
       <child  link="Link6"/>
       <origin rpy="0 0 0" xyz="0 0.0 0.4073795094300223" />
     <axis xyz="1 0 0"/>
       <limit effort="0.0" lower="-3.14159" upper="3.14159" velocity="0.0"/>
    </joint>
    <link name="Link6">
        <inertial>
            <origin xyz="0 -0.26353386121569955 -0.32110846135345184" rpy="0 0 0"/>
            <mass value="1" />
            <inertia ixx="100" ixy="0" ixz="0" iyy="100" iyz="0" izz="100" />
        </inertial>
        <visual>
            <origin xyz="0 -0.26353386121569955 -0.32110846135345184" rpy="0 0 0"/>
            <geometry>
                <box size="0.3080956797103864 0.5270677224313991 0.6422169227069037" />
            </geometry>
            <material name="Blue">
                <color rgba="0 0.0 1.0 1.0"/>
            </material>
        </visual>
        <collision>
            <origin xyz="0 -0.26353386121569955 -0.32110846135345184" rpy="0 0 0"/>
            <geometry>
                <box size="0.3080956797103864 0.5270677224313991 0.6422169227069037" />
            </geometry>
        </collision>
    </link>
</robot>