<robot name = "robot">
    <link name="Link0">
        <inertial>
            <origin xyz="0 0 2.4579339736041637" rpy="0 0 0"/>
            <mass value="1" />
            <inertia ixx="100" ixy="0" ixz="0" iyy="100" iyz="0" izz="100" />
        </inertial>
        <visual>
            <origin xyz="0 0 2.4579339736041637" rpy="0 0 0"/>
            <geometry>
                <box size="0.30463590560018006 0.6382789281113096 0.9158679472083274" />
            </geometry>
            <material name="Green">
                <color rgba="0 1.0 0.0 1.0"/>
            </material>
        </visual>
        <collision>
            <origin xyz="0 0 2.4579339736041637" rpy="0 0 0"/>
            <geometry>
                <box size="0.30463590560018006 0.6382789281113096 0.9158679472083274" />
            </geometry>
        </collision>
    </link>
    <joint name="Link0_Link1" type="revolute">
       <parent link="Link0"/>
       <child  link="Link1"/>
       <origin rpy="0 0 0" xyz="0 0.3191394640556548 2.9158679472083273" />
     <axis xyz="1 0 0"/>
       <limit effort="0.0" lower="-3.14159" upper="3.14159" velocity="0.0"/>
    </joint>
    <link name="Link1">
        <inertial>
            <origin xyz="0 0.3191394640556548 -0.4579339736041637" rpy="0 0 0"/>
            <mass value="1" />
            <inertia ixx="100" ixy="0" ixz="0" iyy="100" iyz="0" izz="100" />
        </inertial>
        <visual>
            <origin xyz="0 0.3191394640556548 -0.4579339736041637" rpy="0 0 0"/>
            <geometry>
                <box size="0.30463590560018006 0.6382789281113096 0.9158679472083274" />
            </geometry>
            <material name="Green">
                <color rgba="0 1.0 0.0 1.0"/>
            </material>
        </visual>
        <collision>
            <origin xyz="0 0.3191394640556548 -0.4579339736041637" rpy="0 0 0"/>
            <geometry>
                <box size="0.30463590560018006 0.6382789281113096 0.9158679472083274" />
            </geometry>
        </collision>
    </link>
    <joint name="Link1_Link2" type="revolute">
       <parent link="Link1"/>
       <child  link="Link2"/>
       <origin rpy="0 0 0" xyz="-0.15231795280009003 0.3191394640556548 0.0" />
     <axis xyz="0 1 0"/>
       <limit effort="0.0" lower="-3.14159" upper="3.14159" velocity="0.0"/>
    </joint>
    <link name="Link2">
        <inertial>
            <origin xyz="-0.009194172924863075 0 0.30200743932847685" rpy="0 0 0"/>
            <mass value="1" />
            <inertia ixx="100" ixy="0" ixz="0" iyy="100" iyz="0" izz="100" />
        </inertial>
        <visual>
            <origin xyz="-0.009194172924863075 0 0.30200743932847685" rpy="0 0 0"/>
            <geometry>
                <box size="0.01838834584972615 0.2711299929887263 0.6040148786569537" />
            </geometry>
            <material name="Green">
                <color rgba="0 1.0 0.0 1.0"/>
            </material>
        </visual>
        <collision>
            <origin xyz="-0.009194172924863075 0 0.30200743932847685" rpy="0 0 0"/>
            <geometry>
                <box size="0.01838834584972615 0.2711299929887263 0.6040148786569537" />
            </geometry>
        </collision>
    </link>
    <joint name="Link2_Link3" type="revolute">
       <parent link="Link2"/>
       <child  link="Link3"/>
       <origin rpy="0 0 0" xyz="0.0 0 0.6040148786569537" />
     <axis xyz="0 1 0"/>
       <limit effort="0.0" lower="-3.14159" upper="3.14159" velocity="0.0"/>
    </joint>
    <link name="Link3">
        <inertial>
            <origin xyz="0.3328689563088238 0 -0.18080645357870162" rpy="0 0 0"/>
            <mass value="1" />
            <inertia ixx="100" ixy="0" ixz="0" iyy="100" iyz="0" izz="100" />
        </inertial>
        <visual>
            <origin xyz="0.3328689563088238 0 -0.18080645357870162" rpy="0 0 0"/>
            <geometry>
                <box size="0.6657379126176476 0.3698254772162767 0.36161290715740324" />
            </geometry>
            <material name="Green">
                <color rgba="0 1.0 0.0 1.0"/>
            </material>
        </visual>
        <collision>
            <origin xyz="0.3328689563088238 0 -0.18080645357870162" rpy="0 0 0"/>
            <geometry>
                <box size="0.6657379126176476 0.3698254772162767 0.36161290715740324" />
            </geometry>
        </collision>
    </link>
    <joint name="Link3_Link4" type="revolute">
       <parent link="Link3"/>
       <child  link="Link4"/>
       <origin rpy="0 0 0" xyz="0.6657379126176476 0 0.0" />
     <axis xyz="0 1 0"/>
       <limit effort="0.0" lower="-3.14159" upper="3.14159" velocity="0.0"/>
    </joint>
    <link name="Link4">
        <inertial>
            <origin xyz="0.10938243622082366 0 -0.21118799231129087" rpy="0 0 0"/>
            <mass value="1" />
            <inertia ixx="100" ixy="0" ixz="0" iyy="100" iyz="0" izz="100" />
        </inertial>
        <visual>
            <origin xyz="0.10938243622082366 0 -0.21118799231129087" rpy="0 0 0"/>
            <geometry>
                <box size="0.21876487244164733 0.06619297846324856 0.42237598462258175" />
            </geometry>
            <material name="Blue">
                <color rgba="0 0.0 1.0 1.0"/>
            </material>
        </visual>
        <collision>
            <origin xyz="0.10938243622082366 0 -0.21118799231129087" rpy="0 0 0"/>
            <geometry>
                <box size="0.21876487244164733 0.06619297846324856 0.42237598462258175" />
            </geometry>
        </collision>
    </link>
    <joint name="Link4_Link5" type="revolute">
       <parent link="Link4"/>
       <child  link="Link5"/>
       <origin rpy="0 0 0" xyz="0.21876487244164733 0 0.0" />
     <axis xyz="0 1 0"/>
       <limit effort="0.0" lower="-3.14159" upper="3.14159" velocity="0.0"/>
    </joint>
    <link name="Link5">
        <inertial>
            <origin xyz="0.4205599177619956 0 0.12781817811453822" rpy="0 0 0"/>
            <mass value="1" />
            <inertia ixx="100" ixy="0" ixz="0" iyy="100" iyz="0" izz="100" />
        </inertial>
        <visual>
            <origin xyz="0.4205599177619956 0 0.12781817811453822" rpy="0 0 0"/>
            <geometry>
                <box size="0.8411198355239912 0.6202677549957005 0.25563635622907643" />
            </geometry>
            <material name="Green">
                <color rgba="0 1.0 0.0 1.0"/>
            </material>
        </visual>
        <collision>
            <origin xyz="0.4205599177619956 0 0.12781817811453822" rpy="0 0 0"/>
            <geometry>
                <box size="0.8411198355239912 0.6202677549957005 0.25563635622907643" />
            </geometry>
        </collision>
    </link>
</robot>