<robot name = "robot">
    <link name="Link0">
        <inertial>
            <origin xyz="0 0 2.342481079320074" rpy="0 0 0"/>
            <mass value="1" />
            <inertia ixx="100" ixy="0" ixz="0" iyy="100" iyz="0" izz="100" />
        </inertial>
        <visual>
            <origin xyz="0 0 2.342481079320074" rpy="0 0 0"/>
            <geometry>
                <box size="0.6265473101918693 0.39443674847807075 0.6849621586401479" />
            </geometry>
            <material name="Green">
                <color rgba="0 1.0 0.0 1.0"/>
            </material>
        </visual>
        <collision>
            <origin xyz="0 0 2.342481079320074" rpy="0 0 0"/>
            <geometry>
                <box size="0.6265473101918693 0.39443674847807075 0.6849621586401479" />
            </geometry>
        </collision>
    </link>
    <joint name="Link0_Link1" type="revolute">
       <parent link="Link0"/>
       <child  link="Link1"/>
       <origin rpy="0 0 0" xyz="0 0.19721837423903538 2.6849621586401478" />
     <axis xyz="1 0 0"/>
       <limit effort="0.0" lower="-3.14159" upper="3.14159" velocity="0.0"/>
    </joint>
    <link name="Link1">
        <inertial>
            <origin xyz="0 0.19721837423903538 -0.34248107932007393" rpy="0 0 0"/>
            <mass value="1" />
            <inertia ixx="100" ixy="0" ixz="0" iyy="100" iyz="0" izz="100" />
        </inertial>
        <visual>
            <origin xyz="0 0.19721837423903538 -0.34248107932007393" rpy="0 0 0"/>
            <geometry>
                <box size="0.6265473101918693 0.39443674847807075 0.6849621586401479" />
            </geometry>
            <material name="Blue">
                <color rgba="0 0.0 1.0 1.0"/>
            </material>
        </visual>
        <collision>
            <origin xyz="0 0.19721837423903538 -0.34248107932007393" rpy="0 0 0"/>
            <geometry>
                <box size="0.6265473101918693 0.39443674847807075 0.6849621586401479" />
            </geometry>
        </collision>
    </link>
    <joint name="Link1_Link2" type="revolute">
       <parent link="Link1"/>
       <child  link="Link2"/>
       <origin rpy="0 0 0" xyz="0.31327365509593463 0.19721837423903538 0.0" />
     <axis xyz="0 1 0"/>
       <limit effort="0.0" lower="-3.14159" upper="3.14159" velocity="0.0"/>
    </joint>
    <link name="Link2">
        <inertial>
            <origin xyz="0.36919419899784767 0 0.38247906263100495" rpy="0 0 0"/>
            <mass value="1" />
            <inertia ixx="100" ixy="0" ixz="0" iyy="100" iyz="0" izz="100" />
        </inertial>
        <visual>
            <origin xyz="0.36919419899784767 0 0.38247906263100495" rpy="0 0 0"/>
            <geometry>
                <box size="0.7383883979956953 0.450569042102828 0.7649581252620099" />
            </geometry>
            <material name="Blue">
                <color rgba="0 0.0 1.0 1.0"/>
            </material>
        </visual>
        <collision>
            <origin xyz="0.36919419899784767 0 0.38247906263100495" rpy="0 0 0"/>
            <geometry>
                <box size="0.7383883979956953 0.450569042102828 0.7649581252620099" />
            </geometry>
        </collision>
    </link>
    <joint name="Link2_Link3" type="revolute">
       <parent link="Link2"/>
       <child  link="Link3"/>
       <origin rpy="0 0 0" xyz="0.36919419899784767 0.225284521051414 0.7649581252620099" />
     <axis xyz="1 0 0"/>
       <limit effort="0.0" lower="-3.14159" upper="3.14159" velocity="0.0"/>
    </joint>
    <link name="Link3">
        <inertial>
            <origin xyz="0 0.015709941034252883 0.20119977973082243" rpy="0 0 0"/>
            <mass value="1" />
            <inertia ixx="100" ixy="0" ixz="0" iyy="100" iyz="0" izz="100" />
        </inertial>
        <visual>
            <origin xyz="0 0.015709941034252883 0.20119977973082243" rpy="0 0 0"/>
            <geometry>
                <box size="0.0983694804376486 0.03141988206850577 0.40239955946164485" />
            </geometry>
            <material name="Blue">
                <color rgba="0 0.0 1.0 1.0"/>
            </material>
        </visual>
        <collision>
            <origin xyz="0 0.015709941034252883 0.20119977973082243" rpy="0 0 0"/>
            <geometry>
                <box size="0.0983694804376486 0.03141988206850577 0.40239955946164485" />
            </geometry>
        </collision>
    </link>
    <joint name="Link3_Link4" type="revolute">
       <parent link="Link3"/>
       <child  link="Link4"/>
       <origin rpy="0 0 0" xyz="0 0.03141988206850577 0.40239955946164485" />
     <axis xyz="1 0 0"/>
       <limit effort="0.0" lower="-3.14159" upper="3.14159" velocity="0.0"/>
    </joint>
    <link name="Link4">
        <inertial>
            <origin xyz="0 0.4712713754371035 0.11428661717963401" rpy="0 0 0"/>
            <mass value="1" />
            <inertia ixx="100" ixy="0" ixz="0" iyy="100" iyz="0" izz="100" />
        </inertial>
        <visual>
            <origin xyz="0 0.4712713754371035 0.11428661717963401" rpy="0 0 0"/>
            <geometry>
                <box size="0.18754857435872718 0.942542750874207 0.22857323435926802" />
            </geometry>
            <material name="Blue">
                <color rgba="0 0.0 1.0 1.0"/>
            </material>
        </visual>
        <collision>
            <origin xyz="0 0.4712713754371035 0.11428661717963401" rpy="0 0 0"/>
            <geometry>
                <box size="0.18754857435872718 0.942542750874207 0.22857323435926802" />
            </geometry>
        </collision>
    </link>
    <joint name="Link4_Link5" type="revolute">
       <parent link="Link4"/>
       <child  link="Link5"/>
       <origin rpy="0 0 0" xyz="-0.09377428717936359 0.4712713754371035 0.22857323435926802" />
     <axis xyz="0 1 0"/>
       <limit effort="0.0" lower="-3.14159" upper="3.14159" velocity="0.0"/>
    </joint>
    <link name="Link5">
        <inertial>
            <origin xyz="-0.020957013633682298 0 0.2546476281468411" rpy="0 0 0"/>
            <mass value="1" />
            <inertia ixx="100" ixy="0" ixz="0" iyy="100" iyz="0" izz="100" />
        </inertial>
        <visual>
            <origin xyz="-0.020957013633682298 0 0.2546476281468411" rpy="0 0 0"/>
            <geometry>
                <box size="0.041914027267364595 0.709408580210526 0.5092952562936822" />
            </geometry>
            <material name="Blue">
                <color rgba="0 0.0 1.0 1.0"/>
            </material>
        </visual>
        <collision>
            <origin xyz="-0.020957013633682298 0 0.2546476281468411" rpy="0 0 0"/>
            <geometry>
                <box size="0.041914027267364595 0.709408580210526 0.5092952562936822" />
            </geometry>
        </collision>
    </link>
    <joint name="Link5_Link6" type="revolute">
       <parent link="Link5"/>
       <child  link="Link6"/>
       <origin rpy="0 0 0" xyz="-0.041914027267364595 0 0.5092952562936822" />
     <axis xyz="0 1 0"/>
       <limit effort="0.0" lower="-3.14159" upper="3.14159" velocity="0.0"/>
    </joint>
    <link name="Link6">
        <inertial>
            <origin xyz="-0.02244465620600611 0 0.08600978338313353" rpy="0 0 0"/>
            <mass value="1" />
            <inertia ixx="100" ixy="0" ixz="0" iyy="100" iyz="0" izz="100" />
        </inertial>
        <visual>
            <origin xyz="-0.02244465620600611 0 0.08600978338313353" rpy="0 0 0"/>
            <geometry>
                <box size="0.04488931241201222 0.21203332066464664 0.17201956676626706" />
            </geometry>
            <material name="Green">
                <color rgba="0 1.0 0.0 1.0"/>
            </material>
        </visual>
        <collision>
            <origin xyz="-0.02244465620600611 0 0.08600978338313353" rpy="0 0 0"/>
            <geometry>
                <box size="0.04488931241201222 0.21203332066464664 0.17201956676626706" />
            </geometry>
        </collision>
    </link>
</robot>