<robot name = "robot">
    <link name="Link0">
        <inertial>
            <origin xyz="0 0 2.1965184303156797" rpy="0 0 0"/>
            <mass value="1" />
            <inertia ixx="100" ixy="0" ixz="0" iyy="100" iyz="0" izz="100" />
        </inertial>
        <visual>
            <origin xyz="0 0 2.1965184303156797" rpy="0 0 0"/>
            <geometry>
                <box size="0.3771176170772572 0.9598104954054897 0.39303686063135934" />
            </geometry>
            <material name="Green">
                <color rgba="0 1.0 0.0 1.0"/>
            </material>
        </visual>
        <collision>
            <origin xyz="0 0 2.1965184303156797" rpy="0 0 0"/>
            <geometry>
                <box size="0.3771176170772572 0.9598104954054897 0.39303686063135934" />
            </geometry>
        </collision>
    </link>
    <joint name="Link0_Link1" type="revolute">
       <parent link="Link0"/>
       <child  link="Link1"/>
       <origin rpy="0 0 0" xyz="0 0.47990524770274484 2.3930368606313595" />
     <axis xyz="1 0 0"/>
       <limit effort="0.0" lower="-3.14159" upper="3.14159" velocity="0.0"/>
    </joint>
    <link name="Link1">
        <inertial>
            <origin xyz="0 0.47990524770274484 -0.19651843031567967" rpy="0 0 0"/>
            <mass value="1" />
            <inertia ixx="100" ixy="0" ixz="0" iyy="100" iyz="0" izz="100" />
        </inertial>
        <visual>
            <origin xyz="0 0.47990524770274484 -0.19651843031567967" rpy="0 0 0"/>
            <geometry>
                <box size="0.3771176170772572 0.9598104954054897 0.39303686063135934" />
            </geometry>
            <material name="Blue">
                <color rgba="0 0.0 1.0 1.0"/>
            </material>
        </visual>
        <collision>
            <origin xyz="0 0.47990524770274484 -0.19651843031567967" rpy="0 0 0"/>
            <geometry>
                <box size="0.3771176170772572 0.9598104954054897 0.39303686063135934" />
            </geometry>
        </collision>
    </link>
    <joint name="Link1_Link2" type="revolute">
       <parent link="Link1"/>
       <child  link="Link2"/>
       <origin rpy="0 0 0" xyz="0 0.9598104954054897 0.0" />
     <axis xyz="1 0 0"/>
       <limit effort="0.0" lower="-3.14159" upper="3.14159" velocity="0.0"/>
    </joint>
    <link name="Link2">
        <inertial>
            <origin xyz="0 0.10241019513552352 -0.05540841428203214" rpy="0 0 0"/>
            <mass value="1" />
            <inertia ixx="100" ixy="0" ixz="0" iyy="100" iyz="0" izz="100" />
        </inertial>
        <visual>
            <origin xyz="0 0.10241019513552352 -0.05540841428203214" rpy="0 0 0"/>
            <geometry>
                <box size="0.7497757720250324 0.20482039027104704 0.11081682856406427" />
            </geometry>
            <material name="Green">
                <color rgba="0 1.0 0.0 1.0"/>
            </material>
        </visual>
        <collision>
            <origin xyz="0 0.10241019513552352 -0.05540841428203214" rpy="0 0 0"/>
            <geometry>
                <box size="0.7497757720250324 0.20482039027104704 0.11081682856406427" />
            </geometry>
        </collision>
    </link>
    <joint name="Link2_Link3" type="revolute">
       <parent link="Link2"/>
       <child  link="Link3"/>
       <origin rpy="0 0 0" xyz="0 0.20482039027104704 0.0" />
     <axis xyz="1 0 0"/>
       <limit effort="0.0" lower="-3.14159" upper="3.14159" velocity="0.0"/>
    </joint>
    <link name="Link3">
        <inertial>
            <origin xyz="0 0.44960298655176856 0.2328399274953682" rpy="0 0 0"/>
            <mass value="1" />
            <inertia ixx="100" ixy="0" ixz="0" iyy="100" iyz="0" izz="100" />
        </inertial>
        <visual>
            <origin xyz="0 0.44960298655176856 0.2328399274953682" rpy="0 0 0"/>
            <geometry>
                <box size="0.6840603797525926 0.8992059731035371 0.4656798549907364" />
            </geometry>
            <material name="Green">
                <color rgba="0 1.0 0.0 1.0"/>
            </material>
        </visual>
        <collision>
            <origin xyz="0 0.44960298655176856 0.2328399274953682" rpy="0 0 0"/>
            <geometry>
                <box size="0.6840603797525926 0.8992059731035371 0.4656798549907364" />
            </geometry>
        </collision>
    </link>
    <joint name="Link3_Link4" type="revolute">
       <parent link="Link3"/>
       <child  link="Link4"/>
       <origin rpy="0 0 0" xyz="0.3420301898762963 0.44960298655176856 0.4656798549907364" />
     <axis xyz="0 1 0"/>
       <limit effort="0.0" lower="-3.14159" upper="3.14159" velocity="0.0"/>
    </joint>
    <link name="Link4">
        <inertial>
            <origin xyz="0.380904891508728 0 0.06611523617084658" rpy="0 0 0"/>
            <mass value="1" />
            <inertia ixx="100" ixy="0" ixz="0" iyy="100" iyz="0" izz="100" />
        </inertial>
        <visual>
            <origin xyz="0.380904891508728 0 0.06611523617084658" rpy="0 0 0"/>
            <geometry>
                <box size="0.761809783017456 0.16819809489978976 0.13223047234169316" />
            </geometry>
            <material name="Blue">
                <color rgba="0 0.0 1.0 1.0"/>
            </material>
        </visual>
        <collision>
            <origin xyz="0.380904891508728 0 0.06611523617084658" rpy="0 0 0"/>
            <geometry>
                <box size="0.761809783017456 0.16819809489978976 0.13223047234169316" />
            </geometry>
        </collision>
    </link>
</robot>