<robot name = "robot">
    <link name="Link0">
        <inertial>
            <origin xyz="0 0 2.417022316857612" rpy="0 0 0"/>
            <mass value="1" />
            <inertia ixx="100" ixy="0" ixz="0" iyy="100" iyz="0" izz="100" />
        </inertial>
        <visual>
            <origin xyz="0 0 2.417022316857612" rpy="0 0 0"/>
            <geometry>
                <box size="0.6886594505475311 0.020531114191365663 0.8340446337152239" />
            </geometry>
            <material name="Green">
                <color rgba="0 1.0 0.0 1.0"/>
            </material>
        </visual>
        <collision>
            <origin xyz="0 0 2.417022316857612" rpy="0 0 0"/>
            <geometry>
                <box size="0.6886594505475311 0.020531114191365663 0.8340446337152239" />
            </geometry>
        </collision>
    </link>
    <joint name="Link0_Link1" type="revolute">
       <parent link="Link0"/>
       <child  link="Link1"/>
       <origin rpy="0 0 0" xyz="0 0.010265557095682831 2.834044633715224" />
     <axis xyz="1 0 0"/>
       <limit effort="0.0" lower="-3.14159" upper="3.14159" velocity="0.0"/>
    </joint>
    <link name="Link1">
        <inertial>
            <origin xyz="0 0.010265557095682831 -0.41702231685761193" rpy="0 0 0"/>
            <mass value="1" />
            <inertia ixx="100" ixy="0" ixz="0" iyy="100" iyz="0" izz="100" />
        </inertial>
        <visual>
            <origin xyz="0 0.010265557095682831 -0.41702231685761193" rpy="0 0 0"/>
            <geometry>
                <box size="0.6886594505475311 0.020531114191365663 0.8340446337152239" />
            </geometry>
            <material name="Blue">
                <color rgba="0 0.0 1.0 1.0"/>
            </material>
        </visual>
        <collision>
            <origin xyz="0 0.010265557095682831 -0.41702231685761193" rpy="0 0 0"/>
            <geometry>
                <box size="0.6886594505475311 0.020531114191365663 0.8340446337152239" />
            </geometry>
        </collision>
    </link>
    <joint name="Link1_Link2" type="revolute">
       <parent link="Link1"/>
       <child  link="Link2"/>
       <origin rpy="0 0 0" xyz="-0.34432972527376554 0.010265557095682831 0.0" />
     <axis xyz="0 1 0"/>
       <limit effort="0.0" lower="-3.14159" upper="3.14159" velocity="0.0"/>
    </joint>
    <link name="Link2">
        <inertial>
            <origin xyz="-0.1528626555274621 0 0.013952886217724336" rpy="0 0 0"/>
            <mass value="1" />
            <inertia ixx="100" ixy="0" ixz="0" iyy="100" iyz="0" izz="100" />
        </inertial>
        <visual>
            <origin xyz="-0.1528626555274621 0 0.013952886217724336" rpy="0 0 0"/>
            <geometry>
                <box size="0.3057253110549242 0.05849548488579204 0.027905772435448672" />
            </geometry>
            <material name="Blue">
                <color rgba="0 0.0 1.0 1.0"/>
            </material>
        </visual>
        <collision>
            <origin xyz="-0.1528626555274621 0 0.013952886217724336" rpy="0 0 0"/>
            <geometry>
                <box size="0.3057253110549242 0.05849548488579204 0.027905772435448672" />
            </geometry>
        </collision>
    </link>
    <joint name="Link2_Link3" type="revolute">
       <parent link="Link2"/>
       <child  link="Link3"/>
       <origin rpy="0 0 0" xyz="0.0 0 0.027905772435448672" />
     <axis xyz="0 1 0"/>
       <limit effort="0.0" lower="-3.14159" upper="3.14159" velocity="0.0"/>
    </joint>
    <link name="Link3">
        <inertial>
            <origin xyz="0.36434753428452815 0 0.26384487859522887" rpy="0 0 0"/>
            <mass value="1" />
            <inertia ixx="100" ixy="0" ixz="0" iyy="100" iyz="0" izz="100" />
        </inertial>
        <visual>
            <origin xyz="0.36434753428452815 0 0.26384487859522887" rpy="0 0 0"/>
            <geometry>
                <box size="0.7286950685690563 0.025374876049155115 0.5276897571904577" />
            </geometry>
            <material name="Blue">
                <color rgba="0 0.0 1.0 1.0"/>
            </material>
        </visual>
        <collision>
            <origin xyz="0.36434753428452815 0 0.26384487859522887" rpy="0 0 0"/>
            <geometry>
                <box size="0.7286950685690563 0.025374876049155115 0.5276897571904577" />
            </geometry>
        </collision>
    </link>
    <joint name="Link3_Link4" type="revolute">
       <parent link="Link3"/>
       <child  link="Link4"/>
       <origin rpy="0 0 0" xyz="0.36434753428452815 -0.012687438024577558 0.5276897571904577" />
     <axis xyz="1 0 0"/>
       <limit effort="0.0" lower="-3.14159" upper="3.14159" velocity="0.0"/>
    </joint>
    <link name="Link4">
        <inertial>
            <origin xyz="0 -0.23510949171371964 0.39467853685782717" rpy="0 0 0"/>
            <mass value="1" />
            <inertia ixx="100" ixy="0" ixz="0" iyy="100" iyz="0" izz="100" />
        </inertial>
        <visual>
            <origin xyz="0 -0.23510949171371964 0.39467853685782717" rpy="0 0 0"/>
            <geometry>
                <box size="0.4698377247528003 0.4702189834274393 0.7893570737156543" />
            </geometry>
            <material name="Green">
                <color rgba="0 1.0 0.0 1.0"/>
            </material>
        </visual>
        <collision>
            <origin xyz="0 -0.23510949171371964 0.39467853685782717" rpy="0 0 0"/>
            <geometry>
                <box size="0.4698377247528003 0.4702189834274393 0.7893570737156543" />
            </geometry>
        </collision>
    </link>
</robot>