<robot name = "robot">
    <link name="Link0">
        <inertial>
            <origin xyz="0 0 2.095276755018214" rpy="0 0 0"/>
            <mass value="1" />
            <inertia ixx="100" ixy="0" ixz="0" iyy="100" iyz="0" izz="100" />
        </inertial>
        <visual>
            <origin xyz="0 0 2.095276755018214" rpy="0 0 0"/>
            <geometry>
                <box size="0.6810871950590427 0.02674303561661484 0.1905535100364274" />
            </geometry>
            <material name="Green">
                <color rgba="0 1.0 0.0 1.0"/>
            </material>
        </visual>
        <collision>
            <origin xyz="0 0 2.095276755018214" rpy="0 0 0"/>
            <geometry>
                <box size="0.6810871950590427 0.02674303561661484 0.1905535100364274" />
            </geometry>
        </collision>
    </link>
    <joint name="Link0_Link1" type="revolute">
       <parent link="Link0"/>
       <child  link="Link1"/>
       <origin rpy="0 0 0" xyz="0 0.01337151780830742 2.1905535100364273" />
     <axis xyz="1 0 0"/>
       <limit effort="0.0" lower="-3.14159" upper="3.14159" velocity="0.0"/>
    </joint>
    <link name="Link1">
        <inertial>
            <origin xyz="0 0.01337151780830742 -0.0952767550182137" rpy="0 0 0"/>
            <mass value="1" />
            <inertia ixx="100" ixy="0" ixz="0" iyy="100" iyz="0" izz="100" />
        </inertial>
        <visual>
            <origin xyz="0 0.01337151780830742 -0.0952767550182137" rpy="0 0 0"/>
            <geometry>
                <box size="0.6810871950590427 0.02674303561661484 0.1905535100364274" />
            </geometry>
            <material name="Blue">
                <color rgba="0 0.0 1.0 1.0"/>
            </material>
        </visual>
        <collision>
            <origin xyz="0 0.01337151780830742 -0.0952767550182137" rpy="0 0 0"/>
            <geometry>
                <box size="0.6810871950590427 0.02674303561661484 0.1905535100364274" />
            </geometry>
        </collision>
    </link>
    <joint name="Link1_Link2" type="revolute">
       <parent link="Link1"/>
       <child  link="Link2"/>
       <origin rpy="0 0 0" xyz="-0.34054359752952135 0.01337151780830742 0.0" />
     <axis xyz="0 1 0"/>
       <limit effort="0.0" lower="-3.14159" upper="3.14159" velocity="0.0"/>
    </joint>
    <link name="Link2">
        <inertial>
            <origin xyz="-0.2121048355297498 0 -0.05206632131307848" rpy="0 0 0"/>
            <mass value="1" />
            <inertia ixx="100" ixy="0" ixz="0" iyy="100" iyz="0" izz="100" />
        </inertial>
        <visual>
            <origin xyz="-0.2121048355297498 0 -0.05206632131307848" rpy="0 0 0"/>
            <geometry>
                <box size="0.4242096710594996 0.39053908280336724 0.10413264262615696" />
            </geometry>
            <material name="Green">
                <color rgba="0 1.0 0.0 1.0"/>
            </material>
        </visual>
        <collision>
            <origin xyz="-0.2121048355297498 0 -0.05206632131307848" rpy="0 0 0"/>
            <geometry>
                <box size="0.4242096710594996 0.39053908280336724 0.10413264262615696" />
            </geometry>
        </collision>
    </link>
    <joint name="Link2_Link3" type="revolute">
       <parent link="Link2"/>
       <child  link="Link3"/>
       <origin rpy="0 0 0" xyz="0.0 0 0.0" />
     <axis xyz="0 1 0"/>
       <limit effort="0.0" lower="-3.14159" upper="3.14159" velocity="0.0"/>
    </joint>
    <link name="Link3">
        <inertial>
            <origin xyz="0.054590062672656925 0 0.2746396753813469" rpy="0 0 0"/>
            <mass value="1" />
            <inertia ixx="100" ixy="0" ixz="0" iyy="100" iyz="0" izz="100" />
        </inertial>
        <visual>
            <origin xyz="0.054590062672656925 0 0.2746396753813469" rpy="0 0 0"/>
            <geometry>
                <box size="0.10918012534531385 0.6349658693364891 0.5492793507626939" />
            </geometry>
            <material name="Green">
                <color rgba="0 1.0 0.0 1.0"/>
            </material>
        </visual>
        <collision>
            <origin xyz="0.054590062672656925 0 0.2746396753813469" rpy="0 0 0"/>
            <geometry>
                <box size="0.10918012534531385 0.6349658693364891 0.5492793507626939" />
            </geometry>
        </collision>
    </link>
    <joint name="Link3_Link4" type="revolute">
       <parent link="Link3"/>
       <child  link="Link4"/>
       <origin rpy="0 0 0" xyz="0.10918012534531385 0 0.5492793507626939" />
     <axis xyz="0 1 0"/>
       <limit effort="0.0" lower="-3.14159" upper="3.14159" velocity="0.0"/>
    </joint>
    <link name="Link4">
        <inertial>
            <origin xyz="0.4599512039736146 0 0.1155926126641843" rpy="0 0 0"/>
            <mass value="1" />
            <inertia ixx="100" ixy="0" ixz="0" iyy="100" iyz="0" izz="100" />
        </inertial>
        <visual>
            <origin xyz="0.4599512039736146 0 0.1155926126641843" rpy="0 0 0"/>
            <geometry>
                <box size="0.9199024079472292 0.9819583830026896 0.2311852253283686" />
            </geometry>
            <material name="Green">
                <color rgba="0 1.0 0.0 1.0"/>
            </material>
        </visual>
        <collision>
            <origin xyz="0.4599512039736146 0 0.1155926126641843" rpy="0 0 0"/>
            <geometry>
                <box size="0.9199024079472292 0.9819583830026896 0.2311852253283686" />
            </geometry>
        </collision>
    </link>
    <joint name="Link4_Link5" type="revolute">
       <parent link="Link4"/>
       <child  link="Link5"/>
       <origin rpy="0 0 0" xyz="0.4599512039736146 -0.4909791915013448 0.2311852253283686" />
     <axis xyz="1 0 0"/>
       <limit effort="0.0" lower="-3.14159" upper="3.14159" velocity="0.0"/>
    </joint>
    <link name="Link5">
        <inertial>
            <origin xyz="0 -0.31618139303723114 -0.34241858146054294" rpy="0 0 0"/>
            <mass value="1" />
            <inertia ixx="100" ixy="0" ixz="0" iyy="100" iyz="0" izz="100" />
        </inertial>
        <visual>
            <origin xyz="0 -0.31618139303723114 -0.34241858146054294" rpy="0 0 0"/>
            <geometry>
                <box size="0.2305876284656193 0.6323627860744623 0.6848371629210859" />
            </geometry>
            <material name="Green">
                <color rgba="0 1.0 0.0 1.0"/>
            </material>
        </visual>
        <collision>
            <origin xyz="0 -0.31618139303723114 -0.34241858146054294" rpy="0 0 0"/>
            <geometry>
                <box size="0.2305876284656193 0.6323627860744623 0.6848371629210859" />
            </geometry>
        </collision>
    </link>
</robot>