<robot name = "robot">
    <link name="Link0">
        <inertial>
            <origin xyz="0 0 2.2744049938770603" rpy="0 0 0"/>
            <mass value="1" />
            <inertia ixx="100" ixy="0" ixz="0" iyy="100" iyz="0" izz="100" />
        </inertial>
        <visual>
            <origin xyz="0 0 2.2744049938770603" rpy="0 0 0"/>
            <geometry>
                <box size="0.026861915599130315 0.9710623074946828 0.5488099877541208" />
            </geometry>
            <material name="Green">
                <color rgba="0 1.0 0.0 1.0"/>
            </material>
        </visual>
        <collision>
            <origin xyz="0 0 2.2744049938770603" rpy="0 0 0"/>
            <geometry>
                <box size="0.026861915599130315 0.9710623074946828 0.5488099877541208" />
            </geometry>
        </collision>
    </link>
    <joint name="Link0_Link1" type="revolute">
       <parent link="Link0"/>
       <child  link="Link1"/>
       <origin rpy="0 0 0" xyz="0 0.4855311537473414 2.5488099877541206" />
     <axis xyz="1 0 0"/>
       <limit effort="0.0" lower="-3.14159" upper="3.14159" velocity="0.0"/>
    </joint>
    <link name="Link1">
        <inertial>
            <origin xyz="0 0.4855311537473414 -0.2744049938770604" rpy="0 0 0"/>
            <mass value="1" />
            <inertia ixx="100" ixy="0" ixz="0" iyy="100" iyz="0" izz="100" />
        </inertial>
        <visual>
            <origin xyz="0 0.4855311537473414 -0.2744049938770604" rpy="0 0 0"/>
            <geometry>
                <box size="0.026861915599130315 0.9710623074946828 0.5488099877541208" />
            </geometry>
            <material name="Blue">
                <color rgba="0 0.0 1.0 1.0"/>
            </material>
        </visual>
        <collision>
            <origin xyz="0 0.4855311537473414 -0.2744049938770604" rpy="0 0 0"/>
            <geometry>
                <box size="0.026861915599130315 0.9710623074946828 0.5488099877541208" />
            </geometry>
        </collision>
    </link>
    <joint name="Link1_Link2" type="revolute">
       <parent link="Link1"/>
       <child  link="Link2"/>
       <origin rpy="0 0 0" xyz="-0.013430957799565157 0.4855311537473414 0.0" />
     <axis xyz="0 1 0"/>
       <limit effort="0.0" lower="-3.14159" upper="3.14159" velocity="0.0"/>
    </joint>
    <link name="Link2">
        <inertial>
            <origin xyz="-0.4329139061570072 0 -0.42139843046406955" rpy="0 0 0"/>
            <mass value="1" />
            <inertia ixx="100" ixy="0" ixz="0" iyy="100" iyz="0" izz="100" />
        </inertial>
        <visual>
            <origin xyz="-0.4329139061570072 0 -0.42139843046406955" rpy="0 0 0"/>
            <geometry>
                <box size="0.8658278123140144 0.9244134127935169 0.8427968609281391" />
            </geometry>
            <material name="Green">
                <color rgba="0 1.0 0.0 1.0"/>
            </material>
        </visual>
        <collision>
            <origin xyz="-0.4329139061570072 0 -0.42139843046406955" rpy="0 0 0"/>
            <geometry>
                <box size="0.8658278123140144 0.9244134127935169 0.8427968609281391" />
            </geometry>
        </collision>
    </link>
    <joint name="Link2_Link3" type="revolute">
       <parent link="Link2"/>
       <child  link="Link3"/>
       <origin rpy="0 0 0" xyz="-0.8658278123140144 0 0.0" />
     <axis xyz="0 1 0"/>
       <limit effort="0.0" lower="-3.14159" upper="3.14159" velocity="0.0"/>
    </joint>
    <link name="Link3">
        <inertial>
            <origin xyz="-0.4340299229284792 0 -0.2796591042807699" rpy="0 0 0"/>
            <mass value="1" />
            <inertia ixx="100" ixy="0" ixz="0" iyy="100" iyz="0" izz="100" />
        </inertial>
        <visual>
            <origin xyz="-0.4340299229284792 0 -0.2796591042807699" rpy="0 0 0"/>
            <geometry>
                <box size="0.8680598458569584 0.7960500374041324 0.5593182085615398" />
            </geometry>
            <material name="Blue">
                <color rgba="0 0.0 1.0 1.0"/>
            </material>
        </visual>
        <collision>
            <origin xyz="-0.4340299229284792 0 -0.2796591042807699" rpy="0 0 0"/>
            <geometry>
                <box size="0.8680598458569584 0.7960500374041324 0.5593182085615398" />
            </geometry>
        </collision>
    </link>
    <joint name="Link3_Link4" type="revolute">
       <parent link="Link3"/>
       <child  link="Link4"/>
       <origin rpy="0 0 0" xyz="0.0 0 0.0" />
     <axis xyz="0 1 0"/>
       <limit effort="0.0" lower="-3.14159" upper="3.14159" velocity="0.0"/>
    </joint>
    <link name="Link4">
        <inertial>
            <origin xyz="0.1738557140582941 0 -0.37118438757800276" rpy="0 0 0"/>
            <mass value="1" />
            <inertia ixx="100" ixy="0" ixz="0" iyy="100" iyz="0" izz="100" />
        </inertial>
        <visual>
            <origin xyz="0.1738557140582941 0 -0.37118438757800276" rpy="0 0 0"/>
            <geometry>
                <box size="0.3477114281165882 0.61338324098331 0.7423687751560055" />
            </geometry>
            <material name="Green">
                <color rgba="0 1.0 0.0 1.0"/>
            </material>
        </visual>
        <collision>
            <origin xyz="0.1738557140582941 0 -0.37118438757800276" rpy="0 0 0"/>
            <geometry>
                <box size="0.3477114281165882 0.61338324098331 0.7423687751560055" />
            </geometry>
        </collision>
    </link>
    <joint name="Link4_Link5" type="revolute">
       <parent link="Link4"/>
       <child  link="Link5"/>
       <origin rpy="0 0 0" xyz="0.1738557140582941 0.306691620491655 0.0" />
     <axis xyz="1 0 0"/>
       <limit effort="0.0" lower="-3.14159" upper="3.14159" velocity="0.0"/>
    </joint>
    <link name="Link5">
        <inertial>
            <origin xyz="0 0.3144136175443666 -0.3455883804906108" rpy="0 0 0"/>
            <mass value="1" />
            <inertia ixx="100" ixy="0" ixz="0" iyy="100" iyz="0" izz="100" />
        </inertial>
        <visual>
            <origin xyz="0 0.3144136175443666 -0.3455883804906108" rpy="0 0 0"/>
            <geometry>
                <box size="0.7697122658238263 0.6288272350887332 0.6911767609812216" />
            </geometry>
            <material name="Blue">
                <color rgba="0 0.0 1.0 1.0"/>
            </material>
        </visual>
        <collision>
            <origin xyz="0 0.3144136175443666 -0.3455883804906108" rpy="0 0 0"/>
            <geometry>
                <box size="0.7697122658238263 0.6288272350887332 0.6911767609812216" />
            </geometry>
        </collision>
    </link>
</robot>