<robot name = "robot">
    <link name="Link0">
        <inertial>
            <origin xyz="0 0 2.0318417193190355" rpy="0 0 0"/>
            <mass value="1" />
            <inertia ixx="100" ixy="0" ixz="0" iyy="100" iyz="0" izz="100" />
        </inertial>
        <visual>
            <origin xyz="0 0 2.0318417193190355" rpy="0 0 0"/>
            <geometry>
                <box size="0.7821101395456436 0.438111484462396 0.06368343863807113" />
            </geometry>
            <material name="Green">
                <color rgba="0 1.0 0.0 1.0"/>
            </material>
        </visual>
        <collision>
            <origin xyz="0 0 2.0318417193190355" rpy="0 0 0"/>
            <geometry>
                <box size="0.7821101395456436 0.438111484462396 0.06368343863807113" />
            </geometry>
        </collision>
    </link>
    <joint name="Link0_Link1" type="revolute">
       <parent link="Link0"/>
       <child  link="Link1"/>
       <origin rpy="0 0 0" xyz="0 0.219055742231198 2.063683438638071" />
     <axis xyz="1 0 0"/>
       <limit effort="0.0" lower="-3.14159" upper="3.14159" velocity="0.0"/>
    </joint>
    <link name="Link1">
        <inertial>
            <origin xyz="0 0.219055742231198 -0.031841719319035566" rpy="0 0 0"/>
            <mass value="1" />
            <inertia ixx="100" ixy="0" ixz="0" iyy="100" iyz="0" izz="100" />
        </inertial>
        <visual>
            <origin xyz="0 0.219055742231198 -0.031841719319035566" rpy="0 0 0"/>
            <geometry>
                <box size="0.7821101395456436 0.438111484462396 0.06368343863807113" />
            </geometry>
            <material name="Blue">
                <color rgba="0 0.0 1.0 1.0"/>
            </material>
        </visual>
        <collision>
            <origin xyz="0 0.219055742231198 -0.031841719319035566" rpy="0 0 0"/>
            <geometry>
                <box size="0.7821101395456436 0.438111484462396 0.06368343863807113" />
            </geometry>
        </collision>
    </link>
    <joint name="Link1_Link2" type="revolute">
       <parent link="Link1"/>
       <child  link="Link2"/>
       <origin rpy="0 0 0" xyz="-0.3910550697728218 0.219055742231198 0.0" />
     <axis xyz="0 1 0"/>
       <limit effort="0.0" lower="-3.14159" upper="3.14159" velocity="0.0"/>
    </joint>
    <link name="Link2">
        <inertial>
            <origin xyz="-0.3861709366390854 0 0.16860205313939963" rpy="0 0 0"/>
            <mass value="1" />
            <inertia ixx="100" ixy="0" ixz="0" iyy="100" iyz="0" izz="100" />
        </inertial>
        <visual>
            <origin xyz="-0.3861709366390854 0 0.16860205313939963" rpy="0 0 0"/>
            <geometry>
                <box size="0.7723418732781708 0.7654322251652608 0.33720410627879926" />
            </geometry>
            <material name="Blue">
                <color rgba="0 0.0 1.0 1.0"/>
            </material>
        </visual>
        <collision>
            <origin xyz="-0.3861709366390854 0 0.16860205313939963" rpy="0 0 0"/>
            <geometry>
                <box size="0.7723418732781708 0.7654322251652608 0.33720410627879926" />
            </geometry>
        </collision>
    </link>
    <joint name="Link2_Link3" type="revolute">
       <parent link="Link2"/>
       <child  link="Link3"/>
       <origin rpy="0 0 0" xyz="-0.3861709366390854 0.3827161125826304 0.33720410627879926" />
     <axis xyz="1 0 0"/>
       <limit effort="0.0" lower="-3.14159" upper="3.14159" velocity="0.0"/>
    </joint>
    <link name="Link3">
        <inertial>
            <origin xyz="0 0.2339316148925138 -0.43733518020928563" rpy="0 0 0"/>
            <mass value="1" />
            <inertia ixx="100" ixy="0" ixz="0" iyy="100" iyz="0" izz="100" />
        </inertial>
        <visual>
            <origin xyz="0 0.2339316148925138 -0.43733518020928563" rpy="0 0 0"/>
            <geometry>
                <box size="0.18623758982210814 0.4678632297850276 0.8746703604185713" />
            </geometry>
            <material name="Green">
                <color rgba="0 1.0 0.0 1.0"/>
            </material>
        </visual>
        <collision>
            <origin xyz="0 0.2339316148925138 -0.43733518020928563" rpy="0 0 0"/>
            <geometry>
                <box size="0.18623758982210814 0.4678632297850276 0.8746703604185713" />
            </geometry>
        </collision>
    </link>
    <joint name="Link3_Link4" type="revolute">
       <parent link="Link3"/>
       <child  link="Link4"/>
       <origin rpy="0 0 0" xyz="-0.09311879491105407 0.2339316148925138 0.0" />
     <axis xyz="0 1 0"/>
       <limit effort="0.0" lower="-3.14159" upper="3.14159" velocity="0.0"/>
    </joint>
    <link name="Link4">
        <inertial>
            <origin xyz="-0.4650151467503002 0 0.150085737052694" rpy="0 0 0"/>
            <mass value="1" />
            <inertia ixx="100" ixy="0" ixz="0" iyy="100" iyz="0" izz="100" />
        </inertial>
        <visual>
            <origin xyz="-0.4650151467503002 0 0.150085737052694" rpy="0 0 0"/>
            <geometry>
                <box size="0.9300302935006004 0.31329435694963226 0.300171474105388" />
            </geometry>
            <material name="Green">
                <color rgba="0 1.0 0.0 1.0"/>
            </material>
        </visual>
        <collision>
            <origin xyz="-0.4650151467503002 0 0.150085737052694" rpy="0 0 0"/>
            <geometry>
                <box size="0.9300302935006004 0.31329435694963226 0.300171474105388" />
            </geometry>
        </collision>
    </link>
</robot>