<robot name = "robot">
    <link name="Link0">
        <inertial>
            <origin xyz="0 0 2.0560700115018915" rpy="0 0 0"/>
            <mass value="1" />
            <inertia ixx="100" ixy="0" ixz="0" iyy="100" iyz="0" izz="100" />
        </inertial>
        <visual>
            <origin xyz="0 0 2.0560700115018915" rpy="0 0 0"/>
            <geometry>
                <box size="0.6128952116682578 0.7799392826956371 0.11214002300378323" />
            </geometry>
            <material name="Green">
                <color rgba="0 1.0 0.0 1.0"/>
            </material>
        </visual>
        <collision>
            <origin xyz="0 0 2.0560700115018915" rpy="0 0 0"/>
            <geometry>
                <box size="0.6128952116682578 0.7799392826956371 0.11214002300378323" />
            </geometry>
        </collision>
    </link>
    <joint name="Link0_Link1" type="revolute">
       <parent link="Link0"/>
       <child  link="Link1"/>
       <origin rpy="0 0 0" xyz="0 0.38996964134781853 2.112140023003783" />
     <axis xyz="1 0 0"/>
       <limit effort="0.0" lower="-3.14159" upper="3.14159" velocity="0.0"/>
    </joint>
    <link name="Link1">
        <inertial>
            <origin xyz="0 0.38996964134781853 -0.056070011501891615" rpy="0 0 0"/>
            <mass value="1" />
            <inertia ixx="100" ixy="0" ixz="0" iyy="100" iyz="0" izz="100" />
        </inertial>
        <visual>
            <origin xyz="0 0.38996964134781853 -0.056070011501891615" rpy="0 0 0"/>
            <geometry>
                <box size="0.6128952116682578 0.7799392826956371 0.11214002300378323" />
            </geometry>
            <material name="Blue">
                <color rgba="0 0.0 1.0 1.0"/>
            </material>
        </visual>
        <collision>
            <origin xyz="0 0.38996964134781853 -0.056070011501891615" rpy="0 0 0"/>
            <geometry>
                <box size="0.6128952116682578 0.7799392826956371 0.11214002300378323" />
            </geometry>
        </collision>
    </link>
    <joint name="Link1_Link2" type="revolute">
       <parent link="Link1"/>
       <child  link="Link2"/>
       <origin rpy="0 0 0" xyz="0 0.0 0.0" />
     <axis xyz="1 0 0"/>
       <limit effort="0.0" lower="-3.14159" upper="3.14159" velocity="0.0"/>
    </joint>
    <link name="Link2">
        <inertial>
            <origin xyz="0 -0.2670763874412554 -0.3855465437161404" rpy="0 0 0"/>
            <mass value="1" />
            <inertia ixx="100" ixy="0" ixz="0" iyy="100" iyz="0" izz="100" />
        </inertial>
        <visual>
            <origin xyz="0 -0.2670763874412554 -0.3855465437161404" rpy="0 0 0"/>
            <geometry>
                <box size="0.8585577777749163 0.5341527748825108 0.7710930874322808" />
            </geometry>
            <material name="Blue">
                <color rgba="0 0.0 1.0 1.0"/>
            </material>
        </visual>
        <collision>
            <origin xyz="0 -0.2670763874412554 -0.3855465437161404" rpy="0 0 0"/>
            <geometry>
                <box size="0.8585577777749163 0.5341527748825108 0.7710930874322808" />
            </geometry>
        </collision>
    </link>
    <joint name="Link2_Link3" type="revolute">
       <parent link="Link2"/>
       <child  link="Link3"/>
       <origin rpy="0 0 0" xyz="-0.42927888888745813 -0.2670763874412554 0.0" />
     <axis xyz="0 1 0"/>
       <limit effort="0.0" lower="-3.14159" upper="3.14159" velocity="0.0"/>
    </joint>
    <link name="Link3">
        <inertial>
            <origin xyz="-0.03718886896522383 0 0.08793494521400724" rpy="0 0 0"/>
            <mass value="1" />
            <inertia ixx="100" ixy="0" ixz="0" iyy="100" iyz="0" izz="100" />
        </inertial>
        <visual>
            <origin xyz="-0.03718886896522383 0 0.08793494521400724" rpy="0 0 0"/>
            <geometry>
                <box size="0.07437773793044766 0.42895675729163496 0.17586989042801449" />
            </geometry>
            <material name="Green">
                <color rgba="0 1.0 0.0 1.0"/>
            </material>
        </visual>
        <collision>
            <origin xyz="-0.03718886896522383 0 0.08793494521400724" rpy="0 0 0"/>
            <geometry>
                <box size="0.07437773793044766 0.42895675729163496 0.17586989042801449" />
            </geometry>
        </collision>
    </link>
    <joint name="Link3_Link4" type="revolute">
       <parent link="Link3"/>
       <child  link="Link4"/>
       <origin rpy="0 0 0" xyz="-0.03718886896522383 0.21447837864581748 0.17586989042801449" />
     <axis xyz="1 0 0"/>
       <limit effort="0.0" lower="-3.14159" upper="3.14159" velocity="0.0"/>
    </joint>
    <link name="Link4">
        <inertial>
            <origin xyz="0 0.2672320904686192 0.24849205285828796" rpy="0 0 0"/>
            <mass value="1" />
            <inertia ixx="100" ixy="0" ixz="0" iyy="100" iyz="0" izz="100" />
        </inertial>
        <visual>
            <origin xyz="0 0.2672320904686192 0.24849205285828796" rpy="0 0 0"/>
            <geometry>
                <box size="0.24311247088436772 0.5344641809372384 0.4969841057165759" />
            </geometry>
            <material name="Blue">
                <color rgba="0 0.0 1.0 1.0"/>
            </material>
        </visual>
        <collision>
            <origin xyz="0 0.2672320904686192 0.24849205285828796" rpy="0 0 0"/>
            <geometry>
                <box size="0.24311247088436772 0.5344641809372384 0.4969841057165759" />
            </geometry>
        </collision>
    </link>
    <joint name="Link4_Link5" type="revolute">
       <parent link="Link4"/>
       <child  link="Link5"/>
       <origin rpy="0 0 0" xyz="-0.12155623544218386 0.2672320904686192 0.4969841057165759" />
     <axis xyz="0 1 0"/>
       <limit effort="0.0" lower="-3.14159" upper="3.14159" velocity="0.0"/>
    </joint>
    <link name="Link5">
        <inertial>
            <origin xyz="-0.2909398010323466 0 0.26710441968092263" rpy="0 0 0"/>
            <mass value="1" />
            <inertia ixx="100" ixy="0" ixz="0" iyy="100" iyz="0" izz="100" />
        </inertial>
        <visual>
            <origin xyz="-0.2909398010323466 0 0.26710441968092263" rpy="0 0 0"/>
            <geometry>
                <box size="0.5818796020646932 0.8621493574080237 0.5342088393618453" />
            </geometry>
            <material name="Blue">
                <color rgba="0 0.0 1.0 1.0"/>
            </material>
        </visual>
        <collision>
            <origin xyz="-0.2909398010323466 0 0.26710441968092263" rpy="0 0 0"/>
            <geometry>
                <box size="0.5818796020646932 0.8621493574080237 0.5342088393618453" />
            </geometry>
        </collision>
    </link>
</robot>