<robot name = "robot">
    <link name="Link0">
        <inertial>
            <origin xyz="0 0 2.1966533624528197" rpy="0 0 0"/>
            <mass value="1" />
            <inertia ixx="100" ixy="0" ixz="0" iyy="100" iyz="0" izz="100" />
        </inertial>
        <visual>
            <origin xyz="0 0 2.1966533624528197" rpy="0 0 0"/>
            <geometry>
                <box size="0.17256589931063737 0.9012571487705473 0.39330672490563956" />
            </geometry>
            <material name="Green">
                <color rgba="0 1.0 0.0 1.0"/>
            </material>
        </visual>
        <collision>
            <origin xyz="0 0 2.1966533624528197" rpy="0 0 0"/>
            <geometry>
                <box size="0.17256589931063737 0.9012571487705473 0.39330672490563956" />
            </geometry>
        </collision>
    </link>
    <joint name="Link0_Link1" type="revolute">
       <parent link="Link0"/>
       <child  link="Link1"/>
       <origin rpy="0 0 0" xyz="0 0.45062857438527365 2.3933067249056394" />
     <axis xyz="1 0 0"/>
       <limit effort="0.0" lower="-3.14159" upper="3.14159" velocity="0.0"/>
    </joint>
    <link name="Link1">
        <inertial>
            <origin xyz="0 0.45062857438527365 -0.19665336245281978" rpy="0 0 0"/>
            <mass value="1" />
            <inertia ixx="100" ixy="0" ixz="0" iyy="100" iyz="0" izz="100" />
        </inertial>
        <visual>
            <origin xyz="0 0.45062857438527365 -0.19665336245281978" rpy="0 0 0"/>
            <geometry>
                <box size="0.17256589931063737 0.9012571487705473 0.39330672490563956" />
            </geometry>
            <material name="Green">
                <color rgba="0 1.0 0.0 1.0"/>
            </material>
        </visual>
        <collision>
            <origin xyz="0 0.45062857438527365 -0.19665336245281978" rpy="0 0 0"/>
            <geometry>
                <box size="0.17256589931063737 0.9012571487705473 0.39330672490563956" />
            </geometry>
        </collision>
    </link>
    <joint name="Link1_Link2" type="revolute">
       <parent link="Link1"/>
       <child  link="Link2"/>
       <origin rpy="0 0 0" xyz="0 0.0 0.0" />
     <axis xyz="1 0 0"/>
       <limit effort="0.0" lower="-3.14159" upper="3.14159" velocity="0.0"/>
    </joint>
    <link name="Link2">
        <inertial>
            <origin xyz="0 -0.1061024415811917 0.40644335760160566" rpy="0 0 0"/>
            <mass value="1" />
            <inertia ixx="100" ixy="0" ixz="0" iyy="100" iyz="0" izz="100" />
        </inertial>
        <visual>
            <origin xyz="0 -0.1061024415811917 0.40644335760160566" rpy="0 0 0"/>
            <geometry>
                <box size="0.1188921810565039 0.2122048831623834 0.8128867152032113" />
            </geometry>
            <material name="Green">
                <color rgba="0 1.0 0.0 1.0"/>
            </material>
        </visual>
        <collision>
            <origin xyz="0 -0.1061024415811917 0.40644335760160566" rpy="0 0 0"/>
            <geometry>
                <box size="0.1188921810565039 0.2122048831623834 0.8128867152032113" />
            </geometry>
        </collision>
    </link>
    <joint name="Link2_Link3" type="revolute">
       <parent link="Link2"/>
       <child  link="Link3"/>
       <origin rpy="0 0 0" xyz="-0.05944609052825195 -0.1061024415811917 0.8128867152032113" />
     <axis xyz="0 1 0"/>
       <limit effort="0.0" lower="-3.14159" upper="3.14159" velocity="0.0"/>
    </joint>
    <link name="Link3">
        <inertial>
            <origin xyz="-0.3309957215391175 0 -0.3210508113252071" rpy="0 0 0"/>
            <mass value="1" />
            <inertia ixx="100" ixy="0" ixz="0" iyy="100" iyz="0" izz="100" />
        </inertial>
        <visual>
            <origin xyz="-0.3309957215391175 0 -0.3210508113252071" rpy="0 0 0"/>
            <geometry>
                <box size="0.661991443078235 0.5014230139301444 0.6421016226504141" />
            </geometry>
            <material name="Green">
                <color rgba="0 1.0 0.0 1.0"/>
            </material>
        </visual>
        <collision>
            <origin xyz="-0.3309957215391175 0 -0.3210508113252071" rpy="0 0 0"/>
            <geometry>
                <box size="0.661991443078235 0.5014230139301444 0.6421016226504141" />
            </geometry>
        </collision>
    </link>
    <joint name="Link3_Link4" type="revolute">
       <parent link="Link3"/>
       <child  link="Link4"/>
       <origin rpy="0 0 0" xyz="0.0 0 0.0" />
     <axis xyz="0 1 0"/>
       <limit effort="0.0" lower="-3.14159" upper="3.14159" velocity="0.0"/>
    </joint>
    <link name="Link4">
        <inertial>
            <origin xyz="0.3371301290891914 0 0.3046420766149284" rpy="0 0 0"/>
            <mass value="1" />
            <inertia ixx="100" ixy="0" ixz="0" iyy="100" iyz="0" izz="100" />
        </inertial>
        <visual>
            <origin xyz="0.3371301290891914 0 0.3046420766149284" rpy="0 0 0"/>
            <geometry>
                <box size="0.6742602581783828 0.11506187030899884 0.6092841532298569" />
            </geometry>
            <material name="Blue">
                <color rgba="0 0.0 1.0 1.0"/>
            </material>
        </visual>
        <collision>
            <origin xyz="0.3371301290891914 0 0.3046420766149284" rpy="0 0 0"/>
            <geometry>
                <box size="0.6742602581783828 0.11506187030899884 0.6092841532298569" />
            </geometry>
        </collision>
    </link>
    <joint name="Link4_Link5" type="revolute">
       <parent link="Link4"/>
       <child  link="Link5"/>
       <origin rpy="0 0 0" xyz="0.3371301290891914 -0.05753093515449942 0.6092841532298569" />
     <axis xyz="1 0 0"/>
       <limit effort="0.0" lower="-3.14159" upper="3.14159" velocity="0.0"/>
    </joint>
    <link name="Link5">
        <inertial>
            <origin xyz="0 -0.3556080845079533 -0.25693961156904577" rpy="0 0 0"/>
            <mass value="1" />
            <inertia ixx="100" ixy="0" ixz="0" iyy="100" iyz="0" izz="100" />
        </inertial>
        <visual>
            <origin xyz="0 -0.3556080845079533 -0.25693961156904577" rpy="0 0 0"/>
            <geometry>
                <box size="0.37552462142881127 0.7112161690159066 0.5138792231380915" />
            </geometry>
            <material name="Green">
                <color rgba="0 1.0 0.0 1.0"/>
            </material>
        </visual>
        <collision>
            <origin xyz="0 -0.3556080845079533 -0.25693961156904577" rpy="0 0 0"/>
            <geometry>
                <box size="0.37552462142881127 0.7112161690159066 0.5138792231380915" />
            </geometry>
        </collision>
    </link>
</robot>