<robot name = "robot">
    <link name="Link0">
        <inertial>
            <origin xyz="0 0 2.359247025970508" rpy="0 0 0"/>
            <mass value="1" />
            <inertia ixx="100" ixy="0" ixz="0" iyy="100" iyz="0" izz="100" />
        </inertial>
        <visual>
            <origin xyz="0 0 2.359247025970508" rpy="0 0 0"/>
            <geometry>
                <box size="0.882348956290861 0.6630016788590115 0.7184940519410153" />
            </geometry>
            <material name="Green">
                <color rgba="0 1.0 0.0 1.0"/>
            </material>
        </visual>
        <collision>
            <origin xyz="0 0 2.359247025970508" rpy="0 0 0"/>
            <geometry>
                <box size="0.882348956290861 0.6630016788590115 0.7184940519410153" />
            </geometry>
        </collision>
    </link>
    <joint name="Link0_Link1" type="revolute">
       <parent link="Link0"/>
       <child  link="Link1"/>
       <origin rpy="0 0 0" xyz="0 0.33150083942950576 2.7184940519410152" />
     <axis xyz="1 0 0"/>
       <limit effort="0.0" lower="-3.14159" upper="3.14159" velocity="0.0"/>
    </joint>
    <link name="Link1">
        <inertial>
            <origin xyz="0 0.33150083942950576 -0.35924702597050767" rpy="0 0 0"/>
            <mass value="1" />
            <inertia ixx="100" ixy="0" ixz="0" iyy="100" iyz="0" izz="100" />
        </inertial>
        <visual>
            <origin xyz="0 0.33150083942950576 -0.35924702597050767" rpy="0 0 0"/>
            <geometry>
                <box size="0.882348956290861 0.6630016788590115 0.7184940519410153" />
            </geometry>
            <material name="Blue">
                <color rgba="0 0.0 1.0 1.0"/>
            </material>
        </visual>
        <collision>
            <origin xyz="0 0.33150083942950576 -0.35924702597050767" rpy="0 0 0"/>
            <geometry>
                <box size="0.882348956290861 0.6630016788590115 0.7184940519410153" />
            </geometry>
        </collision>
    </link>
    <joint name="Link1_Link2" type="revolute">
       <parent link="Link1"/>
       <child  link="Link2"/>
       <origin rpy="0 0 0" xyz="0 0.0 0.0" />
     <axis xyz="1 0 0"/>
       <limit effort="0.0" lower="-3.14159" upper="3.14159" velocity="0.0"/>
    </joint>
    <link name="Link2">
        <inertial>
            <origin xyz="0 -0.4441859926867186 -0.022684019712778114" rpy="0 0 0"/>
            <mass value="1" />
            <inertia ixx="100" ixy="0" ixz="0" iyy="100" iyz="0" izz="100" />
        </inertial>
        <visual>
            <origin xyz="0 -0.4441859926867186 -0.022684019712778114" rpy="0 0 0"/>
            <geometry>
                <box size="0.3644707978380535 0.8883719853734372 0.04536803942555623" />
            </geometry>
            <material name="Blue">
                <color rgba="0 0.0 1.0 1.0"/>
            </material>
        </visual>
        <collision>
            <origin xyz="0 -0.4441859926867186 -0.022684019712778114" rpy="0 0 0"/>
            <geometry>
                <box size="0.3644707978380535 0.8883719853734372 0.04536803942555623" />
            </geometry>
        </collision>
    </link>
    <joint name="Link2_Link3" type="revolute">
       <parent link="Link2"/>
       <child  link="Link3"/>
       <origin rpy="0 0 0" xyz="0 0.0 0.0" />
     <axis xyz="1 0 0"/>
       <limit effort="0.0" lower="-3.14159" upper="3.14159" velocity="0.0"/>
    </joint>
    <link name="Link3">
        <inertial>
            <origin xyz="0 0.10938033119553037 0.41894938917979685" rpy="0 0 0"/>
            <mass value="1" />
            <inertia ixx="100" ixy="0" ixz="0" iyy="100" iyz="0" izz="100" />
        </inertial>
        <visual>
            <origin xyz="0 0.10938033119553037 0.41894938917979685" rpy="0 0 0"/>
            <geometry>
                <box size="0.10717806056058699 0.21876066239106073 0.8378987783595937" />
            </geometry>
            <material name="Green">
                <color rgba="0 1.0 0.0 1.0"/>
            </material>
        </visual>
        <collision>
            <origin xyz="0 0.10938033119553037 0.41894938917979685" rpy="0 0 0"/>
            <geometry>
                <box size="0.10717806056058699 0.21876066239106073 0.8378987783595937" />
            </geometry>
        </collision>
    </link>
    <joint name="Link3_Link4" type="revolute">
       <parent link="Link3"/>
       <child  link="Link4"/>
       <origin rpy="0 0 0" xyz="0 0.21876066239106073 0.8378987783595937" />
     <axis xyz="1 0 0"/>
       <limit effort="0.0" lower="-3.14159" upper="3.14159" velocity="0.0"/>
    </joint>
    <link name="Link4">
        <inertial>
            <origin xyz="0 0.43156978376531274 -0.12329994502690472" rpy="0 0 0"/>
            <mass value="1" />
            <inertia ixx="100" ixy="0" ixz="0" iyy="100" iyz="0" izz="100" />
        </inertial>
        <visual>
            <origin xyz="0 0.43156978376531274 -0.12329994502690472" rpy="0 0 0"/>
            <geometry>
                <box size="0.1039470943454226 0.8631395675306255 0.24659989005380945" />
            </geometry>
            <material name="Blue">
                <color rgba="0 0.0 1.0 1.0"/>
            </material>
        </visual>
        <collision>
            <origin xyz="0 0.43156978376531274 -0.12329994502690472" rpy="0 0 0"/>
            <geometry>
                <box size="0.1039470943454226 0.8631395675306255 0.24659989005380945" />
            </geometry>
        </collision>
    </link>
</robot>