<robot name = "robot">
    <link name="Link0">
        <inertial>
            <origin xyz="0 0 2.3729742521899477" rpy="0 0 0"/>
            <mass value="1" />
            <inertia ixx="100" ixy="0" ixz="0" iyy="100" iyz="0" izz="100" />
        </inertial>
        <visual>
            <origin xyz="0 0 2.3729742521899477" rpy="0 0 0"/>
            <geometry>
                <box size="0.4793922003033191 0.604338986803994 0.7459485043798953" />
            </geometry>
            <material name="Green">
                <color rgba="0 1.0 0.0 1.0"/>
            </material>
        </visual>
        <collision>
            <origin xyz="0 0 2.3729742521899477" rpy="0 0 0"/>
            <geometry>
                <box size="0.4793922003033191 0.604338986803994 0.7459485043798953" />
            </geometry>
        </collision>
    </link>
    <joint name="Link0_Link1" type="revolute">
       <parent link="Link0"/>
       <child  link="Link1"/>
       <origin rpy="0 0 0" xyz="0 0.302169493401997 2.7459485043798955" />
     <axis xyz="1 0 0"/>
       <limit effort="0.0" lower="-3.14159" upper="3.14159" velocity="0.0"/>
    </joint>
    <link name="Link1">
        <inertial>
            <origin xyz="0 0.302169493401997 -0.3729742521899477" rpy="0 0 0"/>
            <mass value="1" />
            <inertia ixx="100" ixy="0" ixz="0" iyy="100" iyz="0" izz="100" />
        </inertial>
        <visual>
            <origin xyz="0 0.302169493401997 -0.3729742521899477" rpy="0 0 0"/>
            <geometry>
                <box size="0.4793922003033191 0.604338986803994 0.7459485043798953" />
            </geometry>
            <material name="Blue">
                <color rgba="0 0.0 1.0 1.0"/>
            </material>
        </visual>
        <collision>
            <origin xyz="0 0.302169493401997 -0.3729742521899477" rpy="0 0 0"/>
            <geometry>
                <box size="0.4793922003033191 0.604338986803994 0.7459485043798953" />
            </geometry>
        </collision>
    </link>
    <joint name="Link1_Link2" type="revolute">
       <parent link="Link1"/>
       <child  link="Link2"/>
       <origin rpy="0 0 0" xyz="-0.23969610015165954 0.302169493401997 0.0" />
     <axis xyz="0 1 0"/>
       <limit effort="0.0" lower="-3.14159" upper="3.14159" velocity="0.0"/>
    </joint>
    <link name="Link2">
        <inertial>
            <origin xyz="-0.042175609413462656 0 -0.31044177167476644" rpy="0 0 0"/>
            <mass value="1" />
            <inertia ixx="100" ixy="0" ixz="0" iyy="100" iyz="0" izz="100" />
        </inertial>
        <visual>
            <origin xyz="-0.042175609413462656 0 -0.31044177167476644" rpy="0 0 0"/>
            <geometry>
                <box size="0.08435121882692531 0.5304952189759884 0.6208835433495329" />
            </geometry>
            <material name="Green">
                <color rgba="0 1.0 0.0 1.0"/>
            </material>
        </visual>
        <collision>
            <origin xyz="-0.042175609413462656 0 -0.31044177167476644" rpy="0 0 0"/>
            <geometry>
                <box size="0.08435121882692531 0.5304952189759884 0.6208835433495329" />
            </geometry>
        </collision>
    </link>
    <joint name="Link2_Link3" type="revolute">
       <parent link="Link2"/>
       <child  link="Link3"/>
       <origin rpy="0 0 0" xyz="-0.042175609413462656 -0.2652476094879942 0.0" />
     <axis xyz="1 0 0"/>
       <limit effort="0.0" lower="-3.14159" upper="3.14159" velocity="0.0"/>
    </joint>
    <link name="Link3">
        <inertial>
            <origin xyz="0 -0.18950108722428716 -0.47354706105631084" rpy="0 0 0"/>
            <mass value="1" />
            <inertia ixx="100" ixy="0" ixz="0" iyy="100" iyz="0" izz="100" />
        </inertial>
        <visual>
            <origin xyz="0 -0.18950108722428716 -0.47354706105631084" rpy="0 0 0"/>
            <geometry>
                <box size="0.7994654596852989 0.3790021744485743 0.9470941221126217" />
            </geometry>
            <material name="Blue">
                <color rgba="0 0.0 1.0 1.0"/>
            </material>
        </visual>
        <collision>
            <origin xyz="0 -0.18950108722428716 -0.47354706105631084" rpy="0 0 0"/>
            <geometry>
                <box size="0.7994654596852989 0.3790021744485743 0.9470941221126217" />
            </geometry>
        </collision>
    </link>
    <joint name="Link3_Link4" type="revolute">
       <parent link="Link3"/>
       <child  link="Link4"/>
       <origin rpy="0 0 0" xyz="0 0.0 0.0" />
     <axis xyz="1 0 0"/>
       <limit effort="0.0" lower="-3.14159" upper="3.14159" velocity="0.0"/>
    </joint>
    <link name="Link4">
        <inertial>
            <origin xyz="0 0.24460972573949158 -0.013745855151189701" rpy="0 0 0"/>
            <mass value="1" />
            <inertia ixx="100" ixy="0" ixz="0" iyy="100" iyz="0" izz="100" />
        </inertial>
        <visual>
            <origin xyz="0 0.24460972573949158 -0.013745855151189701" rpy="0 0 0"/>
            <geometry>
                <box size="0.20439221263950458 0.48921945147898316 0.027491710302379402" />
            </geometry>
            <material name="Blue">
                <color rgba="0 0.0 1.0 1.0"/>
            </material>
        </visual>
        <collision>
            <origin xyz="0 0.24460972573949158 -0.013745855151189701" rpy="0 0 0"/>
            <geometry>
                <box size="0.20439221263950458 0.48921945147898316 0.027491710302379402" />
            </geometry>
        </collision>
    </link>
    <joint name="Link4_Link5" type="revolute">
       <parent link="Link4"/>
       <child  link="Link5"/>
       <origin rpy="0 0 0" xyz="0 0.0 0.0" />
     <axis xyz="1 0 0"/>
       <limit effort="0.0" lower="-3.14159" upper="3.14159" velocity="0.0"/>
    </joint>
    <link name="Link5">
        <inertial>
            <origin xyz="0 -0.47570684002372876 -0.3849764295638231" rpy="0 0 0"/>
            <mass value="1" />
            <inertia ixx="100" ixy="0" ixz="0" iyy="100" iyz="0" izz="100" />
        </inertial>
        <visual>
            <origin xyz="0 -0.47570684002372876 -0.3849764295638231" rpy="0 0 0"/>
            <geometry>
                <box size="0.5574925542534676 0.9514136800474575 0.7699528591276462" />
            </geometry>
            <material name="Blue">
                <color rgba="0 0.0 1.0 1.0"/>
            </material>
        </visual>
        <collision>
            <origin xyz="0 -0.47570684002372876 -0.3849764295638231" rpy="0 0 0"/>
            <geometry>
                <box size="0.5574925542534676 0.9514136800474575 0.7699528591276462" />
            </geometry>
        </collision>
    </link>
    <joint name="Link5_Link6" type="revolute">
       <parent link="Link5"/>
       <child  link="Link6"/>
       <origin rpy="0 0 0" xyz="-0.2787462771267338 -0.47570684002372876 0.0" />
     <axis xyz="0 1 0"/>
       <limit effort="0.0" lower="-3.14159" upper="3.14159" velocity="0.0"/>
    </joint>
    <link name="Link6">
        <inertial>
            <origin xyz="-0.3915394761111643 0 -0.30799276952415644" rpy="0 0 0"/>
            <mass value="1" />
            <inertia ixx="100" ixy="0" ixz="0" iyy="100" iyz="0" izz="100" />
        </inertial>
        <visual>
            <origin xyz="-0.3915394761111643 0 -0.30799276952415644" rpy="0 0 0"/>
            <geometry>
                <box size="0.7830789522223286 0.7701045743805287 0.6159855390483129" />
            </geometry>
            <material name="Blue">
                <color rgba="0 0.0 1.0 1.0"/>
            </material>
        </visual>
        <collision>
            <origin xyz="-0.3915394761111643 0 -0.30799276952415644" rpy="0 0 0"/>
            <geometry>
                <box size="0.7830789522223286 0.7701045743805287 0.6159855390483129" />
            </geometry>
        </collision>
    </link>
</robot>