<robot name = "robot">
    <link name="Link0">
        <inertial>
            <origin xyz="0 0 2.0135015134460814" rpy="0 0 0"/>
            <mass value="1" />
            <inertia ixx="100" ixy="0" ixz="0" iyy="100" iyz="0" izz="100" />
        </inertial>
        <visual>
            <origin xyz="0 0 2.0135015134460814" rpy="0 0 0"/>
            <geometry>
                <box size="0.8585166947158651 0.07148222187900022 0.02700302689216294" />
            </geometry>
            <material name="Green">
                <color rgba="0 1.0 0.0 1.0"/>
            </material>
        </visual>
        <collision>
            <origin xyz="0 0 2.0135015134460814" rpy="0 0 0"/>
            <geometry>
                <box size="0.8585166947158651 0.07148222187900022 0.02700302689216294" />
            </geometry>
        </collision>
    </link>
    <joint name="Link0_Link1" type="revolute">
       <parent link="Link0"/>
       <child  link="Link1"/>
       <origin rpy="0 0 0" xyz="0 0.03574111093950011 2.027003026892163" />
     <axis xyz="1 0 0"/>
       <limit effort="0.0" lower="-3.14159" upper="3.14159" velocity="0.0"/>
    </joint>
    <link name="Link1">
        <inertial>
            <origin xyz="0 0.03574111093950011 -0.01350151344608147" rpy="0 0 0"/>
            <mass value="1" />
            <inertia ixx="100" ixy="0" ixz="0" iyy="100" iyz="0" izz="100" />
        </inertial>
        <visual>
            <origin xyz="0 0.03574111093950011 -0.01350151344608147" rpy="0 0 0"/>
            <geometry>
                <box size="0.8585166947158651 0.07148222187900022 0.02700302689216294" />
            </geometry>
            <material name="Green">
                <color rgba="0 1.0 0.0 1.0"/>
            </material>
        </visual>
        <collision>
            <origin xyz="0 0.03574111093950011 -0.01350151344608147" rpy="0 0 0"/>
            <geometry>
                <box size="0.8585166947158651 0.07148222187900022 0.02700302689216294" />
            </geometry>
        </collision>
    </link>
    <joint name="Link1_Link2" type="revolute">
       <parent link="Link1"/>
       <child  link="Link2"/>
       <origin rpy="0 0 0" xyz="0.42925834735793256 0.03574111093950011 0.0" />
     <axis xyz="0 1 0"/>
       <limit effort="0.0" lower="-3.14159" upper="3.14159" velocity="0.0"/>
    </joint>
    <link name="Link2">
        <inertial>
            <origin xyz="0.02351963184175443 0 -0.13186010916315705" rpy="0 0 0"/>
            <mass value="1" />
            <inertia ixx="100" ixy="0" ixz="0" iyy="100" iyz="0" izz="100" />
        </inertial>
        <visual>
            <origin xyz="0.02351963184175443 0 -0.13186010916315705" rpy="0 0 0"/>
            <geometry>
                <box size="0.04703926368350886 0.8880799042497557 0.2637202183263141" />
            </geometry>
            <material name="Blue">
                <color rgba="0 0.0 1.0 1.0"/>
            </material>
        </visual>
        <collision>
            <origin xyz="0.02351963184175443 0 -0.13186010916315705" rpy="0 0 0"/>
            <geometry>
                <box size="0.04703926368350886 0.8880799042497557 0.2637202183263141" />
            </geometry>
        </collision>
    </link>
    <joint name="Link2_Link3" type="revolute">
       <parent link="Link2"/>
       <child  link="Link3"/>
       <origin rpy="0 0 0" xyz="0.04703926368350886 0 0.0" />
     <axis xyz="0 1 0"/>
       <limit effort="0.0" lower="-3.14159" upper="3.14159" velocity="0.0"/>
    </joint>
    <link name="Link3">
        <inertial>
            <origin xyz="0.0993716875037658 0 -0.15045818628585567" rpy="0 0 0"/>
            <mass value="1" />
            <inertia ixx="100" ixy="0" ixz="0" iyy="100" iyz="0" izz="100" />
        </inertial>
        <visual>
            <origin xyz="0.0993716875037658 0 -0.15045818628585567" rpy="0 0 0"/>
            <geometry>
                <box size="0.1987433750075316 0.15184888053925893 0.30091637257171133" />
            </geometry>
            <material name="Blue">
                <color rgba="0 0.0 1.0 1.0"/>
            </material>
        </visual>
        <collision>
            <origin xyz="0.0993716875037658 0 -0.15045818628585567" rpy="0 0 0"/>
            <geometry>
                <box size="0.1987433750075316 0.15184888053925893 0.30091637257171133" />
            </geometry>
        </collision>
    </link>
    <joint name="Link3_Link4" type="revolute">
       <parent link="Link3"/>
       <child  link="Link4"/>
       <origin rpy="0 0 0" xyz="0.0993716875037658 0.07592444026962947 0.0" />
     <axis xyz="1 0 0"/>
       <limit effort="0.0" lower="-3.14159" upper="3.14159" velocity="0.0"/>
    </joint>
    <link name="Link4">
        <inertial>
            <origin xyz="0 0.03422602997031665 0.19738237071411202" rpy="0 0 0"/>
            <mass value="1" />
            <inertia ixx="100" ixy="0" ixz="0" iyy="100" iyz="0" izz="100" />
        </inertial>
        <visual>
            <origin xyz="0 0.03422602997031665 0.19738237071411202" rpy="0 0 0"/>
            <geometry>
                <box size="0.5723313172485217 0.0684520599406333 0.39476474142822404" />
            </geometry>
            <material name="Green">
                <color rgba="0 1.0 0.0 1.0"/>
            </material>
        </visual>
        <collision>
            <origin xyz="0 0.03422602997031665 0.19738237071411202" rpy="0 0 0"/>
            <geometry>
                <box size="0.5723313172485217 0.0684520599406333 0.39476474142822404" />
            </geometry>
        </collision>
    </link>
    <joint name="Link4_Link5" type="revolute">
       <parent link="Link4"/>
       <child  link="Link5"/>
       <origin rpy="0 0 0" xyz="-0.28616565862426085 0.03422602997031665 0.39476474142822404" />
     <axis xyz="0 1 0"/>
       <limit effort="0.0" lower="-3.14159" upper="3.14159" velocity="0.0"/>
    </joint>
    <link name="Link5">
        <inertial>
            <origin xyz="-0.31146221817777103 0 0.029082413335395796" rpy="0 0 0"/>
            <mass value="1" />
            <inertia ixx="100" ixy="0" ixz="0" iyy="100" iyz="0" izz="100" />
        </inertial>
        <visual>
            <origin xyz="-0.31146221817777103 0 0.029082413335395796" rpy="0 0 0"/>
            <geometry>
                <box size="0.6229244363555421 0.9096149908587045 0.05816482667079159" />
            </geometry>
            <material name="Blue">
                <color rgba="0 0.0 1.0 1.0"/>
            </material>
        </visual>
        <collision>
            <origin xyz="-0.31146221817777103 0 0.029082413335395796" rpy="0 0 0"/>
            <geometry>
                <box size="0.6229244363555421 0.9096149908587045 0.05816482667079159" />
            </geometry>
        </collision>
    </link>
    <joint name="Link5_Link6" type="revolute">
       <parent link="Link5"/>
       <child  link="Link6"/>
       <origin rpy="0 0 0" xyz="-0.6229244363555421 0 0.05816482667079159" />
     <axis xyz="0 1 0"/>
       <limit effort="0.0" lower="-3.14159" upper="3.14159" velocity="0.0"/>
    </joint>
    <link name="Link6">
        <inertial>
            <origin xyz="-0.4591157036610287 0 0.21478704104215046" rpy="0 0 0"/>
            <mass value="1" />
            <inertia ixx="100" ixy="0" ixz="0" iyy="100" iyz="0" izz="100" />
        </inertial>
        <visual>
            <origin xyz="-0.4591157036610287 0 0.21478704104215046" rpy="0 0 0"/>
            <geometry>
                <box size="0.9182314073220574 0.3697965190646395 0.4295740820843009" />
            </geometry>
            <material name="Green">
                <color rgba="0 1.0 0.0 1.0"/>
            </material>
        </visual>
        <collision>
            <origin xyz="-0.4591157036610287 0 0.21478704104215046" rpy="0 0 0"/>
            <geometry>
                <box size="0.9182314073220574 0.3697965190646395 0.4295740820843009" />
            </geometry>
        </collision>
    </link>
</robot>