<robot name = "robot">
    <link name="Link0">
        <inertial>
            <origin xyz="0 0 2.0935127274790686" rpy="0 0 0"/>
            <mass value="1" />
            <inertia ixx="100" ixy="0" ixz="0" iyy="100" iyz="0" izz="100" />
        </inertial>
        <visual>
            <origin xyz="0 0 2.0935127274790686" rpy="0 0 0"/>
            <geometry>
                <box size="0.2670485691586484 0.8162062784439597 0.18702545495813672" />
            </geometry>
            <material name="Green">
                <color rgba="0 1.0 0.0 1.0"/>
            </material>
        </visual>
        <collision>
            <origin xyz="0 0 2.0935127274790686" rpy="0 0 0"/>
            <geometry>
                <box size="0.2670485691586484 0.8162062784439597 0.18702545495813672" />
            </geometry>
        </collision>
    </link>
    <joint name="Link0_Link1" type="revolute">
       <parent link="Link0"/>
       <child  link="Link1"/>
       <origin rpy="0 0 0" xyz="0 0.4081031392219798 2.1870254549581367" />
     <axis xyz="1 0 0"/>
       <limit effort="0.0" lower="-3.14159" upper="3.14159" velocity="0.0"/>
    </joint>
    <link name="Link1">
        <inertial>
            <origin xyz="0 0.4081031392219798 -0.09351272747906836" rpy="0 0 0"/>
            <mass value="1" />
            <inertia ixx="100" ixy="0" ixz="0" iyy="100" iyz="0" izz="100" />
        </inertial>
        <visual>
            <origin xyz="0 0.4081031392219798 -0.09351272747906836" rpy="0 0 0"/>
            <geometry>
                <box size="0.2670485691586484 0.8162062784439597 0.18702545495813672" />
            </geometry>
            <material name="Blue">
                <color rgba="0 0.0 1.0 1.0"/>
            </material>
        </visual>
        <collision>
            <origin xyz="0 0.4081031392219798 -0.09351272747906836" rpy="0 0 0"/>
            <geometry>
                <box size="0.2670485691586484 0.8162062784439597 0.18702545495813672" />
            </geometry>
        </collision>
    </link>
    <joint name="Link1_Link2" type="revolute">
       <parent link="Link1"/>
       <child  link="Link2"/>
       <origin rpy="0 0 0" xyz="0 0.0 0.0" />
     <axis xyz="1 0 0"/>
       <limit effort="0.0" lower="-3.14159" upper="3.14159" velocity="0.0"/>
    </joint>
    <link name="Link2">
        <inertial>
            <origin xyz="0 -0.061140191018044354 -0.4204220103825034" rpy="0 0 0"/>
            <mass value="1" />
            <inertia ixx="100" ixy="0" ixz="0" iyy="100" iyz="0" izz="100" />
        </inertial>
        <visual>
            <origin xyz="0 -0.061140191018044354 -0.4204220103825034" rpy="0 0 0"/>
            <geometry>
                <box size="0.9948566208964469 0.12228038203608871 0.8408440207650067" />
            </geometry>
            <material name="Blue">
                <color rgba="0 0.0 1.0 1.0"/>
            </material>
        </visual>
        <collision>
            <origin xyz="0 -0.061140191018044354 -0.4204220103825034" rpy="0 0 0"/>
            <geometry>
                <box size="0.9948566208964469 0.12228038203608871 0.8408440207650067" />
            </geometry>
        </collision>
    </link>
    <joint name="Link2_Link3" type="revolute">
       <parent link="Link2"/>
       <child  link="Link3"/>
       <origin rpy="0 0 0" xyz="-0.49742831044822344 -0.061140191018044354 0.0" />
     <axis xyz="0 1 0"/>
       <limit effort="0.0" lower="-3.14159" upper="3.14159" velocity="0.0"/>
    </joint>
    <link name="Link3">
        <inertial>
            <origin xyz="-0.3327726287992061 0 -0.38702927107290463" rpy="0 0 0"/>
            <mass value="1" />
            <inertia ixx="100" ixy="0" ixz="0" iyy="100" iyz="0" izz="100" />
        </inertial>
        <visual>
            <origin xyz="-0.3327726287992061 0 -0.38702927107290463" rpy="0 0 0"/>
            <geometry>
                <box size="0.6655452575984122 0.9766327490481316 0.7740585421458093" />
            </geometry>
            <material name="Green">
                <color rgba="0 1.0 0.0 1.0"/>
            </material>
        </visual>
        <collision>
            <origin xyz="-0.3327726287992061 0 -0.38702927107290463" rpy="0 0 0"/>
            <geometry>
                <box size="0.6655452575984122 0.9766327490481316 0.7740585421458093" />
            </geometry>
        </collision>
    </link>
    <joint name="Link3_Link4" type="revolute">
       <parent link="Link3"/>
       <child  link="Link4"/>
       <origin rpy="0 0 0" xyz="-0.3327726287992061 -0.4883163745240658 0.0" />
     <axis xyz="1 0 0"/>
       <limit effort="0.0" lower="-3.14159" upper="3.14159" velocity="0.0"/>
    </joint>
    <link name="Link4">
        <inertial>
            <origin xyz="0 -0.07076750601344384 0.2770121131820607" rpy="0 0 0"/>
            <mass value="1" />
            <inertia ixx="100" ixy="0" ixz="0" iyy="100" iyz="0" izz="100" />
        </inertial>
        <visual>
            <origin xyz="0 -0.07076750601344384 0.2770121131820607" rpy="0 0 0"/>
            <geometry>
                <box size="0.08266738302227983 0.14153501202688767 0.5540242263641214" />
            </geometry>
            <material name="Green">
                <color rgba="0 1.0 0.0 1.0"/>
            </material>
        </visual>
        <collision>
            <origin xyz="0 -0.07076750601344384 0.2770121131820607" rpy="0 0 0"/>
            <geometry>
                <box size="0.08266738302227983 0.14153501202688767 0.5540242263641214" />
            </geometry>
        </collision>
    </link>
    <joint name="Link4_Link5" type="revolute">
       <parent link="Link4"/>
       <child  link="Link5"/>
       <origin rpy="0 0 0" xyz="0 -0.14153501202688767 0.5540242263641214" />
     <axis xyz="1 0 0"/>
       <limit effort="0.0" lower="-3.14159" upper="3.14159" velocity="0.0"/>
    </joint>
    <link name="Link5">
        <inertial>
            <origin xyz="0 -0.12468936723429114 0.1405077772229958" rpy="0 0 0"/>
            <mass value="1" />
            <inertia ixx="100" ixy="0" ixz="0" iyy="100" iyz="0" izz="100" />
        </inertial>
        <visual>
            <origin xyz="0 -0.12468936723429114 0.1405077772229958" rpy="0 0 0"/>
            <geometry>
                <box size="0.06373227504299295 0.24937873446858227 0.2810155544459916" />
            </geometry>
            <material name="Blue">
                <color rgba="0 0.0 1.0 1.0"/>
            </material>
        </visual>
        <collision>
            <origin xyz="0 -0.12468936723429114 0.1405077772229958" rpy="0 0 0"/>
            <geometry>
                <box size="0.06373227504299295 0.24937873446858227 0.2810155544459916" />
            </geometry>
        </collision>
    </link>
    <joint name="Link5_Link6" type="revolute">
       <parent link="Link5"/>
       <child  link="Link6"/>
       <origin rpy="0 0 0" xyz="-0.031866137521496474 -0.12468936723429114 0.2810155544459916" />
     <axis xyz="0 1 0"/>
       <limit effort="0.0" lower="-3.14159" upper="3.14159" velocity="0.0"/>
    </joint>
    <link name="Link6">
        <inertial>
            <origin xyz="-0.09479635022466687 0 -0.2553524725894463" rpy="0 0 0"/>
            <mass value="1" />
            <inertia ixx="100" ixy="0" ixz="0" iyy="100" iyz="0" izz="100" />
        </inertial>
        <visual>
            <origin xyz="-0.09479635022466687 0 -0.2553524725894463" rpy="0 0 0"/>
            <geometry>
                <box size="0.18959270044933374 0.4463119305955575 0.5107049451788926" />
            </geometry>
            <material name="Green">
                <color rgba="0 1.0 0.0 1.0"/>
            </material>
        </visual>
        <collision>
            <origin xyz="-0.09479635022466687 0 -0.2553524725894463" rpy="0 0 0"/>
            <geometry>
                <box size="0.18959270044933374 0.4463119305955575 0.5107049451788926" />
            </geometry>
        </collision>
    </link>
</robot>