<robot name = "robot">
    <link name="Link0">
        <inertial>
            <origin xyz="0 0 2.28902163491857" rpy="0 0 0"/>
            <mass value="1" />
            <inertia ixx="100" ixy="0" ixz="0" iyy="100" iyz="0" izz="100" />
        </inertial>
        <visual>
            <origin xyz="0 0 2.28902163491857" rpy="0 0 0"/>
            <geometry>
                <box size="0.21688797919064695 0.1344404756950941 0.5780432698371403" />
            </geometry>
            <material name="Green">
                <color rgba="0 1.0 0.0 1.0"/>
            </material>
        </visual>
        <collision>
            <origin xyz="0 0 2.28902163491857" rpy="0 0 0"/>
            <geometry>
                <box size="0.21688797919064695 0.1344404756950941 0.5780432698371403" />
            </geometry>
        </collision>
    </link>
    <joint name="Link0_Link1" type="revolute">
       <parent link="Link0"/>
       <child  link="Link1"/>
       <origin rpy="0 0 0" xyz="0 0.06722023784754705 2.5780432698371403" />
     <axis xyz="1 0 0"/>
       <limit effort="0.0" lower="-3.14159" upper="3.14159" velocity="0.0"/>
    </joint>
    <link name="Link1">
        <inertial>
            <origin xyz="0 0.06722023784754705 -0.28902163491857014" rpy="0 0 0"/>
            <mass value="1" />
            <inertia ixx="100" ixy="0" ixz="0" iyy="100" iyz="0" izz="100" />
        </inertial>
        <visual>
            <origin xyz="0 0.06722023784754705 -0.28902163491857014" rpy="0 0 0"/>
            <geometry>
                <box size="0.21688797919064695 0.1344404756950941 0.5780432698371403" />
            </geometry>
            <material name="Blue">
                <color rgba="0 0.0 1.0 1.0"/>
            </material>
        </visual>
        <collision>
            <origin xyz="0 0.06722023784754705 -0.28902163491857014" rpy="0 0 0"/>
            <geometry>
                <box size="0.21688797919064695 0.1344404756950941 0.5780432698371403" />
            </geometry>
        </collision>
    </link>
    <joint name="Link1_Link2" type="revolute">
       <parent link="Link1"/>
       <child  link="Link2"/>
       <origin rpy="0 0 0" xyz="-0.10844398959532348 0.06722023784754705 0.0" />
     <axis xyz="0 1 0"/>
       <limit effort="0.0" lower="-3.14159" upper="3.14159" velocity="0.0"/>
    </joint>
    <link name="Link2">
        <inertial>
            <origin xyz="-0.08541883343032491 0 0.3498485187430567" rpy="0 0 0"/>
            <mass value="1" />
            <inertia ixx="100" ixy="0" ixz="0" iyy="100" iyz="0" izz="100" />
        </inertial>
        <visual>
            <origin xyz="-0.08541883343032491 0 0.3498485187430567" rpy="0 0 0"/>
            <geometry>
                <box size="0.17083766686064983 0.771834525883359 0.6996970374861134" />
            </geometry>
            <material name="Green">
                <color rgba="0 1.0 0.0 1.0"/>
            </material>
        </visual>
        <collision>
            <origin xyz="-0.08541883343032491 0 0.3498485187430567" rpy="0 0 0"/>
            <geometry>
                <box size="0.17083766686064983 0.771834525883359 0.6996970374861134" />
            </geometry>
        </collision>
    </link>
    <joint name="Link2_Link3" type="revolute">
       <parent link="Link2"/>
       <child  link="Link3"/>
       <origin rpy="0 0 0" xyz="-0.17083766686064983 0 0.6996970374861134" />
     <axis xyz="0 1 0"/>
       <limit effort="0.0" lower="-3.14159" upper="3.14159" velocity="0.0"/>
    </joint>
    <link name="Link3">
        <inertial>
            <origin xyz="-0.18310115846368524 0 -0.41037057667672283" rpy="0 0 0"/>
            <mass value="1" />
            <inertia ixx="100" ixy="0" ixz="0" iyy="100" iyz="0" izz="100" />
        </inertial>
        <visual>
            <origin xyz="-0.18310115846368524 0 -0.41037057667672283" rpy="0 0 0"/>
            <geometry>
                <box size="0.3662023169273705 0.6592114207944781 0.8207411533534457" />
            </geometry>
            <material name="Blue">
                <color rgba="0 0.0 1.0 1.0"/>
            </material>
        </visual>
        <collision>
            <origin xyz="-0.18310115846368524 0 -0.41037057667672283" rpy="0 0 0"/>
            <geometry>
                <box size="0.3662023169273705 0.6592114207944781 0.8207411533534457" />
            </geometry>
        </collision>
    </link>
    <joint name="Link3_Link4" type="revolute">
       <parent link="Link3"/>
       <child  link="Link4"/>
       <origin rpy="0 0 0" xyz="-0.3662023169273705 0 0.0" />
     <axis xyz="0 1 0"/>
       <limit effort="0.0" lower="-3.14159" upper="3.14159" velocity="0.0"/>
    </joint>
    <link name="Link4">
        <inertial>
            <origin xyz="-0.3383882913657636 0 0.2873868015092216" rpy="0 0 0"/>
            <mass value="1" />
            <inertia ixx="100" ixy="0" ixz="0" iyy="100" iyz="0" izz="100" />
        </inertial>
        <visual>
            <origin xyz="-0.3383882913657636 0 0.2873868015092216" rpy="0 0 0"/>
            <geometry>
                <box size="0.6767765827315272 0.36128744646571365 0.5747736030184432" />
            </geometry>
            <material name="Green">
                <color rgba="0 1.0 0.0 1.0"/>
            </material>
        </visual>
        <collision>
            <origin xyz="-0.3383882913657636 0 0.2873868015092216" rpy="0 0 0"/>
            <geometry>
                <box size="0.6767765827315272 0.36128744646571365 0.5747736030184432" />
            </geometry>
        </collision>
    </link>
</robot>