<robot name = "robot">
    <link name="Link0">
        <inertial>
            <origin xyz="0 0 2.490463991688034" rpy="0 0 0"/>
            <mass value="1" />
            <inertia ixx="100" ixy="0" ixz="0" iyy="100" iyz="0" izz="100" />
        </inertial>
        <visual>
            <origin xyz="0 0 2.490463991688034" rpy="0 0 0"/>
            <geometry>
                <box size="0.629975911183454 0.6731535014044535 0.9809279833760685" />
            </geometry>
            <material name="Green">
                <color rgba="0 1.0 0.0 1.0"/>
            </material>
        </visual>
        <collision>
            <origin xyz="0 0 2.490463991688034" rpy="0 0 0"/>
            <geometry>
                <box size="0.629975911183454 0.6731535014044535 0.9809279833760685" />
            </geometry>
        </collision>
    </link>
    <joint name="Link0_Link1" type="revolute">
       <parent link="Link0"/>
       <child  link="Link1"/>
       <origin rpy="0 0 0" xyz="0 0.33657675070222676 2.9809279833760685" />
     <axis xyz="1 0 0"/>
       <limit effort="0.0" lower="-3.14159" upper="3.14159" velocity="0.0"/>
    </joint>
    <link name="Link1">
        <inertial>
            <origin xyz="0 0.33657675070222676 -0.49046399168803423" rpy="0 0 0"/>
            <mass value="1" />
            <inertia ixx="100" ixy="0" ixz="0" iyy="100" iyz="0" izz="100" />
        </inertial>
        <visual>
            <origin xyz="0 0.33657675070222676 -0.49046399168803423" rpy="0 0 0"/>
            <geometry>
                <box size="0.629975911183454 0.6731535014044535 0.9809279833760685" />
            </geometry>
            <material name="Blue">
                <color rgba="0 0.0 1.0 1.0"/>
            </material>
        </visual>
        <collision>
            <origin xyz="0 0.33657675070222676 -0.49046399168803423" rpy="0 0 0"/>
            <geometry>
                <box size="0.629975911183454 0.6731535014044535 0.9809279833760685" />
            </geometry>
        </collision>
    </link>
    <joint name="Link1_Link2" type="revolute">
       <parent link="Link1"/>
       <child  link="Link2"/>
       <origin rpy="0 0 0" xyz="0 0.6731535014044535 0.0" />
     <axis xyz="1 0 0"/>
       <limit effort="0.0" lower="-3.14159" upper="3.14159" velocity="0.0"/>
    </joint>
    <link name="Link2">
        <inertial>
            <origin xyz="0 0.49015896751960203 -0.4475779632813977" rpy="0 0 0"/>
            <mass value="1" />
            <inertia ixx="100" ixy="0" ixz="0" iyy="100" iyz="0" izz="100" />
        </inertial>
        <visual>
            <origin xyz="0 0.49015896751960203 -0.4475779632813977" rpy="0 0 0"/>
            <geometry>
                <box size="0.22108643960632912 0.9803179350392041 0.8951559265627954" />
            </geometry>
            <material name="Green">
                <color rgba="0 1.0 0.0 1.0"/>
            </material>
        </visual>
        <collision>
            <origin xyz="0 0.49015896751960203 -0.4475779632813977" rpy="0 0 0"/>
            <geometry>
                <box size="0.22108643960632912 0.9803179350392041 0.8951559265627954" />
            </geometry>
        </collision>
    </link>
    <joint name="Link2_Link3" type="revolute">
       <parent link="Link2"/>
       <child  link="Link3"/>
       <origin rpy="0 0 0" xyz="0 0.0 0.0" />
     <axis xyz="1 0 0"/>
       <limit effort="0.0" lower="-3.14159" upper="3.14159" velocity="0.0"/>
    </joint>
    <link name="Link3">
        <inertial>
            <origin xyz="0 -0.16334379456955556 -0.12145754476231657" rpy="0 0 0"/>
            <mass value="1" />
            <inertia ixx="100" ixy="0" ixz="0" iyy="100" iyz="0" izz="100" />
        </inertial>
        <visual>
            <origin xyz="0 -0.16334379456955556 -0.12145754476231657" rpy="0 0 0"/>
            <geometry>
                <box size="0.1951983506741678 0.3266875891391111 0.24291508952463314" />
            </geometry>
            <material name="Green">
                <color rgba="0 1.0 0.0 1.0"/>
            </material>
        </visual>
        <collision>
            <origin xyz="0 -0.16334379456955556 -0.12145754476231657" rpy="0 0 0"/>
            <geometry>
                <box size="0.1951983506741678 0.3266875891391111 0.24291508952463314" />
            </geometry>
        </collision>
    </link>
    <joint name="Link3_Link4" type="revolute">
       <parent link="Link3"/>
       <child  link="Link4"/>
       <origin rpy="0 0 0" xyz="0.0975991753370839 -0.16334379456955556 0.0" />
     <axis xyz="0 1 0"/>
       <limit effort="0.0" lower="-3.14159" upper="3.14159" velocity="0.0"/>
    </joint>
    <link name="Link4">
        <inertial>
            <origin xyz="0.34037291369128214 0 0.16685512586247114" rpy="0 0 0"/>
            <mass value="1" />
            <inertia ixx="100" ixy="0" ixz="0" iyy="100" iyz="0" izz="100" />
        </inertial>
        <visual>
            <origin xyz="0.34037291369128214 0 0.16685512586247114" rpy="0 0 0"/>
            <geometry>
                <box size="0.6807458273825643 0.6201469183214179 0.3337102517249423" />
            </geometry>
            <material name="Green">
                <color rgba="0 1.0 0.0 1.0"/>
            </material>
        </visual>
        <collision>
            <origin xyz="0.34037291369128214 0 0.16685512586247114" rpy="0 0 0"/>
            <geometry>
                <box size="0.6807458273825643 0.6201469183214179 0.3337102517249423" />
            </geometry>
        </collision>
    </link>
    <joint name="Link4_Link5" type="revolute">
       <parent link="Link4"/>
       <child  link="Link5"/>
       <origin rpy="0 0 0" xyz="0.6807458273825643 0 0.3337102517249423" />
     <axis xyz="0 1 0"/>
       <limit effort="0.0" lower="-3.14159" upper="3.14159" velocity="0.0"/>
    </joint>
    <link name="Link5">
        <inertial>
            <origin xyz="0.2887660643333867 0 0.424449859714" rpy="0 0 0"/>
            <mass value="1" />
            <inertia ixx="100" ixy="0" ixz="0" iyy="100" iyz="0" izz="100" />
        </inertial>
        <visual>
            <origin xyz="0.2887660643333867 0 0.424449859714" rpy="0 0 0"/>
            <geometry>
                <box size="0.5775321286667734 0.20662698202781515 0.848899719428" />
            </geometry>
            <material name="Blue">
                <color rgba="0 0.0 1.0 1.0"/>
            </material>
        </visual>
        <collision>
            <origin xyz="0.2887660643333867 0 0.424449859714" rpy="0 0 0"/>
            <geometry>
                <box size="0.5775321286667734 0.20662698202781515 0.848899719428" />
            </geometry>
        </collision>
    </link>
</robot>