<robot name = "robot">
    <link name="Link0">
        <inertial>
            <origin xyz="0 0 2.106838834676397" rpy="0 0 0"/>
            <mass value="1" />
            <inertia ixx="100" ixy="0" ixz="0" iyy="100" iyz="0" izz="100" />
        </inertial>
        <visual>
            <origin xyz="0 0 2.106838834676397" rpy="0 0 0"/>
            <geometry>
                <box size="0.821188662392965 0.27009084836156194 0.21367766935279453" />
            </geometry>
            <material name="Green">
                <color rgba="0 1.0 0.0 1.0"/>
            </material>
        </visual>
        <collision>
            <origin xyz="0 0 2.106838834676397" rpy="0 0 0"/>
            <geometry>
                <box size="0.821188662392965 0.27009084836156194 0.21367766935279453" />
            </geometry>
        </collision>
    </link>
    <joint name="Link0_Link1" type="revolute">
       <parent link="Link0"/>
       <child  link="Link1"/>
       <origin rpy="0 0 0" xyz="0 0.13504542418078097 2.2136776693527946" />
     <axis xyz="1 0 0"/>
       <limit effort="0.0" lower="-3.14159" upper="3.14159" velocity="0.0"/>
    </joint>
    <link name="Link1">
        <inertial>
            <origin xyz="0 0.13504542418078097 -0.10683883467639727" rpy="0 0 0"/>
            <mass value="1" />
            <inertia ixx="100" ixy="0" ixz="0" iyy="100" iyz="0" izz="100" />
        </inertial>
        <visual>
            <origin xyz="0 0.13504542418078097 -0.10683883467639727" rpy="0 0 0"/>
            <geometry>
                <box size="0.821188662392965 0.27009084836156194 0.21367766935279453" />
            </geometry>
            <material name="Blue">
                <color rgba="0 0.0 1.0 1.0"/>
            </material>
        </visual>
        <collision>
            <origin xyz="0 0.13504542418078097 -0.10683883467639727" rpy="0 0 0"/>
            <geometry>
                <box size="0.821188662392965 0.27009084836156194 0.21367766935279453" />
            </geometry>
        </collision>
    </link>
    <joint name="Link1_Link2" type="revolute">
       <parent link="Link1"/>
       <child  link="Link2"/>
       <origin rpy="0 0 0" xyz="-0.4105943311964825 0.13504542418078097 0.0" />
     <axis xyz="0 1 0"/>
       <limit effort="0.0" lower="-3.14159" upper="3.14159" velocity="0.0"/>
    </joint>
    <link name="Link2">
        <inertial>
            <origin xyz="-0.06055490227689375 0 0.140925541711314" rpy="0 0 0"/>
            <mass value="1" />
            <inertia ixx="100" ixy="0" ixz="0" iyy="100" iyz="0" izz="100" />
        </inertial>
        <visual>
            <origin xyz="-0.06055490227689375 0 0.140925541711314" rpy="0 0 0"/>
            <geometry>
                <box size="0.1211098045537875 0.06720337333914483 0.281851083422628" />
            </geometry>
            <material name="Green">
                <color rgba="0 1.0 0.0 1.0"/>
            </material>
        </visual>
        <collision>
            <origin xyz="-0.06055490227689375 0 0.140925541711314" rpy="0 0 0"/>
            <geometry>
                <box size="0.1211098045537875 0.06720337333914483 0.281851083422628" />
            </geometry>
        </collision>
    </link>
    <joint name="Link2_Link3" type="revolute">
       <parent link="Link2"/>
       <child  link="Link3"/>
       <origin rpy="0 0 0" xyz="0.0 0 0.281851083422628" />
     <axis xyz="0 1 0"/>
       <limit effort="0.0" lower="-3.14159" upper="3.14159" velocity="0.0"/>
    </joint>
    <link name="Link3">
        <inertial>
            <origin xyz="0.4458987004643012 0 0.4538270009531534" rpy="0 0 0"/>
            <mass value="1" />
            <inertia ixx="100" ixy="0" ixz="0" iyy="100" iyz="0" izz="100" />
        </inertial>
        <visual>
            <origin xyz="0.4458987004643012 0 0.4538270009531534" rpy="0 0 0"/>
            <geometry>
                <box size="0.8917974009286024 0.7038165338586652 0.9076540019063069" />
            </geometry>
            <material name="Green">
                <color rgba="0 1.0 0.0 1.0"/>
            </material>
        </visual>
        <collision>
            <origin xyz="0.4458987004643012 0 0.4538270009531534" rpy="0 0 0"/>
            <geometry>
                <box size="0.8917974009286024 0.7038165338586652 0.9076540019063069" />
            </geometry>
        </collision>
    </link>
    <joint name="Link3_Link4" type="revolute">
       <parent link="Link3"/>
       <child  link="Link4"/>
       <origin rpy="0 0 0" xyz="0.8917974009286024 0 0.9076540019063069" />
     <axis xyz="0 1 0"/>
       <limit effort="0.0" lower="-3.14159" upper="3.14159" velocity="0.0"/>
    </joint>
    <link name="Link4">
        <inertial>
            <origin xyz="0.08751387059145876 0 0.13537225145071502" rpy="0 0 0"/>
            <mass value="1" />
            <inertia ixx="100" ixy="0" ixz="0" iyy="100" iyz="0" izz="100" />
        </inertial>
        <visual>
            <origin xyz="0.08751387059145876 0 0.13537225145071502" rpy="0 0 0"/>
            <geometry>
                <box size="0.17502774118291753 0.8286622343702841 0.27074450290143004" />
            </geometry>
            <material name="Green">
                <color rgba="0 1.0 0.0 1.0"/>
            </material>
        </visual>
        <collision>
            <origin xyz="0.08751387059145876 0 0.13537225145071502" rpy="0 0 0"/>
            <geometry>
                <box size="0.17502774118291753 0.8286622343702841 0.27074450290143004" />
            </geometry>
        </collision>
    </link>
    <joint name="Link4_Link5" type="revolute">
       <parent link="Link4"/>
       <child  link="Link5"/>
       <origin rpy="0 0 0" xyz="0.17502774118291753 0 0.27074450290143004" />
     <axis xyz="0 1 0"/>
       <limit effort="0.0" lower="-3.14159" upper="3.14159" velocity="0.0"/>
    </joint>
    <link name="Link5">
        <inertial>
            <origin xyz="0.03131003690273554 0 -0.02460550629155578" rpy="0 0 0"/>
            <mass value="1" />
            <inertia ixx="100" ixy="0" ixz="0" iyy="100" iyz="0" izz="100" />
        </inertial>
        <visual>
            <origin xyz="0.03131003690273554 0 -0.02460550629155578" rpy="0 0 0"/>
            <geometry>
                <box size="0.06262007380547108 0.14526030328894257 0.04921101258311156" />
            </geometry>
            <material name="Green">
                <color rgba="0 1.0 0.0 1.0"/>
            </material>
        </visual>
        <collision>
            <origin xyz="0.03131003690273554 0 -0.02460550629155578" rpy="0 0 0"/>
            <geometry>
                <box size="0.06262007380547108 0.14526030328894257 0.04921101258311156" />
            </geometry>
        </collision>
    </link>
</robot>