<robot name = "robot">
    <link name="Link0">
        <inertial>
            <origin xyz="0 0 2.2153684341626914" rpy="0 0 0"/>
            <mass value="1" />
            <inertia ixx="100" ixy="0" ixz="0" iyy="100" iyz="0" izz="100" />
        </inertial>
        <visual>
            <origin xyz="0 0 2.2153684341626914" rpy="0 0 0"/>
            <geometry>
                <box size="0.4728622492254546 0.24365855658989766 0.4307368683253826" />
            </geometry>
            <material name="Green">
                <color rgba="0 1.0 0.0 1.0"/>
            </material>
        </visual>
        <collision>
            <origin xyz="0 0 2.2153684341626914" rpy="0 0 0"/>
            <geometry>
                <box size="0.4728622492254546 0.24365855658989766 0.4307368683253826" />
            </geometry>
        </collision>
    </link>
    <joint name="Link0_Link1" type="revolute">
       <parent link="Link0"/>
       <child  link="Link1"/>
       <origin rpy="0 0 0" xyz="0 0.12182927829494883 2.4307368683253827" />
     <axis xyz="1 0 0"/>
       <limit effort="0.0" lower="-3.14159" upper="3.14159" velocity="0.0"/>
    </joint>
    <link name="Link1">
        <inertial>
            <origin xyz="0 0.12182927829494883 -0.2153684341626913" rpy="0 0 0"/>
            <mass value="1" />
            <inertia ixx="100" ixy="0" ixz="0" iyy="100" iyz="0" izz="100" />
        </inertial>
        <visual>
            <origin xyz="0 0.12182927829494883 -0.2153684341626913" rpy="0 0 0"/>
            <geometry>
                <box size="0.4728622492254546 0.24365855658989766 0.4307368683253826" />
            </geometry>
            <material name="Green">
                <color rgba="0 1.0 0.0 1.0"/>
            </material>
        </visual>
        <collision>
            <origin xyz="0 0.12182927829494883 -0.2153684341626913" rpy="0 0 0"/>
            <geometry>
                <box size="0.4728622492254546 0.24365855658989766 0.4307368683253826" />
            </geometry>
        </collision>
    </link>
    <joint name="Link1_Link2" type="revolute">
       <parent link="Link1"/>
       <child  link="Link2"/>
       <origin rpy="0 0 0" xyz="0 0.0 0.0" />
     <axis xyz="1 0 0"/>
       <limit effort="0.0" lower="-3.14159" upper="3.14159" velocity="0.0"/>
    </joint>
    <link name="Link2">
        <inertial>
            <origin xyz="0 -0.09825369411688939 -0.3711399531539622" rpy="0 0 0"/>
            <mass value="1" />
            <inertia ixx="100" ixy="0" ixz="0" iyy="100" iyz="0" izz="100" />
        </inertial>
        <visual>
            <origin xyz="0 -0.09825369411688939 -0.3711399531539622" rpy="0 0 0"/>
            <geometry>
                <box size="0.6148375865930088 0.19650738823377878 0.7422799063079244" />
            </geometry>
            <material name="Blue">
                <color rgba="0 0.0 1.0 1.0"/>
            </material>
        </visual>
        <collision>
            <origin xyz="0 -0.09825369411688939 -0.3711399531539622" rpy="0 0 0"/>
            <geometry>
                <box size="0.6148375865930088 0.19650738823377878 0.7422799063079244" />
            </geometry>
        </collision>
    </link>
    <joint name="Link2_Link3" type="revolute">
       <parent link="Link2"/>
       <child  link="Link3"/>
       <origin rpy="0 0 0" xyz="-0.3074187932965044 -0.09825369411688939 0.0" />
     <axis xyz="0 1 0"/>
       <limit effort="0.0" lower="-3.14159" upper="3.14159" velocity="0.0"/>
    </joint>
    <link name="Link3">
        <inertial>
            <origin xyz="-0.1929415440214508 0 0.06966697303929148" rpy="0 0 0"/>
            <mass value="1" />
            <inertia ixx="100" ixy="0" ixz="0" iyy="100" iyz="0" izz="100" />
        </inertial>
        <visual>
            <origin xyz="-0.1929415440214508 0 0.06966697303929148" rpy="0 0 0"/>
            <geometry>
                <box size="0.3858830880429016 0.8895902667675538 0.13933394607858296" />
            </geometry>
            <material name="Green">
                <color rgba="0 1.0 0.0 1.0"/>
            </material>
        </visual>
        <collision>
            <origin xyz="-0.1929415440214508 0 0.06966697303929148" rpy="0 0 0"/>
            <geometry>
                <box size="0.3858830880429016 0.8895902667675538 0.13933394607858296" />
            </geometry>
        </collision>
    </link>
    <joint name="Link3_Link4" type="revolute">
       <parent link="Link3"/>
       <child  link="Link4"/>
       <origin rpy="0 0 0" xyz="-0.3858830880429016 0 0.13933394607858296" />
     <axis xyz="0 1 0"/>
       <limit effort="0.0" lower="-3.14159" upper="3.14159" velocity="0.0"/>
    </joint>
    <link name="Link4">
        <inertial>
            <origin xyz="-0.03614885510050647 0 -0.27024234198655617" rpy="0 0 0"/>
            <mass value="1" />
            <inertia ixx="100" ixy="0" ixz="0" iyy="100" iyz="0" izz="100" />
        </inertial>
        <visual>
            <origin xyz="-0.03614885510050647 0 -0.27024234198655617" rpy="0 0 0"/>
            <geometry>
                <box size="0.07229771020101294 0.28765175851734714 0.5404846839731123" />
            </geometry>
            <material name="Blue">
                <color rgba="0 0.0 1.0 1.0"/>
            </material>
        </visual>
        <collision>
            <origin xyz="-0.03614885510050647 0 -0.27024234198655617" rpy="0 0 0"/>
            <geometry>
                <box size="0.07229771020101294 0.28765175851734714 0.5404846839731123" />
            </geometry>
        </collision>
    </link>
    <joint name="Link4_Link5" type="revolute">
       <parent link="Link4"/>
       <child  link="Link5"/>
       <origin rpy="0 0 0" xyz="-0.03614885510050647 -0.14382587925867357 0.0" />
     <axis xyz="1 0 0"/>
       <limit effort="0.0" lower="-3.14159" upper="3.14159" velocity="0.0"/>
    </joint>
    <link name="Link5">
        <inertial>
            <origin xyz="0 -0.0307209528881221 0.3900877420435967" rpy="0 0 0"/>
            <mass value="1" />
            <inertia ixx="100" ixy="0" ixz="0" iyy="100" iyz="0" izz="100" />
        </inertial>
        <visual>
            <origin xyz="0 -0.0307209528881221 0.3900877420435967" rpy="0 0 0"/>
            <geometry>
                <box size="0.4325977321389912 0.0614419057762442 0.7801754840871934" />
            </geometry>
            <material name="Green">
                <color rgba="0 1.0 0.0 1.0"/>
            </material>
        </visual>
        <collision>
            <origin xyz="0 -0.0307209528881221 0.3900877420435967" rpy="0 0 0"/>
            <geometry>
                <box size="0.4325977321389912 0.0614419057762442 0.7801754840871934" />
            </geometry>
        </collision>
    </link>
    <joint name="Link5_Link6" type="revolute">
       <parent link="Link5"/>
       <child  link="Link6"/>
       <origin rpy="0 0 0" xyz="0 0.0 0.7801754840871934" />
     <axis xyz="1 0 0"/>
       <limit effort="0.0" lower="-3.14159" upper="3.14159" velocity="0.0"/>
    </joint>
    <link name="Link6">
        <inertial>
            <origin xyz="0 0.06245304918831024 -0.04150668202808244" rpy="0 0 0"/>
            <mass value="1" />
            <inertia ixx="100" ixy="0" ixz="0" iyy="100" iyz="0" izz="100" />
        </inertial>
        <visual>
            <origin xyz="0 0.06245304918831024 -0.04150668202808244" rpy="0 0 0"/>
            <geometry>
                <box size="0.9744229107035745 0.12490609837662048 0.08301336405616488" />
            </geometry>
            <material name="Blue">
                <color rgba="0 0.0 1.0 1.0"/>
            </material>
        </visual>
        <collision>
            <origin xyz="0 0.06245304918831024 -0.04150668202808244" rpy="0 0 0"/>
            <geometry>
                <box size="0.9744229107035745 0.12490609837662048 0.08301336405616488" />
            </geometry>
        </collision>
    </link>
</robot>