<robot name = "robot">
    <link name="Link0">
        <inertial>
            <origin xyz="0 0 2.425594008471652" rpy="0 0 0"/>
            <mass value="1" />
            <inertia ixx="100" ixy="0" ixz="0" iyy="100" iyz="0" izz="100" />
        </inertial>
        <visual>
            <origin xyz="0 0 2.425594008471652" rpy="0 0 0"/>
            <geometry>
                <box size="0.39150725812576415 0.4532883558573274 0.8511880169433038" />
            </geometry>
            <material name="Green">
                <color rgba="0 1.0 0.0 1.0"/>
            </material>
        </visual>
        <collision>
            <origin xyz="0 0 2.425594008471652" rpy="0 0 0"/>
            <geometry>
                <box size="0.39150725812576415 0.4532883558573274 0.8511880169433038" />
            </geometry>
        </collision>
    </link>
    <joint name="Link0_Link1" type="revolute">
       <parent link="Link0"/>
       <child  link="Link1"/>
       <origin rpy="0 0 0" xyz="0 0.2266441779286637 2.8511880169433037" />
     <axis xyz="1 0 0"/>
       <limit effort="0.0" lower="-3.14159" upper="3.14159" velocity="0.0"/>
    </joint>
    <link name="Link1">
        <inertial>
            <origin xyz="0 0.2266441779286637 -0.4255940084716519" rpy="0 0 0"/>
            <mass value="1" />
            <inertia ixx="100" ixy="0" ixz="0" iyy="100" iyz="0" izz="100" />
        </inertial>
        <visual>
            <origin xyz="0 0.2266441779286637 -0.4255940084716519" rpy="0 0 0"/>
            <geometry>
                <box size="0.39150725812576415 0.4532883558573274 0.8511880169433038" />
            </geometry>
            <material name="Blue">
                <color rgba="0 0.0 1.0 1.0"/>
            </material>
        </visual>
        <collision>
            <origin xyz="0 0.2266441779286637 -0.4255940084716519" rpy="0 0 0"/>
            <geometry>
                <box size="0.39150725812576415 0.4532883558573274 0.8511880169433038" />
            </geometry>
        </collision>
    </link>
    <joint name="Link1_Link2" type="revolute">
       <parent link="Link1"/>
       <child  link="Link2"/>
       <origin rpy="0 0 0" xyz="0.19575362906288207 0.2266441779286637 0.0" />
     <axis xyz="0 1 0"/>
       <limit effort="0.0" lower="-3.14159" upper="3.14159" velocity="0.0"/>
    </joint>
    <link name="Link2">
        <inertial>
            <origin xyz="0.09872269254102789 0 -0.1579221483568236" rpy="0 0 0"/>
            <mass value="1" />
            <inertia ixx="100" ixy="0" ixz="0" iyy="100" iyz="0" izz="100" />
        </inertial>
        <visual>
            <origin xyz="0.09872269254102789 0 -0.1579221483568236" rpy="0 0 0"/>
            <geometry>
                <box size="0.19744538508205578 0.8203133464155025 0.3158442967136472" />
            </geometry>
            <material name="Green">
                <color rgba="0 1.0 0.0 1.0"/>
            </material>
        </visual>
        <collision>
            <origin xyz="0.09872269254102789 0 -0.1579221483568236" rpy="0 0 0"/>
            <geometry>
                <box size="0.19744538508205578 0.8203133464155025 0.3158442967136472" />
            </geometry>
        </collision>
    </link>
    <joint name="Link2_Link3" type="revolute">
       <parent link="Link2"/>
       <child  link="Link3"/>
       <origin rpy="0 0 0" xyz="0.19744538508205578 0 0.0" />
     <axis xyz="0 1 0"/>
       <limit effort="0.0" lower="-3.14159" upper="3.14159" velocity="0.0"/>
    </joint>
    <link name="Link3">
        <inertial>
            <origin xyz="0.22673280784468847 0 -0.38817692727659886" rpy="0 0 0"/>
            <mass value="1" />
            <inertia ixx="100" ixy="0" ixz="0" iyy="100" iyz="0" izz="100" />
        </inertial>
        <visual>
            <origin xyz="0.22673280784468847 0 -0.38817692727659886" rpy="0 0 0"/>
            <geometry>
                <box size="0.45346561568937693 0.3009951498637856 0.7763538545531977" />
            </geometry>
            <material name="Blue">
                <color rgba="0 0.0 1.0 1.0"/>
            </material>
        </visual>
        <collision>
            <origin xyz="0.22673280784468847 0 -0.38817692727659886" rpy="0 0 0"/>
            <geometry>
                <box size="0.45346561568937693 0.3009951498637856 0.7763538545531977" />
            </geometry>
        </collision>
    </link>
    <joint name="Link3_Link4" type="revolute">
       <parent link="Link3"/>
       <child  link="Link4"/>
       <origin rpy="0 0 0" xyz="0.22673280784468847 0.1504975749318928 0.0" />
     <axis xyz="1 0 0"/>
       <limit effort="0.0" lower="-3.14159" upper="3.14159" velocity="0.0"/>
    </joint>
    <link name="Link4">
        <inertial>
            <origin xyz="0 0.1599543739416197 0.44424225756598407" rpy="0 0 0"/>
            <mass value="1" />
            <inertia ixx="100" ixy="0" ixz="0" iyy="100" iyz="0" izz="100" />
        </inertial>
        <visual>
            <origin xyz="0 0.1599543739416197 0.44424225756598407" rpy="0 0 0"/>
            <geometry>
                <box size="0.5273928135682361 0.3199087478832394 0.8884845151319681" />
            </geometry>
            <material name="Blue">
                <color rgba="0 0.0 1.0 1.0"/>
            </material>
        </visual>
        <collision>
            <origin xyz="0 0.1599543739416197 0.44424225756598407" rpy="0 0 0"/>
            <geometry>
                <box size="0.5273928135682361 0.3199087478832394 0.8884845151319681" />
            </geometry>
        </collision>
    </link>
    <joint name="Link4_Link5" type="revolute">
       <parent link="Link4"/>
       <child  link="Link5"/>
       <origin rpy="0 0 0" xyz="0 0.0 0.8884845151319681" />
     <axis xyz="1 0 0"/>
       <limit effort="0.0" lower="-3.14159" upper="3.14159" velocity="0.0"/>
    </joint>
    <link name="Link5">
        <inertial>
            <origin xyz="0 -0.28862844660991177 -0.002190507088296989" rpy="0 0 0"/>
            <mass value="1" />
            <inertia ixx="100" ixy="0" ixz="0" iyy="100" iyz="0" izz="100" />
        </inertial>
        <visual>
            <origin xyz="0 -0.28862844660991177 -0.002190507088296989" rpy="0 0 0"/>
            <geometry>
                <box size="0.9208760465910438 0.5772568932198235 0.004381014176593978" />
            </geometry>
            <material name="Green">
                <color rgba="0 1.0 0.0 1.0"/>
            </material>
        </visual>
        <collision>
            <origin xyz="0 -0.28862844660991177 -0.002190507088296989" rpy="0 0 0"/>
            <geometry>
                <box size="0.9208760465910438 0.5772568932198235 0.004381014176593978" />
            </geometry>
        </collision>
    </link>
</robot>