<robot name = "robot">
    <link name="Link0">
        <inertial>
            <origin xyz="0 0 2.113591986900637" rpy="0 0 0"/>
            <mass value="1" />
            <inertia ixx="100" ixy="0" ixz="0" iyy="100" iyz="0" izz="100" />
        </inertial>
        <visual>
            <origin xyz="0 0 2.113591986900637" rpy="0 0 0"/>
            <geometry>
                <box size="0.23618404208308685 0.4236978616090724 0.22718397380127464" />
            </geometry>
            <material name="Green">
                <color rgba="0 1.0 0.0 1.0"/>
            </material>
        </visual>
        <collision>
            <origin xyz="0 0 2.113591986900637" rpy="0 0 0"/>
            <geometry>
                <box size="0.23618404208308685 0.4236978616090724 0.22718397380127464" />
            </geometry>
        </collision>
    </link>
    <joint name="Link0_Link1" type="revolute">
       <parent link="Link0"/>
       <child  link="Link1"/>
       <origin rpy="0 0 0" xyz="0 0.2118489308045362 2.2271839738012744" />
     <axis xyz="1 0 0"/>
       <limit effort="0.0" lower="-3.14159" upper="3.14159" velocity="0.0"/>
    </joint>
    <link name="Link1">
        <inertial>
            <origin xyz="0 0.2118489308045362 -0.11359198690063732" rpy="0 0 0"/>
            <mass value="1" />
            <inertia ixx="100" ixy="0" ixz="0" iyy="100" iyz="0" izz="100" />
        </inertial>
        <visual>
            <origin xyz="0 0.2118489308045362 -0.11359198690063732" rpy="0 0 0"/>
            <geometry>
                <box size="0.23618404208308685 0.4236978616090724 0.22718397380127464" />
            </geometry>
            <material name="Green">
                <color rgba="0 1.0 0.0 1.0"/>
            </material>
        </visual>
        <collision>
            <origin xyz="0 0.2118489308045362 -0.11359198690063732" rpy="0 0 0"/>
            <geometry>
                <box size="0.23618404208308685 0.4236978616090724 0.22718397380127464" />
            </geometry>
        </collision>
    </link>
    <joint name="Link1_Link2" type="revolute">
       <parent link="Link1"/>
       <child  link="Link2"/>
       <origin rpy="0 0 0" xyz="0 0.4236978616090724 0.0" />
     <axis xyz="1 0 0"/>
       <limit effort="0.0" lower="-3.14159" upper="3.14159" velocity="0.0"/>
    </joint>
    <link name="Link2">
        <inertial>
            <origin xyz="0 0.24632020494907964 0.4288526861348705" rpy="0 0 0"/>
            <mass value="1" />
            <inertia ixx="100" ixy="0" ixz="0" iyy="100" iyz="0" izz="100" />
        </inertial>
        <visual>
            <origin xyz="0 0.24632020494907964 0.4288526861348705" rpy="0 0 0"/>
            <geometry>
                <box size="0.7446689965349315 0.49264040989815927 0.857705372269741" />
            </geometry>
            <material name="Green">
                <color rgba="0 1.0 0.0 1.0"/>
            </material>
        </visual>
        <collision>
            <origin xyz="0 0.24632020494907964 0.4288526861348705" rpy="0 0 0"/>
            <geometry>
                <box size="0.7446689965349315 0.49264040989815927 0.857705372269741" />
            </geometry>
        </collision>
    </link>
    <joint name="Link2_Link3" type="revolute">
       <parent link="Link2"/>
       <child  link="Link3"/>
       <origin rpy="0 0 0" xyz="0.37233449826746573 0.24632020494907964 0.857705372269741" />
     <axis xyz="0 1 0"/>
       <limit effort="0.0" lower="-3.14159" upper="3.14159" velocity="0.0"/>
    </joint>
    <link name="Link3">
        <inertial>
            <origin xyz="0.3318375501453078 0 0.19142387396870758" rpy="0 0 0"/>
            <mass value="1" />
            <inertia ixx="100" ixy="0" ixz="0" iyy="100" iyz="0" izz="100" />
        </inertial>
        <visual>
            <origin xyz="0.3318375501453078 0 0.19142387396870758" rpy="0 0 0"/>
            <geometry>
                <box size="0.6636751002906156 0.6652262662253519 0.38284774793741516" />
            </geometry>
            <material name="Green">
                <color rgba="0 1.0 0.0 1.0"/>
            </material>
        </visual>
        <collision>
            <origin xyz="0.3318375501453078 0 0.19142387396870758" rpy="0 0 0"/>
            <geometry>
                <box size="0.6636751002906156 0.6652262662253519 0.38284774793741516" />
            </geometry>
        </collision>
    </link>
    <joint name="Link3_Link4" type="revolute">
       <parent link="Link3"/>
       <child  link="Link4"/>
       <origin rpy="0 0 0" xyz="0.3318375501453078 -0.33261313311267593 0.38284774793741516" />
     <axis xyz="1 0 0"/>
       <limit effort="0.0" lower="-3.14159" upper="3.14159" velocity="0.0"/>
    </joint>
    <link name="Link4">
        <inertial>
            <origin xyz="0 -0.13102942435954779 -0.1861863032435302" rpy="0 0 0"/>
            <mass value="1" />
            <inertia ixx="100" ixy="0" ixz="0" iyy="100" iyz="0" izz="100" />
        </inertial>
        <visual>
            <origin xyz="0 -0.13102942435954779 -0.1861863032435302" rpy="0 0 0"/>
            <geometry>
                <box size="0.4918237229016955 0.26205884871909557 0.3723726064870604" />
            </geometry>
            <material name="Blue">
                <color rgba="0 0.0 1.0 1.0"/>
            </material>
        </visual>
        <collision>
            <origin xyz="0 -0.13102942435954779 -0.1861863032435302" rpy="0 0 0"/>
            <geometry>
                <box size="0.4918237229016955 0.26205884871909557 0.3723726064870604" />
            </geometry>
        </collision>
    </link>
    <joint name="Link4_Link5" type="revolute">
       <parent link="Link4"/>
       <child  link="Link5"/>
       <origin rpy="0 0 0" xyz="-0.24591186145084776 -0.13102942435954779 0.0" />
     <axis xyz="0 1 0"/>
       <limit effort="0.0" lower="-3.14159" upper="3.14159" velocity="0.0"/>
    </joint>
    <link name="Link5">
        <inertial>
            <origin xyz="-0.23725418917566282 0 0.4120992818909775" rpy="0 0 0"/>
            <mass value="1" />
            <inertia ixx="100" ixy="0" ixz="0" iyy="100" iyz="0" izz="100" />
        </inertial>
        <visual>
            <origin xyz="-0.23725418917566282 0 0.4120992818909775" rpy="0 0 0"/>
            <geometry>
                <box size="0.47450837835132564 0.33085954845536303 0.824198563781955" />
            </geometry>
            <material name="Blue">
                <color rgba="0 0.0 1.0 1.0"/>
            </material>
        </visual>
        <collision>
            <origin xyz="-0.23725418917566282 0 0.4120992818909775" rpy="0 0 0"/>
            <geometry>
                <box size="0.47450837835132564 0.33085954845536303 0.824198563781955" />
            </geometry>
        </collision>
    </link>
    <joint name="Link5_Link6" type="revolute">
       <parent link="Link5"/>
       <child  link="Link6"/>
       <origin rpy="0 0 0" xyz="-0.23725418917566282 0.16542977422768151 0.824198563781955" />
     <axis xyz="1 0 0"/>
       <limit effort="0.0" lower="-3.14159" upper="3.14159" velocity="0.0"/>
    </joint>
    <link name="Link6">
        <inertial>
            <origin xyz="0 0.11814993192434747 -0.2874817722438595" rpy="0 0 0"/>
            <mass value="1" />
            <inertia ixx="100" ixy="0" ixz="0" iyy="100" iyz="0" izz="100" />
        </inertial>
        <visual>
            <origin xyz="0 0.11814993192434747 -0.2874817722438595" rpy="0 0 0"/>
            <geometry>
                <box size="0.5297042255333853 0.23629986384869495 0.574963544487719" />
            </geometry>
            <material name="Green">
                <color rgba="0 1.0 0.0 1.0"/>
            </material>
        </visual>
        <collision>
            <origin xyz="0 0.11814993192434747 -0.2874817722438595" rpy="0 0 0"/>
            <geometry>
                <box size="0.5297042255333853 0.23629986384869495 0.574963544487719" />
            </geometry>
        </collision>
    </link>
</robot>