<robot name = "robot">
    <link name="Link0">
        <inertial>
            <origin xyz="0 0 2.1034131806776926" rpy="0 0 0"/>
            <mass value="1" />
            <inertia ixx="100" ixy="0" ixz="0" iyy="100" iyz="0" izz="100" />
        </inertial>
        <visual>
            <origin xyz="0 0 2.1034131806776926" rpy="0 0 0"/>
            <geometry>
                <box size="0.8838315450256236 0.3069819447052261 0.2068263613553849" />
            </geometry>
            <material name="Green">
                <color rgba="0 1.0 0.0 1.0"/>
            </material>
        </visual>
        <collision>
            <origin xyz="0 0 2.1034131806776926" rpy="0 0 0"/>
            <geometry>
                <box size="0.8838315450256236 0.3069819447052261 0.2068263613553849" />
            </geometry>
        </collision>
    </link>
    <joint name="Link0_Link1" type="revolute">
       <parent link="Link0"/>
       <child  link="Link1"/>
       <origin rpy="0 0 0" xyz="0 0.15349097235261305 2.206826361355385" />
     <axis xyz="1 0 0"/>
       <limit effort="0.0" lower="-3.14159" upper="3.14159" velocity="0.0"/>
    </joint>
    <link name="Link1">
        <inertial>
            <origin xyz="0 0.15349097235261305 -0.10341318067769245" rpy="0 0 0"/>
            <mass value="1" />
            <inertia ixx="100" ixy="0" ixz="0" iyy="100" iyz="0" izz="100" />
        </inertial>
        <visual>
            <origin xyz="0 0.15349097235261305 -0.10341318067769245" rpy="0 0 0"/>
            <geometry>
                <box size="0.8838315450256236 0.3069819447052261 0.2068263613553849" />
            </geometry>
            <material name="Blue">
                <color rgba="0 0.0 1.0 1.0"/>
            </material>
        </visual>
        <collision>
            <origin xyz="0 0.15349097235261305 -0.10341318067769245" rpy="0 0 0"/>
            <geometry>
                <box size="0.8838315450256236 0.3069819447052261 0.2068263613553849" />
            </geometry>
        </collision>
    </link>
    <joint name="Link1_Link2" type="revolute">
       <parent link="Link1"/>
       <child  link="Link2"/>
       <origin rpy="0 0 0" xyz="0 0.0 0.0" />
     <axis xyz="1 0 0"/>
       <limit effort="0.0" lower="-3.14159" upper="3.14159" velocity="0.0"/>
    </joint>
    <link name="Link2">
        <inertial>
            <origin xyz="0 -0.008451599214029937 0.44048703673722306" rpy="0 0 0"/>
            <mass value="1" />
            <inertia ixx="100" ixy="0" ixz="0" iyy="100" iyz="0" izz="100" />
        </inertial>
        <visual>
            <origin xyz="0 -0.008451599214029937 0.44048703673722306" rpy="0 0 0"/>
            <geometry>
                <box size="0.19266440888898162 0.016903198428059873 0.8809740734744461" />
            </geometry>
            <material name="Green">
                <color rgba="0 1.0 0.0 1.0"/>
            </material>
        </visual>
        <collision>
            <origin xyz="0 -0.008451599214029937 0.44048703673722306" rpy="0 0 0"/>
            <geometry>
                <box size="0.19266440888898162 0.016903198428059873 0.8809740734744461" />
            </geometry>
        </collision>
    </link>
    <joint name="Link2_Link3" type="revolute">
       <parent link="Link2"/>
       <child  link="Link3"/>
       <origin rpy="0 0 0" xyz="-0.09633220444449081 -0.008451599214029937 0.8809740734744461" />
     <axis xyz="0 1 0"/>
       <limit effort="0.0" lower="-3.14159" upper="3.14159" velocity="0.0"/>
    </joint>
    <link name="Link3">
        <inertial>
            <origin xyz="-0.4726159912633174 0 -0.2614682058129141" rpy="0 0 0"/>
            <mass value="1" />
            <inertia ixx="100" ixy="0" ixz="0" iyy="100" iyz="0" izz="100" />
        </inertial>
        <visual>
            <origin xyz="-0.4726159912633174 0 -0.2614682058129141" rpy="0 0 0"/>
            <geometry>
                <box size="0.9452319825266348 0.6714285674692383 0.5229364116258282" />
            </geometry>
            <material name="Green">
                <color rgba="0 1.0 0.0 1.0"/>
            </material>
        </visual>
        <collision>
            <origin xyz="-0.4726159912633174 0 -0.2614682058129141" rpy="0 0 0"/>
            <geometry>
                <box size="0.9452319825266348 0.6714285674692383 0.5229364116258282" />
            </geometry>
        </collision>
    </link>
    <joint name="Link3_Link4" type="revolute">
       <parent link="Link3"/>
       <child  link="Link4"/>
       <origin rpy="0 0 0" xyz="-0.9452319825266348 0 0.0" />
     <axis xyz="0 1 0"/>
       <limit effort="0.0" lower="-3.14159" upper="3.14159" velocity="0.0"/>
    </joint>
    <link name="Link4">
        <inertial>
            <origin xyz="-0.12347909540589008 0 0.1930974967272619" rpy="0 0 0"/>
            <mass value="1" />
            <inertia ixx="100" ixy="0" ixz="0" iyy="100" iyz="0" izz="100" />
        </inertial>
        <visual>
            <origin xyz="-0.12347909540589008 0 0.1930974967272619" rpy="0 0 0"/>
            <geometry>
                <box size="0.24695819081178016 0.2941504506582072 0.3861949934545238" />
            </geometry>
            <material name="Blue">
                <color rgba="0 0.0 1.0 1.0"/>
            </material>
        </visual>
        <collision>
            <origin xyz="-0.12347909540589008 0 0.1930974967272619" rpy="0 0 0"/>
            <geometry>
                <box size="0.24695819081178016 0.2941504506582072 0.3861949934545238" />
            </geometry>
        </collision>
    </link>
    <joint name="Link4_Link5" type="revolute">
       <parent link="Link4"/>
       <child  link="Link5"/>
       <origin rpy="0 0 0" xyz="0.0 0 0.3861949934545238" />
     <axis xyz="0 1 0"/>
       <limit effort="0.0" lower="-3.14159" upper="3.14159" velocity="0.0"/>
    </joint>
    <link name="Link5">
        <inertial>
            <origin xyz="0.44550175942155296 0 0.30063603524268234" rpy="0 0 0"/>
            <mass value="1" />
            <inertia ixx="100" ixy="0" ixz="0" iyy="100" iyz="0" izz="100" />
        </inertial>
        <visual>
            <origin xyz="0.44550175942155296 0 0.30063603524268234" rpy="0 0 0"/>
            <geometry>
                <box size="0.8910035188431059 0.4286742410236841 0.6012720704853647" />
            </geometry>
            <material name="Blue">
                <color rgba="0 0.0 1.0 1.0"/>
            </material>
        </visual>
        <collision>
            <origin xyz="0.44550175942155296 0 0.30063603524268234" rpy="0 0 0"/>
            <geometry>
                <box size="0.8910035188431059 0.4286742410236841 0.6012720704853647" />
            </geometry>
        </collision>
    </link>
    <joint name="Link5_Link6" type="revolute">
       <parent link="Link5"/>
       <child  link="Link6"/>
       <origin rpy="0 0 0" xyz="0.0 0 0.6012720704853647" />
     <axis xyz="0 1 0"/>
       <limit effort="0.0" lower="-3.14159" upper="3.14159" velocity="0.0"/>
    </joint>
    <link name="Link6">
        <inertial>
            <origin xyz="-0.36300978440530896 0 -0.18711103767590626" rpy="0 0 0"/>
            <mass value="1" />
            <inertia ixx="100" ixy="0" ixz="0" iyy="100" iyz="0" izz="100" />
        </inertial>
        <visual>
            <origin xyz="-0.36300978440530896 0 -0.18711103767590626" rpy="0 0 0"/>
            <geometry>
                <box size="0.7260195688106179 0.45758654932384224 0.3742220753518125" />
            </geometry>
            <material name="Green">
                <color rgba="0 1.0 0.0 1.0"/>
            </material>
        </visual>
        <collision>
            <origin xyz="-0.36300978440530896 0 -0.18711103767590626" rpy="0 0 0"/>
            <geometry>
                <box size="0.7260195688106179 0.45758654932384224 0.3742220753518125" />
            </geometry>
        </collision>
    </link>
</robot>