<robot name = "robot">
    <link name="Link0">
        <inertial>
            <origin xyz="0 0 2.4357293594856997" rpy="0 0 0"/>
            <mass value="1" />
            <inertia ixx="100" ixy="0" ixz="0" iyy="100" iyz="0" izz="100" />
        </inertial>
        <visual>
            <origin xyz="0 0 2.4357293594856997" rpy="0 0 0"/>
            <geometry>
                <box size="0.8636441812418921 0.3377842894704859 0.8714587189713995" />
            </geometry>
            <material name="Green">
                <color rgba="0 1.0 0.0 1.0"/>
            </material>
        </visual>
        <collision>
            <origin xyz="0 0 2.4357293594856997" rpy="0 0 0"/>
            <geometry>
                <box size="0.8636441812418921 0.3377842894704859 0.8714587189713995" />
            </geometry>
        </collision>
    </link>
    <joint name="Link0_Link1" type="revolute">
       <parent link="Link0"/>
       <child  link="Link1"/>
       <origin rpy="0 0 0" xyz="0 0.16889214473524294 2.8714587189713994" />
     <axis xyz="1 0 0"/>
       <limit effort="0.0" lower="-3.14159" upper="3.14159" velocity="0.0"/>
    </joint>
    <link name="Link1">
        <inertial>
            <origin xyz="0 0.16889214473524294 -0.43572935948569974" rpy="0 0 0"/>
            <mass value="1" />
            <inertia ixx="100" ixy="0" ixz="0" iyy="100" iyz="0" izz="100" />
        </inertial>
        <visual>
            <origin xyz="0 0.16889214473524294 -0.43572935948569974" rpy="0 0 0"/>
            <geometry>
                <box size="0.8636441812418921 0.3377842894704859 0.8714587189713995" />
            </geometry>
            <material name="Blue">
                <color rgba="0 0.0 1.0 1.0"/>
            </material>
        </visual>
        <collision>
            <origin xyz="0 0.16889214473524294 -0.43572935948569974" rpy="0 0 0"/>
            <geometry>
                <box size="0.8636441812418921 0.3377842894704859 0.8714587189713995" />
            </geometry>
        </collision>
    </link>
    <joint name="Link1_Link2" type="revolute">
       <parent link="Link1"/>
       <child  link="Link2"/>
       <origin rpy="0 0 0" xyz="-0.43182209062094606 0.16889214473524294 0.0" />
     <axis xyz="0 1 0"/>
       <limit effort="0.0" lower="-3.14159" upper="3.14159" velocity="0.0"/>
    </joint>
    <link name="Link2">
        <inertial>
            <origin xyz="-0.07722304498690558 0 -0.30780869926350124" rpy="0 0 0"/>
            <mass value="1" />
            <inertia ixx="100" ixy="0" ixz="0" iyy="100" iyz="0" izz="100" />
        </inertial>
        <visual>
            <origin xyz="-0.07722304498690558 0 -0.30780869926350124" rpy="0 0 0"/>
            <geometry>
                <box size="0.15444608997381115 0.5781587279770117 0.6156173985270025" />
            </geometry>
            <material name="Blue">
                <color rgba="0 0.0 1.0 1.0"/>
            </material>
        </visual>
        <collision>
            <origin xyz="-0.07722304498690558 0 -0.30780869926350124" rpy="0 0 0"/>
            <geometry>
                <box size="0.15444608997381115 0.5781587279770117 0.6156173985270025" />
            </geometry>
        </collision>
    </link>
    <joint name="Link2_Link3" type="revolute">
       <parent link="Link2"/>
       <child  link="Link3"/>
       <origin rpy="0 0 0" xyz="-0.15444608997381115 0 0.0" />
     <axis xyz="0 1 0"/>
       <limit effort="0.0" lower="-3.14159" upper="3.14159" velocity="0.0"/>
    </joint>
    <link name="Link3">
        <inertial>
            <origin xyz="-0.1115111992595656 0 -0.3230687592763446" rpy="0 0 0"/>
            <mass value="1" />
            <inertia ixx="100" ixy="0" ixz="0" iyy="100" iyz="0" izz="100" />
        </inertial>
        <visual>
            <origin xyz="-0.1115111992595656 0 -0.3230687592763446" rpy="0 0 0"/>
            <geometry>
                <box size="0.2230223985191312 0.5946733462382914 0.6461375185526892" />
            </geometry>
            <material name="Green">
                <color rgba="0 1.0 0.0 1.0"/>
            </material>
        </visual>
        <collision>
            <origin xyz="-0.1115111992595656 0 -0.3230687592763446" rpy="0 0 0"/>
            <geometry>
                <box size="0.2230223985191312 0.5946733462382914 0.6461375185526892" />
            </geometry>
        </collision>
    </link>
    <joint name="Link3_Link4" type="revolute">
       <parent link="Link3"/>
       <child  link="Link4"/>
       <origin rpy="0 0 0" xyz="-0.1115111992595656 0.2973366731191457 0.0" />
     <axis xyz="1 0 0"/>
       <limit effort="0.0" lower="-3.14159" upper="3.14159" velocity="0.0"/>
    </joint>
    <link name="Link4">
        <inertial>
            <origin xyz="0 0.3439675889005185 -0.4195236878361726" rpy="0 0 0"/>
            <mass value="1" />
            <inertia ixx="100" ixy="0" ixz="0" iyy="100" iyz="0" izz="100" />
        </inertial>
        <visual>
            <origin xyz="0 0.3439675889005185 -0.4195236878361726" rpy="0 0 0"/>
            <geometry>
                <box size="0.003021869380577802 0.687935177801037 0.8390473756723452" />
            </geometry>
            <material name="Green">
                <color rgba="0 1.0 0.0 1.0"/>
            </material>
        </visual>
        <collision>
            <origin xyz="0 0.3439675889005185 -0.4195236878361726" rpy="0 0 0"/>
            <geometry>
                <box size="0.003021869380577802 0.687935177801037 0.8390473756723452" />
            </geometry>
        </collision>
    </link>
    <joint name="Link4_Link5" type="revolute">
       <parent link="Link4"/>
       <child  link="Link5"/>
       <origin rpy="0 0 0" xyz="0.001510934690288901 0.3439675889005185 0.0" />
     <axis xyz="0 1 0"/>
       <limit effort="0.0" lower="-3.14159" upper="3.14159" velocity="0.0"/>
    </joint>
    <link name="Link5">
        <inertial>
            <origin xyz="0.12877695370450626 0 0.2513021317214561" rpy="0 0 0"/>
            <mass value="1" />
            <inertia ixx="100" ixy="0" ixz="0" iyy="100" iyz="0" izz="100" />
        </inertial>
        <visual>
            <origin xyz="0.12877695370450626 0 0.2513021317214561" rpy="0 0 0"/>
            <geometry>
                <box size="0.2575539074090125 0.5430223040605353 0.5026042634429122" />
            </geometry>
            <material name="Green">
                <color rgba="0 1.0 0.0 1.0"/>
            </material>
        </visual>
        <collision>
            <origin xyz="0.12877695370450626 0 0.2513021317214561" rpy="0 0 0"/>
            <geometry>
                <box size="0.2575539074090125 0.5430223040605353 0.5026042634429122" />
            </geometry>
        </collision>
    </link>
    <joint name="Link5_Link6" type="revolute">
       <parent link="Link5"/>
       <child  link="Link6"/>
       <origin rpy="0 0 0" xyz="0.12877695370450626 -0.27151115203026766 0.5026042634429122" />
     <axis xyz="1 0 0"/>
       <limit effort="0.0" lower="-3.14159" upper="3.14159" velocity="0.0"/>
    </joint>
    <link name="Link6">
        <inertial>
            <origin xyz="0 -0.44041425139250395 -0.2846943788023879" rpy="0 0 0"/>
            <mass value="1" />
            <inertia ixx="100" ixy="0" ixz="0" iyy="100" iyz="0" izz="100" />
        </inertial>
        <visual>
            <origin xyz="0 -0.44041425139250395 -0.2846943788023879" rpy="0 0 0"/>
            <geometry>
                <box size="0.45889747695365757 0.8808285027850079 0.5693887576047758" />
            </geometry>
            <material name="Blue">
                <color rgba="0 0.0 1.0 1.0"/>
            </material>
        </visual>
        <collision>
            <origin xyz="0 -0.44041425139250395 -0.2846943788023879" rpy="0 0 0"/>
            <geometry>
                <box size="0.45889747695365757 0.8808285027850079 0.5693887576047758" />
            </geometry>
        </collision>
    </link>
</robot>