<robot name = "robot">
    <link name="Link0">
        <inertial>
            <origin xyz="0 0 2.1481271248741196" rpy="0 0 0"/>
            <mass value="1" />
            <inertia ixx="100" ixy="0" ixz="0" iyy="100" iyz="0" izz="100" />
        </inertial>
        <visual>
            <origin xyz="0 0 2.1481271248741196" rpy="0 0 0"/>
            <geometry>
                <box size="0.007797925252579718 0.5022696988771248 0.29625424974823933" />
            </geometry>
            <material name="Green">
                <color rgba="0 1.0 0.0 1.0"/>
            </material>
        </visual>
        <collision>
            <origin xyz="0 0 2.1481271248741196" rpy="0 0 0"/>
            <geometry>
                <box size="0.007797925252579718 0.5022696988771248 0.29625424974823933" />
            </geometry>
        </collision>
    </link>
    <joint name="Link0_Link1" type="revolute">
       <parent link="Link0"/>
       <child  link="Link1"/>
       <origin rpy="0 0 0" xyz="0 0.2511348494385624 2.296254249748239" />
     <axis xyz="1 0 0"/>
       <limit effort="0.0" lower="-3.14159" upper="3.14159" velocity="0.0"/>
    </joint>
    <link name="Link1">
        <inertial>
            <origin xyz="0 0.2511348494385624 -0.14812712487411966" rpy="0 0 0"/>
            <mass value="1" />
            <inertia ixx="100" ixy="0" ixz="0" iyy="100" iyz="0" izz="100" />
        </inertial>
        <visual>
            <origin xyz="0 0.2511348494385624 -0.14812712487411966" rpy="0 0 0"/>
            <geometry>
                <box size="0.007797925252579718 0.5022696988771248 0.29625424974823933" />
            </geometry>
            <material name="Blue">
                <color rgba="0 0.0 1.0 1.0"/>
            </material>
        </visual>
        <collision>
            <origin xyz="0 0.2511348494385624 -0.14812712487411966" rpy="0 0 0"/>
            <geometry>
                <box size="0.007797925252579718 0.5022696988771248 0.29625424974823933" />
            </geometry>
        </collision>
    </link>
    <joint name="Link1_Link2" type="revolute">
       <parent link="Link1"/>
       <child  link="Link2"/>
       <origin rpy="0 0 0" xyz="-0.003898962626289859 0.2511348494385624 0.0" />
     <axis xyz="0 1 0"/>
       <limit effort="0.0" lower="-3.14159" upper="3.14159" velocity="0.0"/>
    </joint>
    <link name="Link2">
        <inertial>
            <origin xyz="-0.3059753142645324 0 0.1600563270783093" rpy="0 0 0"/>
            <mass value="1" />
            <inertia ixx="100" ixy="0" ixz="0" iyy="100" iyz="0" izz="100" />
        </inertial>
        <visual>
            <origin xyz="-0.3059753142645324 0 0.1600563270783093" rpy="0 0 0"/>
            <geometry>
                <box size="0.6119506285290648 0.44892221435448376 0.3201126541566186" />
            </geometry>
            <material name="Blue">
                <color rgba="0 0.0 1.0 1.0"/>
            </material>
        </visual>
        <collision>
            <origin xyz="-0.3059753142645324 0 0.1600563270783093" rpy="0 0 0"/>
            <geometry>
                <box size="0.6119506285290648 0.44892221435448376 0.3201126541566186" />
            </geometry>
        </collision>
    </link>
    <joint name="Link2_Link3" type="revolute">
       <parent link="Link2"/>
       <child  link="Link3"/>
       <origin rpy="0 0 0" xyz="-0.6119506285290648 0 0.3201126541566186" />
     <axis xyz="0 1 0"/>
       <limit effort="0.0" lower="-3.14159" upper="3.14159" velocity="0.0"/>
    </joint>
    <link name="Link3">
        <inertial>
            <origin xyz="-0.4154737286494868 0 -0.4738154138797653" rpy="0 0 0"/>
            <mass value="1" />
            <inertia ixx="100" ixy="0" ixz="0" iyy="100" iyz="0" izz="100" />
        </inertial>
        <visual>
            <origin xyz="-0.4154737286494868 0 -0.4738154138797653" rpy="0 0 0"/>
            <geometry>
                <box size="0.8309474572989736 0.4339338212787943 0.9476308277595306" />
            </geometry>
            <material name="Blue">
                <color rgba="0 0.0 1.0 1.0"/>
            </material>
        </visual>
        <collision>
            <origin xyz="-0.4154737286494868 0 -0.4738154138797653" rpy="0 0 0"/>
            <geometry>
                <box size="0.8309474572989736 0.4339338212787943 0.9476308277595306" />
            </geometry>
        </collision>
    </link>
    <joint name="Link3_Link4" type="revolute">
       <parent link="Link3"/>
       <child  link="Link4"/>
       <origin rpy="0 0 0" xyz="-0.4154737286494868 0.21696691063939716 0.0" />
     <axis xyz="1 0 0"/>
       <limit effort="0.0" lower="-3.14159" upper="3.14159" velocity="0.0"/>
    </joint>
    <link name="Link4">
        <inertial>
            <origin xyz="0 0.27026879476389964 0.4842892366067886" rpy="0 0 0"/>
            <mass value="1" />
            <inertia ixx="100" ixy="0" ixz="0" iyy="100" iyz="0" izz="100" />
        </inertial>
        <visual>
            <origin xyz="0 0.27026879476389964 0.4842892366067886" rpy="0 0 0"/>
            <geometry>
                <box size="0.004105588932365678 0.5405375895277993 0.9685784732135772" />
            </geometry>
            <material name="Green">
                <color rgba="0 1.0 0.0 1.0"/>
            </material>
        </visual>
        <collision>
            <origin xyz="0 0.27026879476389964 0.4842892366067886" rpy="0 0 0"/>
            <geometry>
                <box size="0.004105588932365678 0.5405375895277993 0.9685784732135772" />
            </geometry>
        </collision>
    </link>
    <joint name="Link4_Link5" type="revolute">
       <parent link="Link4"/>
       <child  link="Link5"/>
       <origin rpy="0 0 0" xyz="-0.002052794466182839 0.27026879476389964 0.9685784732135772" />
     <axis xyz="0 1 0"/>
       <limit effort="0.0" lower="-3.14159" upper="3.14159" velocity="0.0"/>
    </joint>
    <link name="Link5">
        <inertial>
            <origin xyz="-0.45295731743560275 0 0.0005576098211698133" rpy="0 0 0"/>
            <mass value="1" />
            <inertia ixx="100" ixy="0" ixz="0" iyy="100" iyz="0" izz="100" />
        </inertial>
        <visual>
            <origin xyz="-0.45295731743560275 0 0.0005576098211698133" rpy="0 0 0"/>
            <geometry>
                <box size="0.9059146348712055 0.6837575848170592 0.0011152196423396266" />
            </geometry>
            <material name="Blue">
                <color rgba="0 0.0 1.0 1.0"/>
            </material>
        </visual>
        <collision>
            <origin xyz="-0.45295731743560275 0 0.0005576098211698133" rpy="0 0 0"/>
            <geometry>
                <box size="0.9059146348712055 0.6837575848170592 0.0011152196423396266" />
            </geometry>
        </collision>
    </link>
    <joint name="Link5_Link6" type="revolute">
       <parent link="Link5"/>
       <child  link="Link6"/>
       <origin rpy="0 0 0" xyz="0.0 0 0.0011152196423396266" />
     <axis xyz="0 1 0"/>
       <limit effort="0.0" lower="-3.14159" upper="3.14159" velocity="0.0"/>
    </joint>
    <link name="Link6">
        <inertial>
            <origin xyz="0.03536468797611181 0 -0.4652846672826363" rpy="0 0 0"/>
            <mass value="1" />
            <inertia ixx="100" ixy="0" ixz="0" iyy="100" iyz="0" izz="100" />
        </inertial>
        <visual>
            <origin xyz="0.03536468797611181 0 -0.4652846672826363" rpy="0 0 0"/>
            <geometry>
                <box size="0.07072937595222362 0.42045106189448145 0.9305693345652726" />
            </geometry>
            <material name="Green">
                <color rgba="0 1.0 0.0 1.0"/>
            </material>
        </visual>
        <collision>
            <origin xyz="0.03536468797611181 0 -0.4652846672826363" rpy="0 0 0"/>
            <geometry>
                <box size="0.07072937595222362 0.42045106189448145 0.9305693345652726" />
            </geometry>
        </collision>
    </link>
</robot>