<robot name = "robot">
    <link name="Link0">
        <inertial>
            <origin xyz="0 0 2.4038653730398605" rpy="0 0 0"/>
            <mass value="1" />
            <inertia ixx="100" ixy="0" ixz="0" iyy="100" iyz="0" izz="100" />
        </inertial>
        <visual>
            <origin xyz="0 0 2.4038653730398605" rpy="0 0 0"/>
            <geometry>
                <box size="0.713952895041077 0.57585991893707 0.8077307460797213" />
            </geometry>
            <material name="Green">
                <color rgba="0 1.0 0.0 1.0"/>
            </material>
        </visual>
        <collision>
            <origin xyz="0 0 2.4038653730398605" rpy="0 0 0"/>
            <geometry>
                <box size="0.713952895041077 0.57585991893707 0.8077307460797213" />
            </geometry>
        </collision>
    </link>
    <joint name="Link0_Link1" type="revolute">
       <parent link="Link0"/>
       <child  link="Link1"/>
       <origin rpy="0 0 0" xyz="0 0.287929959468535 2.8077307460797214" />
     <axis xyz="1 0 0"/>
       <limit effort="0.0" lower="-3.14159" upper="3.14159" velocity="0.0"/>
    </joint>
    <link name="Link1">
        <inertial>
            <origin xyz="0 0.287929959468535 -0.40386537303986064" rpy="0 0 0"/>
            <mass value="1" />
            <inertia ixx="100" ixy="0" ixz="0" iyy="100" iyz="0" izz="100" />
        </inertial>
        <visual>
            <origin xyz="0 0.287929959468535 -0.40386537303986064" rpy="0 0 0"/>
            <geometry>
                <box size="0.713952895041077 0.57585991893707 0.8077307460797213" />
            </geometry>
            <material name="Blue">
                <color rgba="0 0.0 1.0 1.0"/>
            </material>
        </visual>
        <collision>
            <origin xyz="0 0.287929959468535 -0.40386537303986064" rpy="0 0 0"/>
            <geometry>
                <box size="0.713952895041077 0.57585991893707 0.8077307460797213" />
            </geometry>
        </collision>
    </link>
    <joint name="Link1_Link2" type="revolute">
       <parent link="Link1"/>
       <child  link="Link2"/>
       <origin rpy="0 0 0" xyz="0 0.57585991893707 0.0" />
     <axis xyz="1 0 0"/>
       <limit effort="0.0" lower="-3.14159" upper="3.14159" velocity="0.0"/>
    </joint>
    <link name="Link2">
        <inertial>
            <origin xyz="0 0.43809001612683346 0.00347989602965193" rpy="0 0 0"/>
            <mass value="1" />
            <inertia ixx="100" ixy="0" ixz="0" iyy="100" iyz="0" izz="100" />
        </inertial>
        <visual>
            <origin xyz="0 0.43809001612683346 0.00347989602965193" rpy="0 0 0"/>
            <geometry>
                <box size="0.6324852917849874 0.8761800322536669 0.00695979205930386" />
            </geometry>
            <material name="Green">
                <color rgba="0 1.0 0.0 1.0"/>
            </material>
        </visual>
        <collision>
            <origin xyz="0 0.43809001612683346 0.00347989602965193" rpy="0 0 0"/>
            <geometry>
                <box size="0.6324852917849874 0.8761800322536669 0.00695979205930386" />
            </geometry>
        </collision>
    </link>
    <joint name="Link2_Link3" type="revolute">
       <parent link="Link2"/>
       <child  link="Link3"/>
       <origin rpy="0 0 0" xyz="-0.3162426458924937 0.43809001612683346 0.00695979205930386" />
     <axis xyz="0 1 0"/>
       <limit effort="0.0" lower="-3.14159" upper="3.14159" velocity="0.0"/>
    </joint>
    <link name="Link3">
        <inertial>
            <origin xyz="-0.49238075370903794 0 -0.43826253140232746" rpy="0 0 0"/>
            <mass value="1" />
            <inertia ixx="100" ixy="0" ixz="0" iyy="100" iyz="0" izz="100" />
        </inertial>
        <visual>
            <origin xyz="-0.49238075370903794 0 -0.43826253140232746" rpy="0 0 0"/>
            <geometry>
                <box size="0.9847615074180759 0.5758876333016316 0.8765250628046549" />
            </geometry>
            <material name="Blue">
                <color rgba="0 0.0 1.0 1.0"/>
            </material>
        </visual>
        <collision>
            <origin xyz="-0.49238075370903794 0 -0.43826253140232746" rpy="0 0 0"/>
            <geometry>
                <box size="0.9847615074180759 0.5758876333016316 0.8765250628046549" />
            </geometry>
        </collision>
    </link>
    <joint name="Link3_Link4" type="revolute">
       <parent link="Link3"/>
       <child  link="Link4"/>
       <origin rpy="0 0 0" xyz="-0.49238075370903794 0.2879438166508158 0.0" />
     <axis xyz="1 0 0"/>
       <limit effort="0.0" lower="-3.14159" upper="3.14159" velocity="0.0"/>
    </joint>
    <link name="Link4">
        <inertial>
            <origin xyz="0 0.2364755229292363 0.07545936861467312" rpy="0 0 0"/>
            <mass value="1" />
            <inertia ixx="100" ixy="0" ixz="0" iyy="100" iyz="0" izz="100" />
        </inertial>
        <visual>
            <origin xyz="0 0.2364755229292363 0.07545936861467312" rpy="0 0 0"/>
            <geometry>
                <box size="0.35983349362744776 0.4729510458584726 0.15091873722934623" />
            </geometry>
            <material name="Blue">
                <color rgba="0 0.0 1.0 1.0"/>
            </material>
        </visual>
        <collision>
            <origin xyz="0 0.2364755229292363 0.07545936861467312" rpy="0 0 0"/>
            <geometry>
                <box size="0.35983349362744776 0.4729510458584726 0.15091873722934623" />
            </geometry>
        </collision>
    </link>
</robot>