<robot name = "robot">
    <link name="Link0">
        <inertial>
            <origin xyz="0 0 2.1495444419407694" rpy="0 0 0"/>
            <mass value="1" />
            <inertia ixx="100" ixy="0" ixz="0" iyy="100" iyz="0" izz="100" />
        </inertial>
        <visual>
            <origin xyz="0 0 2.1495444419407694" rpy="0 0 0"/>
            <geometry>
                <box size="0.5803409639611369 0.7248757632870179 0.29908888388153887" />
            </geometry>
            <material name="Green">
                <color rgba="0 1.0 0.0 1.0"/>
            </material>
        </visual>
        <collision>
            <origin xyz="0 0 2.1495444419407694" rpy="0 0 0"/>
            <geometry>
                <box size="0.5803409639611369 0.7248757632870179 0.29908888388153887" />
            </geometry>
        </collision>
    </link>
    <joint name="Link0_Link1" type="revolute">
       <parent link="Link0"/>
       <child  link="Link1"/>
       <origin rpy="0 0 0" xyz="0 0.36243788164350893 2.299088883881539" />
     <axis xyz="1 0 0"/>
       <limit effort="0.0" lower="-3.14159" upper="3.14159" velocity="0.0"/>
    </joint>
    <link name="Link1">
        <inertial>
            <origin xyz="0 0.36243788164350893 -0.14954444194076943" rpy="0 0 0"/>
            <mass value="1" />
            <inertia ixx="100" ixy="0" ixz="0" iyy="100" iyz="0" izz="100" />
        </inertial>
        <visual>
            <origin xyz="0 0.36243788164350893 -0.14954444194076943" rpy="0 0 0"/>
            <geometry>
                <box size="0.5803409639611369 0.7248757632870179 0.29908888388153887" />
            </geometry>
            <material name="Blue">
                <color rgba="0 0.0 1.0 1.0"/>
            </material>
        </visual>
        <collision>
            <origin xyz="0 0.36243788164350893 -0.14954444194076943" rpy="0 0 0"/>
            <geometry>
                <box size="0.5803409639611369 0.7248757632870179 0.29908888388153887" />
            </geometry>
        </collision>
    </link>
    <joint name="Link1_Link2" type="revolute">
       <parent link="Link1"/>
       <child  link="Link2"/>
       <origin rpy="0 0 0" xyz="0 0.7248757632870179 0.0" />
     <axis xyz="1 0 0"/>
       <limit effort="0.0" lower="-3.14159" upper="3.14159" velocity="0.0"/>
    </joint>
    <link name="Link2">
        <inertial>
            <origin xyz="0 0.1643510911420314 -0.14702158241518343" rpy="0 0 0"/>
            <mass value="1" />
            <inertia ixx="100" ixy="0" ixz="0" iyy="100" iyz="0" izz="100" />
        </inertial>
        <visual>
            <origin xyz="0 0.1643510911420314 -0.14702158241518343" rpy="0 0 0"/>
            <geometry>
                <box size="0.26369875278989297 0.3287021822840628 0.29404316483036685" />
            </geometry>
            <material name="Green">
                <color rgba="0 1.0 0.0 1.0"/>
            </material>
        </visual>
        <collision>
            <origin xyz="0 0.1643510911420314 -0.14702158241518343" rpy="0 0 0"/>
            <geometry>
                <box size="0.26369875278989297 0.3287021822840628 0.29404316483036685" />
            </geometry>
        </collision>
    </link>
    <joint name="Link2_Link3" type="revolute">
       <parent link="Link2"/>
       <child  link="Link3"/>
       <origin rpy="0 0 0" xyz="0 0.0 0.0" />
     <axis xyz="1 0 0"/>
       <limit effort="0.0" lower="-3.14159" upper="3.14159" velocity="0.0"/>
    </joint>
    <link name="Link3">
        <inertial>
            <origin xyz="0 -0.004212606790579221 -0.22382283271559755" rpy="0 0 0"/>
            <mass value="1" />
            <inertia ixx="100" ixy="0" ixz="0" iyy="100" iyz="0" izz="100" />
        </inertial>
        <visual>
            <origin xyz="0 -0.004212606790579221 -0.22382283271559755" rpy="0 0 0"/>
            <geometry>
                <box size="0.7990045104951591 0.008425213581158442 0.4476456654311951" />
            </geometry>
            <material name="Blue">
                <color rgba="0 0.0 1.0 1.0"/>
            </material>
        </visual>
        <collision>
            <origin xyz="0 -0.004212606790579221 -0.22382283271559755" rpy="0 0 0"/>
            <geometry>
                <box size="0.7990045104951591 0.008425213581158442 0.4476456654311951" />
            </geometry>
        </collision>
    </link>
    <joint name="Link3_Link4" type="revolute">
       <parent link="Link3"/>
       <child  link="Link4"/>
       <origin rpy="0 0 0" xyz="-0.39950225524757954 -0.004212606790579221 0.0" />
     <axis xyz="0 1 0"/>
       <limit effort="0.0" lower="-3.14159" upper="3.14159" velocity="0.0"/>
    </joint>
    <link name="Link4">
        <inertial>
            <origin xyz="-0.09132753007359368 0 -0.015024621398544602" rpy="0 0 0"/>
            <mass value="1" />
            <inertia ixx="100" ixy="0" ixz="0" iyy="100" iyz="0" izz="100" />
        </inertial>
        <visual>
            <origin xyz="-0.09132753007359368 0 -0.015024621398544602" rpy="0 0 0"/>
            <geometry>
                <box size="0.18265506014718735 0.7311110588151026 0.030049242797089204" />
            </geometry>
            <material name="Blue">
                <color rgba="0 0.0 1.0 1.0"/>
            </material>
        </visual>
        <collision>
            <origin xyz="-0.09132753007359368 0 -0.015024621398544602" rpy="0 0 0"/>
            <geometry>
                <box size="0.18265506014718735 0.7311110588151026 0.030049242797089204" />
            </geometry>
        </collision>
    </link>
</robot>