<robot name = "robot">
    <link name="Link0">
        <inertial>
            <origin xyz="0 0 2.227770140442891" rpy="0 0 0"/>
            <mass value="1" />
            <inertia ixx="100" ixy="0" ixz="0" iyy="100" iyz="0" izz="100" />
        </inertial>
        <visual>
            <origin xyz="0 0 2.227770140442891" rpy="0 0 0"/>
            <geometry>
                <box size="0.662845962802134 0.797607697919967 0.4555402808857826" />
            </geometry>
            <material name="Green">
                <color rgba="0 1.0 0.0 1.0"/>
            </material>
        </visual>
        <collision>
            <origin xyz="0 0 2.227770140442891" rpy="0 0 0"/>
            <geometry>
                <box size="0.662845962802134 0.797607697919967 0.4555402808857826" />
            </geometry>
        </collision>
    </link>
    <joint name="Link0_Link1" type="revolute">
       <parent link="Link0"/>
       <child  link="Link1"/>
       <origin rpy="0 0 0" xyz="0 0.3988038489599835 2.4555402808857827" />
     <axis xyz="1 0 0"/>
       <limit effort="0.0" lower="-3.14159" upper="3.14159" velocity="0.0"/>
    </joint>
    <link name="Link1">
        <inertial>
            <origin xyz="0 0.3988038489599835 -0.2277701404428913" rpy="0 0 0"/>
            <mass value="1" />
            <inertia ixx="100" ixy="0" ixz="0" iyy="100" iyz="0" izz="100" />
        </inertial>
        <visual>
            <origin xyz="0 0.3988038489599835 -0.2277701404428913" rpy="0 0 0"/>
            <geometry>
                <box size="0.662845962802134 0.797607697919967 0.4555402808857826" />
            </geometry>
            <material name="Blue">
                <color rgba="0 0.0 1.0 1.0"/>
            </material>
        </visual>
        <collision>
            <origin xyz="0 0.3988038489599835 -0.2277701404428913" rpy="0 0 0"/>
            <geometry>
                <box size="0.662845962802134 0.797607697919967 0.4555402808857826" />
            </geometry>
        </collision>
    </link>
    <joint name="Link1_Link2" type="revolute">
       <parent link="Link1"/>
       <child  link="Link2"/>
       <origin rpy="0 0 0" xyz="0 0.0 0.0" />
     <axis xyz="1 0 0"/>
       <limit effort="0.0" lower="-3.14159" upper="3.14159" velocity="0.0"/>
    </joint>
    <link name="Link2">
        <inertial>
            <origin xyz="0 -0.03316630806786308 0.29796116440532605" rpy="0 0 0"/>
            <mass value="1" />
            <inertia ixx="100" ixy="0" ixz="0" iyy="100" iyz="0" izz="100" />
        </inertial>
        <visual>
            <origin xyz="0 -0.03316630806786308 0.29796116440532605" rpy="0 0 0"/>
            <geometry>
                <box size="0.9170354891580605 0.06633261613572616 0.5959223288106521" />
            </geometry>
            <material name="Green">
                <color rgba="0 1.0 0.0 1.0"/>
            </material>
        </visual>
        <collision>
            <origin xyz="0 -0.03316630806786308 0.29796116440532605" rpy="0 0 0"/>
            <geometry>
                <box size="0.9170354891580605 0.06633261613572616 0.5959223288106521" />
            </geometry>
        </collision>
    </link>
    <joint name="Link2_Link3" type="revolute">
       <parent link="Link2"/>
       <child  link="Link3"/>
       <origin rpy="0 0 0" xyz="-0.4585177445790303 -0.03316630806786308 0.5959223288106521" />
     <axis xyz="0 1 0"/>
       <limit effort="0.0" lower="-3.14159" upper="3.14159" velocity="0.0"/>
    </joint>
    <link name="Link3">
        <inertial>
            <origin xyz="-0.17253188707716166 0 -0.26624948775480217" rpy="0 0 0"/>
            <mass value="1" />
            <inertia ixx="100" ixy="0" ixz="0" iyy="100" iyz="0" izz="100" />
        </inertial>
        <visual>
            <origin xyz="-0.17253188707716166 0 -0.26624948775480217" rpy="0 0 0"/>
            <geometry>
                <box size="0.3450637741543233 0.05188016900712866 0.5324989755096043" />
            </geometry>
            <material name="Blue">
                <color rgba="0 0.0 1.0 1.0"/>
            </material>
        </visual>
        <collision>
            <origin xyz="-0.17253188707716166 0 -0.26624948775480217" rpy="0 0 0"/>
            <geometry>
                <box size="0.3450637741543233 0.05188016900712866 0.5324989755096043" />
            </geometry>
        </collision>
    </link>
    <joint name="Link3_Link4" type="revolute">
       <parent link="Link3"/>
       <child  link="Link4"/>
       <origin rpy="0 0 0" xyz="0.0 0 0.0" />
     <axis xyz="0 1 0"/>
       <limit effort="0.0" lower="-3.14159" upper="3.14159" velocity="0.0"/>
    </joint>
    <link name="Link4">
        <inertial>
            <origin xyz="0.2266106299332925 0 0.2867710175743923" rpy="0 0 0"/>
            <mass value="1" />
            <inertia ixx="100" ixy="0" ixz="0" iyy="100" iyz="0" izz="100" />
        </inertial>
        <visual>
            <origin xyz="0.2266106299332925 0 0.2867710175743923" rpy="0 0 0"/>
            <geometry>
                <box size="0.453221259866585 0.9742472818543069 0.5735420351487845" />
            </geometry>
            <material name="Green">
                <color rgba="0 1.0 0.0 1.0"/>
            </material>
        </visual>
        <collision>
            <origin xyz="0.2266106299332925 0 0.2867710175743923" rpy="0 0 0"/>
            <geometry>
                <box size="0.453221259866585 0.9742472818543069 0.5735420351487845" />
            </geometry>
        </collision>
    </link>
    <joint name="Link4_Link5" type="revolute">
       <parent link="Link4"/>
       <child  link="Link5"/>
       <origin rpy="0 0 0" xyz="0.2266106299332925 -0.48712364092715343 0.5735420351487845" />
     <axis xyz="1 0 0"/>
       <limit effort="0.0" lower="-3.14159" upper="3.14159" velocity="0.0"/>
    </joint>
    <link name="Link5">
        <inertial>
            <origin xyz="0 -0.02561789217080901 -0.13818339039884087" rpy="0 0 0"/>
            <mass value="1" />
            <inertia ixx="100" ixy="0" ixz="0" iyy="100" iyz="0" izz="100" />
        </inertial>
        <visual>
            <origin xyz="0 -0.02561789217080901 -0.13818339039884087" rpy="0 0 0"/>
            <geometry>
                <box size="0.5485771462793216 0.05123578434161802 0.27636678079768173" />
            </geometry>
            <material name="Blue">
                <color rgba="0 0.0 1.0 1.0"/>
            </material>
        </visual>
        <collision>
            <origin xyz="0 -0.02561789217080901 -0.13818339039884087" rpy="0 0 0"/>
            <geometry>
                <box size="0.5485771462793216 0.05123578434161802 0.27636678079768173" />
            </geometry>
        </collision>
    </link>
</robot>