<robot name = "robot">
    <link name="Link0">
        <inertial>
            <origin xyz="0 0 2.1981798624885864" rpy="0 0 0"/>
            <mass value="1" />
            <inertia ixx="100" ixy="0" ixz="0" iyy="100" iyz="0" izz="100" />
        </inertial>
        <visual>
            <origin xyz="0 0 2.1981798624885864" rpy="0 0 0"/>
            <geometry>
                <box size="0.228120438380657 0.21836196312991207 0.396359724977173" />
            </geometry>
            <material name="Green">
                <color rgba="0 1.0 0.0 1.0"/>
            </material>
        </visual>
        <collision>
            <origin xyz="0 0 2.1981798624885864" rpy="0 0 0"/>
            <geometry>
                <box size="0.228120438380657 0.21836196312991207 0.396359724977173" />
            </geometry>
        </collision>
    </link>
    <joint name="Link0_Link1" type="revolute">
       <parent link="Link0"/>
       <child  link="Link1"/>
       <origin rpy="0 0 0" xyz="0 0.10918098156495604 2.396359724977173" />
     <axis xyz="1 0 0"/>
       <limit effort="0.0" lower="-3.14159" upper="3.14159" velocity="0.0"/>
    </joint>
    <link name="Link1">
        <inertial>
            <origin xyz="0 0.10918098156495604 -0.1981798624885865" rpy="0 0 0"/>
            <mass value="1" />
            <inertia ixx="100" ixy="0" ixz="0" iyy="100" iyz="0" izz="100" />
        </inertial>
        <visual>
            <origin xyz="0 0.10918098156495604 -0.1981798624885865" rpy="0 0 0"/>
            <geometry>
                <box size="0.228120438380657 0.21836196312991207 0.396359724977173" />
            </geometry>
            <material name="Blue">
                <color rgba="0 0.0 1.0 1.0"/>
            </material>
        </visual>
        <collision>
            <origin xyz="0 0.10918098156495604 -0.1981798624885865" rpy="0 0 0"/>
            <geometry>
                <box size="0.228120438380657 0.21836196312991207 0.396359724977173" />
            </geometry>
        </collision>
    </link>
    <joint name="Link1_Link2" type="revolute">
       <parent link="Link1"/>
       <child  link="Link2"/>
       <origin rpy="0 0 0" xyz="0.1140602191903285 0.10918098156495604 0.0" />
     <axis xyz="0 1 0"/>
       <limit effort="0.0" lower="-3.14159" upper="3.14159" velocity="0.0"/>
    </joint>
    <link name="Link2">
        <inertial>
            <origin xyz="0.43324150692993213 0 -0.4213345641346176" rpy="0 0 0"/>
            <mass value="1" />
            <inertia ixx="100" ixy="0" ixz="0" iyy="100" iyz="0" izz="100" />
        </inertial>
        <visual>
            <origin xyz="0.43324150692993213 0 -0.4213345641346176" rpy="0 0 0"/>
            <geometry>
                <box size="0.8664830138598643 0.4865887623536186 0.8426691282692352" />
            </geometry>
            <material name="Green">
                <color rgba="0 1.0 0.0 1.0"/>
            </material>
        </visual>
        <collision>
            <origin xyz="0.43324150692993213 0 -0.4213345641346176" rpy="0 0 0"/>
            <geometry>
                <box size="0.8664830138598643 0.4865887623536186 0.8426691282692352" />
            </geometry>
        </collision>
    </link>
    <joint name="Link2_Link3" type="revolute">
       <parent link="Link2"/>
       <child  link="Link3"/>
       <origin rpy="0 0 0" xyz="0.8664830138598643 0 0.0" />
     <axis xyz="0 1 0"/>
       <limit effort="0.0" lower="-3.14159" upper="3.14159" velocity="0.0"/>
    </joint>
    <link name="Link3">
        <inertial>
            <origin xyz="0.36628365715914724 0 0.4657802789953618" rpy="0 0 0"/>
            <mass value="1" />
            <inertia ixx="100" ixy="0" ixz="0" iyy="100" iyz="0" izz="100" />
        </inertial>
        <visual>
            <origin xyz="0.36628365715914724 0 0.4657802789953618" rpy="0 0 0"/>
            <geometry>
                <box size="0.7325673143182945 0.8311489860334728 0.9315605579907236" />
            </geometry>
            <material name="Blue">
                <color rgba="0 0.0 1.0 1.0"/>
            </material>
        </visual>
        <collision>
            <origin xyz="0.36628365715914724 0 0.4657802789953618" rpy="0 0 0"/>
            <geometry>
                <box size="0.7325673143182945 0.8311489860334728 0.9315605579907236" />
            </geometry>
        </collision>
    </link>
    <joint name="Link3_Link4" type="revolute">
       <parent link="Link3"/>
       <child  link="Link4"/>
       <origin rpy="0 0 0" xyz="0.0 0 0.9315605579907236" />
     <axis xyz="0 1 0"/>
       <limit effort="0.0" lower="-3.14159" upper="3.14159" velocity="0.0"/>
    </joint>
    <link name="Link4">
        <inertial>
            <origin xyz="-0.20494337435490056 0 -0.22747399433180882" rpy="0 0 0"/>
            <mass value="1" />
            <inertia ixx="100" ixy="0" ixz="0" iyy="100" iyz="0" izz="100" />
        </inertial>
        <visual>
            <origin xyz="-0.20494337435490056 0 -0.22747399433180882" rpy="0 0 0"/>
            <geometry>
                <box size="0.40988674870980113 0.9184124732151454 0.45494798866361763" />
            </geometry>
            <material name="Green">
                <color rgba="0 1.0 0.0 1.0"/>
            </material>
        </visual>
        <collision>
            <origin xyz="-0.20494337435490056 0 -0.22747399433180882" rpy="0 0 0"/>
            <geometry>
                <box size="0.40988674870980113 0.9184124732151454 0.45494798866361763" />
            </geometry>
        </collision>
    </link>
    <joint name="Link4_Link5" type="revolute">
       <parent link="Link4"/>
       <child  link="Link5"/>
       <origin rpy="0 0 0" xyz="0.0 0 0.0" />
     <axis xyz="0 1 0"/>
       <limit effort="0.0" lower="-3.14159" upper="3.14159" velocity="0.0"/>
    </joint>
    <link name="Link5">
        <inertial>
            <origin xyz="0.01675252453053716 0 0.01326291655718953" rpy="0 0 0"/>
            <mass value="1" />
            <inertia ixx="100" ixy="0" ixz="0" iyy="100" iyz="0" izz="100" />
        </inertial>
        <visual>
            <origin xyz="0.01675252453053716 0 0.01326291655718953" rpy="0 0 0"/>
            <geometry>
                <box size="0.03350504906107432 0.7857336550916547 0.02652583311437906" />
            </geometry>
            <material name="Green">
                <color rgba="0 1.0 0.0 1.0"/>
            </material>
        </visual>
        <collision>
            <origin xyz="0.01675252453053716 0 0.01326291655718953" rpy="0 0 0"/>
            <geometry>
                <box size="0.03350504906107432 0.7857336550916547 0.02652583311437906" />
            </geometry>
        </collision>
    </link>
</robot>