<robot name = "robot">
    <link name="Link0">
        <inertial>
            <origin xyz="0 0 2.3024825683009067" rpy="0 0 0"/>
            <mass value="1" />
            <inertia ixx="100" ixy="0" ixz="0" iyy="100" iyz="0" izz="100" />
        </inertial>
        <visual>
            <origin xyz="0 0 2.3024825683009067" rpy="0 0 0"/>
            <geometry>
                <box size="0.8797947927426556 0.49824806319806514 0.6049651366018132" />
            </geometry>
            <material name="Green">
                <color rgba="0 1.0 0.0 1.0"/>
            </material>
        </visual>
        <collision>
            <origin xyz="0 0 2.3024825683009067" rpy="0 0 0"/>
            <geometry>
                <box size="0.8797947927426556 0.49824806319806514 0.6049651366018132" />
            </geometry>
        </collision>
    </link>
    <joint name="Link0_Link1" type="revolute">
       <parent link="Link0"/>
       <child  link="Link1"/>
       <origin rpy="0 0 0" xyz="0 0.24912403159903257 2.6049651366018134" />
     <axis xyz="1 0 0"/>
       <limit effort="0.0" lower="-3.14159" upper="3.14159" velocity="0.0"/>
    </joint>
    <link name="Link1">
        <inertial>
            <origin xyz="0 0.24912403159903257 -0.3024825683009066" rpy="0 0 0"/>
            <mass value="1" />
            <inertia ixx="100" ixy="0" ixz="0" iyy="100" iyz="0" izz="100" />
        </inertial>
        <visual>
            <origin xyz="0 0.24912403159903257 -0.3024825683009066" rpy="0 0 0"/>
            <geometry>
                <box size="0.8797947927426556 0.49824806319806514 0.6049651366018132" />
            </geometry>
            <material name="Green">
                <color rgba="0 1.0 0.0 1.0"/>
            </material>
        </visual>
        <collision>
            <origin xyz="0 0.24912403159903257 -0.3024825683009066" rpy="0 0 0"/>
            <geometry>
                <box size="0.8797947927426556 0.49824806319806514 0.6049651366018132" />
            </geometry>
        </collision>
    </link>
    <joint name="Link1_Link2" type="revolute">
       <parent link="Link1"/>
       <child  link="Link2"/>
       <origin rpy="0 0 0" xyz="-0.4398973963713278 0.24912403159903257 0.0" />
     <axis xyz="0 1 0"/>
       <limit effort="0.0" lower="-3.14159" upper="3.14159" velocity="0.0"/>
    </joint>
    <link name="Link2">
        <inertial>
            <origin xyz="-0.18729588094948924 0 -0.4286633674613424" rpy="0 0 0"/>
            <mass value="1" />
            <inertia ixx="100" ixy="0" ixz="0" iyy="100" iyz="0" izz="100" />
        </inertial>
        <visual>
            <origin xyz="-0.18729588094948924 0 -0.4286633674613424" rpy="0 0 0"/>
            <geometry>
                <box size="0.37459176189897847 0.8895460336421804 0.8573267349226849" />
            </geometry>
            <material name="Blue">
                <color rgba="0 0.0 1.0 1.0"/>
            </material>
        </visual>
        <collision>
            <origin xyz="-0.18729588094948924 0 -0.4286633674613424" rpy="0 0 0"/>
            <geometry>
                <box size="0.37459176189897847 0.8895460336421804 0.8573267349226849" />
            </geometry>
        </collision>
    </link>
    <joint name="Link2_Link3" type="revolute">
       <parent link="Link2"/>
       <child  link="Link3"/>
       <origin rpy="0 0 0" xyz="-0.18729588094948924 0.4447730168210902 0.0" />
     <axis xyz="1 0 0"/>
       <limit effort="0.0" lower="-3.14159" upper="3.14159" velocity="0.0"/>
    </joint>
    <link name="Link3">
        <inertial>
            <origin xyz="0 0.2402193380120673 -0.40595202259793683" rpy="0 0 0"/>
            <mass value="1" />
            <inertia ixx="100" ixy="0" ixz="0" iyy="100" iyz="0" izz="100" />
        </inertial>
        <visual>
            <origin xyz="0 0.2402193380120673 -0.40595202259793683" rpy="0 0 0"/>
            <geometry>
                <box size="0.12760081633209008 0.4804386760241346 0.8119040451958737" />
            </geometry>
            <material name="Green">
                <color rgba="0 1.0 0.0 1.0"/>
            </material>
        </visual>
        <collision>
            <origin xyz="0 0.2402193380120673 -0.40595202259793683" rpy="0 0 0"/>
            <geometry>
                <box size="0.12760081633209008 0.4804386760241346 0.8119040451958737" />
            </geometry>
        </collision>
    </link>
    <joint name="Link3_Link4" type="revolute">
       <parent link="Link3"/>
       <child  link="Link4"/>
       <origin rpy="0 0 0" xyz="0 0.0 0.0" />
     <axis xyz="1 0 0"/>
       <limit effort="0.0" lower="-3.14159" upper="3.14159" velocity="0.0"/>
    </joint>
    <link name="Link4">
        <inertial>
            <origin xyz="0 -0.358875874200592 -0.07717338533997598" rpy="0 0 0"/>
            <mass value="1" />
            <inertia ixx="100" ixy="0" ixz="0" iyy="100" iyz="0" izz="100" />
        </inertial>
        <visual>
            <origin xyz="0 -0.358875874200592 -0.07717338533997598" rpy="0 0 0"/>
            <geometry>
                <box size="0.044443517826039725 0.717751748401184 0.15434677067995195" />
            </geometry>
            <material name="Blue">
                <color rgba="0 0.0 1.0 1.0"/>
            </material>
        </visual>
        <collision>
            <origin xyz="0 -0.358875874200592 -0.07717338533997598" rpy="0 0 0"/>
            <geometry>
                <box size="0.044443517826039725 0.717751748401184 0.15434677067995195" />
            </geometry>
        </collision>
    </link>
    <joint name="Link4_Link5" type="revolute">
       <parent link="Link4"/>
       <child  link="Link5"/>
       <origin rpy="0 0 0" xyz="0 0.0 0.0" />
     <axis xyz="1 0 0"/>
       <limit effort="0.0" lower="-3.14159" upper="3.14159" velocity="0.0"/>
    </joint>
    <link name="Link5">
        <inertial>
            <origin xyz="0 0.4342207071199008 0.206349256469244" rpy="0 0 0"/>
            <mass value="1" />
            <inertia ixx="100" ixy="0" ixz="0" iyy="100" iyz="0" izz="100" />
        </inertial>
        <visual>
            <origin xyz="0 0.4342207071199008 0.206349256469244" rpy="0 0 0"/>
            <geometry>
                <box size="0.7453528442367504 0.8684414142398016 0.412698512938488" />
            </geometry>
            <material name="Blue">
                <color rgba="0 0.0 1.0 1.0"/>
            </material>
        </visual>
        <collision>
            <origin xyz="0 0.4342207071199008 0.206349256469244" rpy="0 0 0"/>
            <geometry>
                <box size="0.7453528442367504 0.8684414142398016 0.412698512938488" />
            </geometry>
        </collision>
    </link>
</robot>