<robot name = "robot">
    <link name="Link0">
        <inertial>
            <origin xyz="0 0 2.2459822906955553" rpy="0 0 0"/>
            <mass value="1" />
            <inertia ixx="100" ixy="0" ixz="0" iyy="100" iyz="0" izz="100" />
        </inertial>
        <visual>
            <origin xyz="0 0 2.2459822906955553" rpy="0 0 0"/>
            <geometry>
                <box size="0.8053167530930019 0.347986772615974 0.49196458139111066" />
            </geometry>
            <material name="Green">
                <color rgba="0 1.0 0.0 1.0"/>
            </material>
        </visual>
        <collision>
            <origin xyz="0 0 2.2459822906955553" rpy="0 0 0"/>
            <geometry>
                <box size="0.8053167530930019 0.347986772615974 0.49196458139111066" />
            </geometry>
        </collision>
    </link>
    <joint name="Link0_Link1" type="revolute">
       <parent link="Link0"/>
       <child  link="Link1"/>
       <origin rpy="0 0 0" xyz="0 0.173993386307987 2.4919645813911107" />
     <axis xyz="1 0 0"/>
       <limit effort="0.0" lower="-3.14159" upper="3.14159" velocity="0.0"/>
    </joint>
    <link name="Link1">
        <inertial>
            <origin xyz="0 0.173993386307987 -0.24598229069555533" rpy="0 0 0"/>
            <mass value="1" />
            <inertia ixx="100" ixy="0" ixz="0" iyy="100" iyz="0" izz="100" />
        </inertial>
        <visual>
            <origin xyz="0 0.173993386307987 -0.24598229069555533" rpy="0 0 0"/>
            <geometry>
                <box size="0.8053167530930019 0.347986772615974 0.49196458139111066" />
            </geometry>
            <material name="Blue">
                <color rgba="0 0.0 1.0 1.0"/>
            </material>
        </visual>
        <collision>
            <origin xyz="0 0.173993386307987 -0.24598229069555533" rpy="0 0 0"/>
            <geometry>
                <box size="0.8053167530930019 0.347986772615974 0.49196458139111066" />
            </geometry>
        </collision>
    </link>
    <joint name="Link1_Link2" type="revolute">
       <parent link="Link1"/>
       <child  link="Link2"/>
       <origin rpy="0 0 0" xyz="0 0.347986772615974 0.0" />
     <axis xyz="1 0 0"/>
       <limit effort="0.0" lower="-3.14159" upper="3.14159" velocity="0.0"/>
    </joint>
    <link name="Link2">
        <inertial>
            <origin xyz="0 0.18660498213531374 -0.14298712900380978" rpy="0 0 0"/>
            <mass value="1" />
            <inertia ixx="100" ixy="0" ixz="0" iyy="100" iyz="0" izz="100" />
        </inertial>
        <visual>
            <origin xyz="0 0.18660498213531374 -0.14298712900380978" rpy="0 0 0"/>
            <geometry>
                <box size="0.9948310619688071 0.37320996427062747 0.28597425800761955" />
            </geometry>
            <material name="Blue">
                <color rgba="0 0.0 1.0 1.0"/>
            </material>
        </visual>
        <collision>
            <origin xyz="0 0.18660498213531374 -0.14298712900380978" rpy="0 0 0"/>
            <geometry>
                <box size="0.9948310619688071 0.37320996427062747 0.28597425800761955" />
            </geometry>
        </collision>
    </link>
    <joint name="Link2_Link3" type="revolute">
       <parent link="Link2"/>
       <child  link="Link3"/>
       <origin rpy="0 0 0" xyz="0 0.37320996427062747 0.0" />
     <axis xyz="1 0 0"/>
       <limit effort="0.0" lower="-3.14159" upper="3.14159" velocity="0.0"/>
    </joint>
    <link name="Link3">
        <inertial>
            <origin xyz="0 0.44927251402045765 0.49656178485905517" rpy="0 0 0"/>
            <mass value="1" />
            <inertia ixx="100" ixy="0" ixz="0" iyy="100" iyz="0" izz="100" />
        </inertial>
        <visual>
            <origin xyz="0 0.44927251402045765 0.49656178485905517" rpy="0 0 0"/>
            <geometry>
                <box size="0.29062639628032405 0.8985450280409153 0.9931235697181103" />
            </geometry>
            <material name="Green">
                <color rgba="0 1.0 0.0 1.0"/>
            </material>
        </visual>
        <collision>
            <origin xyz="0 0.44927251402045765 0.49656178485905517" rpy="0 0 0"/>
            <geometry>
                <box size="0.29062639628032405 0.8985450280409153 0.9931235697181103" />
            </geometry>
        </collision>
    </link>
    <joint name="Link3_Link4" type="revolute">
       <parent link="Link3"/>
       <child  link="Link4"/>
       <origin rpy="0 0 0" xyz="0 0.0 0.9931235697181103" />
     <axis xyz="1 0 0"/>
       <limit effort="0.0" lower="-3.14159" upper="3.14159" velocity="0.0"/>
    </joint>
    <link name="Link4">
        <inertial>
            <origin xyz="0 -0.158605882152218 0.27857817237507154" rpy="0 0 0"/>
            <mass value="1" />
            <inertia ixx="100" ixy="0" ixz="0" iyy="100" iyz="0" izz="100" />
        </inertial>
        <visual>
            <origin xyz="0 -0.158605882152218 0.27857817237507154" rpy="0 0 0"/>
            <geometry>
                <box size="0.4896111213153058 0.317211764304436 0.5571563447501431" />
            </geometry>
            <material name="Blue">
                <color rgba="0 0.0 1.0 1.0"/>
            </material>
        </visual>
        <collision>
            <origin xyz="0 -0.158605882152218 0.27857817237507154" rpy="0 0 0"/>
            <geometry>
                <box size="0.4896111213153058 0.317211764304436 0.5571563447501431" />
            </geometry>
        </collision>
    </link>
    <joint name="Link4_Link5" type="revolute">
       <parent link="Link4"/>
       <child  link="Link5"/>
       <origin rpy="0 0 0" xyz="-0.2448055606576529 -0.158605882152218 0.5571563447501431" />
     <axis xyz="0 1 0"/>
       <limit effort="0.0" lower="-3.14159" upper="3.14159" velocity="0.0"/>
    </joint>
    <link name="Link5">
        <inertial>
            <origin xyz="-0.23711716922422416 0 0.15980942444019314" rpy="0 0 0"/>
            <mass value="1" />
            <inertia ixx="100" ixy="0" ixz="0" iyy="100" iyz="0" izz="100" />
        </inertial>
        <visual>
            <origin xyz="-0.23711716922422416 0 0.15980942444019314" rpy="0 0 0"/>
            <geometry>
                <box size="0.4742343384484483 0.41183295049738067 0.3196188488803863" />
            </geometry>
            <material name="Blue">
                <color rgba="0 0.0 1.0 1.0"/>
            </material>
        </visual>
        <collision>
            <origin xyz="-0.23711716922422416 0 0.15980942444019314" rpy="0 0 0"/>
            <geometry>
                <box size="0.4742343384484483 0.41183295049738067 0.3196188488803863" />
            </geometry>
        </collision>
    </link>
    <joint name="Link5_Link6" type="revolute">
       <parent link="Link5"/>
       <child  link="Link6"/>
       <origin rpy="0 0 0" xyz="-0.23711716922422416 0.20591647524869033 0.3196188488803863" />
     <axis xyz="1 0 0"/>
       <limit effort="0.0" lower="-3.14159" upper="3.14159" velocity="0.0"/>
    </joint>
    <link name="Link6">
        <inertial>
            <origin xyz="0 0.12911978778583932 -0.4719109037101518" rpy="0 0 0"/>
            <mass value="1" />
            <inertia ixx="100" ixy="0" ixz="0" iyy="100" iyz="0" izz="100" />
        </inertial>
        <visual>
            <origin xyz="0 0.12911978778583932 -0.4719109037101518" rpy="0 0 0"/>
            <geometry>
                <box size="0.3122410902319981 0.25823957557167865 0.9438218074203036" />
            </geometry>
            <material name="Green">
                <color rgba="0 1.0 0.0 1.0"/>
            </material>
        </visual>
        <collision>
            <origin xyz="0 0.12911978778583932 -0.4719109037101518" rpy="0 0 0"/>
            <geometry>
                <box size="0.3122410902319981 0.25823957557167865 0.9438218074203036" />
            </geometry>
        </collision>
    </link>
</robot>