<robot name = "robot">
    <link name="Link0">
        <inertial>
            <origin xyz="0 0 2.281106567068827" rpy="0 0 0"/>
            <mass value="1" />
            <inertia ixx="100" ixy="0" ixz="0" iyy="100" iyz="0" izz="100" />
        </inertial>
        <visual>
            <origin xyz="0 0 2.281106567068827" rpy="0 0 0"/>
            <geometry>
                <box size="0.1337852587833097 0.7673085606512259 0.5622131341376534" />
            </geometry>
            <material name="Green">
                <color rgba="0 1.0 0.0 1.0"/>
            </material>
        </visual>
        <collision>
            <origin xyz="0 0 2.281106567068827" rpy="0 0 0"/>
            <geometry>
                <box size="0.1337852587833097 0.7673085606512259 0.5622131341376534" />
            </geometry>
        </collision>
    </link>
    <joint name="Link0_Link1" type="revolute">
       <parent link="Link0"/>
       <child  link="Link1"/>
       <origin rpy="0 0 0" xyz="0 0.38365428032561294 2.5622131341376533" />
     <axis xyz="1 0 0"/>
       <limit effort="0.0" lower="-3.14159" upper="3.14159" velocity="0.0"/>
    </joint>
    <link name="Link1">
        <inertial>
            <origin xyz="0 0.38365428032561294 -0.2811065670688267" rpy="0 0 0"/>
            <mass value="1" />
            <inertia ixx="100" ixy="0" ixz="0" iyy="100" iyz="0" izz="100" />
        </inertial>
        <visual>
            <origin xyz="0 0.38365428032561294 -0.2811065670688267" rpy="0 0 0"/>
            <geometry>
                <box size="0.1337852587833097 0.7673085606512259 0.5622131341376534" />
            </geometry>
            <material name="Blue">
                <color rgba="0 0.0 1.0 1.0"/>
            </material>
        </visual>
        <collision>
            <origin xyz="0 0.38365428032561294 -0.2811065670688267" rpy="0 0 0"/>
            <geometry>
                <box size="0.1337852587833097 0.7673085606512259 0.5622131341376534" />
            </geometry>
        </collision>
    </link>
    <joint name="Link1_Link2" type="revolute">
       <parent link="Link1"/>
       <child  link="Link2"/>
       <origin rpy="0 0 0" xyz="0.06689262939165486 0.38365428032561294 0.0" />
     <axis xyz="0 1 0"/>
       <limit effort="0.0" lower="-3.14159" upper="3.14159" velocity="0.0"/>
    </joint>
    <link name="Link2">
        <inertial>
            <origin xyz="0.09225590710773418 0 -0.3209731661723434" rpy="0 0 0"/>
            <mass value="1" />
            <inertia ixx="100" ixy="0" ixz="0" iyy="100" iyz="0" izz="100" />
        </inertial>
        <visual>
            <origin xyz="0.09225590710773418 0 -0.3209731661723434" rpy="0 0 0"/>
            <geometry>
                <box size="0.18451181421546836 0.0220091169657628 0.6419463323446868" />
            </geometry>
            <material name="Blue">
                <color rgba="0 0.0 1.0 1.0"/>
            </material>
        </visual>
        <collision>
            <origin xyz="0.09225590710773418 0 -0.3209731661723434" rpy="0 0 0"/>
            <geometry>
                <box size="0.18451181421546836 0.0220091169657628 0.6419463323446868" />
            </geometry>
        </collision>
    </link>
    <joint name="Link2_Link3" type="revolute">
       <parent link="Link2"/>
       <child  link="Link3"/>
       <origin rpy="0 0 0" xyz="0.18451181421546836 0 0.0" />
     <axis xyz="0 1 0"/>
       <limit effort="0.0" lower="-3.14159" upper="3.14159" velocity="0.0"/>
    </joint>
    <link name="Link3">
        <inertial>
            <origin xyz="0.11530833414884512 0 -0.41977213268243874" rpy="0 0 0"/>
            <mass value="1" />
            <inertia ixx="100" ixy="0" ixz="0" iyy="100" iyz="0" izz="100" />
        </inertial>
        <visual>
            <origin xyz="0.11530833414884512 0 -0.41977213268243874" rpy="0 0 0"/>
            <geometry>
                <box size="0.23061666829769023 0.8418153377808762 0.8395442653648775" />
            </geometry>
            <material name="Green">
                <color rgba="0 1.0 0.0 1.0"/>
            </material>
        </visual>
        <collision>
            <origin xyz="0.11530833414884512 0 -0.41977213268243874" rpy="0 0 0"/>
            <geometry>
                <box size="0.23061666829769023 0.8418153377808762 0.8395442653648775" />
            </geometry>
        </collision>
    </link>
    <joint name="Link3_Link4" type="revolute">
       <parent link="Link3"/>
       <child  link="Link4"/>
       <origin rpy="0 0 0" xyz="0.23061666829769023 0 0.0" />
     <axis xyz="0 1 0"/>
       <limit effort="0.0" lower="-3.14159" upper="3.14159" velocity="0.0"/>
    </joint>
    <link name="Link4">
        <inertial>
            <origin xyz="0.1461551773563951 0 -0.29983620372195346" rpy="0 0 0"/>
            <mass value="1" />
            <inertia ixx="100" ixy="0" ixz="0" iyy="100" iyz="0" izz="100" />
        </inertial>
        <visual>
            <origin xyz="0.1461551773563951 0 -0.29983620372195346" rpy="0 0 0"/>
            <geometry>
                <box size="0.2923103547127902 0.7186754307920735 0.5996724074439069" />
            </geometry>
            <material name="Blue">
                <color rgba="0 0.0 1.0 1.0"/>
            </material>
        </visual>
        <collision>
            <origin xyz="0.1461551773563951 0 -0.29983620372195346" rpy="0 0 0"/>
            <geometry>
                <box size="0.2923103547127902 0.7186754307920735 0.5996724074439069" />
            </geometry>
        </collision>
    </link>
    <joint name="Link4_Link5" type="revolute">
       <parent link="Link4"/>
       <child  link="Link5"/>
       <origin rpy="0 0 0" xyz="0.2923103547127902 0 0.0" />
     <axis xyz="0 1 0"/>
       <limit effort="0.0" lower="-3.14159" upper="3.14159" velocity="0.0"/>
    </joint>
    <link name="Link5">
        <inertial>
            <origin xyz="0.39580497828060257 0 -0.16473994680158188" rpy="0 0 0"/>
            <mass value="1" />
            <inertia ixx="100" ixy="0" ixz="0" iyy="100" iyz="0" izz="100" />
        </inertial>
        <visual>
            <origin xyz="0.39580497828060257 0 -0.16473994680158188" rpy="0 0 0"/>
            <geometry>
                <box size="0.7916099565612051 0.6407186190927718 0.32947989360316376" />
            </geometry>
            <material name="Green">
                <color rgba="0 1.0 0.0 1.0"/>
            </material>
        </visual>
        <collision>
            <origin xyz="0.39580497828060257 0 -0.16473994680158188" rpy="0 0 0"/>
            <geometry>
                <box size="0.7916099565612051 0.6407186190927718 0.32947989360316376" />
            </geometry>
        </collision>
    </link>
</robot>