<robot name = "robot">
    <link name="Link0">
        <inertial>
            <origin xyz="0 0 2.333952953064475" rpy="0 0 0"/>
            <mass value="1" />
            <inertia ixx="100" ixy="0" ixz="0" iyy="100" iyz="0" izz="100" />
        </inertial>
        <visual>
            <origin xyz="0 0 2.333952953064475" rpy="0 0 0"/>
            <geometry>
                <box size="0.6082111120663967 0.48519678120376797 0.6679059061289497" />
            </geometry>
            <material name="Green">
                <color rgba="0 1.0 0.0 1.0"/>
            </material>
        </visual>
        <collision>
            <origin xyz="0 0 2.333952953064475" rpy="0 0 0"/>
            <geometry>
                <box size="0.6082111120663967 0.48519678120376797 0.6679059061289497" />
            </geometry>
        </collision>
    </link>
    <joint name="Link0_Link1" type="revolute">
       <parent link="Link0"/>
       <child  link="Link1"/>
       <origin rpy="0 0 0" xyz="0 0.24259839060188398 2.66790590612895" />
     <axis xyz="1 0 0"/>
       <limit effort="0.0" lower="-3.14159" upper="3.14159" velocity="0.0"/>
    </joint>
    <link name="Link1">
        <inertial>
            <origin xyz="0 0.24259839060188398 -0.33395295306447487" rpy="0 0 0"/>
            <mass value="1" />
            <inertia ixx="100" ixy="0" ixz="0" iyy="100" iyz="0" izz="100" />
        </inertial>
        <visual>
            <origin xyz="0 0.24259839060188398 -0.33395295306447487" rpy="0 0 0"/>
            <geometry>
                <box size="0.6082111120663967 0.48519678120376797 0.6679059061289497" />
            </geometry>
            <material name="Green">
                <color rgba="0 1.0 0.0 1.0"/>
            </material>
        </visual>
        <collision>
            <origin xyz="0 0.24259839060188398 -0.33395295306447487" rpy="0 0 0"/>
            <geometry>
                <box size="0.6082111120663967 0.48519678120376797 0.6679059061289497" />
            </geometry>
        </collision>
    </link>
    <joint name="Link1_Link2" type="revolute">
       <parent link="Link1"/>
       <child  link="Link2"/>
       <origin rpy="0 0 0" xyz="-0.30410555603319833 0.24259839060188398 0.0" />
     <axis xyz="0 1 0"/>
       <limit effort="0.0" lower="-3.14159" upper="3.14159" velocity="0.0"/>
    </joint>
    <link name="Link2">
        <inertial>
            <origin xyz="-0.1652369828176793 0 0.25042862402585436" rpy="0 0 0"/>
            <mass value="1" />
            <inertia ixx="100" ixy="0" ixz="0" iyy="100" iyz="0" izz="100" />
        </inertial>
        <visual>
            <origin xyz="-0.1652369828176793 0 0.25042862402585436" rpy="0 0 0"/>
            <geometry>
                <box size="0.3304739656353586 0.9875994865386584 0.5008572480517087" />
            </geometry>
            <material name="Blue">
                <color rgba="0 0.0 1.0 1.0"/>
            </material>
        </visual>
        <collision>
            <origin xyz="-0.1652369828176793 0 0.25042862402585436" rpy="0 0 0"/>
            <geometry>
                <box size="0.3304739656353586 0.9875994865386584 0.5008572480517087" />
            </geometry>
        </collision>
    </link>
    <joint name="Link2_Link3" type="revolute">
       <parent link="Link2"/>
       <child  link="Link3"/>
       <origin rpy="0 0 0" xyz="-0.1652369828176793 0.4937997432693292 0.5008572480517087" />
     <axis xyz="1 0 0"/>
       <limit effort="0.0" lower="-3.14159" upper="3.14159" velocity="0.0"/>
    </joint>
    <link name="Link3">
        <inertial>
            <origin xyz="0 0.40001292055604387 -0.3236132574714077" rpy="0 0 0"/>
            <mass value="1" />
            <inertia ixx="100" ixy="0" ixz="0" iyy="100" iyz="0" izz="100" />
        </inertial>
        <visual>
            <origin xyz="0 0.40001292055604387 -0.3236132574714077" rpy="0 0 0"/>
            <geometry>
                <box size="0.3655422616819687 0.8000258411120877 0.6472265149428154" />
            </geometry>
            <material name="Blue">
                <color rgba="0 0.0 1.0 1.0"/>
            </material>
        </visual>
        <collision>
            <origin xyz="0 0.40001292055604387 -0.3236132574714077" rpy="0 0 0"/>
            <geometry>
                <box size="0.3655422616819687 0.8000258411120877 0.6472265149428154" />
            </geometry>
        </collision>
    </link>
    <joint name="Link3_Link4" type="revolute">
       <parent link="Link3"/>
       <child  link="Link4"/>
       <origin rpy="0 0 0" xyz="0 0.0 0.0" />
     <axis xyz="1 0 0"/>
       <limit effort="0.0" lower="-3.14159" upper="3.14159" velocity="0.0"/>
    </joint>
    <link name="Link4">
        <inertial>
            <origin xyz="0 -0.46404725472827163 0.40285395226876847" rpy="0 0 0"/>
            <mass value="1" />
            <inertia ixx="100" ixy="0" ixz="0" iyy="100" iyz="0" izz="100" />
        </inertial>
        <visual>
            <origin xyz="0 -0.46404725472827163 0.40285395226876847" rpy="0 0 0"/>
            <geometry>
                <box size="0.9303603445008753 0.9280945094565433 0.8057079045375369" />
            </geometry>
            <material name="Green">
                <color rgba="0 1.0 0.0 1.0"/>
            </material>
        </visual>
        <collision>
            <origin xyz="0 -0.46404725472827163 0.40285395226876847" rpy="0 0 0"/>
            <geometry>
                <box size="0.9303603445008753 0.9280945094565433 0.8057079045375369" />
            </geometry>
        </collision>
    </link>
    <joint name="Link4_Link5" type="revolute">
       <parent link="Link4"/>
       <child  link="Link5"/>
       <origin rpy="0 0 0" xyz="0 -0.9280945094565433 0.8057079045375369" />
     <axis xyz="1 0 0"/>
       <limit effort="0.0" lower="-3.14159" upper="3.14159" velocity="0.0"/>
    </joint>
    <link name="Link5">
        <inertial>
            <origin xyz="0 -0.47197759507834375 0.08932463175677025" rpy="0 0 0"/>
            <mass value="1" />
            <inertia ixx="100" ixy="0" ixz="0" iyy="100" iyz="0" izz="100" />
        </inertial>
        <visual>
            <origin xyz="0 -0.47197759507834375 0.08932463175677025" rpy="0 0 0"/>
            <geometry>
                <box size="0.3502546511096153 0.9439551901566875 0.1786492635135405" />
            </geometry>
            <material name="Blue">
                <color rgba="0 0.0 1.0 1.0"/>
            </material>
        </visual>
        <collision>
            <origin xyz="0 -0.47197759507834375 0.08932463175677025" rpy="0 0 0"/>
            <geometry>
                <box size="0.3502546511096153 0.9439551901566875 0.1786492635135405" />
            </geometry>
        </collision>
    </link>
</robot>