<robot name = "robot">
    <link name="Link0">
        <inertial>
            <origin xyz="0 0 2.0264254434158007" rpy="0 0 0"/>
            <mass value="1" />
            <inertia ixx="100" ixy="0" ixz="0" iyy="100" iyz="0" izz="100" />
        </inertial>
        <visual>
            <origin xyz="0 0 2.0264254434158007" rpy="0 0 0"/>
            <geometry>
                <box size="0.7094925722241349 0.0192191540994191 0.052850886831600996" />
            </geometry>
            <material name="Green">
                <color rgba="0 1.0 0.0 1.0"/>
            </material>
        </visual>
        <collision>
            <origin xyz="0 0 2.0264254434158007" rpy="0 0 0"/>
            <geometry>
                <box size="0.7094925722241349 0.0192191540994191 0.052850886831600996" />
            </geometry>
        </collision>
    </link>
    <joint name="Link0_Link1" type="revolute">
       <parent link="Link0"/>
       <child  link="Link1"/>
       <origin rpy="0 0 0" xyz="0 0.00960957704970955 2.052850886831601" />
     <axis xyz="1 0 0"/>
       <limit effort="0.0" lower="-3.14159" upper="3.14159" velocity="0.0"/>
    </joint>
    <link name="Link1">
        <inertial>
            <origin xyz="0 0.00960957704970955 -0.026425443415800498" rpy="0 0 0"/>
            <mass value="1" />
            <inertia ixx="100" ixy="0" ixz="0" iyy="100" iyz="0" izz="100" />
        </inertial>
        <visual>
            <origin xyz="0 0.00960957704970955 -0.026425443415800498" rpy="0 0 0"/>
            <geometry>
                <box size="0.7094925722241349 0.0192191540994191 0.052850886831600996" />
            </geometry>
            <material name="Blue">
                <color rgba="0 0.0 1.0 1.0"/>
            </material>
        </visual>
        <collision>
            <origin xyz="0 0.00960957704970955 -0.026425443415800498" rpy="0 0 0"/>
            <geometry>
                <box size="0.7094925722241349 0.0192191540994191 0.052850886831600996" />
            </geometry>
        </collision>
    </link>
    <joint name="Link1_Link2" type="revolute">
       <parent link="Link1"/>
       <child  link="Link2"/>
       <origin rpy="0 0 0" xyz="0.35474628611206743 0.00960957704970955 0.0" />
     <axis xyz="0 1 0"/>
       <limit effort="0.0" lower="-3.14159" upper="3.14159" velocity="0.0"/>
    </joint>
    <link name="Link2">
        <inertial>
            <origin xyz="0.3390064481480425 0 -0.20266342382672686" rpy="0 0 0"/>
            <mass value="1" />
            <inertia ixx="100" ixy="0" ixz="0" iyy="100" iyz="0" izz="100" />
        </inertial>
        <visual>
            <origin xyz="0.3390064481480425 0 -0.20266342382672686" rpy="0 0 0"/>
            <geometry>
                <box size="0.678012896296085 0.954807592386167 0.4053268476534537" />
            </geometry>
            <material name="Blue">
                <color rgba="0 0.0 1.0 1.0"/>
            </material>
        </visual>
        <collision>
            <origin xyz="0.3390064481480425 0 -0.20266342382672686" rpy="0 0 0"/>
            <geometry>
                <box size="0.678012896296085 0.954807592386167 0.4053268476534537" />
            </geometry>
        </collision>
    </link>
    <joint name="Link2_Link3" type="revolute">
       <parent link="Link2"/>
       <child  link="Link3"/>
       <origin rpy="0 0 0" xyz="0.3390064481480425 -0.4774037961930835 0.0" />
     <axis xyz="1 0 0"/>
       <limit effort="0.0" lower="-3.14159" upper="3.14159" velocity="0.0"/>
    </joint>
    <link name="Link3">
        <inertial>
            <origin xyz="0 -0.2722375305904861 -0.03075016227379762" rpy="0 0 0"/>
            <mass value="1" />
            <inertia ixx="100" ixy="0" ixz="0" iyy="100" iyz="0" izz="100" />
        </inertial>
        <visual>
            <origin xyz="0 -0.2722375305904861 -0.03075016227379762" rpy="0 0 0"/>
            <geometry>
                <box size="0.12558316148044035 0.5444750611809722 0.06150032454759524" />
            </geometry>
            <material name="Blue">
                <color rgba="0 0.0 1.0 1.0"/>
            </material>
        </visual>
        <collision>
            <origin xyz="0 -0.2722375305904861 -0.03075016227379762" rpy="0 0 0"/>
            <geometry>
                <box size="0.12558316148044035 0.5444750611809722 0.06150032454759524" />
            </geometry>
        </collision>
    </link>
    <joint name="Link3_Link4" type="revolute">
       <parent link="Link3"/>
       <child  link="Link4"/>
       <origin rpy="0 0 0" xyz="0 -0.5444750611809722 0.0" />
     <axis xyz="1 0 0"/>
       <limit effort="0.0" lower="-3.14159" upper="3.14159" velocity="0.0"/>
    </joint>
    <link name="Link4">
        <inertial>
            <origin xyz="0 -0.32012481306260715 -0.41584384137376645" rpy="0 0 0"/>
            <mass value="1" />
            <inertia ixx="100" ixy="0" ixz="0" iyy="100" iyz="0" izz="100" />
        </inertial>
        <visual>
            <origin xyz="0 -0.32012481306260715 -0.41584384137376645" rpy="0 0 0"/>
            <geometry>
                <box size="0.19969894389772813 0.6402496261252143 0.8316876827475329" />
            </geometry>
            <material name="Green">
                <color rgba="0 1.0 0.0 1.0"/>
            </material>
        </visual>
        <collision>
            <origin xyz="0 -0.32012481306260715 -0.41584384137376645" rpy="0 0 0"/>
            <geometry>
                <box size="0.19969894389772813 0.6402496261252143 0.8316876827475329" />
            </geometry>
        </collision>
    </link>
    <joint name="Link4_Link5" type="revolute">
       <parent link="Link4"/>
       <child  link="Link5"/>
       <origin rpy="0 0 0" xyz="0 0.0 0.0" />
     <axis xyz="1 0 0"/>
       <limit effort="0.0" lower="-3.14159" upper="3.14159" velocity="0.0"/>
    </joint>
    <link name="Link5">
        <inertial>
            <origin xyz="0 0.2591202932413014 -0.4895063165335737" rpy="0 0 0"/>
            <mass value="1" />
            <inertia ixx="100" ixy="0" ixz="0" iyy="100" iyz="0" izz="100" />
        </inertial>
        <visual>
            <origin xyz="0 0.2591202932413014 -0.4895063165335737" rpy="0 0 0"/>
            <geometry>
                <box size="0.7829019600627121 0.5182405864826028 0.9790126330671474" />
            </geometry>
            <material name="Green">
                <color rgba="0 1.0 0.0 1.0"/>
            </material>
        </visual>
        <collision>
            <origin xyz="0 0.2591202932413014 -0.4895063165335737" rpy="0 0 0"/>
            <geometry>
                <box size="0.7829019600627121 0.5182405864826028 0.9790126330671474" />
            </geometry>
        </collision>
    </link>
</robot>