<robot name = "robot">
    <link name="Link0">
        <inertial>
            <origin xyz="0 0 2.0034249315495978" rpy="0 0 0"/>
            <mass value="1" />
            <inertia ixx="100" ixy="0" ixz="0" iyy="100" iyz="0" izz="100" />
        </inertial>
        <visual>
            <origin xyz="0 0 2.0034249315495978" rpy="0 0 0"/>
            <geometry>
                <box size="0.5183279184124302 0.05829022659431771 0.006849863099195774" />
            </geometry>
            <material name="Green">
                <color rgba="0 1.0 0.0 1.0"/>
            </material>
        </visual>
        <collision>
            <origin xyz="0 0 2.0034249315495978" rpy="0 0 0"/>
            <geometry>
                <box size="0.5183279184124302 0.05829022659431771 0.006849863099195774" />
            </geometry>
        </collision>
    </link>
    <joint name="Link0_Link1" type="revolute">
       <parent link="Link0"/>
       <child  link="Link1"/>
       <origin rpy="0 0 0" xyz="0 0.029145113297158853 2.0068498630991956" />
     <axis xyz="1 0 0"/>
       <limit effort="0.0" lower="-3.14159" upper="3.14159" velocity="0.0"/>
    </joint>
    <link name="Link1">
        <inertial>
            <origin xyz="0 0.029145113297158853 -0.003424931549597887" rpy="0 0 0"/>
            <mass value="1" />
            <inertia ixx="100" ixy="0" ixz="0" iyy="100" iyz="0" izz="100" />
        </inertial>
        <visual>
            <origin xyz="0 0.029145113297158853 -0.003424931549597887" rpy="0 0 0"/>
            <geometry>
                <box size="0.5183279184124302 0.05829022659431771 0.006849863099195774" />
            </geometry>
            <material name="Blue">
                <color rgba="0 0.0 1.0 1.0"/>
            </material>
        </visual>
        <collision>
            <origin xyz="0 0.029145113297158853 -0.003424931549597887" rpy="0 0 0"/>
            <geometry>
                <box size="0.5183279184124302 0.05829022659431771 0.006849863099195774" />
            </geometry>
        </collision>
    </link>
    <joint name="Link1_Link2" type="revolute">
       <parent link="Link1"/>
       <child  link="Link2"/>
       <origin rpy="0 0 0" xyz="-0.2591639592062151 0.029145113297158853 0.0" />
     <axis xyz="0 1 0"/>
       <limit effort="0.0" lower="-3.14159" upper="3.14159" velocity="0.0"/>
    </joint>
    <link name="Link2">
        <inertial>
            <origin xyz="-0.2007124908733658 0 -0.14815036467720855" rpy="0 0 0"/>
            <mass value="1" />
            <inertia ixx="100" ixy="0" ixz="0" iyy="100" iyz="0" izz="100" />
        </inertial>
        <visual>
            <origin xyz="-0.2007124908733658 0 -0.14815036467720855" rpy="0 0 0"/>
            <geometry>
                <box size="0.4014249817467316 0.43486082941859616 0.2963007293544171" />
            </geometry>
            <material name="Blue">
                <color rgba="0 0.0 1.0 1.0"/>
            </material>
        </visual>
        <collision>
            <origin xyz="-0.2007124908733658 0 -0.14815036467720855" rpy="0 0 0"/>
            <geometry>
                <box size="0.4014249817467316 0.43486082941859616 0.2963007293544171" />
            </geometry>
        </collision>
    </link>
    <joint name="Link2_Link3" type="revolute">
       <parent link="Link2"/>
       <child  link="Link3"/>
       <origin rpy="0 0 0" xyz="0.0 0 0.0" />
     <axis xyz="0 1 0"/>
       <limit effort="0.0" lower="-3.14159" upper="3.14159" velocity="0.0"/>
    </joint>
    <link name="Link3">
        <inertial>
            <origin xyz="0.1774198054337413 0 0.1831609163390438" rpy="0 0 0"/>
            <mass value="1" />
            <inertia ixx="100" ixy="0" ixz="0" iyy="100" iyz="0" izz="100" />
        </inertial>
        <visual>
            <origin xyz="0.1774198054337413 0 0.1831609163390438" rpy="0 0 0"/>
            <geometry>
                <box size="0.3548396108674826 0.11613006690524263 0.3663218326780876" />
            </geometry>
            <material name="Green">
                <color rgba="0 1.0 0.0 1.0"/>
            </material>
        </visual>
        <collision>
            <origin xyz="0.1774198054337413 0 0.1831609163390438" rpy="0 0 0"/>
            <geometry>
                <box size="0.3548396108674826 0.11613006690524263 0.3663218326780876" />
            </geometry>
        </collision>
    </link>
    <joint name="Link3_Link4" type="revolute">
       <parent link="Link3"/>
       <child  link="Link4"/>
       <origin rpy="0 0 0" xyz="0.0 0 0.3663218326780876" />
     <axis xyz="0 1 0"/>
       <limit effort="0.0" lower="-3.14159" upper="3.14159" velocity="0.0"/>
    </joint>
    <link name="Link4">
        <inertial>
            <origin xyz="-0.4545825363499004 0 0.31309846136502323" rpy="0 0 0"/>
            <mass value="1" />
            <inertia ixx="100" ixy="0" ixz="0" iyy="100" iyz="0" izz="100" />
        </inertial>
        <visual>
            <origin xyz="-0.4545825363499004 0 0.31309846136502323" rpy="0 0 0"/>
            <geometry>
                <box size="0.9091650726998008 0.9169579398035062 0.6261969227300465" />
            </geometry>
            <material name="Blue">
                <color rgba="0 0.0 1.0 1.0"/>
            </material>
        </visual>
        <collision>
            <origin xyz="-0.4545825363499004 0 0.31309846136502323" rpy="0 0 0"/>
            <geometry>
                <box size="0.9091650726998008 0.9169579398035062 0.6261969227300465" />
            </geometry>
        </collision>
    </link>
    <joint name="Link4_Link5" type="revolute">
       <parent link="Link4"/>
       <child  link="Link5"/>
       <origin rpy="0 0 0" xyz="-0.9091650726998008 0 0.6261969227300465" />
     <axis xyz="0 1 0"/>
       <limit effort="0.0" lower="-3.14159" upper="3.14159" velocity="0.0"/>
    </joint>
    <link name="Link5">
        <inertial>
            <origin xyz="-0.14250807268775695 0 0.41693060463525744" rpy="0 0 0"/>
            <mass value="1" />
            <inertia ixx="100" ixy="0" ixz="0" iyy="100" iyz="0" izz="100" />
        </inertial>
        <visual>
            <origin xyz="-0.14250807268775695 0 0.41693060463525744" rpy="0 0 0"/>
            <geometry>
                <box size="0.2850161453755139 0.32684362275868295 0.8338612092705149" />
            </geometry>
            <material name="Green">
                <color rgba="0 1.0 0.0 1.0"/>
            </material>
        </visual>
        <collision>
            <origin xyz="-0.14250807268775695 0 0.41693060463525744" rpy="0 0 0"/>
            <geometry>
                <box size="0.2850161453755139 0.32684362275868295 0.8338612092705149" />
            </geometry>
        </collision>
    </link>
</robot>