<robot name = "robot">
    <link name="Link0">
        <inertial>
            <origin xyz="0 0 2.3738429566221115" rpy="0 0 0"/>
            <mass value="1" />
            <inertia ixx="100" ixy="0" ixz="0" iyy="100" iyz="0" izz="100" />
        </inertial>
        <visual>
            <origin xyz="0 0 2.3738429566221115" rpy="0 0 0"/>
            <geometry>
                <box size="0.18146175689982047 0.3491100096171038 0.7476859132442231" />
            </geometry>
            <material name="Green">
                <color rgba="0 1.0 0.0 1.0"/>
            </material>
        </visual>
        <collision>
            <origin xyz="0 0 2.3738429566221115" rpy="0 0 0"/>
            <geometry>
                <box size="0.18146175689982047 0.3491100096171038 0.7476859132442231" />
            </geometry>
        </collision>
    </link>
    <joint name="Link0_Link1" type="revolute">
       <parent link="Link0"/>
       <child  link="Link1"/>
       <origin rpy="0 0 0" xyz="0 0.1745550048085519 2.747685913244223" />
     <axis xyz="1 0 0"/>
       <limit effort="0.0" lower="-3.14159" upper="3.14159" velocity="0.0"/>
    </joint>
    <link name="Link1">
        <inertial>
            <origin xyz="0 0.1745550048085519 -0.37384295662211153" rpy="0 0 0"/>
            <mass value="1" />
            <inertia ixx="100" ixy="0" ixz="0" iyy="100" iyz="0" izz="100" />
        </inertial>
        <visual>
            <origin xyz="0 0.1745550048085519 -0.37384295662211153" rpy="0 0 0"/>
            <geometry>
                <box size="0.18146175689982047 0.3491100096171038 0.7476859132442231" />
            </geometry>
            <material name="Green">
                <color rgba="0 1.0 0.0 1.0"/>
            </material>
        </visual>
        <collision>
            <origin xyz="0 0.1745550048085519 -0.37384295662211153" rpy="0 0 0"/>
            <geometry>
                <box size="0.18146175689982047 0.3491100096171038 0.7476859132442231" />
            </geometry>
        </collision>
    </link>
    <joint name="Link1_Link2" type="revolute">
       <parent link="Link1"/>
       <child  link="Link2"/>
       <origin rpy="0 0 0" xyz="0 0.3491100096171038 0.0" />
     <axis xyz="1 0 0"/>
       <limit effort="0.0" lower="-3.14159" upper="3.14159" velocity="0.0"/>
    </joint>
    <link name="Link2">
        <inertial>
            <origin xyz="0 0.08730120736914426 0.36377322398707584" rpy="0 0 0"/>
            <mass value="1" />
            <inertia ixx="100" ixy="0" ixz="0" iyy="100" iyz="0" izz="100" />
        </inertial>
        <visual>
            <origin xyz="0 0.08730120736914426 0.36377322398707584" rpy="0 0 0"/>
            <geometry>
                <box size="0.6553920869433661 0.17460241473828852 0.7275464479741517" />
            </geometry>
            <material name="Green">
                <color rgba="0 1.0 0.0 1.0"/>
            </material>
        </visual>
        <collision>
            <origin xyz="0 0.08730120736914426 0.36377322398707584" rpy="0 0 0"/>
            <geometry>
                <box size="0.6553920869433661 0.17460241473828852 0.7275464479741517" />
            </geometry>
        </collision>
    </link>
    <joint name="Link2_Link3" type="revolute">
       <parent link="Link2"/>
       <child  link="Link3"/>
       <origin rpy="0 0 0" xyz="-0.3276960434716831 0.08730120736914426 0.7275464479741517" />
     <axis xyz="0 1 0"/>
       <limit effort="0.0" lower="-3.14159" upper="3.14159" velocity="0.0"/>
    </joint>
    <link name="Link3">
        <inertial>
            <origin xyz="-0.2160350989546318 0 -0.2188969941362578" rpy="0 0 0"/>
            <mass value="1" />
            <inertia ixx="100" ixy="0" ixz="0" iyy="100" iyz="0" izz="100" />
        </inertial>
        <visual>
            <origin xyz="-0.2160350989546318 0 -0.2188969941362578" rpy="0 0 0"/>
            <geometry>
                <box size="0.4320701979092636 0.24818607378425384 0.4377939882725156" />
            </geometry>
            <material name="Green">
                <color rgba="0 1.0 0.0 1.0"/>
            </material>
        </visual>
        <collision>
            <origin xyz="-0.2160350989546318 0 -0.2188969941362578" rpy="0 0 0"/>
            <geometry>
                <box size="0.4320701979092636 0.24818607378425384 0.4377939882725156" />
            </geometry>
        </collision>
    </link>
    <joint name="Link3_Link4" type="revolute">
       <parent link="Link3"/>
       <child  link="Link4"/>
       <origin rpy="0 0 0" xyz="0.0 0 0.0" />
     <axis xyz="0 1 0"/>
       <limit effort="0.0" lower="-3.14159" upper="3.14159" velocity="0.0"/>
    </joint>
    <link name="Link4">
        <inertial>
            <origin xyz="0.40342190177658144 0 -0.402379987338994" rpy="0 0 0"/>
            <mass value="1" />
            <inertia ixx="100" ixy="0" ixz="0" iyy="100" iyz="0" izz="100" />
        </inertial>
        <visual>
            <origin xyz="0.40342190177658144 0 -0.402379987338994" rpy="0 0 0"/>
            <geometry>
                <box size="0.8068438035531629 0.29425291077407323 0.804759974677988" />
            </geometry>
            <material name="Green">
                <color rgba="0 1.0 0.0 1.0"/>
            </material>
        </visual>
        <collision>
            <origin xyz="0.40342190177658144 0 -0.402379987338994" rpy="0 0 0"/>
            <geometry>
                <box size="0.8068438035531629 0.29425291077407323 0.804759974677988" />
            </geometry>
        </collision>
    </link>
</robot>