<robot name = "robot">
    <link name="Link0">
        <inertial>
            <origin xyz="0 0 2.0400691138233205" rpy="0 0 0"/>
            <mass value="1" />
            <inertia ixx="100" ixy="0" ixz="0" iyy="100" iyz="0" izz="100" />
        </inertial>
        <visual>
            <origin xyz="0 0 2.0400691138233205" rpy="0 0 0"/>
            <geometry>
                <box size="0.39252903796612026 0.38374898610418307 0.08013822764664136" />
            </geometry>
            <material name="Green">
                <color rgba="0 1.0 0.0 1.0"/>
            </material>
        </visual>
        <collision>
            <origin xyz="0 0 2.0400691138233205" rpy="0 0 0"/>
            <geometry>
                <box size="0.39252903796612026 0.38374898610418307 0.08013822764664136" />
            </geometry>
        </collision>
    </link>
    <joint name="Link0_Link1" type="revolute">
       <parent link="Link0"/>
       <child  link="Link1"/>
       <origin rpy="0 0 0" xyz="0 0.19187449305209153 2.0801382276466414" />
     <axis xyz="1 0 0"/>
       <limit effort="0.0" lower="-3.14159" upper="3.14159" velocity="0.0"/>
    </joint>
    <link name="Link1">
        <inertial>
            <origin xyz="0 0.19187449305209153 -0.04006911382332068" rpy="0 0 0"/>
            <mass value="1" />
            <inertia ixx="100" ixy="0" ixz="0" iyy="100" iyz="0" izz="100" />
        </inertial>
        <visual>
            <origin xyz="0 0.19187449305209153 -0.04006911382332068" rpy="0 0 0"/>
            <geometry>
                <box size="0.39252903796612026 0.38374898610418307 0.08013822764664136" />
            </geometry>
            <material name="Green">
                <color rgba="0 1.0 0.0 1.0"/>
            </material>
        </visual>
        <collision>
            <origin xyz="0 0.19187449305209153 -0.04006911382332068" rpy="0 0 0"/>
            <geometry>
                <box size="0.39252903796612026 0.38374898610418307 0.08013822764664136" />
            </geometry>
        </collision>
    </link>
    <joint name="Link1_Link2" type="revolute">
       <parent link="Link1"/>
       <child  link="Link2"/>
       <origin rpy="0 0 0" xyz="0 0.38374898610418307 0.0" />
     <axis xyz="1 0 0"/>
       <limit effort="0.0" lower="-3.14159" upper="3.14159" velocity="0.0"/>
    </joint>
    <link name="Link2">
        <inertial>
            <origin xyz="0 0.08754689067749333 -0.32524068326239525" rpy="0 0 0"/>
            <mass value="1" />
            <inertia ixx="100" ixy="0" ixz="0" iyy="100" iyz="0" izz="100" />
        </inertial>
        <visual>
            <origin xyz="0 0.08754689067749333 -0.32524068326239525" rpy="0 0 0"/>
            <geometry>
                <box size="0.23502550490452356 0.17509378135498666 0.6504813665247905" />
            </geometry>
            <material name="Green">
                <color rgba="0 1.0 0.0 1.0"/>
            </material>
        </visual>
        <collision>
            <origin xyz="0 0.08754689067749333 -0.32524068326239525" rpy="0 0 0"/>
            <geometry>
                <box size="0.23502550490452356 0.17509378135498666 0.6504813665247905" />
            </geometry>
        </collision>
    </link>
    <joint name="Link2_Link3" type="revolute">
       <parent link="Link2"/>
       <child  link="Link3"/>
       <origin rpy="0 0 0" xyz="0.11751275245226178 0.08754689067749333 0.0" />
     <axis xyz="0 1 0"/>
       <limit effort="0.0" lower="-3.14159" upper="3.14159" velocity="0.0"/>
    </joint>
    <link name="Link3">
        <inertial>
            <origin xyz="0.4286271989692706 0 -0.4810143428924183" rpy="0 0 0"/>
            <mass value="1" />
            <inertia ixx="100" ixy="0" ixz="0" iyy="100" iyz="0" izz="100" />
        </inertial>
        <visual>
            <origin xyz="0.4286271989692706 0 -0.4810143428924183" rpy="0 0 0"/>
            <geometry>
                <box size="0.8572543979385412 0.6567225748996557 0.9620286857848366" />
            </geometry>
            <material name="Blue">
                <color rgba="0 0.0 1.0 1.0"/>
            </material>
        </visual>
        <collision>
            <origin xyz="0.4286271989692706 0 -0.4810143428924183" rpy="0 0 0"/>
            <geometry>
                <box size="0.8572543979385412 0.6567225748996557 0.9620286857848366" />
            </geometry>
        </collision>
    </link>
    <joint name="Link3_Link4" type="revolute">
       <parent link="Link3"/>
       <child  link="Link4"/>
       <origin rpy="0 0 0" xyz="0.4286271989692706 -0.32836128744982784 0.0" />
     <axis xyz="1 0 0"/>
       <limit effort="0.0" lower="-3.14159" upper="3.14159" velocity="0.0"/>
    </joint>
    <link name="Link4">
        <inertial>
            <origin xyz="0 -0.20192058674756658 0.21367757289637823" rpy="0 0 0"/>
            <mass value="1" />
            <inertia ixx="100" ixy="0" ixz="0" iyy="100" iyz="0" izz="100" />
        </inertial>
        <visual>
            <origin xyz="0 -0.20192058674756658 0.21367757289637823" rpy="0 0 0"/>
            <geometry>
                <box size="0.68353296410432 0.40384117349513315 0.42735514579275646" />
            </geometry>
            <material name="Green">
                <color rgba="0 1.0 0.0 1.0"/>
            </material>
        </visual>
        <collision>
            <origin xyz="0 -0.20192058674756658 0.21367757289637823" rpy="0 0 0"/>
            <geometry>
                <box size="0.68353296410432 0.40384117349513315 0.42735514579275646" />
            </geometry>
        </collision>
    </link>
    <joint name="Link4_Link5" type="revolute">
       <parent link="Link4"/>
       <child  link="Link5"/>
       <origin rpy="0 0 0" xyz="0 0.0 0.42735514579275646" />
     <axis xyz="1 0 0"/>
       <limit effort="0.0" lower="-3.14159" upper="3.14159" velocity="0.0"/>
    </joint>
    <link name="Link5">
        <inertial>
            <origin xyz="0 0.4282784717324177 0.27967957643781916" rpy="0 0 0"/>
            <mass value="1" />
            <inertia ixx="100" ixy="0" ixz="0" iyy="100" iyz="0" izz="100" />
        </inertial>
        <visual>
            <origin xyz="0 0.4282784717324177 0.27967957643781916" rpy="0 0 0"/>
            <geometry>
                <box size="0.15267663116042562 0.8565569434648354 0.5593591528756383" />
            </geometry>
            <material name="Blue">
                <color rgba="0 0.0 1.0 1.0"/>
            </material>
        </visual>
        <collision>
            <origin xyz="0 0.4282784717324177 0.27967957643781916" rpy="0 0 0"/>
            <geometry>
                <box size="0.15267663116042562 0.8565569434648354 0.5593591528756383" />
            </geometry>
        </collision>
    </link>
</robot>