<robot name = "robot">
    <link name="Link0">
        <inertial>
            <origin xyz="0 0 2.044710513546004" rpy="0 0 0"/>
            <mass value="1" />
            <inertia ixx="100" ixy="0" ixz="0" iyy="100" iyz="0" izz="100" />
        </inertial>
        <visual>
            <origin xyz="0 0 2.044710513546004" rpy="0 0 0"/>
            <geometry>
                <box size="0.046313327754550215 0.49285648631067047 0.08942102709200805" />
            </geometry>
            <material name="Green">
                <color rgba="0 1.0 0.0 1.0"/>
            </material>
        </visual>
        <collision>
            <origin xyz="0 0 2.044710513546004" rpy="0 0 0"/>
            <geometry>
                <box size="0.046313327754550215 0.49285648631067047 0.08942102709200805" />
            </geometry>
        </collision>
    </link>
    <joint name="Link0_Link1" type="revolute">
       <parent link="Link0"/>
       <child  link="Link1"/>
       <origin rpy="0 0 0" xyz="0 0.24642824315533524 2.089421027092008" />
     <axis xyz="1 0 0"/>
       <limit effort="0.0" lower="-3.14159" upper="3.14159" velocity="0.0"/>
    </joint>
    <link name="Link1">
        <inertial>
            <origin xyz="0 0.24642824315533524 -0.04471051354600403" rpy="0 0 0"/>
            <mass value="1" />
            <inertia ixx="100" ixy="0" ixz="0" iyy="100" iyz="0" izz="100" />
        </inertial>
        <visual>
            <origin xyz="0 0.24642824315533524 -0.04471051354600403" rpy="0 0 0"/>
            <geometry>
                <box size="0.046313327754550215 0.49285648631067047 0.08942102709200805" />
            </geometry>
            <material name="Blue">
                <color rgba="0 0.0 1.0 1.0"/>
            </material>
        </visual>
        <collision>
            <origin xyz="0 0.24642824315533524 -0.04471051354600403" rpy="0 0 0"/>
            <geometry>
                <box size="0.046313327754550215 0.49285648631067047 0.08942102709200805" />
            </geometry>
        </collision>
    </link>
    <joint name="Link1_Link2" type="revolute">
       <parent link="Link1"/>
       <child  link="Link2"/>
       <origin rpy="0 0 0" xyz="-0.023156663877275108 0.24642824315533524 0.0" />
     <axis xyz="0 1 0"/>
       <limit effort="0.0" lower="-3.14159" upper="3.14159" velocity="0.0"/>
    </joint>
    <link name="Link2">
        <inertial>
            <origin xyz="-0.21079141869244122 0 -0.38945102905068457" rpy="0 0 0"/>
            <mass value="1" />
            <inertia ixx="100" ixy="0" ixz="0" iyy="100" iyz="0" izz="100" />
        </inertial>
        <visual>
            <origin xyz="-0.21079141869244122 0 -0.38945102905068457" rpy="0 0 0"/>
            <geometry>
                <box size="0.42158283738488245 0.731616550277733 0.7789020581013691" />
            </geometry>
            <material name="Blue">
                <color rgba="0 0.0 1.0 1.0"/>
            </material>
        </visual>
        <collision>
            <origin xyz="-0.21079141869244122 0 -0.38945102905068457" rpy="0 0 0"/>
            <geometry>
                <box size="0.42158283738488245 0.731616550277733 0.7789020581013691" />
            </geometry>
        </collision>
    </link>
    <joint name="Link2_Link3" type="revolute">
       <parent link="Link2"/>
       <child  link="Link3"/>
       <origin rpy="0 0 0" xyz="-0.42158283738488245 0 0.0" />
     <axis xyz="0 1 0"/>
       <limit effort="0.0" lower="-3.14159" upper="3.14159" velocity="0.0"/>
    </joint>
    <link name="Link3">
        <inertial>
            <origin xyz="-0.28383448511462717 0 0.43815739528034037" rpy="0 0 0"/>
            <mass value="1" />
            <inertia ixx="100" ixy="0" ixz="0" iyy="100" iyz="0" izz="100" />
        </inertial>
        <visual>
            <origin xyz="-0.28383448511462717 0 0.43815739528034037" rpy="0 0 0"/>
            <geometry>
                <box size="0.5676689702292543 0.7339237033469987 0.8763147905606807" />
            </geometry>
            <material name="Green">
                <color rgba="0 1.0 0.0 1.0"/>
            </material>
        </visual>
        <collision>
            <origin xyz="-0.28383448511462717 0 0.43815739528034037" rpy="0 0 0"/>
            <geometry>
                <box size="0.5676689702292543 0.7339237033469987 0.8763147905606807" />
            </geometry>
        </collision>
    </link>
    <joint name="Link3_Link4" type="revolute">
       <parent link="Link3"/>
       <child  link="Link4"/>
       <origin rpy="0 0 0" xyz="-0.28383448511462717 -0.3669618516734994 0.8763147905606807" />
     <axis xyz="1 0 0"/>
       <limit effort="0.0" lower="-3.14159" upper="3.14159" velocity="0.0"/>
    </joint>
    <link name="Link4">
        <inertial>
            <origin xyz="0 -0.011609003116990202 0.3003273490194309" rpy="0 0 0"/>
            <mass value="1" />
            <inertia ixx="100" ixy="0" ixz="0" iyy="100" iyz="0" izz="100" />
        </inertial>
        <visual>
            <origin xyz="0 -0.011609003116990202 0.3003273490194309" rpy="0 0 0"/>
            <geometry>
                <box size="0.20219601349431537 0.023218006233980404 0.6006546980388618" />
            </geometry>
            <material name="Blue">
                <color rgba="0 0.0 1.0 1.0"/>
            </material>
        </visual>
        <collision>
            <origin xyz="0 -0.011609003116990202 0.3003273490194309" rpy="0 0 0"/>
            <geometry>
                <box size="0.20219601349431537 0.023218006233980404 0.6006546980388618" />
            </geometry>
        </collision>
    </link>
</robot>