<robot name = "robot">
    <link name="Link0">
        <inertial>
            <origin xyz="0 0 2.3182005306930877" rpy="0 0 0"/>
            <mass value="1" />
            <inertia ixx="100" ixy="0" ixz="0" iyy="100" iyz="0" izz="100" />
        </inertial>
        <visual>
            <origin xyz="0 0 2.3182005306930877" rpy="0 0 0"/>
            <geometry>
                <box size="0.19493517370204272 0.5236421332538053 0.6364010613861752" />
            </geometry>
            <material name="Green">
                <color rgba="0 1.0 0.0 1.0"/>
            </material>
        </visual>
        <collision>
            <origin xyz="0 0 2.3182005306930877" rpy="0 0 0"/>
            <geometry>
                <box size="0.19493517370204272 0.5236421332538053 0.6364010613861752" />
            </geometry>
        </collision>
    </link>
    <joint name="Link0_Link1" type="revolute">
       <parent link="Link0"/>
       <child  link="Link1"/>
       <origin rpy="0 0 0" xyz="0 0.26182106662690263 2.6364010613861755" />
     <axis xyz="1 0 0"/>
       <limit effort="0.0" lower="-3.14159" upper="3.14159" velocity="0.0"/>
    </joint>
    <link name="Link1">
        <inertial>
            <origin xyz="0 0.26182106662690263 -0.3182005306930876" rpy="0 0 0"/>
            <mass value="1" />
            <inertia ixx="100" ixy="0" ixz="0" iyy="100" iyz="0" izz="100" />
        </inertial>
        <visual>
            <origin xyz="0 0.26182106662690263 -0.3182005306930876" rpy="0 0 0"/>
            <geometry>
                <box size="0.19493517370204272 0.5236421332538053 0.6364010613861752" />
            </geometry>
            <material name="Blue">
                <color rgba="0 0.0 1.0 1.0"/>
            </material>
        </visual>
        <collision>
            <origin xyz="0 0.26182106662690263 -0.3182005306930876" rpy="0 0 0"/>
            <geometry>
                <box size="0.19493517370204272 0.5236421332538053 0.6364010613861752" />
            </geometry>
        </collision>
    </link>
    <joint name="Link1_Link2" type="revolute">
       <parent link="Link1"/>
       <child  link="Link2"/>
       <origin rpy="0 0 0" xyz="0 0.5236421332538053 0.0" />
     <axis xyz="1 0 0"/>
       <limit effort="0.0" lower="-3.14159" upper="3.14159" velocity="0.0"/>
    </joint>
    <link name="Link2">
        <inertial>
            <origin xyz="0 0.29708288170458563 0.47872532188121203" rpy="0 0 0"/>
            <mass value="1" />
            <inertia ixx="100" ixy="0" ixz="0" iyy="100" iyz="0" izz="100" />
        </inertial>
        <visual>
            <origin xyz="0 0.29708288170458563 0.47872532188121203" rpy="0 0 0"/>
            <geometry>
                <box size="0.42716810231835756 0.5941657634091713 0.9574506437624241" />
            </geometry>
            <material name="Blue">
                <color rgba="0 0.0 1.0 1.0"/>
            </material>
        </visual>
        <collision>
            <origin xyz="0 0.29708288170458563 0.47872532188121203" rpy="0 0 0"/>
            <geometry>
                <box size="0.42716810231835756 0.5941657634091713 0.9574506437624241" />
            </geometry>
        </collision>
    </link>
    <joint name="Link2_Link3" type="revolute">
       <parent link="Link2"/>
       <child  link="Link3"/>
       <origin rpy="0 0 0" xyz="0 0.0 0.9574506437624241" />
     <axis xyz="1 0 0"/>
       <limit effort="0.0" lower="-3.14159" upper="3.14159" velocity="0.0"/>
    </joint>
    <link name="Link3">
        <inertial>
            <origin xyz="0 -0.0017002583633436985 0.14578571695309717" rpy="0 0 0"/>
            <mass value="1" />
            <inertia ixx="100" ixy="0" ixz="0" iyy="100" iyz="0" izz="100" />
        </inertial>
        <visual>
            <origin xyz="0 -0.0017002583633436985 0.14578571695309717" rpy="0 0 0"/>
            <geometry>
                <box size="0.36461439074153623 0.003400516726687397 0.29157143390619433" />
            </geometry>
            <material name="Blue">
                <color rgba="0 0.0 1.0 1.0"/>
            </material>
        </visual>
        <collision>
            <origin xyz="0 -0.0017002583633436985 0.14578571695309717" rpy="0 0 0"/>
            <geometry>
                <box size="0.36461439074153623 0.003400516726687397 0.29157143390619433" />
            </geometry>
        </collision>
    </link>
    <joint name="Link3_Link4" type="revolute">
       <parent link="Link3"/>
       <child  link="Link4"/>
       <origin rpy="0 0 0" xyz="0 0.0 0.29157143390619433" />
     <axis xyz="1 0 0"/>
       <limit effort="0.0" lower="-3.14159" upper="3.14159" velocity="0.0"/>
    </joint>
    <link name="Link4">
        <inertial>
            <origin xyz="0 0.029372998410366447 -0.39431866664424414" rpy="0 0 0"/>
            <mass value="1" />
            <inertia ixx="100" ixy="0" ixz="0" iyy="100" iyz="0" izz="100" />
        </inertial>
        <visual>
            <origin xyz="0 0.029372998410366447 -0.39431866664424414" rpy="0 0 0"/>
            <geometry>
                <box size="0.1514915094118401 0.05874599682073289 0.7886373332884883" />
            </geometry>
            <material name="Green">
                <color rgba="0 1.0 0.0 1.0"/>
            </material>
        </visual>
        <collision>
            <origin xyz="0 0.029372998410366447 -0.39431866664424414" rpy="0 0 0"/>
            <geometry>
                <box size="0.1514915094118401 0.05874599682073289 0.7886373332884883" />
            </geometry>
        </collision>
    </link>
    <joint name="Link4_Link5" type="revolute">
       <parent link="Link4"/>
       <child  link="Link5"/>
       <origin rpy="0 0 0" xyz="-0.07574575470592004 0.029372998410366447 0.0" />
     <axis xyz="0 1 0"/>
       <limit effort="0.0" lower="-3.14159" upper="3.14159" velocity="0.0"/>
    </joint>
    <link name="Link5">
        <inertial>
            <origin xyz="-0.0019070262042493735 0 0.48690767699379095" rpy="0 0 0"/>
            <mass value="1" />
            <inertia ixx="100" ixy="0" ixz="0" iyy="100" iyz="0" izz="100" />
        </inertial>
        <visual>
            <origin xyz="-0.0019070262042493735 0 0.48690767699379095" rpy="0 0 0"/>
            <geometry>
                <box size="0.003814052408498747 0.15635502845842075 0.9738153539875819" />
            </geometry>
            <material name="Blue">
                <color rgba="0 0.0 1.0 1.0"/>
            </material>
        </visual>
        <collision>
            <origin xyz="-0.0019070262042493735 0 0.48690767699379095" rpy="0 0 0"/>
            <geometry>
                <box size="0.003814052408498747 0.15635502845842075 0.9738153539875819" />
            </geometry>
        </collision>
    </link>
</robot>