<robot name = "robot">
    <link name="Link0">
        <inertial>
            <origin xyz="0 0 2.3233493048214227" rpy="0 0 0"/>
            <mass value="1" />
            <inertia ixx="100" ixy="0" ixz="0" iyy="100" iyz="0" izz="100" />
        </inertial>
        <visual>
            <origin xyz="0 0 2.3233493048214227" rpy="0 0 0"/>
            <geometry>
                <box size="0.599190951706165 0.38716889453531045 0.646698609642845" />
            </geometry>
            <material name="Green">
                <color rgba="0 1.0 0.0 1.0"/>
            </material>
        </visual>
        <collision>
            <origin xyz="0 0 2.3233493048214227" rpy="0 0 0"/>
            <geometry>
                <box size="0.599190951706165 0.38716889453531045 0.646698609642845" />
            </geometry>
        </collision>
    </link>
    <joint name="Link0_Link1" type="revolute">
       <parent link="Link0"/>
       <child  link="Link1"/>
       <origin rpy="0 0 0" xyz="0 0.19358444726765522 2.646698609642845" />
     <axis xyz="1 0 0"/>
       <limit effort="0.0" lower="-3.14159" upper="3.14159" velocity="0.0"/>
    </joint>
    <link name="Link1">
        <inertial>
            <origin xyz="0 0.19358444726765522 -0.3233493048214225" rpy="0 0 0"/>
            <mass value="1" />
            <inertia ixx="100" ixy="0" ixz="0" iyy="100" iyz="0" izz="100" />
        </inertial>
        <visual>
            <origin xyz="0 0.19358444726765522 -0.3233493048214225" rpy="0 0 0"/>
            <geometry>
                <box size="0.599190951706165 0.38716889453531045 0.646698609642845" />
            </geometry>
            <material name="Green">
                <color rgba="0 1.0 0.0 1.0"/>
            </material>
        </visual>
        <collision>
            <origin xyz="0 0.19358444726765522 -0.3233493048214225" rpy="0 0 0"/>
            <geometry>
                <box size="0.599190951706165 0.38716889453531045 0.646698609642845" />
            </geometry>
        </collision>
    </link>
    <joint name="Link1_Link2" type="revolute">
       <parent link="Link1"/>
       <child  link="Link2"/>
       <origin rpy="0 0 0" xyz="0 0.38716889453531045 0.0" />
     <axis xyz="1 0 0"/>
       <limit effort="0.0" lower="-3.14159" upper="3.14159" velocity="0.0"/>
    </joint>
    <link name="Link2">
        <inertial>
            <origin xyz="0 0.48215571443697014 0.3119677599321104" rpy="0 0 0"/>
            <mass value="1" />
            <inertia ixx="100" ixy="0" ixz="0" iyy="100" iyz="0" izz="100" />
        </inertial>
        <visual>
            <origin xyz="0 0.48215571443697014 0.3119677599321104" rpy="0 0 0"/>
            <geometry>
                <box size="0.8613587650704329 0.9643114288739403 0.6239355198642208" />
            </geometry>
            <material name="Blue">
                <color rgba="0 0.0 1.0 1.0"/>
            </material>
        </visual>
        <collision>
            <origin xyz="0 0.48215571443697014 0.3119677599321104" rpy="0 0 0"/>
            <geometry>
                <box size="0.8613587650704329 0.9643114288739403 0.6239355198642208" />
            </geometry>
        </collision>
    </link>
    <joint name="Link2_Link3" type="revolute">
       <parent link="Link2"/>
       <child  link="Link3"/>
       <origin rpy="0 0 0" xyz="0 0.9643114288739403 0.6239355198642208" />
     <axis xyz="1 0 0"/>
       <limit effort="0.0" lower="-3.14159" upper="3.14159" velocity="0.0"/>
    </joint>
    <link name="Link3">
        <inertial>
            <origin xyz="0 0.3187334967199374 0.01059366800084377" rpy="0 0 0"/>
            <mass value="1" />
            <inertia ixx="100" ixy="0" ixz="0" iyy="100" iyz="0" izz="100" />
        </inertial>
        <visual>
            <origin xyz="0 0.3187334967199374 0.01059366800084377" rpy="0 0 0"/>
            <geometry>
                <box size="0.1497630015540995 0.6374669934398748 0.02118733600168754" />
            </geometry>
            <material name="Green">
                <color rgba="0 1.0 0.0 1.0"/>
            </material>
        </visual>
        <collision>
            <origin xyz="0 0.3187334967199374 0.01059366800084377" rpy="0 0 0"/>
            <geometry>
                <box size="0.1497630015540995 0.6374669934398748 0.02118733600168754" />
            </geometry>
        </collision>
    </link>
    <joint name="Link3_Link4" type="revolute">
       <parent link="Link3"/>
       <child  link="Link4"/>
       <origin rpy="0 0 0" xyz="-0.07488150077704975 0.3187334967199374 0.02118733600168754" />
     <axis xyz="0 1 0"/>
       <limit effort="0.0" lower="-3.14159" upper="3.14159" velocity="0.0"/>
    </joint>
    <link name="Link4">
        <inertial>
            <origin xyz="-0.2963374587157195 0 0.3971766725411276" rpy="0 0 0"/>
            <mass value="1" />
            <inertia ixx="100" ixy="0" ixz="0" iyy="100" iyz="0" izz="100" />
        </inertial>
        <visual>
            <origin xyz="-0.2963374587157195 0 0.3971766725411276" rpy="0 0 0"/>
            <geometry>
                <box size="0.592674917431439 0.7168110323603205 0.7943533450822552" />
            </geometry>
            <material name="Green">
                <color rgba="0 1.0 0.0 1.0"/>
            </material>
        </visual>
        <collision>
            <origin xyz="-0.2963374587157195 0 0.3971766725411276" rpy="0 0 0"/>
            <geometry>
                <box size="0.592674917431439 0.7168110323603205 0.7943533450822552" />
            </geometry>
        </collision>
    </link>
</robot>