<robot name = "robot">
    <link name="Link0">
        <inertial>
            <origin xyz="0 0 2.335233442376823" rpy="0 0 0"/>
            <mass value="1" />
            <inertia ixx="100" ixy="0" ixz="0" iyy="100" iyz="0" izz="100" />
        </inertial>
        <visual>
            <origin xyz="0 0 2.335233442376823" rpy="0 0 0"/>
            <geometry>
                <box size="0.6792904451286326 0.926966373696853 0.6704668847536461" />
            </geometry>
            <material name="Green">
                <color rgba="0 1.0 0.0 1.0"/>
            </material>
        </visual>
        <collision>
            <origin xyz="0 0 2.335233442376823" rpy="0 0 0"/>
            <geometry>
                <box size="0.6792904451286326 0.926966373696853 0.6704668847536461" />
            </geometry>
        </collision>
    </link>
    <joint name="Link0_Link1" type="revolute">
       <parent link="Link0"/>
       <child  link="Link1"/>
       <origin rpy="0 0 0" xyz="0 0.4634831868484265 2.670466884753646" />
     <axis xyz="1 0 0"/>
       <limit effort="0.0" lower="-3.14159" upper="3.14159" velocity="0.0"/>
    </joint>
    <link name="Link1">
        <inertial>
            <origin xyz="0 0.4634831868484265 -0.33523344237682307" rpy="0 0 0"/>
            <mass value="1" />
            <inertia ixx="100" ixy="0" ixz="0" iyy="100" iyz="0" izz="100" />
        </inertial>
        <visual>
            <origin xyz="0 0.4634831868484265 -0.33523344237682307" rpy="0 0 0"/>
            <geometry>
                <box size="0.6792904451286326 0.926966373696853 0.6704668847536461" />
            </geometry>
            <material name="Blue">
                <color rgba="0 0.0 1.0 1.0"/>
            </material>
        </visual>
        <collision>
            <origin xyz="0 0.4634831868484265 -0.33523344237682307" rpy="0 0 0"/>
            <geometry>
                <box size="0.6792904451286326 0.926966373696853 0.6704668847536461" />
            </geometry>
        </collision>
    </link>
    <joint name="Link1_Link2" type="revolute">
       <parent link="Link1"/>
       <child  link="Link2"/>
       <origin rpy="0 0 0" xyz="-0.3396452225643163 0.4634831868484265 0.0" />
     <axis xyz="0 1 0"/>
       <limit effort="0.0" lower="-3.14159" upper="3.14159" velocity="0.0"/>
    </joint>
    <link name="Link2">
        <inertial>
            <origin xyz="-0.34644982160031795 0 -0.4005754841684861" rpy="0 0 0"/>
            <mass value="1" />
            <inertia ixx="100" ixy="0" ixz="0" iyy="100" iyz="0" izz="100" />
        </inertial>
        <visual>
            <origin xyz="-0.34644982160031795 0 -0.4005754841684861" rpy="0 0 0"/>
            <geometry>
                <box size="0.6928996432006359 0.8467611698419655 0.8011509683369722" />
            </geometry>
            <material name="Green">
                <color rgba="0 1.0 0.0 1.0"/>
            </material>
        </visual>
        <collision>
            <origin xyz="-0.34644982160031795 0 -0.4005754841684861" rpy="0 0 0"/>
            <geometry>
                <box size="0.6928996432006359 0.8467611698419655 0.8011509683369722" />
            </geometry>
        </collision>
    </link>
    <joint name="Link2_Link3" type="revolute">
       <parent link="Link2"/>
       <child  link="Link3"/>
       <origin rpy="0 0 0" xyz="0.0 0 0.0" />
     <axis xyz="0 1 0"/>
       <limit effort="0.0" lower="-3.14159" upper="3.14159" velocity="0.0"/>
    </joint>
    <link name="Link3">
        <inertial>
            <origin xyz="0.2159728621560032 0 0.36142143235268887" rpy="0 0 0"/>
            <mass value="1" />
            <inertia ixx="100" ixy="0" ixz="0" iyy="100" iyz="0" izz="100" />
        </inertial>
        <visual>
            <origin xyz="0.2159728621560032 0 0.36142143235268887" rpy="0 0 0"/>
            <geometry>
                <box size="0.4319457243120064 0.9650692005100823 0.7228428647053777" />
            </geometry>
            <material name="Blue">
                <color rgba="0 0.0 1.0 1.0"/>
            </material>
        </visual>
        <collision>
            <origin xyz="0.2159728621560032 0 0.36142143235268887" rpy="0 0 0"/>
            <geometry>
                <box size="0.4319457243120064 0.9650692005100823 0.7228428647053777" />
            </geometry>
        </collision>
    </link>
    <joint name="Link3_Link4" type="revolute">
       <parent link="Link3"/>
       <child  link="Link4"/>
       <origin rpy="0 0 0" xyz="0.0 0 0.7228428647053777" />
     <axis xyz="0 1 0"/>
       <limit effort="0.0" lower="-3.14159" upper="3.14159" velocity="0.0"/>
    </joint>
    <link name="Link4">
        <inertial>
            <origin xyz="-0.26146126313681733 0 0.0927545544553166" rpy="0 0 0"/>
            <mass value="1" />
            <inertia ixx="100" ixy="0" ixz="0" iyy="100" iyz="0" izz="100" />
        </inertial>
        <visual>
            <origin xyz="-0.26146126313681733 0 0.0927545544553166" rpy="0 0 0"/>
            <geometry>
                <box size="0.5229225262736347 0.5600622269296307 0.1855091089106332" />
            </geometry>
            <material name="Blue">
                <color rgba="0 0.0 1.0 1.0"/>
            </material>
        </visual>
        <collision>
            <origin xyz="-0.26146126313681733 0 0.0927545544553166" rpy="0 0 0"/>
            <geometry>
                <box size="0.5229225262736347 0.5600622269296307 0.1855091089106332" />
            </geometry>
        </collision>
    </link>
    <joint name="Link4_Link5" type="revolute">
       <parent link="Link4"/>
       <child  link="Link5"/>
       <origin rpy="0 0 0" xyz="-0.26146126313681733 0.28003111346481535 0.1855091089106332" />
     <axis xyz="1 0 0"/>
       <limit effort="0.0" lower="-3.14159" upper="3.14159" velocity="0.0"/>
    </joint>
    <link name="Link5">
        <inertial>
            <origin xyz="0 0.24273907484816892 -0.39531088714133744" rpy="0 0 0"/>
            <mass value="1" />
            <inertia ixx="100" ixy="0" ixz="0" iyy="100" iyz="0" izz="100" />
        </inertial>
        <visual>
            <origin xyz="0 0.24273907484816892 -0.39531088714133744" rpy="0 0 0"/>
            <geometry>
                <box size="0.7815282185689079 0.48547814969633785 0.7906217742826749" />
            </geometry>
            <material name="Green">
                <color rgba="0 1.0 0.0 1.0"/>
            </material>
        </visual>
        <collision>
            <origin xyz="0 0.24273907484816892 -0.39531088714133744" rpy="0 0 0"/>
            <geometry>
                <box size="0.7815282185689079 0.48547814969633785 0.7906217742826749" />
            </geometry>
        </collision>
    </link>
</robot>