<robot name = "robot">
    <link name="Link0">
        <inertial>
            <origin xyz="0 0 2.1527794689241837" rpy="0 0 0"/>
            <mass value="1" />
            <inertia ixx="100" ixy="0" ixz="0" iyy="100" iyz="0" izz="100" />
        </inertial>
        <visual>
            <origin xyz="0 0 2.1527794689241837" rpy="0 0 0"/>
            <geometry>
                <box size="0.3798454993175677 0.14363367154010598 0.30555893784836696" />
            </geometry>
            <material name="Green">
                <color rgba="0 1.0 0.0 1.0"/>
            </material>
        </visual>
        <collision>
            <origin xyz="0 0 2.1527794689241837" rpy="0 0 0"/>
            <geometry>
                <box size="0.3798454993175677 0.14363367154010598 0.30555893784836696" />
            </geometry>
        </collision>
    </link>
    <joint name="Link0_Link1" type="revolute">
       <parent link="Link0"/>
       <child  link="Link1"/>
       <origin rpy="0 0 0" xyz="0 0.07181683577005299 2.305558937848367" />
     <axis xyz="1 0 0"/>
       <limit effort="0.0" lower="-3.14159" upper="3.14159" velocity="0.0"/>
    </joint>
    <link name="Link1">
        <inertial>
            <origin xyz="0 0.07181683577005299 -0.15277946892418348" rpy="0 0 0"/>
            <mass value="1" />
            <inertia ixx="100" ixy="0" ixz="0" iyy="100" iyz="0" izz="100" />
        </inertial>
        <visual>
            <origin xyz="0 0.07181683577005299 -0.15277946892418348" rpy="0 0 0"/>
            <geometry>
                <box size="0.3798454993175677 0.14363367154010598 0.30555893784836696" />
            </geometry>
            <material name="Green">
                <color rgba="0 1.0 0.0 1.0"/>
            </material>
        </visual>
        <collision>
            <origin xyz="0 0.07181683577005299 -0.15277946892418348" rpy="0 0 0"/>
            <geometry>
                <box size="0.3798454993175677 0.14363367154010598 0.30555893784836696" />
            </geometry>
        </collision>
    </link>
    <joint name="Link1_Link2" type="revolute">
       <parent link="Link1"/>
       <child  link="Link2"/>
       <origin rpy="0 0 0" xyz="0 0.0 0.0" />
     <axis xyz="1 0 0"/>
       <limit effort="0.0" lower="-3.14159" upper="3.14159" velocity="0.0"/>
    </joint>
    <link name="Link2">
        <inertial>
            <origin xyz="0 -0.4651019249155335 -0.20358072798733107" rpy="0 0 0"/>
            <mass value="1" />
            <inertia ixx="100" ixy="0" ixz="0" iyy="100" iyz="0" izz="100" />
        </inertial>
        <visual>
            <origin xyz="0 -0.4651019249155335 -0.20358072798733107" rpy="0 0 0"/>
            <geometry>
                <box size="0.29313145778060334 0.930203849831067 0.40716145597466213" />
            </geometry>
            <material name="Blue">
                <color rgba="0 0.0 1.0 1.0"/>
            </material>
        </visual>
        <collision>
            <origin xyz="0 -0.4651019249155335 -0.20358072798733107" rpy="0 0 0"/>
            <geometry>
                <box size="0.29313145778060334 0.930203849831067 0.40716145597466213" />
            </geometry>
        </collision>
    </link>
    <joint name="Link2_Link3" type="revolute">
       <parent link="Link2"/>
       <child  link="Link3"/>
       <origin rpy="0 0 0" xyz="0.14656572889030167 -0.4651019249155335 0.0" />
     <axis xyz="0 1 0"/>
       <limit effort="0.0" lower="-3.14159" upper="3.14159" velocity="0.0"/>
    </joint>
    <link name="Link3">
        <inertial>
            <origin xyz="0.10175618324407171 0 -0.18925950732383245" rpy="0 0 0"/>
            <mass value="1" />
            <inertia ixx="100" ixy="0" ixz="0" iyy="100" iyz="0" izz="100" />
        </inertial>
        <visual>
            <origin xyz="0.10175618324407171 0 -0.18925950732383245" rpy="0 0 0"/>
            <geometry>
                <box size="0.20351236648814341 0.501340245167337 0.3785190146476649" />
            </geometry>
            <material name="Blue">
                <color rgba="0 0.0 1.0 1.0"/>
            </material>
        </visual>
        <collision>
            <origin xyz="0.10175618324407171 0 -0.18925950732383245" rpy="0 0 0"/>
            <geometry>
                <box size="0.20351236648814341 0.501340245167337 0.3785190146476649" />
            </geometry>
        </collision>
    </link>
    <joint name="Link3_Link4" type="revolute">
       <parent link="Link3"/>
       <child  link="Link4"/>
       <origin rpy="0 0 0" xyz="0.10175618324407171 0.2506701225836685 0.0" />
     <axis xyz="1 0 0"/>
       <limit effort="0.0" lower="-3.14159" upper="3.14159" velocity="0.0"/>
    </joint>
    <link name="Link4">
        <inertial>
            <origin xyz="0 0.18597761362354576 0.3866296847172989" rpy="0 0 0"/>
            <mass value="1" />
            <inertia ixx="100" ixy="0" ixz="0" iyy="100" iyz="0" izz="100" />
        </inertial>
        <visual>
            <origin xyz="0 0.18597761362354576 0.3866296847172989" rpy="0 0 0"/>
            <geometry>
                <box size="0.6728596031832934 0.3719552272470915 0.7732593694345978" />
            </geometry>
            <material name="Green">
                <color rgba="0 1.0 0.0 1.0"/>
            </material>
        </visual>
        <collision>
            <origin xyz="0 0.18597761362354576 0.3866296847172989" rpy="0 0 0"/>
            <geometry>
                <box size="0.6728596031832934 0.3719552272470915 0.7732593694345978" />
            </geometry>
        </collision>
    </link>
    <joint name="Link4_Link5" type="revolute">
       <parent link="Link4"/>
       <child  link="Link5"/>
       <origin rpy="0 0 0" xyz="0 0.3719552272470915 0.7732593694345978" />
     <axis xyz="1 0 0"/>
       <limit effort="0.0" lower="-3.14159" upper="3.14159" velocity="0.0"/>
    </joint>
    <link name="Link5">
        <inertial>
            <origin xyz="0 0.047829642515871684 -0.18452532463595844" rpy="0 0 0"/>
            <mass value="1" />
            <inertia ixx="100" ixy="0" ixz="0" iyy="100" iyz="0" izz="100" />
        </inertial>
        <visual>
            <origin xyz="0 0.047829642515871684 -0.18452532463595844" rpy="0 0 0"/>
            <geometry>
                <box size="0.1843124618963824 0.09565928503174337 0.3690506492719169" />
            </geometry>
            <material name="Blue">
                <color rgba="0 0.0 1.0 1.0"/>
            </material>
        </visual>
        <collision>
            <origin xyz="0 0.047829642515871684 -0.18452532463595844" rpy="0 0 0"/>
            <geometry>
                <box size="0.1843124618963824 0.09565928503174337 0.3690506492719169" />
            </geometry>
        </collision>
    </link>
    <joint name="Link5_Link6" type="revolute">
       <parent link="Link5"/>
       <child  link="Link6"/>
       <origin rpy="0 0 0" xyz="0.0921562309481912 0.047829642515871684 0.0" />
     <axis xyz="0 1 0"/>
       <limit effort="0.0" lower="-3.14159" upper="3.14159" velocity="0.0"/>
    </joint>
    <link name="Link6">
        <inertial>
            <origin xyz="0.17405366649634918 0 -0.3379463510555219" rpy="0 0 0"/>
            <mass value="1" />
            <inertia ixx="100" ixy="0" ixz="0" iyy="100" iyz="0" izz="100" />
        </inertial>
        <visual>
            <origin xyz="0.17405366649634918 0 -0.3379463510555219" rpy="0 0 0"/>
            <geometry>
                <box size="0.34810733299269836 0.6393717763098595 0.6758927021110438" />
            </geometry>
            <material name="Blue">
                <color rgba="0 0.0 1.0 1.0"/>
            </material>
        </visual>
        <collision>
            <origin xyz="0.17405366649634918 0 -0.3379463510555219" rpy="0 0 0"/>
            <geometry>
                <box size="0.34810733299269836 0.6393717763098595 0.6758927021110438" />
            </geometry>
        </collision>
    </link>
</robot>