<robot name = "robot">
    <link name="Link0">
        <inertial>
            <origin xyz="0 0 2.0938105171198456" rpy="0 0 0"/>
            <mass value="1" />
            <inertia ixx="100" ixy="0" ixz="0" iyy="100" iyz="0" izz="100" />
        </inertial>
        <visual>
            <origin xyz="0 0 2.0938105171198456" rpy="0 0 0"/>
            <geometry>
                <box size="0.1458893148301874 0.8473945390927132 0.1876210342396908" />
            </geometry>
            <material name="Green">
                <color rgba="0 1.0 0.0 1.0"/>
            </material>
        </visual>
        <collision>
            <origin xyz="0 0 2.0938105171198456" rpy="0 0 0"/>
            <geometry>
                <box size="0.1458893148301874 0.8473945390927132 0.1876210342396908" />
            </geometry>
        </collision>
    </link>
    <joint name="Link0_Link1" type="revolute">
       <parent link="Link0"/>
       <child  link="Link1"/>
       <origin rpy="0 0 0" xyz="0 0.4236972695463566 2.1876210342396907" />
     <axis xyz="1 0 0"/>
       <limit effort="0.0" lower="-3.14159" upper="3.14159" velocity="0.0"/>
    </joint>
    <link name="Link1">
        <inertial>
            <origin xyz="0 0.4236972695463566 -0.0938105171198454" rpy="0 0 0"/>
            <mass value="1" />
            <inertia ixx="100" ixy="0" ixz="0" iyy="100" iyz="0" izz="100" />
        </inertial>
        <visual>
            <origin xyz="0 0.4236972695463566 -0.0938105171198454" rpy="0 0 0"/>
            <geometry>
                <box size="0.1458893148301874 0.8473945390927132 0.1876210342396908" />
            </geometry>
            <material name="Blue">
                <color rgba="0 0.0 1.0 1.0"/>
            </material>
        </visual>
        <collision>
            <origin xyz="0 0.4236972695463566 -0.0938105171198454" rpy="0 0 0"/>
            <geometry>
                <box size="0.1458893148301874 0.8473945390927132 0.1876210342396908" />
            </geometry>
        </collision>
    </link>
    <joint name="Link1_Link2" type="revolute">
       <parent link="Link1"/>
       <child  link="Link2"/>
       <origin rpy="0 0 0" xyz="-0.0729446574150937 0.4236972695463566 0.0" />
     <axis xyz="0 1 0"/>
       <limit effort="0.0" lower="-3.14159" upper="3.14159" velocity="0.0"/>
    </joint>
    <link name="Link2">
        <inertial>
            <origin xyz="-0.47859449476040244 0 -0.19126026638207216" rpy="0 0 0"/>
            <mass value="1" />
            <inertia ixx="100" ixy="0" ixz="0" iyy="100" iyz="0" izz="100" />
        </inertial>
        <visual>
            <origin xyz="-0.47859449476040244 0 -0.19126026638207216" rpy="0 0 0"/>
            <geometry>
                <box size="0.9571889895208049 0.9619103573686371 0.3825205327641443" />
            </geometry>
            <material name="Green">
                <color rgba="0 1.0 0.0 1.0"/>
            </material>
        </visual>
        <collision>
            <origin xyz="-0.47859449476040244 0 -0.19126026638207216" rpy="0 0 0"/>
            <geometry>
                <box size="0.9571889895208049 0.9619103573686371 0.3825205327641443" />
            </geometry>
        </collision>
    </link>
    <joint name="Link2_Link3" type="revolute">
       <parent link="Link2"/>
       <child  link="Link3"/>
       <origin rpy="0 0 0" xyz="-0.9571889895208049 0 0.0" />
     <axis xyz="0 1 0"/>
       <limit effort="0.0" lower="-3.14159" upper="3.14159" velocity="0.0"/>
    </joint>
    <link name="Link3">
        <inertial>
            <origin xyz="-0.2774596186426847 0 -0.280630438538209" rpy="0 0 0"/>
            <mass value="1" />
            <inertia ixx="100" ixy="0" ixz="0" iyy="100" iyz="0" izz="100" />
        </inertial>
        <visual>
            <origin xyz="-0.2774596186426847 0 -0.280630438538209" rpy="0 0 0"/>
            <geometry>
                <box size="0.5549192372853694 0.6060940018124056 0.561260877076418" />
            </geometry>
            <material name="Green">
                <color rgba="0 1.0 0.0 1.0"/>
            </material>
        </visual>
        <collision>
            <origin xyz="-0.2774596186426847 0 -0.280630438538209" rpy="0 0 0"/>
            <geometry>
                <box size="0.5549192372853694 0.6060940018124056 0.561260877076418" />
            </geometry>
        </collision>
    </link>
    <joint name="Link3_Link4" type="revolute">
       <parent link="Link3"/>
       <child  link="Link4"/>
       <origin rpy="0 0 0" xyz="-0.5549192372853694 0 0.0" />
     <axis xyz="0 1 0"/>
       <limit effort="0.0" lower="-3.14159" upper="3.14159" velocity="0.0"/>
    </joint>
    <link name="Link4">
        <inertial>
            <origin xyz="-0.2567072583850247 0 0.46940182433724786" rpy="0 0 0"/>
            <mass value="1" />
            <inertia ixx="100" ixy="0" ixz="0" iyy="100" iyz="0" izz="100" />
        </inertial>
        <visual>
            <origin xyz="-0.2567072583850247 0 0.46940182433724786" rpy="0 0 0"/>
            <geometry>
                <box size="0.5134145167700493 0.8096849777810418 0.9388036486744957" />
            </geometry>
            <material name="Green">
                <color rgba="0 1.0 0.0 1.0"/>
            </material>
        </visual>
        <collision>
            <origin xyz="-0.2567072583850247 0 0.46940182433724786" rpy="0 0 0"/>
            <geometry>
                <box size="0.5134145167700493 0.8096849777810418 0.9388036486744957" />
            </geometry>
        </collision>
    </link>
</robot>