<robot name = "robot">
    <link name="Link0">
        <inertial>
            <origin xyz="0 0 2.0785936797175193" rpy="0 0 0"/>
            <mass value="1" />
            <inertia ixx="100" ixy="0" ixz="0" iyy="100" iyz="0" izz="100" />
        </inertial>
        <visual>
            <origin xyz="0 0 2.0785936797175193" rpy="0 0 0"/>
            <geometry>
                <box size="0.697764878469229 0.7340170307847725 0.1571873594350387" />
            </geometry>
            <material name="Green">
                <color rgba="0 1.0 0.0 1.0"/>
            </material>
        </visual>
        <collision>
            <origin xyz="0 0 2.0785936797175193" rpy="0 0 0"/>
            <geometry>
                <box size="0.697764878469229 0.7340170307847725 0.1571873594350387" />
            </geometry>
        </collision>
    </link>
    <joint name="Link0_Link1" type="revolute">
       <parent link="Link0"/>
       <child  link="Link1"/>
       <origin rpy="0 0 0" xyz="0 0.36700851539238627 2.1571873594350386" />
     <axis xyz="1 0 0"/>
       <limit effort="0.0" lower="-3.14159" upper="3.14159" velocity="0.0"/>
    </joint>
    <link name="Link1">
        <inertial>
            <origin xyz="0 0.36700851539238627 -0.07859367971751935" rpy="0 0 0"/>
            <mass value="1" />
            <inertia ixx="100" ixy="0" ixz="0" iyy="100" iyz="0" izz="100" />
        </inertial>
        <visual>
            <origin xyz="0 0.36700851539238627 -0.07859367971751935" rpy="0 0 0"/>
            <geometry>
                <box size="0.697764878469229 0.7340170307847725 0.1571873594350387" />
            </geometry>
            <material name="Green">
                <color rgba="0 1.0 0.0 1.0"/>
            </material>
        </visual>
        <collision>
            <origin xyz="0 0.36700851539238627 -0.07859367971751935" rpy="0 0 0"/>
            <geometry>
                <box size="0.697764878469229 0.7340170307847725 0.1571873594350387" />
            </geometry>
        </collision>
    </link>
    <joint name="Link1_Link2" type="revolute">
       <parent link="Link1"/>
       <child  link="Link2"/>
       <origin rpy="0 0 0" xyz="0.3488824392346145 0.36700851539238627 0.0" />
     <axis xyz="0 1 0"/>
       <limit effort="0.0" lower="-3.14159" upper="3.14159" velocity="0.0"/>
    </joint>
    <link name="Link2">
        <inertial>
            <origin xyz="0.3581519493252264 0 0.056721842330933525" rpy="0 0 0"/>
            <mass value="1" />
            <inertia ixx="100" ixy="0" ixz="0" iyy="100" iyz="0" izz="100" />
        </inertial>
        <visual>
            <origin xyz="0.3581519493252264 0 0.056721842330933525" rpy="0 0 0"/>
            <geometry>
                <box size="0.7163038986504529 0.9492971637273084 0.11344368466186705" />
            </geometry>
            <material name="Green">
                <color rgba="0 1.0 0.0 1.0"/>
            </material>
        </visual>
        <collision>
            <origin xyz="0.3581519493252264 0 0.056721842330933525" rpy="0 0 0"/>
            <geometry>
                <box size="0.7163038986504529 0.9492971637273084 0.11344368466186705" />
            </geometry>
        </collision>
    </link>
    <joint name="Link2_Link3" type="revolute">
       <parent link="Link2"/>
       <child  link="Link3"/>
       <origin rpy="0 0 0" xyz="0.7163038986504529 0 0.11344368466186705" />
     <axis xyz="0 1 0"/>
       <limit effort="0.0" lower="-3.14159" upper="3.14159" velocity="0.0"/>
    </joint>
    <link name="Link3">
        <inertial>
            <origin xyz="0.02828308635884058 0 0.031801820755589794" rpy="0 0 0"/>
            <mass value="1" />
            <inertia ixx="100" ixy="0" ixz="0" iyy="100" iyz="0" izz="100" />
        </inertial>
        <visual>
            <origin xyz="0.02828308635884058 0 0.031801820755589794" rpy="0 0 0"/>
            <geometry>
                <box size="0.05656617271768116 0.48519822942020363 0.06360364151117959" />
            </geometry>
            <material name="Blue">
                <color rgba="0 0.0 1.0 1.0"/>
            </material>
        </visual>
        <collision>
            <origin xyz="0.02828308635884058 0 0.031801820755589794" rpy="0 0 0"/>
            <geometry>
                <box size="0.05656617271768116 0.48519822942020363 0.06360364151117959" />
            </geometry>
        </collision>
    </link>
    <joint name="Link3_Link4" type="revolute">
       <parent link="Link3"/>
       <child  link="Link4"/>
       <origin rpy="0 0 0" xyz="0.0 0 0.06360364151117959" />
     <axis xyz="0 1 0"/>
       <limit effort="0.0" lower="-3.14159" upper="3.14159" velocity="0.0"/>
    </joint>
    <link name="Link4">
        <inertial>
            <origin xyz="-0.4338193499893807 0 0.3742346700797509" rpy="0 0 0"/>
            <mass value="1" />
            <inertia ixx="100" ixy="0" ixz="0" iyy="100" iyz="0" izz="100" />
        </inertial>
        <visual>
            <origin xyz="-0.4338193499893807 0 0.3742346700797509" rpy="0 0 0"/>
            <geometry>
                <box size="0.8676386999787614 0.9923623098903771 0.7484693401595018" />
            </geometry>
            <material name="Green">
                <color rgba="0 1.0 0.0 1.0"/>
            </material>
        </visual>
        <collision>
            <origin xyz="-0.4338193499893807 0 0.3742346700797509" rpy="0 0 0"/>
            <geometry>
                <box size="0.8676386999787614 0.9923623098903771 0.7484693401595018" />
            </geometry>
        </collision>
    </link>
    <joint name="Link4_Link5" type="revolute">
       <parent link="Link4"/>
       <child  link="Link5"/>
       <origin rpy="0 0 0" xyz="-0.8676386999787614 0 0.7484693401595018" />
     <axis xyz="0 1 0"/>
       <limit effort="0.0" lower="-3.14159" upper="3.14159" velocity="0.0"/>
    </joint>
    <link name="Link5">
        <inertial>
            <origin xyz="-0.2761295889964417 0 0.3984655485149211" rpy="0 0 0"/>
            <mass value="1" />
            <inertia ixx="100" ixy="0" ixz="0" iyy="100" iyz="0" izz="100" />
        </inertial>
        <visual>
            <origin xyz="-0.2761295889964417 0 0.3984655485149211" rpy="0 0 0"/>
            <geometry>
                <box size="0.5522591779928834 0.18872449792210744 0.7969310970298422" />
            </geometry>
            <material name="Blue">
                <color rgba="0 0.0 1.0 1.0"/>
            </material>
        </visual>
        <collision>
            <origin xyz="-0.2761295889964417 0 0.3984655485149211" rpy="0 0 0"/>
            <geometry>
                <box size="0.5522591779928834 0.18872449792210744 0.7969310970298422" />
            </geometry>
        </collision>
    </link>
    <joint name="Link5_Link6" type="revolute">
       <parent link="Link5"/>
       <child  link="Link6"/>
       <origin rpy="0 0 0" xyz="-0.2761295889964417 0.09436224896105372 0.7969310970298422" />
     <axis xyz="1 0 0"/>
       <limit effort="0.0" lower="-3.14159" upper="3.14159" velocity="0.0"/>
    </joint>
    <link name="Link6">
        <inertial>
            <origin xyz="0 0.44642030611785505 0.4409052482441468" rpy="0 0 0"/>
            <mass value="1" />
            <inertia ixx="100" ixy="0" ixz="0" iyy="100" iyz="0" izz="100" />
        </inertial>
        <visual>
            <origin xyz="0 0.44642030611785505 0.4409052482441468" rpy="0 0 0"/>
            <geometry>
                <box size="0.3111168328772973 0.8928406122357101 0.8818104964882936" />
            </geometry>
            <material name="Blue">
                <color rgba="0 0.0 1.0 1.0"/>
            </material>
        </visual>
        <collision>
            <origin xyz="0 0.44642030611785505 0.4409052482441468" rpy="0 0 0"/>
            <geometry>
                <box size="0.3111168328772973 0.8928406122357101 0.8818104964882936" />
            </geometry>
        </collision>
    </link>
</robot>