<robot name = "robot">
    <link name="Link0">
        <inertial>
            <origin xyz="0 0 2.384071228251003" rpy="0 0 0"/>
            <mass value="1" />
            <inertia ixx="100" ixy="0" ixz="0" iyy="100" iyz="0" izz="100" />
        </inertial>
        <visual>
            <origin xyz="0 0 2.384071228251003" rpy="0 0 0"/>
            <geometry>
                <box size="0.4567036764530207 0.6636852147485436 0.7681424565020061" />
            </geometry>
            <material name="Green">
                <color rgba="0 1.0 0.0 1.0"/>
            </material>
        </visual>
        <collision>
            <origin xyz="0 0 2.384071228251003" rpy="0 0 0"/>
            <geometry>
                <box size="0.4567036764530207 0.6636852147485436 0.7681424565020061" />
            </geometry>
        </collision>
    </link>
    <joint name="Link0_Link1" type="revolute">
       <parent link="Link0"/>
       <child  link="Link1"/>
       <origin rpy="0 0 0" xyz="0 0.3318426073742718 2.768142456502006" />
     <axis xyz="1 0 0"/>
       <limit effort="0.0" lower="-3.14159" upper="3.14159" velocity="0.0"/>
    </joint>
    <link name="Link1">
        <inertial>
            <origin xyz="0 0.3318426073742718 -0.38407122825100304" rpy="0 0 0"/>
            <mass value="1" />
            <inertia ixx="100" ixy="0" ixz="0" iyy="100" iyz="0" izz="100" />
        </inertial>
        <visual>
            <origin xyz="0 0.3318426073742718 -0.38407122825100304" rpy="0 0 0"/>
            <geometry>
                <box size="0.4567036764530207 0.6636852147485436 0.7681424565020061" />
            </geometry>
            <material name="Blue">
                <color rgba="0 0.0 1.0 1.0"/>
            </material>
        </visual>
        <collision>
            <origin xyz="0 0.3318426073742718 -0.38407122825100304" rpy="0 0 0"/>
            <geometry>
                <box size="0.4567036764530207 0.6636852147485436 0.7681424565020061" />
            </geometry>
        </collision>
    </link>
    <joint name="Link1_Link2" type="revolute">
       <parent link="Link1"/>
       <child  link="Link2"/>
       <origin rpy="0 0 0" xyz="0 0.6636852147485436 0.0" />
     <axis xyz="1 0 0"/>
       <limit effort="0.0" lower="-3.14159" upper="3.14159" velocity="0.0"/>
    </joint>
    <link name="Link2">
        <inertial>
            <origin xyz="0 0.3066605808032569 -0.07222541012223843" rpy="0 0 0"/>
            <mass value="1" />
            <inertia ixx="100" ixy="0" ixz="0" iyy="100" iyz="0" izz="100" />
        </inertial>
        <visual>
            <origin xyz="0 0.3066605808032569 -0.07222541012223843" rpy="0 0 0"/>
            <geometry>
                <box size="0.6201431966802806 0.6133211616065138 0.14445082024447686" />
            </geometry>
            <material name="Green">
                <color rgba="0 1.0 0.0 1.0"/>
            </material>
        </visual>
        <collision>
            <origin xyz="0 0.3066605808032569 -0.07222541012223843" rpy="0 0 0"/>
            <geometry>
                <box size="0.6201431966802806 0.6133211616065138 0.14445082024447686" />
            </geometry>
        </collision>
    </link>
    <joint name="Link2_Link3" type="revolute">
       <parent link="Link2"/>
       <child  link="Link3"/>
       <origin rpy="0 0 0" xyz="0 0.6133211616065138 0.0" />
     <axis xyz="1 0 0"/>
       <limit effort="0.0" lower="-3.14159" upper="3.14159" velocity="0.0"/>
    </joint>
    <link name="Link3">
        <inertial>
            <origin xyz="0 0.34490027318025446 -0.40454536292178495" rpy="0 0 0"/>
            <mass value="1" />
            <inertia ixx="100" ixy="0" ixz="0" iyy="100" iyz="0" izz="100" />
        </inertial>
        <visual>
            <origin xyz="0 0.34490027318025446 -0.40454536292178495" rpy="0 0 0"/>
            <geometry>
                <box size="0.12135197348703985 0.6898005463605089 0.8090907258435699" />
            </geometry>
            <material name="Green">
                <color rgba="0 1.0 0.0 1.0"/>
            </material>
        </visual>
        <collision>
            <origin xyz="0 0.34490027318025446 -0.40454536292178495" rpy="0 0 0"/>
            <geometry>
                <box size="0.12135197348703985 0.6898005463605089 0.8090907258435699" />
            </geometry>
        </collision>
    </link>
    <joint name="Link3_Link4" type="revolute">
       <parent link="Link3"/>
       <child  link="Link4"/>
       <origin rpy="0 0 0" xyz="-0.06067598674351993 0.34490027318025446 0.0" />
     <axis xyz="0 1 0"/>
       <limit effort="0.0" lower="-3.14159" upper="3.14159" velocity="0.0"/>
    </joint>
    <link name="Link4">
        <inertial>
            <origin xyz="-0.16546472161025555 0 -0.23765147440045598" rpy="0 0 0"/>
            <mass value="1" />
            <inertia ixx="100" ixy="0" ixz="0" iyy="100" iyz="0" izz="100" />
        </inertial>
        <visual>
            <origin xyz="-0.16546472161025555 0 -0.23765147440045598" rpy="0 0 0"/>
            <geometry>
                <box size="0.3309294432205111 0.9819456481363953 0.47530294880091195" />
            </geometry>
            <material name="Blue">
                <color rgba="0 0.0 1.0 1.0"/>
            </material>
        </visual>
        <collision>
            <origin xyz="-0.16546472161025555 0 -0.23765147440045598" rpy="0 0 0"/>
            <geometry>
                <box size="0.3309294432205111 0.9819456481363953 0.47530294880091195" />
            </geometry>
        </collision>
    </link>
    <joint name="Link4_Link5" type="revolute">
       <parent link="Link4"/>
       <child  link="Link5"/>
       <origin rpy="0 0 0" xyz="-0.3309294432205111 0 0.0" />
     <axis xyz="0 1 0"/>
       <limit effort="0.0" lower="-3.14159" upper="3.14159" velocity="0.0"/>
    </joint>
    <link name="Link5">
        <inertial>
            <origin xyz="-0.0039111203977261755 0 -0.1900289273246087" rpy="0 0 0"/>
            <mass value="1" />
            <inertia ixx="100" ixy="0" ixz="0" iyy="100" iyz="0" izz="100" />
        </inertial>
        <visual>
            <origin xyz="-0.0039111203977261755 0 -0.1900289273246087" rpy="0 0 0"/>
            <geometry>
                <box size="0.007822240795452351 0.5828986940108941 0.3800578546492174" />
            </geometry>
            <material name="Blue">
                <color rgba="0 0.0 1.0 1.0"/>
            </material>
        </visual>
        <collision>
            <origin xyz="-0.0039111203977261755 0 -0.1900289273246087" rpy="0 0 0"/>
            <geometry>
                <box size="0.007822240795452351 0.5828986940108941 0.3800578546492174" />
            </geometry>
        </collision>
    </link>
</robot>