<robot name = "robot">
    <link name="Link0">
        <inertial>
            <origin xyz="0 0 2.152766466714206" rpy="0 0 0"/>
            <mass value="1" />
            <inertia ixx="100" ixy="0" ixz="0" iyy="100" iyz="0" izz="100" />
        </inertial>
        <visual>
            <origin xyz="0 0 2.152766466714206" rpy="0 0 0"/>
            <geometry>
                <box size="0.3366627255015108 0.8809756605003488 0.30553293342841237" />
            </geometry>
            <material name="Green">
                <color rgba="0 1.0 0.0 1.0"/>
            </material>
        </visual>
        <collision>
            <origin xyz="0 0 2.152766466714206" rpy="0 0 0"/>
            <geometry>
                <box size="0.3366627255015108 0.8809756605003488 0.30553293342841237" />
            </geometry>
        </collision>
    </link>
    <joint name="Link0_Link1" type="revolute">
       <parent link="Link0"/>
       <child  link="Link1"/>
       <origin rpy="0 0 0" xyz="0 0.4404878302501744 2.3055329334284123" />
     <axis xyz="1 0 0"/>
       <limit effort="0.0" lower="-3.14159" upper="3.14159" velocity="0.0"/>
    </joint>
    <link name="Link1">
        <inertial>
            <origin xyz="0 0.4404878302501744 -0.15276646671420618" rpy="0 0 0"/>
            <mass value="1" />
            <inertia ixx="100" ixy="0" ixz="0" iyy="100" iyz="0" izz="100" />
        </inertial>
        <visual>
            <origin xyz="0 0.4404878302501744 -0.15276646671420618" rpy="0 0 0"/>
            <geometry>
                <box size="0.3366627255015108 0.8809756605003488 0.30553293342841237" />
            </geometry>
            <material name="Green">
                <color rgba="0 1.0 0.0 1.0"/>
            </material>
        </visual>
        <collision>
            <origin xyz="0 0.4404878302501744 -0.15276646671420618" rpy="0 0 0"/>
            <geometry>
                <box size="0.3366627255015108 0.8809756605003488 0.30553293342841237" />
            </geometry>
        </collision>
    </link>
    <joint name="Link1_Link2" type="revolute">
       <parent link="Link1"/>
       <child  link="Link2"/>
       <origin rpy="0 0 0" xyz="0 0.0 0.0" />
     <axis xyz="1 0 0"/>
       <limit effort="0.0" lower="-3.14159" upper="3.14159" velocity="0.0"/>
    </joint>
    <link name="Link2">
        <inertial>
            <origin xyz="0 -0.4860481228539364 0.2623841537907466" rpy="0 0 0"/>
            <mass value="1" />
            <inertia ixx="100" ixy="0" ixz="0" iyy="100" iyz="0" izz="100" />
        </inertial>
        <visual>
            <origin xyz="0 -0.4860481228539364 0.2623841537907466" rpy="0 0 0"/>
            <geometry>
                <box size="0.18395496869966022 0.9720962457078728 0.5247683075814932" />
            </geometry>
            <material name="Green">
                <color rgba="0 1.0 0.0 1.0"/>
            </material>
        </visual>
        <collision>
            <origin xyz="0 -0.4860481228539364 0.2623841537907466" rpy="0 0 0"/>
            <geometry>
                <box size="0.18395496869966022 0.9720962457078728 0.5247683075814932" />
            </geometry>
        </collision>
    </link>
    <joint name="Link2_Link3" type="revolute">
       <parent link="Link2"/>
       <child  link="Link3"/>
       <origin rpy="0 0 0" xyz="0.09197748434983011 -0.4860481228539364 0.5247683075814932" />
     <axis xyz="0 1 0"/>
       <limit effort="0.0" lower="-3.14159" upper="3.14159" velocity="0.0"/>
    </joint>
    <link name="Link3">
        <inertial>
            <origin xyz="0.3185399839433712 0 0.21917921365630855" rpy="0 0 0"/>
            <mass value="1" />
            <inertia ixx="100" ixy="0" ixz="0" iyy="100" iyz="0" izz="100" />
        </inertial>
        <visual>
            <origin xyz="0.3185399839433712 0 0.21917921365630855" rpy="0 0 0"/>
            <geometry>
                <box size="0.6370799678867424 0.0777282053080749 0.4383584273126171" />
            </geometry>
            <material name="Blue">
                <color rgba="0 0.0 1.0 1.0"/>
            </material>
        </visual>
        <collision>
            <origin xyz="0.3185399839433712 0 0.21917921365630855" rpy="0 0 0"/>
            <geometry>
                <box size="0.6370799678867424 0.0777282053080749 0.4383584273126171" />
            </geometry>
        </collision>
    </link>
    <joint name="Link3_Link4" type="revolute">
       <parent link="Link3"/>
       <child  link="Link4"/>
       <origin rpy="0 0 0" xyz="0.0 0 0.4383584273126171" />
     <axis xyz="0 1 0"/>
       <limit effort="0.0" lower="-3.14159" upper="3.14159" velocity="0.0"/>
    </joint>
    <link name="Link4">
        <inertial>
            <origin xyz="-0.2542593079054866 0 0.039282372775965024" rpy="0 0 0"/>
            <mass value="1" />
            <inertia ixx="100" ixy="0" ixz="0" iyy="100" iyz="0" izz="100" />
        </inertial>
        <visual>
            <origin xyz="-0.2542593079054866 0 0.039282372775965024" rpy="0 0 0"/>
            <geometry>
                <box size="0.5085186158109732 0.7927429735113782 0.07856474555193005" />
            </geometry>
            <material name="Green">
                <color rgba="0 1.0 0.0 1.0"/>
            </material>
        </visual>
        <collision>
            <origin xyz="-0.2542593079054866 0 0.039282372775965024" rpy="0 0 0"/>
            <geometry>
                <box size="0.5085186158109732 0.7927429735113782 0.07856474555193005" />
            </geometry>
        </collision>
    </link>
    <joint name="Link4_Link5" type="revolute">
       <parent link="Link4"/>
       <child  link="Link5"/>
       <origin rpy="0 0 0" xyz="-0.5085186158109732 0 0.07856474555193005" />
     <axis xyz="0 1 0"/>
       <limit effort="0.0" lower="-3.14159" upper="3.14159" velocity="0.0"/>
    </joint>
    <link name="Link5">
        <inertial>
            <origin xyz="-0.3374945680570614 0 -0.41258381410404843" rpy="0 0 0"/>
            <mass value="1" />
            <inertia ixx="100" ixy="0" ixz="0" iyy="100" iyz="0" izz="100" />
        </inertial>
        <visual>
            <origin xyz="-0.3374945680570614 0 -0.41258381410404843" rpy="0 0 0"/>
            <geometry>
                <box size="0.6749891361141228 0.8554829032951944 0.8251676282080969" />
            </geometry>
            <material name="Green">
                <color rgba="0 1.0 0.0 1.0"/>
            </material>
        </visual>
        <collision>
            <origin xyz="-0.3374945680570614 0 -0.41258381410404843" rpy="0 0 0"/>
            <geometry>
                <box size="0.6749891361141228 0.8554829032951944 0.8251676282080969" />
            </geometry>
        </collision>
    </link>
</robot>