<robot name = "robot">
    <link name="Link0">
        <inertial>
            <origin xyz="0 0 2.216194232758595" rpy="0 0 0"/>
            <mass value="1" />
            <inertia ixx="100" ixy="0" ixz="0" iyy="100" iyz="0" izz="100" />
        </inertial>
        <visual>
            <origin xyz="0 0 2.216194232758595" rpy="0 0 0"/>
            <geometry>
                <box size="0.9389587652182287 0.6908157760549498 0.43238846551718935" />
            </geometry>
            <material name="Green">
                <color rgba="0 1.0 0.0 1.0"/>
            </material>
        </visual>
        <collision>
            <origin xyz="0 0 2.216194232758595" rpy="0 0 0"/>
            <geometry>
                <box size="0.9389587652182287 0.6908157760549498 0.43238846551718935" />
            </geometry>
        </collision>
    </link>
    <joint name="Link0_Link1" type="revolute">
       <parent link="Link0"/>
       <child  link="Link1"/>
       <origin rpy="0 0 0" xyz="0 0.3454078880274749 2.4323884655171892" />
     <axis xyz="1 0 0"/>
       <limit effort="0.0" lower="-3.14159" upper="3.14159" velocity="0.0"/>
    </joint>
    <link name="Link1">
        <inertial>
            <origin xyz="0 0.3454078880274749 -0.21619423275859467" rpy="0 0 0"/>
            <mass value="1" />
            <inertia ixx="100" ixy="0" ixz="0" iyy="100" iyz="0" izz="100" />
        </inertial>
        <visual>
            <origin xyz="0 0.3454078880274749 -0.21619423275859467" rpy="0 0 0"/>
            <geometry>
                <box size="0.9389587652182287 0.6908157760549498 0.43238846551718935" />
            </geometry>
            <material name="Green">
                <color rgba="0 1.0 0.0 1.0"/>
            </material>
        </visual>
        <collision>
            <origin xyz="0 0.3454078880274749 -0.21619423275859467" rpy="0 0 0"/>
            <geometry>
                <box size="0.9389587652182287 0.6908157760549498 0.43238846551718935" />
            </geometry>
        </collision>
    </link>
    <joint name="Link1_Link2" type="revolute">
       <parent link="Link1"/>
       <child  link="Link2"/>
       <origin rpy="0 0 0" xyz="0 0.6908157760549498 0.0" />
     <axis xyz="1 0 0"/>
       <limit effort="0.0" lower="-3.14159" upper="3.14159" velocity="0.0"/>
    </joint>
    <link name="Link2">
        <inertial>
            <origin xyz="0 0.23006601111920566 -0.4188798435568264" rpy="0 0 0"/>
            <mass value="1" />
            <inertia ixx="100" ixy="0" ixz="0" iyy="100" iyz="0" izz="100" />
        </inertial>
        <visual>
            <origin xyz="0 0.23006601111920566 -0.4188798435568264" rpy="0 0 0"/>
            <geometry>
                <box size="0.8181474665679682 0.4601320222384113 0.8377596871136528" />
            </geometry>
            <material name="Blue">
                <color rgba="0 0.0 1.0 1.0"/>
            </material>
        </visual>
        <collision>
            <origin xyz="0 0.23006601111920566 -0.4188798435568264" rpy="0 0 0"/>
            <geometry>
                <box size="0.8181474665679682 0.4601320222384113 0.8377596871136528" />
            </geometry>
        </collision>
    </link>
    <joint name="Link2_Link3" type="revolute">
       <parent link="Link2"/>
       <child  link="Link3"/>
       <origin rpy="0 0 0" xyz="0 0.4601320222384113 0.0" />
     <axis xyz="1 0 0"/>
       <limit effort="0.0" lower="-3.14159" upper="3.14159" velocity="0.0"/>
    </joint>
    <link name="Link3">
        <inertial>
            <origin xyz="0 0.010526319302213871 -0.2250134962045232" rpy="0 0 0"/>
            <mass value="1" />
            <inertia ixx="100" ixy="0" ixz="0" iyy="100" iyz="0" izz="100" />
        </inertial>
        <visual>
            <origin xyz="0 0.010526319302213871 -0.2250134962045232" rpy="0 0 0"/>
            <geometry>
                <box size="0.35342425812288203 0.021052638604427742 0.4500269924090464" />
            </geometry>
            <material name="Blue">
                <color rgba="0 0.0 1.0 1.0"/>
            </material>
        </visual>
        <collision>
            <origin xyz="0 0.010526319302213871 -0.2250134962045232" rpy="0 0 0"/>
            <geometry>
                <box size="0.35342425812288203 0.021052638604427742 0.4500269924090464" />
            </geometry>
        </collision>
    </link>
    <joint name="Link3_Link4" type="revolute">
       <parent link="Link3"/>
       <child  link="Link4"/>
       <origin rpy="0 0 0" xyz="-0.17671212906144101 0.010526319302213871 0.0" />
     <axis xyz="0 1 0"/>
       <limit effort="0.0" lower="-3.14159" upper="3.14159" velocity="0.0"/>
    </joint>
    <link name="Link4">
        <inertial>
            <origin xyz="-0.19847623734731074 0 -0.03838596672433475" rpy="0 0 0"/>
            <mass value="1" />
            <inertia ixx="100" ixy="0" ixz="0" iyy="100" iyz="0" izz="100" />
        </inertial>
        <visual>
            <origin xyz="-0.19847623734731074 0 -0.03838596672433475" rpy="0 0 0"/>
            <geometry>
                <box size="0.39695247469462147 0.6198759211905653 0.0767719334486695" />
            </geometry>
            <material name="Green">
                <color rgba="0 1.0 0.0 1.0"/>
            </material>
        </visual>
        <collision>
            <origin xyz="-0.19847623734731074 0 -0.03838596672433475" rpy="0 0 0"/>
            <geometry>
                <box size="0.39695247469462147 0.6198759211905653 0.0767719334486695" />
            </geometry>
        </collision>
    </link>
</robot>