<robot name = "robot">
    <link name="Link0">
        <inertial>
            <origin xyz="0 0 2.3178432752514255" rpy="0 0 0"/>
            <mass value="1" />
            <inertia ixx="100" ixy="0" ixz="0" iyy="100" iyz="0" izz="100" />
        </inertial>
        <visual>
            <origin xyz="0 0 2.3178432752514255" rpy="0 0 0"/>
            <geometry>
                <box size="0.1308435702674341 0.8290634462446211 0.6356865505028509" />
            </geometry>
            <material name="Green">
                <color rgba="0 1.0 0.0 1.0"/>
            </material>
        </visual>
        <collision>
            <origin xyz="0 0 2.3178432752514255" rpy="0 0 0"/>
            <geometry>
                <box size="0.1308435702674341 0.8290634462446211 0.6356865505028509" />
            </geometry>
        </collision>
    </link>
    <joint name="Link0_Link1" type="revolute">
       <parent link="Link0"/>
       <child  link="Link1"/>
       <origin rpy="0 0 0" xyz="0 0.41453172312231057 2.635686550502851" />
     <axis xyz="1 0 0"/>
       <limit effort="0.0" lower="-3.14159" upper="3.14159" velocity="0.0"/>
    </joint>
    <link name="Link1">
        <inertial>
            <origin xyz="0 0.41453172312231057 -0.31784327525142547" rpy="0 0 0"/>
            <mass value="1" />
            <inertia ixx="100" ixy="0" ixz="0" iyy="100" iyz="0" izz="100" />
        </inertial>
        <visual>
            <origin xyz="0 0.41453172312231057 -0.31784327525142547" rpy="0 0 0"/>
            <geometry>
                <box size="0.1308435702674341 0.8290634462446211 0.6356865505028509" />
            </geometry>
            <material name="Blue">
                <color rgba="0 0.0 1.0 1.0"/>
            </material>
        </visual>
        <collision>
            <origin xyz="0 0.41453172312231057 -0.31784327525142547" rpy="0 0 0"/>
            <geometry>
                <box size="0.1308435702674341 0.8290634462446211 0.6356865505028509" />
            </geometry>
        </collision>
    </link>
    <joint name="Link1_Link2" type="revolute">
       <parent link="Link1"/>
       <child  link="Link2"/>
       <origin rpy="0 0 0" xyz="-0.06542178513371705 0.41453172312231057 0.0" />
     <axis xyz="0 1 0"/>
       <limit effort="0.0" lower="-3.14159" upper="3.14159" velocity="0.0"/>
    </joint>
    <link name="Link2">
        <inertial>
            <origin xyz="-0.4716615479918104 0 -0.1892487449705978" rpy="0 0 0"/>
            <mass value="1" />
            <inertia ixx="100" ixy="0" ixz="0" iyy="100" iyz="0" izz="100" />
        </inertial>
        <visual>
            <origin xyz="-0.4716615479918104 0 -0.1892487449705978" rpy="0 0 0"/>
            <geometry>
                <box size="0.9433230959836209 0.2702759336189129 0.3784974899411956" />
            </geometry>
            <material name="Green">
                <color rgba="0 1.0 0.0 1.0"/>
            </material>
        </visual>
        <collision>
            <origin xyz="-0.4716615479918104 0 -0.1892487449705978" rpy="0 0 0"/>
            <geometry>
                <box size="0.9433230959836209 0.2702759336189129 0.3784974899411956" />
            </geometry>
        </collision>
    </link>
    <joint name="Link2_Link3" type="revolute">
       <parent link="Link2"/>
       <child  link="Link3"/>
       <origin rpy="0 0 0" xyz="-0.4716615479918104 -0.13513796680945644 0.0" />
     <axis xyz="1 0 0"/>
       <limit effort="0.0" lower="-3.14159" upper="3.14159" velocity="0.0"/>
    </joint>
    <link name="Link3">
        <inertial>
            <origin xyz="0 -0.04572905830111179 -0.2659552394679016" rpy="0 0 0"/>
            <mass value="1" />
            <inertia ixx="100" ixy="0" ixz="0" iyy="100" iyz="0" izz="100" />
        </inertial>
        <visual>
            <origin xyz="0 -0.04572905830111179 -0.2659552394679016" rpy="0 0 0"/>
            <geometry>
                <box size="0.7499233165094313 0.09145811660222358 0.5319104789358032" />
            </geometry>
            <material name="Blue">
                <color rgba="0 0.0 1.0 1.0"/>
            </material>
        </visual>
        <collision>
            <origin xyz="0 -0.04572905830111179 -0.2659552394679016" rpy="0 0 0"/>
            <geometry>
                <box size="0.7499233165094313 0.09145811660222358 0.5319104789358032" />
            </geometry>
        </collision>
    </link>
    <joint name="Link3_Link4" type="revolute">
       <parent link="Link3"/>
       <child  link="Link4"/>
       <origin rpy="0 0 0" xyz="0.37496165825471567 -0.04572905830111179 0.0" />
     <axis xyz="0 1 0"/>
       <limit effort="0.0" lower="-3.14159" upper="3.14159" velocity="0.0"/>
    </joint>
    <link name="Link4">
        <inertial>
            <origin xyz="0.37628250987736866 0 -0.3528848094884681" rpy="0 0 0"/>
            <mass value="1" />
            <inertia ixx="100" ixy="0" ixz="0" iyy="100" iyz="0" izz="100" />
        </inertial>
        <visual>
            <origin xyz="0.37628250987736866 0 -0.3528848094884681" rpy="0 0 0"/>
            <geometry>
                <box size="0.7525650197547373 0.6224769437924857 0.7057696189769362" />
            </geometry>
            <material name="Blue">
                <color rgba="0 0.0 1.0 1.0"/>
            </material>
        </visual>
        <collision>
            <origin xyz="0.37628250987736866 0 -0.3528848094884681" rpy="0 0 0"/>
            <geometry>
                <box size="0.7525650197547373 0.6224769437924857 0.7057696189769362" />
            </geometry>
        </collision>
    </link>
</robot>