<robot name = "robot">
    <link name="Link0">
        <inertial>
            <origin xyz="0 0 2.26538036493572" rpy="0 0 0"/>
            <mass value="1" />
            <inertia ixx="100" ixy="0" ixz="0" iyy="100" iyz="0" izz="100" />
        </inertial>
        <visual>
            <origin xyz="0 0 2.26538036493572" rpy="0 0 0"/>
            <geometry>
                <box size="0.650207683182581 0.8030821412771889 0.53076072987144" />
            </geometry>
            <material name="Green">
                <color rgba="0 1.0 0.0 1.0"/>
            </material>
        </visual>
        <collision>
            <origin xyz="0 0 2.26538036493572" rpy="0 0 0"/>
            <geometry>
                <box size="0.650207683182581 0.8030821412771889 0.53076072987144" />
            </geometry>
        </collision>
    </link>
    <joint name="Link0_Link1" type="revolute">
       <parent link="Link0"/>
       <child  link="Link1"/>
       <origin rpy="0 0 0" xyz="0 0.40154107063859446 2.53076072987144" />
     <axis xyz="1 0 0"/>
       <limit effort="0.0" lower="-3.14159" upper="3.14159" velocity="0.0"/>
    </joint>
    <link name="Link1">
        <inertial>
            <origin xyz="0 0.40154107063859446 -0.26538036493572" rpy="0 0 0"/>
            <mass value="1" />
            <inertia ixx="100" ixy="0" ixz="0" iyy="100" iyz="0" izz="100" />
        </inertial>
        <visual>
            <origin xyz="0 0.40154107063859446 -0.26538036493572" rpy="0 0 0"/>
            <geometry>
                <box size="0.650207683182581 0.8030821412771889 0.53076072987144" />
            </geometry>
            <material name="Blue">
                <color rgba="0 0.0 1.0 1.0"/>
            </material>
        </visual>
        <collision>
            <origin xyz="0 0.40154107063859446 -0.26538036493572" rpy="0 0 0"/>
            <geometry>
                <box size="0.650207683182581 0.8030821412771889 0.53076072987144" />
            </geometry>
        </collision>
    </link>
    <joint name="Link1_Link2" type="revolute">
       <parent link="Link1"/>
       <child  link="Link2"/>
       <origin rpy="0 0 0" xyz="0 0.0 0.0" />
     <axis xyz="1 0 0"/>
       <limit effort="0.0" lower="-3.14159" upper="3.14159" velocity="0.0"/>
    </joint>
    <link name="Link2">
        <inertial>
            <origin xyz="0 -0.41794620353293127 -0.1461995069627665" rpy="0 0 0"/>
            <mass value="1" />
            <inertia ixx="100" ixy="0" ixz="0" iyy="100" iyz="0" izz="100" />
        </inertial>
        <visual>
            <origin xyz="0 -0.41794620353293127 -0.1461995069627665" rpy="0 0 0"/>
            <geometry>
                <box size="0.3800630700580949 0.8358924070658625 0.292399013925533" />
            </geometry>
            <material name="Blue">
                <color rgba="0 0.0 1.0 1.0"/>
            </material>
        </visual>
        <collision>
            <origin xyz="0 -0.41794620353293127 -0.1461995069627665" rpy="0 0 0"/>
            <geometry>
                <box size="0.3800630700580949 0.8358924070658625 0.292399013925533" />
            </geometry>
        </collision>
    </link>
    <joint name="Link2_Link3" type="revolute">
       <parent link="Link2"/>
       <child  link="Link3"/>
       <origin rpy="0 0 0" xyz="-0.19003153502904746 -0.41794620353293127 0.0" />
     <axis xyz="0 1 0"/>
       <limit effort="0.0" lower="-3.14159" upper="3.14159" velocity="0.0"/>
    </joint>
    <link name="Link3">
        <inertial>
            <origin xyz="-0.38331484191320386 0 -0.20328745433090067" rpy="0 0 0"/>
            <mass value="1" />
            <inertia ixx="100" ixy="0" ixz="0" iyy="100" iyz="0" izz="100" />
        </inertial>
        <visual>
            <origin xyz="-0.38331484191320386 0 -0.20328745433090067" rpy="0 0 0"/>
            <geometry>
                <box size="0.7666296838264077 0.42073506283928175 0.40657490866180135" />
            </geometry>
            <material name="Green">
                <color rgba="0 1.0 0.0 1.0"/>
            </material>
        </visual>
        <collision>
            <origin xyz="-0.38331484191320386 0 -0.20328745433090067" rpy="0 0 0"/>
            <geometry>
                <box size="0.7666296838264077 0.42073506283928175 0.40657490866180135" />
            </geometry>
        </collision>
    </link>
    <joint name="Link3_Link4" type="revolute">
       <parent link="Link3"/>
       <child  link="Link4"/>
       <origin rpy="0 0 0" xyz="-0.38331484191320386 0.21036753141964087 0.0" />
     <axis xyz="1 0 0"/>
       <limit effort="0.0" lower="-3.14159" upper="3.14159" velocity="0.0"/>
    </joint>
    <link name="Link4">
        <inertial>
            <origin xyz="0 0.3616776410668148 -0.0853719683526325" rpy="0 0 0"/>
            <mass value="1" />
            <inertia ixx="100" ixy="0" ixz="0" iyy="100" iyz="0" izz="100" />
        </inertial>
        <visual>
            <origin xyz="0 0.3616776410668148 -0.0853719683526325" rpy="0 0 0"/>
            <geometry>
                <box size="0.8702319932734951 0.7233552821336297 0.170743936705265" />
            </geometry>
            <material name="Blue">
                <color rgba="0 0.0 1.0 1.0"/>
            </material>
        </visual>
        <collision>
            <origin xyz="0 0.3616776410668148 -0.0853719683526325" rpy="0 0 0"/>
            <geometry>
                <box size="0.8702319932734951 0.7233552821336297 0.170743936705265" />
            </geometry>
        </collision>
    </link>
    <joint name="Link4_Link5" type="revolute">
       <parent link="Link4"/>
       <child  link="Link5"/>
       <origin rpy="0 0 0" xyz="0 0.7233552821336297 0.0" />
     <axis xyz="1 0 0"/>
       <limit effort="0.0" lower="-3.14159" upper="3.14159" velocity="0.0"/>
    </joint>
    <link name="Link5">
        <inertial>
            <origin xyz="0 0.2562819053673317 -0.22193121538094462" rpy="0 0 0"/>
            <mass value="1" />
            <inertia ixx="100" ixy="0" ixz="0" iyy="100" iyz="0" izz="100" />
        </inertial>
        <visual>
            <origin xyz="0 0.2562819053673317 -0.22193121538094462" rpy="0 0 0"/>
            <geometry>
                <box size="0.7687779913079895 0.5125638107346634 0.44386243076188925" />
            </geometry>
            <material name="Blue">
                <color rgba="0 0.0 1.0 1.0"/>
            </material>
        </visual>
        <collision>
            <origin xyz="0 0.2562819053673317 -0.22193121538094462" rpy="0 0 0"/>
            <geometry>
                <box size="0.7687779913079895 0.5125638107346634 0.44386243076188925" />
            </geometry>
        </collision>
    </link>
</robot>