<robot name = "robot">
    <link name="Link0">
        <inertial>
            <origin xyz="0 0 2.4045707015497886" rpy="0 0 0"/>
            <mass value="1" />
            <inertia ixx="100" ixy="0" ixz="0" iyy="100" iyz="0" izz="100" />
        </inertial>
        <visual>
            <origin xyz="0 0 2.4045707015497886" rpy="0 0 0"/>
            <geometry>
                <box size="0.24652131887921158 0.7448265580948322 0.8091414030995769" />
            </geometry>
            <material name="Green">
                <color rgba="0 1.0 0.0 1.0"/>
            </material>
        </visual>
        <collision>
            <origin xyz="0 0 2.4045707015497886" rpy="0 0 0"/>
            <geometry>
                <box size="0.24652131887921158 0.7448265580948322 0.8091414030995769" />
            </geometry>
        </collision>
    </link>
    <joint name="Link0_Link1" type="revolute">
       <parent link="Link0"/>
       <child  link="Link1"/>
       <origin rpy="0 0 0" xyz="0 0.3724132790474161 2.809141403099577" />
     <axis xyz="1 0 0"/>
       <limit effort="0.0" lower="-3.14159" upper="3.14159" velocity="0.0"/>
    </joint>
    <link name="Link1">
        <inertial>
            <origin xyz="0 0.3724132790474161 -0.40457070154978847" rpy="0 0 0"/>
            <mass value="1" />
            <inertia ixx="100" ixy="0" ixz="0" iyy="100" iyz="0" izz="100" />
        </inertial>
        <visual>
            <origin xyz="0 0.3724132790474161 -0.40457070154978847" rpy="0 0 0"/>
            <geometry>
                <box size="0.24652131887921158 0.7448265580948322 0.8091414030995769" />
            </geometry>
            <material name="Green">
                <color rgba="0 1.0 0.0 1.0"/>
            </material>
        </visual>
        <collision>
            <origin xyz="0 0.3724132790474161 -0.40457070154978847" rpy="0 0 0"/>
            <geometry>
                <box size="0.24652131887921158 0.7448265580948322 0.8091414030995769" />
            </geometry>
        </collision>
    </link>
    <joint name="Link1_Link2" type="revolute">
       <parent link="Link1"/>
       <child  link="Link2"/>
       <origin rpy="0 0 0" xyz="-0.12326065943960579 0.3724132790474161 0.0" />
     <axis xyz="0 1 0"/>
       <limit effort="0.0" lower="-3.14159" upper="3.14159" velocity="0.0"/>
    </joint>
    <link name="Link2">
        <inertial>
            <origin xyz="-0.04433919938642139 0 0.34717862109543374" rpy="0 0 0"/>
            <mass value="1" />
            <inertia ixx="100" ixy="0" ixz="0" iyy="100" iyz="0" izz="100" />
        </inertial>
        <visual>
            <origin xyz="-0.04433919938642139 0 0.34717862109543374" rpy="0 0 0"/>
            <geometry>
                <box size="0.08867839877284278 0.5984698686146543 0.6943572421908675" />
            </geometry>
            <material name="Blue">
                <color rgba="0 0.0 1.0 1.0"/>
            </material>
        </visual>
        <collision>
            <origin xyz="-0.04433919938642139 0 0.34717862109543374" rpy="0 0 0"/>
            <geometry>
                <box size="0.08867839877284278 0.5984698686146543 0.6943572421908675" />
            </geometry>
        </collision>
    </link>
    <joint name="Link2_Link3" type="revolute">
       <parent link="Link2"/>
       <child  link="Link3"/>
       <origin rpy="0 0 0" xyz="-0.04433919938642139 -0.29923493430732717 0.6943572421908675" />
     <axis xyz="1 0 0"/>
       <limit effort="0.0" lower="-3.14159" upper="3.14159" velocity="0.0"/>
    </joint>
    <link name="Link3">
        <inertial>
            <origin xyz="0 -0.04881029237403589 -0.036583749592684844" rpy="0 0 0"/>
            <mass value="1" />
            <inertia ixx="100" ixy="0" ixz="0" iyy="100" iyz="0" izz="100" />
        </inertial>
        <visual>
            <origin xyz="0 -0.04881029237403589 -0.036583749592684844" rpy="0 0 0"/>
            <geometry>
                <box size="0.8138362512096146 0.09762058474807178 0.07316749918536969" />
            </geometry>
            <material name="Blue">
                <color rgba="0 0.0 1.0 1.0"/>
            </material>
        </visual>
        <collision>
            <origin xyz="0 -0.04881029237403589 -0.036583749592684844" rpy="0 0 0"/>
            <geometry>
                <box size="0.8138362512096146 0.09762058474807178 0.07316749918536969" />
            </geometry>
        </collision>
    </link>
    <joint name="Link3_Link4" type="revolute">
       <parent link="Link3"/>
       <child  link="Link4"/>
       <origin rpy="0 0 0" xyz="0 -0.09762058474807178 0.0" />
     <axis xyz="1 0 0"/>
       <limit effort="0.0" lower="-3.14159" upper="3.14159" velocity="0.0"/>
    </joint>
    <link name="Link4">
        <inertial>
            <origin xyz="0 -0.33019900499307675 0.3330938048426652" rpy="0 0 0"/>
            <mass value="1" />
            <inertia ixx="100" ixy="0" ixz="0" iyy="100" iyz="0" izz="100" />
        </inertial>
        <visual>
            <origin xyz="0 -0.33019900499307675 0.3330938048426652" rpy="0 0 0"/>
            <geometry>
                <box size="0.07588266591808113 0.6603980099861535 0.6661876096853304" />
            </geometry>
            <material name="Blue">
                <color rgba="0 0.0 1.0 1.0"/>
            </material>
        </visual>
        <collision>
            <origin xyz="0 -0.33019900499307675 0.3330938048426652" rpy="0 0 0"/>
            <geometry>
                <box size="0.07588266591808113 0.6603980099861535 0.6661876096853304" />
            </geometry>
        </collision>
    </link>
</robot>