<robot name = "robot">
    <link name="Link0">
        <inertial>
            <origin xyz="0 0 2.294916947710009" rpy="0 0 0"/>
            <mass value="1" />
            <inertia ixx="100" ixy="0" ixz="0" iyy="100" iyz="0" izz="100" />
        </inertial>
        <visual>
            <origin xyz="0 0 2.294916947710009" rpy="0 0 0"/>
            <geometry>
                <box size="0.9382137846636243 0.694680362648391 0.589833895420018" />
            </geometry>
            <material name="Green">
                <color rgba="0 1.0 0.0 1.0"/>
            </material>
        </visual>
        <collision>
            <origin xyz="0 0 2.294916947710009" rpy="0 0 0"/>
            <geometry>
                <box size="0.9382137846636243 0.694680362648391 0.589833895420018" />
            </geometry>
        </collision>
    </link>
    <joint name="Link0_Link1" type="revolute">
       <parent link="Link0"/>
       <child  link="Link1"/>
       <origin rpy="0 0 0" xyz="0 0.3473401813241955 2.5898338954200177" />
     <axis xyz="1 0 0"/>
       <limit effort="0.0" lower="-3.14159" upper="3.14159" velocity="0.0"/>
    </joint>
    <link name="Link1">
        <inertial>
            <origin xyz="0 0.3473401813241955 -0.294916947710009" rpy="0 0 0"/>
            <mass value="1" />
            <inertia ixx="100" ixy="0" ixz="0" iyy="100" iyz="0" izz="100" />
        </inertial>
        <visual>
            <origin xyz="0 0.3473401813241955 -0.294916947710009" rpy="0 0 0"/>
            <geometry>
                <box size="0.9382137846636243 0.694680362648391 0.589833895420018" />
            </geometry>
            <material name="Green">
                <color rgba="0 1.0 0.0 1.0"/>
            </material>
        </visual>
        <collision>
            <origin xyz="0 0.3473401813241955 -0.294916947710009" rpy="0 0 0"/>
            <geometry>
                <box size="0.9382137846636243 0.694680362648391 0.589833895420018" />
            </geometry>
        </collision>
    </link>
    <joint name="Link1_Link2" type="revolute">
       <parent link="Link1"/>
       <child  link="Link2"/>
       <origin rpy="0 0 0" xyz="0 0.694680362648391 0.0" />
     <axis xyz="1 0 0"/>
       <limit effort="0.0" lower="-3.14159" upper="3.14159" velocity="0.0"/>
    </joint>
    <link name="Link2">
        <inertial>
            <origin xyz="0 0.41889133374529797 0.48339490542076535" rpy="0 0 0"/>
            <mass value="1" />
            <inertia ixx="100" ixy="0" ixz="0" iyy="100" iyz="0" izz="100" />
        </inertial>
        <visual>
            <origin xyz="0 0.41889133374529797 0.48339490542076535" rpy="0 0 0"/>
            <geometry>
                <box size="0.30218728333273415 0.8377826674905959 0.9667898108415307" />
            </geometry>
            <material name="Green">
                <color rgba="0 1.0 0.0 1.0"/>
            </material>
        </visual>
        <collision>
            <origin xyz="0 0.41889133374529797 0.48339490542076535" rpy="0 0 0"/>
            <geometry>
                <box size="0.30218728333273415 0.8377826674905959 0.9667898108415307" />
            </geometry>
        </collision>
    </link>
    <joint name="Link2_Link3" type="revolute">
       <parent link="Link2"/>
       <child  link="Link3"/>
       <origin rpy="0 0 0" xyz="0 0.8377826674905959 0.9667898108415307" />
     <axis xyz="1 0 0"/>
       <limit effort="0.0" lower="-3.14159" upper="3.14159" velocity="0.0"/>
    </joint>
    <link name="Link3">
        <inertial>
            <origin xyz="0 0.19971178975145992 -0.1888847285893155" rpy="0 0 0"/>
            <mass value="1" />
            <inertia ixx="100" ixy="0" ixz="0" iyy="100" iyz="0" izz="100" />
        </inertial>
        <visual>
            <origin xyz="0 0.19971178975145992 -0.1888847285893155" rpy="0 0 0"/>
            <geometry>
                <box size="0.06030783241667326 0.39942357950291985 0.377769457178631" />
            </geometry>
            <material name="Blue">
                <color rgba="0 0.0 1.0 1.0"/>
            </material>
        </visual>
        <collision>
            <origin xyz="0 0.19971178975145992 -0.1888847285893155" rpy="0 0 0"/>
            <geometry>
                <box size="0.06030783241667326 0.39942357950291985 0.377769457178631" />
            </geometry>
        </collision>
    </link>
    <joint name="Link3_Link4" type="revolute">
       <parent link="Link3"/>
       <child  link="Link4"/>
       <origin rpy="0 0 0" xyz="0 0.39942357950291985 0.0" />
     <axis xyz="1 0 0"/>
       <limit effort="0.0" lower="-3.14159" upper="3.14159" velocity="0.0"/>
    </joint>
    <link name="Link4">
        <inertial>
            <origin xyz="0 0.19811490613974797 -0.42669478606443445" rpy="0 0 0"/>
            <mass value="1" />
            <inertia ixx="100" ixy="0" ixz="0" iyy="100" iyz="0" izz="100" />
        </inertial>
        <visual>
            <origin xyz="0 0.19811490613974797 -0.42669478606443445" rpy="0 0 0"/>
            <geometry>
                <box size="0.9416040884609141 0.39622981227949594 0.8533895721288689" />
            </geometry>
            <material name="Green">
                <color rgba="0 1.0 0.0 1.0"/>
            </material>
        </visual>
        <collision>
            <origin xyz="0 0.19811490613974797 -0.42669478606443445" rpy="0 0 0"/>
            <geometry>
                <box size="0.9416040884609141 0.39622981227949594 0.8533895721288689" />
            </geometry>
        </collision>
    </link>
    <joint name="Link4_Link5" type="revolute">
       <parent link="Link4"/>
       <child  link="Link5"/>
       <origin rpy="0 0 0" xyz="0 0.0 0.0" />
     <axis xyz="1 0 0"/>
       <limit effort="0.0" lower="-3.14159" upper="3.14159" velocity="0.0"/>
    </joint>
    <link name="Link5">
        <inertial>
            <origin xyz="0 -0.017613712458498187 -0.28811519167287053" rpy="0 0 0"/>
            <mass value="1" />
            <inertia ixx="100" ixy="0" ixz="0" iyy="100" iyz="0" izz="100" />
        </inertial>
        <visual>
            <origin xyz="0 -0.017613712458498187 -0.28811519167287053" rpy="0 0 0"/>
            <geometry>
                <box size="0.6091568475455617 0.035227424916996375 0.5762303833457411" />
            </geometry>
            <material name="Blue">
                <color rgba="0 0.0 1.0 1.0"/>
            </material>
        </visual>
        <collision>
            <origin xyz="0 -0.017613712458498187 -0.28811519167287053" rpy="0 0 0"/>
            <geometry>
                <box size="0.6091568475455617 0.035227424916996375 0.5762303833457411" />
            </geometry>
        </collision>
    </link>
    <joint name="Link5_Link6" type="revolute">
       <parent link="Link5"/>
       <child  link="Link6"/>
       <origin rpy="0 0 0" xyz="0.3045784237727808 -0.017613712458498187 0.0" />
     <axis xyz="0 1 0"/>
       <limit effort="0.0" lower="-3.14159" upper="3.14159" velocity="0.0"/>
    </joint>
    <link name="Link6">
        <inertial>
            <origin xyz="0.03606908842368994 0 -0.004529171688029465" rpy="0 0 0"/>
            <mass value="1" />
            <inertia ixx="100" ixy="0" ixz="0" iyy="100" iyz="0" izz="100" />
        </inertial>
        <visual>
            <origin xyz="0.03606908842368994 0 -0.004529171688029465" rpy="0 0 0"/>
            <geometry>
                <box size="0.07213817684737989 0.9563459555522377 0.00905834337605893" />
            </geometry>
            <material name="Green">
                <color rgba="0 1.0 0.0 1.0"/>
            </material>
        </visual>
        <collision>
            <origin xyz="0.03606908842368994 0 -0.004529171688029465" rpy="0 0 0"/>
            <geometry>
                <box size="0.07213817684737989 0.9563459555522377 0.00905834337605893" />
            </geometry>
        </collision>
    </link>
</robot>