<robot name = "robot">
    <link name="Link0">
        <inertial>
            <origin xyz="0 0 2.3555779143292246" rpy="0 0 0"/>
            <mass value="1" />
            <inertia ixx="100" ixy="0" ixz="0" iyy="100" iyz="0" izz="100" />
        </inertial>
        <visual>
            <origin xyz="0 0 2.3555779143292246" rpy="0 0 0"/>
            <geometry>
                <box size="0.854326147129773 0.20928670476665345 0.7111558286584492" />
            </geometry>
            <material name="Green">
                <color rgba="0 1.0 0.0 1.0"/>
            </material>
        </visual>
        <collision>
            <origin xyz="0 0 2.3555779143292246" rpy="0 0 0"/>
            <geometry>
                <box size="0.854326147129773 0.20928670476665345 0.7111558286584492" />
            </geometry>
        </collision>
    </link>
    <joint name="Link0_Link1" type="revolute">
       <parent link="Link0"/>
       <child  link="Link1"/>
       <origin rpy="0 0 0" xyz="0 0.10464335238332673 2.711155828658449" />
     <axis xyz="1 0 0"/>
       <limit effort="0.0" lower="-3.14159" upper="3.14159" velocity="0.0"/>
    </joint>
    <link name="Link1">
        <inertial>
            <origin xyz="0 0.10464335238332673 -0.3555779143292246" rpy="0 0 0"/>
            <mass value="1" />
            <inertia ixx="100" ixy="0" ixz="0" iyy="100" iyz="0" izz="100" />
        </inertial>
        <visual>
            <origin xyz="0 0.10464335238332673 -0.3555779143292246" rpy="0 0 0"/>
            <geometry>
                <box size="0.854326147129773 0.20928670476665345 0.7111558286584492" />
            </geometry>
            <material name="Green">
                <color rgba="0 1.0 0.0 1.0"/>
            </material>
        </visual>
        <collision>
            <origin xyz="0 0.10464335238332673 -0.3555779143292246" rpy="0 0 0"/>
            <geometry>
                <box size="0.854326147129773 0.20928670476665345 0.7111558286584492" />
            </geometry>
        </collision>
    </link>
    <joint name="Link1_Link2" type="revolute">
       <parent link="Link1"/>
       <child  link="Link2"/>
       <origin rpy="0 0 0" xyz="-0.4271630735648865 0.10464335238332673 0.0" />
     <axis xyz="0 1 0"/>
       <limit effort="0.0" lower="-3.14159" upper="3.14159" velocity="0.0"/>
    </joint>
    <link name="Link2">
        <inertial>
            <origin xyz="-0.07745502219636019 0 0.0648968764221422" rpy="0 0 0"/>
            <mass value="1" />
            <inertia ixx="100" ixy="0" ixz="0" iyy="100" iyz="0" izz="100" />
        </inertial>
        <visual>
            <origin xyz="-0.07745502219636019 0 0.0648968764221422" rpy="0 0 0"/>
            <geometry>
                <box size="0.15491004439272038 0.04062899299961098 0.1297937528442844" />
            </geometry>
            <material name="Blue">
                <color rgba="0 0.0 1.0 1.0"/>
            </material>
        </visual>
        <collision>
            <origin xyz="-0.07745502219636019 0 0.0648968764221422" rpy="0 0 0"/>
            <geometry>
                <box size="0.15491004439272038 0.04062899299961098 0.1297937528442844" />
            </geometry>
        </collision>
    </link>
    <joint name="Link2_Link3" type="revolute">
       <parent link="Link2"/>
       <child  link="Link3"/>
       <origin rpy="0 0 0" xyz="-0.07745502219636019 0.02031449649980549 0.1297937528442844" />
     <axis xyz="1 0 0"/>
       <limit effort="0.0" lower="-3.14159" upper="3.14159" velocity="0.0"/>
    </joint>
    <link name="Link3">
        <inertial>
            <origin xyz="0 0.48071636190832595 0.03862706761554613" rpy="0 0 0"/>
            <mass value="1" />
            <inertia ixx="100" ixy="0" ixz="0" iyy="100" iyz="0" izz="100" />
        </inertial>
        <visual>
            <origin xyz="0 0.48071636190832595 0.03862706761554613" rpy="0 0 0"/>
            <geometry>
                <box size="0.5806265897925057 0.9614327238166519 0.07725413523109226" />
            </geometry>
            <material name="Blue">
                <color rgba="0 0.0 1.0 1.0"/>
            </material>
        </visual>
        <collision>
            <origin xyz="0 0.48071636190832595 0.03862706761554613" rpy="0 0 0"/>
            <geometry>
                <box size="0.5806265897925057 0.9614327238166519 0.07725413523109226" />
            </geometry>
        </collision>
    </link>
    <joint name="Link3_Link4" type="revolute">
       <parent link="Link3"/>
       <child  link="Link4"/>
       <origin rpy="0 0 0" xyz="-0.29031329489625285 0.48071636190832595 0.07725413523109226" />
     <axis xyz="0 1 0"/>
       <limit effort="0.0" lower="-3.14159" upper="3.14159" velocity="0.0"/>
    </joint>
    <link name="Link4">
        <inertial>
            <origin xyz="-0.18704444865609182 0 -0.10612761860281539" rpy="0 0 0"/>
            <mass value="1" />
            <inertia ixx="100" ixy="0" ixz="0" iyy="100" iyz="0" izz="100" />
        </inertial>
        <visual>
            <origin xyz="-0.18704444865609182 0 -0.10612761860281539" rpy="0 0 0"/>
            <geometry>
                <box size="0.37408889731218364 0.6520927954912578 0.21225523720563078" />
            </geometry>
            <material name="Blue">
                <color rgba="0 0.0 1.0 1.0"/>
            </material>
        </visual>
        <collision>
            <origin xyz="-0.18704444865609182 0 -0.10612761860281539" rpy="0 0 0"/>
            <geometry>
                <box size="0.37408889731218364 0.6520927954912578 0.21225523720563078" />
            </geometry>
        </collision>
    </link>
    <joint name="Link4_Link5" type="revolute">
       <parent link="Link4"/>
       <child  link="Link5"/>
       <origin rpy="0 0 0" xyz="-0.37408889731218364 0 0.0" />
     <axis xyz="0 1 0"/>
       <limit effort="0.0" lower="-3.14159" upper="3.14159" velocity="0.0"/>
    </joint>
    <link name="Link5">
        <inertial>
            <origin xyz="-0.3617279638734331 0 0.41987602784246975" rpy="0 0 0"/>
            <mass value="1" />
            <inertia ixx="100" ixy="0" ixz="0" iyy="100" iyz="0" izz="100" />
        </inertial>
        <visual>
            <origin xyz="-0.3617279638734331 0 0.41987602784246975" rpy="0 0 0"/>
            <geometry>
                <box size="0.7234559277468662 0.28096813784934815 0.8397520556849395" />
            </geometry>
            <material name="Green">
                <color rgba="0 1.0 0.0 1.0"/>
            </material>
        </visual>
        <collision>
            <origin xyz="-0.3617279638734331 0 0.41987602784246975" rpy="0 0 0"/>
            <geometry>
                <box size="0.7234559277468662 0.28096813784934815 0.8397520556849395" />
            </geometry>
        </collision>
    </link>
</robot>