<robot name = "robot">
    <link name="Link0">
        <inertial>
            <origin xyz="0 0 2.395213599277946" rpy="0 0 0"/>
            <mass value="1" />
            <inertia ixx="100" ixy="0" ixz="0" iyy="100" iyz="0" izz="100" />
        </inertial>
        <visual>
            <origin xyz="0 0 2.395213599277946" rpy="0 0 0"/>
            <geometry>
                <box size="0.5392057917888207 0.09959915740588587 0.7904271985558923" />
            </geometry>
            <material name="Green">
                <color rgba="0 1.0 0.0 1.0"/>
            </material>
        </visual>
        <collision>
            <origin xyz="0 0 2.395213599277946" rpy="0 0 0"/>
            <geometry>
                <box size="0.5392057917888207 0.09959915740588587 0.7904271985558923" />
            </geometry>
        </collision>
    </link>
    <joint name="Link0_Link1" type="revolute">
       <parent link="Link0"/>
       <child  link="Link1"/>
       <origin rpy="0 0 0" xyz="0 0.04979957870294294 2.7904271985558924" />
     <axis xyz="1 0 0"/>
       <limit effort="0.0" lower="-3.14159" upper="3.14159" velocity="0.0"/>
    </joint>
    <link name="Link1">
        <inertial>
            <origin xyz="0 0.04979957870294294 -0.39521359927794614" rpy="0 0 0"/>
            <mass value="1" />
            <inertia ixx="100" ixy="0" ixz="0" iyy="100" iyz="0" izz="100" />
        </inertial>
        <visual>
            <origin xyz="0 0.04979957870294294 -0.39521359927794614" rpy="0 0 0"/>
            <geometry>
                <box size="0.5392057917888207 0.09959915740588587 0.7904271985558923" />
            </geometry>
            <material name="Green">
                <color rgba="0 1.0 0.0 1.0"/>
            </material>
        </visual>
        <collision>
            <origin xyz="0 0.04979957870294294 -0.39521359927794614" rpy="0 0 0"/>
            <geometry>
                <box size="0.5392057917888207 0.09959915740588587 0.7904271985558923" />
            </geometry>
        </collision>
    </link>
    <joint name="Link1_Link2" type="revolute">
       <parent link="Link1"/>
       <child  link="Link2"/>
       <origin rpy="0 0 0" xyz="0 0.0 0.0" />
     <axis xyz="1 0 0"/>
       <limit effort="0.0" lower="-3.14159" upper="3.14159" velocity="0.0"/>
    </joint>
    <link name="Link2">
        <inertial>
            <origin xyz="0 -0.012191364440551244 0.032929482797432075" rpy="0 0 0"/>
            <mass value="1" />
            <inertia ixx="100" ixy="0" ixz="0" iyy="100" iyz="0" izz="100" />
        </inertial>
        <visual>
            <origin xyz="0 -0.012191364440551244 0.032929482797432075" rpy="0 0 0"/>
            <geometry>
                <box size="0.9522452531284873 0.02438272888110249 0.06585896559486415" />
            </geometry>
            <material name="Blue">
                <color rgba="0 0.0 1.0 1.0"/>
            </material>
        </visual>
        <collision>
            <origin xyz="0 -0.012191364440551244 0.032929482797432075" rpy="0 0 0"/>
            <geometry>
                <box size="0.9522452531284873 0.02438272888110249 0.06585896559486415" />
            </geometry>
        </collision>
    </link>
    <joint name="Link2_Link3" type="revolute">
       <parent link="Link2"/>
       <child  link="Link3"/>
       <origin rpy="0 0 0" xyz="0 -0.02438272888110249 0.06585896559486415" />
     <axis xyz="1 0 0"/>
       <limit effort="0.0" lower="-3.14159" upper="3.14159" velocity="0.0"/>
    </joint>
    <link name="Link3">
        <inertial>
            <origin xyz="0 -0.09707255346010946 -0.04602841640448235" rpy="0 0 0"/>
            <mass value="1" />
            <inertia ixx="100" ixy="0" ixz="0" iyy="100" iyz="0" izz="100" />
        </inertial>
        <visual>
            <origin xyz="0 -0.09707255346010946 -0.04602841640448235" rpy="0 0 0"/>
            <geometry>
                <box size="0.8239760468849325 0.1941451069202189 0.0920568328089647" />
            </geometry>
            <material name="Green">
                <color rgba="0 1.0 0.0 1.0"/>
            </material>
        </visual>
        <collision>
            <origin xyz="0 -0.09707255346010946 -0.04602841640448235" rpy="0 0 0"/>
            <geometry>
                <box size="0.8239760468849325 0.1941451069202189 0.0920568328089647" />
            </geometry>
        </collision>
    </link>
    <joint name="Link3_Link4" type="revolute">
       <parent link="Link3"/>
       <child  link="Link4"/>
       <origin rpy="0 0 0" xyz="0.41198802344246627 -0.09707255346010946 0.0" />
     <axis xyz="0 1 0"/>
       <limit effort="0.0" lower="-3.14159" upper="3.14159" velocity="0.0"/>
    </joint>
    <link name="Link4">
        <inertial>
            <origin xyz="0.002669048468494195 0 -0.017248798986709002" rpy="0 0 0"/>
            <mass value="1" />
            <inertia ixx="100" ixy="0" ixz="0" iyy="100" iyz="0" izz="100" />
        </inertial>
        <visual>
            <origin xyz="0.002669048468494195 0 -0.017248798986709002" rpy="0 0 0"/>
            <geometry>
                <box size="0.00533809693698839 0.2196018792194363 0.034497597973418004" />
            </geometry>
            <material name="Blue">
                <color rgba="0 0.0 1.0 1.0"/>
            </material>
        </visual>
        <collision>
            <origin xyz="0.002669048468494195 0 -0.017248798986709002" rpy="0 0 0"/>
            <geometry>
                <box size="0.00533809693698839 0.2196018792194363 0.034497597973418004" />
            </geometry>
        </collision>
    </link>
    <joint name="Link4_Link5" type="revolute">
       <parent link="Link4"/>
       <child  link="Link5"/>
       <origin rpy="0 0 0" xyz="0.002669048468494195 -0.10980093960971815 0.0" />
     <axis xyz="1 0 0"/>
       <limit effort="0.0" lower="-3.14159" upper="3.14159" velocity="0.0"/>
    </joint>
    <link name="Link5">
        <inertial>
            <origin xyz="0 -0.013506409620285653 0.09720223106311326" rpy="0 0 0"/>
            <mass value="1" />
            <inertia ixx="100" ixy="0" ixz="0" iyy="100" iyz="0" izz="100" />
        </inertial>
        <visual>
            <origin xyz="0 -0.013506409620285653 0.09720223106311326" rpy="0 0 0"/>
            <geometry>
                <box size="0.18901428709666546 0.027012819240571306 0.19440446212622653" />
            </geometry>
            <material name="Blue">
                <color rgba="0 0.0 1.0 1.0"/>
            </material>
        </visual>
        <collision>
            <origin xyz="0 -0.013506409620285653 0.09720223106311326" rpy="0 0 0"/>
            <geometry>
                <box size="0.18901428709666546 0.027012819240571306 0.19440446212622653" />
            </geometry>
        </collision>
    </link>
    <joint name="Link5_Link6" type="revolute">
       <parent link="Link5"/>
       <child  link="Link6"/>
       <origin rpy="0 0 0" xyz="0 0.0 0.19440446212622653" />
     <axis xyz="1 0 0"/>
       <limit effort="0.0" lower="-3.14159" upper="3.14159" velocity="0.0"/>
    </joint>
    <link name="Link6">
        <inertial>
            <origin xyz="0 0.31136584938784645 -0.13699167756205155" rpy="0 0 0"/>
            <mass value="1" />
            <inertia ixx="100" ixy="0" ixz="0" iyy="100" iyz="0" izz="100" />
        </inertial>
        <visual>
            <origin xyz="0 0.31136584938784645 -0.13699167756205155" rpy="0 0 0"/>
            <geometry>
                <box size="0.020541733500606174 0.6227316987756929 0.2739833551241031" />
            </geometry>
            <material name="Green">
                <color rgba="0 1.0 0.0 1.0"/>
            </material>
        </visual>
        <collision>
            <origin xyz="0 0.31136584938784645 -0.13699167756205155" rpy="0 0 0"/>
            <geometry>
                <box size="0.020541733500606174 0.6227316987756929 0.2739833551241031" />
            </geometry>
        </collision>
    </link>
</robot>