<robot name = "robot">
    <link name="Link0">
        <inertial>
            <origin xyz="0 0 2.060376941027076" rpy="0 0 0"/>
            <mass value="1" />
            <inertia ixx="100" ixy="0" ixz="0" iyy="100" iyz="0" izz="100" />
        </inertial>
        <visual>
            <origin xyz="0 0 2.060376941027076" rpy="0 0 0"/>
            <geometry>
                <box size="0.6257349374981899 0.4939161761206414 0.12075388205415216" />
            </geometry>
            <material name="Green">
                <color rgba="0 1.0 0.0 1.0"/>
            </material>
        </visual>
        <collision>
            <origin xyz="0 0 2.060376941027076" rpy="0 0 0"/>
            <geometry>
                <box size="0.6257349374981899 0.4939161761206414 0.12075388205415216" />
            </geometry>
        </collision>
    </link>
    <joint name="Link0_Link1" type="revolute">
       <parent link="Link0"/>
       <child  link="Link1"/>
       <origin rpy="0 0 0" xyz="0 0.2469580880603207 2.120753882054152" />
     <axis xyz="1 0 0"/>
       <limit effort="0.0" lower="-3.14159" upper="3.14159" velocity="0.0"/>
    </joint>
    <link name="Link1">
        <inertial>
            <origin xyz="0 0.2469580880603207 -0.06037694102707608" rpy="0 0 0"/>
            <mass value="1" />
            <inertia ixx="100" ixy="0" ixz="0" iyy="100" iyz="0" izz="100" />
        </inertial>
        <visual>
            <origin xyz="0 0.2469580880603207 -0.06037694102707608" rpy="0 0 0"/>
            <geometry>
                <box size="0.6257349374981899 0.4939161761206414 0.12075388205415216" />
            </geometry>
            <material name="Green">
                <color rgba="0 1.0 0.0 1.0"/>
            </material>
        </visual>
        <collision>
            <origin xyz="0 0.2469580880603207 -0.06037694102707608" rpy="0 0 0"/>
            <geometry>
                <box size="0.6257349374981899 0.4939161761206414 0.12075388205415216" />
            </geometry>
        </collision>
    </link>
    <joint name="Link1_Link2" type="revolute">
       <parent link="Link1"/>
       <child  link="Link2"/>
       <origin rpy="0 0 0" xyz="0.31286746874909493 0.2469580880603207 0.0" />
     <axis xyz="0 1 0"/>
       <limit effort="0.0" lower="-3.14159" upper="3.14159" velocity="0.0"/>
    </joint>
    <link name="Link2">
        <inertial>
            <origin xyz="0.12892429445698028 0 -0.4245467187040246" rpy="0 0 0"/>
            <mass value="1" />
            <inertia ixx="100" ixy="0" ixz="0" iyy="100" iyz="0" izz="100" />
        </inertial>
        <visual>
            <origin xyz="0.12892429445698028 0 -0.4245467187040246" rpy="0 0 0"/>
            <geometry>
                <box size="0.25784858891396056 0.7007704379778198 0.8490934374080492" />
            </geometry>
            <material name="Blue">
                <color rgba="0 0.0 1.0 1.0"/>
            </material>
        </visual>
        <collision>
            <origin xyz="0.12892429445698028 0 -0.4245467187040246" rpy="0 0 0"/>
            <geometry>
                <box size="0.25784858891396056 0.7007704379778198 0.8490934374080492" />
            </geometry>
        </collision>
    </link>
    <joint name="Link2_Link3" type="revolute">
       <parent link="Link2"/>
       <child  link="Link3"/>
       <origin rpy="0 0 0" xyz="0.12892429445698028 0.3503852189889099 0.0" />
     <axis xyz="1 0 0"/>
       <limit effort="0.0" lower="-3.14159" upper="3.14159" velocity="0.0"/>
    </joint>
    <link name="Link3">
        <inertial>
            <origin xyz="0 0.23805000566529028 -0.34325756322116263" rpy="0 0 0"/>
            <mass value="1" />
            <inertia ixx="100" ixy="0" ixz="0" iyy="100" iyz="0" izz="100" />
        </inertial>
        <visual>
            <origin xyz="0 0.23805000566529028 -0.34325756322116263" rpy="0 0 0"/>
            <geometry>
                <box size="0.8380715147241063 0.47610001133058055 0.6865151264423253" />
            </geometry>
            <material name="Green">
                <color rgba="0 1.0 0.0 1.0"/>
            </material>
        </visual>
        <collision>
            <origin xyz="0 0.23805000566529028 -0.34325756322116263" rpy="0 0 0"/>
            <geometry>
                <box size="0.8380715147241063 0.47610001133058055 0.6865151264423253" />
            </geometry>
        </collision>
    </link>
    <joint name="Link3_Link4" type="revolute">
       <parent link="Link3"/>
       <child  link="Link4"/>
       <origin rpy="0 0 0" xyz="-0.4190357573620532 0.23805000566529028 0.0" />
     <axis xyz="0 1 0"/>
       <limit effort="0.0" lower="-3.14159" upper="3.14159" velocity="0.0"/>
    </joint>
    <link name="Link4">
        <inertial>
            <origin xyz="-0.4362329224570308 0 0.48229319923674835" rpy="0 0 0"/>
            <mass value="1" />
            <inertia ixx="100" ixy="0" ixz="0" iyy="100" iyz="0" izz="100" />
        </inertial>
        <visual>
            <origin xyz="-0.4362329224570308 0 0.48229319923674835" rpy="0 0 0"/>
            <geometry>
                <box size="0.8724658449140617 0.15127294651696244 0.9645863984734967" />
            </geometry>
            <material name="Green">
                <color rgba="0 1.0 0.0 1.0"/>
            </material>
        </visual>
        <collision>
            <origin xyz="-0.4362329224570308 0 0.48229319923674835" rpy="0 0 0"/>
            <geometry>
                <box size="0.8724658449140617 0.15127294651696244 0.9645863984734967" />
            </geometry>
        </collision>
    </link>
    <joint name="Link4_Link5" type="revolute">
       <parent link="Link4"/>
       <child  link="Link5"/>
       <origin rpy="0 0 0" xyz="0.0 0 0.9645863984734967" />
     <axis xyz="0 1 0"/>
       <limit effort="0.0" lower="-3.14159" upper="3.14159" velocity="0.0"/>
    </joint>
    <link name="Link5">
        <inertial>
            <origin xyz="0.4772048985714809 0 0.25766990068770007" rpy="0 0 0"/>
            <mass value="1" />
            <inertia ixx="100" ixy="0" ixz="0" iyy="100" iyz="0" izz="100" />
        </inertial>
        <visual>
            <origin xyz="0.4772048985714809 0 0.25766990068770007" rpy="0 0 0"/>
            <geometry>
                <box size="0.9544097971429618 0.5179468226645265 0.5153398013754001" />
            </geometry>
            <material name="Blue">
                <color rgba="0 0.0 1.0 1.0"/>
            </material>
        </visual>
        <collision>
            <origin xyz="0.4772048985714809 0 0.25766990068770007" rpy="0 0 0"/>
            <geometry>
                <box size="0.9544097971429618 0.5179468226645265 0.5153398013754001" />
            </geometry>
        </collision>
    </link>
    <joint name="Link5_Link6" type="revolute">
       <parent link="Link5"/>
       <child  link="Link6"/>
       <origin rpy="0 0 0" xyz="0.4772048985714809 0.25897341133226326 0.5153398013754001" />
     <axis xyz="1 0 0"/>
       <limit effort="0.0" lower="-3.14159" upper="3.14159" velocity="0.0"/>
    </joint>
    <link name="Link6">
        <inertial>
            <origin xyz="0 0.17172440871395755 0.2608348031100997" rpy="0 0 0"/>
            <mass value="1" />
            <inertia ixx="100" ixy="0" ixz="0" iyy="100" iyz="0" izz="100" />
        </inertial>
        <visual>
            <origin xyz="0 0.17172440871395755 0.2608348031100997" rpy="0 0 0"/>
            <geometry>
                <box size="0.9403574891605058 0.3434488174279151 0.5216696062201994" />
            </geometry>
            <material name="Blue">
                <color rgba="0 0.0 1.0 1.0"/>
            </material>
        </visual>
        <collision>
            <origin xyz="0 0.17172440871395755 0.2608348031100997" rpy="0 0 0"/>
            <geometry>
                <box size="0.9403574891605058 0.3434488174279151 0.5216696062201994" />
            </geometry>
        </collision>
    </link>
</robot>