<robot name = "robot">
    <link name="Link0">
        <inertial>
            <origin xyz="0 0 2.378477877337095" rpy="0 0 0"/>
            <mass value="1" />
            <inertia ixx="100" ixy="0" ixz="0" iyy="100" iyz="0" izz="100" />
        </inertial>
        <visual>
            <origin xyz="0 0 2.378477877337095" rpy="0 0 0"/>
            <geometry>
                <box size="0.1268813747407539 0.0451066357719182 0.7569557546741906" />
            </geometry>
            <material name="Green">
                <color rgba="0 1.0 0.0 1.0"/>
            </material>
        </visual>
        <collision>
            <origin xyz="0 0 2.378477877337095" rpy="0 0 0"/>
            <geometry>
                <box size="0.1268813747407539 0.0451066357719182 0.7569557546741906" />
            </geometry>
        </collision>
    </link>
    <joint name="Link0_Link1" type="revolute">
       <parent link="Link0"/>
       <child  link="Link1"/>
       <origin rpy="0 0 0" xyz="0 0.0225533178859591 2.7569557546741907" />
     <axis xyz="1 0 0"/>
       <limit effort="0.0" lower="-3.14159" upper="3.14159" velocity="0.0"/>
    </joint>
    <link name="Link1">
        <inertial>
            <origin xyz="0 0.0225533178859591 -0.3784778773370953" rpy="0 0 0"/>
            <mass value="1" />
            <inertia ixx="100" ixy="0" ixz="0" iyy="100" iyz="0" izz="100" />
        </inertial>
        <visual>
            <origin xyz="0 0.0225533178859591 -0.3784778773370953" rpy="0 0 0"/>
            <geometry>
                <box size="0.1268813747407539 0.0451066357719182 0.7569557546741906" />
            </geometry>
            <material name="Blue">
                <color rgba="0 0.0 1.0 1.0"/>
            </material>
        </visual>
        <collision>
            <origin xyz="0 0.0225533178859591 -0.3784778773370953" rpy="0 0 0"/>
            <geometry>
                <box size="0.1268813747407539 0.0451066357719182 0.7569557546741906" />
            </geometry>
        </collision>
    </link>
    <joint name="Link1_Link2" type="revolute">
       <parent link="Link1"/>
       <child  link="Link2"/>
       <origin rpy="0 0 0" xyz="0 0.0451066357719182 0.0" />
     <axis xyz="1 0 0"/>
       <limit effort="0.0" lower="-3.14159" upper="3.14159" velocity="0.0"/>
    </joint>
    <link name="Link2">
        <inertial>
            <origin xyz="0 0.32626917153231927 0.36277454505889073" rpy="0 0 0"/>
            <mass value="1" />
            <inertia ixx="100" ixy="0" ixz="0" iyy="100" iyz="0" izz="100" />
        </inertial>
        <visual>
            <origin xyz="0 0.32626917153231927 0.36277454505889073" rpy="0 0 0"/>
            <geometry>
                <box size="0.02976753811066757 0.6525383430646385 0.7255490901177815" />
            </geometry>
            <material name="Blue">
                <color rgba="0 0.0 1.0 1.0"/>
            </material>
        </visual>
        <collision>
            <origin xyz="0 0.32626917153231927 0.36277454505889073" rpy="0 0 0"/>
            <geometry>
                <box size="0.02976753811066757 0.6525383430646385 0.7255490901177815" />
            </geometry>
        </collision>
    </link>
    <joint name="Link2_Link3" type="revolute">
       <parent link="Link2"/>
       <child  link="Link3"/>
       <origin rpy="0 0 0" xyz="0 0.0 0.7255490901177815" />
     <axis xyz="1 0 0"/>
       <limit effort="0.0" lower="-3.14159" upper="3.14159" velocity="0.0"/>
    </joint>
    <link name="Link3">
        <inertial>
            <origin xyz="0 -0.44673580602052637 -0.30705350919434604" rpy="0 0 0"/>
            <mass value="1" />
            <inertia ixx="100" ixy="0" ixz="0" iyy="100" iyz="0" izz="100" />
        </inertial>
        <visual>
            <origin xyz="0 -0.44673580602052637 -0.30705350919434604" rpy="0 0 0"/>
            <geometry>
                <box size="0.6967411216406147 0.8934716120410527 0.6141070183886921" />
            </geometry>
            <material name="Blue">
                <color rgba="0 0.0 1.0 1.0"/>
            </material>
        </visual>
        <collision>
            <origin xyz="0 -0.44673580602052637 -0.30705350919434604" rpy="0 0 0"/>
            <geometry>
                <box size="0.6967411216406147 0.8934716120410527 0.6141070183886921" />
            </geometry>
        </collision>
    </link>
    <joint name="Link3_Link4" type="revolute">
       <parent link="Link3"/>
       <child  link="Link4"/>
       <origin rpy="0 0 0" xyz="0 0.0 0.0" />
     <axis xyz="1 0 0"/>
       <limit effort="0.0" lower="-3.14159" upper="3.14159" velocity="0.0"/>
    </joint>
    <link name="Link4">
        <inertial>
            <origin xyz="0 0.2695095930912852 0.4533461448643067" rpy="0 0 0"/>
            <mass value="1" />
            <inertia ixx="100" ixy="0" ixz="0" iyy="100" iyz="0" izz="100" />
        </inertial>
        <visual>
            <origin xyz="0 0.2695095930912852 0.4533461448643067" rpy="0 0 0"/>
            <geometry>
                <box size="0.08233863353523163 0.5390191861825704 0.9066922897286134" />
            </geometry>
            <material name="Green">
                <color rgba="0 1.0 0.0 1.0"/>
            </material>
        </visual>
        <collision>
            <origin xyz="0 0.2695095930912852 0.4533461448643067" rpy="0 0 0"/>
            <geometry>
                <box size="0.08233863353523163 0.5390191861825704 0.9066922897286134" />
            </geometry>
        </collision>
    </link>
</robot>