<robot name = "robot">
    <link name="Link0">
        <inertial>
            <origin xyz="0 0 2.3851114659459705" rpy="0 0 0"/>
            <mass value="1" />
            <inertia ixx="100" ixy="0" ixz="0" iyy="100" iyz="0" izz="100" />
        </inertial>
        <visual>
            <origin xyz="0 0 2.3851114659459705" rpy="0 0 0"/>
            <geometry>
                <box size="0.6737244577080371 0.6645303278034357 0.7702229318919407" />
            </geometry>
            <material name="Green">
                <color rgba="0 1.0 0.0 1.0"/>
            </material>
        </visual>
        <collision>
            <origin xyz="0 0 2.3851114659459705" rpy="0 0 0"/>
            <geometry>
                <box size="0.6737244577080371 0.6645303278034357 0.7702229318919407" />
            </geometry>
        </collision>
    </link>
    <joint name="Link0_Link1" type="revolute">
       <parent link="Link0"/>
       <child  link="Link1"/>
       <origin rpy="0 0 0" xyz="0 0.33226516390171784 2.770222931891941" />
     <axis xyz="1 0 0"/>
       <limit effort="0.0" lower="-3.14159" upper="3.14159" velocity="0.0"/>
    </joint>
    <link name="Link1">
        <inertial>
            <origin xyz="0 0.33226516390171784 -0.38511146594597034" rpy="0 0 0"/>
            <mass value="1" />
            <inertia ixx="100" ixy="0" ixz="0" iyy="100" iyz="0" izz="100" />
        </inertial>
        <visual>
            <origin xyz="0 0.33226516390171784 -0.38511146594597034" rpy="0 0 0"/>
            <geometry>
                <box size="0.6737244577080371 0.6645303278034357 0.7702229318919407" />
            </geometry>
            <material name="Blue">
                <color rgba="0 0.0 1.0 1.0"/>
            </material>
        </visual>
        <collision>
            <origin xyz="0 0.33226516390171784 -0.38511146594597034" rpy="0 0 0"/>
            <geometry>
                <box size="0.6737244577080371 0.6645303278034357 0.7702229318919407" />
            </geometry>
        </collision>
    </link>
    <joint name="Link1_Link2" type="revolute">
       <parent link="Link1"/>
       <child  link="Link2"/>
       <origin rpy="0 0 0" xyz="0.33686222885401856 0.33226516390171784 0.0" />
     <axis xyz="0 1 0"/>
       <limit effort="0.0" lower="-3.14159" upper="3.14159" velocity="0.0"/>
    </joint>
    <link name="Link2">
        <inertial>
            <origin xyz="0.15968440821737467 0 0.21103302208622626" rpy="0 0 0"/>
            <mass value="1" />
            <inertia ixx="100" ixy="0" ixz="0" iyy="100" iyz="0" izz="100" />
        </inertial>
        <visual>
            <origin xyz="0.15968440821737467 0 0.21103302208622626" rpy="0 0 0"/>
            <geometry>
                <box size="0.31936881643474935 0.1503014800802377 0.4220660441724525" />
            </geometry>
            <material name="Green">
                <color rgba="0 1.0 0.0 1.0"/>
            </material>
        </visual>
        <collision>
            <origin xyz="0.15968440821737467 0 0.21103302208622626" rpy="0 0 0"/>
            <geometry>
                <box size="0.31936881643474935 0.1503014800802377 0.4220660441724525" />
            </geometry>
        </collision>
    </link>
    <joint name="Link2_Link3" type="revolute">
       <parent link="Link2"/>
       <child  link="Link3"/>
       <origin rpy="0 0 0" xyz="0.0 0 0.4220660441724525" />
     <axis xyz="0 1 0"/>
       <limit effort="0.0" lower="-3.14159" upper="3.14159" velocity="0.0"/>
    </joint>
    <link name="Link3">
        <inertial>
            <origin xyz="-0.3775763917777665 0 -0.3249722088027728" rpy="0 0 0"/>
            <mass value="1" />
            <inertia ixx="100" ixy="0" ixz="0" iyy="100" iyz="0" izz="100" />
        </inertial>
        <visual>
            <origin xyz="-0.3775763917777665 0 -0.3249722088027728" rpy="0 0 0"/>
            <geometry>
                <box size="0.755152783555533 0.8544387027119524 0.6499444176055456" />
            </geometry>
            <material name="Blue">
                <color rgba="0 0.0 1.0 1.0"/>
            </material>
        </visual>
        <collision>
            <origin xyz="-0.3775763917777665 0 -0.3249722088027728" rpy="0 0 0"/>
            <geometry>
                <box size="0.755152783555533 0.8544387027119524 0.6499444176055456" />
            </geometry>
        </collision>
    </link>
    <joint name="Link3_Link4" type="revolute">
       <parent link="Link3"/>
       <child  link="Link4"/>
       <origin rpy="0 0 0" xyz="-0.3775763917777665 -0.4272193513559762 0.0" />
     <axis xyz="1 0 0"/>
       <limit effort="0.0" lower="-3.14159" upper="3.14159" velocity="0.0"/>
    </joint>
    <link name="Link4">
        <inertial>
            <origin xyz="0 -0.3298114223459258 -0.14306886150308884" rpy="0 0 0"/>
            <mass value="1" />
            <inertia ixx="100" ixy="0" ixz="0" iyy="100" iyz="0" izz="100" />
        </inertial>
        <visual>
            <origin xyz="0 -0.3298114223459258 -0.14306886150308884" rpy="0 0 0"/>
            <geometry>
                <box size="0.6330187586263243 0.6596228446918516 0.2861377230061777" />
            </geometry>
            <material name="Green">
                <color rgba="0 1.0 0.0 1.0"/>
            </material>
        </visual>
        <collision>
            <origin xyz="0 -0.3298114223459258 -0.14306886150308884" rpy="0 0 0"/>
            <geometry>
                <box size="0.6330187586263243 0.6596228446918516 0.2861377230061777" />
            </geometry>
        </collision>
    </link>
    <joint name="Link4_Link5" type="revolute">
       <parent link="Link4"/>
       <child  link="Link5"/>
       <origin rpy="0 0 0" xyz="0 0.0 0.0" />
     <axis xyz="1 0 0"/>
       <limit effort="0.0" lower="-3.14159" upper="3.14159" velocity="0.0"/>
    </joint>
    <link name="Link5">
        <inertial>
            <origin xyz="0 0.06705794338111026 0.24483061974084847" rpy="0 0 0"/>
            <mass value="1" />
            <inertia ixx="100" ixy="0" ixz="0" iyy="100" iyz="0" izz="100" />
        </inertial>
        <visual>
            <origin xyz="0 0.06705794338111026 0.24483061974084847" rpy="0 0 0"/>
            <geometry>
                <box size="0.6476712680340594 0.13411588676222053 0.48966123948169693" />
            </geometry>
            <material name="Blue">
                <color rgba="0 0.0 1.0 1.0"/>
            </material>
        </visual>
        <collision>
            <origin xyz="0 0.06705794338111026 0.24483061974084847" rpy="0 0 0"/>
            <geometry>
                <box size="0.6476712680340594 0.13411588676222053 0.48966123948169693" />
            </geometry>
        </collision>
    </link>
    <joint name="Link5_Link6" type="revolute">
       <parent link="Link5"/>
       <child  link="Link6"/>
       <origin rpy="0 0 0" xyz="0 0.13411588676222053 0.48966123948169693" />
     <axis xyz="1 0 0"/>
       <limit effort="0.0" lower="-3.14159" upper="3.14159" velocity="0.0"/>
    </joint>
    <link name="Link6">
        <inertial>
            <origin xyz="0 0.26571450354443277 0.02043842081115188" rpy="0 0 0"/>
            <mass value="1" />
            <inertia ixx="100" ixy="0" ixz="0" iyy="100" iyz="0" izz="100" />
        </inertial>
        <visual>
            <origin xyz="0 0.26571450354443277 0.02043842081115188" rpy="0 0 0"/>
            <geometry>
                <box size="0.8520967615434668 0.5314290070888655 0.04087684162230376" />
            </geometry>
            <material name="Green">
                <color rgba="0 1.0 0.0 1.0"/>
            </material>
        </visual>
        <collision>
            <origin xyz="0 0.26571450354443277 0.02043842081115188" rpy="0 0 0"/>
            <geometry>
                <box size="0.8520967615434668 0.5314290070888655 0.04087684162230376" />
            </geometry>
        </collision>
    </link>
</robot>