<robot name = "robot">
    <link name="Link0">
        <inertial>
            <origin xyz="0 0 2.3443090834030973" rpy="0 0 0"/>
            <mass value="1" />
            <inertia ixx="100" ixy="0" ixz="0" iyy="100" iyz="0" izz="100" />
        </inertial>
        <visual>
            <origin xyz="0 0 2.3443090834030973" rpy="0 0 0"/>
            <geometry>
                <box size="0.6772855546117909 0.7248108423791837 0.6886181668061948" />
            </geometry>
            <material name="Green">
                <color rgba="0 1.0 0.0 1.0"/>
            </material>
        </visual>
        <collision>
            <origin xyz="0 0 2.3443090834030973" rpy="0 0 0"/>
            <geometry>
                <box size="0.6772855546117909 0.7248108423791837 0.6886181668061948" />
            </geometry>
        </collision>
    </link>
    <joint name="Link0_Link1" type="revolute">
       <parent link="Link0"/>
       <child  link="Link1"/>
       <origin rpy="0 0 0" xyz="0 0.36240542118959185 2.6886181668061946" />
     <axis xyz="1 0 0"/>
       <limit effort="0.0" lower="-3.14159" upper="3.14159" velocity="0.0"/>
    </joint>
    <link name="Link1">
        <inertial>
            <origin xyz="0 0.36240542118959185 -0.3443090834030974" rpy="0 0 0"/>
            <mass value="1" />
            <inertia ixx="100" ixy="0" ixz="0" iyy="100" iyz="0" izz="100" />
        </inertial>
        <visual>
            <origin xyz="0 0.36240542118959185 -0.3443090834030974" rpy="0 0 0"/>
            <geometry>
                <box size="0.6772855546117909 0.7248108423791837 0.6886181668061948" />
            </geometry>
            <material name="Blue">
                <color rgba="0 0.0 1.0 1.0"/>
            </material>
        </visual>
        <collision>
            <origin xyz="0 0.36240542118959185 -0.3443090834030974" rpy="0 0 0"/>
            <geometry>
                <box size="0.6772855546117909 0.7248108423791837 0.6886181668061948" />
            </geometry>
        </collision>
    </link>
    <joint name="Link1_Link2" type="revolute">
       <parent link="Link1"/>
       <child  link="Link2"/>
       <origin rpy="0 0 0" xyz="0 0.0 0.0" />
     <axis xyz="1 0 0"/>
       <limit effort="0.0" lower="-3.14159" upper="3.14159" velocity="0.0"/>
    </joint>
    <link name="Link2">
        <inertial>
            <origin xyz="0 -0.47859527704791105 0.3391036430513392" rpy="0 0 0"/>
            <mass value="1" />
            <inertia ixx="100" ixy="0" ixz="0" iyy="100" iyz="0" izz="100" />
        </inertial>
        <visual>
            <origin xyz="0 -0.47859527704791105 0.3391036430513392" rpy="0 0 0"/>
            <geometry>
                <box size="0.8931137432281553 0.9571905540958221 0.6782072861026784" />
            </geometry>
            <material name="Green">
                <color rgba="0 1.0 0.0 1.0"/>
            </material>
        </visual>
        <collision>
            <origin xyz="0 -0.47859527704791105 0.3391036430513392" rpy="0 0 0"/>
            <geometry>
                <box size="0.8931137432281553 0.9571905540958221 0.6782072861026784" />
            </geometry>
        </collision>
    </link>
    <joint name="Link2_Link3" type="revolute">
       <parent link="Link2"/>
       <child  link="Link3"/>
       <origin rpy="0 0 0" xyz="0 0.0 0.6782072861026784" />
     <axis xyz="1 0 0"/>
       <limit effort="0.0" lower="-3.14159" upper="3.14159" velocity="0.0"/>
    </joint>
    <link name="Link3">
        <inertial>
            <origin xyz="0 0.17217884377523085 -0.03932049124810655" rpy="0 0 0"/>
            <mass value="1" />
            <inertia ixx="100" ixy="0" ixz="0" iyy="100" iyz="0" izz="100" />
        </inertial>
        <visual>
            <origin xyz="0 0.17217884377523085 -0.03932049124810655" rpy="0 0 0"/>
            <geometry>
                <box size="0.3975023647350059 0.3443576875504617 0.0786409824962131" />
            </geometry>
            <material name="Blue">
                <color rgba="0 0.0 1.0 1.0"/>
            </material>
        </visual>
        <collision>
            <origin xyz="0 0.17217884377523085 -0.03932049124810655" rpy="0 0 0"/>
            <geometry>
                <box size="0.3975023647350059 0.3443576875504617 0.0786409824962131" />
            </geometry>
        </collision>
    </link>
    <joint name="Link3_Link4" type="revolute">
       <parent link="Link3"/>
       <child  link="Link4"/>
       <origin rpy="0 0 0" xyz="0.19875118236750294 0.17217884377523085 0.0" />
     <axis xyz="0 1 0"/>
       <limit effort="0.0" lower="-3.14159" upper="3.14159" velocity="0.0"/>
    </joint>
    <link name="Link4">
        <inertial>
            <origin xyz="0.3081458582658194 0 -0.08225100791492451" rpy="0 0 0"/>
            <mass value="1" />
            <inertia ixx="100" ixy="0" ixz="0" iyy="100" iyz="0" izz="100" />
        </inertial>
        <visual>
            <origin xyz="0.3081458582658194 0 -0.08225100791492451" rpy="0 0 0"/>
            <geometry>
                <box size="0.6162917165316388 0.493453460865126 0.16450201582984902" />
            </geometry>
            <material name="Blue">
                <color rgba="0 0.0 1.0 1.0"/>
            </material>
        </visual>
        <collision>
            <origin xyz="0.3081458582658194 0 -0.08225100791492451" rpy="0 0 0"/>
            <geometry>
                <box size="0.6162917165316388 0.493453460865126 0.16450201582984902" />
            </geometry>
        </collision>
    </link>
</robot>