<robot name = "robot">
    <link name="Link0">
        <inertial>
            <origin xyz="0 0 2.201044761149296" rpy="0 0 0"/>
            <mass value="1" />
            <inertia ixx="100" ixy="0" ixz="0" iyy="100" iyz="0" izz="100" />
        </inertial>
        <visual>
            <origin xyz="0 0 2.201044761149296" rpy="0 0 0"/>
            <geometry>
                <box size="0.30517193527393016 0.20659679094190286 0.4020895222985923" />
            </geometry>
            <material name="Green">
                <color rgba="0 1.0 0.0 1.0"/>
            </material>
        </visual>
        <collision>
            <origin xyz="0 0 2.201044761149296" rpy="0 0 0"/>
            <geometry>
                <box size="0.30517193527393016 0.20659679094190286 0.4020895222985923" />
            </geometry>
        </collision>
    </link>
    <joint name="Link0_Link1" type="revolute">
       <parent link="Link0"/>
       <child  link="Link1"/>
       <origin rpy="0 0 0" xyz="0 0.10329839547095143 2.402089522298592" />
     <axis xyz="1 0 0"/>
       <limit effort="0.0" lower="-3.14159" upper="3.14159" velocity="0.0"/>
    </joint>
    <link name="Link1">
        <inertial>
            <origin xyz="0 0.10329839547095143 -0.20104476114929615" rpy="0 0 0"/>
            <mass value="1" />
            <inertia ixx="100" ixy="0" ixz="0" iyy="100" iyz="0" izz="100" />
        </inertial>
        <visual>
            <origin xyz="0 0.10329839547095143 -0.20104476114929615" rpy="0 0 0"/>
            <geometry>
                <box size="0.30517193527393016 0.20659679094190286 0.4020895222985923" />
            </geometry>
            <material name="Green">
                <color rgba="0 1.0 0.0 1.0"/>
            </material>
        </visual>
        <collision>
            <origin xyz="0 0.10329839547095143 -0.20104476114929615" rpy="0 0 0"/>
            <geometry>
                <box size="0.30517193527393016 0.20659679094190286 0.4020895222985923" />
            </geometry>
        </collision>
    </link>
    <joint name="Link1_Link2" type="revolute">
       <parent link="Link1"/>
       <child  link="Link2"/>
       <origin rpy="0 0 0" xyz="0 0.20659679094190286 0.0" />
     <axis xyz="1 0 0"/>
       <limit effort="0.0" lower="-3.14159" upper="3.14159" velocity="0.0"/>
    </joint>
    <link name="Link2">
        <inertial>
            <origin xyz="0 0.04062850847337601 0.42664986127327403" rpy="0 0 0"/>
            <mass value="1" />
            <inertia ixx="100" ixy="0" ixz="0" iyy="100" iyz="0" izz="100" />
        </inertial>
        <visual>
            <origin xyz="0 0.04062850847337601 0.42664986127327403" rpy="0 0 0"/>
            <geometry>
                <box size="0.2714879910246326 0.08125701694675203 0.8532997225465481" />
            </geometry>
            <material name="Blue">
                <color rgba="0 0.0 1.0 1.0"/>
            </material>
        </visual>
        <collision>
            <origin xyz="0 0.04062850847337601 0.42664986127327403" rpy="0 0 0"/>
            <geometry>
                <box size="0.2714879910246326 0.08125701694675203 0.8532997225465481" />
            </geometry>
        </collision>
    </link>
    <joint name="Link2_Link3" type="revolute">
       <parent link="Link2"/>
       <child  link="Link3"/>
       <origin rpy="0 0 0" xyz="0 0.0 0.8532997225465481" />
     <axis xyz="1 0 0"/>
       <limit effort="0.0" lower="-3.14159" upper="3.14159" velocity="0.0"/>
    </joint>
    <link name="Link3">
        <inertial>
            <origin xyz="0 -0.35508867779974085 0.02301975866352335" rpy="0 0 0"/>
            <mass value="1" />
            <inertia ixx="100" ixy="0" ixz="0" iyy="100" iyz="0" izz="100" />
        </inertial>
        <visual>
            <origin xyz="0 -0.35508867779974085 0.02301975866352335" rpy="0 0 0"/>
            <geometry>
                <box size="0.9705545870538411 0.7101773555994817 0.0460395173270467" />
            </geometry>
            <material name="Blue">
                <color rgba="0 0.0 1.0 1.0"/>
            </material>
        </visual>
        <collision>
            <origin xyz="0 -0.35508867779974085 0.02301975866352335" rpy="0 0 0"/>
            <geometry>
                <box size="0.9705545870538411 0.7101773555994817 0.0460395173270467" />
            </geometry>
        </collision>
    </link>
    <joint name="Link3_Link4" type="revolute">
       <parent link="Link3"/>
       <child  link="Link4"/>
       <origin rpy="0 0 0" xyz="0 0.0 0.0460395173270467" />
     <axis xyz="1 0 0"/>
       <limit effort="0.0" lower="-3.14159" upper="3.14159" velocity="0.0"/>
    </joint>
    <link name="Link4">
        <inertial>
            <origin xyz="0 0.42212324149656033 -0.14951168099796902" rpy="0 0 0"/>
            <mass value="1" />
            <inertia ixx="100" ixy="0" ixz="0" iyy="100" iyz="0" izz="100" />
        </inertial>
        <visual>
            <origin xyz="0 0.42212324149656033 -0.14951168099796902" rpy="0 0 0"/>
            <geometry>
                <box size="0.7948594822167999 0.8442464829931207 0.29902336199593804" />
            </geometry>
            <material name="Blue">
                <color rgba="0 0.0 1.0 1.0"/>
            </material>
        </visual>
        <collision>
            <origin xyz="0 0.42212324149656033 -0.14951168099796902" rpy="0 0 0"/>
            <geometry>
                <box size="0.7948594822167999 0.8442464829931207 0.29902336199593804" />
            </geometry>
        </collision>
    </link>
</robot>