<robot name = "robot">
    <link name="Link0">
        <inertial>
            <origin xyz="0 0 2.468230934251098" rpy="0 0 0"/>
            <mass value="1" />
            <inertia ixx="100" ixy="0" ixz="0" iyy="100" iyz="0" izz="100" />
        </inertial>
        <visual>
            <origin xyz="0 0 2.468230934251098" rpy="0 0 0"/>
            <geometry>
                <box size="0.779240724199823 0.605936447851724 0.9364618685021957" />
            </geometry>
            <material name="Green">
                <color rgba="0 1.0 0.0 1.0"/>
            </material>
        </visual>
        <collision>
            <origin xyz="0 0 2.468230934251098" rpy="0 0 0"/>
            <geometry>
                <box size="0.779240724199823 0.605936447851724 0.9364618685021957" />
            </geometry>
        </collision>
    </link>
    <joint name="Link0_Link1" type="revolute">
       <parent link="Link0"/>
       <child  link="Link1"/>
       <origin rpy="0 0 0" xyz="0 0.302968223925862 2.936461868502196" />
     <axis xyz="1 0 0"/>
       <limit effort="0.0" lower="-3.14159" upper="3.14159" velocity="0.0"/>
    </joint>
    <link name="Link1">
        <inertial>
            <origin xyz="0 0.302968223925862 -0.46823093425109785" rpy="0 0 0"/>
            <mass value="1" />
            <inertia ixx="100" ixy="0" ixz="0" iyy="100" iyz="0" izz="100" />
        </inertial>
        <visual>
            <origin xyz="0 0.302968223925862 -0.46823093425109785" rpy="0 0 0"/>
            <geometry>
                <box size="0.779240724199823 0.605936447851724 0.9364618685021957" />
            </geometry>
            <material name="Blue">
                <color rgba="0 0.0 1.0 1.0"/>
            </material>
        </visual>
        <collision>
            <origin xyz="0 0.302968223925862 -0.46823093425109785" rpy="0 0 0"/>
            <geometry>
                <box size="0.779240724199823 0.605936447851724 0.9364618685021957" />
            </geometry>
        </collision>
    </link>
    <joint name="Link1_Link2" type="revolute">
       <parent link="Link1"/>
       <child  link="Link2"/>
       <origin rpy="0 0 0" xyz="0.3896203620999115 0.302968223925862 0.0" />
     <axis xyz="0 1 0"/>
       <limit effort="0.0" lower="-3.14159" upper="3.14159" velocity="0.0"/>
    </joint>
    <link name="Link2">
        <inertial>
            <origin xyz="0.49402762113293897 0 -0.2177934225940334" rpy="0 0 0"/>
            <mass value="1" />
            <inertia ixx="100" ixy="0" ixz="0" iyy="100" iyz="0" izz="100" />
        </inertial>
        <visual>
            <origin xyz="0.49402762113293897 0 -0.2177934225940334" rpy="0 0 0"/>
            <geometry>
                <box size="0.9880552422658779 0.9002791890401283 0.4355868451880668" />
            </geometry>
            <material name="Green">
                <color rgba="0 1.0 0.0 1.0"/>
            </material>
        </visual>
        <collision>
            <origin xyz="0.49402762113293897 0 -0.2177934225940334" rpy="0 0 0"/>
            <geometry>
                <box size="0.9880552422658779 0.9002791890401283 0.4355868451880668" />
            </geometry>
        </collision>
    </link>
    <joint name="Link2_Link3" type="revolute">
       <parent link="Link2"/>
       <child  link="Link3"/>
       <origin rpy="0 0 0" xyz="0.9880552422658779 0 0.0" />
     <axis xyz="0 1 0"/>
       <limit effort="0.0" lower="-3.14159" upper="3.14159" velocity="0.0"/>
    </joint>
    <link name="Link3">
        <inertial>
            <origin xyz="0.37537674555506895 0 -0.1331573423880234" rpy="0 0 0"/>
            <mass value="1" />
            <inertia ixx="100" ixy="0" ixz="0" iyy="100" iyz="0" izz="100" />
        </inertial>
        <visual>
            <origin xyz="0.37537674555506895 0 -0.1331573423880234" rpy="0 0 0"/>
            <geometry>
                <box size="0.7507534911101379 0.04795418664847928 0.2663146847760468" />
            </geometry>
            <material name="Blue">
                <color rgba="0 0.0 1.0 1.0"/>
            </material>
        </visual>
        <collision>
            <origin xyz="0.37537674555506895 0 -0.1331573423880234" rpy="0 0 0"/>
            <geometry>
                <box size="0.7507534911101379 0.04795418664847928 0.2663146847760468" />
            </geometry>
        </collision>
    </link>
    <joint name="Link3_Link4" type="revolute">
       <parent link="Link3"/>
       <child  link="Link4"/>
       <origin rpy="0 0 0" xyz="0.7507534911101379 0 0.0" />
     <axis xyz="0 1 0"/>
       <limit effort="0.0" lower="-3.14159" upper="3.14159" velocity="0.0"/>
    </joint>
    <link name="Link4">
        <inertial>
            <origin xyz="0.45898771076330913 0 0.11168320600673981" rpy="0 0 0"/>
            <mass value="1" />
            <inertia ixx="100" ixy="0" ixz="0" iyy="100" iyz="0" izz="100" />
        </inertial>
        <visual>
            <origin xyz="0.45898771076330913 0 0.11168320600673981" rpy="0 0 0"/>
            <geometry>
                <box size="0.9179754215266183 0.5718933015373954 0.22336641201347962" />
            </geometry>
            <material name="Blue">
                <color rgba="0 0.0 1.0 1.0"/>
            </material>
        </visual>
        <collision>
            <origin xyz="0.45898771076330913 0 0.11168320600673981" rpy="0 0 0"/>
            <geometry>
                <box size="0.9179754215266183 0.5718933015373954 0.22336641201347962" />
            </geometry>
        </collision>
    </link>
    <joint name="Link4_Link5" type="revolute">
       <parent link="Link4"/>
       <child  link="Link5"/>
       <origin rpy="0 0 0" xyz="0.0 0 0.22336641201347962" />
     <axis xyz="0 1 0"/>
       <limit effort="0.0" lower="-3.14159" upper="3.14159" velocity="0.0"/>
    </joint>
    <link name="Link5">
        <inertial>
            <origin xyz="-0.41408749719663973 0 -0.4120576271570139" rpy="0 0 0"/>
            <mass value="1" />
            <inertia ixx="100" ixy="0" ixz="0" iyy="100" iyz="0" izz="100" />
        </inertial>
        <visual>
            <origin xyz="-0.41408749719663973 0 -0.4120576271570139" rpy="0 0 0"/>
            <geometry>
                <box size="0.8281749943932795 0.12721846540092663 0.8241152543140278" />
            </geometry>
            <material name="Green">
                <color rgba="0 1.0 0.0 1.0"/>
            </material>
        </visual>
        <collision>
            <origin xyz="-0.41408749719663973 0 -0.4120576271570139" rpy="0 0 0"/>
            <geometry>
                <box size="0.8281749943932795 0.12721846540092663 0.8241152543140278" />
            </geometry>
        </collision>
    </link>
    <joint name="Link5_Link6" type="revolute">
       <parent link="Link5"/>
       <child  link="Link6"/>
       <origin rpy="0 0 0" xyz="-0.41408749719663973 -0.06360923270046331 0.0" />
     <axis xyz="1 0 0"/>
       <limit effort="0.0" lower="-3.14159" upper="3.14159" velocity="0.0"/>
    </joint>
    <link name="Link6">
        <inertial>
            <origin xyz="0 -0.28984075138979043 0.09522446981530852" rpy="0 0 0"/>
            <mass value="1" />
            <inertia ixx="100" ixy="0" ixz="0" iyy="100" iyz="0" izz="100" />
        </inertial>
        <visual>
            <origin xyz="0 -0.28984075138979043 0.09522446981530852" rpy="0 0 0"/>
            <geometry>
                <box size="0.7151060891957025 0.5796815027795809 0.19044893963061704" />
            </geometry>
            <material name="Blue">
                <color rgba="0 0.0 1.0 1.0"/>
            </material>
        </visual>
        <collision>
            <origin xyz="0 -0.28984075138979043 0.09522446981530852" rpy="0 0 0"/>
            <geometry>
                <box size="0.7151060891957025 0.5796815027795809 0.19044893963061704" />
            </geometry>
        </collision>
    </link>
</robot>