<robot name = "robot">
    <link name="Link0">
        <inertial>
            <origin xyz="0 0 2.3327559255501877" rpy="0 0 0"/>
            <mass value="1" />
            <inertia ixx="100" ixy="0" ixz="0" iyy="100" iyz="0" izz="100" />
        </inertial>
        <visual>
            <origin xyz="0 0 2.3327559255501877" rpy="0 0 0"/>
            <geometry>
                <box size="0.8613054058102116 0.23235791688765928 0.6655118511003753" />
            </geometry>
            <material name="Green">
                <color rgba="0 1.0 0.0 1.0"/>
            </material>
        </visual>
        <collision>
            <origin xyz="0 0 2.3327559255501877" rpy="0 0 0"/>
            <geometry>
                <box size="0.8613054058102116 0.23235791688765928 0.6655118511003753" />
            </geometry>
        </collision>
    </link>
    <joint name="Link0_Link1" type="revolute">
       <parent link="Link0"/>
       <child  link="Link1"/>
       <origin rpy="0 0 0" xyz="0 0.11617895844382964 2.6655118511003755" />
     <axis xyz="1 0 0"/>
       <limit effort="0.0" lower="-3.14159" upper="3.14159" velocity="0.0"/>
    </joint>
    <link name="Link1">
        <inertial>
            <origin xyz="0 0.11617895844382964 -0.3327559255501876" rpy="0 0 0"/>
            <mass value="1" />
            <inertia ixx="100" ixy="0" ixz="0" iyy="100" iyz="0" izz="100" />
        </inertial>
        <visual>
            <origin xyz="0 0.11617895844382964 -0.3327559255501876" rpy="0 0 0"/>
            <geometry>
                <box size="0.8613054058102116 0.23235791688765928 0.6655118511003753" />
            </geometry>
            <material name="Green">
                <color rgba="0 1.0 0.0 1.0"/>
            </material>
        </visual>
        <collision>
            <origin xyz="0 0.11617895844382964 -0.3327559255501876" rpy="0 0 0"/>
            <geometry>
                <box size="0.8613054058102116 0.23235791688765928 0.6655118511003753" />
            </geometry>
        </collision>
    </link>
    <joint name="Link1_Link2" type="revolute">
       <parent link="Link1"/>
       <child  link="Link2"/>
       <origin rpy="0 0 0" xyz="0 0.23235791688765928 0.0" />
     <axis xyz="1 0 0"/>
       <limit effort="0.0" lower="-3.14159" upper="3.14159" velocity="0.0"/>
    </joint>
    <link name="Link2">
        <inertial>
            <origin xyz="0 0.03107250206195622 -0.0760607034220589" rpy="0 0 0"/>
            <mass value="1" />
            <inertia ixx="100" ixy="0" ixz="0" iyy="100" iyz="0" izz="100" />
        </inertial>
        <visual>
            <origin xyz="0 0.03107250206195622 -0.0760607034220589" rpy="0 0 0"/>
            <geometry>
                <box size="0.6104738113493106 0.06214500412391244 0.1521214068441178" />
            </geometry>
            <material name="Blue">
                <color rgba="0 0.0 1.0 1.0"/>
            </material>
        </visual>
        <collision>
            <origin xyz="0 0.03107250206195622 -0.0760607034220589" rpy="0 0 0"/>
            <geometry>
                <box size="0.6104738113493106 0.06214500412391244 0.1521214068441178" />
            </geometry>
        </collision>
    </link>
    <joint name="Link2_Link3" type="revolute">
       <parent link="Link2"/>
       <child  link="Link3"/>
       <origin rpy="0 0 0" xyz="-0.3052369056746553 0.03107250206195622 0.0" />
     <axis xyz="0 1 0"/>
       <limit effort="0.0" lower="-3.14159" upper="3.14159" velocity="0.0"/>
    </joint>
    <link name="Link3">
        <inertial>
            <origin xyz="-0.40349841254662994 0 0.2755820327091397" rpy="0 0 0"/>
            <mass value="1" />
            <inertia ixx="100" ixy="0" ixz="0" iyy="100" iyz="0" izz="100" />
        </inertial>
        <visual>
            <origin xyz="-0.40349841254662994 0 0.2755820327091397" rpy="0 0 0"/>
            <geometry>
                <box size="0.8069968250932599 0.24391914739266018 0.5511640654182794" />
            </geometry>
            <material name="Blue">
                <color rgba="0 0.0 1.0 1.0"/>
            </material>
        </visual>
        <collision>
            <origin xyz="-0.40349841254662994 0 0.2755820327091397" rpy="0 0 0"/>
            <geometry>
                <box size="0.8069968250932599 0.24391914739266018 0.5511640654182794" />
            </geometry>
        </collision>
    </link>
    <joint name="Link3_Link4" type="revolute">
       <parent link="Link3"/>
       <child  link="Link4"/>
       <origin rpy="0 0 0" xyz="0.0 0 0.5511640654182794" />
     <axis xyz="0 1 0"/>
       <limit effort="0.0" lower="-3.14159" upper="3.14159" velocity="0.0"/>
    </joint>
    <link name="Link4">
        <inertial>
            <origin xyz="0.15923499446384204 0 -0.11435438137543474" rpy="0 0 0"/>
            <mass value="1" />
            <inertia ixx="100" ixy="0" ixz="0" iyy="100" iyz="0" izz="100" />
        </inertial>
        <visual>
            <origin xyz="0.15923499446384204 0 -0.11435438137543474" rpy="0 0 0"/>
            <geometry>
                <box size="0.3184699889276841 0.8226296563051043 0.2287087627508695" />
            </geometry>
            <material name="Green">
                <color rgba="0 1.0 0.0 1.0"/>
            </material>
        </visual>
        <collision>
            <origin xyz="0.15923499446384204 0 -0.11435438137543474" rpy="0 0 0"/>
            <geometry>
                <box size="0.3184699889276841 0.8226296563051043 0.2287087627508695" />
            </geometry>
        </collision>
    </link>
</robot>