<robot name = "robot">
    <link name="Link0">
        <inertial>
            <origin xyz="0 0 2.0106860565037796" rpy="0 0 0"/>
            <mass value="1" />
            <inertia ixx="100" ixy="0" ixz="0" iyy="100" iyz="0" izz="100" />
        </inertial>
        <visual>
            <origin xyz="0 0 2.0106860565037796" rpy="0 0 0"/>
            <geometry>
                <box size="0.9240645676442127 0.3564588219697452 0.021372113007559257" />
            </geometry>
            <material name="Green">
                <color rgba="0 1.0 0.0 1.0"/>
            </material>
        </visual>
        <collision>
            <origin xyz="0 0 2.0106860565037796" rpy="0 0 0"/>
            <geometry>
                <box size="0.9240645676442127 0.3564588219697452 0.021372113007559257" />
            </geometry>
        </collision>
    </link>
    <joint name="Link0_Link1" type="revolute">
       <parent link="Link0"/>
       <child  link="Link1"/>
       <origin rpy="0 0 0" xyz="0 0.1782294109848726 2.0213721130075593" />
     <axis xyz="1 0 0"/>
       <limit effort="0.0" lower="-3.14159" upper="3.14159" velocity="0.0"/>
    </joint>
    <link name="Link1">
        <inertial>
            <origin xyz="0 0.1782294109848726 -0.010686056503779628" rpy="0 0 0"/>
            <mass value="1" />
            <inertia ixx="100" ixy="0" ixz="0" iyy="100" iyz="0" izz="100" />
        </inertial>
        <visual>
            <origin xyz="0 0.1782294109848726 -0.010686056503779628" rpy="0 0 0"/>
            <geometry>
                <box size="0.9240645676442127 0.3564588219697452 0.021372113007559257" />
            </geometry>
            <material name="Green">
                <color rgba="0 1.0 0.0 1.0"/>
            </material>
        </visual>
        <collision>
            <origin xyz="0 0.1782294109848726 -0.010686056503779628" rpy="0 0 0"/>
            <geometry>
                <box size="0.9240645676442127 0.3564588219697452 0.021372113007559257" />
            </geometry>
        </collision>
    </link>
    <joint name="Link1_Link2" type="revolute">
       <parent link="Link1"/>
       <child  link="Link2"/>
       <origin rpy="0 0 0" xyz="0 0.0 0.0" />
     <axis xyz="1 0 0"/>
       <limit effort="0.0" lower="-3.14159" upper="3.14159" velocity="0.0"/>
    </joint>
    <link name="Link2">
        <inertial>
            <origin xyz="0 -0.13501210041276357 -0.11451897442195846" rpy="0 0 0"/>
            <mass value="1" />
            <inertia ixx="100" ixy="0" ixz="0" iyy="100" iyz="0" izz="100" />
        </inertial>
        <visual>
            <origin xyz="0 -0.13501210041276357 -0.11451897442195846" rpy="0 0 0"/>
            <geometry>
                <box size="0.32495536226970134 0.27002420082552714 0.22903794884391693" />
            </geometry>
            <material name="Green">
                <color rgba="0 1.0 0.0 1.0"/>
            </material>
        </visual>
        <collision>
            <origin xyz="0 -0.13501210041276357 -0.11451897442195846" rpy="0 0 0"/>
            <geometry>
                <box size="0.32495536226970134 0.27002420082552714 0.22903794884391693" />
            </geometry>
        </collision>
    </link>
    <joint name="Link2_Link3" type="revolute">
       <parent link="Link2"/>
       <child  link="Link3"/>
       <origin rpy="0 0 0" xyz="-0.16247768113485067 -0.13501210041276357 0.0" />
     <axis xyz="0 1 0"/>
       <limit effort="0.0" lower="-3.14159" upper="3.14159" velocity="0.0"/>
    </joint>
    <link name="Link3">
        <inertial>
            <origin xyz="-0.34028532035469516 0 0.3315816136803659" rpy="0 0 0"/>
            <mass value="1" />
            <inertia ixx="100" ixy="0" ixz="0" iyy="100" iyz="0" izz="100" />
        </inertial>
        <visual>
            <origin xyz="-0.34028532035469516 0 0.3315816136803659" rpy="0 0 0"/>
            <geometry>
                <box size="0.6805706407093903 0.5871912771279745 0.6631632273607319" />
            </geometry>
            <material name="Green">
                <color rgba="0 1.0 0.0 1.0"/>
            </material>
        </visual>
        <collision>
            <origin xyz="-0.34028532035469516 0 0.3315816136803659" rpy="0 0 0"/>
            <geometry>
                <box size="0.6805706407093903 0.5871912771279745 0.6631632273607319" />
            </geometry>
        </collision>
    </link>
    <joint name="Link3_Link4" type="revolute">
       <parent link="Link3"/>
       <child  link="Link4"/>
       <origin rpy="0 0 0" xyz="-0.34028532035469516 0.29359563856398724 0.6631632273607319" />
     <axis xyz="1 0 0"/>
       <limit effort="0.0" lower="-3.14159" upper="3.14159" velocity="0.0"/>
    </joint>
    <link name="Link4">
        <inertial>
            <origin xyz="0 0.4996478234303258 0.38657741146452984" rpy="0 0 0"/>
            <mass value="1" />
            <inertia ixx="100" ixy="0" ixz="0" iyy="100" iyz="0" izz="100" />
        </inertial>
        <visual>
            <origin xyz="0 0.4996478234303258 0.38657741146452984" rpy="0 0 0"/>
            <geometry>
                <box size="0.873854119560313 0.9992956468606516 0.7731548229290597" />
            </geometry>
            <material name="Blue">
                <color rgba="0 0.0 1.0 1.0"/>
            </material>
        </visual>
        <collision>
            <origin xyz="0 0.4996478234303258 0.38657741146452984" rpy="0 0 0"/>
            <geometry>
                <box size="0.873854119560313 0.9992956468606516 0.7731548229290597" />
            </geometry>
        </collision>
    </link>
</robot>