<robot name = "robot">
    <link name="Link0">
        <inertial>
            <origin xyz="0 0 2.4525342513330255" rpy="0 0 0"/>
            <mass value="1" />
            <inertia ixx="100" ixy="0" ixz="0" iyy="100" iyz="0" izz="100" />
        </inertial>
        <visual>
            <origin xyz="0 0 2.4525342513330255" rpy="0 0 0"/>
            <geometry>
                <box size="0.8093154903463335 0.5286544271007811 0.9050685026660514" />
            </geometry>
            <material name="Green">
                <color rgba="0 1.0 0.0 1.0"/>
            </material>
        </visual>
        <collision>
            <origin xyz="0 0 2.4525342513330255" rpy="0 0 0"/>
            <geometry>
                <box size="0.8093154903463335 0.5286544271007811 0.9050685026660514" />
            </geometry>
        </collision>
    </link>
    <joint name="Link0_Link1" type="revolute">
       <parent link="Link0"/>
       <child  link="Link1"/>
       <origin rpy="0 0 0" xyz="0 0.26432721355039057 2.9050685026660514" />
     <axis xyz="1 0 0"/>
       <limit effort="0.0" lower="-3.14159" upper="3.14159" velocity="0.0"/>
    </joint>
    <link name="Link1">
        <inertial>
            <origin xyz="0 0.26432721355039057 -0.4525342513330257" rpy="0 0 0"/>
            <mass value="1" />
            <inertia ixx="100" ixy="0" ixz="0" iyy="100" iyz="0" izz="100" />
        </inertial>
        <visual>
            <origin xyz="0 0.26432721355039057 -0.4525342513330257" rpy="0 0 0"/>
            <geometry>
                <box size="0.8093154903463335 0.5286544271007811 0.9050685026660514" />
            </geometry>
            <material name="Green">
                <color rgba="0 1.0 0.0 1.0"/>
            </material>
        </visual>
        <collision>
            <origin xyz="0 0.26432721355039057 -0.4525342513330257" rpy="0 0 0"/>
            <geometry>
                <box size="0.8093154903463335 0.5286544271007811 0.9050685026660514" />
            </geometry>
        </collision>
    </link>
    <joint name="Link1_Link2" type="revolute">
       <parent link="Link1"/>
       <child  link="Link2"/>
       <origin rpy="0 0 0" xyz="0 0.5286544271007811 0.0" />
     <axis xyz="1 0 0"/>
       <limit effort="0.0" lower="-3.14159" upper="3.14159" velocity="0.0"/>
    </joint>
    <link name="Link2">
        <inertial>
            <origin xyz="0 0.4752702127604852 0.24977340187608033" rpy="0 0 0"/>
            <mass value="1" />
            <inertia ixx="100" ixy="0" ixz="0" iyy="100" iyz="0" izz="100" />
        </inertial>
        <visual>
            <origin xyz="0 0.4752702127604852 0.24977340187608033" rpy="0 0 0"/>
            <geometry>
                <box size="0.1564660089699319 0.9505404255209704 0.49954680375216065" />
            </geometry>
            <material name="Green">
                <color rgba="0 1.0 0.0 1.0"/>
            </material>
        </visual>
        <collision>
            <origin xyz="0 0.4752702127604852 0.24977340187608033" rpy="0 0 0"/>
            <geometry>
                <box size="0.1564660089699319 0.9505404255209704 0.49954680375216065" />
            </geometry>
        </collision>
    </link>
    <joint name="Link2_Link3" type="revolute">
       <parent link="Link2"/>
       <child  link="Link3"/>
       <origin rpy="0 0 0" xyz="0 0.0 0.49954680375216065" />
     <axis xyz="1 0 0"/>
       <limit effort="0.0" lower="-3.14159" upper="3.14159" velocity="0.0"/>
    </joint>
    <link name="Link3">
        <inertial>
            <origin xyz="0 -0.2733557310165556 0.3584190847034495" rpy="0 0 0"/>
            <mass value="1" />
            <inertia ixx="100" ixy="0" ixz="0" iyy="100" iyz="0" izz="100" />
        </inertial>
        <visual>
            <origin xyz="0 -0.2733557310165556 0.3584190847034495" rpy="0 0 0"/>
            <geometry>
                <box size="0.7640006670540074 0.5467114620331112 0.716838169406899" />
            </geometry>
            <material name="Blue">
                <color rgba="0 0.0 1.0 1.0"/>
            </material>
        </visual>
        <collision>
            <origin xyz="0 -0.2733557310165556 0.3584190847034495" rpy="0 0 0"/>
            <geometry>
                <box size="0.7640006670540074 0.5467114620331112 0.716838169406899" />
            </geometry>
        </collision>
    </link>
    <joint name="Link3_Link4" type="revolute">
       <parent link="Link3"/>
       <child  link="Link4"/>
       <origin rpy="0 0 0" xyz="0.3820003335270037 -0.2733557310165556 0.716838169406899" />
     <axis xyz="0 1 0"/>
       <limit effort="0.0" lower="-3.14159" upper="3.14159" velocity="0.0"/>
    </joint>
    <link name="Link4">
        <inertial>
            <origin xyz="0.4397486552072123 0 -0.10335519120859776" rpy="0 0 0"/>
            <mass value="1" />
            <inertia ixx="100" ixy="0" ixz="0" iyy="100" iyz="0" izz="100" />
        </inertial>
        <visual>
            <origin xyz="0.4397486552072123 0 -0.10335519120859776" rpy="0 0 0"/>
            <geometry>
                <box size="0.8794973104144246 0.3673914357542776 0.20671038241719553" />
            </geometry>
            <material name="Green">
                <color rgba="0 1.0 0.0 1.0"/>
            </material>
        </visual>
        <collision>
            <origin xyz="0.4397486552072123 0 -0.10335519120859776" rpy="0 0 0"/>
            <geometry>
                <box size="0.8794973104144246 0.3673914357542776 0.20671038241719553" />
            </geometry>
        </collision>
    </link>
</robot>