<robot name = "robot">
    <link name="Link0">
        <inertial>
            <origin xyz="0 0 2.376533264478966" rpy="0 0 0"/>
            <mass value="1" />
            <inertia ixx="100" ixy="0" ixz="0" iyy="100" iyz="0" izz="100" />
        </inertial>
        <visual>
            <origin xyz="0 0 2.376533264478966" rpy="0 0 0"/>
            <geometry>
                <box size="0.5597719450657079 0.19706487705511422 0.753066528957932" />
            </geometry>
            <material name="Green">
                <color rgba="0 1.0 0.0 1.0"/>
            </material>
        </visual>
        <collision>
            <origin xyz="0 0 2.376533264478966" rpy="0 0 0"/>
            <geometry>
                <box size="0.5597719450657079 0.19706487705511422 0.753066528957932" />
            </geometry>
        </collision>
    </link>
    <joint name="Link0_Link1" type="revolute">
       <parent link="Link0"/>
       <child  link="Link1"/>
       <origin rpy="0 0 0" xyz="0 0.09853243852755711 2.753066528957932" />
     <axis xyz="1 0 0"/>
       <limit effort="0.0" lower="-3.14159" upper="3.14159" velocity="0.0"/>
    </joint>
    <link name="Link1">
        <inertial>
            <origin xyz="0 0.09853243852755711 -0.376533264478966" rpy="0 0 0"/>
            <mass value="1" />
            <inertia ixx="100" ixy="0" ixz="0" iyy="100" iyz="0" izz="100" />
        </inertial>
        <visual>
            <origin xyz="0 0.09853243852755711 -0.376533264478966" rpy="0 0 0"/>
            <geometry>
                <box size="0.5597719450657079 0.19706487705511422 0.753066528957932" />
            </geometry>
            <material name="Blue">
                <color rgba="0 0.0 1.0 1.0"/>
            </material>
        </visual>
        <collision>
            <origin xyz="0 0.09853243852755711 -0.376533264478966" rpy="0 0 0"/>
            <geometry>
                <box size="0.5597719450657079 0.19706487705511422 0.753066528957932" />
            </geometry>
        </collision>
    </link>
    <joint name="Link1_Link2" type="revolute">
       <parent link="Link1"/>
       <child  link="Link2"/>
       <origin rpy="0 0 0" xyz="0 0.19706487705511422 0.0" />
     <axis xyz="1 0 0"/>
       <limit effort="0.0" lower="-3.14159" upper="3.14159" velocity="0.0"/>
    </joint>
    <link name="Link2">
        <inertial>
            <origin xyz="0 0.01105518441447051 0.08523963611046953" rpy="0 0 0"/>
            <mass value="1" />
            <inertia ixx="100" ixy="0" ixz="0" iyy="100" iyz="0" izz="100" />
        </inertial>
        <visual>
            <origin xyz="0 0.01105518441447051 0.08523963611046953" rpy="0 0 0"/>
            <geometry>
                <box size="0.4566833091146624 0.02211036882894102 0.17047927222093906" />
            </geometry>
            <material name="Blue">
                <color rgba="0 0.0 1.0 1.0"/>
            </material>
        </visual>
        <collision>
            <origin xyz="0 0.01105518441447051 0.08523963611046953" rpy="0 0 0"/>
            <geometry>
                <box size="0.4566833091146624 0.02211036882894102 0.17047927222093906" />
            </geometry>
        </collision>
    </link>
    <joint name="Link2_Link3" type="revolute">
       <parent link="Link2"/>
       <child  link="Link3"/>
       <origin rpy="0 0 0" xyz="0.2283416545573312 0.01105518441447051 0.17047927222093906" />
     <axis xyz="0 1 0"/>
       <limit effort="0.0" lower="-3.14159" upper="3.14159" velocity="0.0"/>
    </joint>
    <link name="Link3">
        <inertial>
            <origin xyz="0.19493042283795403 0 0.26160113703157395" rpy="0 0 0"/>
            <mass value="1" />
            <inertia ixx="100" ixy="0" ixz="0" iyy="100" iyz="0" izz="100" />
        </inertial>
        <visual>
            <origin xyz="0.19493042283795403 0 0.26160113703157395" rpy="0 0 0"/>
            <geometry>
                <box size="0.38986084567590806 0.11086953847688763 0.5232022740631479" />
            </geometry>
            <material name="Green">
                <color rgba="0 1.0 0.0 1.0"/>
            </material>
        </visual>
        <collision>
            <origin xyz="0.19493042283795403 0 0.26160113703157395" rpy="0 0 0"/>
            <geometry>
                <box size="0.38986084567590806 0.11086953847688763 0.5232022740631479" />
            </geometry>
        </collision>
    </link>
    <joint name="Link3_Link4" type="revolute">
       <parent link="Link3"/>
       <child  link="Link4"/>
       <origin rpy="0 0 0" xyz="0.38986084567590806 0 0.5232022740631479" />
     <axis xyz="0 1 0"/>
       <limit effort="0.0" lower="-3.14159" upper="3.14159" velocity="0.0"/>
    </joint>
    <link name="Link4">
        <inertial>
            <origin xyz="0.3485385269711927 0 0.04915386182246401" rpy="0 0 0"/>
            <mass value="1" />
            <inertia ixx="100" ixy="0" ixz="0" iyy="100" iyz="0" izz="100" />
        </inertial>
        <visual>
            <origin xyz="0.3485385269711927 0 0.04915386182246401" rpy="0 0 0"/>
            <geometry>
                <box size="0.6970770539423854 0.28108984116585667 0.09830772364492801" />
            </geometry>
            <material name="Blue">
                <color rgba="0 0.0 1.0 1.0"/>
            </material>
        </visual>
        <collision>
            <origin xyz="0.3485385269711927 0 0.04915386182246401" rpy="0 0 0"/>
            <geometry>
                <box size="0.6970770539423854 0.28108984116585667 0.09830772364492801" />
            </geometry>
        </collision>
    </link>
    <joint name="Link4_Link5" type="revolute">
       <parent link="Link4"/>
       <child  link="Link5"/>
       <origin rpy="0 0 0" xyz="0.3485385269711927 -0.14054492058292833 0.09830772364492801" />
     <axis xyz="1 0 0"/>
       <limit effort="0.0" lower="-3.14159" upper="3.14159" velocity="0.0"/>
    </joint>
    <link name="Link5">
        <inertial>
            <origin xyz="0 -0.31040696725415645 0.2270227774666218" rpy="0 0 0"/>
            <mass value="1" />
            <inertia ixx="100" ixy="0" ixz="0" iyy="100" iyz="0" izz="100" />
        </inertial>
        <visual>
            <origin xyz="0 -0.31040696725415645 0.2270227774666218" rpy="0 0 0"/>
            <geometry>
                <box size="0.6548486358497378 0.6208139345083129 0.4540455549332436" />
            </geometry>
            <material name="Green">
                <color rgba="0 1.0 0.0 1.0"/>
            </material>
        </visual>
        <collision>
            <origin xyz="0 -0.31040696725415645 0.2270227774666218" rpy="0 0 0"/>
            <geometry>
                <box size="0.6548486358497378 0.6208139345083129 0.4540455549332436" />
            </geometry>
        </collision>
    </link>
    <joint name="Link5_Link6" type="revolute">
       <parent link="Link5"/>
       <child  link="Link6"/>
       <origin rpy="0 0 0" xyz="0 0.0 0.4540455549332436" />
     <axis xyz="1 0 0"/>
       <limit effort="0.0" lower="-3.14159" upper="3.14159" velocity="0.0"/>
    </joint>
    <link name="Link6">
        <inertial>
            <origin xyz="0 0.23587028935587795 0.4328510807236998" rpy="0 0 0"/>
            <mass value="1" />
            <inertia ixx="100" ixy="0" ixz="0" iyy="100" iyz="0" izz="100" />
        </inertial>
        <visual>
            <origin xyz="0 0.23587028935587795 0.4328510807236998" rpy="0 0 0"/>
            <geometry>
                <box size="0.6114581451286768 0.4717405787117559 0.8657021614473996" />
            </geometry>
            <material name="Green">
                <color rgba="0 1.0 0.0 1.0"/>
            </material>
        </visual>
        <collision>
            <origin xyz="0 0.23587028935587795 0.4328510807236998" rpy="0 0 0"/>
            <geometry>
                <box size="0.6114581451286768 0.4717405787117559 0.8657021614473996" />
            </geometry>
        </collision>
    </link>
</robot>