<robot name = "robot">
    <link name="Link0">
        <inertial>
            <origin xyz="0 0 2.0785895603303706" rpy="0 0 0"/>
            <mass value="1" />
            <inertia ixx="100" ixy="0" ixz="0" iyy="100" iyz="0" izz="100" />
        </inertial>
        <visual>
            <origin xyz="0 0 2.0785895603303706" rpy="0 0 0"/>
            <geometry>
                <box size="0.296803845878281 0.6127847712001007 0.1571791206607408" />
            </geometry>
            <material name="Green">
                <color rgba="0 1.0 0.0 1.0"/>
            </material>
        </visual>
        <collision>
            <origin xyz="0 0 2.0785895603303706" rpy="0 0 0"/>
            <geometry>
                <box size="0.296803845878281 0.6127847712001007 0.1571791206607408" />
            </geometry>
        </collision>
    </link>
    <joint name="Link0_Link1" type="revolute">
       <parent link="Link0"/>
       <child  link="Link1"/>
       <origin rpy="0 0 0" xyz="0 0.30639238560005033 2.1571791206607407" />
     <axis xyz="1 0 0"/>
       <limit effort="0.0" lower="-3.14159" upper="3.14159" velocity="0.0"/>
    </joint>
    <link name="Link1">
        <inertial>
            <origin xyz="0 0.30639238560005033 -0.0785895603303704" rpy="0 0 0"/>
            <mass value="1" />
            <inertia ixx="100" ixy="0" ixz="0" iyy="100" iyz="0" izz="100" />
        </inertial>
        <visual>
            <origin xyz="0 0.30639238560005033 -0.0785895603303704" rpy="0 0 0"/>
            <geometry>
                <box size="0.296803845878281 0.6127847712001007 0.1571791206607408" />
            </geometry>
            <material name="Green">
                <color rgba="0 1.0 0.0 1.0"/>
            </material>
        </visual>
        <collision>
            <origin xyz="0 0.30639238560005033 -0.0785895603303704" rpy="0 0 0"/>
            <geometry>
                <box size="0.296803845878281 0.6127847712001007 0.1571791206607408" />
            </geometry>
        </collision>
    </link>
    <joint name="Link1_Link2" type="revolute">
       <parent link="Link1"/>
       <child  link="Link2"/>
       <origin rpy="0 0 0" xyz="-0.1484019229391405 0.30639238560005033 0.0" />
     <axis xyz="0 1 0"/>
       <limit effort="0.0" lower="-3.14159" upper="3.14159" velocity="0.0"/>
    </joint>
    <link name="Link2">
        <inertial>
            <origin xyz="-0.47171558009932607 0 -0.3418692027991087" rpy="0 0 0"/>
            <mass value="1" />
            <inertia ixx="100" ixy="0" ixz="0" iyy="100" iyz="0" izz="100" />
        </inertial>
        <visual>
            <origin xyz="-0.47171558009932607 0 -0.3418692027991087" rpy="0 0 0"/>
            <geometry>
                <box size="0.9434311601986521 0.06116828226141113 0.6837384055982174" />
            </geometry>
            <material name="Green">
                <color rgba="0 1.0 0.0 1.0"/>
            </material>
        </visual>
        <collision>
            <origin xyz="-0.47171558009932607 0 -0.3418692027991087" rpy="0 0 0"/>
            <geometry>
                <box size="0.9434311601986521 0.06116828226141113 0.6837384055982174" />
            </geometry>
        </collision>
    </link>
    <joint name="Link2_Link3" type="revolute">
       <parent link="Link2"/>
       <child  link="Link3"/>
       <origin rpy="0 0 0" xyz="0.0 0 0.0" />
     <axis xyz="0 1 0"/>
       <limit effort="0.0" lower="-3.14159" upper="3.14159" velocity="0.0"/>
    </joint>
    <link name="Link3">
        <inertial>
            <origin xyz="0.28483349118766305 0 -0.31315507809646037" rpy="0 0 0"/>
            <mass value="1" />
            <inertia ixx="100" ixy="0" ixz="0" iyy="100" iyz="0" izz="100" />
        </inertial>
        <visual>
            <origin xyz="0.28483349118766305 0 -0.31315507809646037" rpy="0 0 0"/>
            <geometry>
                <box size="0.5696669823753261 0.5214003808977845 0.6263101561929207" />
            </geometry>
            <material name="Blue">
                <color rgba="0 0.0 1.0 1.0"/>
            </material>
        </visual>
        <collision>
            <origin xyz="0.28483349118766305 0 -0.31315507809646037" rpy="0 0 0"/>
            <geometry>
                <box size="0.5696669823753261 0.5214003808977845 0.6263101561929207" />
            </geometry>
        </collision>
    </link>
    <joint name="Link3_Link4" type="revolute">
       <parent link="Link3"/>
       <child  link="Link4"/>
       <origin rpy="0 0 0" xyz="0.28483349118766305 0.26070019044889226 0.0" />
     <axis xyz="1 0 0"/>
       <limit effort="0.0" lower="-3.14159" upper="3.14159" velocity="0.0"/>
    </joint>
    <link name="Link4">
        <inertial>
            <origin xyz="0 0.309764378976393 0.3049544652230029" rpy="0 0 0"/>
            <mass value="1" />
            <inertia ixx="100" ixy="0" ixz="0" iyy="100" iyz="0" izz="100" />
        </inertial>
        <visual>
            <origin xyz="0 0.309764378976393 0.3049544652230029" rpy="0 0 0"/>
            <geometry>
                <box size="0.06203109260181161 0.619528757952786 0.6099089304460058" />
            </geometry>
            <material name="Green">
                <color rgba="0 1.0 0.0 1.0"/>
            </material>
        </visual>
        <collision>
            <origin xyz="0 0.309764378976393 0.3049544652230029" rpy="0 0 0"/>
            <geometry>
                <box size="0.06203109260181161 0.619528757952786 0.6099089304460058" />
            </geometry>
        </collision>
    </link>
</robot>