<robot name = "robot">
    <link name="Link0">
        <inertial>
            <origin xyz="0 0 2.399690150553943" rpy="0 0 0"/>
            <mass value="1" />
            <inertia ixx="100" ixy="0" ixz="0" iyy="100" iyz="0" izz="100" />
        </inertial>
        <visual>
            <origin xyz="0 0 2.399690150553943" rpy="0 0 0"/>
            <geometry>
                <box size="0.4797288785807122 0.5871037526131985 0.7993803011078866" />
            </geometry>
            <material name="Green">
                <color rgba="0 1.0 0.0 1.0"/>
            </material>
        </visual>
        <collision>
            <origin xyz="0 0 2.399690150553943" rpy="0 0 0"/>
            <geometry>
                <box size="0.4797288785807122 0.5871037526131985 0.7993803011078866" />
            </geometry>
        </collision>
    </link>
    <joint name="Link0_Link1" type="revolute">
       <parent link="Link0"/>
       <child  link="Link1"/>
       <origin rpy="0 0 0" xyz="0 0.29355187630659924 2.7993803011078864" />
     <axis xyz="1 0 0"/>
       <limit effort="0.0" lower="-3.14159" upper="3.14159" velocity="0.0"/>
    </joint>
    <link name="Link1">
        <inertial>
            <origin xyz="0 0.29355187630659924 -0.3996901505539433" rpy="0 0 0"/>
            <mass value="1" />
            <inertia ixx="100" ixy="0" ixz="0" iyy="100" iyz="0" izz="100" />
        </inertial>
        <visual>
            <origin xyz="0 0.29355187630659924 -0.3996901505539433" rpy="0 0 0"/>
            <geometry>
                <box size="0.4797288785807122 0.5871037526131985 0.7993803011078866" />
            </geometry>
            <material name="Green">
                <color rgba="0 1.0 0.0 1.0"/>
            </material>
        </visual>
        <collision>
            <origin xyz="0 0.29355187630659924 -0.3996901505539433" rpy="0 0 0"/>
            <geometry>
                <box size="0.4797288785807122 0.5871037526131985 0.7993803011078866" />
            </geometry>
        </collision>
    </link>
    <joint name="Link1_Link2" type="revolute">
       <parent link="Link1"/>
       <child  link="Link2"/>
       <origin rpy="0 0 0" xyz="0 0.0 0.0" />
     <axis xyz="1 0 0"/>
       <limit effort="0.0" lower="-3.14159" upper="3.14159" velocity="0.0"/>
    </joint>
    <link name="Link2">
        <inertial>
            <origin xyz="0 -0.09712046011108583 -0.13479040244477886" rpy="0 0 0"/>
            <mass value="1" />
            <inertia ixx="100" ixy="0" ixz="0" iyy="100" iyz="0" izz="100" />
        </inertial>
        <visual>
            <origin xyz="0 -0.09712046011108583 -0.13479040244477886" rpy="0 0 0"/>
            <geometry>
                <box size="0.41593637854911536 0.19424092022217165 0.2695808048895577" />
            </geometry>
            <material name="Green">
                <color rgba="0 1.0 0.0 1.0"/>
            </material>
        </visual>
        <collision>
            <origin xyz="0 -0.09712046011108583 -0.13479040244477886" rpy="0 0 0"/>
            <geometry>
                <box size="0.41593637854911536 0.19424092022217165 0.2695808048895577" />
            </geometry>
        </collision>
    </link>
    <joint name="Link2_Link3" type="revolute">
       <parent link="Link2"/>
       <child  link="Link3"/>
       <origin rpy="0 0 0" xyz="0 0.0 0.0" />
     <axis xyz="1 0 0"/>
       <limit effort="0.0" lower="-3.14159" upper="3.14159" velocity="0.0"/>
    </joint>
    <link name="Link3">
        <inertial>
            <origin xyz="0 0.1427847800907111 -0.32207116382658774" rpy="0 0 0"/>
            <mass value="1" />
            <inertia ixx="100" ixy="0" ixz="0" iyy="100" iyz="0" izz="100" />
        </inertial>
        <visual>
            <origin xyz="0 0.1427847800907111 -0.32207116382658774" rpy="0 0 0"/>
            <geometry>
                <box size="0.5322174567910515 0.2855695601814222 0.6441423276531755" />
            </geometry>
            <material name="Green">
                <color rgba="0 1.0 0.0 1.0"/>
            </material>
        </visual>
        <collision>
            <origin xyz="0 0.1427847800907111 -0.32207116382658774" rpy="0 0 0"/>
            <geometry>
                <box size="0.5322174567910515 0.2855695601814222 0.6441423276531755" />
            </geometry>
        </collision>
    </link>
    <joint name="Link3_Link4" type="revolute">
       <parent link="Link3"/>
       <child  link="Link4"/>
       <origin rpy="0 0 0" xyz="-0.26610872839552574 0.1427847800907111 0.0" />
     <axis xyz="0 1 0"/>
       <limit effort="0.0" lower="-3.14159" upper="3.14159" velocity="0.0"/>
    </joint>
    <link name="Link4">
        <inertial>
            <origin xyz="-0.24997537243158546 0 -0.35153167459544304" rpy="0 0 0"/>
            <mass value="1" />
            <inertia ixx="100" ixy="0" ixz="0" iyy="100" iyz="0" izz="100" />
        </inertial>
        <visual>
            <origin xyz="-0.24997537243158546 0 -0.35153167459544304" rpy="0 0 0"/>
            <geometry>
                <box size="0.4999507448631709 0.22403725010028042 0.7030633491908861" />
            </geometry>
            <material name="Green">
                <color rgba="0 1.0 0.0 1.0"/>
            </material>
        </visual>
        <collision>
            <origin xyz="-0.24997537243158546 0 -0.35153167459544304" rpy="0 0 0"/>
            <geometry>
                <box size="0.4999507448631709 0.22403725010028042 0.7030633491908861" />
            </geometry>
        </collision>
    </link>
    <joint name="Link4_Link5" type="revolute">
       <parent link="Link4"/>
       <child  link="Link5"/>
       <origin rpy="0 0 0" xyz="0.0 0 0.0" />
     <axis xyz="0 1 0"/>
       <limit effort="0.0" lower="-3.14159" upper="3.14159" velocity="0.0"/>
    </joint>
    <link name="Link5">
        <inertial>
            <origin xyz="0.27201518178562717 0 0.14991088090530602" rpy="0 0 0"/>
            <mass value="1" />
            <inertia ixx="100" ixy="0" ixz="0" iyy="100" iyz="0" izz="100" />
        </inertial>
        <visual>
            <origin xyz="0.27201518178562717 0 0.14991088090530602" rpy="0 0 0"/>
            <geometry>
                <box size="0.5440303635712543 0.16084992220264693 0.29982176181061204" />
            </geometry>
            <material name="Blue">
                <color rgba="0 0.0 1.0 1.0"/>
            </material>
        </visual>
        <collision>
            <origin xyz="0.27201518178562717 0 0.14991088090530602" rpy="0 0 0"/>
            <geometry>
                <box size="0.5440303635712543 0.16084992220264693 0.29982176181061204" />
            </geometry>
        </collision>
    </link>
    <joint name="Link5_Link6" type="revolute">
       <parent link="Link5"/>
       <child  link="Link6"/>
       <origin rpy="0 0 0" xyz="0.5440303635712543 0 0.29982176181061204" />
     <axis xyz="0 1 0"/>
       <limit effort="0.0" lower="-3.14159" upper="3.14159" velocity="0.0"/>
    </joint>
    <link name="Link6">
        <inertial>
            <origin xyz="0.12574791760802895 0 0.25484892908496043" rpy="0 0 0"/>
            <mass value="1" />
            <inertia ixx="100" ixy="0" ixz="0" iyy="100" iyz="0" izz="100" />
        </inertial>
        <visual>
            <origin xyz="0.12574791760802895 0 0.25484892908496043" rpy="0 0 0"/>
            <geometry>
                <box size="0.2514958352160579 0.49563743713697017 0.5096978581699209" />
            </geometry>
            <material name="Blue">
                <color rgba="0 0.0 1.0 1.0"/>
            </material>
        </visual>
        <collision>
            <origin xyz="0.12574791760802895 0 0.25484892908496043" rpy="0 0 0"/>
            <geometry>
                <box size="0.2514958352160579 0.49563743713697017 0.5096978581699209" />
            </geometry>
        </collision>
    </link>
</robot>