<robot name = "robot">
    <link name="Link0">
        <inertial>
            <origin xyz="0 0 2.480857931672501" rpy="0 0 0"/>
            <mass value="1" />
            <inertia ixx="100" ixy="0" ixz="0" iyy="100" iyz="0" izz="100" />
        </inertial>
        <visual>
            <origin xyz="0 0 2.480857931672501" rpy="0 0 0"/>
            <geometry>
                <box size="0.7864900224912439 0.18005165262893175 0.9617158633450014" />
            </geometry>
            <material name="Green">
                <color rgba="0 1.0 0.0 1.0"/>
            </material>
        </visual>
        <collision>
            <origin xyz="0 0 2.480857931672501" rpy="0 0 0"/>
            <geometry>
                <box size="0.7864900224912439 0.18005165262893175 0.9617158633450014" />
            </geometry>
        </collision>
    </link>
    <joint name="Link0_Link1" type="revolute">
       <parent link="Link0"/>
       <child  link="Link1"/>
       <origin rpy="0 0 0" xyz="0 0.09002582631446587 2.9617158633450016" />
     <axis xyz="1 0 0"/>
       <limit effort="0.0" lower="-3.14159" upper="3.14159" velocity="0.0"/>
    </joint>
    <link name="Link1">
        <inertial>
            <origin xyz="0 0.09002582631446587 -0.4808579316725007" rpy="0 0 0"/>
            <mass value="1" />
            <inertia ixx="100" ixy="0" ixz="0" iyy="100" iyz="0" izz="100" />
        </inertial>
        <visual>
            <origin xyz="0 0.09002582631446587 -0.4808579316725007" rpy="0 0 0"/>
            <geometry>
                <box size="0.7864900224912439 0.18005165262893175 0.9617158633450014" />
            </geometry>
            <material name="Blue">
                <color rgba="0 0.0 1.0 1.0"/>
            </material>
        </visual>
        <collision>
            <origin xyz="0 0.09002582631446587 -0.4808579316725007" rpy="0 0 0"/>
            <geometry>
                <box size="0.7864900224912439 0.18005165262893175 0.9617158633450014" />
            </geometry>
        </collision>
    </link>
    <joint name="Link1_Link2" type="revolute">
       <parent link="Link1"/>
       <child  link="Link2"/>
       <origin rpy="0 0 0" xyz="-0.39324501124562194 0.09002582631446587 0.0" />
     <axis xyz="0 1 0"/>
       <limit effort="0.0" lower="-3.14159" upper="3.14159" velocity="0.0"/>
    </joint>
    <link name="Link2">
        <inertial>
            <origin xyz="-0.24890756317462814 0 -0.03911372360662785" rpy="0 0 0"/>
            <mass value="1" />
            <inertia ixx="100" ixy="0" ixz="0" iyy="100" iyz="0" izz="100" />
        </inertial>
        <visual>
            <origin xyz="-0.24890756317462814 0 -0.03911372360662785" rpy="0 0 0"/>
            <geometry>
                <box size="0.4978151263492563 0.41339582276368925 0.0782274472132557" />
            </geometry>
            <material name="Blue">
                <color rgba="0 0.0 1.0 1.0"/>
            </material>
        </visual>
        <collision>
            <origin xyz="-0.24890756317462814 0 -0.03911372360662785" rpy="0 0 0"/>
            <geometry>
                <box size="0.4978151263492563 0.41339582276368925 0.0782274472132557" />
            </geometry>
        </collision>
    </link>
    <joint name="Link2_Link3" type="revolute">
       <parent link="Link2"/>
       <child  link="Link3"/>
       <origin rpy="0 0 0" xyz="0.0 0 0.0" />
     <axis xyz="0 1 0"/>
       <limit effort="0.0" lower="-3.14159" upper="3.14159" velocity="0.0"/>
    </joint>
    <link name="Link3">
        <inertial>
            <origin xyz="0.29798139809574675 0 -0.48110651789413883" rpy="0 0 0"/>
            <mass value="1" />
            <inertia ixx="100" ixy="0" ixz="0" iyy="100" iyz="0" izz="100" />
        </inertial>
        <visual>
            <origin xyz="0.29798139809574675 0 -0.48110651789413883" rpy="0 0 0"/>
            <geometry>
                <box size="0.5959627961914935 0.908776131156045 0.9622130357882777" />
            </geometry>
            <material name="Blue">
                <color rgba="0 0.0 1.0 1.0"/>
            </material>
        </visual>
        <collision>
            <origin xyz="0.29798139809574675 0 -0.48110651789413883" rpy="0 0 0"/>
            <geometry>
                <box size="0.5959627961914935 0.908776131156045 0.9622130357882777" />
            </geometry>
        </collision>
    </link>
    <joint name="Link3_Link4" type="revolute">
       <parent link="Link3"/>
       <child  link="Link4"/>
       <origin rpy="0 0 0" xyz="0.29798139809574675 0.4543880655780225 0.0" />
     <axis xyz="1 0 0"/>
       <limit effort="0.0" lower="-3.14159" upper="3.14159" velocity="0.0"/>
    </joint>
    <link name="Link4">
        <inertial>
            <origin xyz="0 0.08135919626997384 0.470935114018843" rpy="0 0 0"/>
            <mass value="1" />
            <inertia ixx="100" ixy="0" ixz="0" iyy="100" iyz="0" izz="100" />
        </inertial>
        <visual>
            <origin xyz="0 0.08135919626997384 0.470935114018843" rpy="0 0 0"/>
            <geometry>
                <box size="0.6683600199257925 0.1627183925399477 0.941870228037686" />
            </geometry>
            <material name="Green">
                <color rgba="0 1.0 0.0 1.0"/>
            </material>
        </visual>
        <collision>
            <origin xyz="0 0.08135919626997384 0.470935114018843" rpy="0 0 0"/>
            <geometry>
                <box size="0.6683600199257925 0.1627183925399477 0.941870228037686" />
            </geometry>
        </collision>
    </link>
    <joint name="Link4_Link5" type="revolute">
       <parent link="Link4"/>
       <child  link="Link5"/>
       <origin rpy="0 0 0" xyz="0.33418000996289626 0.08135919626997384 0.941870228037686" />
     <axis xyz="0 1 0"/>
       <limit effort="0.0" lower="-3.14159" upper="3.14159" velocity="0.0"/>
    </joint>
    <link name="Link5">
        <inertial>
            <origin xyz="0.2067994676617846 0 0.2627367749849302" rpy="0 0 0"/>
            <mass value="1" />
            <inertia ixx="100" ixy="0" ixz="0" iyy="100" iyz="0" izz="100" />
        </inertial>
        <visual>
            <origin xyz="0.2067994676617846 0 0.2627367749849302" rpy="0 0 0"/>
            <geometry>
                <box size="0.4135989353235692 0.2889909388916627 0.5254735499698604" />
            </geometry>
            <material name="Blue">
                <color rgba="0 0.0 1.0 1.0"/>
            </material>
        </visual>
        <collision>
            <origin xyz="0.2067994676617846 0 0.2627367749849302" rpy="0 0 0"/>
            <geometry>
                <box size="0.4135989353235692 0.2889909388916627 0.5254735499698604" />
            </geometry>
        </collision>
    </link>
    <joint name="Link5_Link6" type="revolute">
       <parent link="Link5"/>
       <child  link="Link6"/>
       <origin rpy="0 0 0" xyz="0.4135989353235692 0 0.5254735499698604" />
     <axis xyz="0 1 0"/>
       <limit effort="0.0" lower="-3.14159" upper="3.14159" velocity="0.0"/>
    </joint>
    <link name="Link6">
        <inertial>
            <origin xyz="0.35027595806405304 0 -0.013927915169218152" rpy="0 0 0"/>
            <mass value="1" />
            <inertia ixx="100" ixy="0" ixz="0" iyy="100" iyz="0" izz="100" />
        </inertial>
        <visual>
            <origin xyz="0.35027595806405304 0 -0.013927915169218152" rpy="0 0 0"/>
            <geometry>
                <box size="0.7005519161281061 0.2041994240681646 0.027855830338436305" />
            </geometry>
            <material name="Blue">
                <color rgba="0 0.0 1.0 1.0"/>
            </material>
        </visual>
        <collision>
            <origin xyz="0.35027595806405304 0 -0.013927915169218152" rpy="0 0 0"/>
            <geometry>
                <box size="0.7005519161281061 0.2041994240681646 0.027855830338436305" />
            </geometry>
        </collision>
    </link>
</robot>