<robot name = "robot">
    <link name="Link0">
        <inertial>
            <origin xyz="0 0 2.45326035140302" rpy="0 0 0"/>
            <mass value="1" />
            <inertia ixx="100" ixy="0" ixz="0" iyy="100" iyz="0" izz="100" />
        </inertial>
        <visual>
            <origin xyz="0 0 2.45326035140302" rpy="0 0 0"/>
            <geometry>
                <box size="0.9319618926154578 0.8063683253988796 0.9065207028060391" />
            </geometry>
            <material name="Green">
                <color rgba="0 1.0 0.0 1.0"/>
            </material>
        </visual>
        <collision>
            <origin xyz="0 0 2.45326035140302" rpy="0 0 0"/>
            <geometry>
                <box size="0.9319618926154578 0.8063683253988796 0.9065207028060391" />
            </geometry>
        </collision>
    </link>
    <joint name="Link0_Link1" type="revolute">
       <parent link="Link0"/>
       <child  link="Link1"/>
       <origin rpy="0 0 0" xyz="0 0.4031841626994398 2.906520702806039" />
     <axis xyz="1 0 0"/>
       <limit effort="0.0" lower="-3.14159" upper="3.14159" velocity="0.0"/>
    </joint>
    <link name="Link1">
        <inertial>
            <origin xyz="0 0.4031841626994398 -0.45326035140301957" rpy="0 0 0"/>
            <mass value="1" />
            <inertia ixx="100" ixy="0" ixz="0" iyy="100" iyz="0" izz="100" />
        </inertial>
        <visual>
            <origin xyz="0 0.4031841626994398 -0.45326035140301957" rpy="0 0 0"/>
            <geometry>
                <box size="0.9319618926154578 0.8063683253988796 0.9065207028060391" />
            </geometry>
            <material name="Green">
                <color rgba="0 1.0 0.0 1.0"/>
            </material>
        </visual>
        <collision>
            <origin xyz="0 0.4031841626994398 -0.45326035140301957" rpy="0 0 0"/>
            <geometry>
                <box size="0.9319618926154578 0.8063683253988796 0.9065207028060391" />
            </geometry>
        </collision>
    </link>
    <joint name="Link1_Link2" type="revolute">
       <parent link="Link1"/>
       <child  link="Link2"/>
       <origin rpy="0 0 0" xyz="0 0.8063683253988796 0.0" />
     <axis xyz="1 0 0"/>
       <limit effort="0.0" lower="-3.14159" upper="3.14159" velocity="0.0"/>
    </joint>
    <link name="Link2">
        <inertial>
            <origin xyz="0 0.44126089094900584 0.31806753718466557" rpy="0 0 0"/>
            <mass value="1" />
            <inertia ixx="100" ixy="0" ixz="0" iyy="100" iyz="0" izz="100" />
        </inertial>
        <visual>
            <origin xyz="0 0.44126089094900584 0.31806753718466557" rpy="0 0 0"/>
            <geometry>
                <box size="0.7942232600090174 0.8825217818980117 0.6361350743693311" />
            </geometry>
            <material name="Blue">
                <color rgba="0 0.0 1.0 1.0"/>
            </material>
        </visual>
        <collision>
            <origin xyz="0 0.44126089094900584 0.31806753718466557" rpy="0 0 0"/>
            <geometry>
                <box size="0.7942232600090174 0.8825217818980117 0.6361350743693311" />
            </geometry>
        </collision>
    </link>
    <joint name="Link2_Link3" type="revolute">
       <parent link="Link2"/>
       <child  link="Link3"/>
       <origin rpy="0 0 0" xyz="0 0.8825217818980117 0.6361350743693311" />
     <axis xyz="1 0 0"/>
       <limit effort="0.0" lower="-3.14159" upper="3.14159" velocity="0.0"/>
    </joint>
    <link name="Link3">
        <inertial>
            <origin xyz="0 0.15976640041663542 0.2703886729412943" rpy="0 0 0"/>
            <mass value="1" />
            <inertia ixx="100" ixy="0" ixz="0" iyy="100" iyz="0" izz="100" />
        </inertial>
        <visual>
            <origin xyz="0 0.15976640041663542 0.2703886729412943" rpy="0 0 0"/>
            <geometry>
                <box size="0.14530146915484643 0.31953280083327085 0.5407773458825886" />
            </geometry>
            <material name="Blue">
                <color rgba="0 0.0 1.0 1.0"/>
            </material>
        </visual>
        <collision>
            <origin xyz="0 0.15976640041663542 0.2703886729412943" rpy="0 0 0"/>
            <geometry>
                <box size="0.14530146915484643 0.31953280083327085 0.5407773458825886" />
            </geometry>
        </collision>
    </link>
    <joint name="Link3_Link4" type="revolute">
       <parent link="Link3"/>
       <child  link="Link4"/>
       <origin rpy="0 0 0" xyz="-0.07265073457742321 0.15976640041663542 0.5407773458825886" />
     <axis xyz="0 1 0"/>
       <limit effort="0.0" lower="-3.14159" upper="3.14159" velocity="0.0"/>
    </joint>
    <link name="Link4">
        <inertial>
            <origin xyz="-0.3272202455051394 0 -0.03678569190572184" rpy="0 0 0"/>
            <mass value="1" />
            <inertia ixx="100" ixy="0" ixz="0" iyy="100" iyz="0" izz="100" />
        </inertial>
        <visual>
            <origin xyz="-0.3272202455051394 0 -0.03678569190572184" rpy="0 0 0"/>
            <geometry>
                <box size="0.6544404910102788 0.2687720577711259 0.07357138381144368" />
            </geometry>
            <material name="Blue">
                <color rgba="0 0.0 1.0 1.0"/>
            </material>
        </visual>
        <collision>
            <origin xyz="-0.3272202455051394 0 -0.03678569190572184" rpy="0 0 0"/>
            <geometry>
                <box size="0.6544404910102788 0.2687720577711259 0.07357138381144368" />
            </geometry>
        </collision>
    </link>
    <joint name="Link4_Link5" type="revolute">
       <parent link="Link4"/>
       <child  link="Link5"/>
       <origin rpy="0 0 0" xyz="-0.3272202455051394 0.13438602888556295 0.0" />
     <axis xyz="1 0 0"/>
       <limit effort="0.0" lower="-3.14159" upper="3.14159" velocity="0.0"/>
    </joint>
    <link name="Link5">
        <inertial>
            <origin xyz="0 0.18442363444853033 0.03412642818931677" rpy="0 0 0"/>
            <mass value="1" />
            <inertia ixx="100" ixy="0" ixz="0" iyy="100" iyz="0" izz="100" />
        </inertial>
        <visual>
            <origin xyz="0 0.18442363444853033 0.03412642818931677" rpy="0 0 0"/>
            <geometry>
                <box size="0.5781547642824048 0.36884726889706065 0.06825285637863354" />
            </geometry>
            <material name="Blue">
                <color rgba="0 0.0 1.0 1.0"/>
            </material>
        </visual>
        <collision>
            <origin xyz="0 0.18442363444853033 0.03412642818931677" rpy="0 0 0"/>
            <geometry>
                <box size="0.5781547642824048 0.36884726889706065 0.06825285637863354" />
            </geometry>
        </collision>
    </link>
</robot>