<robot name = "robot">
    <link name="Link0">
        <inertial>
            <origin xyz="0 0 2.330774438464013" rpy="0 0 0"/>
            <mass value="1" />
            <inertia ixx="100" ixy="0" ixz="0" iyy="100" iyz="0" izz="100" />
        </inertial>
        <visual>
            <origin xyz="0 0 2.330774438464013" rpy="0 0 0"/>
            <geometry>
                <box size="0.023128231627607687 0.5820872783225317 0.6615488769280258" />
            </geometry>
            <material name="Green">
                <color rgba="0 1.0 0.0 1.0"/>
            </material>
        </visual>
        <collision>
            <origin xyz="0 0 2.330774438464013" rpy="0 0 0"/>
            <geometry>
                <box size="0.023128231627607687 0.5820872783225317 0.6615488769280258" />
            </geometry>
        </collision>
    </link>
    <joint name="Link0_Link1" type="revolute">
       <parent link="Link0"/>
       <child  link="Link1"/>
       <origin rpy="0 0 0" xyz="0 0.29104363916126585 2.661548876928026" />
     <axis xyz="1 0 0"/>
       <limit effort="0.0" lower="-3.14159" upper="3.14159" velocity="0.0"/>
    </joint>
    <link name="Link1">
        <inertial>
            <origin xyz="0 0.29104363916126585 -0.3307744384640129" rpy="0 0 0"/>
            <mass value="1" />
            <inertia ixx="100" ixy="0" ixz="0" iyy="100" iyz="0" izz="100" />
        </inertial>
        <visual>
            <origin xyz="0 0.29104363916126585 -0.3307744384640129" rpy="0 0 0"/>
            <geometry>
                <box size="0.023128231627607687 0.5820872783225317 0.6615488769280258" />
            </geometry>
            <material name="Green">
                <color rgba="0 1.0 0.0 1.0"/>
            </material>
        </visual>
        <collision>
            <origin xyz="0 0.29104363916126585 -0.3307744384640129" rpy="0 0 0"/>
            <geometry>
                <box size="0.023128231627607687 0.5820872783225317 0.6615488769280258" />
            </geometry>
        </collision>
    </link>
    <joint name="Link1_Link2" type="revolute">
       <parent link="Link1"/>
       <child  link="Link2"/>
       <origin rpy="0 0 0" xyz="-0.011564115813803844 0.29104363916126585 0.0" />
     <axis xyz="0 1 0"/>
       <limit effort="0.0" lower="-3.14159" upper="3.14159" velocity="0.0"/>
    </joint>
    <link name="Link2">
        <inertial>
            <origin xyz="-0.21939851857686432 0 0.08093223884756101" rpy="0 0 0"/>
            <mass value="1" />
            <inertia ixx="100" ixy="0" ixz="0" iyy="100" iyz="0" izz="100" />
        </inertial>
        <visual>
            <origin xyz="-0.21939851857686432 0 0.08093223884756101" rpy="0 0 0"/>
            <geometry>
                <box size="0.43879703715372864 0.7283913491984787 0.16186447769512202" />
            </geometry>
            <material name="Blue">
                <color rgba="0 0.0 1.0 1.0"/>
            </material>
        </visual>
        <collision>
            <origin xyz="-0.21939851857686432 0 0.08093223884756101" rpy="0 0 0"/>
            <geometry>
                <box size="0.43879703715372864 0.7283913491984787 0.16186447769512202" />
            </geometry>
        </collision>
    </link>
    <joint name="Link2_Link3" type="revolute">
       <parent link="Link2"/>
       <child  link="Link3"/>
       <origin rpy="0 0 0" xyz="-0.21939851857686432 0.36419567459923935 0.16186447769512202" />
     <axis xyz="1 0 0"/>
       <limit effort="0.0" lower="-3.14159" upper="3.14159" velocity="0.0"/>
    </joint>
    <link name="Link3">
        <inertial>
            <origin xyz="0 0.05647541305288406 -0.35736256319598175" rpy="0 0 0"/>
            <mass value="1" />
            <inertia ixx="100" ixy="0" ixz="0" iyy="100" iyz="0" izz="100" />
        </inertial>
        <visual>
            <origin xyz="0 0.05647541305288406 -0.35736256319598175" rpy="0 0 0"/>
            <geometry>
                <box size="0.6941467278376899 0.11295082610576812 0.7147251263919635" />
            </geometry>
            <material name="Blue">
                <color rgba="0 0.0 1.0 1.0"/>
            </material>
        </visual>
        <collision>
            <origin xyz="0 0.05647541305288406 -0.35736256319598175" rpy="0 0 0"/>
            <geometry>
                <box size="0.6941467278376899 0.11295082610576812 0.7147251263919635" />
            </geometry>
        </collision>
    </link>
    <joint name="Link3_Link4" type="revolute">
       <parent link="Link3"/>
       <child  link="Link4"/>
       <origin rpy="0 0 0" xyz="-0.34707336391884497 0.05647541305288406 0.0" />
     <axis xyz="0 1 0"/>
       <limit effort="0.0" lower="-3.14159" upper="3.14159" velocity="0.0"/>
    </joint>
    <link name="Link4">
        <inertial>
            <origin xyz="-0.45078677793752653 0 0.4657287987202226" rpy="0 0 0"/>
            <mass value="1" />
            <inertia ixx="100" ixy="0" ixz="0" iyy="100" iyz="0" izz="100" />
        </inertial>
        <visual>
            <origin xyz="-0.45078677793752653 0 0.4657287987202226" rpy="0 0 0"/>
            <geometry>
                <box size="0.9015735558750531 0.2917707116929886 0.9314575974404452" />
            </geometry>
            <material name="Blue">
                <color rgba="0 0.0 1.0 1.0"/>
            </material>
        </visual>
        <collision>
            <origin xyz="-0.45078677793752653 0 0.4657287987202226" rpy="0 0 0"/>
            <geometry>
                <box size="0.9015735558750531 0.2917707116929886 0.9314575974404452" />
            </geometry>
        </collision>
    </link>
</robot>