<robot name = "robot">
    <link name="Link0">
        <inertial>
            <origin xyz="0 0 2.0814123805252955" rpy="0 0 0"/>
            <mass value="1" />
            <inertia ixx="100" ixy="0" ixz="0" iyy="100" iyz="0" izz="100" />
        </inertial>
        <visual>
            <origin xyz="0 0 2.0814123805252955" rpy="0 0 0"/>
            <geometry>
                <box size="0.6567596519840913 0.39637047081169496 0.1628247610505913" />
            </geometry>
            <material name="Green">
                <color rgba="0 1.0 0.0 1.0"/>
            </material>
        </visual>
        <collision>
            <origin xyz="0 0 2.0814123805252955" rpy="0 0 0"/>
            <geometry>
                <box size="0.6567596519840913 0.39637047081169496 0.1628247610505913" />
            </geometry>
        </collision>
    </link>
    <joint name="Link0_Link1" type="revolute">
       <parent link="Link0"/>
       <child  link="Link1"/>
       <origin rpy="0 0 0" xyz="0 0.19818523540584748 2.162824761050591" />
     <axis xyz="1 0 0"/>
       <limit effort="0.0" lower="-3.14159" upper="3.14159" velocity="0.0"/>
    </joint>
    <link name="Link1">
        <inertial>
            <origin xyz="0 0.19818523540584748 -0.08141238052529565" rpy="0 0 0"/>
            <mass value="1" />
            <inertia ixx="100" ixy="0" ixz="0" iyy="100" iyz="0" izz="100" />
        </inertial>
        <visual>
            <origin xyz="0 0.19818523540584748 -0.08141238052529565" rpy="0 0 0"/>
            <geometry>
                <box size="0.6567596519840913 0.39637047081169496 0.1628247610505913" />
            </geometry>
            <material name="Blue">
                <color rgba="0 0.0 1.0 1.0"/>
            </material>
        </visual>
        <collision>
            <origin xyz="0 0.19818523540584748 -0.08141238052529565" rpy="0 0 0"/>
            <geometry>
                <box size="0.6567596519840913 0.39637047081169496 0.1628247610505913" />
            </geometry>
        </collision>
    </link>
    <joint name="Link1_Link2" type="revolute">
       <parent link="Link1"/>
       <child  link="Link2"/>
       <origin rpy="0 0 0" xyz="-0.3283798259920456 0.19818523540584748 0.0" />
     <axis xyz="0 1 0"/>
       <limit effort="0.0" lower="-3.14159" upper="3.14159" velocity="0.0"/>
    </joint>
    <link name="Link2">
        <inertial>
            <origin xyz="-0.2167750215367245 0 0.12946332380220754" rpy="0 0 0"/>
            <mass value="1" />
            <inertia ixx="100" ixy="0" ixz="0" iyy="100" iyz="0" izz="100" />
        </inertial>
        <visual>
            <origin xyz="-0.2167750215367245 0 0.12946332380220754" rpy="0 0 0"/>
            <geometry>
                <box size="0.433550043073449 0.5099483275450077 0.2589266476044151" />
            </geometry>
            <material name="Blue">
                <color rgba="0 0.0 1.0 1.0"/>
            </material>
        </visual>
        <collision>
            <origin xyz="-0.2167750215367245 0 0.12946332380220754" rpy="0 0 0"/>
            <geometry>
                <box size="0.433550043073449 0.5099483275450077 0.2589266476044151" />
            </geometry>
        </collision>
    </link>
    <joint name="Link2_Link3" type="revolute">
       <parent link="Link2"/>
       <child  link="Link3"/>
       <origin rpy="0 0 0" xyz="-0.433550043073449 0 0.2589266476044151" />
     <axis xyz="0 1 0"/>
       <limit effort="0.0" lower="-3.14159" upper="3.14159" velocity="0.0"/>
    </joint>
    <link name="Link3">
        <inertial>
            <origin xyz="-0.22020951516054976 0 0.2040062642393135" rpy="0 0 0"/>
            <mass value="1" />
            <inertia ixx="100" ixy="0" ixz="0" iyy="100" iyz="0" izz="100" />
        </inertial>
        <visual>
            <origin xyz="-0.22020951516054976 0 0.2040062642393135" rpy="0 0 0"/>
            <geometry>
                <box size="0.4404190303210995 0.9843703487178287 0.408012528478627" />
            </geometry>
            <material name="Blue">
                <color rgba="0 0.0 1.0 1.0"/>
            </material>
        </visual>
        <collision>
            <origin xyz="-0.22020951516054976 0 0.2040062642393135" rpy="0 0 0"/>
            <geometry>
                <box size="0.4404190303210995 0.9843703487178287 0.408012528478627" />
            </geometry>
        </collision>
    </link>
    <joint name="Link3_Link4" type="revolute">
       <parent link="Link3"/>
       <child  link="Link4"/>
       <origin rpy="0 0 0" xyz="-0.22020951516054976 0.49218517435891435 0.408012528478627" />
     <axis xyz="1 0 0"/>
       <limit effort="0.0" lower="-3.14159" upper="3.14159" velocity="0.0"/>
    </joint>
    <link name="Link4">
        <inertial>
            <origin xyz="0 0.35506987807987117 0.02002536940936772" rpy="0 0 0"/>
            <mass value="1" />
            <inertia ixx="100" ixy="0" ixz="0" iyy="100" iyz="0" izz="100" />
        </inertial>
        <visual>
            <origin xyz="0 0.35506987807987117 0.02002536940936772" rpy="0 0 0"/>
            <geometry>
                <box size="0.7017142403699933 0.7101397561597423 0.04005073881873544" />
            </geometry>
            <material name="Blue">
                <color rgba="0 0.0 1.0 1.0"/>
            </material>
        </visual>
        <collision>
            <origin xyz="0 0.35506987807987117 0.02002536940936772" rpy="0 0 0"/>
            <geometry>
                <box size="0.7017142403699933 0.7101397561597423 0.04005073881873544" />
            </geometry>
        </collision>
    </link>
</robot>