<robot name = "robot">
    <link name="Link0">
        <inertial>
            <origin xyz="0 0 2.4612303012234222" rpy="0 0 0"/>
            <mass value="1" />
            <inertia ixx="100" ixy="0" ixz="0" iyy="100" iyz="0" izz="100" />
        </inertial>
        <visual>
            <origin xyz="0 0 2.4612303012234222" rpy="0 0 0"/>
            <geometry>
                <box size="0.5131245236668288 0.053991602727100574 0.9224606024468447" />
            </geometry>
            <material name="Green">
                <color rgba="0 1.0 0.0 1.0"/>
            </material>
        </visual>
        <collision>
            <origin xyz="0 0 2.4612303012234222" rpy="0 0 0"/>
            <geometry>
                <box size="0.5131245236668288 0.053991602727100574 0.9224606024468447" />
            </geometry>
        </collision>
    </link>
    <joint name="Link0_Link1" type="revolute">
       <parent link="Link0"/>
       <child  link="Link1"/>
       <origin rpy="0 0 0" xyz="0 0.026995801363550287 2.9224606024468445" />
     <axis xyz="1 0 0"/>
       <limit effort="0.0" lower="-3.14159" upper="3.14159" velocity="0.0"/>
    </joint>
    <link name="Link1">
        <inertial>
            <origin xyz="0 0.026995801363550287 -0.46123030122342235" rpy="0 0 0"/>
            <mass value="1" />
            <inertia ixx="100" ixy="0" ixz="0" iyy="100" iyz="0" izz="100" />
        </inertial>
        <visual>
            <origin xyz="0 0.026995801363550287 -0.46123030122342235" rpy="0 0 0"/>
            <geometry>
                <box size="0.5131245236668288 0.053991602727100574 0.9224606024468447" />
            </geometry>
            <material name="Green">
                <color rgba="0 1.0 0.0 1.0"/>
            </material>
        </visual>
        <collision>
            <origin xyz="0 0.026995801363550287 -0.46123030122342235" rpy="0 0 0"/>
            <geometry>
                <box size="0.5131245236668288 0.053991602727100574 0.9224606024468447" />
            </geometry>
        </collision>
    </link>
    <joint name="Link1_Link2" type="revolute">
       <parent link="Link1"/>
       <child  link="Link2"/>
       <origin rpy="0 0 0" xyz="-0.2565622618334144 0.026995801363550287 0.0" />
     <axis xyz="0 1 0"/>
       <limit effort="0.0" lower="-3.14159" upper="3.14159" velocity="0.0"/>
    </joint>
    <link name="Link2">
        <inertial>
            <origin xyz="-0.0888172660633636 0 0.10467011101349627" rpy="0 0 0"/>
            <mass value="1" />
            <inertia ixx="100" ixy="0" ixz="0" iyy="100" iyz="0" izz="100" />
        </inertial>
        <visual>
            <origin xyz="-0.0888172660633636 0 0.10467011101349627" rpy="0 0 0"/>
            <geometry>
                <box size="0.1776345321267272 0.6690736976508186 0.20934022202699254" />
            </geometry>
            <material name="Blue">
                <color rgba="0 0.0 1.0 1.0"/>
            </material>
        </visual>
        <collision>
            <origin xyz="-0.0888172660633636 0 0.10467011101349627" rpy="0 0 0"/>
            <geometry>
                <box size="0.1776345321267272 0.6690736976508186 0.20934022202699254" />
            </geometry>
        </collision>
    </link>
    <joint name="Link2_Link3" type="revolute">
       <parent link="Link2"/>
       <child  link="Link3"/>
       <origin rpy="0 0 0" xyz="-0.1776345321267272 0 0.20934022202699254" />
     <axis xyz="0 1 0"/>
       <limit effort="0.0" lower="-3.14159" upper="3.14159" velocity="0.0"/>
    </joint>
    <link name="Link3">
        <inertial>
            <origin xyz="-0.4799556815184154 0 -0.43994576257450174" rpy="0 0 0"/>
            <mass value="1" />
            <inertia ixx="100" ixy="0" ixz="0" iyy="100" iyz="0" izz="100" />
        </inertial>
        <visual>
            <origin xyz="-0.4799556815184154 0 -0.43994576257450174" rpy="0 0 0"/>
            <geometry>
                <box size="0.9599113630368308 0.0007352333242112152 0.8798915251490035" />
            </geometry>
            <material name="Blue">
                <color rgba="0 0.0 1.0 1.0"/>
            </material>
        </visual>
        <collision>
            <origin xyz="-0.4799556815184154 0 -0.43994576257450174" rpy="0 0 0"/>
            <geometry>
                <box size="0.9599113630368308 0.0007352333242112152 0.8798915251490035" />
            </geometry>
        </collision>
    </link>
    <joint name="Link3_Link4" type="revolute">
       <parent link="Link3"/>
       <child  link="Link4"/>
       <origin rpy="0 0 0" xyz="-0.9599113630368308 0 0.0" />
     <axis xyz="0 1 0"/>
       <limit effort="0.0" lower="-3.14159" upper="3.14159" velocity="0.0"/>
    </joint>
    <link name="Link4">
        <inertial>
            <origin xyz="-0.1618127905794225 0 -0.24948950214287346" rpy="0 0 0"/>
            <mass value="1" />
            <inertia ixx="100" ixy="0" ixz="0" iyy="100" iyz="0" izz="100" />
        </inertial>
        <visual>
            <origin xyz="-0.1618127905794225 0 -0.24948950214287346" rpy="0 0 0"/>
            <geometry>
                <box size="0.323625581158845 0.9464763856593845 0.49897900428574693" />
            </geometry>
            <material name="Blue">
                <color rgba="0 0.0 1.0 1.0"/>
            </material>
        </visual>
        <collision>
            <origin xyz="-0.1618127905794225 0 -0.24948950214287346" rpy="0 0 0"/>
            <geometry>
                <box size="0.323625581158845 0.9464763856593845 0.49897900428574693" />
            </geometry>
        </collision>
    </link>
</robot>