<robot name = "robot">
    <link name="Link0">
        <inertial>
            <origin xyz="0 0 2.1845819684309165" rpy="0 0 0"/>
            <mass value="1" />
            <inertia ixx="100" ixy="0" ixz="0" iyy="100" iyz="0" izz="100" />
        </inertial>
        <visual>
            <origin xyz="0 0 2.1845819684309165" rpy="0 0 0"/>
            <geometry>
                <box size="0.896753288235335 0.9487313171974022 0.3691639368618327" />
            </geometry>
            <material name="Green">
                <color rgba="0 1.0 0.0 1.0"/>
            </material>
        </visual>
        <collision>
            <origin xyz="0 0 2.1845819684309165" rpy="0 0 0"/>
            <geometry>
                <box size="0.896753288235335 0.9487313171974022 0.3691639368618327" />
            </geometry>
        </collision>
    </link>
    <joint name="Link0_Link1" type="revolute">
       <parent link="Link0"/>
       <child  link="Link1"/>
       <origin rpy="0 0 0" xyz="0 0.4743656585987011 2.369163936861833" />
     <axis xyz="1 0 0"/>
       <limit effort="0.0" lower="-3.14159" upper="3.14159" velocity="0.0"/>
    </joint>
    <link name="Link1">
        <inertial>
            <origin xyz="0 0.4743656585987011 -0.18458196843091634" rpy="0 0 0"/>
            <mass value="1" />
            <inertia ixx="100" ixy="0" ixz="0" iyy="100" iyz="0" izz="100" />
        </inertial>
        <visual>
            <origin xyz="0 0.4743656585987011 -0.18458196843091634" rpy="0 0 0"/>
            <geometry>
                <box size="0.896753288235335 0.9487313171974022 0.3691639368618327" />
            </geometry>
            <material name="Green">
                <color rgba="0 1.0 0.0 1.0"/>
            </material>
        </visual>
        <collision>
            <origin xyz="0 0.4743656585987011 -0.18458196843091634" rpy="0 0 0"/>
            <geometry>
                <box size="0.896753288235335 0.9487313171974022 0.3691639368618327" />
            </geometry>
        </collision>
    </link>
    <joint name="Link1_Link2" type="revolute">
       <parent link="Link1"/>
       <child  link="Link2"/>
       <origin rpy="0 0 0" xyz="0 0.0 0.0" />
     <axis xyz="1 0 0"/>
       <limit effort="0.0" lower="-3.14159" upper="3.14159" velocity="0.0"/>
    </joint>
    <link name="Link2">
        <inertial>
            <origin xyz="0 -0.3139655903853264 0.3540727818300673" rpy="0 0 0"/>
            <mass value="1" />
            <inertia ixx="100" ixy="0" ixz="0" iyy="100" iyz="0" izz="100" />
        </inertial>
        <visual>
            <origin xyz="0 -0.3139655903853264 0.3540727818300673" rpy="0 0 0"/>
            <geometry>
                <box size="0.5623323219991571 0.6279311807706528 0.7081455636601346" />
            </geometry>
            <material name="Green">
                <color rgba="0 1.0 0.0 1.0"/>
            </material>
        </visual>
        <collision>
            <origin xyz="0 -0.3139655903853264 0.3540727818300673" rpy="0 0 0"/>
            <geometry>
                <box size="0.5623323219991571 0.6279311807706528 0.7081455636601346" />
            </geometry>
        </collision>
    </link>
    <joint name="Link2_Link3" type="revolute">
       <parent link="Link2"/>
       <child  link="Link3"/>
       <origin rpy="0 0 0" xyz="0 0.0 0.7081455636601346" />
     <axis xyz="1 0 0"/>
       <limit effort="0.0" lower="-3.14159" upper="3.14159" velocity="0.0"/>
    </joint>
    <link name="Link3">
        <inertial>
            <origin xyz="0 0.26069793134266417 0.30822879739031916" rpy="0 0 0"/>
            <mass value="1" />
            <inertia ixx="100" ixy="0" ixz="0" iyy="100" iyz="0" izz="100" />
        </inertial>
        <visual>
            <origin xyz="0 0.26069793134266417 0.30822879739031916" rpy="0 0 0"/>
            <geometry>
                <box size="0.2620926499505085 0.5213958626853283 0.6164575947806383" />
            </geometry>
            <material name="Blue">
                <color rgba="0 0.0 1.0 1.0"/>
            </material>
        </visual>
        <collision>
            <origin xyz="0 0.26069793134266417 0.30822879739031916" rpy="0 0 0"/>
            <geometry>
                <box size="0.2620926499505085 0.5213958626853283 0.6164575947806383" />
            </geometry>
        </collision>
    </link>
    <joint name="Link3_Link4" type="revolute">
       <parent link="Link3"/>
       <child  link="Link4"/>
       <origin rpy="0 0 0" xyz="0 0.5213958626853283 0.6164575947806383" />
     <axis xyz="1 0 0"/>
       <limit effort="0.0" lower="-3.14159" upper="3.14159" velocity="0.0"/>
    </joint>
    <link name="Link4">
        <inertial>
            <origin xyz="0 0.4447668515070398 -0.4020425872776315" rpy="0 0 0"/>
            <mass value="1" />
            <inertia ixx="100" ixy="0" ixz="0" iyy="100" iyz="0" izz="100" />
        </inertial>
        <visual>
            <origin xyz="0 0.4447668515070398 -0.4020425872776315" rpy="0 0 0"/>
            <geometry>
                <box size="0.8431206964494439 0.8895337030140796 0.804085174555263" />
            </geometry>
            <material name="Green">
                <color rgba="0 1.0 0.0 1.0"/>
            </material>
        </visual>
        <collision>
            <origin xyz="0 0.4447668515070398 -0.4020425872776315" rpy="0 0 0"/>
            <geometry>
                <box size="0.8431206964494439 0.8895337030140796 0.804085174555263" />
            </geometry>
        </collision>
    </link>
    <joint name="Link4_Link5" type="revolute">
       <parent link="Link4"/>
       <child  link="Link5"/>
       <origin rpy="0 0 0" xyz="0 0.8895337030140796 0.0" />
     <axis xyz="1 0 0"/>
       <limit effort="0.0" lower="-3.14159" upper="3.14159" velocity="0.0"/>
    </joint>
    <link name="Link5">
        <inertial>
            <origin xyz="0 0.25187564583746386 0.09672637632969039" rpy="0 0 0"/>
            <mass value="1" />
            <inertia ixx="100" ixy="0" ixz="0" iyy="100" iyz="0" izz="100" />
        </inertial>
        <visual>
            <origin xyz="0 0.25187564583746386 0.09672637632969039" rpy="0 0 0"/>
            <geometry>
                <box size="0.6130634838188757 0.5037512916749277 0.19345275265938078" />
            </geometry>
            <material name="Green">
                <color rgba="0 1.0 0.0 1.0"/>
            </material>
        </visual>
        <collision>
            <origin xyz="0 0.25187564583746386 0.09672637632969039" rpy="0 0 0"/>
            <geometry>
                <box size="0.6130634838188757 0.5037512916749277 0.19345275265938078" />
            </geometry>
        </collision>
    </link>
    <joint name="Link5_Link6" type="revolute">
       <parent link="Link5"/>
       <child  link="Link6"/>
       <origin rpy="0 0 0" xyz="0 0.0 0.19345275265938078" />
     <axis xyz="1 0 0"/>
       <limit effort="0.0" lower="-3.14159" upper="3.14159" velocity="0.0"/>
    </joint>
    <link name="Link6">
        <inertial>
            <origin xyz="0 -0.4542239559503553 0.1820505502033707" rpy="0 0 0"/>
            <mass value="1" />
            <inertia ixx="100" ixy="0" ixz="0" iyy="100" iyz="0" izz="100" />
        </inertial>
        <visual>
            <origin xyz="0 -0.4542239559503553 0.1820505502033707" rpy="0 0 0"/>
            <geometry>
                <box size="0.6140476186792226 0.9084479119007106 0.3641011004067414" />
            </geometry>
            <material name="Green">
                <color rgba="0 1.0 0.0 1.0"/>
            </material>
        </visual>
        <collision>
            <origin xyz="0 -0.4542239559503553 0.1820505502033707" rpy="0 0 0"/>
            <geometry>
                <box size="0.6140476186792226 0.9084479119007106 0.3641011004067414" />
            </geometry>
        </collision>
    </link>
</robot>