<robot name = "robot">
    <link name="Link0">
        <inertial>
            <origin xyz="0 0 2.1220349506754648" rpy="0 0 0"/>
            <mass value="1" />
            <inertia ixx="100" ixy="0" ixz="0" iyy="100" iyz="0" izz="100" />
        </inertial>
        <visual>
            <origin xyz="0 0 2.1220349506754648" rpy="0 0 0"/>
            <geometry>
                <box size="0.6031900226703191 0.7616974690007485 0.24406990135092976" />
            </geometry>
            <material name="Green">
                <color rgba="0 1.0 0.0 1.0"/>
            </material>
        </visual>
        <collision>
            <origin xyz="0 0 2.1220349506754648" rpy="0 0 0"/>
            <geometry>
                <box size="0.6031900226703191 0.7616974690007485 0.24406990135092976" />
            </geometry>
        </collision>
    </link>
    <joint name="Link0_Link1" type="revolute">
       <parent link="Link0"/>
       <child  link="Link1"/>
       <origin rpy="0 0 0" xyz="0 0.38084873450037426 2.2440699013509295" />
     <axis xyz="1 0 0"/>
       <limit effort="0.0" lower="-3.14159" upper="3.14159" velocity="0.0"/>
    </joint>
    <link name="Link1">
        <inertial>
            <origin xyz="0 0.38084873450037426 -0.12203495067546488" rpy="0 0 0"/>
            <mass value="1" />
            <inertia ixx="100" ixy="0" ixz="0" iyy="100" iyz="0" izz="100" />
        </inertial>
        <visual>
            <origin xyz="0 0.38084873450037426 -0.12203495067546488" rpy="0 0 0"/>
            <geometry>
                <box size="0.6031900226703191 0.7616974690007485 0.24406990135092976" />
            </geometry>
            <material name="Green">
                <color rgba="0 1.0 0.0 1.0"/>
            </material>
        </visual>
        <collision>
            <origin xyz="0 0.38084873450037426 -0.12203495067546488" rpy="0 0 0"/>
            <geometry>
                <box size="0.6031900226703191 0.7616974690007485 0.24406990135092976" />
            </geometry>
        </collision>
    </link>
    <joint name="Link1_Link2" type="revolute">
       <parent link="Link1"/>
       <child  link="Link2"/>
       <origin rpy="0 0 0" xyz="0 0.0 0.0" />
     <axis xyz="1 0 0"/>
       <limit effort="0.0" lower="-3.14159" upper="3.14159" velocity="0.0"/>
    </joint>
    <link name="Link2">
        <inertial>
            <origin xyz="0 -0.1944981013654754 -0.04821750784127349" rpy="0 0 0"/>
            <mass value="1" />
            <inertia ixx="100" ixy="0" ixz="0" iyy="100" iyz="0" izz="100" />
        </inertial>
        <visual>
            <origin xyz="0 -0.1944981013654754 -0.04821750784127349" rpy="0 0 0"/>
            <geometry>
                <box size="0.43389719616033484 0.3889962027309508 0.09643501568254698" />
            </geometry>
            <material name="Green">
                <color rgba="0 1.0 0.0 1.0"/>
            </material>
        </visual>
        <collision>
            <origin xyz="0 -0.1944981013654754 -0.04821750784127349" rpy="0 0 0"/>
            <geometry>
                <box size="0.43389719616033484 0.3889962027309508 0.09643501568254698" />
            </geometry>
        </collision>
    </link>
    <joint name="Link2_Link3" type="revolute">
       <parent link="Link2"/>
       <child  link="Link3"/>
       <origin rpy="0 0 0" xyz="0.21694859808016742 -0.1944981013654754 0.0" />
     <axis xyz="0 1 0"/>
       <limit effort="0.0" lower="-3.14159" upper="3.14159" velocity="0.0"/>
    </joint>
    <link name="Link3">
        <inertial>
            <origin xyz="0.10987229727370496 0 -0.40917583683590886" rpy="0 0 0"/>
            <mass value="1" />
            <inertia ixx="100" ixy="0" ixz="0" iyy="100" iyz="0" izz="100" />
        </inertial>
        <visual>
            <origin xyz="0.10987229727370496 0 -0.40917583683590886" rpy="0 0 0"/>
            <geometry>
                <box size="0.2197445945474099 0.4886732232802776 0.8183516736718177" />
            </geometry>
            <material name="Green">
                <color rgba="0 1.0 0.0 1.0"/>
            </material>
        </visual>
        <collision>
            <origin xyz="0.10987229727370496 0 -0.40917583683590886" rpy="0 0 0"/>
            <geometry>
                <box size="0.2197445945474099 0.4886732232802776 0.8183516736718177" />
            </geometry>
        </collision>
    </link>
    <joint name="Link3_Link4" type="revolute">
       <parent link="Link3"/>
       <child  link="Link4"/>
       <origin rpy="0 0 0" xyz="0.0 0 0.0" />
     <axis xyz="0 1 0"/>
       <limit effort="0.0" lower="-3.14159" upper="3.14159" velocity="0.0"/>
    </joint>
    <link name="Link4">
        <inertial>
            <origin xyz="-0.13480958540202942 0 0.11841290774489421" rpy="0 0 0"/>
            <mass value="1" />
            <inertia ixx="100" ixy="0" ixz="0" iyy="100" iyz="0" izz="100" />
        </inertial>
        <visual>
            <origin xyz="-0.13480958540202942 0 0.11841290774489421" rpy="0 0 0"/>
            <geometry>
                <box size="0.26961917080405884 0.20277153890757493 0.23682581548978843" />
            </geometry>
            <material name="Blue">
                <color rgba="0 0.0 1.0 1.0"/>
            </material>
        </visual>
        <collision>
            <origin xyz="-0.13480958540202942 0 0.11841290774489421" rpy="0 0 0"/>
            <geometry>
                <box size="0.26961917080405884 0.20277153890757493 0.23682581548978843" />
            </geometry>
        </collision>
    </link>
    <joint name="Link4_Link5" type="revolute">
       <parent link="Link4"/>
       <child  link="Link5"/>
       <origin rpy="0 0 0" xyz="0.0 0 0.23682581548978843" />
     <axis xyz="0 1 0"/>
       <limit effort="0.0" lower="-3.14159" upper="3.14159" velocity="0.0"/>
    </joint>
    <link name="Link5">
        <inertial>
            <origin xyz="0.03057762369282052 0 -0.17739957359648933" rpy="0 0 0"/>
            <mass value="1" />
            <inertia ixx="100" ixy="0" ixz="0" iyy="100" iyz="0" izz="100" />
        </inertial>
        <visual>
            <origin xyz="0.03057762369282052 0 -0.17739957359648933" rpy="0 0 0"/>
            <geometry>
                <box size="0.06115524738564104 0.038464099842046906 0.35479914719297867" />
            </geometry>
            <material name="Green">
                <color rgba="0 1.0 0.0 1.0"/>
            </material>
        </visual>
        <collision>
            <origin xyz="0.03057762369282052 0 -0.17739957359648933" rpy="0 0 0"/>
            <geometry>
                <box size="0.06115524738564104 0.038464099842046906 0.35479914719297867" />
            </geometry>
        </collision>
    </link>
</robot>