<robot name = "robot">
    <link name="Link0">
        <inertial>
            <origin xyz="0 0 2.3203227543756055" rpy="0 0 0"/>
            <mass value="1" />
            <inertia ixx="100" ixy="0" ixz="0" iyy="100" iyz="0" izz="100" />
        </inertial>
        <visual>
            <origin xyz="0 0 2.3203227543756055" rpy="0 0 0"/>
            <geometry>
                <box size="0.14690170097251043 0.7265365974052455 0.640645508751211" />
            </geometry>
            <material name="Green">
                <color rgba="0 1.0 0.0 1.0"/>
            </material>
        </visual>
        <collision>
            <origin xyz="0 0 2.3203227543756055" rpy="0 0 0"/>
            <geometry>
                <box size="0.14690170097251043 0.7265365974052455 0.640645508751211" />
            </geometry>
        </collision>
    </link>
    <joint name="Link0_Link1" type="revolute">
       <parent link="Link0"/>
       <child  link="Link1"/>
       <origin rpy="0 0 0" xyz="0 0.3632682987026227 2.640645508751211" />
     <axis xyz="1 0 0"/>
       <limit effort="0.0" lower="-3.14159" upper="3.14159" velocity="0.0"/>
    </joint>
    <link name="Link1">
        <inertial>
            <origin xyz="0 0.3632682987026227 -0.3203227543756055" rpy="0 0 0"/>
            <mass value="1" />
            <inertia ixx="100" ixy="0" ixz="0" iyy="100" iyz="0" izz="100" />
        </inertial>
        <visual>
            <origin xyz="0 0.3632682987026227 -0.3203227543756055" rpy="0 0 0"/>
            <geometry>
                <box size="0.14690170097251043 0.7265365974052455 0.640645508751211" />
            </geometry>
            <material name="Blue">
                <color rgba="0 0.0 1.0 1.0"/>
            </material>
        </visual>
        <collision>
            <origin xyz="0 0.3632682987026227 -0.3203227543756055" rpy="0 0 0"/>
            <geometry>
                <box size="0.14690170097251043 0.7265365974052455 0.640645508751211" />
            </geometry>
        </collision>
    </link>
    <joint name="Link1_Link2" type="revolute">
       <parent link="Link1"/>
       <child  link="Link2"/>
       <origin rpy="0 0 0" xyz="0 0.0 0.0" />
     <axis xyz="1 0 0"/>
       <limit effort="0.0" lower="-3.14159" upper="3.14159" velocity="0.0"/>
    </joint>
    <link name="Link2">
        <inertial>
            <origin xyz="0 -0.2652002596636222 -0.2079561153847898" rpy="0 0 0"/>
            <mass value="1" />
            <inertia ixx="100" ixy="0" ixz="0" iyy="100" iyz="0" izz="100" />
        </inertial>
        <visual>
            <origin xyz="0 -0.2652002596636222 -0.2079561153847898" rpy="0 0 0"/>
            <geometry>
                <box size="0.0631171176961538 0.5304005193272444 0.4159122307695796" />
            </geometry>
            <material name="Blue">
                <color rgba="0 0.0 1.0 1.0"/>
            </material>
        </visual>
        <collision>
            <origin xyz="0 -0.2652002596636222 -0.2079561153847898" rpy="0 0 0"/>
            <geometry>
                <box size="0.0631171176961538 0.5304005193272444 0.4159122307695796" />
            </geometry>
        </collision>
    </link>
    <joint name="Link2_Link3" type="revolute">
       <parent link="Link2"/>
       <child  link="Link3"/>
       <origin rpy="0 0 0" xyz="0.0315585588480769 -0.2652002596636222 0.0" />
     <axis xyz="0 1 0"/>
       <limit effort="0.0" lower="-3.14159" upper="3.14159" velocity="0.0"/>
    </joint>
    <link name="Link3">
        <inertial>
            <origin xyz="0.4697261725948589 0 -0.4083428395690541" rpy="0 0 0"/>
            <mass value="1" />
            <inertia ixx="100" ixy="0" ixz="0" iyy="100" iyz="0" izz="100" />
        </inertial>
        <visual>
            <origin xyz="0.4697261725948589 0 -0.4083428395690541" rpy="0 0 0"/>
            <geometry>
                <box size="0.9394523451897178 0.8816485087281655 0.8166856791381082" />
            </geometry>
            <material name="Green">
                <color rgba="0 1.0 0.0 1.0"/>
            </material>
        </visual>
        <collision>
            <origin xyz="0.4697261725948589 0 -0.4083428395690541" rpy="0 0 0"/>
            <geometry>
                <box size="0.9394523451897178 0.8816485087281655 0.8166856791381082" />
            </geometry>
        </collision>
    </link>
    <joint name="Link3_Link4" type="revolute">
       <parent link="Link3"/>
       <child  link="Link4"/>
       <origin rpy="0 0 0" xyz="0.4697261725948589 0.44082425436408273 0.0" />
     <axis xyz="1 0 0"/>
       <limit effort="0.0" lower="-3.14159" upper="3.14159" velocity="0.0"/>
    </joint>
    <link name="Link4">
        <inertial>
            <origin xyz="0 0.2779853130508175 -0.232440942593242" rpy="0 0 0"/>
            <mass value="1" />
            <inertia ixx="100" ixy="0" ixz="0" iyy="100" iyz="0" izz="100" />
        </inertial>
        <visual>
            <origin xyz="0 0.2779853130508175 -0.232440942593242" rpy="0 0 0"/>
            <geometry>
                <box size="0.18047242104123895 0.555970626101635 0.464881885186484" />
            </geometry>
            <material name="Blue">
                <color rgba="0 0.0 1.0 1.0"/>
            </material>
        </visual>
        <collision>
            <origin xyz="0 0.2779853130508175 -0.232440942593242" rpy="0 0 0"/>
            <geometry>
                <box size="0.18047242104123895 0.555970626101635 0.464881885186484" />
            </geometry>
        </collision>
    </link>
    <joint name="Link4_Link5" type="revolute">
       <parent link="Link4"/>
       <child  link="Link5"/>
       <origin rpy="0 0 0" xyz="0 0.555970626101635 0.0" />
     <axis xyz="1 0 0"/>
       <limit effort="0.0" lower="-3.14159" upper="3.14159" velocity="0.0"/>
    </joint>
    <link name="Link5">
        <inertial>
            <origin xyz="0 0.4031206358240344 -0.008075229861565392" rpy="0 0 0"/>
            <mass value="1" />
            <inertia ixx="100" ixy="0" ixz="0" iyy="100" iyz="0" izz="100" />
        </inertial>
        <visual>
            <origin xyz="0 0.4031206358240344 -0.008075229861565392" rpy="0 0 0"/>
            <geometry>
                <box size="0.06300361845626556 0.8062412716480688 0.016150459723130783" />
            </geometry>
            <material name="Green">
                <color rgba="0 1.0 0.0 1.0"/>
            </material>
        </visual>
        <collision>
            <origin xyz="0 0.4031206358240344 -0.008075229861565392" rpy="0 0 0"/>
            <geometry>
                <box size="0.06300361845626556 0.8062412716480688 0.016150459723130783" />
            </geometry>
        </collision>
    </link>
</robot>