<robot name = "robot">
    <link name="Link0">
        <inertial>
            <origin xyz="0 0 2.3189985532934334" rpy="0 0 0"/>
            <mass value="1" />
            <inertia ixx="100" ixy="0" ixz="0" iyy="100" iyz="0" izz="100" />
        </inertial>
        <visual>
            <origin xyz="0 0 2.3189985532934334" rpy="0 0 0"/>
            <geometry>
                <box size="0.3382310551262935 0.8390671503933158 0.6379971065868667" />
            </geometry>
            <material name="Green">
                <color rgba="0 1.0 0.0 1.0"/>
            </material>
        </visual>
        <collision>
            <origin xyz="0 0 2.3189985532934334" rpy="0 0 0"/>
            <geometry>
                <box size="0.3382310551262935 0.8390671503933158 0.6379971065868667" />
            </geometry>
        </collision>
    </link>
    <joint name="Link0_Link1" type="revolute">
       <parent link="Link0"/>
       <child  link="Link1"/>
       <origin rpy="0 0 0" xyz="0 0.4195335751966579 2.637997106586867" />
     <axis xyz="1 0 0"/>
       <limit effort="0.0" lower="-3.14159" upper="3.14159" velocity="0.0"/>
    </joint>
    <link name="Link1">
        <inertial>
            <origin xyz="0 0.4195335751966579 -0.31899855329343335" rpy="0 0 0"/>
            <mass value="1" />
            <inertia ixx="100" ixy="0" ixz="0" iyy="100" iyz="0" izz="100" />
        </inertial>
        <visual>
            <origin xyz="0 0.4195335751966579 -0.31899855329343335" rpy="0 0 0"/>
            <geometry>
                <box size="0.3382310551262935 0.8390671503933158 0.6379971065868667" />
            </geometry>
            <material name="Green">
                <color rgba="0 1.0 0.0 1.0"/>
            </material>
        </visual>
        <collision>
            <origin xyz="0 0.4195335751966579 -0.31899855329343335" rpy="0 0 0"/>
            <geometry>
                <box size="0.3382310551262935 0.8390671503933158 0.6379971065868667" />
            </geometry>
        </collision>
    </link>
    <joint name="Link1_Link2" type="revolute">
       <parent link="Link1"/>
       <child  link="Link2"/>
       <origin rpy="0 0 0" xyz="0 0.0 0.0" />
     <axis xyz="1 0 0"/>
       <limit effort="0.0" lower="-3.14159" upper="3.14159" velocity="0.0"/>
    </joint>
    <link name="Link2">
        <inertial>
            <origin xyz="0 -0.45722438890543327 0.4806507433131403" rpy="0 0 0"/>
            <mass value="1" />
            <inertia ixx="100" ixy="0" ixz="0" iyy="100" iyz="0" izz="100" />
        </inertial>
        <visual>
            <origin xyz="0 -0.45722438890543327 0.4806507433131403" rpy="0 0 0"/>
            <geometry>
                <box size="0.5941329420764161 0.9144487778108665 0.9613014866262806" />
            </geometry>
            <material name="Blue">
                <color rgba="0 0.0 1.0 1.0"/>
            </material>
        </visual>
        <collision>
            <origin xyz="0 -0.45722438890543327 0.4806507433131403" rpy="0 0 0"/>
            <geometry>
                <box size="0.5941329420764161 0.9144487778108665 0.9613014866262806" />
            </geometry>
        </collision>
    </link>
    <joint name="Link2_Link3" type="revolute">
       <parent link="Link2"/>
       <child  link="Link3"/>
       <origin rpy="0 0 0" xyz="-0.29706647103820805 -0.45722438890543327 0.9613014866262806" />
     <axis xyz="0 1 0"/>
       <limit effort="0.0" lower="-3.14159" upper="3.14159" velocity="0.0"/>
    </joint>
    <link name="Link3">
        <inertial>
            <origin xyz="-0.09219042710388714 0 -0.07329321679828299" rpy="0 0 0"/>
            <mass value="1" />
            <inertia ixx="100" ixy="0" ixz="0" iyy="100" iyz="0" izz="100" />
        </inertial>
        <visual>
            <origin xyz="-0.09219042710388714 0 -0.07329321679828299" rpy="0 0 0"/>
            <geometry>
                <box size="0.18438085420777428 0.4563548161074503 0.14658643359656598" />
            </geometry>
            <material name="Green">
                <color rgba="0 1.0 0.0 1.0"/>
            </material>
        </visual>
        <collision>
            <origin xyz="-0.09219042710388714 0 -0.07329321679828299" rpy="0 0 0"/>
            <geometry>
                <box size="0.18438085420777428 0.4563548161074503 0.14658643359656598" />
            </geometry>
        </collision>
    </link>
    <joint name="Link3_Link4" type="revolute">
       <parent link="Link3"/>
       <child  link="Link4"/>
       <origin rpy="0 0 0" xyz="-0.18438085420777428 0 0.0" />
     <axis xyz="0 1 0"/>
       <limit effort="0.0" lower="-3.14159" upper="3.14159" velocity="0.0"/>
    </joint>
    <link name="Link4">
        <inertial>
            <origin xyz="-0.4943420058221279 0 -0.4058771183188117" rpy="0 0 0"/>
            <mass value="1" />
            <inertia ixx="100" ixy="0" ixz="0" iyy="100" iyz="0" izz="100" />
        </inertial>
        <visual>
            <origin xyz="-0.4943420058221279 0 -0.4058771183188117" rpy="0 0 0"/>
            <geometry>
                <box size="0.9886840116442558 0.15058615988714696 0.8117542366376234" />
            </geometry>
            <material name="Green">
                <color rgba="0 1.0 0.0 1.0"/>
            </material>
        </visual>
        <collision>
            <origin xyz="-0.4943420058221279 0 -0.4058771183188117" rpy="0 0 0"/>
            <geometry>
                <box size="0.9886840116442558 0.15058615988714696 0.8117542366376234" />
            </geometry>
        </collision>
    </link>
    <joint name="Link4_Link5" type="revolute">
       <parent link="Link4"/>
       <child  link="Link5"/>
       <origin rpy="0 0 0" xyz="0.0 0 0.0" />
     <axis xyz="0 1 0"/>
       <limit effort="0.0" lower="-3.14159" upper="3.14159" velocity="0.0"/>
    </joint>
    <link name="Link5">
        <inertial>
            <origin xyz="0.3409054350206213 0 0.3402532857304214" rpy="0 0 0"/>
            <mass value="1" />
            <inertia ixx="100" ixy="0" ixz="0" iyy="100" iyz="0" izz="100" />
        </inertial>
        <visual>
            <origin xyz="0.3409054350206213 0 0.3402532857304214" rpy="0 0 0"/>
            <geometry>
                <box size="0.6818108700412426 0.9766970639647401 0.6805065714608428" />
            </geometry>
            <material name="Green">
                <color rgba="0 1.0 0.0 1.0"/>
            </material>
        </visual>
        <collision>
            <origin xyz="0.3409054350206213 0 0.3402532857304214" rpy="0 0 0"/>
            <geometry>
                <box size="0.6818108700412426 0.9766970639647401 0.6805065714608428" />
            </geometry>
        </collision>
    </link>
</robot>