<robot name = "robot">
    <link name="Link0">
        <inertial>
            <origin xyz="0 0 2.479582901301727" rpy="0 0 0"/>
            <mass value="1" />
            <inertia ixx="100" ixy="0" ixz="0" iyy="100" iyz="0" izz="100" />
        </inertial>
        <visual>
            <origin xyz="0 0 2.479582901301727" rpy="0 0 0"/>
            <geometry>
                <box size="0.409808790113793 0.5550378634522883 0.9591658026034547" />
            </geometry>
            <material name="Green">
                <color rgba="0 1.0 0.0 1.0"/>
            </material>
        </visual>
        <collision>
            <origin xyz="0 0 2.479582901301727" rpy="0 0 0"/>
            <geometry>
                <box size="0.409808790113793 0.5550378634522883 0.9591658026034547" />
            </geometry>
        </collision>
    </link>
    <joint name="Link0_Link1" type="revolute">
       <parent link="Link0"/>
       <child  link="Link1"/>
       <origin rpy="0 0 0" xyz="0 0.27751893172614417 2.959165802603455" />
     <axis xyz="1 0 0"/>
       <limit effort="0.0" lower="-3.14159" upper="3.14159" velocity="0.0"/>
    </joint>
    <link name="Link1">
        <inertial>
            <origin xyz="0 0.27751893172614417 -0.47958290130172737" rpy="0 0 0"/>
            <mass value="1" />
            <inertia ixx="100" ixy="0" ixz="0" iyy="100" iyz="0" izz="100" />
        </inertial>
        <visual>
            <origin xyz="0 0.27751893172614417 -0.47958290130172737" rpy="0 0 0"/>
            <geometry>
                <box size="0.409808790113793 0.5550378634522883 0.9591658026034547" />
            </geometry>
            <material name="Green">
                <color rgba="0 1.0 0.0 1.0"/>
            </material>
        </visual>
        <collision>
            <origin xyz="0 0.27751893172614417 -0.47958290130172737" rpy="0 0 0"/>
            <geometry>
                <box size="0.409808790113793 0.5550378634522883 0.9591658026034547" />
            </geometry>
        </collision>
    </link>
    <joint name="Link1_Link2" type="revolute">
       <parent link="Link1"/>
       <child  link="Link2"/>
       <origin rpy="0 0 0" xyz="0 0.0 0.0" />
     <axis xyz="1 0 0"/>
       <limit effort="0.0" lower="-3.14159" upper="3.14159" velocity="0.0"/>
    </joint>
    <link name="Link2">
        <inertial>
            <origin xyz="0 -0.21305214459945998 0.3403374444486221" rpy="0 0 0"/>
            <mass value="1" />
            <inertia ixx="100" ixy="0" ixz="0" iyy="100" iyz="0" izz="100" />
        </inertial>
        <visual>
            <origin xyz="0 -0.21305214459945998 0.3403374444486221" rpy="0 0 0"/>
            <geometry>
                <box size="0.27886549223816526 0.42610428919891996 0.6806748888972441" />
            </geometry>
            <material name="Green">
                <color rgba="0 1.0 0.0 1.0"/>
            </material>
        </visual>
        <collision>
            <origin xyz="0 -0.21305214459945998 0.3403374444486221" rpy="0 0 0"/>
            <geometry>
                <box size="0.27886549223816526 0.42610428919891996 0.6806748888972441" />
            </geometry>
        </collision>
    </link>
    <joint name="Link2_Link3" type="revolute">
       <parent link="Link2"/>
       <child  link="Link3"/>
       <origin rpy="0 0 0" xyz="-0.13943274611908263 -0.21305214459945998 0.6806748888972441" />
     <axis xyz="0 1 0"/>
       <limit effort="0.0" lower="-3.14159" upper="3.14159" velocity="0.0"/>
    </joint>
    <link name="Link3">
        <inertial>
            <origin xyz="-0.22127272652550412 0 -0.06943839367135152" rpy="0 0 0"/>
            <mass value="1" />
            <inertia ixx="100" ixy="0" ixz="0" iyy="100" iyz="0" izz="100" />
        </inertial>
        <visual>
            <origin xyz="-0.22127272652550412 0 -0.06943839367135152" rpy="0 0 0"/>
            <geometry>
                <box size="0.44254545305100823 0.13826712182656709 0.13887678734270303" />
            </geometry>
            <material name="Blue">
                <color rgba="0 0.0 1.0 1.0"/>
            </material>
        </visual>
        <collision>
            <origin xyz="-0.22127272652550412 0 -0.06943839367135152" rpy="0 0 0"/>
            <geometry>
                <box size="0.44254545305100823 0.13826712182656709 0.13887678734270303" />
            </geometry>
        </collision>
    </link>
    <joint name="Link3_Link4" type="revolute">
       <parent link="Link3"/>
       <child  link="Link4"/>
       <origin rpy="0 0 0" xyz="-0.44254545305100823 0 0.0" />
     <axis xyz="0 1 0"/>
       <limit effort="0.0" lower="-3.14159" upper="3.14159" velocity="0.0"/>
    </joint>
    <link name="Link4">
        <inertial>
            <origin xyz="-0.09801175473432672 0 0.43012696083264707" rpy="0 0 0"/>
            <mass value="1" />
            <inertia ixx="100" ixy="0" ixz="0" iyy="100" iyz="0" izz="100" />
        </inertial>
        <visual>
            <origin xyz="-0.09801175473432672 0 0.43012696083264707" rpy="0 0 0"/>
            <geometry>
                <box size="0.19602350946865343 0.759961983264422 0.8602539216652941" />
            </geometry>
            <material name="Blue">
                <color rgba="0 0.0 1.0 1.0"/>
            </material>
        </visual>
        <collision>
            <origin xyz="-0.09801175473432672 0 0.43012696083264707" rpy="0 0 0"/>
            <geometry>
                <box size="0.19602350946865343 0.759961983264422 0.8602539216652941" />
            </geometry>
        </collision>
    </link>
    <joint name="Link4_Link5" type="revolute">
       <parent link="Link4"/>
       <child  link="Link5"/>
       <origin rpy="0 0 0" xyz="-0.19602350946865343 0 0.8602539216652941" />
     <axis xyz="0 1 0"/>
       <limit effort="0.0" lower="-3.14159" upper="3.14159" velocity="0.0"/>
    </joint>
    <link name="Link5">
        <inertial>
            <origin xyz="-0.31329715229023997 0 0.09506282272861966" rpy="0 0 0"/>
            <mass value="1" />
            <inertia ixx="100" ixy="0" ixz="0" iyy="100" iyz="0" izz="100" />
        </inertial>
        <visual>
            <origin xyz="-0.31329715229023997 0 0.09506282272861966" rpy="0 0 0"/>
            <geometry>
                <box size="0.6265943045804799 0.7320267241190586 0.1901256454572393" />
            </geometry>
            <material name="Blue">
                <color rgba="0 0.0 1.0 1.0"/>
            </material>
        </visual>
        <collision>
            <origin xyz="-0.31329715229023997 0 0.09506282272861966" rpy="0 0 0"/>
            <geometry>
                <box size="0.6265943045804799 0.7320267241190586 0.1901256454572393" />
            </geometry>
        </collision>
    </link>
    <joint name="Link5_Link6" type="revolute">
       <parent link="Link5"/>
       <child  link="Link6"/>
       <origin rpy="0 0 0" xyz="0.0 0 0.1901256454572393" />
     <axis xyz="0 1 0"/>
       <limit effort="0.0" lower="-3.14159" upper="3.14159" velocity="0.0"/>
    </joint>
    <link name="Link6">
        <inertial>
            <origin xyz="0.23878335026123138 0 -0.2494665652174632" rpy="0 0 0"/>
            <mass value="1" />
            <inertia ixx="100" ixy="0" ixz="0" iyy="100" iyz="0" izz="100" />
        </inertial>
        <visual>
            <origin xyz="0.23878335026123138 0 -0.2494665652174632" rpy="0 0 0"/>
            <geometry>
                <box size="0.47756670052246275 0.19523231636382288 0.4989331304349264" />
            </geometry>
            <material name="Blue">
                <color rgba="0 0.0 1.0 1.0"/>
            </material>
        </visual>
        <collision>
            <origin xyz="0.23878335026123138 0 -0.2494665652174632" rpy="0 0 0"/>
            <geometry>
                <box size="0.47756670052246275 0.19523231636382288 0.4989331304349264" />
            </geometry>
        </collision>
    </link>
</robot>