<robot name = "robot">
    <link name="Link0">
        <inertial>
            <origin xyz="0 0 2.126019351552523" rpy="0 0 0"/>
            <mass value="1" />
            <inertia ixx="100" ixy="0" ixz="0" iyy="100" iyz="0" izz="100" />
        </inertial>
        <visual>
            <origin xyz="0 0 2.126019351552523" rpy="0 0 0"/>
            <geometry>
                <box size="0.7895180147954339 0.22738828347043138 0.25203870310504584" />
            </geometry>
            <material name="Green">
                <color rgba="0 1.0 0.0 1.0"/>
            </material>
        </visual>
        <collision>
            <origin xyz="0 0 2.126019351552523" rpy="0 0 0"/>
            <geometry>
                <box size="0.7895180147954339 0.22738828347043138 0.25203870310504584" />
            </geometry>
        </collision>
    </link>
    <joint name="Link0_Link1" type="revolute">
       <parent link="Link0"/>
       <child  link="Link1"/>
       <origin rpy="0 0 0" xyz="0 0.11369414173521569 2.252038703105046" />
     <axis xyz="1 0 0"/>
       <limit effort="0.0" lower="-3.14159" upper="3.14159" velocity="0.0"/>
    </joint>
    <link name="Link1">
        <inertial>
            <origin xyz="0 0.11369414173521569 -0.12601935155252292" rpy="0 0 0"/>
            <mass value="1" />
            <inertia ixx="100" ixy="0" ixz="0" iyy="100" iyz="0" izz="100" />
        </inertial>
        <visual>
            <origin xyz="0 0.11369414173521569 -0.12601935155252292" rpy="0 0 0"/>
            <geometry>
                <box size="0.7895180147954339 0.22738828347043138 0.25203870310504584" />
            </geometry>
            <material name="Blue">
                <color rgba="0 0.0 1.0 1.0"/>
            </material>
        </visual>
        <collision>
            <origin xyz="0 0.11369414173521569 -0.12601935155252292" rpy="0 0 0"/>
            <geometry>
                <box size="0.7895180147954339 0.22738828347043138 0.25203870310504584" />
            </geometry>
        </collision>
    </link>
    <joint name="Link1_Link2" type="revolute">
       <parent link="Link1"/>
       <child  link="Link2"/>
       <origin rpy="0 0 0" xyz="0 0.0 0.0" />
     <axis xyz="1 0 0"/>
       <limit effort="0.0" lower="-3.14159" upper="3.14159" velocity="0.0"/>
    </joint>
    <link name="Link2">
        <inertial>
            <origin xyz="0 -0.09800839694337188 0.4185245260585279" rpy="0 0 0"/>
            <mass value="1" />
            <inertia ixx="100" ixy="0" ixz="0" iyy="100" iyz="0" izz="100" />
        </inertial>
        <visual>
            <origin xyz="0 -0.09800839694337188 0.4185245260585279" rpy="0 0 0"/>
            <geometry>
                <box size="0.28541010007178913 0.19601679388674376 0.8370490521170558" />
            </geometry>
            <material name="Green">
                <color rgba="0 1.0 0.0 1.0"/>
            </material>
        </visual>
        <collision>
            <origin xyz="0 -0.09800839694337188 0.4185245260585279" rpy="0 0 0"/>
            <geometry>
                <box size="0.28541010007178913 0.19601679388674376 0.8370490521170558" />
            </geometry>
        </collision>
    </link>
    <joint name="Link2_Link3" type="revolute">
       <parent link="Link2"/>
       <child  link="Link3"/>
       <origin rpy="0 0 0" xyz="0.14270505003589457 -0.09800839694337188 0.8370490521170558" />
     <axis xyz="0 1 0"/>
       <limit effort="0.0" lower="-3.14159" upper="3.14159" velocity="0.0"/>
    </joint>
    <link name="Link3">
        <inertial>
            <origin xyz="0.3207038191947749 0 0.35565486519885137" rpy="0 0 0"/>
            <mass value="1" />
            <inertia ixx="100" ixy="0" ixz="0" iyy="100" iyz="0" izz="100" />
        </inertial>
        <visual>
            <origin xyz="0.3207038191947749 0 0.35565486519885137" rpy="0 0 0"/>
            <geometry>
                <box size="0.6414076383895498 0.5621932418026875 0.7113097303977027" />
            </geometry>
            <material name="Blue">
                <color rgba="0 0.0 1.0 1.0"/>
            </material>
        </visual>
        <collision>
            <origin xyz="0.3207038191947749 0 0.35565486519885137" rpy="0 0 0"/>
            <geometry>
                <box size="0.6414076383895498 0.5621932418026875 0.7113097303977027" />
            </geometry>
        </collision>
    </link>
    <joint name="Link3_Link4" type="revolute">
       <parent link="Link3"/>
       <child  link="Link4"/>
       <origin rpy="0 0 0" xyz="0.0 0 0.7113097303977027" />
     <axis xyz="0 1 0"/>
       <limit effort="0.0" lower="-3.14159" upper="3.14159" velocity="0.0"/>
    </joint>
    <link name="Link4">
        <inertial>
            <origin xyz="-0.3606543591653964 0 -0.4276853236275125" rpy="0 0 0"/>
            <mass value="1" />
            <inertia ixx="100" ixy="0" ixz="0" iyy="100" iyz="0" izz="100" />
        </inertial>
        <visual>
            <origin xyz="-0.3606543591653964 0 -0.4276853236275125" rpy="0 0 0"/>
            <geometry>
                <box size="0.7213087183307928 0.690457435553389 0.855370647255025" />
            </geometry>
            <material name="Blue">
                <color rgba="0 0.0 1.0 1.0"/>
            </material>
        </visual>
        <collision>
            <origin xyz="-0.3606543591653964 0 -0.4276853236275125" rpy="0 0 0"/>
            <geometry>
                <box size="0.7213087183307928 0.690457435553389 0.855370647255025" />
            </geometry>
        </collision>
    </link>
    <joint name="Link4_Link5" type="revolute">
       <parent link="Link4"/>
       <child  link="Link5"/>
       <origin rpy="0 0 0" xyz="-0.3606543591653964 -0.3452287177766945 0.0" />
     <axis xyz="1 0 0"/>
       <limit effort="0.0" lower="-3.14159" upper="3.14159" velocity="0.0"/>
    </joint>
    <link name="Link5">
        <inertial>
            <origin xyz="0 -0.06208260680811778 0.3561311495548192" rpy="0 0 0"/>
            <mass value="1" />
            <inertia ixx="100" ixy="0" ixz="0" iyy="100" iyz="0" izz="100" />
        </inertial>
        <visual>
            <origin xyz="0 -0.06208260680811778 0.3561311495548192" rpy="0 0 0"/>
            <geometry>
                <box size="0.701991800155391 0.12416521361623556 0.7122622991096385" />
            </geometry>
            <material name="Blue">
                <color rgba="0 0.0 1.0 1.0"/>
            </material>
        </visual>
        <collision>
            <origin xyz="0 -0.06208260680811778 0.3561311495548192" rpy="0 0 0"/>
            <geometry>
                <box size="0.701991800155391 0.12416521361623556 0.7122622991096385" />
            </geometry>
        </collision>
    </link>
</robot>