<robot name = "robot">
    <link name="Link0">
        <inertial>
            <origin xyz="0 0 2.1940086644294663" rpy="0 0 0"/>
            <mass value="1" />
            <inertia ixx="100" ixy="0" ixz="0" iyy="100" iyz="0" izz="100" />
        </inertial>
        <visual>
            <origin xyz="0 0 2.1940086644294663" rpy="0 0 0"/>
            <geometry>
                <box size="0.24026621743305532 0.2511994323106993 0.3880173288589328" />
            </geometry>
            <material name="Green">
                <color rgba="0 1.0 0.0 1.0"/>
            </material>
        </visual>
        <collision>
            <origin xyz="0 0 2.1940086644294663" rpy="0 0 0"/>
            <geometry>
                <box size="0.24026621743305532 0.2511994323106993 0.3880173288589328" />
            </geometry>
        </collision>
    </link>
    <joint name="Link0_Link1" type="revolute">
       <parent link="Link0"/>
       <child  link="Link1"/>
       <origin rpy="0 0 0" xyz="0 0.12559971615534965 2.3880173288589326" />
     <axis xyz="1 0 0"/>
       <limit effort="0.0" lower="-3.14159" upper="3.14159" velocity="0.0"/>
    </joint>
    <link name="Link1">
        <inertial>
            <origin xyz="0 0.12559971615534965 -0.1940086644294664" rpy="0 0 0"/>
            <mass value="1" />
            <inertia ixx="100" ixy="0" ixz="0" iyy="100" iyz="0" izz="100" />
        </inertial>
        <visual>
            <origin xyz="0 0.12559971615534965 -0.1940086644294664" rpy="0 0 0"/>
            <geometry>
                <box size="0.24026621743305532 0.2511994323106993 0.3880173288589328" />
            </geometry>
            <material name="Green">
                <color rgba="0 1.0 0.0 1.0"/>
            </material>
        </visual>
        <collision>
            <origin xyz="0 0.12559971615534965 -0.1940086644294664" rpy="0 0 0"/>
            <geometry>
                <box size="0.24026621743305532 0.2511994323106993 0.3880173288589328" />
            </geometry>
        </collision>
    </link>
    <joint name="Link1_Link2" type="revolute">
       <parent link="Link1"/>
       <child  link="Link2"/>
       <origin rpy="0 0 0" xyz="0 0.0 0.0" />
     <axis xyz="1 0 0"/>
       <limit effort="0.0" lower="-3.14159" upper="3.14159" velocity="0.0"/>
    </joint>
    <link name="Link2">
        <inertial>
            <origin xyz="0 -0.3405451824797264 0.386451804932881" rpy="0 0 0"/>
            <mass value="1" />
            <inertia ixx="100" ixy="0" ixz="0" iyy="100" iyz="0" izz="100" />
        </inertial>
        <visual>
            <origin xyz="0 -0.3405451824797264 0.386451804932881" rpy="0 0 0"/>
            <geometry>
                <box size="0.9881770495572212 0.6810903649594529 0.772903609865762" />
            </geometry>
            <material name="Blue">
                <color rgba="0 0.0 1.0 1.0"/>
            </material>
        </visual>
        <collision>
            <origin xyz="0 -0.3405451824797264 0.386451804932881" rpy="0 0 0"/>
            <geometry>
                <box size="0.9881770495572212 0.6810903649594529 0.772903609865762" />
            </geometry>
        </collision>
    </link>
    <joint name="Link2_Link3" type="revolute">
       <parent link="Link2"/>
       <child  link="Link3"/>
       <origin rpy="0 0 0" xyz="0 0.0 0.772903609865762" />
     <axis xyz="1 0 0"/>
       <limit effort="0.0" lower="-3.14159" upper="3.14159" velocity="0.0"/>
    </joint>
    <link name="Link3">
        <inertial>
            <origin xyz="0 0.3214511094371015 -0.4525270274261221" rpy="0 0 0"/>
            <mass value="1" />
            <inertia ixx="100" ixy="0" ixz="0" iyy="100" iyz="0" izz="100" />
        </inertial>
        <visual>
            <origin xyz="0 0.3214511094371015 -0.4525270274261221" rpy="0 0 0"/>
            <geometry>
                <box size="0.7242475802819489 0.642902218874203 0.9050540548522442" />
            </geometry>
            <material name="Green">
                <color rgba="0 1.0 0.0 1.0"/>
            </material>
        </visual>
        <collision>
            <origin xyz="0 0.3214511094371015 -0.4525270274261221" rpy="0 0 0"/>
            <geometry>
                <box size="0.7242475802819489 0.642902218874203 0.9050540548522442" />
            </geometry>
        </collision>
    </link>
    <joint name="Link3_Link4" type="revolute">
       <parent link="Link3"/>
       <child  link="Link4"/>
       <origin rpy="0 0 0" xyz="0 0.0 0.0" />
     <axis xyz="1 0 0"/>
       <limit effort="0.0" lower="-3.14159" upper="3.14159" velocity="0.0"/>
    </joint>
    <link name="Link4">
        <inertial>
            <origin xyz="0 -0.06873837334737987 0.09788290207494393" rpy="0 0 0"/>
            <mass value="1" />
            <inertia ixx="100" ixy="0" ixz="0" iyy="100" iyz="0" izz="100" />
        </inertial>
        <visual>
            <origin xyz="0 -0.06873837334737987 0.09788290207494393" rpy="0 0 0"/>
            <geometry>
                <box size="0.7781208826793271 0.13747674669475973 0.19576580414988787" />
            </geometry>
            <material name="Green">
                <color rgba="0 1.0 0.0 1.0"/>
            </material>
        </visual>
        <collision>
            <origin xyz="0 -0.06873837334737987 0.09788290207494393" rpy="0 0 0"/>
            <geometry>
                <box size="0.7781208826793271 0.13747674669475973 0.19576580414988787" />
            </geometry>
        </collision>
    </link>
    <joint name="Link4_Link5" type="revolute">
       <parent link="Link4"/>
       <child  link="Link5"/>
       <origin rpy="0 0 0" xyz="-0.38906044133966355 -0.06873837334737987 0.19576580414988787" />
     <axis xyz="0 1 0"/>
       <limit effort="0.0" lower="-3.14159" upper="3.14159" velocity="0.0"/>
    </joint>
    <link name="Link5">
        <inertial>
            <origin xyz="-0.39540622971182726 0 0.4688073085106602" rpy="0 0 0"/>
            <mass value="1" />
            <inertia ixx="100" ixy="0" ixz="0" iyy="100" iyz="0" izz="100" />
        </inertial>
        <visual>
            <origin xyz="-0.39540622971182726 0 0.4688073085106602" rpy="0 0 0"/>
            <geometry>
                <box size="0.7908124594236545 0.14368781141147224 0.9376146170213204" />
            </geometry>
            <material name="Blue">
                <color rgba="0 0.0 1.0 1.0"/>
            </material>
        </visual>
        <collision>
            <origin xyz="-0.39540622971182726 0 0.4688073085106602" rpy="0 0 0"/>
            <geometry>
                <box size="0.7908124594236545 0.14368781141147224 0.9376146170213204" />
            </geometry>
        </collision>
    </link>
    <joint name="Link5_Link6" type="revolute">
       <parent link="Link5"/>
       <child  link="Link6"/>
       <origin rpy="0 0 0" xyz="-0.39540622971182726 0.07184390570573612 0.9376146170213204" />
     <axis xyz="1 0 0"/>
       <limit effort="0.0" lower="-3.14159" upper="3.14159" velocity="0.0"/>
    </joint>
    <link name="Link6">
        <inertial>
            <origin xyz="0 0.1696212694822748 0.2549088808253233" rpy="0 0 0"/>
            <mass value="1" />
            <inertia ixx="100" ixy="0" ixz="0" iyy="100" iyz="0" izz="100" />
        </inertial>
        <visual>
            <origin xyz="0 0.1696212694822748 0.2549088808253233" rpy="0 0 0"/>
            <geometry>
                <box size="0.3583025992756447 0.3392425389645496 0.5098177616506466" />
            </geometry>
            <material name="Blue">
                <color rgba="0 0.0 1.0 1.0"/>
            </material>
        </visual>
        <collision>
            <origin xyz="0 0.1696212694822748 0.2549088808253233" rpy="0 0 0"/>
            <geometry>
                <box size="0.3583025992756447 0.3392425389645496 0.5098177616506466" />
            </geometry>
        </collision>
    </link>
</robot>