<robot name = "robot">
    <link name="Link0">
        <inertial>
            <origin xyz="0 0 2.0190801553385613" rpy="0 0 0"/>
            <mass value="1" />
            <inertia ixx="100" ixy="0" ixz="0" iyy="100" iyz="0" izz="100" />
        </inertial>
        <visual>
            <origin xyz="0 0 2.0190801553385613" rpy="0 0 0"/>
            <geometry>
                <box size="0.9234773257266014 0.4097880581252542 0.038160310677122666" />
            </geometry>
            <material name="Green">
                <color rgba="0 1.0 0.0 1.0"/>
            </material>
        </visual>
        <collision>
            <origin xyz="0 0 2.0190801553385613" rpy="0 0 0"/>
            <geometry>
                <box size="0.9234773257266014 0.4097880581252542 0.038160310677122666" />
            </geometry>
        </collision>
    </link>
    <joint name="Link0_Link1" type="revolute">
       <parent link="Link0"/>
       <child  link="Link1"/>
       <origin rpy="0 0 0" xyz="0 0.2048940290626271 2.0381603106771227" />
     <axis xyz="1 0 0"/>
       <limit effort="0.0" lower="-3.14159" upper="3.14159" velocity="0.0"/>
    </joint>
    <link name="Link1">
        <inertial>
            <origin xyz="0 0.2048940290626271 -0.019080155338561333" rpy="0 0 0"/>
            <mass value="1" />
            <inertia ixx="100" ixy="0" ixz="0" iyy="100" iyz="0" izz="100" />
        </inertial>
        <visual>
            <origin xyz="0 0.2048940290626271 -0.019080155338561333" rpy="0 0 0"/>
            <geometry>
                <box size="0.9234773257266014 0.4097880581252542 0.038160310677122666" />
            </geometry>
            <material name="Blue">
                <color rgba="0 0.0 1.0 1.0"/>
            </material>
        </visual>
        <collision>
            <origin xyz="0 0.2048940290626271 -0.019080155338561333" rpy="0 0 0"/>
            <geometry>
                <box size="0.9234773257266014 0.4097880581252542 0.038160310677122666" />
            </geometry>
        </collision>
    </link>
    <joint name="Link1_Link2" type="revolute">
       <parent link="Link1"/>
       <child  link="Link2"/>
       <origin rpy="0 0 0" xyz="-0.4617386628633007 0.2048940290626271 0.0" />
     <axis xyz="0 1 0"/>
       <limit effort="0.0" lower="-3.14159" upper="3.14159" velocity="0.0"/>
    </joint>
    <link name="Link2">
        <inertial>
            <origin xyz="-0.4608609783688514 0 -0.11938879761711907" rpy="0 0 0"/>
            <mass value="1" />
            <inertia ixx="100" ixy="0" ixz="0" iyy="100" iyz="0" izz="100" />
        </inertial>
        <visual>
            <origin xyz="-0.4608609783688514 0 -0.11938879761711907" rpy="0 0 0"/>
            <geometry>
                <box size="0.9217219567377029 0.8222480738553414 0.23877759523423814" />
            </geometry>
            <material name="Green">
                <color rgba="0 1.0 0.0 1.0"/>
            </material>
        </visual>
        <collision>
            <origin xyz="-0.4608609783688514 0 -0.11938879761711907" rpy="0 0 0"/>
            <geometry>
                <box size="0.9217219567377029 0.8222480738553414 0.23877759523423814" />
            </geometry>
        </collision>
    </link>
    <joint name="Link2_Link3" type="revolute">
       <parent link="Link2"/>
       <child  link="Link3"/>
       <origin rpy="0 0 0" xyz="0.0 0 0.0" />
     <axis xyz="0 1 0"/>
       <limit effort="0.0" lower="-3.14159" upper="3.14159" velocity="0.0"/>
    </joint>
    <link name="Link3">
        <inertial>
            <origin xyz="0.13917284145242614 0 0.1898073580594597" rpy="0 0 0"/>
            <mass value="1" />
            <inertia ixx="100" ixy="0" ixz="0" iyy="100" iyz="0" izz="100" />
        </inertial>
        <visual>
            <origin xyz="0.13917284145242614 0 0.1898073580594597" rpy="0 0 0"/>
            <geometry>
                <box size="0.2783456829048523 0.8418789442573501 0.3796147161189194" />
            </geometry>
            <material name="Green">
                <color rgba="0 1.0 0.0 1.0"/>
            </material>
        </visual>
        <collision>
            <origin xyz="0.13917284145242614 0 0.1898073580594597" rpy="0 0 0"/>
            <geometry>
                <box size="0.2783456829048523 0.8418789442573501 0.3796147161189194" />
            </geometry>
        </collision>
    </link>
    <joint name="Link3_Link4" type="revolute">
       <parent link="Link3"/>
       <child  link="Link4"/>
       <origin rpy="0 0 0" xyz="0.13917284145242614 -0.42093947212867505 0.3796147161189194" />
     <axis xyz="1 0 0"/>
       <limit effort="0.0" lower="-3.14159" upper="3.14159" velocity="0.0"/>
    </joint>
    <link name="Link4">
        <inertial>
            <origin xyz="0 -0.22346131302383349 -0.16245994655672208" rpy="0 0 0"/>
            <mass value="1" />
            <inertia ixx="100" ixy="0" ixz="0" iyy="100" iyz="0" izz="100" />
        </inertial>
        <visual>
            <origin xyz="0 -0.22346131302383349 -0.16245994655672208" rpy="0 0 0"/>
            <geometry>
                <box size="0.06370056410467362 0.44692262604766697 0.32491989311344416" />
            </geometry>
            <material name="Green">
                <color rgba="0 1.0 0.0 1.0"/>
            </material>
        </visual>
        <collision>
            <origin xyz="0 -0.22346131302383349 -0.16245994655672208" rpy="0 0 0"/>
            <geometry>
                <box size="0.06370056410467362 0.44692262604766697 0.32491989311344416" />
            </geometry>
        </collision>
    </link>
    <joint name="Link4_Link5" type="revolute">
       <parent link="Link4"/>
       <child  link="Link5"/>
       <origin rpy="0 0 0" xyz="0.03185028205233681 -0.22346131302383349 0.0" />
     <axis xyz="0 1 0"/>
       <limit effort="0.0" lower="-3.14159" upper="3.14159" velocity="0.0"/>
    </joint>
    <link name="Link5">
        <inertial>
            <origin xyz="0.14013684325487746 0 0.15449969263649543" rpy="0 0 0"/>
            <mass value="1" />
            <inertia ixx="100" ixy="0" ixz="0" iyy="100" iyz="0" izz="100" />
        </inertial>
        <visual>
            <origin xyz="0.14013684325487746 0 0.15449969263649543" rpy="0 0 0"/>
            <geometry>
                <box size="0.2802736865097549 0.005673569892215347 0.30899938527299087" />
            </geometry>
            <material name="Blue">
                <color rgba="0 0.0 1.0 1.0"/>
            </material>
        </visual>
        <collision>
            <origin xyz="0.14013684325487746 0 0.15449969263649543" rpy="0 0 0"/>
            <geometry>
                <box size="0.2802736865097549 0.005673569892215347 0.30899938527299087" />
            </geometry>
        </collision>
    </link>
</robot>