<robot name = "robot">
    <link name="Link0">
        <inertial>
            <origin xyz="0 0 2.037812875701486" rpy="0 0 0"/>
            <mass value="1" />
            <inertia ixx="100" ixy="0" ixz="0" iyy="100" iyz="0" izz="100" />
        </inertial>
        <visual>
            <origin xyz="0 0 2.037812875701486" rpy="0 0 0"/>
            <geometry>
                <box size="0.4536629450300169 0.6053568733124836 0.07562575140297201" />
            </geometry>
            <material name="Green">
                <color rgba="0 1.0 0.0 1.0"/>
            </material>
        </visual>
        <collision>
            <origin xyz="0 0 2.037812875701486" rpy="0 0 0"/>
            <geometry>
                <box size="0.4536629450300169 0.6053568733124836 0.07562575140297201" />
            </geometry>
        </collision>
    </link>
    <joint name="Link0_Link1" type="revolute">
       <parent link="Link0"/>
       <child  link="Link1"/>
       <origin rpy="0 0 0" xyz="0 0.3026784366562418 2.075625751402972" />
     <axis xyz="1 0 0"/>
       <limit effort="0.0" lower="-3.14159" upper="3.14159" velocity="0.0"/>
    </joint>
    <link name="Link1">
        <inertial>
            <origin xyz="0 0.3026784366562418 -0.037812875701486004" rpy="0 0 0"/>
            <mass value="1" />
            <inertia ixx="100" ixy="0" ixz="0" iyy="100" iyz="0" izz="100" />
        </inertial>
        <visual>
            <origin xyz="0 0.3026784366562418 -0.037812875701486004" rpy="0 0 0"/>
            <geometry>
                <box size="0.4536629450300169 0.6053568733124836 0.07562575140297201" />
            </geometry>
            <material name="Green">
                <color rgba="0 1.0 0.0 1.0"/>
            </material>
        </visual>
        <collision>
            <origin xyz="0 0.3026784366562418 -0.037812875701486004" rpy="0 0 0"/>
            <geometry>
                <box size="0.4536629450300169 0.6053568733124836 0.07562575140297201" />
            </geometry>
        </collision>
    </link>
    <joint name="Link1_Link2" type="revolute">
       <parent link="Link1"/>
       <child  link="Link2"/>
       <origin rpy="0 0 0" xyz="0 0.0 0.0" />
     <axis xyz="1 0 0"/>
       <limit effort="0.0" lower="-3.14159" upper="3.14159" velocity="0.0"/>
    </joint>
    <link name="Link2">
        <inertial>
            <origin xyz="0 -0.0695281253122274 0.16727385428629798" rpy="0 0 0"/>
            <mass value="1" />
            <inertia ixx="100" ixy="0" ixz="0" iyy="100" iyz="0" izz="100" />
        </inertial>
        <visual>
            <origin xyz="0 -0.0695281253122274 0.16727385428629798" rpy="0 0 0"/>
            <geometry>
                <box size="0.3474753108022841 0.1390562506244548 0.33454770857259597" />
            </geometry>
            <material name="Blue">
                <color rgba="0 0.0 1.0 1.0"/>
            </material>
        </visual>
        <collision>
            <origin xyz="0 -0.0695281253122274 0.16727385428629798" rpy="0 0 0"/>
            <geometry>
                <box size="0.3474753108022841 0.1390562506244548 0.33454770857259597" />
            </geometry>
        </collision>
    </link>
    <joint name="Link2_Link3" type="revolute">
       <parent link="Link2"/>
       <child  link="Link3"/>
       <origin rpy="0 0 0" xyz="-0.17373765540114205 -0.0695281253122274 0.33454770857259597" />
     <axis xyz="0 1 0"/>
       <limit effort="0.0" lower="-3.14159" upper="3.14159" velocity="0.0"/>
    </joint>
    <link name="Link3">
        <inertial>
            <origin xyz="-0.12602452048014323 0 0.134131451156576" rpy="0 0 0"/>
            <mass value="1" />
            <inertia ixx="100" ixy="0" ixz="0" iyy="100" iyz="0" izz="100" />
        </inertial>
        <visual>
            <origin xyz="-0.12602452048014323 0 0.134131451156576" rpy="0 0 0"/>
            <geometry>
                <box size="0.25204904096028646 0.3116140862147053 0.268262902313152" />
            </geometry>
            <material name="Green">
                <color rgba="0 1.0 0.0 1.0"/>
            </material>
        </visual>
        <collision>
            <origin xyz="-0.12602452048014323 0 0.134131451156576" rpy="0 0 0"/>
            <geometry>
                <box size="0.25204904096028646 0.3116140862147053 0.268262902313152" />
            </geometry>
        </collision>
    </link>
    <joint name="Link3_Link4" type="revolute">
       <parent link="Link3"/>
       <child  link="Link4"/>
       <origin rpy="0 0 0" xyz="-0.12602452048014323 -0.15580704310735266 0.268262902313152" />
     <axis xyz="1 0 0"/>
       <limit effort="0.0" lower="-3.14159" upper="3.14159" velocity="0.0"/>
    </joint>
    <link name="Link4">
        <inertial>
            <origin xyz="0 -0.22544655349982828 -0.28973844086283895" rpy="0 0 0"/>
            <mass value="1" />
            <inertia ixx="100" ixy="0" ixz="0" iyy="100" iyz="0" izz="100" />
        </inertial>
        <visual>
            <origin xyz="0 -0.22544655349982828 -0.28973844086283895" rpy="0 0 0"/>
            <geometry>
                <box size="0.536726835223305 0.45089310699965657 0.5794768817256779" />
            </geometry>
            <material name="Blue">
                <color rgba="0 0.0 1.0 1.0"/>
            </material>
        </visual>
        <collision>
            <origin xyz="0 -0.22544655349982828 -0.28973844086283895" rpy="0 0 0"/>
            <geometry>
                <box size="0.536726835223305 0.45089310699965657 0.5794768817256779" />
            </geometry>
        </collision>
    </link>
    <joint name="Link4_Link5" type="revolute">
       <parent link="Link4"/>
       <child  link="Link5"/>
       <origin rpy="0 0 0" xyz="-0.2683634176116525 -0.22544655349982828 0.0" />
     <axis xyz="0 1 0"/>
       <limit effort="0.0" lower="-3.14159" upper="3.14159" velocity="0.0"/>
    </joint>
    <link name="Link5">
        <inertial>
            <origin xyz="-0.4581198916089911 0 0.4358480437724046" rpy="0 0 0"/>
            <mass value="1" />
            <inertia ixx="100" ixy="0" ixz="0" iyy="100" iyz="0" izz="100" />
        </inertial>
        <visual>
            <origin xyz="-0.4581198916089911 0 0.4358480437724046" rpy="0 0 0"/>
            <geometry>
                <box size="0.9162397832179822 0.6910227289053659 0.8716960875448092" />
            </geometry>
            <material name="Blue">
                <color rgba="0 0.0 1.0 1.0"/>
            </material>
        </visual>
        <collision>
            <origin xyz="-0.4581198916089911 0 0.4358480437724046" rpy="0 0 0"/>
            <geometry>
                <box size="0.9162397832179822 0.6910227289053659 0.8716960875448092" />
            </geometry>
        </collision>
    </link>
    <joint name="Link5_Link6" type="revolute">
       <parent link="Link5"/>
       <child  link="Link6"/>
       <origin rpy="0 0 0" xyz="-0.9162397832179822 0 0.8716960875448092" />
     <axis xyz="0 1 0"/>
       <limit effort="0.0" lower="-3.14159" upper="3.14159" velocity="0.0"/>
    </joint>
    <link name="Link6">
        <inertial>
            <origin xyz="-0.08337506772634962 0 0.1720178698818738" rpy="0 0 0"/>
            <mass value="1" />
            <inertia ixx="100" ixy="0" ixz="0" iyy="100" iyz="0" izz="100" />
        </inertial>
        <visual>
            <origin xyz="-0.08337506772634962 0 0.1720178698818738" rpy="0 0 0"/>
            <geometry>
                <box size="0.16675013545269923 0.7363690903897002 0.3440357397637476" />
            </geometry>
            <material name="Blue">
                <color rgba="0 0.0 1.0 1.0"/>
            </material>
        </visual>
        <collision>
            <origin xyz="-0.08337506772634962 0 0.1720178698818738" rpy="0 0 0"/>
            <geometry>
                <box size="0.16675013545269923 0.7363690903897002 0.3440357397637476" />
            </geometry>
        </collision>
    </link>
</robot>