<robot name = "robot">
    <link name="Link0">
        <inertial>
            <origin xyz="0 0 2.4082171138419017" rpy="0 0 0"/>
            <mass value="1" />
            <inertia ixx="100" ixy="0" ixz="0" iyy="100" iyz="0" izz="100" />
        </inertial>
        <visual>
            <origin xyz="0 0 2.4082171138419017" rpy="0 0 0"/>
            <geometry>
                <box size="0.9822243247071613 0.2978227181696931 0.8164342276838032" />
            </geometry>
            <material name="Green">
                <color rgba="0 1.0 0.0 1.0"/>
            </material>
        </visual>
        <collision>
            <origin xyz="0 0 2.4082171138419017" rpy="0 0 0"/>
            <geometry>
                <box size="0.9822243247071613 0.2978227181696931 0.8164342276838032" />
            </geometry>
        </collision>
    </link>
    <joint name="Link0_Link1" type="revolute">
       <parent link="Link0"/>
       <child  link="Link1"/>
       <origin rpy="0 0 0" xyz="0 0.14891135908484654 2.8164342276838035" />
     <axis xyz="1 0 0"/>
       <limit effort="0.0" lower="-3.14159" upper="3.14159" velocity="0.0"/>
    </joint>
    <link name="Link1">
        <inertial>
            <origin xyz="0 0.14891135908484654 -0.4082171138419016" rpy="0 0 0"/>
            <mass value="1" />
            <inertia ixx="100" ixy="0" ixz="0" iyy="100" iyz="0" izz="100" />
        </inertial>
        <visual>
            <origin xyz="0 0.14891135908484654 -0.4082171138419016" rpy="0 0 0"/>
            <geometry>
                <box size="0.9822243247071613 0.2978227181696931 0.8164342276838032" />
            </geometry>
            <material name="Green">
                <color rgba="0 1.0 0.0 1.0"/>
            </material>
        </visual>
        <collision>
            <origin xyz="0 0.14891135908484654 -0.4082171138419016" rpy="0 0 0"/>
            <geometry>
                <box size="0.9822243247071613 0.2978227181696931 0.8164342276838032" />
            </geometry>
        </collision>
    </link>
    <joint name="Link1_Link2" type="revolute">
       <parent link="Link1"/>
       <child  link="Link2"/>
       <origin rpy="0 0 0" xyz="0 0.2978227181696931 0.0" />
     <axis xyz="1 0 0"/>
       <limit effort="0.0" lower="-3.14159" upper="3.14159" velocity="0.0"/>
    </joint>
    <link name="Link2">
        <inertial>
            <origin xyz="0 0.4059150164558232 -0.22518511568789362" rpy="0 0 0"/>
            <mass value="1" />
            <inertia ixx="100" ixy="0" ixz="0" iyy="100" iyz="0" izz="100" />
        </inertial>
        <visual>
            <origin xyz="0 0.4059150164558232 -0.22518511568789362" rpy="0 0 0"/>
            <geometry>
                <box size="0.038162742879427336 0.8118300329116463 0.45037023137578724" />
            </geometry>
            <material name="Blue">
                <color rgba="0 0.0 1.0 1.0"/>
            </material>
        </visual>
        <collision>
            <origin xyz="0 0.4059150164558232 -0.22518511568789362" rpy="0 0 0"/>
            <geometry>
                <box size="0.038162742879427336 0.8118300329116463 0.45037023137578724" />
            </geometry>
        </collision>
    </link>
    <joint name="Link2_Link3" type="revolute">
       <parent link="Link2"/>
       <child  link="Link3"/>
       <origin rpy="0 0 0" xyz="0 0.0 0.0" />
     <axis xyz="1 0 0"/>
       <limit effort="0.0" lower="-3.14159" upper="3.14159" velocity="0.0"/>
    </joint>
    <link name="Link3">
        <inertial>
            <origin xyz="0 -0.23667549627389245 0.16036278059641446" rpy="0 0 0"/>
            <mass value="1" />
            <inertia ixx="100" ixy="0" ixz="0" iyy="100" iyz="0" izz="100" />
        </inertial>
        <visual>
            <origin xyz="0 -0.23667549627389245 0.16036278059641446" rpy="0 0 0"/>
            <geometry>
                <box size="0.21975066888848482 0.4733509925477849 0.3207255611928289" />
            </geometry>
            <material name="Blue">
                <color rgba="0 0.0 1.0 1.0"/>
            </material>
        </visual>
        <collision>
            <origin xyz="0 -0.23667549627389245 0.16036278059641446" rpy="0 0 0"/>
            <geometry>
                <box size="0.21975066888848482 0.4733509925477849 0.3207255611928289" />
            </geometry>
        </collision>
    </link>
    <joint name="Link3_Link4" type="revolute">
       <parent link="Link3"/>
       <child  link="Link4"/>
       <origin rpy="0 0 0" xyz="-0.10987533444424241 -0.23667549627389245 0.3207255611928289" />
     <axis xyz="0 1 0"/>
       <limit effort="0.0" lower="-3.14159" upper="3.14159" velocity="0.0"/>
    </joint>
    <link name="Link4">
        <inertial>
            <origin xyz="-0.45112318389726064 0 0.06067497719310522" rpy="0 0 0"/>
            <mass value="1" />
            <inertia ixx="100" ixy="0" ixz="0" iyy="100" iyz="0" izz="100" />
        </inertial>
        <visual>
            <origin xyz="-0.45112318389726064 0 0.06067497719310522" rpy="0 0 0"/>
            <geometry>
                <box size="0.9022463677945213 0.4021356044651444 0.12134995438621043" />
            </geometry>
            <material name="Blue">
                <color rgba="0 0.0 1.0 1.0"/>
            </material>
        </visual>
        <collision>
            <origin xyz="-0.45112318389726064 0 0.06067497719310522" rpy="0 0 0"/>
            <geometry>
                <box size="0.9022463677945213 0.4021356044651444 0.12134995438621043" />
            </geometry>
        </collision>
    </link>
    <joint name="Link4_Link5" type="revolute">
       <parent link="Link4"/>
       <child  link="Link5"/>
       <origin rpy="0 0 0" xyz="-0.45112318389726064 -0.2010678022325722 0.12134995438621043" />
     <axis xyz="1 0 0"/>
       <limit effort="0.0" lower="-3.14159" upper="3.14159" velocity="0.0"/>
    </joint>
    <link name="Link5">
        <inertial>
            <origin xyz="0 -0.18347082959966232 0.179295495514124" rpy="0 0 0"/>
            <mass value="1" />
            <inertia ixx="100" ixy="0" ixz="0" iyy="100" iyz="0" izz="100" />
        </inertial>
        <visual>
            <origin xyz="0 -0.18347082959966232 0.179295495514124" rpy="0 0 0"/>
            <geometry>
                <box size="0.9198870937241471 0.36694165919932464 0.358590991028248" />
            </geometry>
            <material name="Green">
                <color rgba="0 1.0 0.0 1.0"/>
            </material>
        </visual>
        <collision>
            <origin xyz="0 -0.18347082959966232 0.179295495514124" rpy="0 0 0"/>
            <geometry>
                <box size="0.9198870937241471 0.36694165919932464 0.358590991028248" />
            </geometry>
        </collision>
    </link>
    <joint name="Link5_Link6" type="revolute">
       <parent link="Link5"/>
       <child  link="Link6"/>
       <origin rpy="0 0 0" xyz="-0.45994354686207356 -0.18347082959966232 0.358590991028248" />
     <axis xyz="0 1 0"/>
       <limit effort="0.0" lower="-3.14159" upper="3.14159" velocity="0.0"/>
    </joint>
    <link name="Link6">
        <inertial>
            <origin xyz="-0.37807227709676694 0 -0.48258179405110535" rpy="0 0 0"/>
            <mass value="1" />
            <inertia ixx="100" ixy="0" ixz="0" iyy="100" iyz="0" izz="100" />
        </inertial>
        <visual>
            <origin xyz="-0.37807227709676694 0 -0.48258179405110535" rpy="0 0 0"/>
            <geometry>
                <box size="0.7561445541935339 0.7277780633903324 0.9651635881022107" />
            </geometry>
            <material name="Blue">
                <color rgba="0 0.0 1.0 1.0"/>
            </material>
        </visual>
        <collision>
            <origin xyz="-0.37807227709676694 0 -0.48258179405110535" rpy="0 0 0"/>
            <geometry>
                <box size="0.7561445541935339 0.7277780633903324 0.9651635881022107" />
            </geometry>
        </collision>
    </link>
</robot>