<robot name = "robot">
    <link name="Link0">
        <inertial>
            <origin xyz="0 0 2.2445247332374128" rpy="0 0 0"/>
            <mass value="1" />
            <inertia ixx="100" ixy="0" ixz="0" iyy="100" iyz="0" izz="100" />
        </inertial>
        <visual>
            <origin xyz="0 0 2.2445247332374128" rpy="0 0 0"/>
            <geometry>
                <box size="0.3618852574569261 0.2830986365294319 0.48904946647482517" />
            </geometry>
            <material name="Green">
                <color rgba="0 1.0 0.0 1.0"/>
            </material>
        </visual>
        <collision>
            <origin xyz="0 0 2.2445247332374128" rpy="0 0 0"/>
            <geometry>
                <box size="0.3618852574569261 0.2830986365294319 0.48904946647482517" />
            </geometry>
        </collision>
    </link>
    <joint name="Link0_Link1" type="revolute">
       <parent link="Link0"/>
       <child  link="Link1"/>
       <origin rpy="0 0 0" xyz="0 0.14154931826471595 2.489049466474825" />
     <axis xyz="1 0 0"/>
       <limit effort="0.0" lower="-3.14159" upper="3.14159" velocity="0.0"/>
    </joint>
    <link name="Link1">
        <inertial>
            <origin xyz="0 0.14154931826471595 -0.24452473323741258" rpy="0 0 0"/>
            <mass value="1" />
            <inertia ixx="100" ixy="0" ixz="0" iyy="100" iyz="0" izz="100" />
        </inertial>
        <visual>
            <origin xyz="0 0.14154931826471595 -0.24452473323741258" rpy="0 0 0"/>
            <geometry>
                <box size="0.3618852574569261 0.2830986365294319 0.48904946647482517" />
            </geometry>
            <material name="Green">
                <color rgba="0 1.0 0.0 1.0"/>
            </material>
        </visual>
        <collision>
            <origin xyz="0 0.14154931826471595 -0.24452473323741258" rpy="0 0 0"/>
            <geometry>
                <box size="0.3618852574569261 0.2830986365294319 0.48904946647482517" />
            </geometry>
        </collision>
    </link>
    <joint name="Link1_Link2" type="revolute">
       <parent link="Link1"/>
       <child  link="Link2"/>
       <origin rpy="0 0 0" xyz="0 0.0 0.0" />
     <axis xyz="1 0 0"/>
       <limit effort="0.0" lower="-3.14159" upper="3.14159" velocity="0.0"/>
    </joint>
    <link name="Link2">
        <inertial>
            <origin xyz="0 -0.233595218565822 0.029719216820225325" rpy="0 0 0"/>
            <mass value="1" />
            <inertia ixx="100" ixy="0" ixz="0" iyy="100" iyz="0" izz="100" />
        </inertial>
        <visual>
            <origin xyz="0 -0.233595218565822 0.029719216820225325" rpy="0 0 0"/>
            <geometry>
                <box size="0.7841626026898905 0.467190437131644 0.05943843364045065" />
            </geometry>
            <material name="Blue">
                <color rgba="0 0.0 1.0 1.0"/>
            </material>
        </visual>
        <collision>
            <origin xyz="0 -0.233595218565822 0.029719216820225325" rpy="0 0 0"/>
            <geometry>
                <box size="0.7841626026898905 0.467190437131644 0.05943843364045065" />
            </geometry>
        </collision>
    </link>
    <joint name="Link2_Link3" type="revolute">
       <parent link="Link2"/>
       <child  link="Link3"/>
       <origin rpy="0 0 0" xyz="0 0.0 0.05943843364045065" />
     <axis xyz="1 0 0"/>
       <limit effort="0.0" lower="-3.14159" upper="3.14159" velocity="0.0"/>
    </joint>
    <link name="Link3">
        <inertial>
            <origin xyz="0 0.4134288137905666 -0.23006713968557596" rpy="0 0 0"/>
            <mass value="1" />
            <inertia ixx="100" ixy="0" ixz="0" iyy="100" iyz="0" izz="100" />
        </inertial>
        <visual>
            <origin xyz="0 0.4134288137905666 -0.23006713968557596" rpy="0 0 0"/>
            <geometry>
                <box size="0.540278502377274 0.8268576275811332 0.4601342793711519" />
            </geometry>
            <material name="Blue">
                <color rgba="0 0.0 1.0 1.0"/>
            </material>
        </visual>
        <collision>
            <origin xyz="0 0.4134288137905666 -0.23006713968557596" rpy="0 0 0"/>
            <geometry>
                <box size="0.540278502377274 0.8268576275811332 0.4601342793711519" />
            </geometry>
        </collision>
    </link>
    <joint name="Link3_Link4" type="revolute">
       <parent link="Link3"/>
       <child  link="Link4"/>
       <origin rpy="0 0 0" xyz="0.270139251188637 0.4134288137905666 0.0" />
     <axis xyz="0 1 0"/>
       <limit effort="0.0" lower="-3.14159" upper="3.14159" velocity="0.0"/>
    </joint>
    <link name="Link4">
        <inertial>
            <origin xyz="0.40433459715855696 0 0.19448736602459676" rpy="0 0 0"/>
            <mass value="1" />
            <inertia ixx="100" ixy="0" ixz="0" iyy="100" iyz="0" izz="100" />
        </inertial>
        <visual>
            <origin xyz="0.40433459715855696 0 0.19448736602459676" rpy="0 0 0"/>
            <geometry>
                <box size="0.8086691943171139 0.464167941190032 0.38897473204919353" />
            </geometry>
            <material name="Green">
                <color rgba="0 1.0 0.0 1.0"/>
            </material>
        </visual>
        <collision>
            <origin xyz="0.40433459715855696 0 0.19448736602459676" rpy="0 0 0"/>
            <geometry>
                <box size="0.8086691943171139 0.464167941190032 0.38897473204919353" />
            </geometry>
        </collision>
    </link>
</robot>