<robot name = "robot">
    <link name="Link0">
        <inertial>
            <origin xyz="0 0 2.175929098587537" rpy="0 0 0"/>
            <mass value="1" />
            <inertia ixx="100" ixy="0" ixz="0" iyy="100" iyz="0" izz="100" />
        </inertial>
        <visual>
            <origin xyz="0 0 2.175929098587537" rpy="0 0 0"/>
            <geometry>
                <box size="0.05551304259695178 0.9975625140805421 0.3518581971750733" />
            </geometry>
            <material name="Green">
                <color rgba="0 1.0 0.0 1.0"/>
            </material>
        </visual>
        <collision>
            <origin xyz="0 0 2.175929098587537" rpy="0 0 0"/>
            <geometry>
                <box size="0.05551304259695178 0.9975625140805421 0.3518581971750733" />
            </geometry>
        </collision>
    </link>
    <joint name="Link0_Link1" type="revolute">
       <parent link="Link0"/>
       <child  link="Link1"/>
       <origin rpy="0 0 0" xyz="0 0.49878125704027104 2.351858197175073" />
     <axis xyz="1 0 0"/>
       <limit effort="0.0" lower="-3.14159" upper="3.14159" velocity="0.0"/>
    </joint>
    <link name="Link1">
        <inertial>
            <origin xyz="0 0.49878125704027104 -0.17592909858753664" rpy="0 0 0"/>
            <mass value="1" />
            <inertia ixx="100" ixy="0" ixz="0" iyy="100" iyz="0" izz="100" />
        </inertial>
        <visual>
            <origin xyz="0 0.49878125704027104 -0.17592909858753664" rpy="0 0 0"/>
            <geometry>
                <box size="0.05551304259695178 0.9975625140805421 0.3518581971750733" />
            </geometry>
            <material name="Green">
                <color rgba="0 1.0 0.0 1.0"/>
            </material>
        </visual>
        <collision>
            <origin xyz="0 0.49878125704027104 -0.17592909858753664" rpy="0 0 0"/>
            <geometry>
                <box size="0.05551304259695178 0.9975625140805421 0.3518581971750733" />
            </geometry>
        </collision>
    </link>
    <joint name="Link1_Link2" type="revolute">
       <parent link="Link1"/>
       <child  link="Link2"/>
       <origin rpy="0 0 0" xyz="-0.02775652129847589 0.49878125704027104 0.0" />
     <axis xyz="0 1 0"/>
       <limit effort="0.0" lower="-3.14159" upper="3.14159" velocity="0.0"/>
    </joint>
    <link name="Link2">
        <inertial>
            <origin xyz="-0.4720514588626735 0 0.16345586722369038" rpy="0 0 0"/>
            <mass value="1" />
            <inertia ixx="100" ixy="0" ixz="0" iyy="100" iyz="0" izz="100" />
        </inertial>
        <visual>
            <origin xyz="-0.4720514588626735 0 0.16345586722369038" rpy="0 0 0"/>
            <geometry>
                <box size="0.944102917725347 0.9039009659694756 0.32691173444738075" />
            </geometry>
            <material name="Blue">
                <color rgba="0 0.0 1.0 1.0"/>
            </material>
        </visual>
        <collision>
            <origin xyz="-0.4720514588626735 0 0.16345586722369038" rpy="0 0 0"/>
            <geometry>
                <box size="0.944102917725347 0.9039009659694756 0.32691173444738075" />
            </geometry>
        </collision>
    </link>
    <joint name="Link2_Link3" type="revolute">
       <parent link="Link2"/>
       <child  link="Link3"/>
       <origin rpy="0 0 0" xyz="-0.944102917725347 0 0.32691173444738075" />
     <axis xyz="0 1 0"/>
       <limit effort="0.0" lower="-3.14159" upper="3.14159" velocity="0.0"/>
    </joint>
    <link name="Link3">
        <inertial>
            <origin xyz="-0.46877373010074486 0 0.4871174867834486" rpy="0 0 0"/>
            <mass value="1" />
            <inertia ixx="100" ixy="0" ixz="0" iyy="100" iyz="0" izz="100" />
        </inertial>
        <visual>
            <origin xyz="-0.46877373010074486 0 0.4871174867834486" rpy="0 0 0"/>
            <geometry>
                <box size="0.9375474602014897 0.16257171039376084 0.9742349735668973" />
            </geometry>
            <material name="Blue">
                <color rgba="0 0.0 1.0 1.0"/>
            </material>
        </visual>
        <collision>
            <origin xyz="-0.46877373010074486 0 0.4871174867834486" rpy="0 0 0"/>
            <geometry>
                <box size="0.9375474602014897 0.16257171039376084 0.9742349735668973" />
            </geometry>
        </collision>
    </link>
    <joint name="Link3_Link4" type="revolute">
       <parent link="Link3"/>
       <child  link="Link4"/>
       <origin rpy="0 0 0" xyz="-0.46877373010074486 -0.08128585519688042 0.9742349735668973" />
     <axis xyz="1 0 0"/>
       <limit effort="0.0" lower="-3.14159" upper="3.14159" velocity="0.0"/>
    </joint>
    <link name="Link4">
        <inertial>
            <origin xyz="0 -0.37559776574613785 0.48124881489068644" rpy="0 0 0"/>
            <mass value="1" />
            <inertia ixx="100" ixy="0" ixz="0" iyy="100" iyz="0" izz="100" />
        </inertial>
        <visual>
            <origin xyz="0 -0.37559776574613785 0.48124881489068644" rpy="0 0 0"/>
            <geometry>
                <box size="0.001833029015225196 0.7511955314922757 0.9624976297813729" />
            </geometry>
            <material name="Blue">
                <color rgba="0 0.0 1.0 1.0"/>
            </material>
        </visual>
        <collision>
            <origin xyz="0 -0.37559776574613785 0.48124881489068644" rpy="0 0 0"/>
            <geometry>
                <box size="0.001833029015225196 0.7511955314922757 0.9624976297813729" />
            </geometry>
        </collision>
    </link>
    <joint name="Link4_Link5" type="revolute">
       <parent link="Link4"/>
       <child  link="Link5"/>
       <origin rpy="0 0 0" xyz="0 -0.7511955314922757 0.9624976297813729" />
     <axis xyz="1 0 0"/>
       <limit effort="0.0" lower="-3.14159" upper="3.14159" velocity="0.0"/>
    </joint>
    <link name="Link5">
        <inertial>
            <origin xyz="0 -0.012707276635577469 -0.44039981312999055" rpy="0 0 0"/>
            <mass value="1" />
            <inertia ixx="100" ixy="0" ixz="0" iyy="100" iyz="0" izz="100" />
        </inertial>
        <visual>
            <origin xyz="0 -0.012707276635577469 -0.44039981312999055" rpy="0 0 0"/>
            <geometry>
                <box size="0.8102113522789366 0.025414553271154938 0.8807996262599811" />
            </geometry>
            <material name="Blue">
                <color rgba="0 0.0 1.0 1.0"/>
            </material>
        </visual>
        <collision>
            <origin xyz="0 -0.012707276635577469 -0.44039981312999055" rpy="0 0 0"/>
            <geometry>
                <box size="0.8102113522789366 0.025414553271154938 0.8807996262599811" />
            </geometry>
        </collision>
    </link>
    <joint name="Link5_Link6" type="revolute">
       <parent link="Link5"/>
       <child  link="Link6"/>
       <origin rpy="0 0 0" xyz="0 -0.025414553271154938 0.0" />
     <axis xyz="1 0 0"/>
       <limit effort="0.0" lower="-3.14159" upper="3.14159" velocity="0.0"/>
    </joint>
    <link name="Link6">
        <inertial>
            <origin xyz="0 -0.04453075944896845 0.0435298735026215" rpy="0 0 0"/>
            <mass value="1" />
            <inertia ixx="100" ixy="0" ixz="0" iyy="100" iyz="0" izz="100" />
        </inertial>
        <visual>
            <origin xyz="0 -0.04453075944896845 0.0435298735026215" rpy="0 0 0"/>
            <geometry>
                <box size="0.08770790251377991 0.0890615188979369 0.087059747005243" />
            </geometry>
            <material name="Blue">
                <color rgba="0 0.0 1.0 1.0"/>
            </material>
        </visual>
        <collision>
            <origin xyz="0 -0.04453075944896845 0.0435298735026215" rpy="0 0 0"/>
            <geometry>
                <box size="0.08770790251377991 0.0890615188979369 0.087059747005243" />
            </geometry>
        </collision>
    </link>
</robot>