<robot name = "robot">
    <link name="Link0">
        <inertial>
            <origin xyz="0 0 2.448848061453046" rpy="0 0 0"/>
            <mass value="1" />
            <inertia ixx="100" ixy="0" ixz="0" iyy="100" iyz="0" izz="100" />
        </inertial>
        <visual>
            <origin xyz="0 0 2.448848061453046" rpy="0 0 0"/>
            <geometry>
                <box size="0.018287259654394927 0.44536533152606483 0.8976961229060927" />
            </geometry>
            <material name="Green">
                <color rgba="0 1.0 0.0 1.0"/>
            </material>
        </visual>
        <collision>
            <origin xyz="0 0 2.448848061453046" rpy="0 0 0"/>
            <geometry>
                <box size="0.018287259654394927 0.44536533152606483 0.8976961229060927" />
            </geometry>
        </collision>
    </link>
    <joint name="Link0_Link1" type="revolute">
       <parent link="Link0"/>
       <child  link="Link1"/>
       <origin rpy="0 0 0" xyz="0 0.22268266576303242 2.8976961229060927" />
     <axis xyz="1 0 0"/>
       <limit effort="0.0" lower="-3.14159" upper="3.14159" velocity="0.0"/>
    </joint>
    <link name="Link1">
        <inertial>
            <origin xyz="0 0.22268266576303242 -0.44884806145304634" rpy="0 0 0"/>
            <mass value="1" />
            <inertia ixx="100" ixy="0" ixz="0" iyy="100" iyz="0" izz="100" />
        </inertial>
        <visual>
            <origin xyz="0 0.22268266576303242 -0.44884806145304634" rpy="0 0 0"/>
            <geometry>
                <box size="0.018287259654394927 0.44536533152606483 0.8976961229060927" />
            </geometry>
            <material name="Blue">
                <color rgba="0 0.0 1.0 1.0"/>
            </material>
        </visual>
        <collision>
            <origin xyz="0 0.22268266576303242 -0.44884806145304634" rpy="0 0 0"/>
            <geometry>
                <box size="0.018287259654394927 0.44536533152606483 0.8976961229060927" />
            </geometry>
        </collision>
    </link>
    <joint name="Link1_Link2" type="revolute">
       <parent link="Link1"/>
       <child  link="Link2"/>
       <origin rpy="0 0 0" xyz="-0.009143629827197464 0.22268266576303242 0.0" />
     <axis xyz="0 1 0"/>
       <limit effort="0.0" lower="-3.14159" upper="3.14159" velocity="0.0"/>
    </joint>
    <link name="Link2">
        <inertial>
            <origin xyz="-0.06219011323958051 0 -0.42760903588533444" rpy="0 0 0"/>
            <mass value="1" />
            <inertia ixx="100" ixy="0" ixz="0" iyy="100" iyz="0" izz="100" />
        </inertial>
        <visual>
            <origin xyz="-0.06219011323958051 0 -0.42760903588533444" rpy="0 0 0"/>
            <geometry>
                <box size="0.12438022647916103 0.4773990379829902 0.8552180717706689" />
            </geometry>
            <material name="Green">
                <color rgba="0 1.0 0.0 1.0"/>
            </material>
        </visual>
        <collision>
            <origin xyz="-0.06219011323958051 0 -0.42760903588533444" rpy="0 0 0"/>
            <geometry>
                <box size="0.12438022647916103 0.4773990379829902 0.8552180717706689" />
            </geometry>
        </collision>
    </link>
    <joint name="Link2_Link3" type="revolute">
       <parent link="Link2"/>
       <child  link="Link3"/>
       <origin rpy="0 0 0" xyz="-0.06219011323958051 -0.2386995189914951 0.0" />
     <axis xyz="1 0 0"/>
       <limit effort="0.0" lower="-3.14159" upper="3.14159" velocity="0.0"/>
    </joint>
    <link name="Link3">
        <inertial>
            <origin xyz="0 -0.03055973735344031 -0.4047573143521" rpy="0 0 0"/>
            <mass value="1" />
            <inertia ixx="100" ixy="0" ixz="0" iyy="100" iyz="0" izz="100" />
        </inertial>
        <visual>
            <origin xyz="0 -0.03055973735344031 -0.4047573143521" rpy="0 0 0"/>
            <geometry>
                <box size="0.18743171313499118 0.06111947470688062 0.8095146287042" />
            </geometry>
            <material name="Green">
                <color rgba="0 1.0 0.0 1.0"/>
            </material>
        </visual>
        <collision>
            <origin xyz="0 -0.03055973735344031 -0.4047573143521" rpy="0 0 0"/>
            <geometry>
                <box size="0.18743171313499118 0.06111947470688062 0.8095146287042" />
            </geometry>
        </collision>
    </link>
    <joint name="Link3_Link4" type="revolute">
       <parent link="Link3"/>
       <child  link="Link4"/>
       <origin rpy="0 0 0" xyz="-0.09371585656749559 -0.03055973735344031 0.0" />
     <axis xyz="0 1 0"/>
       <limit effort="0.0" lower="-3.14159" upper="3.14159" velocity="0.0"/>
    </joint>
    <link name="Link4">
        <inertial>
            <origin xyz="-0.3594124054177191 0 -0.4830752016678065" rpy="0 0 0"/>
            <mass value="1" />
            <inertia ixx="100" ixy="0" ixz="0" iyy="100" iyz="0" izz="100" />
        </inertial>
        <visual>
            <origin xyz="-0.3594124054177191 0 -0.4830752016678065" rpy="0 0 0"/>
            <geometry>
                <box size="0.7188248108354383 0.667654983102294 0.966150403335613" />
            </geometry>
            <material name="Blue">
                <color rgba="0 0.0 1.0 1.0"/>
            </material>
        </visual>
        <collision>
            <origin xyz="-0.3594124054177191 0 -0.4830752016678065" rpy="0 0 0"/>
            <geometry>
                <box size="0.7188248108354383 0.667654983102294 0.966150403335613" />
            </geometry>
        </collision>
    </link>
</robot>