<robot name = "robot">
    <link name="Link0">
        <inertial>
            <origin xyz="0 0 2.086765685217537" rpy="0 0 0"/>
            <mass value="1" />
            <inertia ixx="100" ixy="0" ixz="0" iyy="100" iyz="0" izz="100" />
        </inertial>
        <visual>
            <origin xyz="0 0 2.086765685217537" rpy="0 0 0"/>
            <geometry>
                <box size="0.835923184608185 0.10421173318463595 0.17353137043507416" />
            </geometry>
            <material name="Green">
                <color rgba="0 1.0 0.0 1.0"/>
            </material>
        </visual>
        <collision>
            <origin xyz="0 0 2.086765685217537" rpy="0 0 0"/>
            <geometry>
                <box size="0.835923184608185 0.10421173318463595 0.17353137043507416" />
            </geometry>
        </collision>
    </link>
    <joint name="Link0_Link1" type="revolute">
       <parent link="Link0"/>
       <child  link="Link1"/>
       <origin rpy="0 0 0" xyz="0 0.05210586659231797 2.1735313704350743" />
     <axis xyz="1 0 0"/>
       <limit effort="0.0" lower="-3.14159" upper="3.14159" velocity="0.0"/>
    </joint>
    <link name="Link1">
        <inertial>
            <origin xyz="0 0.05210586659231797 -0.08676568521753708" rpy="0 0 0"/>
            <mass value="1" />
            <inertia ixx="100" ixy="0" ixz="0" iyy="100" iyz="0" izz="100" />
        </inertial>
        <visual>
            <origin xyz="0 0.05210586659231797 -0.08676568521753708" rpy="0 0 0"/>
            <geometry>
                <box size="0.835923184608185 0.10421173318463595 0.17353137043507416" />
            </geometry>
            <material name="Green">
                <color rgba="0 1.0 0.0 1.0"/>
            </material>
        </visual>
        <collision>
            <origin xyz="0 0.05210586659231797 -0.08676568521753708" rpy="0 0 0"/>
            <geometry>
                <box size="0.835923184608185 0.10421173318463595 0.17353137043507416" />
            </geometry>
        </collision>
    </link>
    <joint name="Link1_Link2" type="revolute">
       <parent link="Link1"/>
       <child  link="Link2"/>
       <origin rpy="0 0 0" xyz="0 0.10421173318463595 0.0" />
     <axis xyz="1 0 0"/>
       <limit effort="0.0" lower="-3.14159" upper="3.14159" velocity="0.0"/>
    </joint>
    <link name="Link2">
        <inertial>
            <origin xyz="0 0.15750823590529617 0.3727611334129598" rpy="0 0 0"/>
            <mass value="1" />
            <inertia ixx="100" ixy="0" ixz="0" iyy="100" iyz="0" izz="100" />
        </inertial>
        <visual>
            <origin xyz="0 0.15750823590529617 0.3727611334129598" rpy="0 0 0"/>
            <geometry>
                <box size="0.46418458093066783 0.31501647181059234 0.7455222668259196" />
            </geometry>
            <material name="Blue">
                <color rgba="0 0.0 1.0 1.0"/>
            </material>
        </visual>
        <collision>
            <origin xyz="0 0.15750823590529617 0.3727611334129598" rpy="0 0 0"/>
            <geometry>
                <box size="0.46418458093066783 0.31501647181059234 0.7455222668259196" />
            </geometry>
        </collision>
    </link>
    <joint name="Link2_Link3" type="revolute">
       <parent link="Link2"/>
       <child  link="Link3"/>
       <origin rpy="0 0 0" xyz="-0.23209229046533392 0.15750823590529617 0.7455222668259196" />
     <axis xyz="0 1 0"/>
       <limit effort="0.0" lower="-3.14159" upper="3.14159" velocity="0.0"/>
    </joint>
    <link name="Link3">
        <inertial>
            <origin xyz="-0.35143681282677974 0 -0.20347431008644767" rpy="0 0 0"/>
            <mass value="1" />
            <inertia ixx="100" ixy="0" ixz="0" iyy="100" iyz="0" izz="100" />
        </inertial>
        <visual>
            <origin xyz="-0.35143681282677974 0 -0.20347431008644767" rpy="0 0 0"/>
            <geometry>
                <box size="0.7028736256535595 0.07869211290048883 0.40694862017289535" />
            </geometry>
            <material name="Blue">
                <color rgba="0 0.0 1.0 1.0"/>
            </material>
        </visual>
        <collision>
            <origin xyz="-0.35143681282677974 0 -0.20347431008644767" rpy="0 0 0"/>
            <geometry>
                <box size="0.7028736256535595 0.07869211290048883 0.40694862017289535" />
            </geometry>
        </collision>
    </link>
    <joint name="Link3_Link4" type="revolute">
       <parent link="Link3"/>
       <child  link="Link4"/>
       <origin rpy="0 0 0" xyz="-0.35143681282677974 -0.039346056450244415 0.0" />
     <axis xyz="1 0 0"/>
       <limit effort="0.0" lower="-3.14159" upper="3.14159" velocity="0.0"/>
    </joint>
    <link name="Link4">
        <inertial>
            <origin xyz="0 -0.1385332974517769 0.2022705466210979" rpy="0 0 0"/>
            <mass value="1" />
            <inertia ixx="100" ixy="0" ixz="0" iyy="100" iyz="0" izz="100" />
        </inertial>
        <visual>
            <origin xyz="0 -0.1385332974517769 0.2022705466210979" rpy="0 0 0"/>
            <geometry>
                <box size="0.7851239080879652 0.2770665949035538 0.4045410932421958" />
            </geometry>
            <material name="Blue">
                <color rgba="0 0.0 1.0 1.0"/>
            </material>
        </visual>
        <collision>
            <origin xyz="0 -0.1385332974517769 0.2022705466210979" rpy="0 0 0"/>
            <geometry>
                <box size="0.7851239080879652 0.2770665949035538 0.4045410932421958" />
            </geometry>
        </collision>
    </link>
    <joint name="Link4_Link5" type="revolute">
       <parent link="Link4"/>
       <child  link="Link5"/>
       <origin rpy="0 0 0" xyz="0.3925619540439826 -0.1385332974517769 0.4045410932421958" />
     <axis xyz="0 1 0"/>
       <limit effort="0.0" lower="-3.14159" upper="3.14159" velocity="0.0"/>
    </joint>
    <link name="Link5">
        <inertial>
            <origin xyz="0.10904941470174084 0 0.07651225416768587" rpy="0 0 0"/>
            <mass value="1" />
            <inertia ixx="100" ixy="0" ixz="0" iyy="100" iyz="0" izz="100" />
        </inertial>
        <visual>
            <origin xyz="0.10904941470174084 0 0.07651225416768587" rpy="0 0 0"/>
            <geometry>
                <box size="0.2180988294034817 0.8106779450643778 0.15302450833537173" />
            </geometry>
            <material name="Green">
                <color rgba="0 1.0 0.0 1.0"/>
            </material>
        </visual>
        <collision>
            <origin xyz="0.10904941470174084 0 0.07651225416768587" rpy="0 0 0"/>
            <geometry>
                <box size="0.2180988294034817 0.8106779450643778 0.15302450833537173" />
            </geometry>
        </collision>
    </link>
</robot>