<robot name = "robot">
    <link name="Link0">
        <inertial>
            <origin xyz="0 0 2.119850022248037" rpy="0 0 0"/>
            <mass value="1" />
            <inertia ixx="100" ixy="0" ixz="0" iyy="100" iyz="0" izz="100" />
        </inertial>
        <visual>
            <origin xyz="0 0 2.119850022248037" rpy="0 0 0"/>
            <geometry>
                <box size="0.8109057581906274 0.2666359488029133 0.2397000444960743" />
            </geometry>
            <material name="Green">
                <color rgba="0 1.0 0.0 1.0"/>
            </material>
        </visual>
        <collision>
            <origin xyz="0 0 2.119850022248037" rpy="0 0 0"/>
            <geometry>
                <box size="0.8109057581906274 0.2666359488029133 0.2397000444960743" />
            </geometry>
        </collision>
    </link>
    <joint name="Link0_Link1" type="revolute">
       <parent link="Link0"/>
       <child  link="Link1"/>
       <origin rpy="0 0 0" xyz="0 0.13331797440145665 2.2397000444960744" />
     <axis xyz="1 0 0"/>
       <limit effort="0.0" lower="-3.14159" upper="3.14159" velocity="0.0"/>
    </joint>
    <link name="Link1">
        <inertial>
            <origin xyz="0 0.13331797440145665 -0.11985002224803715" rpy="0 0 0"/>
            <mass value="1" />
            <inertia ixx="100" ixy="0" ixz="0" iyy="100" iyz="0" izz="100" />
        </inertial>
        <visual>
            <origin xyz="0 0.13331797440145665 -0.11985002224803715" rpy="0 0 0"/>
            <geometry>
                <box size="0.8109057581906274 0.2666359488029133 0.2397000444960743" />
            </geometry>
            <material name="Green">
                <color rgba="0 1.0 0.0 1.0"/>
            </material>
        </visual>
        <collision>
            <origin xyz="0 0.13331797440145665 -0.11985002224803715" rpy="0 0 0"/>
            <geometry>
                <box size="0.8109057581906274 0.2666359488029133 0.2397000444960743" />
            </geometry>
        </collision>
    </link>
    <joint name="Link1_Link2" type="revolute">
       <parent link="Link1"/>
       <child  link="Link2"/>
       <origin rpy="0 0 0" xyz="0.4054528790953137 0.13331797440145665 0.0" />
     <axis xyz="0 1 0"/>
       <limit effort="0.0" lower="-3.14159" upper="3.14159" velocity="0.0"/>
    </joint>
    <link name="Link2">
        <inertial>
            <origin xyz="0.015134593843121769 0 -0.12277278869729163" rpy="0 0 0"/>
            <mass value="1" />
            <inertia ixx="100" ixy="0" ixz="0" iyy="100" iyz="0" izz="100" />
        </inertial>
        <visual>
            <origin xyz="0.015134593843121769 0 -0.12277278869729163" rpy="0 0 0"/>
            <geometry>
                <box size="0.030269187686243537 0.5817098279821804 0.24554557739458327" />
            </geometry>
            <material name="Green">
                <color rgba="0 1.0 0.0 1.0"/>
            </material>
        </visual>
        <collision>
            <origin xyz="0.015134593843121769 0 -0.12277278869729163" rpy="0 0 0"/>
            <geometry>
                <box size="0.030269187686243537 0.5817098279821804 0.24554557739458327" />
            </geometry>
        </collision>
    </link>
    <joint name="Link2_Link3" type="revolute">
       <parent link="Link2"/>
       <child  link="Link3"/>
       <origin rpy="0 0 0" xyz="0.0 0 0.0" />
     <axis xyz="0 1 0"/>
       <limit effort="0.0" lower="-3.14159" upper="3.14159" velocity="0.0"/>
    </joint>
    <link name="Link3">
        <inertial>
            <origin xyz="-0.19402139685168124 0 0.1476854080979032" rpy="0 0 0"/>
            <mass value="1" />
            <inertia ixx="100" ixy="0" ixz="0" iyy="100" iyz="0" izz="100" />
        </inertial>
        <visual>
            <origin xyz="-0.19402139685168124 0 0.1476854080979032" rpy="0 0 0"/>
            <geometry>
                <box size="0.3880427937033625 0.18970027077366358 0.2953708161958064" />
            </geometry>
            <material name="Blue">
                <color rgba="0 0.0 1.0 1.0"/>
            </material>
        </visual>
        <collision>
            <origin xyz="-0.19402139685168124 0 0.1476854080979032" rpy="0 0 0"/>
            <geometry>
                <box size="0.3880427937033625 0.18970027077366358 0.2953708161958064" />
            </geometry>
        </collision>
    </link>
    <joint name="Link3_Link4" type="revolute">
       <parent link="Link3"/>
       <child  link="Link4"/>
       <origin rpy="0 0 0" xyz="-0.3880427937033625 0 0.2953708161958064" />
     <axis xyz="0 1 0"/>
       <limit effort="0.0" lower="-3.14159" upper="3.14159" velocity="0.0"/>
    </joint>
    <link name="Link4">
        <inertial>
            <origin xyz="-0.21913504472068174 0 0.13188401012609186" rpy="0 0 0"/>
            <mass value="1" />
            <inertia ixx="100" ixy="0" ixz="0" iyy="100" iyz="0" izz="100" />
        </inertial>
        <visual>
            <origin xyz="-0.21913504472068174 0 0.13188401012609186" rpy="0 0 0"/>
            <geometry>
                <box size="0.4382700894413635 0.3577205857711472 0.2637680202521837" />
            </geometry>
            <material name="Green">
                <color rgba="0 1.0 0.0 1.0"/>
            </material>
        </visual>
        <collision>
            <origin xyz="-0.21913504472068174 0 0.13188401012609186" rpy="0 0 0"/>
            <geometry>
                <box size="0.4382700894413635 0.3577205857711472 0.2637680202521837" />
            </geometry>
        </collision>
    </link>
</robot>