<robot name = "robot">
    <link name="Link0">
        <inertial>
            <origin xyz="0 0 2.393191741827237" rpy="0 0 0"/>
            <mass value="1" />
            <inertia ixx="100" ixy="0" ixz="0" iyy="100" iyz="0" izz="100" />
        </inertial>
        <visual>
            <origin xyz="0 0 2.393191741827237" rpy="0 0 0"/>
            <geometry>
                <box size="0.9401481936092967 0.7745986494834588 0.7863834836544733" />
            </geometry>
            <material name="Green">
                <color rgba="0 1.0 0.0 1.0"/>
            </material>
        </visual>
        <collision>
            <origin xyz="0 0 2.393191741827237" rpy="0 0 0"/>
            <geometry>
                <box size="0.9401481936092967 0.7745986494834588 0.7863834836544733" />
            </geometry>
        </collision>
    </link>
    <joint name="Link0_Link1" type="revolute">
       <parent link="Link0"/>
       <child  link="Link1"/>
       <origin rpy="0 0 0" xyz="0 0.3872993247417294 2.786383483654473" />
     <axis xyz="1 0 0"/>
       <limit effort="0.0" lower="-3.14159" upper="3.14159" velocity="0.0"/>
    </joint>
    <link name="Link1">
        <inertial>
            <origin xyz="0 0.3872993247417294 -0.39319174182723665" rpy="0 0 0"/>
            <mass value="1" />
            <inertia ixx="100" ixy="0" ixz="0" iyy="100" iyz="0" izz="100" />
        </inertial>
        <visual>
            <origin xyz="0 0.3872993247417294 -0.39319174182723665" rpy="0 0 0"/>
            <geometry>
                <box size="0.9401481936092967 0.7745986494834588 0.7863834836544733" />
            </geometry>
            <material name="Blue">
                <color rgba="0 0.0 1.0 1.0"/>
            </material>
        </visual>
        <collision>
            <origin xyz="0 0.3872993247417294 -0.39319174182723665" rpy="0 0 0"/>
            <geometry>
                <box size="0.9401481936092967 0.7745986494834588 0.7863834836544733" />
            </geometry>
        </collision>
    </link>
    <joint name="Link1_Link2" type="revolute">
       <parent link="Link1"/>
       <child  link="Link2"/>
       <origin rpy="0 0 0" xyz="0 0.0 0.0" />
     <axis xyz="1 0 0"/>
       <limit effort="0.0" lower="-3.14159" upper="3.14159" velocity="0.0"/>
    </joint>
    <link name="Link2">
        <inertial>
            <origin xyz="0 -0.47866656957915066 0.2721928629924669" rpy="0 0 0"/>
            <mass value="1" />
            <inertia ixx="100" ixy="0" ixz="0" iyy="100" iyz="0" izz="100" />
        </inertial>
        <visual>
            <origin xyz="0 -0.47866656957915066 0.2721928629924669" rpy="0 0 0"/>
            <geometry>
                <box size="0.2150018549943662 0.9573331391583013 0.5443857259849338" />
            </geometry>
            <material name="Green">
                <color rgba="0 1.0 0.0 1.0"/>
            </material>
        </visual>
        <collision>
            <origin xyz="0 -0.47866656957915066 0.2721928629924669" rpy="0 0 0"/>
            <geometry>
                <box size="0.2150018549943662 0.9573331391583013 0.5443857259849338" />
            </geometry>
        </collision>
    </link>
    <joint name="Link2_Link3" type="revolute">
       <parent link="Link2"/>
       <child  link="Link3"/>
       <origin rpy="0 0 0" xyz="0 -0.9573331391583013 0.5443857259849338" />
     <axis xyz="1 0 0"/>
       <limit effort="0.0" lower="-3.14159" upper="3.14159" velocity="0.0"/>
    </joint>
    <link name="Link3">
        <inertial>
            <origin xyz="0 -0.2045767127746751 0.11128814269423398" rpy="0 0 0"/>
            <mass value="1" />
            <inertia ixx="100" ixy="0" ixz="0" iyy="100" iyz="0" izz="100" />
        </inertial>
        <visual>
            <origin xyz="0 -0.2045767127746751 0.11128814269423398" rpy="0 0 0"/>
            <geometry>
                <box size="0.516680310929067 0.4091534255493502 0.22257628538846796" />
            </geometry>
            <material name="Blue">
                <color rgba="0 0.0 1.0 1.0"/>
            </material>
        </visual>
        <collision>
            <origin xyz="0 -0.2045767127746751 0.11128814269423398" rpy="0 0 0"/>
            <geometry>
                <box size="0.516680310929067 0.4091534255493502 0.22257628538846796" />
            </geometry>
        </collision>
    </link>
    <joint name="Link3_Link4" type="revolute">
       <parent link="Link3"/>
       <child  link="Link4"/>
       <origin rpy="0 0 0" xyz="0.2583401554645335 -0.2045767127746751 0.22257628538846796" />
     <axis xyz="0 1 0"/>
       <limit effort="0.0" lower="-3.14159" upper="3.14159" velocity="0.0"/>
    </joint>
    <link name="Link4">
        <inertial>
            <origin xyz="0.19821536358270664 0 -0.22725049778152773" rpy="0 0 0"/>
            <mass value="1" />
            <inertia ixx="100" ixy="0" ixz="0" iyy="100" iyz="0" izz="100" />
        </inertial>
        <visual>
            <origin xyz="0.19821536358270664 0 -0.22725049778152773" rpy="0 0 0"/>
            <geometry>
                <box size="0.3964307271654133 0.42221006554500995 0.45450099556305545" />
            </geometry>
            <material name="Blue">
                <color rgba="0 0.0 1.0 1.0"/>
            </material>
        </visual>
        <collision>
            <origin xyz="0.19821536358270664 0 -0.22725049778152773" rpy="0 0 0"/>
            <geometry>
                <box size="0.3964307271654133 0.42221006554500995 0.45450099556305545" />
            </geometry>
        </collision>
    </link>
</robot>