<robot name = "robot">
    <link name="Link0">
        <inertial>
            <origin xyz="0 0 2.0913410258446143" rpy="0 0 0"/>
            <mass value="1" />
            <inertia ixx="100" ixy="0" ixz="0" iyy="100" iyz="0" izz="100" />
        </inertial>
        <visual>
            <origin xyz="0 0 2.0913410258446143" rpy="0 0 0"/>
            <geometry>
                <box size="0.7544764414795339 0.30453716887631976 0.1826820516892289" />
            </geometry>
            <material name="Green">
                <color rgba="0 1.0 0.0 1.0"/>
            </material>
        </visual>
        <collision>
            <origin xyz="0 0 2.0913410258446143" rpy="0 0 0"/>
            <geometry>
                <box size="0.7544764414795339 0.30453716887631976 0.1826820516892289" />
            </geometry>
        </collision>
    </link>
    <joint name="Link0_Link1" type="revolute">
       <parent link="Link0"/>
       <child  link="Link1"/>
       <origin rpy="0 0 0" xyz="0 0.15226858443815988 2.1826820516892287" />
     <axis xyz="1 0 0"/>
       <limit effort="0.0" lower="-3.14159" upper="3.14159" velocity="0.0"/>
    </joint>
    <link name="Link1">
        <inertial>
            <origin xyz="0 0.15226858443815988 -0.09134102584461445" rpy="0 0 0"/>
            <mass value="1" />
            <inertia ixx="100" ixy="0" ixz="0" iyy="100" iyz="0" izz="100" />
        </inertial>
        <visual>
            <origin xyz="0 0.15226858443815988 -0.09134102584461445" rpy="0 0 0"/>
            <geometry>
                <box size="0.7544764414795339 0.30453716887631976 0.1826820516892289" />
            </geometry>
            <material name="Green">
                <color rgba="0 1.0 0.0 1.0"/>
            </material>
        </visual>
        <collision>
            <origin xyz="0 0.15226858443815988 -0.09134102584461445" rpy="0 0 0"/>
            <geometry>
                <box size="0.7544764414795339 0.30453716887631976 0.1826820516892289" />
            </geometry>
        </collision>
    </link>
    <joint name="Link1_Link2" type="revolute">
       <parent link="Link1"/>
       <child  link="Link2"/>
       <origin rpy="0 0 0" xyz="-0.3772382207397669 0.15226858443815988 0.0" />
     <axis xyz="0 1 0"/>
       <limit effort="0.0" lower="-3.14159" upper="3.14159" velocity="0.0"/>
    </joint>
    <link name="Link2">
        <inertial>
            <origin xyz="-0.17617568241078474 0 0.00301490212026001" rpy="0 0 0"/>
            <mass value="1" />
            <inertia ixx="100" ixy="0" ixz="0" iyy="100" iyz="0" izz="100" />
        </inertial>
        <visual>
            <origin xyz="-0.17617568241078474 0 0.00301490212026001" rpy="0 0 0"/>
            <geometry>
                <box size="0.3523513648215695 0.7890798192514404 0.00602980424052002" />
            </geometry>
            <material name="Blue">
                <color rgba="0 0.0 1.0 1.0"/>
            </material>
        </visual>
        <collision>
            <origin xyz="-0.17617568241078474 0 0.00301490212026001" rpy="0 0 0"/>
            <geometry>
                <box size="0.3523513648215695 0.7890798192514404 0.00602980424052002" />
            </geometry>
        </collision>
    </link>
    <joint name="Link2_Link3" type="revolute">
       <parent link="Link2"/>
       <child  link="Link3"/>
       <origin rpy="0 0 0" xyz="-0.17617568241078474 0.3945399096257202 0.00602980424052002" />
     <axis xyz="1 0 0"/>
       <limit effort="0.0" lower="-3.14159" upper="3.14159" velocity="0.0"/>
    </joint>
    <link name="Link3">
        <inertial>
            <origin xyz="0 0.19326309267614789 0.28638447325421934" rpy="0 0 0"/>
            <mass value="1" />
            <inertia ixx="100" ixy="0" ixz="0" iyy="100" iyz="0" izz="100" />
        </inertial>
        <visual>
            <origin xyz="0 0.19326309267614789 0.28638447325421934" rpy="0 0 0"/>
            <geometry>
                <box size="0.24193097658108753 0.38652618535229577 0.5727689465084387" />
            </geometry>
            <material name="Blue">
                <color rgba="0 0.0 1.0 1.0"/>
            </material>
        </visual>
        <collision>
            <origin xyz="0 0.19326309267614789 0.28638447325421934" rpy="0 0 0"/>
            <geometry>
                <box size="0.24193097658108753 0.38652618535229577 0.5727689465084387" />
            </geometry>
        </collision>
    </link>
    <joint name="Link3_Link4" type="revolute">
       <parent link="Link3"/>
       <child  link="Link4"/>
       <origin rpy="0 0 0" xyz="0 0.38652618535229577 0.5727689465084387" />
     <axis xyz="1 0 0"/>
       <limit effort="0.0" lower="-3.14159" upper="3.14159" velocity="0.0"/>
    </joint>
    <link name="Link4">
        <inertial>
            <origin xyz="0 0.12625263224547384 -0.10837381043456473" rpy="0 0 0"/>
            <mass value="1" />
            <inertia ixx="100" ixy="0" ixz="0" iyy="100" iyz="0" izz="100" />
        </inertial>
        <visual>
            <origin xyz="0 0.12625263224547384 -0.10837381043456473" rpy="0 0 0"/>
            <geometry>
                <box size="0.7519630356051159 0.2525052644909477 0.21674762086912946" />
            </geometry>
            <material name="Green">
                <color rgba="0 1.0 0.0 1.0"/>
            </material>
        </visual>
        <collision>
            <origin xyz="0 0.12625263224547384 -0.10837381043456473" rpy="0 0 0"/>
            <geometry>
                <box size="0.7519630356051159 0.2525052644909477 0.21674762086912946" />
            </geometry>
        </collision>
    </link>
    <joint name="Link4_Link5" type="revolute">
       <parent link="Link4"/>
       <child  link="Link5"/>
       <origin rpy="0 0 0" xyz="0 0.0 0.0" />
     <axis xyz="1 0 0"/>
       <limit effort="0.0" lower="-3.14159" upper="3.14159" velocity="0.0"/>
    </joint>
    <link name="Link5">
        <inertial>
            <origin xyz="0 -0.04487549950733877 -0.06385469378088321" rpy="0 0 0"/>
            <mass value="1" />
            <inertia ixx="100" ixy="0" ixz="0" iyy="100" iyz="0" izz="100" />
        </inertial>
        <visual>
            <origin xyz="0 -0.04487549950733877 -0.06385469378088321" rpy="0 0 0"/>
            <geometry>
                <box size="0.9202242177350184 0.08975099901467753 0.12770938756176642" />
            </geometry>
            <material name="Blue">
                <color rgba="0 0.0 1.0 1.0"/>
            </material>
        </visual>
        <collision>
            <origin xyz="0 -0.04487549950733877 -0.06385469378088321" rpy="0 0 0"/>
            <geometry>
                <box size="0.9202242177350184 0.08975099901467753 0.12770938756176642" />
            </geometry>
        </collision>
    </link>
</robot>