<robot name = "robot">
    <link name="Link0">
        <inertial>
            <origin xyz="0 0 2.036413981534175" rpy="0 0 0"/>
            <mass value="1" />
            <inertia ixx="100" ixy="0" ixz="0" iyy="100" iyz="0" izz="100" />
        </inertial>
        <visual>
            <origin xyz="0 0 2.036413981534175" rpy="0 0 0"/>
            <geometry>
                <box size="0.07697675354733258 0.577464809805596 0.07282796306834938" />
            </geometry>
            <material name="Green">
                <color rgba="0 1.0 0.0 1.0"/>
            </material>
        </visual>
        <collision>
            <origin xyz="0 0 2.036413981534175" rpy="0 0 0"/>
            <geometry>
                <box size="0.07697675354733258 0.577464809805596 0.07282796306834938" />
            </geometry>
        </collision>
    </link>
    <joint name="Link0_Link1" type="revolute">
       <parent link="Link0"/>
       <child  link="Link1"/>
       <origin rpy="0 0 0" xyz="0 0.288732404902798 2.0728279630683493" />
     <axis xyz="1 0 0"/>
       <limit effort="0.0" lower="-3.14159" upper="3.14159" velocity="0.0"/>
    </joint>
    <link name="Link1">
        <inertial>
            <origin xyz="0 0.288732404902798 -0.03641398153417469" rpy="0 0 0"/>
            <mass value="1" />
            <inertia ixx="100" ixy="0" ixz="0" iyy="100" iyz="0" izz="100" />
        </inertial>
        <visual>
            <origin xyz="0 0.288732404902798 -0.03641398153417469" rpy="0 0 0"/>
            <geometry>
                <box size="0.07697675354733258 0.577464809805596 0.07282796306834938" />
            </geometry>
            <material name="Green">
                <color rgba="0 1.0 0.0 1.0"/>
            </material>
        </visual>
        <collision>
            <origin xyz="0 0.288732404902798 -0.03641398153417469" rpy="0 0 0"/>
            <geometry>
                <box size="0.07697675354733258 0.577464809805596 0.07282796306834938" />
            </geometry>
        </collision>
    </link>
    <joint name="Link1_Link2" type="revolute">
       <parent link="Link1"/>
       <child  link="Link2"/>
       <origin rpy="0 0 0" xyz="0 0.0 0.0" />
     <axis xyz="1 0 0"/>
       <limit effort="0.0" lower="-3.14159" upper="3.14159" velocity="0.0"/>
    </joint>
    <link name="Link2">
        <inertial>
            <origin xyz="0 -0.3748833362612017 -0.33008207210789964" rpy="0 0 0"/>
            <mass value="1" />
            <inertia ixx="100" ixy="0" ixz="0" iyy="100" iyz="0" izz="100" />
        </inertial>
        <visual>
            <origin xyz="0 -0.3748833362612017 -0.33008207210789964" rpy="0 0 0"/>
            <geometry>
                <box size="0.5114889706514479 0.7497666725224034 0.6601641442157993" />
            </geometry>
            <material name="Green">
                <color rgba="0 1.0 0.0 1.0"/>
            </material>
        </visual>
        <collision>
            <origin xyz="0 -0.3748833362612017 -0.33008207210789964" rpy="0 0 0"/>
            <geometry>
                <box size="0.5114889706514479 0.7497666725224034 0.6601641442157993" />
            </geometry>
        </collision>
    </link>
    <joint name="Link2_Link3" type="revolute">
       <parent link="Link2"/>
       <child  link="Link3"/>
       <origin rpy="0 0 0" xyz="-0.25574448532572397 -0.3748833362612017 0.0" />
     <axis xyz="0 1 0"/>
       <limit effort="0.0" lower="-3.14159" upper="3.14159" velocity="0.0"/>
    </joint>
    <link name="Link3">
        <inertial>
            <origin xyz="-0.40398135454541206 0 -0.15309980670084578" rpy="0 0 0"/>
            <mass value="1" />
            <inertia ixx="100" ixy="0" ixz="0" iyy="100" iyz="0" izz="100" />
        </inertial>
        <visual>
            <origin xyz="-0.40398135454541206 0 -0.15309980670084578" rpy="0 0 0"/>
            <geometry>
                <box size="0.8079627090908241 0.47555560695631527 0.30619961340169155" />
            </geometry>
            <material name="Blue">
                <color rgba="0 0.0 1.0 1.0"/>
            </material>
        </visual>
        <collision>
            <origin xyz="-0.40398135454541206 0 -0.15309980670084578" rpy="0 0 0"/>
            <geometry>
                <box size="0.8079627090908241 0.47555560695631527 0.30619961340169155" />
            </geometry>
        </collision>
    </link>
    <joint name="Link3_Link4" type="revolute">
       <parent link="Link3"/>
       <child  link="Link4"/>
       <origin rpy="0 0 0" xyz="-0.40398135454541206 0.23777780347815763 0.0" />
     <axis xyz="1 0 0"/>
       <limit effort="0.0" lower="-3.14159" upper="3.14159" velocity="0.0"/>
    </joint>
    <link name="Link4">
        <inertial>
            <origin xyz="0 0.12532849193516482 0.2784348841640807" rpy="0 0 0"/>
            <mass value="1" />
            <inertia ixx="100" ixy="0" ixz="0" iyy="100" iyz="0" izz="100" />
        </inertial>
        <visual>
            <origin xyz="0 0.12532849193516482 0.2784348841640807" rpy="0 0 0"/>
            <geometry>
                <box size="0.9749964065516555 0.25065698387032964 0.5568697683281614" />
            </geometry>
            <material name="Blue">
                <color rgba="0 0.0 1.0 1.0"/>
            </material>
        </visual>
        <collision>
            <origin xyz="0 0.12532849193516482 0.2784348841640807" rpy="0 0 0"/>
            <geometry>
                <box size="0.9749964065516555 0.25065698387032964 0.5568697683281614" />
            </geometry>
        </collision>
    </link>
    <joint name="Link4_Link5" type="revolute">
       <parent link="Link4"/>
       <child  link="Link5"/>
       <origin rpy="0 0 0" xyz="0 0.0 0.5568697683281614" />
     <axis xyz="1 0 0"/>
       <limit effort="0.0" lower="-3.14159" upper="3.14159" velocity="0.0"/>
    </joint>
    <link name="Link5">
        <inertial>
            <origin xyz="0 -0.47046742431458993 -0.10242148237737397" rpy="0 0 0"/>
            <mass value="1" />
            <inertia ixx="100" ixy="0" ixz="0" iyy="100" iyz="0" izz="100" />
        </inertial>
        <visual>
            <origin xyz="0 -0.47046742431458993 -0.10242148237737397" rpy="0 0 0"/>
            <geometry>
                <box size="0.7558207914221833 0.9409348486291799 0.20484296475474795" />
            </geometry>
            <material name="Green">
                <color rgba="0 1.0 0.0 1.0"/>
            </material>
        </visual>
        <collision>
            <origin xyz="0 -0.47046742431458993 -0.10242148237737397" rpy="0 0 0"/>
            <geometry>
                <box size="0.7558207914221833 0.9409348486291799 0.20484296475474795" />
            </geometry>
        </collision>
    </link>
</robot>