<robot name = "robot">
    <link name="Link0">
        <inertial>
            <origin xyz="0 0 2.0280913065886375" rpy="0 0 0"/>
            <mass value="1" />
            <inertia ixx="100" ixy="0" ixz="0" iyy="100" iyz="0" izz="100" />
        </inertial>
        <visual>
            <origin xyz="0 0 2.0280913065886375" rpy="0 0 0"/>
            <geometry>
                <box size="0.38452964385681854 0.8495909108584884 0.05618261317727513" />
            </geometry>
            <material name="Green">
                <color rgba="0 1.0 0.0 1.0"/>
            </material>
        </visual>
        <collision>
            <origin xyz="0 0 2.0280913065886375" rpy="0 0 0"/>
            <geometry>
                <box size="0.38452964385681854 0.8495909108584884 0.05618261317727513" />
            </geometry>
        </collision>
    </link>
    <joint name="Link0_Link1" type="revolute">
       <parent link="Link0"/>
       <child  link="Link1"/>
       <origin rpy="0 0 0" xyz="0 0.4247954554292442 2.056182613177275" />
     <axis xyz="1 0 0"/>
       <limit effort="0.0" lower="-3.14159" upper="3.14159" velocity="0.0"/>
    </joint>
    <link name="Link1">
        <inertial>
            <origin xyz="0 0.4247954554292442 -0.028091306588637566" rpy="0 0 0"/>
            <mass value="1" />
            <inertia ixx="100" ixy="0" ixz="0" iyy="100" iyz="0" izz="100" />
        </inertial>
        <visual>
            <origin xyz="0 0.4247954554292442 -0.028091306588637566" rpy="0 0 0"/>
            <geometry>
                <box size="0.38452964385681854 0.8495909108584884 0.05618261317727513" />
            </geometry>
            <material name="Green">
                <color rgba="0 1.0 0.0 1.0"/>
            </material>
        </visual>
        <collision>
            <origin xyz="0 0.4247954554292442 -0.028091306588637566" rpy="0 0 0"/>
            <geometry>
                <box size="0.38452964385681854 0.8495909108584884 0.05618261317727513" />
            </geometry>
        </collision>
    </link>
    <joint name="Link1_Link2" type="revolute">
       <parent link="Link1"/>
       <child  link="Link2"/>
       <origin rpy="0 0 0" xyz="0 0.8495909108584884 0.0" />
     <axis xyz="1 0 0"/>
       <limit effort="0.0" lower="-3.14159" upper="3.14159" velocity="0.0"/>
    </joint>
    <link name="Link2">
        <inertial>
            <origin xyz="0 0.481496268475367 -0.16467658138848879" rpy="0 0 0"/>
            <mass value="1" />
            <inertia ixx="100" ixy="0" ixz="0" iyy="100" iyz="0" izz="100" />
        </inertial>
        <visual>
            <origin xyz="0 0.481496268475367 -0.16467658138848879" rpy="0 0 0"/>
            <geometry>
                <box size="0.15758632290657615 0.962992536950734 0.32935316277697757" />
            </geometry>
            <material name="Green">
                <color rgba="0 1.0 0.0 1.0"/>
            </material>
        </visual>
        <collision>
            <origin xyz="0 0.481496268475367 -0.16467658138848879" rpy="0 0 0"/>
            <geometry>
                <box size="0.15758632290657615 0.962992536950734 0.32935316277697757" />
            </geometry>
        </collision>
    </link>
    <joint name="Link2_Link3" type="revolute">
       <parent link="Link2"/>
       <child  link="Link3"/>
       <origin rpy="0 0 0" xyz="-0.07879316145328807 0.481496268475367 0.0" />
     <axis xyz="0 1 0"/>
       <limit effort="0.0" lower="-3.14159" upper="3.14159" velocity="0.0"/>
    </joint>
    <link name="Link3">
        <inertial>
            <origin xyz="-0.11938168178335073 0 -0.18653106147524018" rpy="0 0 0"/>
            <mass value="1" />
            <inertia ixx="100" ixy="0" ixz="0" iyy="100" iyz="0" izz="100" />
        </inertial>
        <visual>
            <origin xyz="-0.11938168178335073 0 -0.18653106147524018" rpy="0 0 0"/>
            <geometry>
                <box size="0.23876336356670147 0.0568262028111044 0.37306212295048036" />
            </geometry>
            <material name="Green">
                <color rgba="0 1.0 0.0 1.0"/>
            </material>
        </visual>
        <collision>
            <origin xyz="-0.11938168178335073 0 -0.18653106147524018" rpy="0 0 0"/>
            <geometry>
                <box size="0.23876336356670147 0.0568262028111044 0.37306212295048036" />
            </geometry>
        </collision>
    </link>
    <joint name="Link3_Link4" type="revolute">
       <parent link="Link3"/>
       <child  link="Link4"/>
       <origin rpy="0 0 0" xyz="-0.23876336356670147 0 0.0" />
     <axis xyz="0 1 0"/>
       <limit effort="0.0" lower="-3.14159" upper="3.14159" velocity="0.0"/>
    </joint>
    <link name="Link4">
        <inertial>
            <origin xyz="-0.08472572729121736 0 0.16411505743682814" rpy="0 0 0"/>
            <mass value="1" />
            <inertia ixx="100" ixy="0" ixz="0" iyy="100" iyz="0" izz="100" />
        </inertial>
        <visual>
            <origin xyz="-0.08472572729121736 0 0.16411505743682814" rpy="0 0 0"/>
            <geometry>
                <box size="0.1694514545824347 0.40146781315700886 0.3282301148736563" />
            </geometry>
            <material name="Green">
                <color rgba="0 1.0 0.0 1.0"/>
            </material>
        </visual>
        <collision>
            <origin xyz="-0.08472572729121736 0 0.16411505743682814" rpy="0 0 0"/>
            <geometry>
                <box size="0.1694514545824347 0.40146781315700886 0.3282301148736563" />
            </geometry>
        </collision>
    </link>
</robot>