<robot name = "robot">
    <link name="Link0">
        <inertial>
            <origin xyz="0 0 2.4015129037252088" rpy="0 0 0"/>
            <mass value="1" />
            <inertia ixx="100" ixy="0" ixz="0" iyy="100" iyz="0" izz="100" />
        </inertial>
        <visual>
            <origin xyz="0 0 2.4015129037252088" rpy="0 0 0"/>
            <geometry>
                <box size="0.101126991250579 0.3846640382290404 0.8030258074504171" />
            </geometry>
            <material name="Green">
                <color rgba="0 1.0 0.0 1.0"/>
            </material>
        </visual>
        <collision>
            <origin xyz="0 0 2.4015129037252088" rpy="0 0 0"/>
            <geometry>
                <box size="0.101126991250579 0.3846640382290404 0.8030258074504171" />
            </geometry>
        </collision>
    </link>
    <joint name="Link0_Link1" type="revolute">
       <parent link="Link0"/>
       <child  link="Link1"/>
       <origin rpy="0 0 0" xyz="0 0.1923320191145202 2.803025807450417" />
     <axis xyz="1 0 0"/>
       <limit effort="0.0" lower="-3.14159" upper="3.14159" velocity="0.0"/>
    </joint>
    <link name="Link1">
        <inertial>
            <origin xyz="0 0.1923320191145202 -0.40151290372520854" rpy="0 0 0"/>
            <mass value="1" />
            <inertia ixx="100" ixy="0" ixz="0" iyy="100" iyz="0" izz="100" />
        </inertial>
        <visual>
            <origin xyz="0 0.1923320191145202 -0.40151290372520854" rpy="0 0 0"/>
            <geometry>
                <box size="0.101126991250579 0.3846640382290404 0.8030258074504171" />
            </geometry>
            <material name="Green">
                <color rgba="0 1.0 0.0 1.0"/>
            </material>
        </visual>
        <collision>
            <origin xyz="0 0.1923320191145202 -0.40151290372520854" rpy="0 0 0"/>
            <geometry>
                <box size="0.101126991250579 0.3846640382290404 0.8030258074504171" />
            </geometry>
        </collision>
    </link>
    <joint name="Link1_Link2" type="revolute">
       <parent link="Link1"/>
       <child  link="Link2"/>
       <origin rpy="0 0 0" xyz="0 0.3846640382290404 0.0" />
     <axis xyz="1 0 0"/>
       <limit effort="0.0" lower="-3.14159" upper="3.14159" velocity="0.0"/>
    </joint>
    <link name="Link2">
        <inertial>
            <origin xyz="0 0.11282469957405916 -0.24938777060885575" rpy="0 0 0"/>
            <mass value="1" />
            <inertia ixx="100" ixy="0" ixz="0" iyy="100" iyz="0" izz="100" />
        </inertial>
        <visual>
            <origin xyz="0 0.11282469957405916 -0.24938777060885575" rpy="0 0 0"/>
            <geometry>
                <box size="0.048376302656048975 0.22564939914811832 0.4987755412177115" />
            </geometry>
            <material name="Green">
                <color rgba="0 1.0 0.0 1.0"/>
            </material>
        </visual>
        <collision>
            <origin xyz="0 0.11282469957405916 -0.24938777060885575" rpy="0 0 0"/>
            <geometry>
                <box size="0.048376302656048975 0.22564939914811832 0.4987755412177115" />
            </geometry>
        </collision>
    </link>
    <joint name="Link2_Link3" type="revolute">
       <parent link="Link2"/>
       <child  link="Link3"/>
       <origin rpy="0 0 0" xyz="-0.024188151328024488 0.11282469957405916 0.0" />
     <axis xyz="0 1 0"/>
       <limit effort="0.0" lower="-3.14159" upper="3.14159" velocity="0.0"/>
    </joint>
    <link name="Link3">
        <inertial>
            <origin xyz="-0.16963553222866917 0 0.34923312147827124" rpy="0 0 0"/>
            <mass value="1" />
            <inertia ixx="100" ixy="0" ixz="0" iyy="100" iyz="0" izz="100" />
        </inertial>
        <visual>
            <origin xyz="-0.16963553222866917 0 0.34923312147827124" rpy="0 0 0"/>
            <geometry>
                <box size="0.33927106445733834 0.66439697772467 0.6984662429565425" />
            </geometry>
            <material name="Green">
                <color rgba="0 1.0 0.0 1.0"/>
            </material>
        </visual>
        <collision>
            <origin xyz="-0.16963553222866917 0 0.34923312147827124" rpy="0 0 0"/>
            <geometry>
                <box size="0.33927106445733834 0.66439697772467 0.6984662429565425" />
            </geometry>
        </collision>
    </link>
    <joint name="Link3_Link4" type="revolute">
       <parent link="Link3"/>
       <child  link="Link4"/>
       <origin rpy="0 0 0" xyz="0.0 0 0.6984662429565425" />
     <axis xyz="0 1 0"/>
       <limit effort="0.0" lower="-3.14159" upper="3.14159" velocity="0.0"/>
    </joint>
    <link name="Link4">
        <inertial>
            <origin xyz="0.41083181984465017 0 0.11528159050914444" rpy="0 0 0"/>
            <mass value="1" />
            <inertia ixx="100" ixy="0" ixz="0" iyy="100" iyz="0" izz="100" />
        </inertial>
        <visual>
            <origin xyz="0.41083181984465017 0 0.11528159050914444" rpy="0 0 0"/>
            <geometry>
                <box size="0.8216636396893003 0.47772363625843983 0.23056318101828888" />
            </geometry>
            <material name="Green">
                <color rgba="0 1.0 0.0 1.0"/>
            </material>
        </visual>
        <collision>
            <origin xyz="0.41083181984465017 0 0.11528159050914444" rpy="0 0 0"/>
            <geometry>
                <box size="0.8216636396893003 0.47772363625843983 0.23056318101828888" />
            </geometry>
        </collision>
    </link>
    <joint name="Link4_Link5" type="revolute">
       <parent link="Link4"/>
       <child  link="Link5"/>
       <origin rpy="0 0 0" xyz="0.0 0 0.23056318101828888" />
     <axis xyz="0 1 0"/>
       <limit effort="0.0" lower="-3.14159" upper="3.14159" velocity="0.0"/>
    </joint>
    <link name="Link5">
        <inertial>
            <origin xyz="-0.398334272818259 0 -0.14116348360440673" rpy="0 0 0"/>
            <mass value="1" />
            <inertia ixx="100" ixy="0" ixz="0" iyy="100" iyz="0" izz="100" />
        </inertial>
        <visual>
            <origin xyz="-0.398334272818259 0 -0.14116348360440673" rpy="0 0 0"/>
            <geometry>
                <box size="0.796668545636518 0.5288200077907533 0.28232696720881345" />
            </geometry>
            <material name="Green">
                <color rgba="0 1.0 0.0 1.0"/>
            </material>
        </visual>
        <collision>
            <origin xyz="-0.398334272818259 0 -0.14116348360440673" rpy="0 0 0"/>
            <geometry>
                <box size="0.796668545636518 0.5288200077907533 0.28232696720881345" />
            </geometry>
        </collision>
    </link>
</robot>