<robot name = "robot">
    <link name="Link0">
        <inertial>
            <origin xyz="0 0 2.2890637806763983" rpy="0 0 0"/>
            <mass value="1" />
            <inertia ixx="100" ixy="0" ixz="0" iyy="100" iyz="0" izz="100" />
        </inertial>
        <visual>
            <origin xyz="0 0 2.2890637806763983" rpy="0 0 0"/>
            <geometry>
                <box size="0.3252209949609831 0.3011412957148364 0.5781275613527965" />
            </geometry>
            <material name="Green">
                <color rgba="0 1.0 0.0 1.0"/>
            </material>
        </visual>
        <collision>
            <origin xyz="0 0 2.2890637806763983" rpy="0 0 0"/>
            <geometry>
                <box size="0.3252209949609831 0.3011412957148364 0.5781275613527965" />
            </geometry>
        </collision>
    </link>
    <joint name="Link0_Link1" type="revolute">
       <parent link="Link0"/>
       <child  link="Link1"/>
       <origin rpy="0 0 0" xyz="0 0.1505706478574182 2.5781275613527965" />
     <axis xyz="1 0 0"/>
       <limit effort="0.0" lower="-3.14159" upper="3.14159" velocity="0.0"/>
    </joint>
    <link name="Link1">
        <inertial>
            <origin xyz="0 0.1505706478574182 -0.28906378067639826" rpy="0 0 0"/>
            <mass value="1" />
            <inertia ixx="100" ixy="0" ixz="0" iyy="100" iyz="0" izz="100" />
        </inertial>
        <visual>
            <origin xyz="0 0.1505706478574182 -0.28906378067639826" rpy="0 0 0"/>
            <geometry>
                <box size="0.3252209949609831 0.3011412957148364 0.5781275613527965" />
            </geometry>
            <material name="Green">
                <color rgba="0 1.0 0.0 1.0"/>
            </material>
        </visual>
        <collision>
            <origin xyz="0 0.1505706478574182 -0.28906378067639826" rpy="0 0 0"/>
            <geometry>
                <box size="0.3252209949609831 0.3011412957148364 0.5781275613527965" />
            </geometry>
        </collision>
    </link>
    <joint name="Link1_Link2" type="revolute">
       <parent link="Link1"/>
       <child  link="Link2"/>
       <origin rpy="0 0 0" xyz="0 0.3011412957148364 0.0" />
     <axis xyz="1 0 0"/>
       <limit effort="0.0" lower="-3.14159" upper="3.14159" velocity="0.0"/>
    </joint>
    <link name="Link2">
        <inertial>
            <origin xyz="0 0.03245498769724847 -0.419369554928916" rpy="0 0 0"/>
            <mass value="1" />
            <inertia ixx="100" ixy="0" ixz="0" iyy="100" iyz="0" izz="100" />
        </inertial>
        <visual>
            <origin xyz="0 0.03245498769724847 -0.419369554928916" rpy="0 0 0"/>
            <geometry>
                <box size="0.9663535421380097 0.06490997539449694 0.838739109857832" />
            </geometry>
            <material name="Green">
                <color rgba="0 1.0 0.0 1.0"/>
            </material>
        </visual>
        <collision>
            <origin xyz="0 0.03245498769724847 -0.419369554928916" rpy="0 0 0"/>
            <geometry>
                <box size="0.9663535421380097 0.06490997539449694 0.838739109857832" />
            </geometry>
        </collision>
    </link>
    <joint name="Link2_Link3" type="revolute">
       <parent link="Link2"/>
       <child  link="Link3"/>
       <origin rpy="0 0 0" xyz="0 0.06490997539449694 0.0" />
     <axis xyz="1 0 0"/>
       <limit effort="0.0" lower="-3.14159" upper="3.14159" velocity="0.0"/>
    </joint>
    <link name="Link3">
        <inertial>
            <origin xyz="0 0.25243983139446874 0.4963852383589367" rpy="0 0 0"/>
            <mass value="1" />
            <inertia ixx="100" ixy="0" ixz="0" iyy="100" iyz="0" izz="100" />
        </inertial>
        <visual>
            <origin xyz="0 0.25243983139446874 0.4963852383589367" rpy="0 0 0"/>
            <geometry>
                <box size="0.40711038980396597 0.5048796627889375 0.9927704767178734" />
            </geometry>
            <material name="Blue">
                <color rgba="0 0.0 1.0 1.0"/>
            </material>
        </visual>
        <collision>
            <origin xyz="0 0.25243983139446874 0.4963852383589367" rpy="0 0 0"/>
            <geometry>
                <box size="0.40711038980396597 0.5048796627889375 0.9927704767178734" />
            </geometry>
        </collision>
    </link>
    <joint name="Link3_Link4" type="revolute">
       <parent link="Link3"/>
       <child  link="Link4"/>
       <origin rpy="0 0 0" xyz="0 0.5048796627889375 0.9927704767178734" />
     <axis xyz="1 0 0"/>
       <limit effort="0.0" lower="-3.14159" upper="3.14159" velocity="0.0"/>
    </joint>
    <link name="Link4">
        <inertial>
            <origin xyz="0 0.30916223857674097 0.382733618808004" rpy="0 0 0"/>
            <mass value="1" />
            <inertia ixx="100" ixy="0" ixz="0" iyy="100" iyz="0" izz="100" />
        </inertial>
        <visual>
            <origin xyz="0 0.30916223857674097 0.382733618808004" rpy="0 0 0"/>
            <geometry>
                <box size="0.7911751151287186 0.6183244771534819 0.765467237616008" />
            </geometry>
            <material name="Blue">
                <color rgba="0 0.0 1.0 1.0"/>
            </material>
        </visual>
        <collision>
            <origin xyz="0 0.30916223857674097 0.382733618808004" rpy="0 0 0"/>
            <geometry>
                <box size="0.7911751151287186 0.6183244771534819 0.765467237616008" />
            </geometry>
        </collision>
    </link>
</robot>