<robot name = "robot">
    <link name="Link0">
        <inertial>
            <origin xyz="0 0 2.191528568735159" rpy="0 0 0"/>
            <mass value="1" />
            <inertia ixx="100" ixy="0" ixz="0" iyy="100" iyz="0" izz="100" />
        </inertial>
        <visual>
            <origin xyz="0 0 2.191528568735159" rpy="0 0 0"/>
            <geometry>
                <box size="0.18332525001214195 0.8559639858685272 0.383057137470318" />
            </geometry>
            <material name="Green">
                <color rgba="0 1.0 0.0 1.0"/>
            </material>
        </visual>
        <collision>
            <origin xyz="0 0 2.191528568735159" rpy="0 0 0"/>
            <geometry>
                <box size="0.18332525001214195 0.8559639858685272 0.383057137470318" />
            </geometry>
        </collision>
    </link>
    <joint name="Link0_Link1" type="revolute">
       <parent link="Link0"/>
       <child  link="Link1"/>
       <origin rpy="0 0 0" xyz="0 0.4279819929342636 2.3830571374703178" />
     <axis xyz="1 0 0"/>
       <limit effort="0.0" lower="-3.14159" upper="3.14159" velocity="0.0"/>
    </joint>
    <link name="Link1">
        <inertial>
            <origin xyz="0 0.4279819929342636 -0.191528568735159" rpy="0 0 0"/>
            <mass value="1" />
            <inertia ixx="100" ixy="0" ixz="0" iyy="100" iyz="0" izz="100" />
        </inertial>
        <visual>
            <origin xyz="0 0.4279819929342636 -0.191528568735159" rpy="0 0 0"/>
            <geometry>
                <box size="0.18332525001214195 0.8559639858685272 0.383057137470318" />
            </geometry>
            <material name="Green">
                <color rgba="0 1.0 0.0 1.0"/>
            </material>
        </visual>
        <collision>
            <origin xyz="0 0.4279819929342636 -0.191528568735159" rpy="0 0 0"/>
            <geometry>
                <box size="0.18332525001214195 0.8559639858685272 0.383057137470318" />
            </geometry>
        </collision>
    </link>
    <joint name="Link1_Link2" type="revolute">
       <parent link="Link1"/>
       <child  link="Link2"/>
       <origin rpy="0 0 0" xyz="0 0.0 0.0" />
     <axis xyz="1 0 0"/>
       <limit effort="0.0" lower="-3.14159" upper="3.14159" velocity="0.0"/>
    </joint>
    <link name="Link2">
        <inertial>
            <origin xyz="0 -0.018708830823996436 -0.4283073714538544" rpy="0 0 0"/>
            <mass value="1" />
            <inertia ixx="100" ixy="0" ixz="0" iyy="100" iyz="0" izz="100" />
        </inertial>
        <visual>
            <origin xyz="0 -0.018708830823996436 -0.4283073714538544" rpy="0 0 0"/>
            <geometry>
                <box size="0.8080617395514003 0.03741766164799287 0.8566147429077088" />
            </geometry>
            <material name="Green">
                <color rgba="0 1.0 0.0 1.0"/>
            </material>
        </visual>
        <collision>
            <origin xyz="0 -0.018708830823996436 -0.4283073714538544" rpy="0 0 0"/>
            <geometry>
                <box size="0.8080617395514003 0.03741766164799287 0.8566147429077088" />
            </geometry>
        </collision>
    </link>
    <joint name="Link2_Link3" type="revolute">
       <parent link="Link2"/>
       <child  link="Link3"/>
       <origin rpy="0 0 0" xyz="0 0.0 0.0" />
     <axis xyz="1 0 0"/>
       <limit effort="0.0" lower="-3.14159" upper="3.14159" velocity="0.0"/>
    </joint>
    <link name="Link3">
        <inertial>
            <origin xyz="0 0.3900006912888426 -0.1998827765872776" rpy="0 0 0"/>
            <mass value="1" />
            <inertia ixx="100" ixy="0" ixz="0" iyy="100" iyz="0" izz="100" />
        </inertial>
        <visual>
            <origin xyz="0 0.3900006912888426 -0.1998827765872776" rpy="0 0 0"/>
            <geometry>
                <box size="0.4752765917874603 0.7800013825776853 0.3997655531745552" />
            </geometry>
            <material name="Green">
                <color rgba="0 1.0 0.0 1.0"/>
            </material>
        </visual>
        <collision>
            <origin xyz="0 0.3900006912888426 -0.1998827765872776" rpy="0 0 0"/>
            <geometry>
                <box size="0.4752765917874603 0.7800013825776853 0.3997655531745552" />
            </geometry>
        </collision>
    </link>
    <joint name="Link3_Link4" type="revolute">
       <parent link="Link3"/>
       <child  link="Link4"/>
       <origin rpy="0 0 0" xyz="0.23763829589373014 0.3900006912888426 0.0" />
     <axis xyz="0 1 0"/>
       <limit effort="0.0" lower="-3.14159" upper="3.14159" velocity="0.0"/>
    </joint>
    <link name="Link4">
        <inertial>
            <origin xyz="0.11851531378116492 0 -0.267629395268419" rpy="0 0 0"/>
            <mass value="1" />
            <inertia ixx="100" ixy="0" ixz="0" iyy="100" iyz="0" izz="100" />
        </inertial>
        <visual>
            <origin xyz="0.11851531378116492 0 -0.267629395268419" rpy="0 0 0"/>
            <geometry>
                <box size="0.23703062756232984 0.7539949526932842 0.535258790536838" />
            </geometry>
            <material name="Blue">
                <color rgba="0 0.0 1.0 1.0"/>
            </material>
        </visual>
        <collision>
            <origin xyz="0.11851531378116492 0 -0.267629395268419" rpy="0 0 0"/>
            <geometry>
                <box size="0.23703062756232984 0.7539949526932842 0.535258790536838" />
            </geometry>
        </collision>
    </link>
</robot>