<robot name = "robot">
    <link name="Link0">
        <inertial>
            <origin xyz="0 0 2.12686586426174" rpy="0 0 0"/>
            <mass value="1" />
            <inertia ixx="100" ixy="0" ixz="0" iyy="100" iyz="0" izz="100" />
        </inertial>
        <visual>
            <origin xyz="0 0 2.12686586426174" rpy="0 0 0"/>
            <geometry>
                <box size="0.3337085233728 0.2993112478415969 0.25373172852348025" />
            </geometry>
            <material name="Green">
                <color rgba="0 1.0 0.0 1.0"/>
            </material>
        </visual>
        <collision>
            <origin xyz="0 0 2.12686586426174" rpy="0 0 0"/>
            <geometry>
                <box size="0.3337085233728 0.2993112478415969 0.25373172852348025" />
            </geometry>
        </collision>
    </link>
    <joint name="Link0_Link1" type="revolute">
       <parent link="Link0"/>
       <child  link="Link1"/>
       <origin rpy="0 0 0" xyz="0 0.14965562392079845 2.2537317285234804" />
     <axis xyz="1 0 0"/>
       <limit effort="0.0" lower="-3.14159" upper="3.14159" velocity="0.0"/>
    </joint>
    <link name="Link1">
        <inertial>
            <origin xyz="0 0.14965562392079845 -0.12686586426174012" rpy="0 0 0"/>
            <mass value="1" />
            <inertia ixx="100" ixy="0" ixz="0" iyy="100" iyz="0" izz="100" />
        </inertial>
        <visual>
            <origin xyz="0 0.14965562392079845 -0.12686586426174012" rpy="0 0 0"/>
            <geometry>
                <box size="0.3337085233728 0.2993112478415969 0.25373172852348025" />
            </geometry>
            <material name="Blue">
                <color rgba="0 0.0 1.0 1.0"/>
            </material>
        </visual>
        <collision>
            <origin xyz="0 0.14965562392079845 -0.12686586426174012" rpy="0 0 0"/>
            <geometry>
                <box size="0.3337085233728 0.2993112478415969 0.25373172852348025" />
            </geometry>
        </collision>
    </link>
    <joint name="Link1_Link2" type="revolute">
       <parent link="Link1"/>
       <child  link="Link2"/>
       <origin rpy="0 0 0" xyz="-0.1668542616864 0.14965562392079845 0.0" />
     <axis xyz="0 1 0"/>
       <limit effort="0.0" lower="-3.14159" upper="3.14159" velocity="0.0"/>
    </joint>
    <link name="Link2">
        <inertial>
            <origin xyz="-0.3150162107812902 0 -0.048301770872027305" rpy="0 0 0"/>
            <mass value="1" />
            <inertia ixx="100" ixy="0" ixz="0" iyy="100" iyz="0" izz="100" />
        </inertial>
        <visual>
            <origin xyz="-0.3150162107812902 0 -0.048301770872027305" rpy="0 0 0"/>
            <geometry>
                <box size="0.6300324215625804 0.42756246889057314 0.09660354174405461" />
            </geometry>
            <material name="Blue">
                <color rgba="0 0.0 1.0 1.0"/>
            </material>
        </visual>
        <collision>
            <origin xyz="-0.3150162107812902 0 -0.048301770872027305" rpy="0 0 0"/>
            <geometry>
                <box size="0.6300324215625804 0.42756246889057314 0.09660354174405461" />
            </geometry>
        </collision>
    </link>
    <joint name="Link2_Link3" type="revolute">
       <parent link="Link2"/>
       <child  link="Link3"/>
       <origin rpy="0 0 0" xyz="-0.3150162107812902 0.21378123444528657 0.0" />
     <axis xyz="1 0 0"/>
       <limit effort="0.0" lower="-3.14159" upper="3.14159" velocity="0.0"/>
    </joint>
    <link name="Link3">
        <inertial>
            <origin xyz="0 0.3875509026313506 -0.26645344268516874" rpy="0 0 0"/>
            <mass value="1" />
            <inertia ixx="100" ixy="0" ixz="0" iyy="100" iyz="0" izz="100" />
        </inertial>
        <visual>
            <origin xyz="0 0.3875509026313506 -0.26645344268516874" rpy="0 0 0"/>
            <geometry>
                <box size="0.2779803334284515 0.7751018052627012 0.5329068853703375" />
            </geometry>
            <material name="Blue">
                <color rgba="0 0.0 1.0 1.0"/>
            </material>
        </visual>
        <collision>
            <origin xyz="0 0.3875509026313506 -0.26645344268516874" rpy="0 0 0"/>
            <geometry>
                <box size="0.2779803334284515 0.7751018052627012 0.5329068853703375" />
            </geometry>
        </collision>
    </link>
    <joint name="Link3_Link4" type="revolute">
       <parent link="Link3"/>
       <child  link="Link4"/>
       <origin rpy="0 0 0" xyz="0 0.7751018052627012 0.0" />
     <axis xyz="1 0 0"/>
       <limit effort="0.0" lower="-3.14159" upper="3.14159" velocity="0.0"/>
    </joint>
    <link name="Link4">
        <inertial>
            <origin xyz="0 0.4633416749814449 -0.40107268919459876" rpy="0 0 0"/>
            <mass value="1" />
            <inertia ixx="100" ixy="0" ixz="0" iyy="100" iyz="0" izz="100" />
        </inertial>
        <visual>
            <origin xyz="0 0.4633416749814449 -0.40107268919459876" rpy="0 0 0"/>
            <geometry>
                <box size="0.20826075357003881 0.9266833499628898 0.8021453783891975" />
            </geometry>
            <material name="Blue">
                <color rgba="0 0.0 1.0 1.0"/>
            </material>
        </visual>
        <collision>
            <origin xyz="0 0.4633416749814449 -0.40107268919459876" rpy="0 0 0"/>
            <geometry>
                <box size="0.20826075357003881 0.9266833499628898 0.8021453783891975" />
            </geometry>
        </collision>
    </link>
</robot>