<robot name = "robot">
    <link name="Link0">
        <inertial>
            <origin xyz="0 0 2.017843887528394" rpy="0 0 0"/>
            <mass value="1" />
            <inertia ixx="100" ixy="0" ixz="0" iyy="100" iyz="0" izz="100" />
        </inertial>
        <visual>
            <origin xyz="0 0 2.017843887528394" rpy="0 0 0"/>
            <geometry>
                <box size="0.7502033659238537 0.8213923791340394 0.035687775056787885" />
            </geometry>
            <material name="Green">
                <color rgba="0 1.0 0.0 1.0"/>
            </material>
        </visual>
        <collision>
            <origin xyz="0 0 2.017843887528394" rpy="0 0 0"/>
            <geometry>
                <box size="0.7502033659238537 0.8213923791340394 0.035687775056787885" />
            </geometry>
        </collision>
    </link>
    <joint name="Link0_Link1" type="revolute">
       <parent link="Link0"/>
       <child  link="Link1"/>
       <origin rpy="0 0 0" xyz="0 0.4106961895670197 2.035687775056788" />
     <axis xyz="1 0 0"/>
       <limit effort="0.0" lower="-3.14159" upper="3.14159" velocity="0.0"/>
    </joint>
    <link name="Link1">
        <inertial>
            <origin xyz="0 0.4106961895670197 -0.017843887528393942" rpy="0 0 0"/>
            <mass value="1" />
            <inertia ixx="100" ixy="0" ixz="0" iyy="100" iyz="0" izz="100" />
        </inertial>
        <visual>
            <origin xyz="0 0.4106961895670197 -0.017843887528393942" rpy="0 0 0"/>
            <geometry>
                <box size="0.7502033659238537 0.8213923791340394 0.035687775056787885" />
            </geometry>
            <material name="Green">
                <color rgba="0 1.0 0.0 1.0"/>
            </material>
        </visual>
        <collision>
            <origin xyz="0 0.4106961895670197 -0.017843887528393942" rpy="0 0 0"/>
            <geometry>
                <box size="0.7502033659238537 0.8213923791340394 0.035687775056787885" />
            </geometry>
        </collision>
    </link>
    <joint name="Link1_Link2" type="revolute">
       <parent link="Link1"/>
       <child  link="Link2"/>
       <origin rpy="0 0 0" xyz="0 0.0 0.0" />
     <axis xyz="1 0 0"/>
       <limit effort="0.0" lower="-3.14159" upper="3.14159" velocity="0.0"/>
    </joint>
    <link name="Link2">
        <inertial>
            <origin xyz="0 -0.47283208454434134 -0.22900251278077027" rpy="0 0 0"/>
            <mass value="1" />
            <inertia ixx="100" ixy="0" ixz="0" iyy="100" iyz="0" izz="100" />
        </inertial>
        <visual>
            <origin xyz="0 -0.47283208454434134 -0.22900251278077027" rpy="0 0 0"/>
            <geometry>
                <box size="0.10049041508334167 0.9456641690886827 0.45800502556154055" />
            </geometry>
            <material name="Blue">
                <color rgba="0 0.0 1.0 1.0"/>
            </material>
        </visual>
        <collision>
            <origin xyz="0 -0.47283208454434134 -0.22900251278077027" rpy="0 0 0"/>
            <geometry>
                <box size="0.10049041508334167 0.9456641690886827 0.45800502556154055" />
            </geometry>
        </collision>
    </link>
    <joint name="Link2_Link3" type="revolute">
       <parent link="Link2"/>
       <child  link="Link3"/>
       <origin rpy="0 0 0" xyz="0 0.0 0.0" />
     <axis xyz="1 0 0"/>
       <limit effort="0.0" lower="-3.14159" upper="3.14159" velocity="0.0"/>
    </joint>
    <link name="Link3">
        <inertial>
            <origin xyz="0 0.20610442592108635 -0.3165400436119627" rpy="0 0 0"/>
            <mass value="1" />
            <inertia ixx="100" ixy="0" ixz="0" iyy="100" iyz="0" izz="100" />
        </inertial>
        <visual>
            <origin xyz="0 0.20610442592108635 -0.3165400436119627" rpy="0 0 0"/>
            <geometry>
                <box size="0.284261002362436 0.4122088518421727 0.6330800872239254" />
            </geometry>
            <material name="Green">
                <color rgba="0 1.0 0.0 1.0"/>
            </material>
        </visual>
        <collision>
            <origin xyz="0 0.20610442592108635 -0.3165400436119627" rpy="0 0 0"/>
            <geometry>
                <box size="0.284261002362436 0.4122088518421727 0.6330800872239254" />
            </geometry>
        </collision>
    </link>
    <joint name="Link3_Link4" type="revolute">
       <parent link="Link3"/>
       <child  link="Link4"/>
       <origin rpy="0 0 0" xyz="0 0.4122088518421727 0.0" />
     <axis xyz="1 0 0"/>
       <limit effort="0.0" lower="-3.14159" upper="3.14159" velocity="0.0"/>
    </joint>
    <link name="Link4">
        <inertial>
            <origin xyz="0 0.4343967554218953 0.3674171706746292" rpy="0 0 0"/>
            <mass value="1" />
            <inertia ixx="100" ixy="0" ixz="0" iyy="100" iyz="0" izz="100" />
        </inertial>
        <visual>
            <origin xyz="0 0.4343967554218953 0.3674171706746292" rpy="0 0 0"/>
            <geometry>
                <box size="0.6498744012121175 0.8687935108437906 0.7348343413492584" />
            </geometry>
            <material name="Blue">
                <color rgba="0 0.0 1.0 1.0"/>
            </material>
        </visual>
        <collision>
            <origin xyz="0 0.4343967554218953 0.3674171706746292" rpy="0 0 0"/>
            <geometry>
                <box size="0.6498744012121175 0.8687935108437906 0.7348343413492584" />
            </geometry>
        </collision>
    </link>
    <joint name="Link4_Link5" type="revolute">
       <parent link="Link4"/>
       <child  link="Link5"/>
       <origin rpy="0 0 0" xyz="0 0.0 0.7348343413492584" />
     <axis xyz="1 0 0"/>
       <limit effort="0.0" lower="-3.14159" upper="3.14159" velocity="0.0"/>
    </joint>
    <link name="Link5">
        <inertial>
            <origin xyz="0 -0.15714527595555172 0.024279926826161313" rpy="0 0 0"/>
            <mass value="1" />
            <inertia ixx="100" ixy="0" ixz="0" iyy="100" iyz="0" izz="100" />
        </inertial>
        <visual>
            <origin xyz="0 -0.15714527595555172 0.024279926826161313" rpy="0 0 0"/>
            <geometry>
                <box size="0.3717490143421356 0.31429055191110344 0.048559853652322627" />
            </geometry>
            <material name="Green">
                <color rgba="0 1.0 0.0 1.0"/>
            </material>
        </visual>
        <collision>
            <origin xyz="0 -0.15714527595555172 0.024279926826161313" rpy="0 0 0"/>
            <geometry>
                <box size="0.3717490143421356 0.31429055191110344 0.048559853652322627" />
            </geometry>
        </collision>
    </link>
    <joint name="Link5_Link6" type="revolute">
       <parent link="Link5"/>
       <child  link="Link6"/>
       <origin rpy="0 0 0" xyz="0 -0.31429055191110344 0.048559853652322627" />
     <axis xyz="1 0 0"/>
       <limit effort="0.0" lower="-3.14159" upper="3.14159" velocity="0.0"/>
    </joint>
    <link name="Link6">
        <inertial>
            <origin xyz="0 -0.36471602410825377 0.09829394076905218" rpy="0 0 0"/>
            <mass value="1" />
            <inertia ixx="100" ixy="0" ixz="0" iyy="100" iyz="0" izz="100" />
        </inertial>
        <visual>
            <origin xyz="0 -0.36471602410825377 0.09829394076905218" rpy="0 0 0"/>
            <geometry>
                <box size="0.5941335901714676 0.7294320482165075 0.19658788153810436" />
            </geometry>
            <material name="Green">
                <color rgba="0 1.0 0.0 1.0"/>
            </material>
        </visual>
        <collision>
            <origin xyz="0 -0.36471602410825377 0.09829394076905218" rpy="0 0 0"/>
            <geometry>
                <box size="0.5941335901714676 0.7294320482165075 0.19658788153810436" />
            </geometry>
        </collision>
    </link>
</robot>