<robot name = "robot">
    <link name="Link0">
        <inertial>
            <origin xyz="0 0 2.412246906081387" rpy="0 0 0"/>
            <mass value="1" />
            <inertia ixx="100" ixy="0" ixz="0" iyy="100" iyz="0" izz="100" />
        </inertial>
        <visual>
            <origin xyz="0 0 2.412246906081387" rpy="0 0 0"/>
            <geometry>
                <box size="0.16070006748122012 0.9836645988134058 0.8244938121627738" />
            </geometry>
            <material name="Green">
                <color rgba="0 1.0 0.0 1.0"/>
            </material>
        </visual>
        <collision>
            <origin xyz="0 0 2.412246906081387" rpy="0 0 0"/>
            <geometry>
                <box size="0.16070006748122012 0.9836645988134058 0.8244938121627738" />
            </geometry>
        </collision>
    </link>
    <joint name="Link0_Link1" type="revolute">
       <parent link="Link0"/>
       <child  link="Link1"/>
       <origin rpy="0 0 0" xyz="0 0.4918322994067029 2.824493812162774" />
     <axis xyz="1 0 0"/>
       <limit effort="0.0" lower="-3.14159" upper="3.14159" velocity="0.0"/>
    </joint>
    <link name="Link1">
        <inertial>
            <origin xyz="0 0.4918322994067029 -0.4122469060813869" rpy="0 0 0"/>
            <mass value="1" />
            <inertia ixx="100" ixy="0" ixz="0" iyy="100" iyz="0" izz="100" />
        </inertial>
        <visual>
            <origin xyz="0 0.4918322994067029 -0.4122469060813869" rpy="0 0 0"/>
            <geometry>
                <box size="0.16070006748122012 0.9836645988134058 0.8244938121627738" />
            </geometry>
            <material name="Blue">
                <color rgba="0 0.0 1.0 1.0"/>
            </material>
        </visual>
        <collision>
            <origin xyz="0 0.4918322994067029 -0.4122469060813869" rpy="0 0 0"/>
            <geometry>
                <box size="0.16070006748122012 0.9836645988134058 0.8244938121627738" />
            </geometry>
        </collision>
    </link>
    <joint name="Link1_Link2" type="revolute">
       <parent link="Link1"/>
       <child  link="Link2"/>
       <origin rpy="0 0 0" xyz="0 0.9836645988134058 0.0" />
     <axis xyz="1 0 0"/>
       <limit effort="0.0" lower="-3.14159" upper="3.14159" velocity="0.0"/>
    </joint>
    <link name="Link2">
        <inertial>
            <origin xyz="0 0.015198905032597576 0.24683449464535895" rpy="0 0 0"/>
            <mass value="1" />
            <inertia ixx="100" ixy="0" ixz="0" iyy="100" iyz="0" izz="100" />
        </inertial>
        <visual>
            <origin xyz="0 0.015198905032597576 0.24683449464535895" rpy="0 0 0"/>
            <geometry>
                <box size="0.6461150353560522 0.030397810065195152 0.4936689892907179" />
            </geometry>
            <material name="Blue">
                <color rgba="0 0.0 1.0 1.0"/>
            </material>
        </visual>
        <collision>
            <origin xyz="0 0.015198905032597576 0.24683449464535895" rpy="0 0 0"/>
            <geometry>
                <box size="0.6461150353560522 0.030397810065195152 0.4936689892907179" />
            </geometry>
        </collision>
    </link>
    <joint name="Link2_Link3" type="revolute">
       <parent link="Link2"/>
       <child  link="Link3"/>
       <origin rpy="0 0 0" xyz="0 0.030397810065195152 0.4936689892907179" />
     <axis xyz="1 0 0"/>
       <limit effort="0.0" lower="-3.14159" upper="3.14159" velocity="0.0"/>
    </joint>
    <link name="Link3">
        <inertial>
            <origin xyz="0 0.2443121415775249 0.289324886180735" rpy="0 0 0"/>
            <mass value="1" />
            <inertia ixx="100" ixy="0" ixz="0" iyy="100" iyz="0" izz="100" />
        </inertial>
        <visual>
            <origin xyz="0 0.2443121415775249 0.289324886180735" rpy="0 0 0"/>
            <geometry>
                <box size="0.7443509889398716 0.4886242831550498 0.57864977236147" />
            </geometry>
            <material name="Blue">
                <color rgba="0 0.0 1.0 1.0"/>
            </material>
        </visual>
        <collision>
            <origin xyz="0 0.2443121415775249 0.289324886180735" rpy="0 0 0"/>
            <geometry>
                <box size="0.7443509889398716 0.4886242831550498 0.57864977236147" />
            </geometry>
        </collision>
    </link>
    <joint name="Link3_Link4" type="revolute">
       <parent link="Link3"/>
       <child  link="Link4"/>
       <origin rpy="0 0 0" xyz="0 0.0 0.57864977236147" />
     <axis xyz="1 0 0"/>
       <limit effort="0.0" lower="-3.14159" upper="3.14159" velocity="0.0"/>
    </joint>
    <link name="Link4">
        <inertial>
            <origin xyz="0 -0.09488030080713716 0.21529738061552117" rpy="0 0 0"/>
            <mass value="1" />
            <inertia ixx="100" ixy="0" ixz="0" iyy="100" iyz="0" izz="100" />
        </inertial>
        <visual>
            <origin xyz="0 -0.09488030080713716 0.21529738061552117" rpy="0 0 0"/>
            <geometry>
                <box size="0.022517403048150086 0.18976060161427433 0.43059476123104234" />
            </geometry>
            <material name="Green">
                <color rgba="0 1.0 0.0 1.0"/>
            </material>
        </visual>
        <collision>
            <origin xyz="0 -0.09488030080713716 0.21529738061552117" rpy="0 0 0"/>
            <geometry>
                <box size="0.022517403048150086 0.18976060161427433 0.43059476123104234" />
            </geometry>
        </collision>
    </link>
    <joint name="Link4_Link5" type="revolute">
       <parent link="Link4"/>
       <child  link="Link5"/>
       <origin rpy="0 0 0" xyz="0.011258701524075043 -0.09488030080713716 0.43059476123104234" />
     <axis xyz="0 1 0"/>
       <limit effort="0.0" lower="-3.14159" upper="3.14159" velocity="0.0"/>
    </joint>
    <link name="Link5">
        <inertial>
            <origin xyz="0.4822027333115963 0 0.2900018926714693" rpy="0 0 0"/>
            <mass value="1" />
            <inertia ixx="100" ixy="0" ixz="0" iyy="100" iyz="0" izz="100" />
        </inertial>
        <visual>
            <origin xyz="0.4822027333115963 0 0.2900018926714693" rpy="0 0 0"/>
            <geometry>
                <box size="0.9644054666231926 0.41143304113395296 0.5800037853429386" />
            </geometry>
            <material name="Blue">
                <color rgba="0 0.0 1.0 1.0"/>
            </material>
        </visual>
        <collision>
            <origin xyz="0.4822027333115963 0 0.2900018926714693" rpy="0 0 0"/>
            <geometry>
                <box size="0.9644054666231926 0.41143304113395296 0.5800037853429386" />
            </geometry>
        </collision>
    </link>
    <joint name="Link5_Link6" type="revolute">
       <parent link="Link5"/>
       <child  link="Link6"/>
       <origin rpy="0 0 0" xyz="0.4822027333115963 -0.20571652056697648 0.5800037853429386" />
     <axis xyz="1 0 0"/>
       <limit effort="0.0" lower="-3.14159" upper="3.14159" velocity="0.0"/>
    </joint>
    <link name="Link6">
        <inertial>
            <origin xyz="0 -0.27645438698862007 -0.4613806305700694" rpy="0 0 0"/>
            <mass value="1" />
            <inertia ixx="100" ixy="0" ixz="0" iyy="100" iyz="0" izz="100" />
        </inertial>
        <visual>
            <origin xyz="0 -0.27645438698862007 -0.4613806305700694" rpy="0 0 0"/>
            <geometry>
                <box size="0.11547395311719033 0.5529087739772401 0.9227612611401388" />
            </geometry>
            <material name="Blue">
                <color rgba="0 0.0 1.0 1.0"/>
            </material>
        </visual>
        <collision>
            <origin xyz="0 -0.27645438698862007 -0.4613806305700694" rpy="0 0 0"/>
            <geometry>
                <box size="0.11547395311719033 0.5529087739772401 0.9227612611401388" />
            </geometry>
        </collision>
    </link>
</robot>