<robot name = "robot">
    <link name="Link0">
        <inertial>
            <origin xyz="0 0 2.019313852296534" rpy="0 0 0"/>
            <mass value="1" />
            <inertia ixx="100" ixy="0" ixz="0" iyy="100" iyz="0" izz="100" />
        </inertial>
        <visual>
            <origin xyz="0 0 2.019313852296534" rpy="0 0 0"/>
            <geometry>
                <box size="0.7496652797898494 0.22559091698939437 0.03862770459306808" />
            </geometry>
            <material name="Green">
                <color rgba="0 1.0 0.0 1.0"/>
            </material>
        </visual>
        <collision>
            <origin xyz="0 0 2.019313852296534" rpy="0 0 0"/>
            <geometry>
                <box size="0.7496652797898494 0.22559091698939437 0.03862770459306808" />
            </geometry>
        </collision>
    </link>
    <joint name="Link0_Link1" type="revolute">
       <parent link="Link0"/>
       <child  link="Link1"/>
       <origin rpy="0 0 0" xyz="0 0.11279545849469719 2.0386277045930683" />
     <axis xyz="1 0 0"/>
       <limit effort="0.0" lower="-3.14159" upper="3.14159" velocity="0.0"/>
    </joint>
    <link name="Link1">
        <inertial>
            <origin xyz="0 0.11279545849469719 -0.01931385229653404" rpy="0 0 0"/>
            <mass value="1" />
            <inertia ixx="100" ixy="0" ixz="0" iyy="100" iyz="0" izz="100" />
        </inertial>
        <visual>
            <origin xyz="0 0.11279545849469719 -0.01931385229653404" rpy="0 0 0"/>
            <geometry>
                <box size="0.7496652797898494 0.22559091698939437 0.03862770459306808" />
            </geometry>
            <material name="Blue">
                <color rgba="0 0.0 1.0 1.0"/>
            </material>
        </visual>
        <collision>
            <origin xyz="0 0.11279545849469719 -0.01931385229653404" rpy="0 0 0"/>
            <geometry>
                <box size="0.7496652797898494 0.22559091698939437 0.03862770459306808" />
            </geometry>
        </collision>
    </link>
    <joint name="Link1_Link2" type="revolute">
       <parent link="Link1"/>
       <child  link="Link2"/>
       <origin rpy="0 0 0" xyz="0 0.0 0.0" />
     <axis xyz="1 0 0"/>
       <limit effort="0.0" lower="-3.14159" upper="3.14159" velocity="0.0"/>
    </joint>
    <link name="Link2">
        <inertial>
            <origin xyz="0 -0.4979608330555378 0.13326192055092678" rpy="0 0 0"/>
            <mass value="1" />
            <inertia ixx="100" ixy="0" ixz="0" iyy="100" iyz="0" izz="100" />
        </inertial>
        <visual>
            <origin xyz="0 -0.4979608330555378 0.13326192055092678" rpy="0 0 0"/>
            <geometry>
                <box size="0.688939915446741 0.9959216661110756 0.26652384110185356" />
            </geometry>
            <material name="Blue">
                <color rgba="0 0.0 1.0 1.0"/>
            </material>
        </visual>
        <collision>
            <origin xyz="0 -0.4979608330555378 0.13326192055092678" rpy="0 0 0"/>
            <geometry>
                <box size="0.688939915446741 0.9959216661110756 0.26652384110185356" />
            </geometry>
        </collision>
    </link>
    <joint name="Link2_Link3" type="revolute">
       <parent link="Link2"/>
       <child  link="Link3"/>
       <origin rpy="0 0 0" xyz="-0.3444699577233705 -0.4979608330555378 0.26652384110185356" />
     <axis xyz="0 1 0"/>
       <limit effort="0.0" lower="-3.14159" upper="3.14159" velocity="0.0"/>
    </joint>
    <link name="Link3">
        <inertial>
            <origin xyz="-0.48404311295067054 0 0.17051066866307657" rpy="0 0 0"/>
            <mass value="1" />
            <inertia ixx="100" ixy="0" ixz="0" iyy="100" iyz="0" izz="100" />
        </inertial>
        <visual>
            <origin xyz="-0.48404311295067054 0 0.17051066866307657" rpy="0 0 0"/>
            <geometry>
                <box size="0.9680862259013411 0.8983099731401808 0.34102133732615314" />
            </geometry>
            <material name="Blue">
                <color rgba="0 0.0 1.0 1.0"/>
            </material>
        </visual>
        <collision>
            <origin xyz="-0.48404311295067054 0 0.17051066866307657" rpy="0 0 0"/>
            <geometry>
                <box size="0.9680862259013411 0.8983099731401808 0.34102133732615314" />
            </geometry>
        </collision>
    </link>
    <joint name="Link3_Link4" type="revolute">
       <parent link="Link3"/>
       <child  link="Link4"/>
       <origin rpy="0 0 0" xyz="-0.9680862259013411 0 0.34102133732615314" />
     <axis xyz="0 1 0"/>
       <limit effort="0.0" lower="-3.14159" upper="3.14159" velocity="0.0"/>
    </joint>
    <link name="Link4">
        <inertial>
            <origin xyz="-0.44377558496581754 0 -0.32842171204323356" rpy="0 0 0"/>
            <mass value="1" />
            <inertia ixx="100" ixy="0" ixz="0" iyy="100" iyz="0" izz="100" />
        </inertial>
        <visual>
            <origin xyz="-0.44377558496581754 0 -0.32842171204323356" rpy="0 0 0"/>
            <geometry>
                <box size="0.8875511699316351 0.6539913011142059 0.6568434240864671" />
            </geometry>
            <material name="Green">
                <color rgba="0 1.0 0.0 1.0"/>
            </material>
        </visual>
        <collision>
            <origin xyz="-0.44377558496581754 0 -0.32842171204323356" rpy="0 0 0"/>
            <geometry>
                <box size="0.8875511699316351 0.6539913011142059 0.6568434240864671" />
            </geometry>
        </collision>
    </link>
    <joint name="Link4_Link5" type="revolute">
       <parent link="Link4"/>
       <child  link="Link5"/>
       <origin rpy="0 0 0" xyz="-0.44377558496581754 -0.32699565055710295 0.0" />
     <axis xyz="1 0 0"/>
       <limit effort="0.0" lower="-3.14159" upper="3.14159" velocity="0.0"/>
    </joint>
    <link name="Link5">
        <inertial>
            <origin xyz="0 -0.1205144613008558 -0.4478812690490514" rpy="0 0 0"/>
            <mass value="1" />
            <inertia ixx="100" ixy="0" ixz="0" iyy="100" iyz="0" izz="100" />
        </inertial>
        <visual>
            <origin xyz="0 -0.1205144613008558 -0.4478812690490514" rpy="0 0 0"/>
            <geometry>
                <box size="0.018630596951905498 0.2410289226017116 0.8957625380981028" />
            </geometry>
            <material name="Blue">
                <color rgba="0 0.0 1.0 1.0"/>
            </material>
        </visual>
        <collision>
            <origin xyz="0 -0.1205144613008558 -0.4478812690490514" rpy="0 0 0"/>
            <geometry>
                <box size="0.018630596951905498 0.2410289226017116 0.8957625380981028" />
            </geometry>
        </collision>
    </link>
    <joint name="Link5_Link6" type="revolute">
       <parent link="Link5"/>
       <child  link="Link6"/>
       <origin rpy="0 0 0" xyz="0.009315298475952749 -0.1205144613008558 0.0" />
     <axis xyz="0 1 0"/>
       <limit effort="0.0" lower="-3.14159" upper="3.14159" velocity="0.0"/>
    </joint>
    <link name="Link6">
        <inertial>
            <origin xyz="0.23785365417037263 0 0.008424089724380801" rpy="0 0 0"/>
            <mass value="1" />
            <inertia ixx="100" ixy="0" ixz="0" iyy="100" iyz="0" izz="100" />
        </inertial>
        <visual>
            <origin xyz="0.23785365417037263 0 0.008424089724380801" rpy="0 0 0"/>
            <geometry>
                <box size="0.47570730834074526 0.5680252740537848 0.016848179448761602" />
            </geometry>
            <material name="Green">
                <color rgba="0 1.0 0.0 1.0"/>
            </material>
        </visual>
        <collision>
            <origin xyz="0.23785365417037263 0 0.008424089724380801" rpy="0 0 0"/>
            <geometry>
                <box size="0.47570730834074526 0.5680252740537848 0.016848179448761602" />
            </geometry>
        </collision>
    </link>
</robot>