<robot name = "robot">
    <link name="Link0">
        <inertial>
            <origin xyz="0 0 2.494014584647797" rpy="0 0 0"/>
            <mass value="1" />
            <inertia ixx="100" ixy="0" ixz="0" iyy="100" iyz="0" izz="100" />
        </inertial>
        <visual>
            <origin xyz="0 0 2.494014584647797" rpy="0 0 0"/>
            <geometry>
                <box size="0.9288042894944294 0.6597921804518374 0.9880291692955934" />
            </geometry>
            <material name="Green">
                <color rgba="0 1.0 0.0 1.0"/>
            </material>
        </visual>
        <collision>
            <origin xyz="0 0 2.494014584647797" rpy="0 0 0"/>
            <geometry>
                <box size="0.9288042894944294 0.6597921804518374 0.9880291692955934" />
            </geometry>
        </collision>
    </link>
    <joint name="Link0_Link1" type="revolute">
       <parent link="Link0"/>
       <child  link="Link1"/>
       <origin rpy="0 0 0" xyz="0 0.3298960902259187 2.9880291692955936" />
     <axis xyz="1 0 0"/>
       <limit effort="0.0" lower="-3.14159" upper="3.14159" velocity="0.0"/>
    </joint>
    <link name="Link1">
        <inertial>
            <origin xyz="0 0.3298960902259187 -0.4940145846477967" rpy="0 0 0"/>
            <mass value="1" />
            <inertia ixx="100" ixy="0" ixz="0" iyy="100" iyz="0" izz="100" />
        </inertial>
        <visual>
            <origin xyz="0 0.3298960902259187 -0.4940145846477967" rpy="0 0 0"/>
            <geometry>
                <box size="0.9288042894944294 0.6597921804518374 0.9880291692955934" />
            </geometry>
            <material name="Blue">
                <color rgba="0 0.0 1.0 1.0"/>
            </material>
        </visual>
        <collision>
            <origin xyz="0 0.3298960902259187 -0.4940145846477967" rpy="0 0 0"/>
            <geometry>
                <box size="0.9288042894944294 0.6597921804518374 0.9880291692955934" />
            </geometry>
        </collision>
    </link>
    <joint name="Link1_Link2" type="revolute">
       <parent link="Link1"/>
       <child  link="Link2"/>
       <origin rpy="0 0 0" xyz="0 0.6597921804518374 0.0" />
     <axis xyz="1 0 0"/>
       <limit effort="0.0" lower="-3.14159" upper="3.14159" velocity="0.0"/>
    </joint>
    <link name="Link2">
        <inertial>
            <origin xyz="0 0.48942785330118976 -0.21428071158533357" rpy="0 0 0"/>
            <mass value="1" />
            <inertia ixx="100" ixy="0" ixz="0" iyy="100" iyz="0" izz="100" />
        </inertial>
        <visual>
            <origin xyz="0 0.48942785330118976 -0.21428071158533357" rpy="0 0 0"/>
            <geometry>
                <box size="0.7981694485400308 0.9788557066023795 0.42856142317066714" />
            </geometry>
            <material name="Green">
                <color rgba="0 1.0 0.0 1.0"/>
            </material>
        </visual>
        <collision>
            <origin xyz="0 0.48942785330118976 -0.21428071158533357" rpy="0 0 0"/>
            <geometry>
                <box size="0.7981694485400308 0.9788557066023795 0.42856142317066714" />
            </geometry>
        </collision>
    </link>
    <joint name="Link2_Link3" type="revolute">
       <parent link="Link2"/>
       <child  link="Link3"/>
       <origin rpy="0 0 0" xyz="0 0.9788557066023795 0.0" />
     <axis xyz="1 0 0"/>
       <limit effort="0.0" lower="-3.14159" upper="3.14159" velocity="0.0"/>
    </joint>
    <link name="Link3">
        <inertial>
            <origin xyz="0 0.07405224261347304 -0.28447479101156076" rpy="0 0 0"/>
            <mass value="1" />
            <inertia ixx="100" ixy="0" ixz="0" iyy="100" iyz="0" izz="100" />
        </inertial>
        <visual>
            <origin xyz="0 0.07405224261347304 -0.28447479101156076" rpy="0 0 0"/>
            <geometry>
                <box size="0.5089053865387884 0.14810448522694608 0.5689495820231215" />
            </geometry>
            <material name="Blue">
                <color rgba="0 0.0 1.0 1.0"/>
            </material>
        </visual>
        <collision>
            <origin xyz="0 0.07405224261347304 -0.28447479101156076" rpy="0 0 0"/>
            <geometry>
                <box size="0.5089053865387884 0.14810448522694608 0.5689495820231215" />
            </geometry>
        </collision>
    </link>
    <joint name="Link3_Link4" type="revolute">
       <parent link="Link3"/>
       <child  link="Link4"/>
       <origin rpy="0 0 0" xyz="0 0.0 0.0" />
     <axis xyz="1 0 0"/>
       <limit effort="0.0" lower="-3.14159" upper="3.14159" velocity="0.0"/>
    </joint>
    <link name="Link4">
        <inertial>
            <origin xyz="0 -0.09791631247954768 0.23329143856809442" rpy="0 0 0"/>
            <mass value="1" />
            <inertia ixx="100" ixy="0" ixz="0" iyy="100" iyz="0" izz="100" />
        </inertial>
        <visual>
            <origin xyz="0 -0.09791631247954768 0.23329143856809442" rpy="0 0 0"/>
            <geometry>
                <box size="0.8181536584122524 0.19583262495909537 0.46658287713618884" />
            </geometry>
            <material name="Blue">
                <color rgba="0 0.0 1.0 1.0"/>
            </material>
        </visual>
        <collision>
            <origin xyz="0 -0.09791631247954768 0.23329143856809442" rpy="0 0 0"/>
            <geometry>
                <box size="0.8181536584122524 0.19583262495909537 0.46658287713618884" />
            </geometry>
        </collision>
    </link>
    <joint name="Link4_Link5" type="revolute">
       <parent link="Link4"/>
       <child  link="Link5"/>
       <origin rpy="0 0 0" xyz="-0.4090768292061262 -0.09791631247954768 0.46658287713618884" />
     <axis xyz="0 1 0"/>
       <limit effort="0.0" lower="-3.14159" upper="3.14159" velocity="0.0"/>
    </joint>
    <link name="Link5">
        <inertial>
            <origin xyz="-0.4802946828365172 0 -0.22419082834962734" rpy="0 0 0"/>
            <mass value="1" />
            <inertia ixx="100" ixy="0" ixz="0" iyy="100" iyz="0" izz="100" />
        </inertial>
        <visual>
            <origin xyz="-0.4802946828365172 0 -0.22419082834962734" rpy="0 0 0"/>
            <geometry>
                <box size="0.9605893656730344 0.5438752238816901 0.44838165669925467" />
            </geometry>
            <material name="Blue">
                <color rgba="0 0.0 1.0 1.0"/>
            </material>
        </visual>
        <collision>
            <origin xyz="-0.4802946828365172 0 -0.22419082834962734" rpy="0 0 0"/>
            <geometry>
                <box size="0.9605893656730344 0.5438752238816901 0.44838165669925467" />
            </geometry>
        </collision>
    </link>
    <joint name="Link5_Link6" type="revolute">
       <parent link="Link5"/>
       <child  link="Link6"/>
       <origin rpy="0 0 0" xyz="0.0 0 0.0" />
     <axis xyz="0 1 0"/>
       <limit effort="0.0" lower="-3.14159" upper="3.14159" velocity="0.0"/>
    </joint>
    <link name="Link6">
        <inertial>
            <origin xyz="0.03475403286883477 0 -0.4482067962937276" rpy="0 0 0"/>
            <mass value="1" />
            <inertia ixx="100" ixy="0" ixz="0" iyy="100" iyz="0" izz="100" />
        </inertial>
        <visual>
            <origin xyz="0.03475403286883477 0 -0.4482067962937276" rpy="0 0 0"/>
            <geometry>
                <box size="0.06950806573766954 0.4071669705322407 0.8964135925874552" />
            </geometry>
            <material name="Blue">
                <color rgba="0 0.0 1.0 1.0"/>
            </material>
        </visual>
        <collision>
            <origin xyz="0.03475403286883477 0 -0.4482067962937276" rpy="0 0 0"/>
            <geometry>
                <box size="0.06950806573766954 0.4071669705322407 0.8964135925874552" />
            </geometry>
        </collision>
    </link>
</robot>