<robot name = "robot">
    <link name="Link0">
        <inertial>
            <origin xyz="0 0 2.3399343370790944" rpy="0 0 0"/>
            <mass value="1" />
            <inertia ixx="100" ixy="0" ixz="0" iyy="100" iyz="0" izz="100" />
        </inertial>
        <visual>
            <origin xyz="0 0 2.3399343370790944" rpy="0 0 0"/>
            <geometry>
                <box size="0.7860914426222678 0.37227369929770915 0.6798686741581886" />
            </geometry>
            <material name="Green">
                <color rgba="0 1.0 0.0 1.0"/>
            </material>
        </visual>
        <collision>
            <origin xyz="0 0 2.3399343370790944" rpy="0 0 0"/>
            <geometry>
                <box size="0.7860914426222678 0.37227369929770915 0.6798686741581886" />
            </geometry>
        </collision>
    </link>
    <joint name="Link0_Link1" type="revolute">
       <parent link="Link0"/>
       <child  link="Link1"/>
       <origin rpy="0 0 0" xyz="0 0.18613684964885457 2.6798686741581887" />
     <axis xyz="1 0 0"/>
       <limit effort="0.0" lower="-3.14159" upper="3.14159" velocity="0.0"/>
    </joint>
    <link name="Link1">
        <inertial>
            <origin xyz="0 0.18613684964885457 -0.3399343370790943" rpy="0 0 0"/>
            <mass value="1" />
            <inertia ixx="100" ixy="0" ixz="0" iyy="100" iyz="0" izz="100" />
        </inertial>
        <visual>
            <origin xyz="0 0.18613684964885457 -0.3399343370790943" rpy="0 0 0"/>
            <geometry>
                <box size="0.7860914426222678 0.37227369929770915 0.6798686741581886" />
            </geometry>
            <material name="Blue">
                <color rgba="0 0.0 1.0 1.0"/>
            </material>
        </visual>
        <collision>
            <origin xyz="0 0.18613684964885457 -0.3399343370790943" rpy="0 0 0"/>
            <geometry>
                <box size="0.7860914426222678 0.37227369929770915 0.6798686741581886" />
            </geometry>
        </collision>
    </link>
    <joint name="Link1_Link2" type="revolute">
       <parent link="Link1"/>
       <child  link="Link2"/>
       <origin rpy="0 0 0" xyz="0.3930457213111339 0.18613684964885457 0.0" />
     <axis xyz="0 1 0"/>
       <limit effort="0.0" lower="-3.14159" upper="3.14159" velocity="0.0"/>
    </joint>
    <link name="Link2">
        <inertial>
            <origin xyz="0.44187134443011067 0 -0.2520483839668376" rpy="0 0 0"/>
            <mass value="1" />
            <inertia ixx="100" ixy="0" ixz="0" iyy="100" iyz="0" izz="100" />
        </inertial>
        <visual>
            <origin xyz="0.44187134443011067 0 -0.2520483839668376" rpy="0 0 0"/>
            <geometry>
                <box size="0.8837426888602213 0.4918506527490025 0.5040967679336752" />
            </geometry>
            <material name="Green">
                <color rgba="0 1.0 0.0 1.0"/>
            </material>
        </visual>
        <collision>
            <origin xyz="0.44187134443011067 0 -0.2520483839668376" rpy="0 0 0"/>
            <geometry>
                <box size="0.8837426888602213 0.4918506527490025 0.5040967679336752" />
            </geometry>
        </collision>
    </link>
    <joint name="Link2_Link3" type="revolute">
       <parent link="Link2"/>
       <child  link="Link3"/>
       <origin rpy="0 0 0" xyz="0.44187134443011067 0.24592532637450126 0.0" />
     <axis xyz="1 0 0"/>
       <limit effort="0.0" lower="-3.14159" upper="3.14159" velocity="0.0"/>
    </joint>
    <link name="Link3">
        <inertial>
            <origin xyz="0 0.008642908948367667 -0.18655054614490152" rpy="0 0 0"/>
            <mass value="1" />
            <inertia ixx="100" ixy="0" ixz="0" iyy="100" iyz="0" izz="100" />
        </inertial>
        <visual>
            <origin xyz="0 0.008642908948367667 -0.18655054614490152" rpy="0 0 0"/>
            <geometry>
                <box size="0.931172175561464 0.017285817896735334 0.37310109228980304" />
            </geometry>
            <material name="Green">
                <color rgba="0 1.0 0.0 1.0"/>
            </material>
        </visual>
        <collision>
            <origin xyz="0 0.008642908948367667 -0.18655054614490152" rpy="0 0 0"/>
            <geometry>
                <box size="0.931172175561464 0.017285817896735334 0.37310109228980304" />
            </geometry>
        </collision>
    </link>
    <joint name="Link3_Link4" type="revolute">
       <parent link="Link3"/>
       <child  link="Link4"/>
       <origin rpy="0 0 0" xyz="-0.465586087780732 0.008642908948367667 0.0" />
     <axis xyz="0 1 0"/>
       <limit effort="0.0" lower="-3.14159" upper="3.14159" velocity="0.0"/>
    </joint>
    <link name="Link4">
        <inertial>
            <origin xyz="-0.14087770302038571 0 0.19142221928715863" rpy="0 0 0"/>
            <mass value="1" />
            <inertia ixx="100" ixy="0" ixz="0" iyy="100" iyz="0" izz="100" />
        </inertial>
        <visual>
            <origin xyz="-0.14087770302038571 0 0.19142221928715863" rpy="0 0 0"/>
            <geometry>
                <box size="0.28175540604077143 0.3977385614094566 0.38284443857431727" />
            </geometry>
            <material name="Blue">
                <color rgba="0 0.0 1.0 1.0"/>
            </material>
        </visual>
        <collision>
            <origin xyz="-0.14087770302038571 0 0.19142221928715863" rpy="0 0 0"/>
            <geometry>
                <box size="0.28175540604077143 0.3977385614094566 0.38284443857431727" />
            </geometry>
        </collision>
    </link>
</robot>