<robot name = "robot">
    <link name="Link0">
        <inertial>
            <origin xyz="0 0 2.4100605374620008" rpy="0 0 0"/>
            <mass value="1" />
            <inertia ixx="100" ixy="0" ixz="0" iyy="100" iyz="0" izz="100" />
        </inertial>
        <visual>
            <origin xyz="0 0 2.4100605374620008" rpy="0 0 0"/>
            <geometry>
                <box size="0.6785780028395751 0.25634494316049994 0.8201210749240017" />
            </geometry>
            <material name="Green">
                <color rgba="0 1.0 0.0 1.0"/>
            </material>
        </visual>
        <collision>
            <origin xyz="0 0 2.4100605374620008" rpy="0 0 0"/>
            <geometry>
                <box size="0.6785780028395751 0.25634494316049994 0.8201210749240017" />
            </geometry>
        </collision>
    </link>
    <joint name="Link0_Link1" type="revolute">
       <parent link="Link0"/>
       <child  link="Link1"/>
       <origin rpy="0 0 0" xyz="0 0.12817247158024997 2.8201210749240015" />
     <axis xyz="1 0 0"/>
       <limit effort="0.0" lower="-3.14159" upper="3.14159" velocity="0.0"/>
    </joint>
    <link name="Link1">
        <inertial>
            <origin xyz="0 0.12817247158024997 -0.41006053746200083" rpy="0 0 0"/>
            <mass value="1" />
            <inertia ixx="100" ixy="0" ixz="0" iyy="100" iyz="0" izz="100" />
        </inertial>
        <visual>
            <origin xyz="0 0.12817247158024997 -0.41006053746200083" rpy="0 0 0"/>
            <geometry>
                <box size="0.6785780028395751 0.25634494316049994 0.8201210749240017" />
            </geometry>
            <material name="Blue">
                <color rgba="0 0.0 1.0 1.0"/>
            </material>
        </visual>
        <collision>
            <origin xyz="0 0.12817247158024997 -0.41006053746200083" rpy="0 0 0"/>
            <geometry>
                <box size="0.6785780028395751 0.25634494316049994 0.8201210749240017" />
            </geometry>
        </collision>
    </link>
    <joint name="Link1_Link2" type="revolute">
       <parent link="Link1"/>
       <child  link="Link2"/>
       <origin rpy="0 0 0" xyz="0 0.0 0.0" />
     <axis xyz="1 0 0"/>
       <limit effort="0.0" lower="-3.14159" upper="3.14159" velocity="0.0"/>
    </joint>
    <link name="Link2">
        <inertial>
            <origin xyz="0 -0.45601202271076363 0.4447376267823937" rpy="0 0 0"/>
            <mass value="1" />
            <inertia ixx="100" ixy="0" ixz="0" iyy="100" iyz="0" izz="100" />
        </inertial>
        <visual>
            <origin xyz="0 -0.45601202271076363 0.4447376267823937" rpy="0 0 0"/>
            <geometry>
                <box size="0.7390120251620472 0.9120240454215273 0.8894752535647874" />
            </geometry>
            <material name="Green">
                <color rgba="0 1.0 0.0 1.0"/>
            </material>
        </visual>
        <collision>
            <origin xyz="0 -0.45601202271076363 0.4447376267823937" rpy="0 0 0"/>
            <geometry>
                <box size="0.7390120251620472 0.9120240454215273 0.8894752535647874" />
            </geometry>
        </collision>
    </link>
    <joint name="Link2_Link3" type="revolute">
       <parent link="Link2"/>
       <child  link="Link3"/>
       <origin rpy="0 0 0" xyz="0 0.0 0.8894752535647874" />
     <axis xyz="1 0 0"/>
       <limit effort="0.0" lower="-3.14159" upper="3.14159" velocity="0.0"/>
    </joint>
    <link name="Link3">
        <inertial>
            <origin xyz="0 0.35710935515276643 0.49530397814532434" rpy="0 0 0"/>
            <mass value="1" />
            <inertia ixx="100" ixy="0" ixz="0" iyy="100" iyz="0" izz="100" />
        </inertial>
        <visual>
            <origin xyz="0 0.35710935515276643 0.49530397814532434" rpy="0 0 0"/>
            <geometry>
                <box size="0.21149760895645087 0.7142187103055329 0.9906079562906487" />
            </geometry>
            <material name="Green">
                <color rgba="0 1.0 0.0 1.0"/>
            </material>
        </visual>
        <collision>
            <origin xyz="0 0.35710935515276643 0.49530397814532434" rpy="0 0 0"/>
            <geometry>
                <box size="0.21149760895645087 0.7142187103055329 0.9906079562906487" />
            </geometry>
        </collision>
    </link>
    <joint name="Link3_Link4" type="revolute">
       <parent link="Link3"/>
       <child  link="Link4"/>
       <origin rpy="0 0 0" xyz="0 0.0 0.9906079562906487" />
     <axis xyz="1 0 0"/>
       <limit effort="0.0" lower="-3.14159" upper="3.14159" velocity="0.0"/>
    </joint>
    <link name="Link4">
        <inertial>
            <origin xyz="0 -0.4332011875938206 -0.4952195545642421" rpy="0 0 0"/>
            <mass value="1" />
            <inertia ixx="100" ixy="0" ixz="0" iyy="100" iyz="0" izz="100" />
        </inertial>
        <visual>
            <origin xyz="0 -0.4332011875938206 -0.4952195545642421" rpy="0 0 0"/>
            <geometry>
                <box size="0.7066375233808266 0.8664023751876412 0.9904391091284842" />
            </geometry>
            <material name="Green">
                <color rgba="0 1.0 0.0 1.0"/>
            </material>
        </visual>
        <collision>
            <origin xyz="0 -0.4332011875938206 -0.4952195545642421" rpy="0 0 0"/>
            <geometry>
                <box size="0.7066375233808266 0.8664023751876412 0.9904391091284842" />
            </geometry>
        </collision>
    </link>
    <joint name="Link4_Link5" type="revolute">
       <parent link="Link4"/>
       <child  link="Link5"/>
       <origin rpy="0 0 0" xyz="0 0.0 0.0" />
     <axis xyz="1 0 0"/>
       <limit effort="0.0" lower="-3.14159" upper="3.14159" velocity="0.0"/>
    </joint>
    <link name="Link5">
        <inertial>
            <origin xyz="0 0.07757513858905657 -0.2201880276147365" rpy="0 0 0"/>
            <mass value="1" />
            <inertia ixx="100" ixy="0" ixz="0" iyy="100" iyz="0" izz="100" />
        </inertial>
        <visual>
            <origin xyz="0 0.07757513858905657 -0.2201880276147365" rpy="0 0 0"/>
            <geometry>
                <box size="0.30995969463027695 0.15515027717811314 0.440376055229473" />
            </geometry>
            <material name="Blue">
                <color rgba="0 0.0 1.0 1.0"/>
            </material>
        </visual>
        <collision>
            <origin xyz="0 0.07757513858905657 -0.2201880276147365" rpy="0 0 0"/>
            <geometry>
                <box size="0.30995969463027695 0.15515027717811314 0.440376055229473" />
            </geometry>
        </collision>
    </link>
</robot>