<robot name = "robot">
    <link name="Link0">
        <inertial>
            <origin xyz="0 0 2.2583535816153475" rpy="0 0 0"/>
            <mass value="1" />
            <inertia ixx="100" ixy="0" ixz="0" iyy="100" iyz="0" izz="100" />
        </inertial>
        <visual>
            <origin xyz="0 0 2.2583535816153475" rpy="0 0 0"/>
            <geometry>
                <box size="0.2366750642504044 0.6448710076956025 0.5167071632306953" />
            </geometry>
            <material name="Green">
                <color rgba="0 1.0 0.0 1.0"/>
            </material>
        </visual>
        <collision>
            <origin xyz="0 0 2.2583535816153475" rpy="0 0 0"/>
            <geometry>
                <box size="0.2366750642504044 0.6448710076956025 0.5167071632306953" />
            </geometry>
        </collision>
    </link>
    <joint name="Link0_Link1" type="revolute">
       <parent link="Link0"/>
       <child  link="Link1"/>
       <origin rpy="0 0 0" xyz="0 0.32243550384780123 2.5167071632306954" />
     <axis xyz="1 0 0"/>
       <limit effort="0.0" lower="-3.14159" upper="3.14159" velocity="0.0"/>
    </joint>
    <link name="Link1">
        <inertial>
            <origin xyz="0 0.32243550384780123 -0.25835358161534766" rpy="0 0 0"/>
            <mass value="1" />
            <inertia ixx="100" ixy="0" ixz="0" iyy="100" iyz="0" izz="100" />
        </inertial>
        <visual>
            <origin xyz="0 0.32243550384780123 -0.25835358161534766" rpy="0 0 0"/>
            <geometry>
                <box size="0.2366750642504044 0.6448710076956025 0.5167071632306953" />
            </geometry>
            <material name="Blue">
                <color rgba="0 0.0 1.0 1.0"/>
            </material>
        </visual>
        <collision>
            <origin xyz="0 0.32243550384780123 -0.25835358161534766" rpy="0 0 0"/>
            <geometry>
                <box size="0.2366750642504044 0.6448710076956025 0.5167071632306953" />
            </geometry>
        </collision>
    </link>
    <joint name="Link1_Link2" type="revolute">
       <parent link="Link1"/>
       <child  link="Link2"/>
       <origin rpy="0 0 0" xyz="0.1183375321252022 0.32243550384780123 0.0" />
     <axis xyz="0 1 0"/>
       <limit effort="0.0" lower="-3.14159" upper="3.14159" velocity="0.0"/>
    </joint>
    <link name="Link2">
        <inertial>
            <origin xyz="0.21989268491303277 0 -0.00017417864296565" rpy="0 0 0"/>
            <mass value="1" />
            <inertia ixx="100" ixy="0" ixz="0" iyy="100" iyz="0" izz="100" />
        </inertial>
        <visual>
            <origin xyz="0.21989268491303277 0 -0.00017417864296565" rpy="0 0 0"/>
            <geometry>
                <box size="0.43978536982606553 0.6945206470971995 0.0003483572859313" />
            </geometry>
            <material name="Green">
                <color rgba="0 1.0 0.0 1.0"/>
            </material>
        </visual>
        <collision>
            <origin xyz="0.21989268491303277 0 -0.00017417864296565" rpy="0 0 0"/>
            <geometry>
                <box size="0.43978536982606553 0.6945206470971995 0.0003483572859313" />
            </geometry>
        </collision>
    </link>
    <joint name="Link2_Link3" type="revolute">
       <parent link="Link2"/>
       <child  link="Link3"/>
       <origin rpy="0 0 0" xyz="0.43978536982606553 0 0.0" />
     <axis xyz="0 1 0"/>
       <limit effort="0.0" lower="-3.14159" upper="3.14159" velocity="0.0"/>
    </joint>
    <link name="Link3">
        <inertial>
            <origin xyz="0.34951154405766593 0 0.49575364573716296" rpy="0 0 0"/>
            <mass value="1" />
            <inertia ixx="100" ixy="0" ixz="0" iyy="100" iyz="0" izz="100" />
        </inertial>
        <visual>
            <origin xyz="0.34951154405766593 0 0.49575364573716296" rpy="0 0 0"/>
            <geometry>
                <box size="0.6990230881153319 0.8447147721762526 0.9915072914743259" />
            </geometry>
            <material name="Green">
                <color rgba="0 1.0 0.0 1.0"/>
            </material>
        </visual>
        <collision>
            <origin xyz="0.34951154405766593 0 0.49575364573716296" rpy="0 0 0"/>
            <geometry>
                <box size="0.6990230881153319 0.8447147721762526 0.9915072914743259" />
            </geometry>
        </collision>
    </link>
    <joint name="Link3_Link4" type="revolute">
       <parent link="Link3"/>
       <child  link="Link4"/>
       <origin rpy="0 0 0" xyz="0.34951154405766593 0.4223573860881263 0.9915072914743259" />
     <axis xyz="1 0 0"/>
       <limit effort="0.0" lower="-3.14159" upper="3.14159" velocity="0.0"/>
    </joint>
    <link name="Link4">
        <inertial>
            <origin xyz="0 0.02080451163892494 0.06313085871106872" rpy="0 0 0"/>
            <mass value="1" />
            <inertia ixx="100" ixy="0" ixz="0" iyy="100" iyz="0" izz="100" />
        </inertial>
        <visual>
            <origin xyz="0 0.02080451163892494 0.06313085871106872" rpy="0 0 0"/>
            <geometry>
                <box size="0.875093284984376 0.04160902327784988 0.12626171742213743" />
            </geometry>
            <material name="Green">
                <color rgba="0 1.0 0.0 1.0"/>
            </material>
        </visual>
        <collision>
            <origin xyz="0 0.02080451163892494 0.06313085871106872" rpy="0 0 0"/>
            <geometry>
                <box size="0.875093284984376 0.04160902327784988 0.12626171742213743" />
            </geometry>
        </collision>
    </link>
    <joint name="Link4_Link5" type="revolute">
       <parent link="Link4"/>
       <child  link="Link5"/>
       <origin rpy="0 0 0" xyz="-0.437546642492188 0.02080451163892494 0.12626171742213743" />
     <axis xyz="0 1 0"/>
       <limit effort="0.0" lower="-3.14159" upper="3.14159" velocity="0.0"/>
    </joint>
    <link name="Link5">
        <inertial>
            <origin xyz="-0.44356162499324925 0 0.15769240861609896" rpy="0 0 0"/>
            <mass value="1" />
            <inertia ixx="100" ixy="0" ixz="0" iyy="100" iyz="0" izz="100" />
        </inertial>
        <visual>
            <origin xyz="-0.44356162499324925 0 0.15769240861609896" rpy="0 0 0"/>
            <geometry>
                <box size="0.8871232499864985 0.343380290966689 0.3153848172321979" />
            </geometry>
            <material name="Blue">
                <color rgba="0 0.0 1.0 1.0"/>
            </material>
        </visual>
        <collision>
            <origin xyz="-0.44356162499324925 0 0.15769240861609896" rpy="0 0 0"/>
            <geometry>
                <box size="0.8871232499864985 0.343380290966689 0.3153848172321979" />
            </geometry>
        </collision>
    </link>
    <joint name="Link5_Link6" type="revolute">
       <parent link="Link5"/>
       <child  link="Link6"/>
       <origin rpy="0 0 0" xyz="-0.44356162499324925 0.1716901454833445 0.3153848172321979" />
     <axis xyz="1 0 0"/>
       <limit effort="0.0" lower="-3.14159" upper="3.14159" velocity="0.0"/>
    </joint>
    <link name="Link6">
        <inertial>
            <origin xyz="0 0.03701046815585557 -0.019158614977531352" rpy="0 0 0"/>
            <mass value="1" />
            <inertia ixx="100" ixy="0" ixz="0" iyy="100" iyz="0" izz="100" />
        </inertial>
        <visual>
            <origin xyz="0 0.03701046815585557 -0.019158614977531352" rpy="0 0 0"/>
            <geometry>
                <box size="0.6478657172720774 0.07402093631171114 0.038317229955062704" />
            </geometry>
            <material name="Blue">
                <color rgba="0 0.0 1.0 1.0"/>
            </material>
        </visual>
        <collision>
            <origin xyz="0 0.03701046815585557 -0.019158614977531352" rpy="0 0 0"/>
            <geometry>
                <box size="0.6478657172720774 0.07402093631171114 0.038317229955062704" />
            </geometry>
        </collision>
    </link>
</robot>