<robot name = "robot">
    <link name="Link0">
        <inertial>
            <origin xyz="0 0 2.358056588435222" rpy="0 0 0"/>
            <mass value="1" />
            <inertia ixx="100" ixy="0" ixz="0" iyy="100" iyz="0" izz="100" />
        </inertial>
        <visual>
            <origin xyz="0 0 2.358056588435222" rpy="0 0 0"/>
            <geometry>
                <box size="0.8765946962885341 0.2274598724314828 0.7161131768704434" />
            </geometry>
            <material name="Green">
                <color rgba="0 1.0 0.0 1.0"/>
            </material>
        </visual>
        <collision>
            <origin xyz="0 0 2.358056588435222" rpy="0 0 0"/>
            <geometry>
                <box size="0.8765946962885341 0.2274598724314828 0.7161131768704434" />
            </geometry>
        </collision>
    </link>
    <joint name="Link0_Link1" type="revolute">
       <parent link="Link0"/>
       <child  link="Link1"/>
       <origin rpy="0 0 0" xyz="0 0.1137299362157414 2.7161131768704436" />
     <axis xyz="1 0 0"/>
       <limit effort="0.0" lower="-3.14159" upper="3.14159" velocity="0.0"/>
    </joint>
    <link name="Link1">
        <inertial>
            <origin xyz="0 0.1137299362157414 -0.3580565884352217" rpy="0 0 0"/>
            <mass value="1" />
            <inertia ixx="100" ixy="0" ixz="0" iyy="100" iyz="0" izz="100" />
        </inertial>
        <visual>
            <origin xyz="0 0.1137299362157414 -0.3580565884352217" rpy="0 0 0"/>
            <geometry>
                <box size="0.8765946962885341 0.2274598724314828 0.7161131768704434" />
            </geometry>
            <material name="Blue">
                <color rgba="0 0.0 1.0 1.0"/>
            </material>
        </visual>
        <collision>
            <origin xyz="0 0.1137299362157414 -0.3580565884352217" rpy="0 0 0"/>
            <geometry>
                <box size="0.8765946962885341 0.2274598724314828 0.7161131768704434" />
            </geometry>
        </collision>
    </link>
    <joint name="Link1_Link2" type="revolute">
       <parent link="Link1"/>
       <child  link="Link2"/>
       <origin rpy="0 0 0" xyz="0 0.2274598724314828 0.0" />
     <axis xyz="1 0 0"/>
       <limit effort="0.0" lower="-3.14159" upper="3.14159" velocity="0.0"/>
    </joint>
    <link name="Link2">
        <inertial>
            <origin xyz="0 0.26874598584366377 -0.45191977266173133" rpy="0 0 0"/>
            <mass value="1" />
            <inertia ixx="100" ixy="0" ixz="0" iyy="100" iyz="0" izz="100" />
        </inertial>
        <visual>
            <origin xyz="0 0.26874598584366377 -0.45191977266173133" rpy="0 0 0"/>
            <geometry>
                <box size="0.047907050196408396 0.5374919716873275 0.9038395453234627" />
            </geometry>
            <material name="Blue">
                <color rgba="0 0.0 1.0 1.0"/>
            </material>
        </visual>
        <collision>
            <origin xyz="0 0.26874598584366377 -0.45191977266173133" rpy="0 0 0"/>
            <geometry>
                <box size="0.047907050196408396 0.5374919716873275 0.9038395453234627" />
            </geometry>
        </collision>
    </link>
    <joint name="Link2_Link3" type="revolute">
       <parent link="Link2"/>
       <child  link="Link3"/>
       <origin rpy="0 0 0" xyz="0 0.5374919716873275 0.0" />
     <axis xyz="1 0 0"/>
       <limit effort="0.0" lower="-3.14159" upper="3.14159" velocity="0.0"/>
    </joint>
    <link name="Link3">
        <inertial>
            <origin xyz="0 0.3797324315534903 -0.1607603838124655" rpy="0 0 0"/>
            <mass value="1" />
            <inertia ixx="100" ixy="0" ixz="0" iyy="100" iyz="0" izz="100" />
        </inertial>
        <visual>
            <origin xyz="0 0.3797324315534903 -0.1607603838124655" rpy="0 0 0"/>
            <geometry>
                <box size="0.41642231143537134 0.7594648631069806 0.321520767624931" />
            </geometry>
            <material name="Green">
                <color rgba="0 1.0 0.0 1.0"/>
            </material>
        </visual>
        <collision>
            <origin xyz="0 0.3797324315534903 -0.1607603838124655" rpy="0 0 0"/>
            <geometry>
                <box size="0.41642231143537134 0.7594648631069806 0.321520767624931" />
            </geometry>
        </collision>
    </link>
    <joint name="Link3_Link4" type="revolute">
       <parent link="Link3"/>
       <child  link="Link4"/>
       <origin rpy="0 0 0" xyz="-0.20821115571768567 0.3797324315534903 0.0" />
     <axis xyz="0 1 0"/>
       <limit effort="0.0" lower="-3.14159" upper="3.14159" velocity="0.0"/>
    </joint>
    <link name="Link4">
        <inertial>
            <origin xyz="-0.06944097804636029 0 -0.19994505522162415" rpy="0 0 0"/>
            <mass value="1" />
            <inertia ixx="100" ixy="0" ixz="0" iyy="100" iyz="0" izz="100" />
        </inertial>
        <visual>
            <origin xyz="-0.06944097804636029 0 -0.19994505522162415" rpy="0 0 0"/>
            <geometry>
                <box size="0.13888195609272058 0.8829719362179671 0.3998901104432483" />
            </geometry>
            <material name="Green">
                <color rgba="0 1.0 0.0 1.0"/>
            </material>
        </visual>
        <collision>
            <origin xyz="-0.06944097804636029 0 -0.19994505522162415" rpy="0 0 0"/>
            <geometry>
                <box size="0.13888195609272058 0.8829719362179671 0.3998901104432483" />
            </geometry>
        </collision>
    </link>
    <joint name="Link4_Link5" type="revolute">
       <parent link="Link4"/>
       <child  link="Link5"/>
       <origin rpy="0 0 0" xyz="-0.13888195609272058 0 0.0" />
     <axis xyz="0 1 0"/>
       <limit effort="0.0" lower="-3.14159" upper="3.14159" velocity="0.0"/>
    </joint>
    <link name="Link5">
        <inertial>
            <origin xyz="-0.2559917185914971 0 -0.2028550405961202" rpy="0 0 0"/>
            <mass value="1" />
            <inertia ixx="100" ixy="0" ixz="0" iyy="100" iyz="0" izz="100" />
        </inertial>
        <visual>
            <origin xyz="-0.2559917185914971 0 -0.2028550405961202" rpy="0 0 0"/>
            <geometry>
                <box size="0.5119834371829942 0.1089357586884292 0.4057100811922404" />
            </geometry>
            <material name="Green">
                <color rgba="0 1.0 0.0 1.0"/>
            </material>
        </visual>
        <collision>
            <origin xyz="-0.2559917185914971 0 -0.2028550405961202" rpy="0 0 0"/>
            <geometry>
                <box size="0.5119834371829942 0.1089357586884292 0.4057100811922404" />
            </geometry>
        </collision>
    </link>
    <joint name="Link5_Link6" type="revolute">
       <parent link="Link5"/>
       <child  link="Link6"/>
       <origin rpy="0 0 0" xyz="-0.5119834371829942 0 0.0" />
     <axis xyz="0 1 0"/>
       <limit effort="0.0" lower="-3.14159" upper="3.14159" velocity="0.0"/>
    </joint>
    <link name="Link6">
        <inertial>
            <origin xyz="-0.12090287253536547 0 -0.42511306309892044" rpy="0 0 0"/>
            <mass value="1" />
            <inertia ixx="100" ixy="0" ixz="0" iyy="100" iyz="0" izz="100" />
        </inertial>
        <visual>
            <origin xyz="-0.12090287253536547 0 -0.42511306309892044" rpy="0 0 0"/>
            <geometry>
                <box size="0.24180574507073094 0.6613170425567021 0.8502261261978409" />
            </geometry>
            <material name="Green">
                <color rgba="0 1.0 0.0 1.0"/>
            </material>
        </visual>
        <collision>
            <origin xyz="-0.12090287253536547 0 -0.42511306309892044" rpy="0 0 0"/>
            <geometry>
                <box size="0.24180574507073094 0.6613170425567021 0.8502261261978409" />
            </geometry>
        </collision>
    </link>
</robot>