<robot name = "robot">
    <link name="Link0">
        <inertial>
            <origin xyz="0 0 2.0997334597521626" rpy="0 0 0"/>
            <mass value="1" />
            <inertia ixx="100" ixy="0" ixz="0" iyy="100" iyz="0" izz="100" />
        </inertial>
        <visual>
            <origin xyz="0 0 2.0997334597521626" rpy="0 0 0"/>
            <geometry>
                <box size="0.7608333321660825 0.8590708955832399 0.19946691950432527" />
            </geometry>
            <material name="Green">
                <color rgba="0 1.0 0.0 1.0"/>
            </material>
        </visual>
        <collision>
            <origin xyz="0 0 2.0997334597521626" rpy="0 0 0"/>
            <geometry>
                <box size="0.7608333321660825 0.8590708955832399 0.19946691950432527" />
            </geometry>
        </collision>
    </link>
    <joint name="Link0_Link1" type="revolute">
       <parent link="Link0"/>
       <child  link="Link1"/>
       <origin rpy="0 0 0" xyz="0 0.42953544779161995 2.1994669195043253" />
     <axis xyz="1 0 0"/>
       <limit effort="0.0" lower="-3.14159" upper="3.14159" velocity="0.0"/>
    </joint>
    <link name="Link1">
        <inertial>
            <origin xyz="0 0.42953544779161995 -0.09973345975216263" rpy="0 0 0"/>
            <mass value="1" />
            <inertia ixx="100" ixy="0" ixz="0" iyy="100" iyz="0" izz="100" />
        </inertial>
        <visual>
            <origin xyz="0 0.42953544779161995 -0.09973345975216263" rpy="0 0 0"/>
            <geometry>
                <box size="0.7608333321660825 0.8590708955832399 0.19946691950432527" />
            </geometry>
            <material name="Blue">
                <color rgba="0 0.0 1.0 1.0"/>
            </material>
        </visual>
        <collision>
            <origin xyz="0 0.42953544779161995 -0.09973345975216263" rpy="0 0 0"/>
            <geometry>
                <box size="0.7608333321660825 0.8590708955832399 0.19946691950432527" />
            </geometry>
        </collision>
    </link>
    <joint name="Link1_Link2" type="revolute">
       <parent link="Link1"/>
       <child  link="Link2"/>
       <origin rpy="0 0 0" xyz="-0.38041666608304125 0.42953544779161995 0.0" />
     <axis xyz="0 1 0"/>
       <limit effort="0.0" lower="-3.14159" upper="3.14159" velocity="0.0"/>
    </joint>
    <link name="Link2">
        <inertial>
            <origin xyz="-0.37419071118054725 0 -0.1645249481794427" rpy="0 0 0"/>
            <mass value="1" />
            <inertia ixx="100" ixy="0" ixz="0" iyy="100" iyz="0" izz="100" />
        </inertial>
        <visual>
            <origin xyz="-0.37419071118054725 0 -0.1645249481794427" rpy="0 0 0"/>
            <geometry>
                <box size="0.7483814223610945 0.8921314256895282 0.3290498963588854" />
            </geometry>
            <material name="Green">
                <color rgba="0 1.0 0.0 1.0"/>
            </material>
        </visual>
        <collision>
            <origin xyz="-0.37419071118054725 0 -0.1645249481794427" rpy="0 0 0"/>
            <geometry>
                <box size="0.7483814223610945 0.8921314256895282 0.3290498963588854" />
            </geometry>
        </collision>
    </link>
    <joint name="Link2_Link3" type="revolute">
       <parent link="Link2"/>
       <child  link="Link3"/>
       <origin rpy="0 0 0" xyz="0.0 0 0.0" />
     <axis xyz="0 1 0"/>
       <limit effort="0.0" lower="-3.14159" upper="3.14159" velocity="0.0"/>
    </joint>
    <link name="Link3">
        <inertial>
            <origin xyz="0.26474871511794845 0 -0.2594775983053819" rpy="0 0 0"/>
            <mass value="1" />
            <inertia ixx="100" ixy="0" ixz="0" iyy="100" iyz="0" izz="100" />
        </inertial>
        <visual>
            <origin xyz="0.26474871511794845 0 -0.2594775983053819" rpy="0 0 0"/>
            <geometry>
                <box size="0.5294974302358969 0.8925336524106825 0.5189551966107638" />
            </geometry>
            <material name="Blue">
                <color rgba="0 0.0 1.0 1.0"/>
            </material>
        </visual>
        <collision>
            <origin xyz="0.26474871511794845 0 -0.2594775983053819" rpy="0 0 0"/>
            <geometry>
                <box size="0.5294974302358969 0.8925336524106825 0.5189551966107638" />
            </geometry>
        </collision>
    </link>
    <joint name="Link3_Link4" type="revolute">
       <parent link="Link3"/>
       <child  link="Link4"/>
       <origin rpy="0 0 0" xyz="0.0 0 0.0" />
     <axis xyz="0 1 0"/>
       <limit effort="0.0" lower="-3.14159" upper="3.14159" velocity="0.0"/>
    </joint>
    <link name="Link4">
        <inertial>
            <origin xyz="-0.07127421637043352 0 0.4359851200112723" rpy="0 0 0"/>
            <mass value="1" />
            <inertia ixx="100" ixy="0" ixz="0" iyy="100" iyz="0" izz="100" />
        </inertial>
        <visual>
            <origin xyz="-0.07127421637043352 0 0.4359851200112723" rpy="0 0 0"/>
            <geometry>
                <box size="0.14254843274086704 0.14615010899184977 0.8719702400225446" />
            </geometry>
            <material name="Blue">
                <color rgba="0 0.0 1.0 1.0"/>
            </material>
        </visual>
        <collision>
            <origin xyz="-0.07127421637043352 0 0.4359851200112723" rpy="0 0 0"/>
            <geometry>
                <box size="0.14254843274086704 0.14615010899184977 0.8719702400225446" />
            </geometry>
        </collision>
    </link>
</robot>