<robot name = "robot">
    <link name="Link0">
        <inertial>
            <origin xyz="0 0 2.0793229678810694" rpy="0 0 0"/>
            <mass value="1" />
            <inertia ixx="100" ixy="0" ixz="0" iyy="100" iyz="0" izz="100" />
        </inertial>
        <visual>
            <origin xyz="0 0 2.0793229678810694" rpy="0 0 0"/>
            <geometry>
                <box size="0.7357317332119934 0.7288959422016723 0.15864593576213848" />
            </geometry>
            <material name="Green">
                <color rgba="0 1.0 0.0 1.0"/>
            </material>
        </visual>
        <collision>
            <origin xyz="0 0 2.0793229678810694" rpy="0 0 0"/>
            <geometry>
                <box size="0.7357317332119934 0.7288959422016723 0.15864593576213848" />
            </geometry>
        </collision>
    </link>
    <joint name="Link0_Link1" type="revolute">
       <parent link="Link0"/>
       <child  link="Link1"/>
       <origin rpy="0 0 0" xyz="0 0.36444797110083615 2.1586459357621384" />
     <axis xyz="1 0 0"/>
       <limit effort="0.0" lower="-3.14159" upper="3.14159" velocity="0.0"/>
    </joint>
    <link name="Link1">
        <inertial>
            <origin xyz="0 0.36444797110083615 -0.07932296788106924" rpy="0 0 0"/>
            <mass value="1" />
            <inertia ixx="100" ixy="0" ixz="0" iyy="100" iyz="0" izz="100" />
        </inertial>
        <visual>
            <origin xyz="0 0.36444797110083615 -0.07932296788106924" rpy="0 0 0"/>
            <geometry>
                <box size="0.7357317332119934 0.7288959422016723 0.15864593576213848" />
            </geometry>
            <material name="Blue">
                <color rgba="0 0.0 1.0 1.0"/>
            </material>
        </visual>
        <collision>
            <origin xyz="0 0.36444797110083615 -0.07932296788106924" rpy="0 0 0"/>
            <geometry>
                <box size="0.7357317332119934 0.7288959422016723 0.15864593576213848" />
            </geometry>
        </collision>
    </link>
    <joint name="Link1_Link2" type="revolute">
       <parent link="Link1"/>
       <child  link="Link2"/>
       <origin rpy="0 0 0" xyz="0 0.7288959422016723 0.0" />
     <axis xyz="1 0 0"/>
       <limit effort="0.0" lower="-3.14159" upper="3.14159" velocity="0.0"/>
    </joint>
    <link name="Link2">
        <inertial>
            <origin xyz="0 0.05494306970143331 -0.380684477555232" rpy="0 0 0"/>
            <mass value="1" />
            <inertia ixx="100" ixy="0" ixz="0" iyy="100" iyz="0" izz="100" />
        </inertial>
        <visual>
            <origin xyz="0 0.05494306970143331 -0.380684477555232" rpy="0 0 0"/>
            <geometry>
                <box size="0.4035559633947331 0.10988613940286662 0.761368955110464" />
            </geometry>
            <material name="Blue">
                <color rgba="0 0.0 1.0 1.0"/>
            </material>
        </visual>
        <collision>
            <origin xyz="0 0.05494306970143331 -0.380684477555232" rpy="0 0 0"/>
            <geometry>
                <box size="0.4035559633947331 0.10988613940286662 0.761368955110464" />
            </geometry>
        </collision>
    </link>
    <joint name="Link2_Link3" type="revolute">
       <parent link="Link2"/>
       <child  link="Link3"/>
       <origin rpy="0 0 0" xyz="-0.20177798169736655 0.05494306970143331 0.0" />
     <axis xyz="0 1 0"/>
       <limit effort="0.0" lower="-3.14159" upper="3.14159" velocity="0.0"/>
    </joint>
    <link name="Link3">
        <inertial>
            <origin xyz="-0.15365151925661674 0 0.14265345576826488" rpy="0 0 0"/>
            <mass value="1" />
            <inertia ixx="100" ixy="0" ixz="0" iyy="100" iyz="0" izz="100" />
        </inertial>
        <visual>
            <origin xyz="-0.15365151925661674 0 0.14265345576826488" rpy="0 0 0"/>
            <geometry>
                <box size="0.3073030385132335 0.6233513455293981 0.28530691153652976" />
            </geometry>
            <material name="Blue">
                <color rgba="0 0.0 1.0 1.0"/>
            </material>
        </visual>
        <collision>
            <origin xyz="-0.15365151925661674 0 0.14265345576826488" rpy="0 0 0"/>
            <geometry>
                <box size="0.3073030385132335 0.6233513455293981 0.28530691153652976" />
            </geometry>
        </collision>
    </link>
    <joint name="Link3_Link4" type="revolute">
       <parent link="Link3"/>
       <child  link="Link4"/>
       <origin rpy="0 0 0" xyz="-0.15365151925661674 -0.31167567276469904 0.28530691153652976" />
     <axis xyz="1 0 0"/>
       <limit effort="0.0" lower="-3.14159" upper="3.14159" velocity="0.0"/>
    </joint>
    <link name="Link4">
        <inertial>
            <origin xyz="0 -0.3959558758634734 0.432395418294398" rpy="0 0 0"/>
            <mass value="1" />
            <inertia ixx="100" ixy="0" ixz="0" iyy="100" iyz="0" izz="100" />
        </inertial>
        <visual>
            <origin xyz="0 -0.3959558758634734 0.432395418294398" rpy="0 0 0"/>
            <geometry>
                <box size="0.2655241805617652 0.7919117517269468 0.864790836588796" />
            </geometry>
            <material name="Blue">
                <color rgba="0 0.0 1.0 1.0"/>
            </material>
        </visual>
        <collision>
            <origin xyz="0 -0.3959558758634734 0.432395418294398" rpy="0 0 0"/>
            <geometry>
                <box size="0.2655241805617652 0.7919117517269468 0.864790836588796" />
            </geometry>
        </collision>
    </link>
    <joint name="Link4_Link5" type="revolute">
       <parent link="Link4"/>
       <child  link="Link5"/>
       <origin rpy="0 0 0" xyz="0 0.0 0.864790836588796" />
     <axis xyz="1 0 0"/>
       <limit effort="0.0" lower="-3.14159" upper="3.14159" velocity="0.0"/>
    </joint>
    <link name="Link5">
        <inertial>
            <origin xyz="0 0.2063978420887882 -0.07874235559253856" rpy="0 0 0"/>
            <mass value="1" />
            <inertia ixx="100" ixy="0" ixz="0" iyy="100" iyz="0" izz="100" />
        </inertial>
        <visual>
            <origin xyz="0 0.2063978420887882 -0.07874235559253856" rpy="0 0 0"/>
            <geometry>
                <box size="0.4406398511332186 0.4127956841775764 0.15748471118507712" />
            </geometry>
            <material name="Blue">
                <color rgba="0 0.0 1.0 1.0"/>
            </material>
        </visual>
        <collision>
            <origin xyz="0 0.2063978420887882 -0.07874235559253856" rpy="0 0 0"/>
            <geometry>
                <box size="0.4406398511332186 0.4127956841775764 0.15748471118507712" />
            </geometry>
        </collision>
    </link>
</robot>