<robot name = "robot">
    <link name="Link0">
        <inertial>
            <origin xyz="0 0 2.3565679864607545" rpy="0 0 0"/>
            <mass value="1" />
            <inertia ixx="100" ixy="0" ixz="0" iyy="100" iyz="0" izz="100" />
        </inertial>
        <visual>
            <origin xyz="0 0 2.3565679864607545" rpy="0 0 0"/>
            <geometry>
                <box size="0.3669394687516325 0.254532459279335 0.7131359729215087" />
            </geometry>
            <material name="Green">
                <color rgba="0 1.0 0.0 1.0"/>
            </material>
        </visual>
        <collision>
            <origin xyz="0 0 2.3565679864607545" rpy="0 0 0"/>
            <geometry>
                <box size="0.3669394687516325 0.254532459279335 0.7131359729215087" />
            </geometry>
        </collision>
    </link>
    <joint name="Link0_Link1" type="revolute">
       <parent link="Link0"/>
       <child  link="Link1"/>
       <origin rpy="0 0 0" xyz="0 0.1272662296396675 2.7131359729215085" />
     <axis xyz="1 0 0"/>
       <limit effort="0.0" lower="-3.14159" upper="3.14159" velocity="0.0"/>
    </joint>
    <link name="Link1">
        <inertial>
            <origin xyz="0 0.1272662296396675 -0.3565679864607543" rpy="0 0 0"/>
            <mass value="1" />
            <inertia ixx="100" ixy="0" ixz="0" iyy="100" iyz="0" izz="100" />
        </inertial>
        <visual>
            <origin xyz="0 0.1272662296396675 -0.3565679864607543" rpy="0 0 0"/>
            <geometry>
                <box size="0.3669394687516325 0.254532459279335 0.7131359729215087" />
            </geometry>
            <material name="Green">
                <color rgba="0 1.0 0.0 1.0"/>
            </material>
        </visual>
        <collision>
            <origin xyz="0 0.1272662296396675 -0.3565679864607543" rpy="0 0 0"/>
            <geometry>
                <box size="0.3669394687516325 0.254532459279335 0.7131359729215087" />
            </geometry>
        </collision>
    </link>
    <joint name="Link1_Link2" type="revolute">
       <parent link="Link1"/>
       <child  link="Link2"/>
       <origin rpy="0 0 0" xyz="0.18346973437581626 0.1272662296396675 0.0" />
     <axis xyz="0 1 0"/>
       <limit effort="0.0" lower="-3.14159" upper="3.14159" velocity="0.0"/>
    </joint>
    <link name="Link2">
        <inertial>
            <origin xyz="0.4757479390221163 0 -0.04514109211789297" rpy="0 0 0"/>
            <mass value="1" />
            <inertia ixx="100" ixy="0" ixz="0" iyy="100" iyz="0" izz="100" />
        </inertial>
        <visual>
            <origin xyz="0.4757479390221163 0 -0.04514109211789297" rpy="0 0 0"/>
            <geometry>
                <box size="0.9514958780442326 0.8419848877490221 0.09028218423578593" />
            </geometry>
            <material name="Green">
                <color rgba="0 1.0 0.0 1.0"/>
            </material>
        </visual>
        <collision>
            <origin xyz="0.4757479390221163 0 -0.04514109211789297" rpy="0 0 0"/>
            <geometry>
                <box size="0.9514958780442326 0.8419848877490221 0.09028218423578593" />
            </geometry>
        </collision>
    </link>
    <joint name="Link2_Link3" type="revolute">
       <parent link="Link2"/>
       <child  link="Link3"/>
       <origin rpy="0 0 0" xyz="0.9514958780442326 0 0.0" />
     <axis xyz="0 1 0"/>
       <limit effort="0.0" lower="-3.14159" upper="3.14159" velocity="0.0"/>
    </joint>
    <link name="Link3">
        <inertial>
            <origin xyz="0.2641792117635389 0 0.20314977404413687" rpy="0 0 0"/>
            <mass value="1" />
            <inertia ixx="100" ixy="0" ixz="0" iyy="100" iyz="0" izz="100" />
        </inertial>
        <visual>
            <origin xyz="0.2641792117635389 0 0.20314977404413687" rpy="0 0 0"/>
            <geometry>
                <box size="0.5283584235270778 0.9381750767112523 0.40629954808827373" />
            </geometry>
            <material name="Blue">
                <color rgba="0 0.0 1.0 1.0"/>
            </material>
        </visual>
        <collision>
            <origin xyz="0.2641792117635389 0 0.20314977404413687" rpy="0 0 0"/>
            <geometry>
                <box size="0.5283584235270778 0.9381750767112523 0.40629954808827373" />
            </geometry>
        </collision>
    </link>
    <joint name="Link3_Link4" type="revolute">
       <parent link="Link3"/>
       <child  link="Link4"/>
       <origin rpy="0 0 0" xyz="0.0 0 0.40629954808827373" />
     <axis xyz="0 1 0"/>
       <limit effort="0.0" lower="-3.14159" upper="3.14159" velocity="0.0"/>
    </joint>
    <link name="Link4">
        <inertial>
            <origin xyz="-0.031767981492035025 0 0.18042826528136385" rpy="0 0 0"/>
            <mass value="1" />
            <inertia ixx="100" ixy="0" ixz="0" iyy="100" iyz="0" izz="100" />
        </inertial>
        <visual>
            <origin xyz="-0.031767981492035025 0 0.18042826528136385" rpy="0 0 0"/>
            <geometry>
                <box size="0.06353596298407005 0.757554000425392 0.3608565305627277" />
            </geometry>
            <material name="Blue">
                <color rgba="0 0.0 1.0 1.0"/>
            </material>
        </visual>
        <collision>
            <origin xyz="-0.031767981492035025 0 0.18042826528136385" rpy="0 0 0"/>
            <geometry>
                <box size="0.06353596298407005 0.757554000425392 0.3608565305627277" />
            </geometry>
        </collision>
    </link>
    <joint name="Link4_Link5" type="revolute">
       <parent link="Link4"/>
       <child  link="Link5"/>
       <origin rpy="0 0 0" xyz="0.0 0 0.3608565305627277" />
     <axis xyz="0 1 0"/>
       <limit effort="0.0" lower="-3.14159" upper="3.14159" velocity="0.0"/>
    </joint>
    <link name="Link5">
        <inertial>
            <origin xyz="0.31540961074034135 0 -0.39177135033198723" rpy="0 0 0"/>
            <mass value="1" />
            <inertia ixx="100" ixy="0" ixz="0" iyy="100" iyz="0" izz="100" />
        </inertial>
        <visual>
            <origin xyz="0.31540961074034135 0 -0.39177135033198723" rpy="0 0 0"/>
            <geometry>
                <box size="0.6308192214806827 0.4513190935310186 0.7835427006639745" />
            </geometry>
            <material name="Green">
                <color rgba="0 1.0 0.0 1.0"/>
            </material>
        </visual>
        <collision>
            <origin xyz="0.31540961074034135 0 -0.39177135033198723" rpy="0 0 0"/>
            <geometry>
                <box size="0.6308192214806827 0.4513190935310186 0.7835427006639745" />
            </geometry>
        </collision>
    </link>
</robot>