<robot name = "robot">
    <link name="Link0">
        <inertial>
            <origin xyz="0 0 2.41300584557101" rpy="0 0 0"/>
            <mass value="1" />
            <inertia ixx="100" ixy="0" ixz="0" iyy="100" iyz="0" izz="100" />
        </inertial>
        <visual>
            <origin xyz="0 0 2.41300584557101" rpy="0 0 0"/>
            <geometry>
                <box size="0.4564150714674503 0.2080336129145962 0.82601169114202" />
            </geometry>
            <material name="Green">
                <color rgba="0 1.0 0.0 1.0"/>
            </material>
        </visual>
        <collision>
            <origin xyz="0 0 2.41300584557101" rpy="0 0 0"/>
            <geometry>
                <box size="0.4564150714674503 0.2080336129145962 0.82601169114202" />
            </geometry>
        </collision>
    </link>
    <joint name="Link0_Link1" type="revolute">
       <parent link="Link0"/>
       <child  link="Link1"/>
       <origin rpy="0 0 0" xyz="0 0.1040168064572981 2.82601169114202" />
     <axis xyz="1 0 0"/>
       <limit effort="0.0" lower="-3.14159" upper="3.14159" velocity="0.0"/>
    </joint>
    <link name="Link1">
        <inertial>
            <origin xyz="0 0.1040168064572981 -0.41300584557101" rpy="0 0 0"/>
            <mass value="1" />
            <inertia ixx="100" ixy="0" ixz="0" iyy="100" iyz="0" izz="100" />
        </inertial>
        <visual>
            <origin xyz="0 0.1040168064572981 -0.41300584557101" rpy="0 0 0"/>
            <geometry>
                <box size="0.4564150714674503 0.2080336129145962 0.82601169114202" />
            </geometry>
            <material name="Green">
                <color rgba="0 1.0 0.0 1.0"/>
            </material>
        </visual>
        <collision>
            <origin xyz="0 0.1040168064572981 -0.41300584557101" rpy="0 0 0"/>
            <geometry>
                <box size="0.4564150714674503 0.2080336129145962 0.82601169114202" />
            </geometry>
        </collision>
    </link>
    <joint name="Link1_Link2" type="revolute">
       <parent link="Link1"/>
       <child  link="Link2"/>
       <origin rpy="0 0 0" xyz="-0.22820753573372515 0.1040168064572981 0.0" />
     <axis xyz="0 1 0"/>
       <limit effort="0.0" lower="-3.14159" upper="3.14159" velocity="0.0"/>
    </joint>
    <link name="Link2">
        <inertial>
            <origin xyz="-0.4806211331687748 0 -0.016944476451903057" rpy="0 0 0"/>
            <mass value="1" />
            <inertia ixx="100" ixy="0" ixz="0" iyy="100" iyz="0" izz="100" />
        </inertial>
        <visual>
            <origin xyz="-0.4806211331687748 0 -0.016944476451903057" rpy="0 0 0"/>
            <geometry>
                <box size="0.9612422663375496 0.7922534383280434 0.03388895290380611" />
            </geometry>
            <material name="Blue">
                <color rgba="0 0.0 1.0 1.0"/>
            </material>
        </visual>
        <collision>
            <origin xyz="-0.4806211331687748 0 -0.016944476451903057" rpy="0 0 0"/>
            <geometry>
                <box size="0.9612422663375496 0.7922534383280434 0.03388895290380611" />
            </geometry>
        </collision>
    </link>
    <joint name="Link2_Link3" type="revolute">
       <parent link="Link2"/>
       <child  link="Link3"/>
       <origin rpy="0 0 0" xyz="-0.4806211331687748 0.3961267191640217 0.0" />
     <axis xyz="1 0 0"/>
       <limit effort="0.0" lower="-3.14159" upper="3.14159" velocity="0.0"/>
    </joint>
    <link name="Link3">
        <inertial>
            <origin xyz="0 0.09680270870642016 -0.2061043846786047" rpy="0 0 0"/>
            <mass value="1" />
            <inertia ixx="100" ixy="0" ixz="0" iyy="100" iyz="0" izz="100" />
        </inertial>
        <visual>
            <origin xyz="0 0.09680270870642016 -0.2061043846786047" rpy="0 0 0"/>
            <geometry>
                <box size="0.6983973984983746 0.19360541741284032 0.4122087693572094" />
            </geometry>
            <material name="Blue">
                <color rgba="0 0.0 1.0 1.0"/>
            </material>
        </visual>
        <collision>
            <origin xyz="0 0.09680270870642016 -0.2061043846786047" rpy="0 0 0"/>
            <geometry>
                <box size="0.6983973984983746 0.19360541741284032 0.4122087693572094" />
            </geometry>
        </collision>
    </link>
    <joint name="Link3_Link4" type="revolute">
       <parent link="Link3"/>
       <child  link="Link4"/>
       <origin rpy="0 0 0" xyz="0.3491986992491873 0.09680270870642016 0.0" />
     <axis xyz="0 1 0"/>
       <limit effort="0.0" lower="-3.14159" upper="3.14159" velocity="0.0"/>
    </joint>
    <link name="Link4">
        <inertial>
            <origin xyz="0.27549730491316304 0 -0.38510739027191065" rpy="0 0 0"/>
            <mass value="1" />
            <inertia ixx="100" ixy="0" ixz="0" iyy="100" iyz="0" izz="100" />
        </inertial>
        <visual>
            <origin xyz="0.27549730491316304 0 -0.38510739027191065" rpy="0 0 0"/>
            <geometry>
                <box size="0.5509946098263261 0.6011623023101581 0.7702147805438213" />
            </geometry>
            <material name="Blue">
                <color rgba="0 0.0 1.0 1.0"/>
            </material>
        </visual>
        <collision>
            <origin xyz="0.27549730491316304 0 -0.38510739027191065" rpy="0 0 0"/>
            <geometry>
                <box size="0.5509946098263261 0.6011623023101581 0.7702147805438213" />
            </geometry>
        </collision>
    </link>
</robot>