<robot name = "robot">
    <link name="Link0">
        <inertial>
            <origin xyz="0 0 2.294597189263116" rpy="0 0 0"/>
            <mass value="1" />
            <inertia ixx="100" ixy="0" ixz="0" iyy="100" iyz="0" izz="100" />
        </inertial>
        <visual>
            <origin xyz="0 0 2.294597189263116" rpy="0 0 0"/>
            <geometry>
                <box size="0.19473295166576798 0.8574248980223986 0.5891943785262317" />
            </geometry>
            <material name="Green">
                <color rgba="0 1.0 0.0 1.0"/>
            </material>
        </visual>
        <collision>
            <origin xyz="0 0 2.294597189263116" rpy="0 0 0"/>
            <geometry>
                <box size="0.19473295166576798 0.8574248980223986 0.5891943785262317" />
            </geometry>
        </collision>
    </link>
    <joint name="Link0_Link1" type="revolute">
       <parent link="Link0"/>
       <child  link="Link1"/>
       <origin rpy="0 0 0" xyz="0 0.4287124490111993 2.5891943785262317" />
     <axis xyz="1 0 0"/>
       <limit effort="0.0" lower="-3.14159" upper="3.14159" velocity="0.0"/>
    </joint>
    <link name="Link1">
        <inertial>
            <origin xyz="0 0.4287124490111993 -0.29459718926311584" rpy="0 0 0"/>
            <mass value="1" />
            <inertia ixx="100" ixy="0" ixz="0" iyy="100" iyz="0" izz="100" />
        </inertial>
        <visual>
            <origin xyz="0 0.4287124490111993 -0.29459718926311584" rpy="0 0 0"/>
            <geometry>
                <box size="0.19473295166576798 0.8574248980223986 0.5891943785262317" />
            </geometry>
            <material name="Blue">
                <color rgba="0 0.0 1.0 1.0"/>
            </material>
        </visual>
        <collision>
            <origin xyz="0 0.4287124490111993 -0.29459718926311584" rpy="0 0 0"/>
            <geometry>
                <box size="0.19473295166576798 0.8574248980223986 0.5891943785262317" />
            </geometry>
        </collision>
    </link>
    <joint name="Link1_Link2" type="revolute">
       <parent link="Link1"/>
       <child  link="Link2"/>
       <origin rpy="0 0 0" xyz="0.09736647583288399 0.4287124490111993 0.0" />
     <axis xyz="0 1 0"/>
       <limit effort="0.0" lower="-3.14159" upper="3.14159" velocity="0.0"/>
    </joint>
    <link name="Link2">
        <inertial>
            <origin xyz="0.42178428100923687 0 -0.21917804526958629" rpy="0 0 0"/>
            <mass value="1" />
            <inertia ixx="100" ixy="0" ixz="0" iyy="100" iyz="0" izz="100" />
        </inertial>
        <visual>
            <origin xyz="0.42178428100923687 0 -0.21917804526958629" rpy="0 0 0"/>
            <geometry>
                <box size="0.8435685620184737 0.9867837280628324 0.43835609053917257" />
            </geometry>
            <material name="Blue">
                <color rgba="0 0.0 1.0 1.0"/>
            </material>
        </visual>
        <collision>
            <origin xyz="0.42178428100923687 0 -0.21917804526958629" rpy="0 0 0"/>
            <geometry>
                <box size="0.8435685620184737 0.9867837280628324 0.43835609053917257" />
            </geometry>
        </collision>
    </link>
    <joint name="Link2_Link3" type="revolute">
       <parent link="Link2"/>
       <child  link="Link3"/>
       <origin rpy="0 0 0" xyz="0.0 0 0.0" />
     <axis xyz="0 1 0"/>
       <limit effort="0.0" lower="-3.14159" upper="3.14159" velocity="0.0"/>
    </joint>
    <link name="Link3">
        <inertial>
            <origin xyz="-0.42818653637472703 0 0.4206026686612413" rpy="0 0 0"/>
            <mass value="1" />
            <inertia ixx="100" ixy="0" ixz="0" iyy="100" iyz="0" izz="100" />
        </inertial>
        <visual>
            <origin xyz="-0.42818653637472703 0 0.4206026686612413" rpy="0 0 0"/>
            <geometry>
                <box size="0.8563730727494541 0.8716196285386292 0.8412053373224826" />
            </geometry>
            <material name="Blue">
                <color rgba="0 0.0 1.0 1.0"/>
            </material>
        </visual>
        <collision>
            <origin xyz="-0.42818653637472703 0 0.4206026686612413" rpy="0 0 0"/>
            <geometry>
                <box size="0.8563730727494541 0.8716196285386292 0.8412053373224826" />
            </geometry>
        </collision>
    </link>
    <joint name="Link3_Link4" type="revolute">
       <parent link="Link3"/>
       <child  link="Link4"/>
       <origin rpy="0 0 0" xyz="-0.8563730727494541 0 0.8412053373224826" />
     <axis xyz="0 1 0"/>
       <limit effort="0.0" lower="-3.14159" upper="3.14159" velocity="0.0"/>
    </joint>
    <link name="Link4">
        <inertial>
            <origin xyz="-0.4880542826043145 0 0.4386184870596354" rpy="0 0 0"/>
            <mass value="1" />
            <inertia ixx="100" ixy="0" ixz="0" iyy="100" iyz="0" izz="100" />
        </inertial>
        <visual>
            <origin xyz="-0.4880542826043145 0 0.4386184870596354" rpy="0 0 0"/>
            <geometry>
                <box size="0.976108565208629 0.1522853185547829 0.8772369741192708" />
            </geometry>
            <material name="Green">
                <color rgba="0 1.0 0.0 1.0"/>
            </material>
        </visual>
        <collision>
            <origin xyz="-0.4880542826043145 0 0.4386184870596354" rpy="0 0 0"/>
            <geometry>
                <box size="0.976108565208629 0.1522853185547829 0.8772369741192708" />
            </geometry>
        </collision>
    </link>
</robot>