<robot name = "robot">
    <link name="Link0">
        <inertial>
            <origin xyz="0 0 2.4036993347545867" rpy="0 0 0"/>
            <mass value="1" />
            <inertia ixx="100" ixy="0" ixz="0" iyy="100" iyz="0" izz="100" />
        </inertial>
        <visual>
            <origin xyz="0 0 2.4036993347545867" rpy="0 0 0"/>
            <geometry>
                <box size="0.4709256012672779 0.2692193964856736 0.8073986695091736" />
            </geometry>
            <material name="Green">
                <color rgba="0 1.0 0.0 1.0"/>
            </material>
        </visual>
        <collision>
            <origin xyz="0 0 2.4036993347545867" rpy="0 0 0"/>
            <geometry>
                <box size="0.4709256012672779 0.2692193964856736 0.8073986695091736" />
            </geometry>
        </collision>
    </link>
    <joint name="Link0_Link1" type="revolute">
       <parent link="Link0"/>
       <child  link="Link1"/>
       <origin rpy="0 0 0" xyz="0 0.1346096982428368 2.8073986695091735" />
     <axis xyz="1 0 0"/>
       <limit effort="0.0" lower="-3.14159" upper="3.14159" velocity="0.0"/>
    </joint>
    <link name="Link1">
        <inertial>
            <origin xyz="0 0.1346096982428368 -0.4036993347545868" rpy="0 0 0"/>
            <mass value="1" />
            <inertia ixx="100" ixy="0" ixz="0" iyy="100" iyz="0" izz="100" />
        </inertial>
        <visual>
            <origin xyz="0 0.1346096982428368 -0.4036993347545868" rpy="0 0 0"/>
            <geometry>
                <box size="0.4709256012672779 0.2692193964856736 0.8073986695091736" />
            </geometry>
            <material name="Green">
                <color rgba="0 1.0 0.0 1.0"/>
            </material>
        </visual>
        <collision>
            <origin xyz="0 0.1346096982428368 -0.4036993347545868" rpy="0 0 0"/>
            <geometry>
                <box size="0.4709256012672779 0.2692193964856736 0.8073986695091736" />
            </geometry>
        </collision>
    </link>
    <joint name="Link1_Link2" type="revolute">
       <parent link="Link1"/>
       <child  link="Link2"/>
       <origin rpy="0 0 0" xyz="-0.23546280063363895 0.1346096982428368 0.0" />
     <axis xyz="0 1 0"/>
       <limit effort="0.0" lower="-3.14159" upper="3.14159" velocity="0.0"/>
    </joint>
    <link name="Link2">
        <inertial>
            <origin xyz="-0.4834750119877073 0 0.3638339632866006" rpy="0 0 0"/>
            <mass value="1" />
            <inertia ixx="100" ixy="0" ixz="0" iyy="100" iyz="0" izz="100" />
        </inertial>
        <visual>
            <origin xyz="-0.4834750119877073 0 0.3638339632866006" rpy="0 0 0"/>
            <geometry>
                <box size="0.9669500239754146 0.3546211574421563 0.7276679265732012" />
            </geometry>
            <material name="Blue">
                <color rgba="0 0.0 1.0 1.0"/>
            </material>
        </visual>
        <collision>
            <origin xyz="-0.4834750119877073 0 0.3638339632866006" rpy="0 0 0"/>
            <geometry>
                <box size="0.9669500239754146 0.3546211574421563 0.7276679265732012" />
            </geometry>
        </collision>
    </link>
    <joint name="Link2_Link3" type="revolute">
       <parent link="Link2"/>
       <child  link="Link3"/>
       <origin rpy="0 0 0" xyz="-0.4834750119877073 0.17731057872107814 0.7276679265732012" />
     <axis xyz="1 0 0"/>
       <limit effort="0.0" lower="-3.14159" upper="3.14159" velocity="0.0"/>
    </joint>
    <link name="Link3">
        <inertial>
            <origin xyz="0 0.13755148399960332 -0.36316873464127236" rpy="0 0 0"/>
            <mass value="1" />
            <inertia ixx="100" ixy="0" ixz="0" iyy="100" iyz="0" izz="100" />
        </inertial>
        <visual>
            <origin xyz="0 0.13755148399960332 -0.36316873464127236" rpy="0 0 0"/>
            <geometry>
                <box size="0.3866644186295559 0.27510296799920664 0.7263374692825447" />
            </geometry>
            <material name="Green">
                <color rgba="0 1.0 0.0 1.0"/>
            </material>
        </visual>
        <collision>
            <origin xyz="0 0.13755148399960332 -0.36316873464127236" rpy="0 0 0"/>
            <geometry>
                <box size="0.3866644186295559 0.27510296799920664 0.7263374692825447" />
            </geometry>
        </collision>
    </link>
    <joint name="Link3_Link4" type="revolute">
       <parent link="Link3"/>
       <child  link="Link4"/>
       <origin rpy="0 0 0" xyz="0.19333220931477796 0.13755148399960332 0.0" />
     <axis xyz="0 1 0"/>
       <limit effort="0.0" lower="-3.14159" upper="3.14159" velocity="0.0"/>
    </joint>
    <link name="Link4">
        <inertial>
            <origin xyz="0.14496047329781064 0 0.2559768266709974" rpy="0 0 0"/>
            <mass value="1" />
            <inertia ixx="100" ixy="0" ixz="0" iyy="100" iyz="0" izz="100" />
        </inertial>
        <visual>
            <origin xyz="0.14496047329781064 0 0.2559768266709974" rpy="0 0 0"/>
            <geometry>
                <box size="0.2899209465956213 0.2858691534807408 0.5119536533419948" />
            </geometry>
            <material name="Green">
                <color rgba="0 1.0 0.0 1.0"/>
            </material>
        </visual>
        <collision>
            <origin xyz="0.14496047329781064 0 0.2559768266709974" rpy="0 0 0"/>
            <geometry>
                <box size="0.2899209465956213 0.2858691534807408 0.5119536533419948" />
            </geometry>
        </collision>
    </link>
    <joint name="Link4_Link5" type="revolute">
       <parent link="Link4"/>
       <child  link="Link5"/>
       <origin rpy="0 0 0" xyz="0.2899209465956213 0 0.5119536533419948" />
     <axis xyz="0 1 0"/>
       <limit effort="0.0" lower="-3.14159" upper="3.14159" velocity="0.0"/>
    </joint>
    <link name="Link5">
        <inertial>
            <origin xyz="0.13593500824777976 0 -0.49445813217334206" rpy="0 0 0"/>
            <mass value="1" />
            <inertia ixx="100" ixy="0" ixz="0" iyy="100" iyz="0" izz="100" />
        </inertial>
        <visual>
            <origin xyz="0.13593500824777976 0 -0.49445813217334206" rpy="0 0 0"/>
            <geometry>
                <box size="0.27187001649555953 0.9485207273904188 0.9889162643466841" />
            </geometry>
            <material name="Green">
                <color rgba="0 1.0 0.0 1.0"/>
            </material>
        </visual>
        <collision>
            <origin xyz="0.13593500824777976 0 -0.49445813217334206" rpy="0 0 0"/>
            <geometry>
                <box size="0.27187001649555953 0.9485207273904188 0.9889162643466841" />
            </geometry>
        </collision>
    </link>
    <joint name="Link5_Link6" type="revolute">
       <parent link="Link5"/>
       <child  link="Link6"/>
       <origin rpy="0 0 0" xyz="0.13593500824777976 -0.4742603636952094 0.0" />
     <axis xyz="1 0 0"/>
       <limit effort="0.0" lower="-3.14159" upper="3.14159" velocity="0.0"/>
    </joint>
    <link name="Link6">
        <inertial>
            <origin xyz="0 -0.044627007970129084 0.23934338168439984" rpy="0 0 0"/>
            <mass value="1" />
            <inertia ixx="100" ixy="0" ixz="0" iyy="100" iyz="0" izz="100" />
        </inertial>
        <visual>
            <origin xyz="0 -0.044627007970129084 0.23934338168439984" rpy="0 0 0"/>
            <geometry>
                <box size="0.5361240247803034 0.08925401594025817 0.4786867633687997" />
            </geometry>
            <material name="Green">
                <color rgba="0 1.0 0.0 1.0"/>
            </material>
        </visual>
        <collision>
            <origin xyz="0 -0.044627007970129084 0.23934338168439984" rpy="0 0 0"/>
            <geometry>
                <box size="0.5361240247803034 0.08925401594025817 0.4786867633687997" />
            </geometry>
        </collision>
    </link>
</robot>