<robot name = "robot">
    <link name="Link0">
        <inertial>
            <origin xyz="0 0 2.1663287056511327" rpy="0 0 0"/>
            <mass value="1" />
            <inertia ixx="100" ixy="0" ixz="0" iyy="100" iyz="0" izz="100" />
        </inertial>
        <visual>
            <origin xyz="0 0 2.1663287056511327" rpy="0 0 0"/>
            <geometry>
                <box size="0.5541225755339111 0.6612848267908283 0.33265741130226567" />
            </geometry>
            <material name="Green">
                <color rgba="0 1.0 0.0 1.0"/>
            </material>
        </visual>
        <collision>
            <origin xyz="0 0 2.1663287056511327" rpy="0 0 0"/>
            <geometry>
                <box size="0.5541225755339111 0.6612848267908283 0.33265741130226567" />
            </geometry>
        </collision>
    </link>
    <joint name="Link0_Link1" type="revolute">
       <parent link="Link0"/>
       <child  link="Link1"/>
       <origin rpy="0 0 0" xyz="0 0.33064241339541417 2.332657411302266" />
     <axis xyz="1 0 0"/>
       <limit effort="0.0" lower="-3.14159" upper="3.14159" velocity="0.0"/>
    </joint>
    <link name="Link1">
        <inertial>
            <origin xyz="0 0.33064241339541417 -0.16632870565113284" rpy="0 0 0"/>
            <mass value="1" />
            <inertia ixx="100" ixy="0" ixz="0" iyy="100" iyz="0" izz="100" />
        </inertial>
        <visual>
            <origin xyz="0 0.33064241339541417 -0.16632870565113284" rpy="0 0 0"/>
            <geometry>
                <box size="0.5541225755339111 0.6612848267908283 0.33265741130226567" />
            </geometry>
            <material name="Blue">
                <color rgba="0 0.0 1.0 1.0"/>
            </material>
        </visual>
        <collision>
            <origin xyz="0 0.33064241339541417 -0.16632870565113284" rpy="0 0 0"/>
            <geometry>
                <box size="0.5541225755339111 0.6612848267908283 0.33265741130226567" />
            </geometry>
        </collision>
    </link>
    <joint name="Link1_Link2" type="revolute">
       <parent link="Link1"/>
       <child  link="Link2"/>
       <origin rpy="0 0 0" xyz="0 0.0 0.0" />
     <axis xyz="1 0 0"/>
       <limit effort="0.0" lower="-3.14159" upper="3.14159" velocity="0.0"/>
    </joint>
    <link name="Link2">
        <inertial>
            <origin xyz="0 -0.04427143937917699 -0.4133348990035658" rpy="0 0 0"/>
            <mass value="1" />
            <inertia ixx="100" ixy="0" ixz="0" iyy="100" iyz="0" izz="100" />
        </inertial>
        <visual>
            <origin xyz="0 -0.04427143937917699 -0.4133348990035658" rpy="0 0 0"/>
            <geometry>
                <box size="0.10084034307132206 0.08854287875835398 0.8266697980071316" />
            </geometry>
            <material name="Green">
                <color rgba="0 1.0 0.0 1.0"/>
            </material>
        </visual>
        <collision>
            <origin xyz="0 -0.04427143937917699 -0.4133348990035658" rpy="0 0 0"/>
            <geometry>
                <box size="0.10084034307132206 0.08854287875835398 0.8266697980071316" />
            </geometry>
        </collision>
    </link>
    <joint name="Link2_Link3" type="revolute">
       <parent link="Link2"/>
       <child  link="Link3"/>
       <origin rpy="0 0 0" xyz="0 0.0 0.0" />
     <axis xyz="1 0 0"/>
       <limit effort="0.0" lower="-3.14159" upper="3.14159" velocity="0.0"/>
    </joint>
    <link name="Link3">
        <inertial>
            <origin xyz="0 0.14362466650273747 -0.19200259554473348" rpy="0 0 0"/>
            <mass value="1" />
            <inertia ixx="100" ixy="0" ixz="0" iyy="100" iyz="0" izz="100" />
        </inertial>
        <visual>
            <origin xyz="0 0.14362466650273747 -0.19200259554473348" rpy="0 0 0"/>
            <geometry>
                <box size="0.18270134984617226 0.28724933300547495 0.38400519108946696" />
            </geometry>
            <material name="Green">
                <color rgba="0 1.0 0.0 1.0"/>
            </material>
        </visual>
        <collision>
            <origin xyz="0 0.14362466650273747 -0.19200259554473348" rpy="0 0 0"/>
            <geometry>
                <box size="0.18270134984617226 0.28724933300547495 0.38400519108946696" />
            </geometry>
        </collision>
    </link>
    <joint name="Link3_Link4" type="revolute">
       <parent link="Link3"/>
       <child  link="Link4"/>
       <origin rpy="0 0 0" xyz="0 0.0 0.0" />
     <axis xyz="1 0 0"/>
       <limit effort="0.0" lower="-3.14159" upper="3.14159" velocity="0.0"/>
    </joint>
    <link name="Link4">
        <inertial>
            <origin xyz="0 -0.349388794629312 0.013582203496376621" rpy="0 0 0"/>
            <mass value="1" />
            <inertia ixx="100" ixy="0" ixz="0" iyy="100" iyz="0" izz="100" />
        </inertial>
        <visual>
            <origin xyz="0 -0.349388794629312 0.013582203496376621" rpy="0 0 0"/>
            <geometry>
                <box size="0.26874676237599926 0.698777589258624 0.027164406992753243" />
            </geometry>
            <material name="Blue">
                <color rgba="0 0.0 1.0 1.0"/>
            </material>
        </visual>
        <collision>
            <origin xyz="0 -0.349388794629312 0.013582203496376621" rpy="0 0 0"/>
            <geometry>
                <box size="0.26874676237599926 0.698777589258624 0.027164406992753243" />
            </geometry>
        </collision>
    </link>
</robot>