<robot name = "robot">
    <link name="Link0">
        <inertial>
            <origin xyz="0 0 2.0323705066599875" rpy="0 0 0"/>
            <mass value="1" />
            <inertia ixx="100" ixy="0" ixz="0" iyy="100" iyz="0" izz="100" />
        </inertial>
        <visual>
            <origin xyz="0 0 2.0323705066599875" rpy="0 0 0"/>
            <geometry>
                <box size="0.7272205176589449 0.8792981133577428 0.06474101331997517" />
            </geometry>
            <material name="Green">
                <color rgba="0 1.0 0.0 1.0"/>
            </material>
        </visual>
        <collision>
            <origin xyz="0 0 2.0323705066599875" rpy="0 0 0"/>
            <geometry>
                <box size="0.7272205176589449 0.8792981133577428 0.06474101331997517" />
            </geometry>
        </collision>
    </link>
    <joint name="Link0_Link1" type="revolute">
       <parent link="Link0"/>
       <child  link="Link1"/>
       <origin rpy="0 0 0" xyz="0 0.4396490566788714 2.064741013319975" />
     <axis xyz="1 0 0"/>
       <limit effort="0.0" lower="-3.14159" upper="3.14159" velocity="0.0"/>
    </joint>
    <link name="Link1">
        <inertial>
            <origin xyz="0 0.4396490566788714 -0.032370506659987586" rpy="0 0 0"/>
            <mass value="1" />
            <inertia ixx="100" ixy="0" ixz="0" iyy="100" iyz="0" izz="100" />
        </inertial>
        <visual>
            <origin xyz="0 0.4396490566788714 -0.032370506659987586" rpy="0 0 0"/>
            <geometry>
                <box size="0.7272205176589449 0.8792981133577428 0.06474101331997517" />
            </geometry>
            <material name="Green">
                <color rgba="0 1.0 0.0 1.0"/>
            </material>
        </visual>
        <collision>
            <origin xyz="0 0.4396490566788714 -0.032370506659987586" rpy="0 0 0"/>
            <geometry>
                <box size="0.7272205176589449 0.8792981133577428 0.06474101331997517" />
            </geometry>
        </collision>
    </link>
    <joint name="Link1_Link2" type="revolute">
       <parent link="Link1"/>
       <child  link="Link2"/>
       <origin rpy="0 0 0" xyz="-0.36361025882947245 0.4396490566788714 0.0" />
     <axis xyz="0 1 0"/>
       <limit effort="0.0" lower="-3.14159" upper="3.14159" velocity="0.0"/>
    </joint>
    <link name="Link2">
        <inertial>
            <origin xyz="-0.4514054945121983 0 -0.20479620960422817" rpy="0 0 0"/>
            <mass value="1" />
            <inertia ixx="100" ixy="0" ixz="0" iyy="100" iyz="0" izz="100" />
        </inertial>
        <visual>
            <origin xyz="-0.4514054945121983 0 -0.20479620960422817" rpy="0 0 0"/>
            <geometry>
                <box size="0.9028109890243966 0.9181516043075496 0.40959241920845635" />
            </geometry>
            <material name="Blue">
                <color rgba="0 0.0 1.0 1.0"/>
            </material>
        </visual>
        <collision>
            <origin xyz="-0.4514054945121983 0 -0.20479620960422817" rpy="0 0 0"/>
            <geometry>
                <box size="0.9028109890243966 0.9181516043075496 0.40959241920845635" />
            </geometry>
        </collision>
    </link>
    <joint name="Link2_Link3" type="revolute">
       <parent link="Link2"/>
       <child  link="Link3"/>
       <origin rpy="0 0 0" xyz="-0.4514054945121983 0.4590758021537748 0.0" />
     <axis xyz="1 0 0"/>
       <limit effort="0.0" lower="-3.14159" upper="3.14159" velocity="0.0"/>
    </joint>
    <link name="Link3">
        <inertial>
            <origin xyz="0 0.3123707535625888 0.07105068204147102" rpy="0 0 0"/>
            <mass value="1" />
            <inertia ixx="100" ixy="0" ixz="0" iyy="100" iyz="0" izz="100" />
        </inertial>
        <visual>
            <origin xyz="0 0.3123707535625888 0.07105068204147102" rpy="0 0 0"/>
            <geometry>
                <box size="0.1149221055326648 0.6247415071251776 0.14210136408294205" />
            </geometry>
            <material name="Blue">
                <color rgba="0 0.0 1.0 1.0"/>
            </material>
        </visual>
        <collision>
            <origin xyz="0 0.3123707535625888 0.07105068204147102" rpy="0 0 0"/>
            <geometry>
                <box size="0.1149221055326648 0.6247415071251776 0.14210136408294205" />
            </geometry>
        </collision>
    </link>
    <joint name="Link3_Link4" type="revolute">
       <parent link="Link3"/>
       <child  link="Link4"/>
       <origin rpy="0 0 0" xyz="0 0.0 0.14210136408294205" />
     <axis xyz="1 0 0"/>
       <limit effort="0.0" lower="-3.14159" upper="3.14159" velocity="0.0"/>
    </joint>
    <link name="Link4">
        <inertial>
            <origin xyz="0 -0.2739028018237529 -0.4539871548137084" rpy="0 0 0"/>
            <mass value="1" />
            <inertia ixx="100" ixy="0" ixz="0" iyy="100" iyz="0" izz="100" />
        </inertial>
        <visual>
            <origin xyz="0 -0.2739028018237529 -0.4539871548137084" rpy="0 0 0"/>
            <geometry>
                <box size="0.7149993107893697 0.5478056036475057 0.9079743096274168" />
            </geometry>
            <material name="Green">
                <color rgba="0 1.0 0.0 1.0"/>
            </material>
        </visual>
        <collision>
            <origin xyz="0 -0.2739028018237529 -0.4539871548137084" rpy="0 0 0"/>
            <geometry>
                <box size="0.7149993107893697 0.5478056036475057 0.9079743096274168" />
            </geometry>
        </collision>
    </link>
    <joint name="Link4_Link5" type="revolute">
       <parent link="Link4"/>
       <child  link="Link5"/>
       <origin rpy="0 0 0" xyz="0 0.0 0.0" />
     <axis xyz="1 0 0"/>
       <limit effort="0.0" lower="-3.14159" upper="3.14159" velocity="0.0"/>
    </joint>
    <link name="Link5">
        <inertial>
            <origin xyz="0 0.26032722739309017 -0.1736262555030363" rpy="0 0 0"/>
            <mass value="1" />
            <inertia ixx="100" ixy="0" ixz="0" iyy="100" iyz="0" izz="100" />
        </inertial>
        <visual>
            <origin xyz="0 0.26032722739309017 -0.1736262555030363" rpy="0 0 0"/>
            <geometry>
                <box size="0.3498261895872975 0.5206544547861803 0.3472525110060726" />
            </geometry>
            <material name="Green">
                <color rgba="0 1.0 0.0 1.0"/>
            </material>
        </visual>
        <collision>
            <origin xyz="0 0.26032722739309017 -0.1736262555030363" rpy="0 0 0"/>
            <geometry>
                <box size="0.3498261895872975 0.5206544547861803 0.3472525110060726" />
            </geometry>
        </collision>
    </link>
    <joint name="Link5_Link6" type="revolute">
       <parent link="Link5"/>
       <child  link="Link6"/>
       <origin rpy="0 0 0" xyz="0 0.0 0.0" />
     <axis xyz="1 0 0"/>
       <limit effort="0.0" lower="-3.14159" upper="3.14159" velocity="0.0"/>
    </joint>
    <link name="Link6">
        <inertial>
            <origin xyz="0 -0.26518663657510616 0.2181025895344924" rpy="0 0 0"/>
            <mass value="1" />
            <inertia ixx="100" ixy="0" ixz="0" iyy="100" iyz="0" izz="100" />
        </inertial>
        <visual>
            <origin xyz="0 -0.26518663657510616 0.2181025895344924" rpy="0 0 0"/>
            <geometry>
                <box size="0.4602343017955862 0.5303732731502123 0.4362051790689848" />
            </geometry>
            <material name="Green">
                <color rgba="0 1.0 0.0 1.0"/>
            </material>
        </visual>
        <collision>
            <origin xyz="0 -0.26518663657510616 0.2181025895344924" rpy="0 0 0"/>
            <geometry>
                <box size="0.4602343017955862 0.5303732731502123 0.4362051790689848" />
            </geometry>
        </collision>
    </link>
</robot>