<robot name = "robot">
    <link name="Link0">
        <inertial>
            <origin xyz="0 0 2.389839731769034" rpy="0 0 0"/>
            <mass value="1" />
            <inertia ixx="100" ixy="0" ixz="0" iyy="100" iyz="0" izz="100" />
        </inertial>
        <visual>
            <origin xyz="0 0 2.389839731769034" rpy="0 0 0"/>
            <geometry>
                <box size="0.5520589687149803 0.6623113467939444 0.7796794635380683" />
            </geometry>
            <material name="Green">
                <color rgba="0 1.0 0.0 1.0"/>
            </material>
        </visual>
        <collision>
            <origin xyz="0 0 2.389839731769034" rpy="0 0 0"/>
            <geometry>
                <box size="0.5520589687149803 0.6623113467939444 0.7796794635380683" />
            </geometry>
        </collision>
    </link>
    <joint name="Link0_Link1" type="revolute">
       <parent link="Link0"/>
       <child  link="Link1"/>
       <origin rpy="0 0 0" xyz="0 0.3311556733969722 2.779679463538068" />
     <axis xyz="1 0 0"/>
       <limit effort="0.0" lower="-3.14159" upper="3.14159" velocity="0.0"/>
    </joint>
    <link name="Link1">
        <inertial>
            <origin xyz="0 0.3311556733969722 -0.38983973176903414" rpy="0 0 0"/>
            <mass value="1" />
            <inertia ixx="100" ixy="0" ixz="0" iyy="100" iyz="0" izz="100" />
        </inertial>
        <visual>
            <origin xyz="0 0.3311556733969722 -0.38983973176903414" rpy="0 0 0"/>
            <geometry>
                <box size="0.5520589687149803 0.6623113467939444 0.7796794635380683" />
            </geometry>
            <material name="Green">
                <color rgba="0 1.0 0.0 1.0"/>
            </material>
        </visual>
        <collision>
            <origin xyz="0 0.3311556733969722 -0.38983973176903414" rpy="0 0 0"/>
            <geometry>
                <box size="0.5520589687149803 0.6623113467939444 0.7796794635380683" />
            </geometry>
        </collision>
    </link>
    <joint name="Link1_Link2" type="revolute">
       <parent link="Link1"/>
       <child  link="Link2"/>
       <origin rpy="0 0 0" xyz="0 0.0 0.0" />
     <axis xyz="1 0 0"/>
       <limit effort="0.0" lower="-3.14159" upper="3.14159" velocity="0.0"/>
    </joint>
    <link name="Link2">
        <inertial>
            <origin xyz="0 -0.37666601285532675 -0.3047709120304465" rpy="0 0 0"/>
            <mass value="1" />
            <inertia ixx="100" ixy="0" ixz="0" iyy="100" iyz="0" izz="100" />
        </inertial>
        <visual>
            <origin xyz="0 -0.37666601285532675 -0.3047709120304465" rpy="0 0 0"/>
            <geometry>
                <box size="0.9862580732504537 0.7533320257106535 0.609541824060893" />
            </geometry>
            <material name="Green">
                <color rgba="0 1.0 0.0 1.0"/>
            </material>
        </visual>
        <collision>
            <origin xyz="0 -0.37666601285532675 -0.3047709120304465" rpy="0 0 0"/>
            <geometry>
                <box size="0.9862580732504537 0.7533320257106535 0.609541824060893" />
            </geometry>
        </collision>
    </link>
    <joint name="Link2_Link3" type="revolute">
       <parent link="Link2"/>
       <child  link="Link3"/>
       <origin rpy="0 0 0" xyz="0 0.0 0.0" />
     <axis xyz="1 0 0"/>
       <limit effort="0.0" lower="-3.14159" upper="3.14159" velocity="0.0"/>
    </joint>
    <link name="Link3">
        <inertial>
            <origin xyz="0 0.10593654411599812 -0.23933362811990122" rpy="0 0 0"/>
            <mass value="1" />
            <inertia ixx="100" ixy="0" ixz="0" iyy="100" iyz="0" izz="100" />
        </inertial>
        <visual>
            <origin xyz="0 0.10593654411599812 -0.23933362811990122" rpy="0 0 0"/>
            <geometry>
                <box size="0.6315271200282466 0.21187308823199624 0.47866725623980244" />
            </geometry>
            <material name="Green">
                <color rgba="0 1.0 0.0 1.0"/>
            </material>
        </visual>
        <collision>
            <origin xyz="0 0.10593654411599812 -0.23933362811990122" rpy="0 0 0"/>
            <geometry>
                <box size="0.6315271200282466 0.21187308823199624 0.47866725623980244" />
            </geometry>
        </collision>
    </link>
    <joint name="Link3_Link4" type="revolute">
       <parent link="Link3"/>
       <child  link="Link4"/>
       <origin rpy="0 0 0" xyz="0.3157635600141233 0.10593654411599812 0.0" />
     <axis xyz="0 1 0"/>
       <limit effort="0.0" lower="-3.14159" upper="3.14159" velocity="0.0"/>
    </joint>
    <link name="Link4">
        <inertial>
            <origin xyz="0.22975315313718891 0 -0.17585849785208246" rpy="0 0 0"/>
            <mass value="1" />
            <inertia ixx="100" ixy="0" ixz="0" iyy="100" iyz="0" izz="100" />
        </inertial>
        <visual>
            <origin xyz="0.22975315313718891 0 -0.17585849785208246" rpy="0 0 0"/>
            <geometry>
                <box size="0.45950630627437783 0.7166675632204418 0.3517169957041649" />
            </geometry>
            <material name="Green">
                <color rgba="0 1.0 0.0 1.0"/>
            </material>
        </visual>
        <collision>
            <origin xyz="0.22975315313718891 0 -0.17585849785208246" rpy="0 0 0"/>
            <geometry>
                <box size="0.45950630627437783 0.7166675632204418 0.3517169957041649" />
            </geometry>
        </collision>
    </link>
    <joint name="Link4_Link5" type="revolute">
       <parent link="Link4"/>
       <child  link="Link5"/>
       <origin rpy="0 0 0" xyz="0.22975315313718891 -0.3583337816102209 0.0" />
     <axis xyz="1 0 0"/>
       <limit effort="0.0" lower="-3.14159" upper="3.14159" velocity="0.0"/>
    </joint>
    <link name="Link5">
        <inertial>
            <origin xyz="0 -0.1588382945813268 0.2488352606270024" rpy="0 0 0"/>
            <mass value="1" />
            <inertia ixx="100" ixy="0" ixz="0" iyy="100" iyz="0" izz="100" />
        </inertial>
        <visual>
            <origin xyz="0 -0.1588382945813268 0.2488352606270024" rpy="0 0 0"/>
            <geometry>
                <box size="0.11972989833010594 0.3176765891626536 0.4976705212540048" />
            </geometry>
            <material name="Blue">
                <color rgba="0 0.0 1.0 1.0"/>
            </material>
        </visual>
        <collision>
            <origin xyz="0 -0.1588382945813268 0.2488352606270024" rpy="0 0 0"/>
            <geometry>
                <box size="0.11972989833010594 0.3176765891626536 0.4976705212540048" />
            </geometry>
        </collision>
    </link>
</robot>