<robot name = "robot">
    <link name="Link0">
        <inertial>
            <origin xyz="0 0 2.060608744631654" rpy="0 0 0"/>
            <mass value="1" />
            <inertia ixx="100" ixy="0" ixz="0" iyy="100" iyz="0" izz="100" />
        </inertial>
        <visual>
            <origin xyz="0 0 2.060608744631654" rpy="0 0 0"/>
            <geometry>
                <box size="0.7520643500957463 0.6550994110853186 0.12121748926330744" />
            </geometry>
            <material name="Green">
                <color rgba="0 1.0 0.0 1.0"/>
            </material>
        </visual>
        <collision>
            <origin xyz="0 0 2.060608744631654" rpy="0 0 0"/>
            <geometry>
                <box size="0.7520643500957463 0.6550994110853186 0.12121748926330744" />
            </geometry>
        </collision>
    </link>
    <joint name="Link0_Link1" type="revolute">
       <parent link="Link0"/>
       <child  link="Link1"/>
       <origin rpy="0 0 0" xyz="0 0.3275497055426593 2.1212174892633073" />
     <axis xyz="1 0 0"/>
       <limit effort="0.0" lower="-3.14159" upper="3.14159" velocity="0.0"/>
    </joint>
    <link name="Link1">
        <inertial>
            <origin xyz="0 0.3275497055426593 -0.06060874463165372" rpy="0 0 0"/>
            <mass value="1" />
            <inertia ixx="100" ixy="0" ixz="0" iyy="100" iyz="0" izz="100" />
        </inertial>
        <visual>
            <origin xyz="0 0.3275497055426593 -0.06060874463165372" rpy="0 0 0"/>
            <geometry>
                <box size="0.7520643500957463 0.6550994110853186 0.12121748926330744" />
            </geometry>
            <material name="Blue">
                <color rgba="0 0.0 1.0 1.0"/>
            </material>
        </visual>
        <collision>
            <origin xyz="0 0.3275497055426593 -0.06060874463165372" rpy="0 0 0"/>
            <geometry>
                <box size="0.7520643500957463 0.6550994110853186 0.12121748926330744" />
            </geometry>
        </collision>
    </link>
    <joint name="Link1_Link2" type="revolute">
       <parent link="Link1"/>
       <child  link="Link2"/>
       <origin rpy="0 0 0" xyz="-0.3760321750478732 0.3275497055426593 0.0" />
     <axis xyz="0 1 0"/>
       <limit effort="0.0" lower="-3.14159" upper="3.14159" velocity="0.0"/>
    </joint>
    <link name="Link2">
        <inertial>
            <origin xyz="-0.46490846097249255 0 0.49842167689905964" rpy="0 0 0"/>
            <mass value="1" />
            <inertia ixx="100" ixy="0" ixz="0" iyy="100" iyz="0" izz="100" />
        </inertial>
        <visual>
            <origin xyz="-0.46490846097249255 0 0.49842167689905964" rpy="0 0 0"/>
            <geometry>
                <box size="0.9298169219449851 0.5997025061207903 0.9968433537981193" />
            </geometry>
            <material name="Blue">
                <color rgba="0 0.0 1.0 1.0"/>
            </material>
        </visual>
        <collision>
            <origin xyz="-0.46490846097249255 0 0.49842167689905964" rpy="0 0 0"/>
            <geometry>
                <box size="0.9298169219449851 0.5997025061207903 0.9968433537981193" />
            </geometry>
        </collision>
    </link>
    <joint name="Link2_Link3" type="revolute">
       <parent link="Link2"/>
       <child  link="Link3"/>
       <origin rpy="0 0 0" xyz="-0.46490846097249255 0.2998512530603952 0.9968433537981193" />
     <axis xyz="1 0 0"/>
       <limit effort="0.0" lower="-3.14159" upper="3.14159" velocity="0.0"/>
    </joint>
    <link name="Link3">
        <inertial>
            <origin xyz="0 0.09602136021628149 -0.1700191369567598" rpy="0 0 0"/>
            <mass value="1" />
            <inertia ixx="100" ixy="0" ixz="0" iyy="100" iyz="0" izz="100" />
        </inertial>
        <visual>
            <origin xyz="0 0.09602136021628149 -0.1700191369567598" rpy="0 0 0"/>
            <geometry>
                <box size="0.8803480338817956 0.19204272043256299 0.3400382739135196" />
            </geometry>
            <material name="Blue">
                <color rgba="0 0.0 1.0 1.0"/>
            </material>
        </visual>
        <collision>
            <origin xyz="0 0.09602136021628149 -0.1700191369567598" rpy="0 0 0"/>
            <geometry>
                <box size="0.8803480338817956 0.19204272043256299 0.3400382739135196" />
            </geometry>
        </collision>
    </link>
    <joint name="Link3_Link4" type="revolute">
       <parent link="Link3"/>
       <child  link="Link4"/>
       <origin rpy="0 0 0" xyz="0 0.19204272043256299 0.0" />
     <axis xyz="1 0 0"/>
       <limit effort="0.0" lower="-3.14159" upper="3.14159" velocity="0.0"/>
    </joint>
    <link name="Link4">
        <inertial>
            <origin xyz="0 0.4385978040461739 0.47484522991833494" rpy="0 0 0"/>
            <mass value="1" />
            <inertia ixx="100" ixy="0" ixz="0" iyy="100" iyz="0" izz="100" />
        </inertial>
        <visual>
            <origin xyz="0 0.4385978040461739 0.47484522991833494" rpy="0 0 0"/>
            <geometry>
                <box size="0.013888292935187896 0.8771956080923478 0.9496904598366699" />
            </geometry>
            <material name="Green">
                <color rgba="0 1.0 0.0 1.0"/>
            </material>
        </visual>
        <collision>
            <origin xyz="0 0.4385978040461739 0.47484522991833494" rpy="0 0 0"/>
            <geometry>
                <box size="0.013888292935187896 0.8771956080923478 0.9496904598366699" />
            </geometry>
        </collision>
    </link>
</robot>