<robot name = "robot">
    <link name="Link0">
        <inertial>
            <origin xyz="0 0 2.260151359367184" rpy="0 0 0"/>
            <mass value="1" />
            <inertia ixx="100" ixy="0" ixz="0" iyy="100" iyz="0" izz="100" />
        </inertial>
        <visual>
            <origin xyz="0 0 2.260151359367184" rpy="0 0 0"/>
            <geometry>
                <box size="0.9413756064456202 0.7762563779922746 0.5203027187343682" />
            </geometry>
            <material name="Green">
                <color rgba="0 1.0 0.0 1.0"/>
            </material>
        </visual>
        <collision>
            <origin xyz="0 0 2.260151359367184" rpy="0 0 0"/>
            <geometry>
                <box size="0.9413756064456202 0.7762563779922746 0.5203027187343682" />
            </geometry>
        </collision>
    </link>
    <joint name="Link0_Link1" type="revolute">
       <parent link="Link0"/>
       <child  link="Link1"/>
       <origin rpy="0 0 0" xyz="0 0.3881281889961373 2.520302718734368" />
     <axis xyz="1 0 0"/>
       <limit effort="0.0" lower="-3.14159" upper="3.14159" velocity="0.0"/>
    </joint>
    <link name="Link1">
        <inertial>
            <origin xyz="0 0.3881281889961373 -0.2601513593671841" rpy="0 0 0"/>
            <mass value="1" />
            <inertia ixx="100" ixy="0" ixz="0" iyy="100" iyz="0" izz="100" />
        </inertial>
        <visual>
            <origin xyz="0 0.3881281889961373 -0.2601513593671841" rpy="0 0 0"/>
            <geometry>
                <box size="0.9413756064456202 0.7762563779922746 0.5203027187343682" />
            </geometry>
            <material name="Green">
                <color rgba="0 1.0 0.0 1.0"/>
            </material>
        </visual>
        <collision>
            <origin xyz="0 0.3881281889961373 -0.2601513593671841" rpy="0 0 0"/>
            <geometry>
                <box size="0.9413756064456202 0.7762563779922746 0.5203027187343682" />
            </geometry>
        </collision>
    </link>
    <joint name="Link1_Link2" type="revolute">
       <parent link="Link1"/>
       <child  link="Link2"/>
       <origin rpy="0 0 0" xyz="0 0.0 0.0" />
     <axis xyz="1 0 0"/>
       <limit effort="0.0" lower="-3.14159" upper="3.14159" velocity="0.0"/>
    </joint>
    <link name="Link2">
        <inertial>
            <origin xyz="0 -0.1478482698513368 0.24810674118178305" rpy="0 0 0"/>
            <mass value="1" />
            <inertia ixx="100" ixy="0" ixz="0" iyy="100" iyz="0" izz="100" />
        </inertial>
        <visual>
            <origin xyz="0 -0.1478482698513368 0.24810674118178305" rpy="0 0 0"/>
            <geometry>
                <box size="0.14843119082731937 0.2956965397026736 0.4962134823635661" />
            </geometry>
            <material name="Blue">
                <color rgba="0 0.0 1.0 1.0"/>
            </material>
        </visual>
        <collision>
            <origin xyz="0 -0.1478482698513368 0.24810674118178305" rpy="0 0 0"/>
            <geometry>
                <box size="0.14843119082731937 0.2956965397026736 0.4962134823635661" />
            </geometry>
        </collision>
    </link>
    <joint name="Link2_Link3" type="revolute">
       <parent link="Link2"/>
       <child  link="Link3"/>
       <origin rpy="0 0 0" xyz="0.07421559541365969 -0.1478482698513368 0.4962134823635661" />
     <axis xyz="0 1 0"/>
       <limit effort="0.0" lower="-3.14159" upper="3.14159" velocity="0.0"/>
    </joint>
    <link name="Link3">
        <inertial>
            <origin xyz="0.0935623229483164 0 0.018050919258085885" rpy="0 0 0"/>
            <mass value="1" />
            <inertia ixx="100" ixy="0" ixz="0" iyy="100" iyz="0" izz="100" />
        </inertial>
        <visual>
            <origin xyz="0.0935623229483164 0 0.018050919258085885" rpy="0 0 0"/>
            <geometry>
                <box size="0.1871246458966328 0.24685619128378 0.03610183851617177" />
            </geometry>
            <material name="Blue">
                <color rgba="0 0.0 1.0 1.0"/>
            </material>
        </visual>
        <collision>
            <origin xyz="0.0935623229483164 0 0.018050919258085885" rpy="0 0 0"/>
            <geometry>
                <box size="0.1871246458966328 0.24685619128378 0.03610183851617177" />
            </geometry>
        </collision>
    </link>
    <joint name="Link3_Link4" type="revolute">
       <parent link="Link3"/>
       <child  link="Link4"/>
       <origin rpy="0 0 0" xyz="0.0935623229483164 0.12342809564189 0.03610183851617177" />
     <axis xyz="1 0 0"/>
       <limit effort="0.0" lower="-3.14159" upper="3.14159" velocity="0.0"/>
    </joint>
    <link name="Link4">
        <inertial>
            <origin xyz="0 0.23583704733499689 0.005441587249148172" rpy="0 0 0"/>
            <mass value="1" />
            <inertia ixx="100" ixy="0" ixz="0" iyy="100" iyz="0" izz="100" />
        </inertial>
        <visual>
            <origin xyz="0 0.23583704733499689 0.005441587249148172" rpy="0 0 0"/>
            <geometry>
                <box size="0.043639411521885885 0.47167409466999377 0.010883174498296344" />
            </geometry>
            <material name="Blue">
                <color rgba="0 0.0 1.0 1.0"/>
            </material>
        </visual>
        <collision>
            <origin xyz="0 0.23583704733499689 0.005441587249148172" rpy="0 0 0"/>
            <geometry>
                <box size="0.043639411521885885 0.47167409466999377 0.010883174498296344" />
            </geometry>
        </collision>
    </link>
    <joint name="Link4_Link5" type="revolute">
       <parent link="Link4"/>
       <child  link="Link5"/>
       <origin rpy="0 0 0" xyz="0.021819705760942942 0.23583704733499689 0.010883174498296344" />
     <axis xyz="0 1 0"/>
       <limit effort="0.0" lower="-3.14159" upper="3.14159" velocity="0.0"/>
    </joint>
    <link name="Link5">
        <inertial>
            <origin xyz="0.21156236702055842 0 0.46025023199297044" rpy="0 0 0"/>
            <mass value="1" />
            <inertia ixx="100" ixy="0" ixz="0" iyy="100" iyz="0" izz="100" />
        </inertial>
        <visual>
            <origin xyz="0.21156236702055842 0 0.46025023199297044" rpy="0 0 0"/>
            <geometry>
                <box size="0.42312473404111683 0.5002828709296345 0.9205004639859409" />
            </geometry>
            <material name="Green">
                <color rgba="0 1.0 0.0 1.0"/>
            </material>
        </visual>
        <collision>
            <origin xyz="0.21156236702055842 0 0.46025023199297044" rpy="0 0 0"/>
            <geometry>
                <box size="0.42312473404111683 0.5002828709296345 0.9205004639859409" />
            </geometry>
        </collision>
    </link>
    <joint name="Link5_Link6" type="revolute">
       <parent link="Link5"/>
       <child  link="Link6"/>
       <origin rpy="0 0 0" xyz="0.21156236702055842 -0.25014143546481726 0.9205004639859409" />
     <axis xyz="1 0 0"/>
       <limit effort="0.0" lower="-3.14159" upper="3.14159" velocity="0.0"/>
    </joint>
    <link name="Link6">
        <inertial>
            <origin xyz="0 -0.2672327597634702 0.2782806807700832" rpy="0 0 0"/>
            <mass value="1" />
            <inertia ixx="100" ixy="0" ixz="0" iyy="100" iyz="0" izz="100" />
        </inertial>
        <visual>
            <origin xyz="0 -0.2672327597634702 0.2782806807700832" rpy="0 0 0"/>
            <geometry>
                <box size="0.6184851717911938 0.5344655195269404 0.5565613615401664" />
            </geometry>
            <material name="Green">
                <color rgba="0 1.0 0.0 1.0"/>
            </material>
        </visual>
        <collision>
            <origin xyz="0 -0.2672327597634702 0.2782806807700832" rpy="0 0 0"/>
            <geometry>
                <box size="0.6184851717911938 0.5344655195269404 0.5565613615401664" />
            </geometry>
        </collision>
    </link>
</robot>