<robot name = "robot">
    <link name="Link0">
        <inertial>
            <origin xyz="0 0 2.208496080091516" rpy="0 0 0"/>
            <mass value="1" />
            <inertia ixx="100" ixy="0" ixz="0" iyy="100" iyz="0" izz="100" />
        </inertial>
        <visual>
            <origin xyz="0 0 2.208496080091516" rpy="0 0 0"/>
            <geometry>
                <box size="0.4274846365941589 0.0005947471600203924 0.4169921601830321" />
            </geometry>
            <material name="Green">
                <color rgba="0 1.0 0.0 1.0"/>
            </material>
        </visual>
        <collision>
            <origin xyz="0 0 2.208496080091516" rpy="0 0 0"/>
            <geometry>
                <box size="0.4274846365941589 0.0005947471600203924 0.4169921601830321" />
            </geometry>
        </collision>
    </link>
    <joint name="Link0_Link1" type="revolute">
       <parent link="Link0"/>
       <child  link="Link1"/>
       <origin rpy="0 0 0" xyz="0 0.0002973735800101962 2.416992160183032" />
     <axis xyz="1 0 0"/>
       <limit effort="0.0" lower="-3.14159" upper="3.14159" velocity="0.0"/>
    </joint>
    <link name="Link1">
        <inertial>
            <origin xyz="0 0.0002973735800101962 -0.20849608009151605" rpy="0 0 0"/>
            <mass value="1" />
            <inertia ixx="100" ixy="0" ixz="0" iyy="100" iyz="0" izz="100" />
        </inertial>
        <visual>
            <origin xyz="0 0.0002973735800101962 -0.20849608009151605" rpy="0 0 0"/>
            <geometry>
                <box size="0.4274846365941589 0.0005947471600203924 0.4169921601830321" />
            </geometry>
            <material name="Green">
                <color rgba="0 1.0 0.0 1.0"/>
            </material>
        </visual>
        <collision>
            <origin xyz="0 0.0002973735800101962 -0.20849608009151605" rpy="0 0 0"/>
            <geometry>
                <box size="0.4274846365941589 0.0005947471600203924 0.4169921601830321" />
            </geometry>
        </collision>
    </link>
    <joint name="Link1_Link2" type="revolute">
       <parent link="Link1"/>
       <child  link="Link2"/>
       <origin rpy="0 0 0" xyz="0 0.0 0.0" />
     <axis xyz="1 0 0"/>
       <limit effort="0.0" lower="-3.14159" upper="3.14159" velocity="0.0"/>
    </joint>
    <link name="Link2">
        <inertial>
            <origin xyz="0 -0.41017023761284993 -0.17969906796543583" rpy="0 0 0"/>
            <mass value="1" />
            <inertia ixx="100" ixy="0" ixz="0" iyy="100" iyz="0" izz="100" />
        </inertial>
        <visual>
            <origin xyz="0 -0.41017023761284993 -0.17969906796543583" rpy="0 0 0"/>
            <geometry>
                <box size="0.46965657602292255 0.8203404752256999 0.35939813593087166" />
            </geometry>
            <material name="Green">
                <color rgba="0 1.0 0.0 1.0"/>
            </material>
        </visual>
        <collision>
            <origin xyz="0 -0.41017023761284993 -0.17969906796543583" rpy="0 0 0"/>
            <geometry>
                <box size="0.46965657602292255 0.8203404752256999 0.35939813593087166" />
            </geometry>
        </collision>
    </link>
    <joint name="Link2_Link3" type="revolute">
       <parent link="Link2"/>
       <child  link="Link3"/>
       <origin rpy="0 0 0" xyz="-0.23482828801146127 -0.41017023761284993 0.0" />
     <axis xyz="0 1 0"/>
       <limit effort="0.0" lower="-3.14159" upper="3.14159" velocity="0.0"/>
    </joint>
    <link name="Link3">
        <inertial>
            <origin xyz="-0.4448163387629709 0 0.03720598114839424" rpy="0 0 0"/>
            <mass value="1" />
            <inertia ixx="100" ixy="0" ixz="0" iyy="100" iyz="0" izz="100" />
        </inertial>
        <visual>
            <origin xyz="-0.4448163387629709 0 0.03720598114839424" rpy="0 0 0"/>
            <geometry>
                <box size="0.8896326775259418 0.2979173150689378 0.07441196229678848" />
            </geometry>
            <material name="Blue">
                <color rgba="0 0.0 1.0 1.0"/>
            </material>
        </visual>
        <collision>
            <origin xyz="-0.4448163387629709 0 0.03720598114839424" rpy="0 0 0"/>
            <geometry>
                <box size="0.8896326775259418 0.2979173150689378 0.07441196229678848" />
            </geometry>
        </collision>
    </link>
    <joint name="Link3_Link4" type="revolute">
       <parent link="Link3"/>
       <child  link="Link4"/>
       <origin rpy="0 0 0" xyz="-0.8896326775259418 0 0.07441196229678848" />
     <axis xyz="0 1 0"/>
       <limit effort="0.0" lower="-3.14159" upper="3.14159" velocity="0.0"/>
    </joint>
    <link name="Link4">
        <inertial>
            <origin xyz="-0.4803165899153369 0 0.09373554443626286" rpy="0 0 0"/>
            <mass value="1" />
            <inertia ixx="100" ixy="0" ixz="0" iyy="100" iyz="0" izz="100" />
        </inertial>
        <visual>
            <origin xyz="-0.4803165899153369 0 0.09373554443626286" rpy="0 0 0"/>
            <geometry>
                <box size="0.9606331798306738 0.6505967430567484 0.18747108887252573" />
            </geometry>
            <material name="Blue">
                <color rgba="0 0.0 1.0 1.0"/>
            </material>
        </visual>
        <collision>
            <origin xyz="-0.4803165899153369 0 0.09373554443626286" rpy="0 0 0"/>
            <geometry>
                <box size="0.9606331798306738 0.6505967430567484 0.18747108887252573" />
            </geometry>
        </collision>
    </link>
    <joint name="Link4_Link5" type="revolute">
       <parent link="Link4"/>
       <child  link="Link5"/>
       <origin rpy="0 0 0" xyz="-0.4803165899153369 0.3252983715283742 0.18747108887252573" />
     <axis xyz="1 0 0"/>
       <limit effort="0.0" lower="-3.14159" upper="3.14159" velocity="0.0"/>
    </joint>
    <link name="Link5">
        <inertial>
            <origin xyz="0 0.3045685733259025 0.2337624263691766" rpy="0 0 0"/>
            <mass value="1" />
            <inertia ixx="100" ixy="0" ixz="0" iyy="100" iyz="0" izz="100" />
        </inertial>
        <visual>
            <origin xyz="0 0.3045685733259025 0.2337624263691766" rpy="0 0 0"/>
            <geometry>
                <box size="0.9431689273694207 0.609137146651805 0.4675248527383532" />
            </geometry>
            <material name="Green">
                <color rgba="0 1.0 0.0 1.0"/>
            </material>
        </visual>
        <collision>
            <origin xyz="0 0.3045685733259025 0.2337624263691766" rpy="0 0 0"/>
            <geometry>
                <box size="0.9431689273694207 0.609137146651805 0.4675248527383532" />
            </geometry>
        </collision>
    </link>
    <joint name="Link5_Link6" type="revolute">
       <parent link="Link5"/>
       <child  link="Link6"/>
       <origin rpy="0 0 0" xyz="0 0.0 0.4675248527383532" />
     <axis xyz="1 0 0"/>
       <limit effort="0.0" lower="-3.14159" upper="3.14159" velocity="0.0"/>
    </joint>
    <link name="Link6">
        <inertial>
            <origin xyz="0 -0.41555305493533884 0.1801130650995147" rpy="0 0 0"/>
            <mass value="1" />
            <inertia ixx="100" ixy="0" ixz="0" iyy="100" iyz="0" izz="100" />
        </inertial>
        <visual>
            <origin xyz="0 -0.41555305493533884 0.1801130650995147" rpy="0 0 0"/>
            <geometry>
                <box size="0.530892542802395 0.8311061098706777 0.3602261301990294" />
            </geometry>
            <material name="Blue">
                <color rgba="0 0.0 1.0 1.0"/>
            </material>
        </visual>
        <collision>
            <origin xyz="0 -0.41555305493533884 0.1801130650995147" rpy="0 0 0"/>
            <geometry>
                <box size="0.530892542802395 0.8311061098706777 0.3602261301990294" />
            </geometry>
        </collision>
    </link>
</robot>