<robot name = "robot">
    <link name="Link0">
        <inertial>
            <origin xyz="0 0 2.135108587869382" rpy="0 0 0"/>
            <mass value="1" />
            <inertia ixx="100" ixy="0" ixz="0" iyy="100" iyz="0" izz="100" />
        </inertial>
        <visual>
            <origin xyz="0 0 2.135108587869382" rpy="0 0 0"/>
            <geometry>
                <box size="0.30148213906982435 0.8536731865888064 0.27021717573876347" />
            </geometry>
            <material name="Green">
                <color rgba="0 1.0 0.0 1.0"/>
            </material>
        </visual>
        <collision>
            <origin xyz="0 0 2.135108587869382" rpy="0 0 0"/>
            <geometry>
                <box size="0.30148213906982435 0.8536731865888064 0.27021717573876347" />
            </geometry>
        </collision>
    </link>
    <joint name="Link0_Link1" type="revolute">
       <parent link="Link0"/>
       <child  link="Link1"/>
       <origin rpy="0 0 0" xyz="0 0.4268365932944032 2.2702171757387637" />
     <axis xyz="1 0 0"/>
       <limit effort="0.0" lower="-3.14159" upper="3.14159" velocity="0.0"/>
    </joint>
    <link name="Link1">
        <inertial>
            <origin xyz="0 0.4268365932944032 -0.13510858786938174" rpy="0 0 0"/>
            <mass value="1" />
            <inertia ixx="100" ixy="0" ixz="0" iyy="100" iyz="0" izz="100" />
        </inertial>
        <visual>
            <origin xyz="0 0.4268365932944032 -0.13510858786938174" rpy="0 0 0"/>
            <geometry>
                <box size="0.30148213906982435 0.8536731865888064 0.27021717573876347" />
            </geometry>
            <material name="Green">
                <color rgba="0 1.0 0.0 1.0"/>
            </material>
        </visual>
        <collision>
            <origin xyz="0 0.4268365932944032 -0.13510858786938174" rpy="0 0 0"/>
            <geometry>
                <box size="0.30148213906982435 0.8536731865888064 0.27021717573876347" />
            </geometry>
        </collision>
    </link>
    <joint name="Link1_Link2" type="revolute">
       <parent link="Link1"/>
       <child  link="Link2"/>
       <origin rpy="0 0 0" xyz="-0.15074106953491218 0.4268365932944032 0.0" />
     <axis xyz="0 1 0"/>
       <limit effort="0.0" lower="-3.14159" upper="3.14159" velocity="0.0"/>
    </joint>
    <link name="Link2">
        <inertial>
            <origin xyz="-0.3194263293611144 0 0.09479956380435667" rpy="0 0 0"/>
            <mass value="1" />
            <inertia ixx="100" ixy="0" ixz="0" iyy="100" iyz="0" izz="100" />
        </inertial>
        <visual>
            <origin xyz="-0.3194263293611144 0 0.09479956380435667" rpy="0 0 0"/>
            <geometry>
                <box size="0.6388526587222288 0.9141571687710787 0.18959912760871334" />
            </geometry>
            <material name="Green">
                <color rgba="0 1.0 0.0 1.0"/>
            </material>
        </visual>
        <collision>
            <origin xyz="-0.3194263293611144 0 0.09479956380435667" rpy="0 0 0"/>
            <geometry>
                <box size="0.6388526587222288 0.9141571687710787 0.18959912760871334" />
            </geometry>
        </collision>
    </link>
    <joint name="Link2_Link3" type="revolute">
       <parent link="Link2"/>
       <child  link="Link3"/>
       <origin rpy="0 0 0" xyz="-0.3194263293611144 -0.45707858438553933 0.18959912760871334" />
     <axis xyz="1 0 0"/>
       <limit effort="0.0" lower="-3.14159" upper="3.14159" velocity="0.0"/>
    </joint>
    <link name="Link3">
        <inertial>
            <origin xyz="0 -0.4747665549927597 0.45168723191471294" rpy="0 0 0"/>
            <mass value="1" />
            <inertia ixx="100" ixy="0" ixz="0" iyy="100" iyz="0" izz="100" />
        </inertial>
        <visual>
            <origin xyz="0 -0.4747665549927597 0.45168723191471294" rpy="0 0 0"/>
            <geometry>
                <box size="0.5073409789482439 0.9495331099855194 0.9033744638294259" />
            </geometry>
            <material name="Blue">
                <color rgba="0 0.0 1.0 1.0"/>
            </material>
        </visual>
        <collision>
            <origin xyz="0 -0.4747665549927597 0.45168723191471294" rpy="0 0 0"/>
            <geometry>
                <box size="0.5073409789482439 0.9495331099855194 0.9033744638294259" />
            </geometry>
        </collision>
    </link>
    <joint name="Link3_Link4" type="revolute">
       <parent link="Link3"/>
       <child  link="Link4"/>
       <origin rpy="0 0 0" xyz="-0.25367048947412196 -0.4747665549927597 0.9033744638294259" />
     <axis xyz="0 1 0"/>
       <limit effort="0.0" lower="-3.14159" upper="3.14159" velocity="0.0"/>
    </joint>
    <link name="Link4">
        <inertial>
            <origin xyz="-0.1197719791128165 0 0.06883799673225843" rpy="0 0 0"/>
            <mass value="1" />
            <inertia ixx="100" ixy="0" ixz="0" iyy="100" iyz="0" izz="100" />
        </inertial>
        <visual>
            <origin xyz="-0.1197719791128165 0 0.06883799673225843" rpy="0 0 0"/>
            <geometry>
                <box size="0.239543958225633 0.28223917433991363 0.13767599346451687" />
            </geometry>
            <material name="Green">
                <color rgba="0 1.0 0.0 1.0"/>
            </material>
        </visual>
        <collision>
            <origin xyz="-0.1197719791128165 0 0.06883799673225843" rpy="0 0 0"/>
            <geometry>
                <box size="0.239543958225633 0.28223917433991363 0.13767599346451687" />
            </geometry>
        </collision>
    </link>
    <joint name="Link4_Link5" type="revolute">
       <parent link="Link4"/>
       <child  link="Link5"/>
       <origin rpy="0 0 0" xyz="0.0 0 0.13767599346451687" />
     <axis xyz="0 1 0"/>
       <limit effort="0.0" lower="-3.14159" upper="3.14159" velocity="0.0"/>
    </joint>
    <link name="Link5">
        <inertial>
            <origin xyz="0.01356272918922291 0 0.1445574299860931" rpy="0 0 0"/>
            <mass value="1" />
            <inertia ixx="100" ixy="0" ixz="0" iyy="100" iyz="0" izz="100" />
        </inertial>
        <visual>
            <origin xyz="0.01356272918922291 0 0.1445574299860931" rpy="0 0 0"/>
            <geometry>
                <box size="0.02712545837844582 0.7914828908705833 0.2891148599721862" />
            </geometry>
            <material name="Green">
                <color rgba="0 1.0 0.0 1.0"/>
            </material>
        </visual>
        <collision>
            <origin xyz="0.01356272918922291 0 0.1445574299860931" rpy="0 0 0"/>
            <geometry>
                <box size="0.02712545837844582 0.7914828908705833 0.2891148599721862" />
            </geometry>
        </collision>
    </link>
</robot>