<robot name = "robot">
    <link name="Link0">
        <inertial>
            <origin xyz="0 0 2.177732075640905" rpy="0 0 0"/>
            <mass value="1" />
            <inertia ixx="100" ixy="0" ixz="0" iyy="100" iyz="0" izz="100" />
        </inertial>
        <visual>
            <origin xyz="0 0 2.177732075640905" rpy="0 0 0"/>
            <geometry>
                <box size="0.14887688408942934 0.14264691849522582 0.3554641512818102" />
            </geometry>
            <material name="Green">
                <color rgba="0 1.0 0.0 1.0"/>
            </material>
        </visual>
        <collision>
            <origin xyz="0 0 2.177732075640905" rpy="0 0 0"/>
            <geometry>
                <box size="0.14887688408942934 0.14264691849522582 0.3554641512818102" />
            </geometry>
        </collision>
    </link>
    <joint name="Link0_Link1" type="revolute">
       <parent link="Link0"/>
       <child  link="Link1"/>
       <origin rpy="0 0 0" xyz="0 0.07132345924761291 2.35546415128181" />
     <axis xyz="1 0 0"/>
       <limit effort="0.0" lower="-3.14159" upper="3.14159" velocity="0.0"/>
    </joint>
    <link name="Link1">
        <inertial>
            <origin xyz="0 0.07132345924761291 -0.1777320756409051" rpy="0 0 0"/>
            <mass value="1" />
            <inertia ixx="100" ixy="0" ixz="0" iyy="100" iyz="0" izz="100" />
        </inertial>
        <visual>
            <origin xyz="0 0.07132345924761291 -0.1777320756409051" rpy="0 0 0"/>
            <geometry>
                <box size="0.14887688408942934 0.14264691849522582 0.3554641512818102" />
            </geometry>
            <material name="Blue">
                <color rgba="0 0.0 1.0 1.0"/>
            </material>
        </visual>
        <collision>
            <origin xyz="0 0.07132345924761291 -0.1777320756409051" rpy="0 0 0"/>
            <geometry>
                <box size="0.14887688408942934 0.14264691849522582 0.3554641512818102" />
            </geometry>
        </collision>
    </link>
    <joint name="Link1_Link2" type="revolute">
       <parent link="Link1"/>
       <child  link="Link2"/>
       <origin rpy="0 0 0" xyz="0 0.0 0.0" />
     <axis xyz="1 0 0"/>
       <limit effort="0.0" lower="-3.14159" upper="3.14159" velocity="0.0"/>
    </joint>
    <link name="Link2">
        <inertial>
            <origin xyz="0 -0.18305727533989657 -0.25549617519036616" rpy="0 0 0"/>
            <mass value="1" />
            <inertia ixx="100" ixy="0" ixz="0" iyy="100" iyz="0" izz="100" />
        </inertial>
        <visual>
            <origin xyz="0 -0.18305727533989657 -0.25549617519036616" rpy="0 0 0"/>
            <geometry>
                <box size="0.0021468980871175436 0.36611455067979315 0.5109923503807323" />
            </geometry>
            <material name="Blue">
                <color rgba="0 0.0 1.0 1.0"/>
            </material>
        </visual>
        <collision>
            <origin xyz="0 -0.18305727533989657 -0.25549617519036616" rpy="0 0 0"/>
            <geometry>
                <box size="0.0021468980871175436 0.36611455067979315 0.5109923503807323" />
            </geometry>
        </collision>
    </link>
    <joint name="Link2_Link3" type="revolute">
       <parent link="Link2"/>
       <child  link="Link3"/>
       <origin rpy="0 0 0" xyz="0 -0.36611455067979315 0.0" />
     <axis xyz="1 0 0"/>
       <limit effort="0.0" lower="-3.14159" upper="3.14159" velocity="0.0"/>
    </joint>
    <link name="Link3">
        <inertial>
            <origin xyz="0 -0.4418480801139531 -0.15816581188801493" rpy="0 0 0"/>
            <mass value="1" />
            <inertia ixx="100" ixy="0" ixz="0" iyy="100" iyz="0" izz="100" />
        </inertial>
        <visual>
            <origin xyz="0 -0.4418480801139531 -0.15816581188801493" rpy="0 0 0"/>
            <geometry>
                <box size="0.6848690569315985 0.8836961602279062 0.31633162377602986" />
            </geometry>
            <material name="Blue">
                <color rgba="0 0.0 1.0 1.0"/>
            </material>
        </visual>
        <collision>
            <origin xyz="0 -0.4418480801139531 -0.15816581188801493" rpy="0 0 0"/>
            <geometry>
                <box size="0.6848690569315985 0.8836961602279062 0.31633162377602986" />
            </geometry>
        </collision>
    </link>
    <joint name="Link3_Link4" type="revolute">
       <parent link="Link3"/>
       <child  link="Link4"/>
       <origin rpy="0 0 0" xyz="0.34243452846579925 -0.4418480801139531 0.0" />
     <axis xyz="0 1 0"/>
       <limit effort="0.0" lower="-3.14159" upper="3.14159" velocity="0.0"/>
    </joint>
    <link name="Link4">
        <inertial>
            <origin xyz="0.06135438715666419 0 0.2793676222131468" rpy="0 0 0"/>
            <mass value="1" />
            <inertia ixx="100" ixy="0" ixz="0" iyy="100" iyz="0" izz="100" />
        </inertial>
        <visual>
            <origin xyz="0.06135438715666419 0 0.2793676222131468" rpy="0 0 0"/>
            <geometry>
                <box size="0.12270877431332838 0.2894913169619948 0.5587352444262936" />
            </geometry>
            <material name="Green">
                <color rgba="0 1.0 0.0 1.0"/>
            </material>
        </visual>
        <collision>
            <origin xyz="0.06135438715666419 0 0.2793676222131468" rpy="0 0 0"/>
            <geometry>
                <box size="0.12270877431332838 0.2894913169619948 0.5587352444262936" />
            </geometry>
        </collision>
    </link>
    <joint name="Link4_Link5" type="revolute">
       <parent link="Link4"/>
       <child  link="Link5"/>
       <origin rpy="0 0 0" xyz="0.06135438715666419 0.1447456584809974 0.5587352444262936" />
     <axis xyz="1 0 0"/>
       <limit effort="0.0" lower="-3.14159" upper="3.14159" velocity="0.0"/>
    </joint>
    <link name="Link5">
        <inertial>
            <origin xyz="0 0.30962741878001404 0.02915912009482241" rpy="0 0 0"/>
            <mass value="1" />
            <inertia ixx="100" ixy="0" ixz="0" iyy="100" iyz="0" izz="100" />
        </inertial>
        <visual>
            <origin xyz="0 0.30962741878001404 0.02915912009482241" rpy="0 0 0"/>
            <geometry>
                <box size="0.7975161746131163 0.6192548375600281 0.05831824018964482" />
            </geometry>
            <material name="Green">
                <color rgba="0 1.0 0.0 1.0"/>
            </material>
        </visual>
        <collision>
            <origin xyz="0 0.30962741878001404 0.02915912009482241" rpy="0 0 0"/>
            <geometry>
                <box size="0.7975161746131163 0.6192548375600281 0.05831824018964482" />
            </geometry>
        </collision>
    </link>
</robot>