<robot name = "robot">
    <link name="Link0">
        <inertial>
            <origin xyz="0 0 2.042554633488142" rpy="0 0 0"/>
            <mass value="1" />
            <inertia ixx="100" ixy="0" ixz="0" iyy="100" iyz="0" izz="100" />
        </inertial>
        <visual>
            <origin xyz="0 0 2.042554633488142" rpy="0 0 0"/>
            <geometry>
                <box size="0.823861636502504 0.6449556551261024 0.08510926697628363" />
            </geometry>
            <material name="Green">
                <color rgba="0 1.0 0.0 1.0"/>
            </material>
        </visual>
        <collision>
            <origin xyz="0 0 2.042554633488142" rpy="0 0 0"/>
            <geometry>
                <box size="0.823861636502504 0.6449556551261024 0.08510926697628363" />
            </geometry>
        </collision>
    </link>
    <joint name="Link0_Link1" type="revolute">
       <parent link="Link0"/>
       <child  link="Link1"/>
       <origin rpy="0 0 0" xyz="0 0.3224778275630512 2.085109266976284" />
     <axis xyz="1 0 0"/>
       <limit effort="0.0" lower="-3.14159" upper="3.14159" velocity="0.0"/>
    </joint>
    <link name="Link1">
        <inertial>
            <origin xyz="0 0.3224778275630512 -0.04255463348814181" rpy="0 0 0"/>
            <mass value="1" />
            <inertia ixx="100" ixy="0" ixz="0" iyy="100" iyz="0" izz="100" />
        </inertial>
        <visual>
            <origin xyz="0 0.3224778275630512 -0.04255463348814181" rpy="0 0 0"/>
            <geometry>
                <box size="0.823861636502504 0.6449556551261024 0.08510926697628363" />
            </geometry>
            <material name="Blue">
                <color rgba="0 0.0 1.0 1.0"/>
            </material>
        </visual>
        <collision>
            <origin xyz="0 0.3224778275630512 -0.04255463348814181" rpy="0 0 0"/>
            <geometry>
                <box size="0.823861636502504 0.6449556551261024 0.08510926697628363" />
            </geometry>
        </collision>
    </link>
    <joint name="Link1_Link2" type="revolute">
       <parent link="Link1"/>
       <child  link="Link2"/>
       <origin rpy="0 0 0" xyz="-0.411930818251252 0.3224778275630512 0.0" />
     <axis xyz="0 1 0"/>
       <limit effort="0.0" lower="-3.14159" upper="3.14159" velocity="0.0"/>
    </joint>
    <link name="Link2">
        <inertial>
            <origin xyz="-0.32440905098786793 0 0.0992178669353373" rpy="0 0 0"/>
            <mass value="1" />
            <inertia ixx="100" ixy="0" ixz="0" iyy="100" iyz="0" izz="100" />
        </inertial>
        <visual>
            <origin xyz="-0.32440905098786793 0 0.0992178669353373" rpy="0 0 0"/>
            <geometry>
                <box size="0.6488181019757359 0.5216251971363888 0.1984357338706746" />
            </geometry>
            <material name="Blue">
                <color rgba="0 0.0 1.0 1.0"/>
            </material>
        </visual>
        <collision>
            <origin xyz="-0.32440905098786793 0 0.0992178669353373" rpy="0 0 0"/>
            <geometry>
                <box size="0.6488181019757359 0.5216251971363888 0.1984357338706746" />
            </geometry>
        </collision>
    </link>
    <joint name="Link2_Link3" type="revolute">
       <parent link="Link2"/>
       <child  link="Link3"/>
       <origin rpy="0 0 0" xyz="0.0 0 0.1984357338706746" />
     <axis xyz="0 1 0"/>
       <limit effort="0.0" lower="-3.14159" upper="3.14159" velocity="0.0"/>
    </joint>
    <link name="Link3">
        <inertial>
            <origin xyz="0.15763702869886392 0 0.13132797915373046" rpy="0 0 0"/>
            <mass value="1" />
            <inertia ixx="100" ixy="0" ixz="0" iyy="100" iyz="0" izz="100" />
        </inertial>
        <visual>
            <origin xyz="0.15763702869886392 0 0.13132797915373046" rpy="0 0 0"/>
            <geometry>
                <box size="0.31527405739772785 0.03655081077388944 0.2626559583074609" />
            </geometry>
            <material name="Blue">
                <color rgba="0 0.0 1.0 1.0"/>
            </material>
        </visual>
        <collision>
            <origin xyz="0.15763702869886392 0 0.13132797915373046" rpy="0 0 0"/>
            <geometry>
                <box size="0.31527405739772785 0.03655081077388944 0.2626559583074609" />
            </geometry>
        </collision>
    </link>
    <joint name="Link3_Link4" type="revolute">
       <parent link="Link3"/>
       <child  link="Link4"/>
       <origin rpy="0 0 0" xyz="0.15763702869886392 -0.01827540538694472 0.2626559583074609" />
     <axis xyz="1 0 0"/>
       <limit effort="0.0" lower="-3.14159" upper="3.14159" velocity="0.0"/>
    </joint>
    <link name="Link4">
        <inertial>
            <origin xyz="0 -0.13755947486928233 0.3031682759232495" rpy="0 0 0"/>
            <mass value="1" />
            <inertia ixx="100" ixy="0" ixz="0" iyy="100" iyz="0" izz="100" />
        </inertial>
        <visual>
            <origin xyz="0 -0.13755947486928233 0.3031682759232495" rpy="0 0 0"/>
            <geometry>
                <box size="0.9432236884553687 0.27511894973856466 0.606336551846499" />
            </geometry>
            <material name="Green">
                <color rgba="0 1.0 0.0 1.0"/>
            </material>
        </visual>
        <collision>
            <origin xyz="0 -0.13755947486928233 0.3031682759232495" rpy="0 0 0"/>
            <geometry>
                <box size="0.9432236884553687 0.27511894973856466 0.606336551846499" />
            </geometry>
        </collision>
    </link>
    <joint name="Link4_Link5" type="revolute">
       <parent link="Link4"/>
       <child  link="Link5"/>
       <origin rpy="0 0 0" xyz="0 0.0 0.606336551846499" />
     <axis xyz="1 0 0"/>
       <limit effort="0.0" lower="-3.14159" upper="3.14159" velocity="0.0"/>
    </joint>
    <link name="Link5">
        <inertial>
            <origin xyz="0 0.4546275078987741 -0.3997926523947194" rpy="0 0 0"/>
            <mass value="1" />
            <inertia ixx="100" ixy="0" ixz="0" iyy="100" iyz="0" izz="100" />
        </inertial>
        <visual>
            <origin xyz="0 0.4546275078987741 -0.3997926523947194" rpy="0 0 0"/>
            <geometry>
                <box size="0.7285421000943881 0.9092550157975482 0.7995853047894388" />
            </geometry>
            <material name="Green">
                <color rgba="0 1.0 0.0 1.0"/>
            </material>
        </visual>
        <collision>
            <origin xyz="0 0.4546275078987741 -0.3997926523947194" rpy="0 0 0"/>
            <geometry>
                <box size="0.7285421000943881 0.9092550157975482 0.7995853047894388" />
            </geometry>
        </collision>
    </link>
</robot>