<robot name = "robot">
    <link name="Link0">
        <inertial>
            <origin xyz="0 0 2.342159855206402" rpy="0 0 0"/>
            <mass value="1" />
            <inertia ixx="100" ixy="0" ixz="0" iyy="100" iyz="0" izz="100" />
        </inertial>
        <visual>
            <origin xyz="0 0 2.342159855206402" rpy="0 0 0"/>
            <geometry>
                <box size="0.40846712726398926 0.5799511810477197 0.6843197104128036" />
            </geometry>
            <material name="Green">
                <color rgba="0 1.0 0.0 1.0"/>
            </material>
        </visual>
        <collision>
            <origin xyz="0 0 2.342159855206402" rpy="0 0 0"/>
            <geometry>
                <box size="0.40846712726398926 0.5799511810477197 0.6843197104128036" />
            </geometry>
        </collision>
    </link>
    <joint name="Link0_Link1" type="revolute">
       <parent link="Link0"/>
       <child  link="Link1"/>
       <origin rpy="0 0 0" xyz="0 0.28997559052385985 2.6843197104128036" />
     <axis xyz="1 0 0"/>
       <limit effort="0.0" lower="-3.14159" upper="3.14159" velocity="0.0"/>
    </joint>
    <link name="Link1">
        <inertial>
            <origin xyz="0 0.28997559052385985 -0.3421598552064018" rpy="0 0 0"/>
            <mass value="1" />
            <inertia ixx="100" ixy="0" ixz="0" iyy="100" iyz="0" izz="100" />
        </inertial>
        <visual>
            <origin xyz="0 0.28997559052385985 -0.3421598552064018" rpy="0 0 0"/>
            <geometry>
                <box size="0.40846712726398926 0.5799511810477197 0.6843197104128036" />
            </geometry>
            <material name="Green">
                <color rgba="0 1.0 0.0 1.0"/>
            </material>
        </visual>
        <collision>
            <origin xyz="0 0.28997559052385985 -0.3421598552064018" rpy="0 0 0"/>
            <geometry>
                <box size="0.40846712726398926 0.5799511810477197 0.6843197104128036" />
            </geometry>
        </collision>
    </link>
    <joint name="Link1_Link2" type="revolute">
       <parent link="Link1"/>
       <child  link="Link2"/>
       <origin rpy="0 0 0" xyz="0.20423356363199463 0.28997559052385985 0.0" />
     <axis xyz="0 1 0"/>
       <limit effort="0.0" lower="-3.14159" upper="3.14159" velocity="0.0"/>
    </joint>
    <link name="Link2">
        <inertial>
            <origin xyz="0.4659255186570496 0 -0.3388391371553037" rpy="0 0 0"/>
            <mass value="1" />
            <inertia ixx="100" ixy="0" ixz="0" iyy="100" iyz="0" izz="100" />
        </inertial>
        <visual>
            <origin xyz="0.4659255186570496 0 -0.3388391371553037" rpy="0 0 0"/>
            <geometry>
                <box size="0.9318510373140992 0.26376477922945374 0.6776782743106075" />
            </geometry>
            <material name="Blue">
                <color rgba="0 0.0 1.0 1.0"/>
            </material>
        </visual>
        <collision>
            <origin xyz="0.4659255186570496 0 -0.3388391371553037" rpy="0 0 0"/>
            <geometry>
                <box size="0.9318510373140992 0.26376477922945374 0.6776782743106075" />
            </geometry>
        </collision>
    </link>
    <joint name="Link2_Link3" type="revolute">
       <parent link="Link2"/>
       <child  link="Link3"/>
       <origin rpy="0 0 0" xyz="0.4659255186570496 -0.13188238961472687 0.0" />
     <axis xyz="1 0 0"/>
       <limit effort="0.0" lower="-3.14159" upper="3.14159" velocity="0.0"/>
    </joint>
    <link name="Link3">
        <inertial>
            <origin xyz="0 -0.4510124768018671 -0.24780628066066246" rpy="0 0 0"/>
            <mass value="1" />
            <inertia ixx="100" ixy="0" ixz="0" iyy="100" iyz="0" izz="100" />
        </inertial>
        <visual>
            <origin xyz="0 -0.4510124768018671 -0.24780628066066246" rpy="0 0 0"/>
            <geometry>
                <box size="0.13002445230520454 0.9020249536037342 0.4956125613213249" />
            </geometry>
            <material name="Blue">
                <color rgba="0 0.0 1.0 1.0"/>
            </material>
        </visual>
        <collision>
            <origin xyz="0 -0.4510124768018671 -0.24780628066066246" rpy="0 0 0"/>
            <geometry>
                <box size="0.13002445230520454 0.9020249536037342 0.4956125613213249" />
            </geometry>
        </collision>
    </link>
    <joint name="Link3_Link4" type="revolute">
       <parent link="Link3"/>
       <child  link="Link4"/>
       <origin rpy="0 0 0" xyz="0 -0.9020249536037342 0.0" />
     <axis xyz="1 0 0"/>
       <limit effort="0.0" lower="-3.14159" upper="3.14159" velocity="0.0"/>
    </joint>
    <link name="Link4">
        <inertial>
            <origin xyz="0 -0.07050002502753216 0.1153625912339048" rpy="0 0 0"/>
            <mass value="1" />
            <inertia ixx="100" ixy="0" ixz="0" iyy="100" iyz="0" izz="100" />
        </inertial>
        <visual>
            <origin xyz="0 -0.07050002502753216 0.1153625912339048" rpy="0 0 0"/>
            <geometry>
                <box size="0.4259056833106373 0.14100005005506433 0.2307251824678096" />
            </geometry>
            <material name="Blue">
                <color rgba="0 0.0 1.0 1.0"/>
            </material>
        </visual>
        <collision>
            <origin xyz="0 -0.07050002502753216 0.1153625912339048" rpy="0 0 0"/>
            <geometry>
                <box size="0.4259056833106373 0.14100005005506433 0.2307251824678096" />
            </geometry>
        </collision>
    </link>
</robot>