<robot name = "robot">
    <link name="Link0">
        <inertial>
            <origin xyz="0 0 2.386226422206403" rpy="0 0 0"/>
            <mass value="1" />
            <inertia ixx="100" ixy="0" ixz="0" iyy="100" iyz="0" izz="100" />
        </inertial>
        <visual>
            <origin xyz="0 0 2.386226422206403" rpy="0 0 0"/>
            <geometry>
                <box size="0.28511464350194693 0.4099957838275251 0.7724528444128054" />
            </geometry>
            <material name="Green">
                <color rgba="0 1.0 0.0 1.0"/>
            </material>
        </visual>
        <collision>
            <origin xyz="0 0 2.386226422206403" rpy="0 0 0"/>
            <geometry>
                <box size="0.28511464350194693 0.4099957838275251 0.7724528444128054" />
            </geometry>
        </collision>
    </link>
    <joint name="Link0_Link1" type="revolute">
       <parent link="Link0"/>
       <child  link="Link1"/>
       <origin rpy="0 0 0" xyz="0 0.20499789191376255 2.7724528444128054" />
     <axis xyz="1 0 0"/>
       <limit effort="0.0" lower="-3.14159" upper="3.14159" velocity="0.0"/>
    </joint>
    <link name="Link1">
        <inertial>
            <origin xyz="0 0.20499789191376255 -0.3862264222064027" rpy="0 0 0"/>
            <mass value="1" />
            <inertia ixx="100" ixy="0" ixz="0" iyy="100" iyz="0" izz="100" />
        </inertial>
        <visual>
            <origin xyz="0 0.20499789191376255 -0.3862264222064027" rpy="0 0 0"/>
            <geometry>
                <box size="0.28511464350194693 0.4099957838275251 0.7724528444128054" />
            </geometry>
            <material name="Green">
                <color rgba="0 1.0 0.0 1.0"/>
            </material>
        </visual>
        <collision>
            <origin xyz="0 0.20499789191376255 -0.3862264222064027" rpy="0 0 0"/>
            <geometry>
                <box size="0.28511464350194693 0.4099957838275251 0.7724528444128054" />
            </geometry>
        </collision>
    </link>
    <joint name="Link1_Link2" type="revolute">
       <parent link="Link1"/>
       <child  link="Link2"/>
       <origin rpy="0 0 0" xyz="0 0.0 0.0" />
     <axis xyz="1 0 0"/>
       <limit effort="0.0" lower="-3.14159" upper="3.14159" velocity="0.0"/>
    </joint>
    <link name="Link2">
        <inertial>
            <origin xyz="0 -0.2220039502018183 -0.39614127810034117" rpy="0 0 0"/>
            <mass value="1" />
            <inertia ixx="100" ixy="0" ixz="0" iyy="100" iyz="0" izz="100" />
        </inertial>
        <visual>
            <origin xyz="0 -0.2220039502018183 -0.39614127810034117" rpy="0 0 0"/>
            <geometry>
                <box size="0.7432209699506049 0.4440079004036366 0.7922825562006823" />
            </geometry>
            <material name="Green">
                <color rgba="0 1.0 0.0 1.0"/>
            </material>
        </visual>
        <collision>
            <origin xyz="0 -0.2220039502018183 -0.39614127810034117" rpy="0 0 0"/>
            <geometry>
                <box size="0.7432209699506049 0.4440079004036366 0.7922825562006823" />
            </geometry>
        </collision>
    </link>
    <joint name="Link2_Link3" type="revolute">
       <parent link="Link2"/>
       <child  link="Link3"/>
       <origin rpy="0 0 0" xyz="-0.37161048497530247 -0.2220039502018183 0.0" />
     <axis xyz="0 1 0"/>
       <limit effort="0.0" lower="-3.14159" upper="3.14159" velocity="0.0"/>
    </joint>
    <link name="Link3">
        <inertial>
            <origin xyz="-0.05479999701085114 0 0.471551146672435" rpy="0 0 0"/>
            <mass value="1" />
            <inertia ixx="100" ixy="0" ixz="0" iyy="100" iyz="0" izz="100" />
        </inertial>
        <visual>
            <origin xyz="-0.05479999701085114 0 0.471551146672435" rpy="0 0 0"/>
            <geometry>
                <box size="0.10959999402170228 0.15692961589596122 0.94310229334487" />
            </geometry>
            <material name="Green">
                <color rgba="0 1.0 0.0 1.0"/>
            </material>
        </visual>
        <collision>
            <origin xyz="-0.05479999701085114 0 0.471551146672435" rpy="0 0 0"/>
            <geometry>
                <box size="0.10959999402170228 0.15692961589596122 0.94310229334487" />
            </geometry>
        </collision>
    </link>
    <joint name="Link3_Link4" type="revolute">
       <parent link="Link3"/>
       <child  link="Link4"/>
       <origin rpy="0 0 0" xyz="-0.05479999701085114 -0.07846480794798061 0.94310229334487" />
     <axis xyz="1 0 0"/>
       <limit effort="0.0" lower="-3.14159" upper="3.14159" velocity="0.0"/>
    </joint>
    <link name="Link4">
        <inertial>
            <origin xyz="0 -0.06522864549195462 -0.48364781314102023" rpy="0 0 0"/>
            <mass value="1" />
            <inertia ixx="100" ixy="0" ixz="0" iyy="100" iyz="0" izz="100" />
        </inertial>
        <visual>
            <origin xyz="0 -0.06522864549195462 -0.48364781314102023" rpy="0 0 0"/>
            <geometry>
                <box size="0.7665718108392888 0.13045729098390924 0.9672956262820405" />
            </geometry>
            <material name="Blue">
                <color rgba="0 0.0 1.0 1.0"/>
            </material>
        </visual>
        <collision>
            <origin xyz="0 -0.06522864549195462 -0.48364781314102023" rpy="0 0 0"/>
            <geometry>
                <box size="0.7665718108392888 0.13045729098390924 0.9672956262820405" />
            </geometry>
        </collision>
    </link>
    <joint name="Link4_Link5" type="revolute">
       <parent link="Link4"/>
       <child  link="Link5"/>
       <origin rpy="0 0 0" xyz="0.3832859054196444 -0.06522864549195462 0.0" />
     <axis xyz="0 1 0"/>
       <limit effort="0.0" lower="-3.14159" upper="3.14159" velocity="0.0"/>
    </joint>
    <link name="Link5">
        <inertial>
            <origin xyz="0.2302811171813932 0 0.009047743078623882" rpy="0 0 0"/>
            <mass value="1" />
            <inertia ixx="100" ixy="0" ixz="0" iyy="100" iyz="0" izz="100" />
        </inertial>
        <visual>
            <origin xyz="0.2302811171813932 0 0.009047743078623882" rpy="0 0 0"/>
            <geometry>
                <box size="0.4605622343627864 0.01189780280049657 0.018095486157247764" />
            </geometry>
            <material name="Blue">
                <color rgba="0 0.0 1.0 1.0"/>
            </material>
        </visual>
        <collision>
            <origin xyz="0.2302811171813932 0 0.009047743078623882" rpy="0 0 0"/>
            <geometry>
                <box size="0.4605622343627864 0.01189780280049657 0.018095486157247764" />
            </geometry>
        </collision>
    </link>
    <joint name="Link5_Link6" type="revolute">
       <parent link="Link5"/>
       <child  link="Link6"/>
       <origin rpy="0 0 0" xyz="0.2302811171813932 -0.005948901400248285 0.018095486157247764" />
     <axis xyz="1 0 0"/>
       <limit effort="0.0" lower="-3.14159" upper="3.14159" velocity="0.0"/>
    </joint>
    <link name="Link6">
        <inertial>
            <origin xyz="0 -0.3478565278914112 -0.39239466221839137" rpy="0 0 0"/>
            <mass value="1" />
            <inertia ixx="100" ixy="0" ixz="0" iyy="100" iyz="0" izz="100" />
        </inertial>
        <visual>
            <origin xyz="0 -0.3478565278914112 -0.39239466221839137" rpy="0 0 0"/>
            <geometry>
                <box size="0.1295676194186548 0.6957130557828224 0.7847893244367827" />
            </geometry>
            <material name="Blue">
                <color rgba="0 0.0 1.0 1.0"/>
            </material>
        </visual>
        <collision>
            <origin xyz="0 -0.3478565278914112 -0.39239466221839137" rpy="0 0 0"/>
            <geometry>
                <box size="0.1295676194186548 0.6957130557828224 0.7847893244367827" />
            </geometry>
        </collision>
    </link>
</robot>