<robot name = "robot">
    <link name="Link0">
        <inertial>
            <origin xyz="0 0 2.3189013055824237" rpy="0 0 0"/>
            <mass value="1" />
            <inertia ixx="100" ixy="0" ixz="0" iyy="100" iyz="0" izz="100" />
        </inertial>
        <visual>
            <origin xyz="0 0 2.3189013055824237" rpy="0 0 0"/>
            <geometry>
                <box size="0.2535607558680565 0.4587672834651084 0.6378026111648478" />
            </geometry>
            <material name="Green">
                <color rgba="0 1.0 0.0 1.0"/>
            </material>
        </visual>
        <collision>
            <origin xyz="0 0 2.3189013055824237" rpy="0 0 0"/>
            <geometry>
                <box size="0.2535607558680565 0.4587672834651084 0.6378026111648478" />
            </geometry>
        </collision>
    </link>
    <joint name="Link0_Link1" type="revolute">
       <parent link="Link0"/>
       <child  link="Link1"/>
       <origin rpy="0 0 0" xyz="0 0.2293836417325542 2.637802611164848" />
     <axis xyz="1 0 0"/>
       <limit effort="0.0" lower="-3.14159" upper="3.14159" velocity="0.0"/>
    </joint>
    <link name="Link1">
        <inertial>
            <origin xyz="0 0.2293836417325542 -0.3189013055824239" rpy="0 0 0"/>
            <mass value="1" />
            <inertia ixx="100" ixy="0" ixz="0" iyy="100" iyz="0" izz="100" />
        </inertial>
        <visual>
            <origin xyz="0 0.2293836417325542 -0.3189013055824239" rpy="0 0 0"/>
            <geometry>
                <box size="0.2535607558680565 0.4587672834651084 0.6378026111648478" />
            </geometry>
            <material name="Blue">
                <color rgba="0 0.0 1.0 1.0"/>
            </material>
        </visual>
        <collision>
            <origin xyz="0 0.2293836417325542 -0.3189013055824239" rpy="0 0 0"/>
            <geometry>
                <box size="0.2535607558680565 0.4587672834651084 0.6378026111648478" />
            </geometry>
        </collision>
    </link>
    <joint name="Link1_Link2" type="revolute">
       <parent link="Link1"/>
       <child  link="Link2"/>
       <origin rpy="0 0 0" xyz="-0.12678037793402824 0.2293836417325542 0.0" />
     <axis xyz="0 1 0"/>
       <limit effort="0.0" lower="-3.14159" upper="3.14159" velocity="0.0"/>
    </joint>
    <link name="Link2">
        <inertial>
            <origin xyz="-0.09830876297852997 0 -0.2912963972802109" rpy="0 0 0"/>
            <mass value="1" />
            <inertia ixx="100" ixy="0" ixz="0" iyy="100" iyz="0" izz="100" />
        </inertial>
        <visual>
            <origin xyz="-0.09830876297852997 0 -0.2912963972802109" rpy="0 0 0"/>
            <geometry>
                <box size="0.19661752595705995 0.4008499984979378 0.5825927945604218" />
            </geometry>
            <material name="Blue">
                <color rgba="0 0.0 1.0 1.0"/>
            </material>
        </visual>
        <collision>
            <origin xyz="-0.09830876297852997 0 -0.2912963972802109" rpy="0 0 0"/>
            <geometry>
                <box size="0.19661752595705995 0.4008499984979378 0.5825927945604218" />
            </geometry>
        </collision>
    </link>
    <joint name="Link2_Link3" type="revolute">
       <parent link="Link2"/>
       <child  link="Link3"/>
       <origin rpy="0 0 0" xyz="-0.09830876297852997 0.2004249992489689 0.0" />
     <axis xyz="1 0 0"/>
       <limit effort="0.0" lower="-3.14159" upper="3.14159" velocity="0.0"/>
    </joint>
    <link name="Link3">
        <inertial>
            <origin xyz="0 0.16020690445339425 0.004684499955694921" rpy="0 0 0"/>
            <mass value="1" />
            <inertia ixx="100" ixy="0" ixz="0" iyy="100" iyz="0" izz="100" />
        </inertial>
        <visual>
            <origin xyz="0 0.16020690445339425 0.004684499955694921" rpy="0 0 0"/>
            <geometry>
                <box size="0.398910046161822 0.3204138089067885 0.009368999911389841" />
            </geometry>
            <material name="Blue">
                <color rgba="0 0.0 1.0 1.0"/>
            </material>
        </visual>
        <collision>
            <origin xyz="0 0.16020690445339425 0.004684499955694921" rpy="0 0 0"/>
            <geometry>
                <box size="0.398910046161822 0.3204138089067885 0.009368999911389841" />
            </geometry>
        </collision>
    </link>
    <joint name="Link3_Link4" type="revolute">
       <parent link="Link3"/>
       <child  link="Link4"/>
       <origin rpy="0 0 0" xyz="0.199455023080911 0.16020690445339425 0.009368999911389841" />
     <axis xyz="0 1 0"/>
       <limit effort="0.0" lower="-3.14159" upper="3.14159" velocity="0.0"/>
    </joint>
    <link name="Link4">
        <inertial>
            <origin xyz="0.18572813060582405 0 -0.10544123470436667" rpy="0 0 0"/>
            <mass value="1" />
            <inertia ixx="100" ixy="0" ixz="0" iyy="100" iyz="0" izz="100" />
        </inertial>
        <visual>
            <origin xyz="0.18572813060582405 0 -0.10544123470436667" rpy="0 0 0"/>
            <geometry>
                <box size="0.3714562612116481 0.9479346450432563 0.21088246940873334" />
            </geometry>
            <material name="Green">
                <color rgba="0 1.0 0.0 1.0"/>
            </material>
        </visual>
        <collision>
            <origin xyz="0.18572813060582405 0 -0.10544123470436667" rpy="0 0 0"/>
            <geometry>
                <box size="0.3714562612116481 0.9479346450432563 0.21088246940873334" />
            </geometry>
        </collision>
    </link>
    <joint name="Link4_Link5" type="revolute">
       <parent link="Link4"/>
       <child  link="Link5"/>
       <origin rpy="0 0 0" xyz="0.3714562612116481 0 0.0" />
     <axis xyz="0 1 0"/>
       <limit effort="0.0" lower="-3.14159" upper="3.14159" velocity="0.0"/>
    </joint>
    <link name="Link5">
        <inertial>
            <origin xyz="0.44464649055173644 0 -0.23962131609349296" rpy="0 0 0"/>
            <mass value="1" />
            <inertia ixx="100" ixy="0" ixz="0" iyy="100" iyz="0" izz="100" />
        </inertial>
        <visual>
            <origin xyz="0.44464649055173644 0 -0.23962131609349296" rpy="0 0 0"/>
            <geometry>
                <box size="0.8892929811034729 0.37589235433231605 0.47924263218698593" />
            </geometry>
            <material name="Green">
                <color rgba="0 1.0 0.0 1.0"/>
            </material>
        </visual>
        <collision>
            <origin xyz="0.44464649055173644 0 -0.23962131609349296" rpy="0 0 0"/>
            <geometry>
                <box size="0.8892929811034729 0.37589235433231605 0.47924263218698593" />
            </geometry>
        </collision>
    </link>
</robot>