<robot name = "robot">
    <link name="Link0">
        <inertial>
            <origin xyz="0 0 2.279671141866081" rpy="0 0 0"/>
            <mass value="1" />
            <inertia ixx="100" ixy="0" ixz="0" iyy="100" iyz="0" izz="100" />
        </inertial>
        <visual>
            <origin xyz="0 0 2.279671141866081" rpy="0 0 0"/>
            <geometry>
                <box size="0.5062423440023336 0.8786841677558919 0.5593422837321618" />
            </geometry>
            <material name="Green">
                <color rgba="0 1.0 0.0 1.0"/>
            </material>
        </visual>
        <collision>
            <origin xyz="0 0 2.279671141866081" rpy="0 0 0"/>
            <geometry>
                <box size="0.5062423440023336 0.8786841677558919 0.5593422837321618" />
            </geometry>
        </collision>
    </link>
    <joint name="Link0_Link1" type="revolute">
       <parent link="Link0"/>
       <child  link="Link1"/>
       <origin rpy="0 0 0" xyz="0 0.43934208387794593 2.5593422837321618" />
     <axis xyz="1 0 0"/>
       <limit effort="0.0" lower="-3.14159" upper="3.14159" velocity="0.0"/>
    </joint>
    <link name="Link1">
        <inertial>
            <origin xyz="0 0.43934208387794593 -0.2796711418660809" rpy="0 0 0"/>
            <mass value="1" />
            <inertia ixx="100" ixy="0" ixz="0" iyy="100" iyz="0" izz="100" />
        </inertial>
        <visual>
            <origin xyz="0 0.43934208387794593 -0.2796711418660809" rpy="0 0 0"/>
            <geometry>
                <box size="0.5062423440023336 0.8786841677558919 0.5593422837321618" />
            </geometry>
            <material name="Blue">
                <color rgba="0 0.0 1.0 1.0"/>
            </material>
        </visual>
        <collision>
            <origin xyz="0 0.43934208387794593 -0.2796711418660809" rpy="0 0 0"/>
            <geometry>
                <box size="0.5062423440023336 0.8786841677558919 0.5593422837321618" />
            </geometry>
        </collision>
    </link>
    <joint name="Link1_Link2" type="revolute">
       <parent link="Link1"/>
       <child  link="Link2"/>
       <origin rpy="0 0 0" xyz="0.2531211720011668 0.43934208387794593 0.0" />
     <axis xyz="0 1 0"/>
       <limit effort="0.0" lower="-3.14159" upper="3.14159" velocity="0.0"/>
    </joint>
    <link name="Link2">
        <inertial>
            <origin xyz="0.23279791979063136 0 -0.07014467095203614" rpy="0 0 0"/>
            <mass value="1" />
            <inertia ixx="100" ixy="0" ixz="0" iyy="100" iyz="0" izz="100" />
        </inertial>
        <visual>
            <origin xyz="0.23279791979063136 0 -0.07014467095203614" rpy="0 0 0"/>
            <geometry>
                <box size="0.4655958395812627 0.05004374150743396 0.14028934190407227" />
            </geometry>
            <material name="Blue">
                <color rgba="0 0.0 1.0 1.0"/>
            </material>
        </visual>
        <collision>
            <origin xyz="0.23279791979063136 0 -0.07014467095203614" rpy="0 0 0"/>
            <geometry>
                <box size="0.4655958395812627 0.05004374150743396 0.14028934190407227" />
            </geometry>
        </collision>
    </link>
    <joint name="Link2_Link3" type="revolute">
       <parent link="Link2"/>
       <child  link="Link3"/>
       <origin rpy="0 0 0" xyz="0.23279791979063136 0.02502187075371698 0.0" />
     <axis xyz="1 0 0"/>
       <limit effort="0.0" lower="-3.14159" upper="3.14159" velocity="0.0"/>
    </joint>
    <link name="Link3">
        <inertial>
            <origin xyz="0 0.42642498018518943 -0.3602186378187664" rpy="0 0 0"/>
            <mass value="1" />
            <inertia ixx="100" ixy="0" ixz="0" iyy="100" iyz="0" izz="100" />
        </inertial>
        <visual>
            <origin xyz="0 0.42642498018518943 -0.3602186378187664" rpy="0 0 0"/>
            <geometry>
                <box size="0.05594714348582652 0.8528499603703789 0.7204372756375328" />
            </geometry>
            <material name="Green">
                <color rgba="0 1.0 0.0 1.0"/>
            </material>
        </visual>
        <collision>
            <origin xyz="0 0.42642498018518943 -0.3602186378187664" rpy="0 0 0"/>
            <geometry>
                <box size="0.05594714348582652 0.8528499603703789 0.7204372756375328" />
            </geometry>
        </collision>
    </link>
    <joint name="Link3_Link4" type="revolute">
       <parent link="Link3"/>
       <child  link="Link4"/>
       <origin rpy="0 0 0" xyz="0 0.8528499603703789 0.0" />
     <axis xyz="1 0 0"/>
       <limit effort="0.0" lower="-3.14159" upper="3.14159" velocity="0.0"/>
    </joint>
    <link name="Link4">
        <inertial>
            <origin xyz="0 0.09877854436697242 -0.14209190656579274" rpy="0 0 0"/>
            <mass value="1" />
            <inertia ixx="100" ixy="0" ixz="0" iyy="100" iyz="0" izz="100" />
        </inertial>
        <visual>
            <origin xyz="0 0.09877854436697242 -0.14209190656579274" rpy="0 0 0"/>
            <geometry>
                <box size="0.2881836376550708 0.19755708873394484 0.28418381313158547" />
            </geometry>
            <material name="Blue">
                <color rgba="0 0.0 1.0 1.0"/>
            </material>
        </visual>
        <collision>
            <origin xyz="0 0.09877854436697242 -0.14209190656579274" rpy="0 0 0"/>
            <geometry>
                <box size="0.2881836376550708 0.19755708873394484 0.28418381313158547" />
            </geometry>
        </collision>
    </link>
</robot>