<robot name = "robot">
    <link name="Link0">
        <inertial>
            <origin xyz="0 0 2.445365179734938" rpy="0 0 0"/>
            <mass value="1" />
            <inertia ixx="100" ixy="0" ixz="0" iyy="100" iyz="0" izz="100" />
        </inertial>
        <visual>
            <origin xyz="0 0 2.445365179734938" rpy="0 0 0"/>
            <geometry>
                <box size="0.3695394208973224 0.6904101403279782 0.8907303594698754" />
            </geometry>
            <material name="Green">
                <color rgba="0 1.0 0.0 1.0"/>
            </material>
        </visual>
        <collision>
            <origin xyz="0 0 2.445365179734938" rpy="0 0 0"/>
            <geometry>
                <box size="0.3695394208973224 0.6904101403279782 0.8907303594698754" />
            </geometry>
        </collision>
    </link>
    <joint name="Link0_Link1" type="revolute">
       <parent link="Link0"/>
       <child  link="Link1"/>
       <origin rpy="0 0 0" xyz="0 0.3452050701639891 2.8907303594698757" />
     <axis xyz="1 0 0"/>
       <limit effort="0.0" lower="-3.14159" upper="3.14159" velocity="0.0"/>
    </joint>
    <link name="Link1">
        <inertial>
            <origin xyz="0 0.3452050701639891 -0.4453651797349377" rpy="0 0 0"/>
            <mass value="1" />
            <inertia ixx="100" ixy="0" ixz="0" iyy="100" iyz="0" izz="100" />
        </inertial>
        <visual>
            <origin xyz="0 0.3452050701639891 -0.4453651797349377" rpy="0 0 0"/>
            <geometry>
                <box size="0.3695394208973224 0.6904101403279782 0.8907303594698754" />
            </geometry>
            <material name="Blue">
                <color rgba="0 0.0 1.0 1.0"/>
            </material>
        </visual>
        <collision>
            <origin xyz="0 0.3452050701639891 -0.4453651797349377" rpy="0 0 0"/>
            <geometry>
                <box size="0.3695394208973224 0.6904101403279782 0.8907303594698754" />
            </geometry>
        </collision>
    </link>
    <joint name="Link1_Link2" type="revolute">
       <parent link="Link1"/>
       <child  link="Link2"/>
       <origin rpy="0 0 0" xyz="-0.1847697104486612 0.3452050701639891 0.0" />
     <axis xyz="0 1 0"/>
       <limit effort="0.0" lower="-3.14159" upper="3.14159" velocity="0.0"/>
    </joint>
    <link name="Link2">
        <inertial>
            <origin xyz="-0.16834578890498886 0 0.4815441547640444" rpy="0 0 0"/>
            <mass value="1" />
            <inertia ixx="100" ixy="0" ixz="0" iyy="100" iyz="0" izz="100" />
        </inertial>
        <visual>
            <origin xyz="-0.16834578890498886 0 0.4815441547640444" rpy="0 0 0"/>
            <geometry>
                <box size="0.3366915778099777 0.4171651122278959 0.9630883095280888" />
            </geometry>
            <material name="Green">
                <color rgba="0 1.0 0.0 1.0"/>
            </material>
        </visual>
        <collision>
            <origin xyz="-0.16834578890498886 0 0.4815441547640444" rpy="0 0 0"/>
            <geometry>
                <box size="0.3366915778099777 0.4171651122278959 0.9630883095280888" />
            </geometry>
        </collision>
    </link>
    <joint name="Link2_Link3" type="revolute">
       <parent link="Link2"/>
       <child  link="Link3"/>
       <origin rpy="0 0 0" xyz="-0.16834578890498886 -0.20858255611394794 0.9630883095280888" />
     <axis xyz="1 0 0"/>
       <limit effort="0.0" lower="-3.14159" upper="3.14159" velocity="0.0"/>
    </joint>
    <link name="Link3">
        <inertial>
            <origin xyz="0 -0.19802504280429217 0.38942231842390607" rpy="0 0 0"/>
            <mass value="1" />
            <inertia ixx="100" ixy="0" ixz="0" iyy="100" iyz="0" izz="100" />
        </inertial>
        <visual>
            <origin xyz="0 -0.19802504280429217 0.38942231842390607" rpy="0 0 0"/>
            <geometry>
                <box size="0.6340387405514233 0.39605008560858435 0.7788446368478121" />
            </geometry>
            <material name="Blue">
                <color rgba="0 0.0 1.0 1.0"/>
            </material>
        </visual>
        <collision>
            <origin xyz="0 -0.19802504280429217 0.38942231842390607" rpy="0 0 0"/>
            <geometry>
                <box size="0.6340387405514233 0.39605008560858435 0.7788446368478121" />
            </geometry>
        </collision>
    </link>
    <joint name="Link3_Link4" type="revolute">
       <parent link="Link3"/>
       <child  link="Link4"/>
       <origin rpy="0 0 0" xyz="0 0.0 0.7788446368478121" />
     <axis xyz="1 0 0"/>
       <limit effort="0.0" lower="-3.14159" upper="3.14159" velocity="0.0"/>
    </joint>
    <link name="Link4">
        <inertial>
            <origin xyz="0 0.38086350268037195 0.19042250787202886" rpy="0 0 0"/>
            <mass value="1" />
            <inertia ixx="100" ixy="0" ixz="0" iyy="100" iyz="0" izz="100" />
        </inertial>
        <visual>
            <origin xyz="0 0.38086350268037195 0.19042250787202886" rpy="0 0 0"/>
            <geometry>
                <box size="0.5333875600687674 0.7617270053607439 0.3808450157440577" />
            </geometry>
            <material name="Green">
                <color rgba="0 1.0 0.0 1.0"/>
            </material>
        </visual>
        <collision>
            <origin xyz="0 0.38086350268037195 0.19042250787202886" rpy="0 0 0"/>
            <geometry>
                <box size="0.5333875600687674 0.7617270053607439 0.3808450157440577" />
            </geometry>
        </collision>
    </link>
</robot>