<robot name = "robot">
    <link name="Link0">
        <inertial>
            <origin xyz="0 0 2.4355678524317845" rpy="0 0 0"/>
            <mass value="1" />
            <inertia ixx="100" ixy="0" ixz="0" iyy="100" iyz="0" izz="100" />
        </inertial>
        <visual>
            <origin xyz="0 0 2.4355678524317845" rpy="0 0 0"/>
            <geometry>
                <box size="0.4634371730334159 0.040084456199805496 0.8711357048635691" />
            </geometry>
            <material name="Green">
                <color rgba="0 1.0 0.0 1.0"/>
            </material>
        </visual>
        <collision>
            <origin xyz="0 0 2.4355678524317845" rpy="0 0 0"/>
            <geometry>
                <box size="0.4634371730334159 0.040084456199805496 0.8711357048635691" />
            </geometry>
        </collision>
    </link>
    <joint name="Link0_Link1" type="revolute">
       <parent link="Link0"/>
       <child  link="Link1"/>
       <origin rpy="0 0 0" xyz="0 0.020042228099902748 2.871135704863569" />
     <axis xyz="1 0 0"/>
       <limit effort="0.0" lower="-3.14159" upper="3.14159" velocity="0.0"/>
    </joint>
    <link name="Link1">
        <inertial>
            <origin xyz="0 0.020042228099902748 -0.43556785243178453" rpy="0 0 0"/>
            <mass value="1" />
            <inertia ixx="100" ixy="0" ixz="0" iyy="100" iyz="0" izz="100" />
        </inertial>
        <visual>
            <origin xyz="0 0.020042228099902748 -0.43556785243178453" rpy="0 0 0"/>
            <geometry>
                <box size="0.4634371730334159 0.040084456199805496 0.8711357048635691" />
            </geometry>
            <material name="Blue">
                <color rgba="0 0.0 1.0 1.0"/>
            </material>
        </visual>
        <collision>
            <origin xyz="0 0.020042228099902748 -0.43556785243178453" rpy="0 0 0"/>
            <geometry>
                <box size="0.4634371730334159 0.040084456199805496 0.8711357048635691" />
            </geometry>
        </collision>
    </link>
    <joint name="Link1_Link2" type="revolute">
       <parent link="Link1"/>
       <child  link="Link2"/>
       <origin rpy="0 0 0" xyz="0 0.040084456199805496 0.0" />
     <axis xyz="1 0 0"/>
       <limit effort="0.0" lower="-3.14159" upper="3.14159" velocity="0.0"/>
    </joint>
    <link name="Link2">
        <inertial>
            <origin xyz="0 0.2690515845473818 -0.25250826600940396" rpy="0 0 0"/>
            <mass value="1" />
            <inertia ixx="100" ixy="0" ixz="0" iyy="100" iyz="0" izz="100" />
        </inertial>
        <visual>
            <origin xyz="0 0.2690515845473818 -0.25250826600940396" rpy="0 0 0"/>
            <geometry>
                <box size="0.6331203827137893 0.5381031690947636 0.5050165320188079" />
            </geometry>
            <material name="Blue">
                <color rgba="0 0.0 1.0 1.0"/>
            </material>
        </visual>
        <collision>
            <origin xyz="0 0.2690515845473818 -0.25250826600940396" rpy="0 0 0"/>
            <geometry>
                <box size="0.6331203827137893 0.5381031690947636 0.5050165320188079" />
            </geometry>
        </collision>
    </link>
    <joint name="Link2_Link3" type="revolute">
       <parent link="Link2"/>
       <child  link="Link3"/>
       <origin rpy="0 0 0" xyz="0.31656019135689467 0.2690515845473818 0.0" />
     <axis xyz="0 1 0"/>
       <limit effort="0.0" lower="-3.14159" upper="3.14159" velocity="0.0"/>
    </joint>
    <link name="Link3">
        <inertial>
            <origin xyz="0.49875907566721117 0 0.4524303261465719" rpy="0 0 0"/>
            <mass value="1" />
            <inertia ixx="100" ixy="0" ixz="0" iyy="100" iyz="0" izz="100" />
        </inertial>
        <visual>
            <origin xyz="0.49875907566721117 0 0.4524303261465719" rpy="0 0 0"/>
            <geometry>
                <box size="0.9975181513344223 0.04866104872906962 0.9048606522931438" />
            </geometry>
            <material name="Blue">
                <color rgba="0 0.0 1.0 1.0"/>
            </material>
        </visual>
        <collision>
            <origin xyz="0.49875907566721117 0 0.4524303261465719" rpy="0 0 0"/>
            <geometry>
                <box size="0.9975181513344223 0.04866104872906962 0.9048606522931438" />
            </geometry>
        </collision>
    </link>
    <joint name="Link3_Link4" type="revolute">
       <parent link="Link3"/>
       <child  link="Link4"/>
       <origin rpy="0 0 0" xyz="0.49875907566721117 -0.02433052436453481 0.9048606522931438" />
     <axis xyz="1 0 0"/>
       <limit effort="0.0" lower="-3.14159" upper="3.14159" velocity="0.0"/>
    </joint>
    <link name="Link4">
        <inertial>
            <origin xyz="0 -0.2458402492406262 -0.18897105449242335" rpy="0 0 0"/>
            <mass value="1" />
            <inertia ixx="100" ixy="0" ixz="0" iyy="100" iyz="0" izz="100" />
        </inertial>
        <visual>
            <origin xyz="0 -0.2458402492406262 -0.18897105449242335" rpy="0 0 0"/>
            <geometry>
                <box size="0.2873786643740871 0.4916804984812524 0.3779421089848467" />
            </geometry>
            <material name="Green">
                <color rgba="0 1.0 0.0 1.0"/>
            </material>
        </visual>
        <collision>
            <origin xyz="0 -0.2458402492406262 -0.18897105449242335" rpy="0 0 0"/>
            <geometry>
                <box size="0.2873786643740871 0.4916804984812524 0.3779421089848467" />
            </geometry>
        </collision>
    </link>
</robot>