<robot name = "robot">
    <link name="Link0">
        <inertial>
            <origin xyz="0 0 2.442774329707452" rpy="0 0 0"/>
            <mass value="1" />
            <inertia ixx="100" ixy="0" ixz="0" iyy="100" iyz="0" izz="100" />
        </inertial>
        <visual>
            <origin xyz="0 0 2.442774329707452" rpy="0 0 0"/>
            <geometry>
                <box size="0.4113367792971625 0.6494666998549611 0.8855486594149042" />
            </geometry>
            <material name="Green">
                <color rgba="0 1.0 0.0 1.0"/>
            </material>
        </visual>
        <collision>
            <origin xyz="0 0 2.442774329707452" rpy="0 0 0"/>
            <geometry>
                <box size="0.4113367792971625 0.6494666998549611 0.8855486594149042" />
            </geometry>
        </collision>
    </link>
    <joint name="Link0_Link1" type="revolute">
       <parent link="Link0"/>
       <child  link="Link1"/>
       <origin rpy="0 0 0" xyz="0 0.32473334992748054 2.885548659414904" />
     <axis xyz="1 0 0"/>
       <limit effort="0.0" lower="-3.14159" upper="3.14159" velocity="0.0"/>
    </joint>
    <link name="Link1">
        <inertial>
            <origin xyz="0 0.32473334992748054 -0.4427743297074521" rpy="0 0 0"/>
            <mass value="1" />
            <inertia ixx="100" ixy="0" ixz="0" iyy="100" iyz="0" izz="100" />
        </inertial>
        <visual>
            <origin xyz="0 0.32473334992748054 -0.4427743297074521" rpy="0 0 0"/>
            <geometry>
                <box size="0.4113367792971625 0.6494666998549611 0.8855486594149042" />
            </geometry>
            <material name="Green">
                <color rgba="0 1.0 0.0 1.0"/>
            </material>
        </visual>
        <collision>
            <origin xyz="0 0.32473334992748054 -0.4427743297074521" rpy="0 0 0"/>
            <geometry>
                <box size="0.4113367792971625 0.6494666998549611 0.8855486594149042" />
            </geometry>
        </collision>
    </link>
    <joint name="Link1_Link2" type="revolute">
       <parent link="Link1"/>
       <child  link="Link2"/>
       <origin rpy="0 0 0" xyz="-0.20566838964858125 0.32473334992748054 0.0" />
     <axis xyz="0 1 0"/>
       <limit effort="0.0" lower="-3.14159" upper="3.14159" velocity="0.0"/>
    </joint>
    <link name="Link2">
        <inertial>
            <origin xyz="-0.3107975870309891 0 0.3465193897225299" rpy="0 0 0"/>
            <mass value="1" />
            <inertia ixx="100" ixy="0" ixz="0" iyy="100" iyz="0" izz="100" />
        </inertial>
        <visual>
            <origin xyz="-0.3107975870309891 0 0.3465193897225299" rpy="0 0 0"/>
            <geometry>
                <box size="0.6215951740619782 0.6925588120655483 0.6930387794450598" />
            </geometry>
            <material name="Blue">
                <color rgba="0 0.0 1.0 1.0"/>
            </material>
        </visual>
        <collision>
            <origin xyz="-0.3107975870309891 0 0.3465193897225299" rpy="0 0 0"/>
            <geometry>
                <box size="0.6215951740619782 0.6925588120655483 0.6930387794450598" />
            </geometry>
        </collision>
    </link>
    <joint name="Link2_Link3" type="revolute">
       <parent link="Link2"/>
       <child  link="Link3"/>
       <origin rpy="0 0 0" xyz="-0.3107975870309891 -0.34627940603277413 0.6930387794450598" />
     <axis xyz="1 0 0"/>
       <limit effort="0.0" lower="-3.14159" upper="3.14159" velocity="0.0"/>
    </joint>
    <link name="Link3">
        <inertial>
            <origin xyz="0 -0.16526088727338495 0.49286077788603316" rpy="0 0 0"/>
            <mass value="1" />
            <inertia ixx="100" ixy="0" ixz="0" iyy="100" iyz="0" izz="100" />
        </inertial>
        <visual>
            <origin xyz="0 -0.16526088727338495 0.49286077788603316" rpy="0 0 0"/>
            <geometry>
                <box size="0.9915322719945332 0.3305217745467699 0.9857215557720663" />
            </geometry>
            <material name="Blue">
                <color rgba="0 0.0 1.0 1.0"/>
            </material>
        </visual>
        <collision>
            <origin xyz="0 -0.16526088727338495 0.49286077788603316" rpy="0 0 0"/>
            <geometry>
                <box size="0.9915322719945332 0.3305217745467699 0.9857215557720663" />
            </geometry>
        </collision>
    </link>
    <joint name="Link3_Link4" type="revolute">
       <parent link="Link3"/>
       <child  link="Link4"/>
       <origin rpy="0 0 0" xyz="0 0.0 0.9857215557720663" />
     <axis xyz="1 0 0"/>
       <limit effort="0.0" lower="-3.14159" upper="3.14159" velocity="0.0"/>
    </joint>
    <link name="Link4">
        <inertial>
            <origin xyz="0 0.09973209118207399 0.4099150837230513" rpy="0 0 0"/>
            <mass value="1" />
            <inertia ixx="100" ixy="0" ixz="0" iyy="100" iyz="0" izz="100" />
        </inertial>
        <visual>
            <origin xyz="0 0.09973209118207399 0.4099150837230513" rpy="0 0 0"/>
            <geometry>
                <box size="0.5375614216907331 0.19946418236414798 0.8198301674461026" />
            </geometry>
            <material name="Green">
                <color rgba="0 1.0 0.0 1.0"/>
            </material>
        </visual>
        <collision>
            <origin xyz="0 0.09973209118207399 0.4099150837230513" rpy="0 0 0"/>
            <geometry>
                <box size="0.5375614216907331 0.19946418236414798 0.8198301674461026" />
            </geometry>
        </collision>
    </link>
</robot>