<robot name = "robot">
    <link name="Link0">
        <inertial>
            <origin xyz="0 0 2.3751080357310688" rpy="0 0 0"/>
            <mass value="1" />
            <inertia ixx="100" ixy="0" ixz="0" iyy="100" iyz="0" izz="100" />
        </inertial>
        <visual>
            <origin xyz="0 0 2.3751080357310688" rpy="0 0 0"/>
            <geometry>
                <box size="0.3370779330027178 0.2936616848658943 0.7502160714621371" />
            </geometry>
            <material name="Green">
                <color rgba="0 1.0 0.0 1.0"/>
            </material>
        </visual>
        <collision>
            <origin xyz="0 0 2.3751080357310688" rpy="0 0 0"/>
            <geometry>
                <box size="0.3370779330027178 0.2936616848658943 0.7502160714621371" />
            </geometry>
        </collision>
    </link>
    <joint name="Link0_Link1" type="revolute">
       <parent link="Link0"/>
       <child  link="Link1"/>
       <origin rpy="0 0 0" xyz="0 0.14683084243294714 2.750216071462137" />
     <axis xyz="1 0 0"/>
       <limit effort="0.0" lower="-3.14159" upper="3.14159" velocity="0.0"/>
    </joint>
    <link name="Link1">
        <inertial>
            <origin xyz="0 0.14683084243294714 -0.37510803573106855" rpy="0 0 0"/>
            <mass value="1" />
            <inertia ixx="100" ixy="0" ixz="0" iyy="100" iyz="0" izz="100" />
        </inertial>
        <visual>
            <origin xyz="0 0.14683084243294714 -0.37510803573106855" rpy="0 0 0"/>
            <geometry>
                <box size="0.3370779330027178 0.2936616848658943 0.7502160714621371" />
            </geometry>
            <material name="Blue">
                <color rgba="0 0.0 1.0 1.0"/>
            </material>
        </visual>
        <collision>
            <origin xyz="0 0.14683084243294714 -0.37510803573106855" rpy="0 0 0"/>
            <geometry>
                <box size="0.3370779330027178 0.2936616848658943 0.7502160714621371" />
            </geometry>
        </collision>
    </link>
    <joint name="Link1_Link2" type="revolute">
       <parent link="Link1"/>
       <child  link="Link2"/>
       <origin rpy="0 0 0" xyz="0 0.0 0.0" />
     <axis xyz="1 0 0"/>
       <limit effort="0.0" lower="-3.14159" upper="3.14159" velocity="0.0"/>
    </joint>
    <link name="Link2">
        <inertial>
            <origin xyz="0 -0.021617742965487297 0.10367825212371168" rpy="0 0 0"/>
            <mass value="1" />
            <inertia ixx="100" ixy="0" ixz="0" iyy="100" iyz="0" izz="100" />
        </inertial>
        <visual>
            <origin xyz="0 -0.021617742965487297 0.10367825212371168" rpy="0 0 0"/>
            <geometry>
                <box size="0.18405977991311828 0.04323548593097459 0.20735650424742336" />
            </geometry>
            <material name="Green">
                <color rgba="0 1.0 0.0 1.0"/>
            </material>
        </visual>
        <collision>
            <origin xyz="0 -0.021617742965487297 0.10367825212371168" rpy="0 0 0"/>
            <geometry>
                <box size="0.18405977991311828 0.04323548593097459 0.20735650424742336" />
            </geometry>
        </collision>
    </link>
    <joint name="Link2_Link3" type="revolute">
       <parent link="Link2"/>
       <child  link="Link3"/>
       <origin rpy="0 0 0" xyz="0 -0.04323548593097459 0.20735650424742336" />
     <axis xyz="1 0 0"/>
       <limit effort="0.0" lower="-3.14159" upper="3.14159" velocity="0.0"/>
    </joint>
    <link name="Link3">
        <inertial>
            <origin xyz="0 -0.17929831656740308 0.07490473395573932" rpy="0 0 0"/>
            <mass value="1" />
            <inertia ixx="100" ixy="0" ixz="0" iyy="100" iyz="0" izz="100" />
        </inertial>
        <visual>
            <origin xyz="0 -0.17929831656740308 0.07490473395573932" rpy="0 0 0"/>
            <geometry>
                <box size="0.4904843723408314 0.35859663313480616 0.14980946791147864" />
            </geometry>
            <material name="Green">
                <color rgba="0 1.0 0.0 1.0"/>
            </material>
        </visual>
        <collision>
            <origin xyz="0 -0.17929831656740308 0.07490473395573932" rpy="0 0 0"/>
            <geometry>
                <box size="0.4904843723408314 0.35859663313480616 0.14980946791147864" />
            </geometry>
        </collision>
    </link>
    <joint name="Link3_Link4" type="revolute">
       <parent link="Link3"/>
       <child  link="Link4"/>
       <origin rpy="0 0 0" xyz="0 0.0 0.14980946791147864" />
     <axis xyz="1 0 0"/>
       <limit effort="0.0" lower="-3.14159" upper="3.14159" velocity="0.0"/>
    </joint>
    <link name="Link4">
        <inertial>
            <origin xyz="0 0.10435628483937276 0.44732952422192246" rpy="0 0 0"/>
            <mass value="1" />
            <inertia ixx="100" ixy="0" ixz="0" iyy="100" iyz="0" izz="100" />
        </inertial>
        <visual>
            <origin xyz="0 0.10435628483937276 0.44732952422192246" rpy="0 0 0"/>
            <geometry>
                <box size="0.9296477227482188 0.20871256967874552 0.8946590484438449" />
            </geometry>
            <material name="Blue">
                <color rgba="0 0.0 1.0 1.0"/>
            </material>
        </visual>
        <collision>
            <origin xyz="0 0.10435628483937276 0.44732952422192246" rpy="0 0 0"/>
            <geometry>
                <box size="0.9296477227482188 0.20871256967874552 0.8946590484438449" />
            </geometry>
        </collision>
    </link>
    <joint name="Link4_Link5" type="revolute">
       <parent link="Link4"/>
       <child  link="Link5"/>
       <origin rpy="0 0 0" xyz="0 0.20871256967874552 0.8946590484438449" />
     <axis xyz="1 0 0"/>
       <limit effort="0.0" lower="-3.14159" upper="3.14159" velocity="0.0"/>
    </joint>
    <link name="Link5">
        <inertial>
            <origin xyz="0 0.36970949882460735 -0.343206978695929" rpy="0 0 0"/>
            <mass value="1" />
            <inertia ixx="100" ixy="0" ixz="0" iyy="100" iyz="0" izz="100" />
        </inertial>
        <visual>
            <origin xyz="0 0.36970949882460735 -0.343206978695929" rpy="0 0 0"/>
            <geometry>
                <box size="0.21047844618996314 0.7394189976492147 0.686413957391858" />
            </geometry>
            <material name="Blue">
                <color rgba="0 0.0 1.0 1.0"/>
            </material>
        </visual>
        <collision>
            <origin xyz="0 0.36970949882460735 -0.343206978695929" rpy="0 0 0"/>
            <geometry>
                <box size="0.21047844618996314 0.7394189976492147 0.686413957391858" />
            </geometry>
        </collision>
    </link>
    <joint name="Link5_Link6" type="revolute">
       <parent link="Link5"/>
       <child  link="Link6"/>
       <origin rpy="0 0 0" xyz="-0.10523922309498157 0.36970949882460735 0.0" />
     <axis xyz="0 1 0"/>
       <limit effort="0.0" lower="-3.14159" upper="3.14159" velocity="0.0"/>
    </joint>
    <link name="Link6">
        <inertial>
            <origin xyz="-0.2579203574754838 0 0.2630152163045167" rpy="0 0 0"/>
            <mass value="1" />
            <inertia ixx="100" ixy="0" ixz="0" iyy="100" iyz="0" izz="100" />
        </inertial>
        <visual>
            <origin xyz="-0.2579203574754838 0 0.2630152163045167" rpy="0 0 0"/>
            <geometry>
                <box size="0.5158407149509676 0.34314639266392455 0.5260304326090334" />
            </geometry>
            <material name="Green">
                <color rgba="0 1.0 0.0 1.0"/>
            </material>
        </visual>
        <collision>
            <origin xyz="-0.2579203574754838 0 0.2630152163045167" rpy="0 0 0"/>
            <geometry>
                <box size="0.5158407149509676 0.34314639266392455 0.5260304326090334" />
            </geometry>
        </collision>
    </link>
</robot>