<robot name = "robot">
    <link name="Link0">
        <inertial>
            <origin xyz="0 0 2.0483081527586857" rpy="0 0 0"/>
            <mass value="1" />
            <inertia ixx="100" ixy="0" ixz="0" iyy="100" iyz="0" izz="100" />
        </inertial>
        <visual>
            <origin xyz="0 0 2.0483081527586857" rpy="0 0 0"/>
            <geometry>
                <box size="0.4276921570213872 0.45249288348299666 0.09661630551737144" />
            </geometry>
            <material name="Green">
                <color rgba="0 1.0 0.0 1.0"/>
            </material>
        </visual>
        <collision>
            <origin xyz="0 0 2.0483081527586857" rpy="0 0 0"/>
            <geometry>
                <box size="0.4276921570213872 0.45249288348299666 0.09661630551737144" />
            </geometry>
        </collision>
    </link>
    <joint name="Link0_Link1" type="revolute">
       <parent link="Link0"/>
       <child  link="Link1"/>
       <origin rpy="0 0 0" xyz="0 0.22624644174149833 2.0966163055173714" />
     <axis xyz="1 0 0"/>
       <limit effort="0.0" lower="-3.14159" upper="3.14159" velocity="0.0"/>
    </joint>
    <link name="Link1">
        <inertial>
            <origin xyz="0 0.22624644174149833 -0.04830815275868572" rpy="0 0 0"/>
            <mass value="1" />
            <inertia ixx="100" ixy="0" ixz="0" iyy="100" iyz="0" izz="100" />
        </inertial>
        <visual>
            <origin xyz="0 0.22624644174149833 -0.04830815275868572" rpy="0 0 0"/>
            <geometry>
                <box size="0.4276921570213872 0.45249288348299666 0.09661630551737144" />
            </geometry>
            <material name="Blue">
                <color rgba="0 0.0 1.0 1.0"/>
            </material>
        </visual>
        <collision>
            <origin xyz="0 0.22624644174149833 -0.04830815275868572" rpy="0 0 0"/>
            <geometry>
                <box size="0.4276921570213872 0.45249288348299666 0.09661630551737144" />
            </geometry>
        </collision>
    </link>
    <joint name="Link1_Link2" type="revolute">
       <parent link="Link1"/>
       <child  link="Link2"/>
       <origin rpy="0 0 0" xyz="0 0.0 0.0" />
     <axis xyz="1 0 0"/>
       <limit effort="0.0" lower="-3.14159" upper="3.14159" velocity="0.0"/>
    </joint>
    <link name="Link2">
        <inertial>
            <origin xyz="0 -0.15908843516183996 0.16040384280964048" rpy="0 0 0"/>
            <mass value="1" />
            <inertia ixx="100" ixy="0" ixz="0" iyy="100" iyz="0" izz="100" />
        </inertial>
        <visual>
            <origin xyz="0 -0.15908843516183996 0.16040384280964048" rpy="0 0 0"/>
            <geometry>
                <box size="0.2018295964386465 0.3181768703236799 0.32080768561928097" />
            </geometry>
            <material name="Green">
                <color rgba="0 1.0 0.0 1.0"/>
            </material>
        </visual>
        <collision>
            <origin xyz="0 -0.15908843516183996 0.16040384280964048" rpy="0 0 0"/>
            <geometry>
                <box size="0.2018295964386465 0.3181768703236799 0.32080768561928097" />
            </geometry>
        </collision>
    </link>
    <joint name="Link2_Link3" type="revolute">
       <parent link="Link2"/>
       <child  link="Link3"/>
       <origin rpy="0 0 0" xyz="-0.10091479821932325 -0.15908843516183996 0.32080768561928097" />
     <axis xyz="0 1 0"/>
       <limit effort="0.0" lower="-3.14159" upper="3.14159" velocity="0.0"/>
    </joint>
    <link name="Link3">
        <inertial>
            <origin xyz="-0.2124674915684922 0 0.05560560797693165" rpy="0 0 0"/>
            <mass value="1" />
            <inertia ixx="100" ixy="0" ixz="0" iyy="100" iyz="0" izz="100" />
        </inertial>
        <visual>
            <origin xyz="-0.2124674915684922 0 0.05560560797693165" rpy="0 0 0"/>
            <geometry>
                <box size="0.4249349831369844 0.35872433344490573 0.1112112159538633" />
            </geometry>
            <material name="Green">
                <color rgba="0 1.0 0.0 1.0"/>
            </material>
        </visual>
        <collision>
            <origin xyz="-0.2124674915684922 0 0.05560560797693165" rpy="0 0 0"/>
            <geometry>
                <box size="0.4249349831369844 0.35872433344490573 0.1112112159538633" />
            </geometry>
        </collision>
    </link>
    <joint name="Link3_Link4" type="revolute">
       <parent link="Link3"/>
       <child  link="Link4"/>
       <origin rpy="0 0 0" xyz="-0.2124674915684922 -0.17936216672245286 0.1112112159538633" />
     <axis xyz="1 0 0"/>
       <limit effort="0.0" lower="-3.14159" upper="3.14159" velocity="0.0"/>
    </joint>
    <link name="Link4">
        <inertial>
            <origin xyz="0 -0.1715613215273144 -0.013981486478434557" rpy="0 0 0"/>
            <mass value="1" />
            <inertia ixx="100" ixy="0" ixz="0" iyy="100" iyz="0" izz="100" />
        </inertial>
        <visual>
            <origin xyz="0 -0.1715613215273144 -0.013981486478434557" rpy="0 0 0"/>
            <geometry>
                <box size="0.3880397406621149 0.3431226430546288 0.027962972956869114" />
            </geometry>
            <material name="Green">
                <color rgba="0 1.0 0.0 1.0"/>
            </material>
        </visual>
        <collision>
            <origin xyz="0 -0.1715613215273144 -0.013981486478434557" rpy="0 0 0"/>
            <geometry>
                <box size="0.3880397406621149 0.3431226430546288 0.027962972956869114" />
            </geometry>
        </collision>
    </link>
    <joint name="Link4_Link5" type="revolute">
       <parent link="Link4"/>
       <child  link="Link5"/>
       <origin rpy="0 0 0" xyz="0.19401987033105744 -0.1715613215273144 0.0" />
     <axis xyz="0 1 0"/>
       <limit effort="0.0" lower="-3.14159" upper="3.14159" velocity="0.0"/>
    </joint>
    <link name="Link5">
        <inertial>
            <origin xyz="0.3295158790966674 0 -0.4052477909331273" rpy="0 0 0"/>
            <mass value="1" />
            <inertia ixx="100" ixy="0" ixz="0" iyy="100" iyz="0" izz="100" />
        </inertial>
        <visual>
            <origin xyz="0.3295158790966674 0 -0.4052477909331273" rpy="0 0 0"/>
            <geometry>
                <box size="0.6590317581933348 0.8308497464025207 0.8104955818662546" />
            </geometry>
            <material name="Green">
                <color rgba="0 1.0 0.0 1.0"/>
            </material>
        </visual>
        <collision>
            <origin xyz="0.3295158790966674 0 -0.4052477909331273" rpy="0 0 0"/>
            <geometry>
                <box size="0.6590317581933348 0.8308497464025207 0.8104955818662546" />
            </geometry>
        </collision>
    </link>
</robot>