<robot name = "robot">
    <link name="Link0">
        <inertial>
            <origin xyz="0 0 2.4413501083837823" rpy="0 0 0"/>
            <mass value="1" />
            <inertia ixx="100" ixy="0" ixz="0" iyy="100" iyz="0" izz="100" />
        </inertial>
        <visual>
            <origin xyz="0 0 2.4413501083837823" rpy="0 0 0"/>
            <geometry>
                <box size="0.751562426861909 0.9378113326732956 0.8827002167675648" />
            </geometry>
            <material name="Green">
                <color rgba="0 1.0 0.0 1.0"/>
            </material>
        </visual>
        <collision>
            <origin xyz="0 0 2.4413501083837823" rpy="0 0 0"/>
            <geometry>
                <box size="0.751562426861909 0.9378113326732956 0.8827002167675648" />
            </geometry>
        </collision>
    </link>
    <joint name="Link0_Link1" type="revolute">
       <parent link="Link0"/>
       <child  link="Link1"/>
       <origin rpy="0 0 0" xyz="0 0.4689056663366478 2.8827002167675646" />
     <axis xyz="1 0 0"/>
       <limit effort="0.0" lower="-3.14159" upper="3.14159" velocity="0.0"/>
    </joint>
    <link name="Link1">
        <inertial>
            <origin xyz="0 0.4689056663366478 -0.4413501083837824" rpy="0 0 0"/>
            <mass value="1" />
            <inertia ixx="100" ixy="0" ixz="0" iyy="100" iyz="0" izz="100" />
        </inertial>
        <visual>
            <origin xyz="0 0.4689056663366478 -0.4413501083837824" rpy="0 0 0"/>
            <geometry>
                <box size="0.751562426861909 0.9378113326732956 0.8827002167675648" />
            </geometry>
            <material name="Green">
                <color rgba="0 1.0 0.0 1.0"/>
            </material>
        </visual>
        <collision>
            <origin xyz="0 0.4689056663366478 -0.4413501083837824" rpy="0 0 0"/>
            <geometry>
                <box size="0.751562426861909 0.9378113326732956 0.8827002167675648" />
            </geometry>
        </collision>
    </link>
    <joint name="Link1_Link2" type="revolute">
       <parent link="Link1"/>
       <child  link="Link2"/>
       <origin rpy="0 0 0" xyz="-0.3757812134309545 0.4689056663366478 0.0" />
     <axis xyz="0 1 0"/>
       <limit effort="0.0" lower="-3.14159" upper="3.14159" velocity="0.0"/>
    </joint>
    <link name="Link2">
        <inertial>
            <origin xyz="-0.14094331566878854 0 -0.14625552229083233" rpy="0 0 0"/>
            <mass value="1" />
            <inertia ixx="100" ixy="0" ixz="0" iyy="100" iyz="0" izz="100" />
        </inertial>
        <visual>
            <origin xyz="-0.14094331566878854 0 -0.14625552229083233" rpy="0 0 0"/>
            <geometry>
                <box size="0.2818866313375771 0.5086471874729483 0.29251104458166466" />
            </geometry>
            <material name="Green">
                <color rgba="0 1.0 0.0 1.0"/>
            </material>
        </visual>
        <collision>
            <origin xyz="-0.14094331566878854 0 -0.14625552229083233" rpy="0 0 0"/>
            <geometry>
                <box size="0.2818866313375771 0.5086471874729483 0.29251104458166466" />
            </geometry>
        </collision>
    </link>
    <joint name="Link2_Link3" type="revolute">
       <parent link="Link2"/>
       <child  link="Link3"/>
       <origin rpy="0 0 0" xyz="-0.2818866313375771 0 0.0" />
     <axis xyz="0 1 0"/>
       <limit effort="0.0" lower="-3.14159" upper="3.14159" velocity="0.0"/>
    </joint>
    <link name="Link3">
        <inertial>
            <origin xyz="-0.04682503356238782 0 -0.09153414924509262" rpy="0 0 0"/>
            <mass value="1" />
            <inertia ixx="100" ixy="0" ixz="0" iyy="100" iyz="0" izz="100" />
        </inertial>
        <visual>
            <origin xyz="-0.04682503356238782 0 -0.09153414924509262" rpy="0 0 0"/>
            <geometry>
                <box size="0.09365006712477564 0.7370457844045989 0.18306829849018524" />
            </geometry>
            <material name="Green">
                <color rgba="0 1.0 0.0 1.0"/>
            </material>
        </visual>
        <collision>
            <origin xyz="-0.04682503356238782 0 -0.09153414924509262" rpy="0 0 0"/>
            <geometry>
                <box size="0.09365006712477564 0.7370457844045989 0.18306829849018524" />
            </geometry>
        </collision>
    </link>
    <joint name="Link3_Link4" type="revolute">
       <parent link="Link3"/>
       <child  link="Link4"/>
       <origin rpy="0 0 0" xyz="-0.04682503356238782 -0.36852289220229945 0.0" />
     <axis xyz="1 0 0"/>
       <limit effort="0.0" lower="-3.14159" upper="3.14159" velocity="0.0"/>
    </joint>
    <link name="Link4">
        <inertial>
            <origin xyz="0 -0.09429946820581592 -0.18682728511754026" rpy="0 0 0"/>
            <mass value="1" />
            <inertia ixx="100" ixy="0" ixz="0" iyy="100" iyz="0" izz="100" />
        </inertial>
        <visual>
            <origin xyz="0 -0.09429946820581592 -0.18682728511754026" rpy="0 0 0"/>
            <geometry>
                <box size="0.04333415304075239 0.18859893641163183 0.37365457023508053" />
            </geometry>
            <material name="Green">
                <color rgba="0 1.0 0.0 1.0"/>
            </material>
        </visual>
        <collision>
            <origin xyz="0 -0.09429946820581592 -0.18682728511754026" rpy="0 0 0"/>
            <geometry>
                <box size="0.04333415304075239 0.18859893641163183 0.37365457023508053" />
            </geometry>
        </collision>
    </link>
</robot>