<robot name = "robot">
    <link name="Link0">
        <inertial>
            <origin xyz="0 0 2.3808991548099243" rpy="0 0 0"/>
            <mass value="1" />
            <inertia ixx="100" ixy="0" ixz="0" iyy="100" iyz="0" izz="100" />
        </inertial>
        <visual>
            <origin xyz="0 0 2.3808991548099243" rpy="0 0 0"/>
            <geometry>
                <box size="0.7693632422812545 0.4228922040737091 0.7617983096198484" />
            </geometry>
            <material name="Green">
                <color rgba="0 1.0 0.0 1.0"/>
            </material>
        </visual>
        <collision>
            <origin xyz="0 0 2.3808991548099243" rpy="0 0 0"/>
            <geometry>
                <box size="0.7693632422812545 0.4228922040737091 0.7617983096198484" />
            </geometry>
        </collision>
    </link>
    <joint name="Link0_Link1" type="revolute">
       <parent link="Link0"/>
       <child  link="Link1"/>
       <origin rpy="0 0 0" xyz="0 0.21144610203685454 2.7617983096198486" />
     <axis xyz="1 0 0"/>
       <limit effort="0.0" lower="-3.14159" upper="3.14159" velocity="0.0"/>
    </joint>
    <link name="Link1">
        <inertial>
            <origin xyz="0 0.21144610203685454 -0.3808991548099242" rpy="0 0 0"/>
            <mass value="1" />
            <inertia ixx="100" ixy="0" ixz="0" iyy="100" iyz="0" izz="100" />
        </inertial>
        <visual>
            <origin xyz="0 0.21144610203685454 -0.3808991548099242" rpy="0 0 0"/>
            <geometry>
                <box size="0.7693632422812545 0.4228922040737091 0.7617983096198484" />
            </geometry>
            <material name="Green">
                <color rgba="0 1.0 0.0 1.0"/>
            </material>
        </visual>
        <collision>
            <origin xyz="0 0.21144610203685454 -0.3808991548099242" rpy="0 0 0"/>
            <geometry>
                <box size="0.7693632422812545 0.4228922040737091 0.7617983096198484" />
            </geometry>
        </collision>
    </link>
    <joint name="Link1_Link2" type="revolute">
       <parent link="Link1"/>
       <child  link="Link2"/>
       <origin rpy="0 0 0" xyz="0 0.0 0.0" />
     <axis xyz="1 0 0"/>
       <limit effort="0.0" lower="-3.14159" upper="3.14159" velocity="0.0"/>
    </joint>
    <link name="Link2">
        <inertial>
            <origin xyz="0 -0.26018128901232934 -0.25385584201978706" rpy="0 0 0"/>
            <mass value="1" />
            <inertia ixx="100" ixy="0" ixz="0" iyy="100" iyz="0" izz="100" />
        </inertial>
        <visual>
            <origin xyz="0 -0.26018128901232934 -0.25385584201978706" rpy="0 0 0"/>
            <geometry>
                <box size="0.6043154827895919 0.5203625780246587 0.5077116840395741" />
            </geometry>
            <material name="Blue">
                <color rgba="0 0.0 1.0 1.0"/>
            </material>
        </visual>
        <collision>
            <origin xyz="0 -0.26018128901232934 -0.25385584201978706" rpy="0 0 0"/>
            <geometry>
                <box size="0.6043154827895919 0.5203625780246587 0.5077116840395741" />
            </geometry>
        </collision>
    </link>
    <joint name="Link2_Link3" type="revolute">
       <parent link="Link2"/>
       <child  link="Link3"/>
       <origin rpy="0 0 0" xyz="0 0.0 0.0" />
     <axis xyz="1 0 0"/>
       <limit effort="0.0" lower="-3.14159" upper="3.14159" velocity="0.0"/>
    </joint>
    <link name="Link3">
        <inertial>
            <origin xyz="0 0.3549703060328717 0.3735265139816637" rpy="0 0 0"/>
            <mass value="1" />
            <inertia ixx="100" ixy="0" ixz="0" iyy="100" iyz="0" izz="100" />
        </inertial>
        <visual>
            <origin xyz="0 0.3549703060328717 0.3735265139816637" rpy="0 0 0"/>
            <geometry>
                <box size="0.4290585144618113 0.7099406120657434 0.7470530279633274" />
            </geometry>
            <material name="Green">
                <color rgba="0 1.0 0.0 1.0"/>
            </material>
        </visual>
        <collision>
            <origin xyz="0 0.3549703060328717 0.3735265139816637" rpy="0 0 0"/>
            <geometry>
                <box size="0.4290585144618113 0.7099406120657434 0.7470530279633274" />
            </geometry>
        </collision>
    </link>
    <joint name="Link3_Link4" type="revolute">
       <parent link="Link3"/>
       <child  link="Link4"/>
       <origin rpy="0 0 0" xyz="0 0.0 0.7470530279633274" />
     <axis xyz="1 0 0"/>
       <limit effort="0.0" lower="-3.14159" upper="3.14159" velocity="0.0"/>
    </joint>
    <link name="Link4">
        <inertial>
            <origin xyz="0 -0.15173335271319838 -0.4451259002228048" rpy="0 0 0"/>
            <mass value="1" />
            <inertia ixx="100" ixy="0" ixz="0" iyy="100" iyz="0" izz="100" />
        </inertial>
        <visual>
            <origin xyz="0 -0.15173335271319838 -0.4451259002228048" rpy="0 0 0"/>
            <geometry>
                <box size="0.24181345605709836 0.30346670542639675 0.8902518004456096" />
            </geometry>
            <material name="Green">
                <color rgba="0 1.0 0.0 1.0"/>
            </material>
        </visual>
        <collision>
            <origin xyz="0 -0.15173335271319838 -0.4451259002228048" rpy="0 0 0"/>
            <geometry>
                <box size="0.24181345605709836 0.30346670542639675 0.8902518004456096" />
            </geometry>
        </collision>
    </link>
</robot>