<robot name = "robot">
    <link name="Link0">
        <inertial>
            <origin xyz="0 0 2.098745580910547" rpy="0 0 0"/>
            <mass value="1" />
            <inertia ixx="100" ixy="0" ixz="0" iyy="100" iyz="0" izz="100" />
        </inertial>
        <visual>
            <origin xyz="0 0 2.098745580910547" rpy="0 0 0"/>
            <geometry>
                <box size="0.396780195933646 0.5472400370583392 0.19749116182109383" />
            </geometry>
            <material name="Green">
                <color rgba="0 1.0 0.0 1.0"/>
            </material>
        </visual>
        <collision>
            <origin xyz="0 0 2.098745580910547" rpy="0 0 0"/>
            <geometry>
                <box size="0.396780195933646 0.5472400370583392 0.19749116182109383" />
            </geometry>
        </collision>
    </link>
    <joint name="Link0_Link1" type="revolute">
       <parent link="Link0"/>
       <child  link="Link1"/>
       <origin rpy="0 0 0" xyz="0 0.2736200185291696 2.1974911618210937" />
     <axis xyz="1 0 0"/>
       <limit effort="0.0" lower="-3.14159" upper="3.14159" velocity="0.0"/>
    </joint>
    <link name="Link1">
        <inertial>
            <origin xyz="0 0.2736200185291696 -0.09874558091054692" rpy="0 0 0"/>
            <mass value="1" />
            <inertia ixx="100" ixy="0" ixz="0" iyy="100" iyz="0" izz="100" />
        </inertial>
        <visual>
            <origin xyz="0 0.2736200185291696 -0.09874558091054692" rpy="0 0 0"/>
            <geometry>
                <box size="0.396780195933646 0.5472400370583392 0.19749116182109383" />
            </geometry>
            <material name="Blue">
                <color rgba="0 0.0 1.0 1.0"/>
            </material>
        </visual>
        <collision>
            <origin xyz="0 0.2736200185291696 -0.09874558091054692" rpy="0 0 0"/>
            <geometry>
                <box size="0.396780195933646 0.5472400370583392 0.19749116182109383" />
            </geometry>
        </collision>
    </link>
    <joint name="Link1_Link2" type="revolute">
       <parent link="Link1"/>
       <child  link="Link2"/>
       <origin rpy="0 0 0" xyz="0 0.0 0.0" />
     <axis xyz="1 0 0"/>
       <limit effort="0.0" lower="-3.14159" upper="3.14159" velocity="0.0"/>
    </joint>
    <link name="Link2">
        <inertial>
            <origin xyz="0 -0.031821324792794536 -0.4514821374913193" rpy="0 0 0"/>
            <mass value="1" />
            <inertia ixx="100" ixy="0" ixz="0" iyy="100" iyz="0" izz="100" />
        </inertial>
        <visual>
            <origin xyz="0 -0.031821324792794536 -0.4514821374913193" rpy="0 0 0"/>
            <geometry>
                <box size="0.4816401989325684 0.06364264958558907 0.9029642749826386" />
            </geometry>
            <material name="Green">
                <color rgba="0 1.0 0.0 1.0"/>
            </material>
        </visual>
        <collision>
            <origin xyz="0 -0.031821324792794536 -0.4514821374913193" rpy="0 0 0"/>
            <geometry>
                <box size="0.4816401989325684 0.06364264958558907 0.9029642749826386" />
            </geometry>
        </collision>
    </link>
    <joint name="Link2_Link3" type="revolute">
       <parent link="Link2"/>
       <child  link="Link3"/>
       <origin rpy="0 0 0" xyz="0 0.0 0.0" />
     <axis xyz="1 0 0"/>
       <limit effort="0.0" lower="-3.14159" upper="3.14159" velocity="0.0"/>
    </joint>
    <link name="Link3">
        <inertial>
            <origin xyz="0 0.1424014975683165 0.19125735506362457" rpy="0 0 0"/>
            <mass value="1" />
            <inertia ixx="100" ixy="0" ixz="0" iyy="100" iyz="0" izz="100" />
        </inertial>
        <visual>
            <origin xyz="0 0.1424014975683165 0.19125735506362457" rpy="0 0 0"/>
            <geometry>
                <box size="0.18519293721463403 0.284802995136633 0.38251471012724914" />
            </geometry>
            <material name="Blue">
                <color rgba="0 0.0 1.0 1.0"/>
            </material>
        </visual>
        <collision>
            <origin xyz="0 0.1424014975683165 0.19125735506362457" rpy="0 0 0"/>
            <geometry>
                <box size="0.18519293721463403 0.284802995136633 0.38251471012724914" />
            </geometry>
        </collision>
    </link>
    <joint name="Link3_Link4" type="revolute">
       <parent link="Link3"/>
       <child  link="Link4"/>
       <origin rpy="0 0 0" xyz="-0.09259646860731702 0.1424014975683165 0.38251471012724914" />
     <axis xyz="0 1 0"/>
       <limit effort="0.0" lower="-3.14159" upper="3.14159" velocity="0.0"/>
    </joint>
    <link name="Link4">
        <inertial>
            <origin xyz="-0.49494293125213845 0 0.05181260792129977" rpy="0 0 0"/>
            <mass value="1" />
            <inertia ixx="100" ixy="0" ixz="0" iyy="100" iyz="0" izz="100" />
        </inertial>
        <visual>
            <origin xyz="-0.49494293125213845 0 0.05181260792129977" rpy="0 0 0"/>
            <geometry>
                <box size="0.9898858625042769 0.2234078299078669 0.10362521584259954" />
            </geometry>
            <material name="Blue">
                <color rgba="0 0.0 1.0 1.0"/>
            </material>
        </visual>
        <collision>
            <origin xyz="-0.49494293125213845 0 0.05181260792129977" rpy="0 0 0"/>
            <geometry>
                <box size="0.9898858625042769 0.2234078299078669 0.10362521584259954" />
            </geometry>
        </collision>
    </link>
    <joint name="Link4_Link5" type="revolute">
       <parent link="Link4"/>
       <child  link="Link5"/>
       <origin rpy="0 0 0" xyz="-0.49494293125213845 0.11170391495393345 0.10362521584259954" />
     <axis xyz="1 0 0"/>
       <limit effort="0.0" lower="-3.14159" upper="3.14159" velocity="0.0"/>
    </joint>
    <link name="Link5">
        <inertial>
            <origin xyz="0 0.17457960708937298 -0.4161586918658558" rpy="0 0 0"/>
            <mass value="1" />
            <inertia ixx="100" ixy="0" ixz="0" iyy="100" iyz="0" izz="100" />
        </inertial>
        <visual>
            <origin xyz="0 0.17457960708937298 -0.4161586918658558" rpy="0 0 0"/>
            <geometry>
                <box size="0.744097323532798 0.34915921417874596 0.8323173837317116" />
            </geometry>
            <material name="Blue">
                <color rgba="0 0.0 1.0 1.0"/>
            </material>
        </visual>
        <collision>
            <origin xyz="0 0.17457960708937298 -0.4161586918658558" rpy="0 0 0"/>
            <geometry>
                <box size="0.744097323532798 0.34915921417874596 0.8323173837317116" />
            </geometry>
        </collision>
    </link>
    <joint name="Link5_Link6" type="revolute">
       <parent link="Link5"/>
       <child  link="Link6"/>
       <origin rpy="0 0 0" xyz="0.372048661766399 0.17457960708937298 0.0" />
     <axis xyz="0 1 0"/>
       <limit effort="0.0" lower="-3.14159" upper="3.14159" velocity="0.0"/>
    </joint>
    <link name="Link6">
        <inertial>
            <origin xyz="0.019307778943586817 0 -0.08351878855294292" rpy="0 0 0"/>
            <mass value="1" />
            <inertia ixx="100" ixy="0" ixz="0" iyy="100" iyz="0" izz="100" />
        </inertial>
        <visual>
            <origin xyz="0.019307778943586817 0 -0.08351878855294292" rpy="0 0 0"/>
            <geometry>
                <box size="0.038615557887173635 0.5582022073376972 0.16703757710588585" />
            </geometry>
            <material name="Blue">
                <color rgba="0 0.0 1.0 1.0"/>
            </material>
        </visual>
        <collision>
            <origin xyz="0.019307778943586817 0 -0.08351878855294292" rpy="0 0 0"/>
            <geometry>
                <box size="0.038615557887173635 0.5582022073376972 0.16703757710588585" />
            </geometry>
        </collision>
    </link>
</robot>