<robot name = "robot">
    <link name="Link0">
        <inertial>
            <origin xyz="0 0 2.279637557886154" rpy="0 0 0"/>
            <mass value="1" />
            <inertia ixx="100" ixy="0" ixz="0" iyy="100" iyz="0" izz="100" />
        </inertial>
        <visual>
            <origin xyz="0 0 2.279637557886154" rpy="0 0 0"/>
            <geometry>
                <box size="0.3494752699079826 0.2727603842174281 0.5592751157723078" />
            </geometry>
            <material name="Green">
                <color rgba="0 1.0 0.0 1.0"/>
            </material>
        </visual>
        <collision>
            <origin xyz="0 0 2.279637557886154" rpy="0 0 0"/>
            <geometry>
                <box size="0.3494752699079826 0.2727603842174281 0.5592751157723078" />
            </geometry>
        </collision>
    </link>
    <joint name="Link0_Link1" type="revolute">
       <parent link="Link0"/>
       <child  link="Link1"/>
       <origin rpy="0 0 0" xyz="0 0.13638019210871405 2.5592751157723077" />
     <axis xyz="1 0 0"/>
       <limit effort="0.0" lower="-3.14159" upper="3.14159" velocity="0.0"/>
    </joint>
    <link name="Link1">
        <inertial>
            <origin xyz="0 0.13638019210871405 -0.2796375578861539" rpy="0 0 0"/>
            <mass value="1" />
            <inertia ixx="100" ixy="0" ixz="0" iyy="100" iyz="0" izz="100" />
        </inertial>
        <visual>
            <origin xyz="0 0.13638019210871405 -0.2796375578861539" rpy="0 0 0"/>
            <geometry>
                <box size="0.3494752699079826 0.2727603842174281 0.5592751157723078" />
            </geometry>
            <material name="Blue">
                <color rgba="0 0.0 1.0 1.0"/>
            </material>
        </visual>
        <collision>
            <origin xyz="0 0.13638019210871405 -0.2796375578861539" rpy="0 0 0"/>
            <geometry>
                <box size="0.3494752699079826 0.2727603842174281 0.5592751157723078" />
            </geometry>
        </collision>
    </link>
    <joint name="Link1_Link2" type="revolute">
       <parent link="Link1"/>
       <child  link="Link2"/>
       <origin rpy="0 0 0" xyz="-0.1747376349539913 0.13638019210871405 0.0" />
     <axis xyz="0 1 0"/>
       <limit effort="0.0" lower="-3.14159" upper="3.14159" velocity="0.0"/>
    </joint>
    <link name="Link2">
        <inertial>
            <origin xyz="-0.09666703125299853 0 0.06384834312468385" rpy="0 0 0"/>
            <mass value="1" />
            <inertia ixx="100" ixy="0" ixz="0" iyy="100" iyz="0" izz="100" />
        </inertial>
        <visual>
            <origin xyz="-0.09666703125299853 0 0.06384834312468385" rpy="0 0 0"/>
            <geometry>
                <box size="0.19333406250599705 0.9356630188462333 0.1276966862493677" />
            </geometry>
            <material name="Green">
                <color rgba="0 1.0 0.0 1.0"/>
            </material>
        </visual>
        <collision>
            <origin xyz="-0.09666703125299853 0 0.06384834312468385" rpy="0 0 0"/>
            <geometry>
                <box size="0.19333406250599705 0.9356630188462333 0.1276966862493677" />
            </geometry>
        </collision>
    </link>
    <joint name="Link2_Link3" type="revolute">
       <parent link="Link2"/>
       <child  link="Link3"/>
       <origin rpy="0 0 0" xyz="-0.09666703125299853 0.46783150942311663 0.1276966862493677" />
     <axis xyz="1 0 0"/>
       <limit effort="0.0" lower="-3.14159" upper="3.14159" velocity="0.0"/>
    </joint>
    <link name="Link3">
        <inertial>
            <origin xyz="0 0.4157785568265389 -0.26630727848199415" rpy="0 0 0"/>
            <mass value="1" />
            <inertia ixx="100" ixy="0" ixz="0" iyy="100" iyz="0" izz="100" />
        </inertial>
        <visual>
            <origin xyz="0 0.4157785568265389 -0.26630727848199415" rpy="0 0 0"/>
            <geometry>
                <box size="0.8805734130567996 0.8315571136530778 0.5326145569639883" />
            </geometry>
            <material name="Blue">
                <color rgba="0 0.0 1.0 1.0"/>
            </material>
        </visual>
        <collision>
            <origin xyz="0 0.4157785568265389 -0.26630727848199415" rpy="0 0 0"/>
            <geometry>
                <box size="0.8805734130567996 0.8315571136530778 0.5326145569639883" />
            </geometry>
        </collision>
    </link>
    <joint name="Link3_Link4" type="revolute">
       <parent link="Link3"/>
       <child  link="Link4"/>
       <origin rpy="0 0 0" xyz="0 0.8315571136530778 0.0" />
     <axis xyz="1 0 0"/>
       <limit effort="0.0" lower="-3.14159" upper="3.14159" velocity="0.0"/>
    </joint>
    <link name="Link4">
        <inertial>
            <origin xyz="0 0.1381137878119284 0.323712569266155" rpy="0 0 0"/>
            <mass value="1" />
            <inertia ixx="100" ixy="0" ixz="0" iyy="100" iyz="0" izz="100" />
        </inertial>
        <visual>
            <origin xyz="0 0.1381137878119284 0.323712569266155" rpy="0 0 0"/>
            <geometry>
                <box size="0.9444228868499739 0.2762275756238568 0.64742513853231" />
            </geometry>
            <material name="Green">
                <color rgba="0 1.0 0.0 1.0"/>
            </material>
        </visual>
        <collision>
            <origin xyz="0 0.1381137878119284 0.323712569266155" rpy="0 0 0"/>
            <geometry>
                <box size="0.9444228868499739 0.2762275756238568 0.64742513853231" />
            </geometry>
        </collision>
    </link>
    <joint name="Link4_Link5" type="revolute">
       <parent link="Link4"/>
       <child  link="Link5"/>
       <origin rpy="0 0 0" xyz="0 0.0 0.64742513853231" />
     <axis xyz="1 0 0"/>
       <limit effort="0.0" lower="-3.14159" upper="3.14159" velocity="0.0"/>
    </joint>
    <link name="Link5">
        <inertial>
            <origin xyz="0 -0.35295560548089683 -0.262192796965325" rpy="0 0 0"/>
            <mass value="1" />
            <inertia ixx="100" ixy="0" ixz="0" iyy="100" iyz="0" izz="100" />
        </inertial>
        <visual>
            <origin xyz="0 -0.35295560548089683 -0.262192796965325" rpy="0 0 0"/>
            <geometry>
                <box size="0.15875421412790203 0.7059112109617937 0.52438559393065" />
            </geometry>
            <material name="Blue">
                <color rgba="0 0.0 1.0 1.0"/>
            </material>
        </visual>
        <collision>
            <origin xyz="0 -0.35295560548089683 -0.262192796965325" rpy="0 0 0"/>
            <geometry>
                <box size="0.15875421412790203 0.7059112109617937 0.52438559393065" />
            </geometry>
        </collision>
    </link>
</robot>