<robot name = "robot">
    <link name="Link0">
        <inertial>
            <origin xyz="0 0 2.4337279745515903" rpy="0 0 0"/>
            <mass value="1" />
            <inertia ixx="100" ixy="0" ixz="0" iyy="100" iyz="0" izz="100" />
        </inertial>
        <visual>
            <origin xyz="0 0 2.4337279745515903" rpy="0 0 0"/>
            <geometry>
                <box size="0.1802435353823565 0.6144060696458655 0.8674559491031802" />
            </geometry>
            <material name="Green">
                <color rgba="0 1.0 0.0 1.0"/>
            </material>
        </visual>
        <collision>
            <origin xyz="0 0 2.4337279745515903" rpy="0 0 0"/>
            <geometry>
                <box size="0.1802435353823565 0.6144060696458655 0.8674559491031802" />
            </geometry>
        </collision>
    </link>
    <joint name="Link0_Link1" type="revolute">
       <parent link="Link0"/>
       <child  link="Link1"/>
       <origin rpy="0 0 0" xyz="0 0.30720303482293276 2.86745594910318" />
     <axis xyz="1 0 0"/>
       <limit effort="0.0" lower="-3.14159" upper="3.14159" velocity="0.0"/>
    </joint>
    <link name="Link1">
        <inertial>
            <origin xyz="0 0.30720303482293276 -0.4337279745515901" rpy="0 0 0"/>
            <mass value="1" />
            <inertia ixx="100" ixy="0" ixz="0" iyy="100" iyz="0" izz="100" />
        </inertial>
        <visual>
            <origin xyz="0 0.30720303482293276 -0.4337279745515901" rpy="0 0 0"/>
            <geometry>
                <box size="0.1802435353823565 0.6144060696458655 0.8674559491031802" />
            </geometry>
            <material name="Green">
                <color rgba="0 1.0 0.0 1.0"/>
            </material>
        </visual>
        <collision>
            <origin xyz="0 0.30720303482293276 -0.4337279745515901" rpy="0 0 0"/>
            <geometry>
                <box size="0.1802435353823565 0.6144060696458655 0.8674559491031802" />
            </geometry>
        </collision>
    </link>
    <joint name="Link1_Link2" type="revolute">
       <parent link="Link1"/>
       <child  link="Link2"/>
       <origin rpy="0 0 0" xyz="0.09012176769117825 0.30720303482293276 0.0" />
     <axis xyz="0 1 0"/>
       <limit effort="0.0" lower="-3.14159" upper="3.14159" velocity="0.0"/>
    </joint>
    <link name="Link2">
        <inertial>
            <origin xyz="0.15264658818325827 0 0.24656895149644936" rpy="0 0 0"/>
            <mass value="1" />
            <inertia ixx="100" ixy="0" ixz="0" iyy="100" iyz="0" izz="100" />
        </inertial>
        <visual>
            <origin xyz="0.15264658818325827 0 0.24656895149644936" rpy="0 0 0"/>
            <geometry>
                <box size="0.30529317636651654 0.518329435970473 0.4931379029928987" />
            </geometry>
            <material name="Green">
                <color rgba="0 1.0 0.0 1.0"/>
            </material>
        </visual>
        <collision>
            <origin xyz="0.15264658818325827 0 0.24656895149644936" rpy="0 0 0"/>
            <geometry>
                <box size="0.30529317636651654 0.518329435970473 0.4931379029928987" />
            </geometry>
        </collision>
    </link>
    <joint name="Link2_Link3" type="revolute">
       <parent link="Link2"/>
       <child  link="Link3"/>
       <origin rpy="0 0 0" xyz="0.15264658818325827 -0.2591647179852365 0.4931379029928987" />
     <axis xyz="1 0 0"/>
       <limit effort="0.0" lower="-3.14159" upper="3.14159" velocity="0.0"/>
    </joint>
    <link name="Link3">
        <inertial>
            <origin xyz="0 -0.37807177856631724 -0.11092639428898549" rpy="0 0 0"/>
            <mass value="1" />
            <inertia ixx="100" ixy="0" ixz="0" iyy="100" iyz="0" izz="100" />
        </inertial>
        <visual>
            <origin xyz="0 -0.37807177856631724 -0.11092639428898549" rpy="0 0 0"/>
            <geometry>
                <box size="0.061625839026417495 0.7561435571326345 0.22185278857797097" />
            </geometry>
            <material name="Green">
                <color rgba="0 1.0 0.0 1.0"/>
            </material>
        </visual>
        <collision>
            <origin xyz="0 -0.37807177856631724 -0.11092639428898549" rpy="0 0 0"/>
            <geometry>
                <box size="0.061625839026417495 0.7561435571326345 0.22185278857797097" />
            </geometry>
        </collision>
    </link>
    <joint name="Link3_Link4" type="revolute">
       <parent link="Link3"/>
       <child  link="Link4"/>
       <origin rpy="0 0 0" xyz="0 0.0 0.0" />
     <axis xyz="1 0 0"/>
       <limit effort="0.0" lower="-3.14159" upper="3.14159" velocity="0.0"/>
    </joint>
    <link name="Link4">
        <inertial>
            <origin xyz="0 0.4310658674167269 -0.12025875709752831" rpy="0 0 0"/>
            <mass value="1" />
            <inertia ixx="100" ixy="0" ixz="0" iyy="100" iyz="0" izz="100" />
        </inertial>
        <visual>
            <origin xyz="0 0.4310658674167269 -0.12025875709752831" rpy="0 0 0"/>
            <geometry>
                <box size="0.03941566065411295 0.8621317348334538 0.24051751419505663" />
            </geometry>
            <material name="Blue">
                <color rgba="0 0.0 1.0 1.0"/>
            </material>
        </visual>
        <collision>
            <origin xyz="0 0.4310658674167269 -0.12025875709752831" rpy="0 0 0"/>
            <geometry>
                <box size="0.03941566065411295 0.8621317348334538 0.24051751419505663" />
            </geometry>
        </collision>
    </link>
</robot>