<robot name = "robot">
    <link name="Link0">
        <inertial>
            <origin xyz="0 0 2.173829964990868" rpy="0 0 0"/>
            <mass value="1" />
            <inertia ixx="100" ixy="0" ixz="0" iyy="100" iyz="0" izz="100" />
        </inertial>
        <visual>
            <origin xyz="0 0 2.173829964990868" rpy="0 0 0"/>
            <geometry>
                <box size="0.6057958846582372 0.8331835216040119 0.34765992998173656" />
            </geometry>
            <material name="Green">
                <color rgba="0 1.0 0.0 1.0"/>
            </material>
        </visual>
        <collision>
            <origin xyz="0 0 2.173829964990868" rpy="0 0 0"/>
            <geometry>
                <box size="0.6057958846582372 0.8331835216040119 0.34765992998173656" />
            </geometry>
        </collision>
    </link>
    <joint name="Link0_Link1" type="revolute">
       <parent link="Link0"/>
       <child  link="Link1"/>
       <origin rpy="0 0 0" xyz="0 0.41659176080200594 2.3476599299817367" />
     <axis xyz="1 0 0"/>
       <limit effort="0.0" lower="-3.14159" upper="3.14159" velocity="0.0"/>
    </joint>
    <link name="Link1">
        <inertial>
            <origin xyz="0 0.41659176080200594 -0.17382996499086828" rpy="0 0 0"/>
            <mass value="1" />
            <inertia ixx="100" ixy="0" ixz="0" iyy="100" iyz="0" izz="100" />
        </inertial>
        <visual>
            <origin xyz="0 0.41659176080200594 -0.17382996499086828" rpy="0 0 0"/>
            <geometry>
                <box size="0.6057958846582372 0.8331835216040119 0.34765992998173656" />
            </geometry>
            <material name="Green">
                <color rgba="0 1.0 0.0 1.0"/>
            </material>
        </visual>
        <collision>
            <origin xyz="0 0.41659176080200594 -0.17382996499086828" rpy="0 0 0"/>
            <geometry>
                <box size="0.6057958846582372 0.8331835216040119 0.34765992998173656" />
            </geometry>
        </collision>
    </link>
    <joint name="Link1_Link2" type="revolute">
       <parent link="Link1"/>
       <child  link="Link2"/>
       <origin rpy="0 0 0" xyz="-0.3028979423291186 0.41659176080200594 0.0" />
     <axis xyz="0 1 0"/>
       <limit effort="0.0" lower="-3.14159" upper="3.14159" velocity="0.0"/>
    </joint>
    <link name="Link2">
        <inertial>
            <origin xyz="-0.3502708002763288 0 0.1548174367318914" rpy="0 0 0"/>
            <mass value="1" />
            <inertia ixx="100" ixy="0" ixz="0" iyy="100" iyz="0" izz="100" />
        </inertial>
        <visual>
            <origin xyz="-0.3502708002763288 0 0.1548174367318914" rpy="0 0 0"/>
            <geometry>
                <box size="0.7005416005526576 0.691618407760551 0.3096348734637828" />
            </geometry>
            <material name="Green">
                <color rgba="0 1.0 0.0 1.0"/>
            </material>
        </visual>
        <collision>
            <origin xyz="-0.3502708002763288 0 0.1548174367318914" rpy="0 0 0"/>
            <geometry>
                <box size="0.7005416005526576 0.691618407760551 0.3096348734637828" />
            </geometry>
        </collision>
    </link>
    <joint name="Link2_Link3" type="revolute">
       <parent link="Link2"/>
       <child  link="Link3"/>
       <origin rpy="0 0 0" xyz="0.0 0 0.3096348734637828" />
     <axis xyz="0 1 0"/>
       <limit effort="0.0" lower="-3.14159" upper="3.14159" velocity="0.0"/>
    </joint>
    <link name="Link3">
        <inertial>
            <origin xyz="0.11844031101943797 0 0.4056228836333822" rpy="0 0 0"/>
            <mass value="1" />
            <inertia ixx="100" ixy="0" ixz="0" iyy="100" iyz="0" izz="100" />
        </inertial>
        <visual>
            <origin xyz="0.11844031101943797 0 0.4056228836333822" rpy="0 0 0"/>
            <geometry>
                <box size="0.23688062203887594 0.1003900126754923 0.8112457672667645" />
            </geometry>
            <material name="Blue">
                <color rgba="0 0.0 1.0 1.0"/>
            </material>
        </visual>
        <collision>
            <origin xyz="0.11844031101943797 0 0.4056228836333822" rpy="0 0 0"/>
            <geometry>
                <box size="0.23688062203887594 0.1003900126754923 0.8112457672667645" />
            </geometry>
        </collision>
    </link>
    <joint name="Link3_Link4" type="revolute">
       <parent link="Link3"/>
       <child  link="Link4"/>
       <origin rpy="0 0 0" xyz="0.0 0 0.8112457672667645" />
     <axis xyz="0 1 0"/>
       <limit effort="0.0" lower="-3.14159" upper="3.14159" velocity="0.0"/>
    </joint>
    <link name="Link4">
        <inertial>
            <origin xyz="-0.24378409199031537 0 0.10539382895930638" rpy="0 0 0"/>
            <mass value="1" />
            <inertia ixx="100" ixy="0" ixz="0" iyy="100" iyz="0" izz="100" />
        </inertial>
        <visual>
            <origin xyz="-0.24378409199031537 0 0.10539382895930638" rpy="0 0 0"/>
            <geometry>
                <box size="0.48756818398063073 0.36841584313738196 0.21078765791861276" />
            </geometry>
            <material name="Green">
                <color rgba="0 1.0 0.0 1.0"/>
            </material>
        </visual>
        <collision>
            <origin xyz="-0.24378409199031537 0 0.10539382895930638" rpy="0 0 0"/>
            <geometry>
                <box size="0.48756818398063073 0.36841584313738196 0.21078765791861276" />
            </geometry>
        </collision>
    </link>
    <joint name="Link4_Link5" type="revolute">
       <parent link="Link4"/>
       <child  link="Link5"/>
       <origin rpy="0 0 0" xyz="-0.24378409199031537 -0.18420792156869098 0.21078765791861276" />
     <axis xyz="1 0 0"/>
       <limit effort="0.0" lower="-3.14159" upper="3.14159" velocity="0.0"/>
    </joint>
    <link name="Link5">
        <inertial>
            <origin xyz="0 -0.4596641707858593 0.281101089919234" rpy="0 0 0"/>
            <mass value="1" />
            <inertia ixx="100" ixy="0" ixz="0" iyy="100" iyz="0" izz="100" />
        </inertial>
        <visual>
            <origin xyz="0 -0.4596641707858593 0.281101089919234" rpy="0 0 0"/>
            <geometry>
                <box size="0.5147000668841063 0.9193283415717186 0.562202179838468" />
            </geometry>
            <material name="Green">
                <color rgba="0 1.0 0.0 1.0"/>
            </material>
        </visual>
        <collision>
            <origin xyz="0 -0.4596641707858593 0.281101089919234" rpy="0 0 0"/>
            <geometry>
                <box size="0.5147000668841063 0.9193283415717186 0.562202179838468" />
            </geometry>
        </collision>
    </link>
</robot>