<robot name = "robot">
    <link name="Link0">
        <inertial>
            <origin xyz="0 0 2.368318107425932" rpy="0 0 0"/>
            <mass value="1" />
            <inertia ixx="100" ixy="0" ixz="0" iyy="100" iyz="0" izz="100" />
        </inertial>
        <visual>
            <origin xyz="0 0 2.368318107425932" rpy="0 0 0"/>
            <geometry>
                <box size="0.06710147029449398 0.670842752105954 0.7366362148518645" />
            </geometry>
            <material name="Green">
                <color rgba="0 1.0 0.0 1.0"/>
            </material>
        </visual>
        <collision>
            <origin xyz="0 0 2.368318107425932" rpy="0 0 0"/>
            <geometry>
                <box size="0.06710147029449398 0.670842752105954 0.7366362148518645" />
            </geometry>
        </collision>
    </link>
    <joint name="Link0_Link1" type="revolute">
       <parent link="Link0"/>
       <child  link="Link1"/>
       <origin rpy="0 0 0" xyz="0 0.335421376052977 2.7366362148518646" />
     <axis xyz="1 0 0"/>
       <limit effort="0.0" lower="-3.14159" upper="3.14159" velocity="0.0"/>
    </joint>
    <link name="Link1">
        <inertial>
            <origin xyz="0 0.335421376052977 -0.36831810742593224" rpy="0 0 0"/>
            <mass value="1" />
            <inertia ixx="100" ixy="0" ixz="0" iyy="100" iyz="0" izz="100" />
        </inertial>
        <visual>
            <origin xyz="0 0.335421376052977 -0.36831810742593224" rpy="0 0 0"/>
            <geometry>
                <box size="0.06710147029449398 0.670842752105954 0.7366362148518645" />
            </geometry>
            <material name="Green">
                <color rgba="0 1.0 0.0 1.0"/>
            </material>
        </visual>
        <collision>
            <origin xyz="0 0.335421376052977 -0.36831810742593224" rpy="0 0 0"/>
            <geometry>
                <box size="0.06710147029449398 0.670842752105954 0.7366362148518645" />
            </geometry>
        </collision>
    </link>
    <joint name="Link1_Link2" type="revolute">
       <parent link="Link1"/>
       <child  link="Link2"/>
       <origin rpy="0 0 0" xyz="0.03355073514724699 0.335421376052977 0.0" />
     <axis xyz="0 1 0"/>
       <limit effort="0.0" lower="-3.14159" upper="3.14159" velocity="0.0"/>
    </joint>
    <link name="Link2">
        <inertial>
            <origin xyz="0.3642675028725983 0 -0.47173857754071097" rpy="0 0 0"/>
            <mass value="1" />
            <inertia ixx="100" ixy="0" ixz="0" iyy="100" iyz="0" izz="100" />
        </inertial>
        <visual>
            <origin xyz="0.3642675028725983 0 -0.47173857754071097" rpy="0 0 0"/>
            <geometry>
                <box size="0.7285350057451966 0.3932587235964846 0.9434771550814219" />
            </geometry>
            <material name="Blue">
                <color rgba="0 0.0 1.0 1.0"/>
            </material>
        </visual>
        <collision>
            <origin xyz="0.3642675028725983 0 -0.47173857754071097" rpy="0 0 0"/>
            <geometry>
                <box size="0.7285350057451966 0.3932587235964846 0.9434771550814219" />
            </geometry>
        </collision>
    </link>
    <joint name="Link2_Link3" type="revolute">
       <parent link="Link2"/>
       <child  link="Link3"/>
       <origin rpy="0 0 0" xyz="0.3642675028725983 0.1966293617982423 0.0" />
     <axis xyz="1 0 0"/>
       <limit effort="0.0" lower="-3.14159" upper="3.14159" velocity="0.0"/>
    </joint>
    <link name="Link3">
        <inertial>
            <origin xyz="0 0.3534833982106916 -0.48922909109869867" rpy="0 0 0"/>
            <mass value="1" />
            <inertia ixx="100" ixy="0" ixz="0" iyy="100" iyz="0" izz="100" />
        </inertial>
        <visual>
            <origin xyz="0 0.3534833982106916 -0.48922909109869867" rpy="0 0 0"/>
            <geometry>
                <box size="0.08535610740720678 0.7069667964213832 0.9784581821973973" />
            </geometry>
            <material name="Green">
                <color rgba="0 1.0 0.0 1.0"/>
            </material>
        </visual>
        <collision>
            <origin xyz="0 0.3534833982106916 -0.48922909109869867" rpy="0 0 0"/>
            <geometry>
                <box size="0.08535610740720678 0.7069667964213832 0.9784581821973973" />
            </geometry>
        </collision>
    </link>
    <joint name="Link3_Link4" type="revolute">
       <parent link="Link3"/>
       <child  link="Link4"/>
       <origin rpy="0 0 0" xyz="0 0.0 0.0" />
     <axis xyz="1 0 0"/>
       <limit effort="0.0" lower="-3.14159" upper="3.14159" velocity="0.0"/>
    </joint>
    <link name="Link4">
        <inertial>
            <origin xyz="0 -0.01198566486525926 0.08663123724976207" rpy="0 0 0"/>
            <mass value="1" />
            <inertia ixx="100" ixy="0" ixz="0" iyy="100" iyz="0" izz="100" />
        </inertial>
        <visual>
            <origin xyz="0 -0.01198566486525926 0.08663123724976207" rpy="0 0 0"/>
            <geometry>
                <box size="0.032218815660205014 0.02397132973051852 0.17326247449952414" />
            </geometry>
            <material name="Green">
                <color rgba="0 1.0 0.0 1.0"/>
            </material>
        </visual>
        <collision>
            <origin xyz="0 -0.01198566486525926 0.08663123724976207" rpy="0 0 0"/>
            <geometry>
                <box size="0.032218815660205014 0.02397132973051852 0.17326247449952414" />
            </geometry>
        </collision>
    </link>
    <joint name="Link4_Link5" type="revolute">
       <parent link="Link4"/>
       <child  link="Link5"/>
       <origin rpy="0 0 0" xyz="0 0.0 0.17326247449952414" />
     <axis xyz="1 0 0"/>
       <limit effort="0.0" lower="-3.14159" upper="3.14159" velocity="0.0"/>
    </joint>
    <link name="Link5">
        <inertial>
            <origin xyz="0 0.2723421397848177 -0.3212049988422647" rpy="0 0 0"/>
            <mass value="1" />
            <inertia ixx="100" ixy="0" ixz="0" iyy="100" iyz="0" izz="100" />
        </inertial>
        <visual>
            <origin xyz="0 0.2723421397848177 -0.3212049988422647" rpy="0 0 0"/>
            <geometry>
                <box size="0.3896914775086687 0.5446842795696354 0.6424099976845294" />
            </geometry>
            <material name="Blue">
                <color rgba="0 0.0 1.0 1.0"/>
            </material>
        </visual>
        <collision>
            <origin xyz="0 0.2723421397848177 -0.3212049988422647" rpy="0 0 0"/>
            <geometry>
                <box size="0.3896914775086687 0.5446842795696354 0.6424099976845294" />
            </geometry>
        </collision>
    </link>
</robot>