<robot name = "robot">
    <link name="Link0">
        <inertial>
            <origin xyz="0 0 2.239992975062416" rpy="0 0 0"/>
            <mass value="1" />
            <inertia ixx="100" ixy="0" ixz="0" iyy="100" iyz="0" izz="100" />
        </inertial>
        <visual>
            <origin xyz="0 0 2.239992975062416" rpy="0 0 0"/>
            <geometry>
                <box size="0.5383521181056784 0.4521619006221842 0.4799859501248319" />
            </geometry>
            <material name="Green">
                <color rgba="0 1.0 0.0 1.0"/>
            </material>
        </visual>
        <collision>
            <origin xyz="0 0 2.239992975062416" rpy="0 0 0"/>
            <geometry>
                <box size="0.5383521181056784 0.4521619006221842 0.4799859501248319" />
            </geometry>
        </collision>
    </link>
    <joint name="Link0_Link1" type="revolute">
       <parent link="Link0"/>
       <child  link="Link1"/>
       <origin rpy="0 0 0" xyz="0 0.2260809503110921 2.479985950124832" />
     <axis xyz="1 0 0"/>
       <limit effort="0.0" lower="-3.14159" upper="3.14159" velocity="0.0"/>
    </joint>
    <link name="Link1">
        <inertial>
            <origin xyz="0 0.2260809503110921 -0.23999297506241596" rpy="0 0 0"/>
            <mass value="1" />
            <inertia ixx="100" ixy="0" ixz="0" iyy="100" iyz="0" izz="100" />
        </inertial>
        <visual>
            <origin xyz="0 0.2260809503110921 -0.23999297506241596" rpy="0 0 0"/>
            <geometry>
                <box size="0.5383521181056784 0.4521619006221842 0.4799859501248319" />
            </geometry>
            <material name="Blue">
                <color rgba="0 0.0 1.0 1.0"/>
            </material>
        </visual>
        <collision>
            <origin xyz="0 0.2260809503110921 -0.23999297506241596" rpy="0 0 0"/>
            <geometry>
                <box size="0.5383521181056784 0.4521619006221842 0.4799859501248319" />
            </geometry>
        </collision>
    </link>
    <joint name="Link1_Link2" type="revolute">
       <parent link="Link1"/>
       <child  link="Link2"/>
       <origin rpy="0 0 0" xyz="0.2691760590528392 0.2260809503110921 0.0" />
     <axis xyz="0 1 0"/>
       <limit effort="0.0" lower="-3.14159" upper="3.14159" velocity="0.0"/>
    </joint>
    <link name="Link2">
        <inertial>
            <origin xyz="0.02430503128799283 0 -0.04438248728479455" rpy="0 0 0"/>
            <mass value="1" />
            <inertia ixx="100" ixy="0" ixz="0" iyy="100" iyz="0" izz="100" />
        </inertial>
        <visual>
            <origin xyz="0.02430503128799283 0 -0.04438248728479455" rpy="0 0 0"/>
            <geometry>
                <box size="0.04861006257598566 0.6644111669042553 0.0887649745695891" />
            </geometry>
            <material name="Blue">
                <color rgba="0 0.0 1.0 1.0"/>
            </material>
        </visual>
        <collision>
            <origin xyz="0.02430503128799283 0 -0.04438248728479455" rpy="0 0 0"/>
            <geometry>
                <box size="0.04861006257598566 0.6644111669042553 0.0887649745695891" />
            </geometry>
        </collision>
    </link>
    <joint name="Link2_Link3" type="revolute">
       <parent link="Link2"/>
       <child  link="Link3"/>
       <origin rpy="0 0 0" xyz="0.02430503128799283 -0.33220558345212764 0.0" />
     <axis xyz="1 0 0"/>
       <limit effort="0.0" lower="-3.14159" upper="3.14159" velocity="0.0"/>
    </joint>
    <link name="Link3">
        <inertial>
            <origin xyz="0 -0.4618494974190374 0.41390983573435153" rpy="0 0 0"/>
            <mass value="1" />
            <inertia ixx="100" ixy="0" ixz="0" iyy="100" iyz="0" izz="100" />
        </inertial>
        <visual>
            <origin xyz="0 -0.4618494974190374 0.41390983573435153" rpy="0 0 0"/>
            <geometry>
                <box size="0.19205140515122465 0.9236989948380748 0.8278196714687031" />
            </geometry>
            <material name="Blue">
                <color rgba="0 0.0 1.0 1.0"/>
            </material>
        </visual>
        <collision>
            <origin xyz="0 -0.4618494974190374 0.41390983573435153" rpy="0 0 0"/>
            <geometry>
                <box size="0.19205140515122465 0.9236989948380748 0.8278196714687031" />
            </geometry>
        </collision>
    </link>
    <joint name="Link3_Link4" type="revolute">
       <parent link="Link3"/>
       <child  link="Link4"/>
       <origin rpy="0 0 0" xyz="0.09602570257561233 -0.4618494974190374 0.8278196714687031" />
     <axis xyz="0 1 0"/>
       <limit effort="0.0" lower="-3.14159" upper="3.14159" velocity="0.0"/>
    </joint>
    <link name="Link4">
        <inertial>
            <origin xyz="0.3551731923794283 0 -0.32074715076322824" rpy="0 0 0"/>
            <mass value="1" />
            <inertia ixx="100" ixy="0" ixz="0" iyy="100" iyz="0" izz="100" />
        </inertial>
        <visual>
            <origin xyz="0.3551731923794283 0 -0.32074715076322824" rpy="0 0 0"/>
            <geometry>
                <box size="0.7103463847588566 0.5750515122015719 0.6414943015264565" />
            </geometry>
            <material name="Green">
                <color rgba="0 1.0 0.0 1.0"/>
            </material>
        </visual>
        <collision>
            <origin xyz="0.3551731923794283 0 -0.32074715076322824" rpy="0 0 0"/>
            <geometry>
                <box size="0.7103463847588566 0.5750515122015719 0.6414943015264565" />
            </geometry>
        </collision>
    </link>
    <joint name="Link4_Link5" type="revolute">
       <parent link="Link4"/>
       <child  link="Link5"/>
       <origin rpy="0 0 0" xyz="0.3551731923794283 0.28752575610078596 0.0" />
     <axis xyz="1 0 0"/>
       <limit effort="0.0" lower="-3.14159" upper="3.14159" velocity="0.0"/>
    </joint>
    <link name="Link5">
        <inertial>
            <origin xyz="0 0.44156984777379327 -0.17044193500819688" rpy="0 0 0"/>
            <mass value="1" />
            <inertia ixx="100" ixy="0" ixz="0" iyy="100" iyz="0" izz="100" />
        </inertial>
        <visual>
            <origin xyz="0 0.44156984777379327 -0.17044193500819688" rpy="0 0 0"/>
            <geometry>
                <box size="0.35235778417299135 0.8831396955475865 0.34088387001639375" />
            </geometry>
            <material name="Blue">
                <color rgba="0 0.0 1.0 1.0"/>
            </material>
        </visual>
        <collision>
            <origin xyz="0 0.44156984777379327 -0.17044193500819688" rpy="0 0 0"/>
            <geometry>
                <box size="0.35235778417299135 0.8831396955475865 0.34088387001639375" />
            </geometry>
        </collision>
    </link>
</robot>