<robot name = "robot">
    <link name="Link0">
        <inertial>
            <origin xyz="0 0 2.186044847321569" rpy="0 0 0"/>
            <mass value="1" />
            <inertia ixx="100" ixy="0" ixz="0" iyy="100" iyz="0" izz="100" />
        </inertial>
        <visual>
            <origin xyz="0 0 2.186044847321569" rpy="0 0 0"/>
            <geometry>
                <box size="0.14438730326162263 0.2733084309315873 0.37208969464313735" />
            </geometry>
            <material name="Green">
                <color rgba="0 1.0 0.0 1.0"/>
            </material>
        </visual>
        <collision>
            <origin xyz="0 0 2.186044847321569" rpy="0 0 0"/>
            <geometry>
                <box size="0.14438730326162263 0.2733084309315873 0.37208969464313735" />
            </geometry>
        </collision>
    </link>
    <joint name="Link0_Link1" type="revolute">
       <parent link="Link0"/>
       <child  link="Link1"/>
       <origin rpy="0 0 0" xyz="0 0.13665421546579365 2.3720896946431376" />
     <axis xyz="1 0 0"/>
       <limit effort="0.0" lower="-3.14159" upper="3.14159" velocity="0.0"/>
    </joint>
    <link name="Link1">
        <inertial>
            <origin xyz="0 0.13665421546579365 -0.18604484732156867" rpy="0 0 0"/>
            <mass value="1" />
            <inertia ixx="100" ixy="0" ixz="0" iyy="100" iyz="0" izz="100" />
        </inertial>
        <visual>
            <origin xyz="0 0.13665421546579365 -0.18604484732156867" rpy="0 0 0"/>
            <geometry>
                <box size="0.14438730326162263 0.2733084309315873 0.37208969464313735" />
            </geometry>
            <material name="Blue">
                <color rgba="0 0.0 1.0 1.0"/>
            </material>
        </visual>
        <collision>
            <origin xyz="0 0.13665421546579365 -0.18604484732156867" rpy="0 0 0"/>
            <geometry>
                <box size="0.14438730326162263 0.2733084309315873 0.37208969464313735" />
            </geometry>
        </collision>
    </link>
    <joint name="Link1_Link2" type="revolute">
       <parent link="Link1"/>
       <child  link="Link2"/>
       <origin rpy="0 0 0" xyz="0.07219365163081132 0.13665421546579365 0.0" />
     <axis xyz="0 1 0"/>
       <limit effort="0.0" lower="-3.14159" upper="3.14159" velocity="0.0"/>
    </joint>
    <link name="Link2">
        <inertial>
            <origin xyz="0.42227721807846097 0 -0.2878109292090395" rpy="0 0 0"/>
            <mass value="1" />
            <inertia ixx="100" ixy="0" ixz="0" iyy="100" iyz="0" izz="100" />
        </inertial>
        <visual>
            <origin xyz="0.42227721807846097 0 -0.2878109292090395" rpy="0 0 0"/>
            <geometry>
                <box size="0.8445544361569219 0.5452514732390275 0.575621858418079" />
            </geometry>
            <material name="Blue">
                <color rgba="0 0.0 1.0 1.0"/>
            </material>
        </visual>
        <collision>
            <origin xyz="0.42227721807846097 0 -0.2878109292090395" rpy="0 0 0"/>
            <geometry>
                <box size="0.8445544361569219 0.5452514732390275 0.575621858418079" />
            </geometry>
        </collision>
    </link>
    <joint name="Link2_Link3" type="revolute">
       <parent link="Link2"/>
       <child  link="Link3"/>
       <origin rpy="0 0 0" xyz="0.42227721807846097 0.2726257366195137 0.0" />
     <axis xyz="1 0 0"/>
       <limit effort="0.0" lower="-3.14159" upper="3.14159" velocity="0.0"/>
    </joint>
    <link name="Link3">
        <inertial>
            <origin xyz="0 0.1097243332439109 0.21537274537836393" rpy="0 0 0"/>
            <mass value="1" />
            <inertia ixx="100" ixy="0" ixz="0" iyy="100" iyz="0" izz="100" />
        </inertial>
        <visual>
            <origin xyz="0 0.1097243332439109 0.21537274537836393" rpy="0 0 0"/>
            <geometry>
                <box size="0.12129033024758429 0.2194486664878218 0.43074549075672786" />
            </geometry>
            <material name="Blue">
                <color rgba="0 0.0 1.0 1.0"/>
            </material>
        </visual>
        <collision>
            <origin xyz="0 0.1097243332439109 0.21537274537836393" rpy="0 0 0"/>
            <geometry>
                <box size="0.12129033024758429 0.2194486664878218 0.43074549075672786" />
            </geometry>
        </collision>
    </link>
    <joint name="Link3_Link4" type="revolute">
       <parent link="Link3"/>
       <child  link="Link4"/>
       <origin rpy="0 0 0" xyz="0 0.2194486664878218 0.43074549075672786" />
     <axis xyz="1 0 0"/>
       <limit effort="0.0" lower="-3.14159" upper="3.14159" velocity="0.0"/>
    </joint>
    <link name="Link4">
        <inertial>
            <origin xyz="0 0.498744770047931 0.3142899485997492" rpy="0 0 0"/>
            <mass value="1" />
            <inertia ixx="100" ixy="0" ixz="0" iyy="100" iyz="0" izz="100" />
        </inertial>
        <visual>
            <origin xyz="0 0.498744770047931 0.3142899485997492" rpy="0 0 0"/>
            <geometry>
                <box size="0.02797539181098807 0.997489540095862 0.6285798971994984" />
            </geometry>
            <material name="Green">
                <color rgba="0 1.0 0.0 1.0"/>
            </material>
        </visual>
        <collision>
            <origin xyz="0 0.498744770047931 0.3142899485997492" rpy="0 0 0"/>
            <geometry>
                <box size="0.02797539181098807 0.997489540095862 0.6285798971994984" />
            </geometry>
        </collision>
    </link>
</robot>