<robot name = "robot">
    <link name="Link0">
        <inertial>
            <origin xyz="0 0 2.2051185906666975" rpy="0 0 0"/>
            <mass value="1" />
            <inertia ixx="100" ixy="0" ixz="0" iyy="100" iyz="0" izz="100" />
        </inertial>
        <visual>
            <origin xyz="0 0 2.2051185906666975" rpy="0 0 0"/>
            <geometry>
                <box size="0.05243314529193621 0.7247660475640598 0.4102371813333954" />
            </geometry>
            <material name="Green">
                <color rgba="0 1.0 0.0 1.0"/>
            </material>
        </visual>
        <collision>
            <origin xyz="0 0 2.2051185906666975" rpy="0 0 0"/>
            <geometry>
                <box size="0.05243314529193621 0.7247660475640598 0.4102371813333954" />
            </geometry>
        </collision>
    </link>
    <joint name="Link0_Link1" type="revolute">
       <parent link="Link0"/>
       <child  link="Link1"/>
       <origin rpy="0 0 0" xyz="0 0.3623830237820299 2.4102371813333954" />
     <axis xyz="1 0 0"/>
       <limit effort="0.0" lower="-3.14159" upper="3.14159" velocity="0.0"/>
    </joint>
    <link name="Link1">
        <inertial>
            <origin xyz="0 0.3623830237820299 -0.2051185906666977" rpy="0 0 0"/>
            <mass value="1" />
            <inertia ixx="100" ixy="0" ixz="0" iyy="100" iyz="0" izz="100" />
        </inertial>
        <visual>
            <origin xyz="0 0.3623830237820299 -0.2051185906666977" rpy="0 0 0"/>
            <geometry>
                <box size="0.05243314529193621 0.7247660475640598 0.4102371813333954" />
            </geometry>
            <material name="Green">
                <color rgba="0 1.0 0.0 1.0"/>
            </material>
        </visual>
        <collision>
            <origin xyz="0 0.3623830237820299 -0.2051185906666977" rpy="0 0 0"/>
            <geometry>
                <box size="0.05243314529193621 0.7247660475640598 0.4102371813333954" />
            </geometry>
        </collision>
    </link>
    <joint name="Link1_Link2" type="revolute">
       <parent link="Link1"/>
       <child  link="Link2"/>
       <origin rpy="0 0 0" xyz="-0.026216572645968106 0.3623830237820299 0.0" />
     <axis xyz="0 1 0"/>
       <limit effort="0.0" lower="-3.14159" upper="3.14159" velocity="0.0"/>
    </joint>
    <link name="Link2">
        <inertial>
            <origin xyz="-0.45221688059405085 0 -0.21164766050500822" rpy="0 0 0"/>
            <mass value="1" />
            <inertia ixx="100" ixy="0" ixz="0" iyy="100" iyz="0" izz="100" />
        </inertial>
        <visual>
            <origin xyz="-0.45221688059405085 0 -0.21164766050500822" rpy="0 0 0"/>
            <geometry>
                <box size="0.9044337611881017 0.8225055137832121 0.42329532101001643" />
            </geometry>
            <material name="Blue">
                <color rgba="0 0.0 1.0 1.0"/>
            </material>
        </visual>
        <collision>
            <origin xyz="-0.45221688059405085 0 -0.21164766050500822" rpy="0 0 0"/>
            <geometry>
                <box size="0.9044337611881017 0.8225055137832121 0.42329532101001643" />
            </geometry>
        </collision>
    </link>
    <joint name="Link2_Link3" type="revolute">
       <parent link="Link2"/>
       <child  link="Link3"/>
       <origin rpy="0 0 0" xyz="-0.45221688059405085 0.41125275689160606 0.0" />
     <axis xyz="1 0 0"/>
       <limit effort="0.0" lower="-3.14159" upper="3.14159" velocity="0.0"/>
    </joint>
    <link name="Link3">
        <inertial>
            <origin xyz="0 0.07149479975707379 0.12516338827266876" rpy="0 0 0"/>
            <mass value="1" />
            <inertia ixx="100" ixy="0" ixz="0" iyy="100" iyz="0" izz="100" />
        </inertial>
        <visual>
            <origin xyz="0 0.07149479975707379 0.12516338827266876" rpy="0 0 0"/>
            <geometry>
                <box size="0.11473582190731868 0.14298959951414758 0.2503267765453375" />
            </geometry>
            <material name="Blue">
                <color rgba="0 0.0 1.0 1.0"/>
            </material>
        </visual>
        <collision>
            <origin xyz="0 0.07149479975707379 0.12516338827266876" rpy="0 0 0"/>
            <geometry>
                <box size="0.11473582190731868 0.14298959951414758 0.2503267765453375" />
            </geometry>
        </collision>
    </link>
    <joint name="Link3_Link4" type="revolute">
       <parent link="Link3"/>
       <child  link="Link4"/>
       <origin rpy="0 0 0" xyz="0 0.14298959951414758 0.2503267765453375" />
     <axis xyz="1 0 0"/>
       <limit effort="0.0" lower="-3.14159" upper="3.14159" velocity="0.0"/>
    </joint>
    <link name="Link4">
        <inertial>
            <origin xyz="0 0.11680037252542153 0.028115009250045953" rpy="0 0 0"/>
            <mass value="1" />
            <inertia ixx="100" ixy="0" ixz="0" iyy="100" iyz="0" izz="100" />
        </inertial>
        <visual>
            <origin xyz="0 0.11680037252542153 0.028115009250045953" rpy="0 0 0"/>
            <geometry>
                <box size="0.5629330206869404 0.23360074505084305 0.056230018500091905" />
            </geometry>
            <material name="Blue">
                <color rgba="0 0.0 1.0 1.0"/>
            </material>
        </visual>
        <collision>
            <origin xyz="0 0.11680037252542153 0.028115009250045953" rpy="0 0 0"/>
            <geometry>
                <box size="0.5629330206869404 0.23360074505084305 0.056230018500091905" />
            </geometry>
        </collision>
    </link>
    <joint name="Link4_Link5" type="revolute">
       <parent link="Link4"/>
       <child  link="Link5"/>
       <origin rpy="0 0 0" xyz="-0.2814665103434702 0.11680037252542153 0.056230018500091905" />
     <axis xyz="0 1 0"/>
       <limit effort="0.0" lower="-3.14159" upper="3.14159" velocity="0.0"/>
    </joint>
    <link name="Link5">
        <inertial>
            <origin xyz="-0.04991583871640015 0 -0.022142681466462644" rpy="0 0 0"/>
            <mass value="1" />
            <inertia ixx="100" ixy="0" ixz="0" iyy="100" iyz="0" izz="100" />
        </inertial>
        <visual>
            <origin xyz="-0.04991583871640015 0 -0.022142681466462644" rpy="0 0 0"/>
            <geometry>
                <box size="0.0998316774328003 0.8174132636032342 0.04428536293292529" />
            </geometry>
            <material name="Blue">
                <color rgba="0 0.0 1.0 1.0"/>
            </material>
        </visual>
        <collision>
            <origin xyz="-0.04991583871640015 0 -0.022142681466462644" rpy="0 0 0"/>
            <geometry>
                <box size="0.0998316774328003 0.8174132636032342 0.04428536293292529" />
            </geometry>
        </collision>
    </link>
</robot>